Workbook

Sheet SUT
A1: Supply and use table in mln euro, NLD 2015 | E1: SUPPLY | AL1: USE
E2: PRODUCTION | AH2: MARGINS PAID | AL2: INTERMEDIATE USE | BP2: INVESTMENT
E3: Products of agriculture, Hunting, Forestry, and Fishing | F3: Basic metals (Steel, Aluminum, Zinc) | G3: Chemical products (Nitric Acid, Urea, Chlorine, other) | H3: Rubber and Plastic (Ethylene, Propylene, other HVC) | I3: non-metallic mineral products (Glass, Ceramic) | J3: Paper and paperboard | K3: Food products and beverages | L3: Rest of economy | M3: Land transport | N3: Water transport (navigation) | O3: Air transport (aviation) | P3: Mining and production of coal products | Q3: Crude oil | R3: Production and refining of petroleum products for energy use | S3: Production and refining of petroleum products for chemical use | T3: Production of natural gas | U3: Production of bio gas | V3: Production of biomass | W3: Production of biofuels | X3: Electricity production by solid fossil fuels | Y3: Electricity production by gas | Z3: Electricity production by petroleum | AA3: Electricity production by hydro | AB3: Electricity production by wind | AC3: Electricity production by solar photovoltaic and solar thermal | AD3: Electricity production by biomass and biofuels | AE3: Electricity production by nuclear | AF3: Heat | AG3: Imports | AH3: Rest of economy | AI3: Land transport | AJ3: Taxes less subsidies | AK3: Margins supplied | AL3: Products of agriculture, Hunting, Forestry, and Fishing | AM3: Basic metals (Steel, Aluminum, Zinc) | AN3: Chemical products (Nitric Acid, Urea, Chlorine, other) | AO3: Rubber and Plastic (Ethylene, Propylene, other HVC) | AP3: non-metallic mineral products (Glass, Ceramic) | AQ3: Paper and paperboard | AR3: Food products and beverages | AS3: Rest of economy | AT3: Land transport | AU3: Water transport (navigation) | AV3: Air transport (aviation) | AW3: Mining and production of coal products | AX3: Crude oil | AY3: Production and refining of petroleum products for energy use | AZ3: Production and refining of petroleum products for chemical use | BA3: Production of natural gas | BB3: Production of bio gas | BC3: Production of biomass | BD3: Production of biofuels | BE3: Electricity production by solid fossil fuels | BF3: Electricity production by gas | BG3: Electricity production by petroleum | BH3: Electricity production by hydro | BI3: Electricity production by wind | BJ3: Electricity production by solar photovoltaic and solar thermal | BK3: Electricity production by biomass and biofuels | BL3: Electricity production by nuclear | BM3: Heat | BN3: Households | BO3: Government | BP3: Products of agriculture, Hunting, Forestry, and Fishing | BQ3: Basic metals (Steel, Aluminum, Zinc) | BR3: Chemical products (Nitric Acid, Urea, Chlorine, other) | BS3: Rubber and Plastic (Ethylene, Propylene, other HVC) | BT3: non-metallic mineral products (Glass, Ceramic) | BU3: Paper and paperboard | BV3: Food products and beverages | BW3: Rest of economy | BX3: Land transport | BY3: Water transport (navigation) | BZ3: Air transport (aviation) | CA3: Mining and production of coal products | CB3: Crude oil | CC3: Production and refining of petroleum products for energy use | CD3: Production and refining of petroleum products for chemical use | CE3: Production of natural gas | CF3: Production of bio gas | CG3: Production of biomass | CH3: Production of biofuels | CI3: Electricity production by solid fossil fuels | CJ3: Electricity production by gas | CK3: Electricity production by petroleum | CL3: Electricity production by hydro | CM3: Electricity production by wind | CN3: Electricity production by solar photovoltaic and solar thermal | CO3: Electricity production by biomass and biofuels | CP3: Electricity production by nuclear | CQ3: Heat | CR3: Exports | CS3: Stocks
E4: sagr | F4: smet | G4: schem | H4: spla | I4: sgla | J4: spap | K4: sfoo | L4: sres | M4: sroa | N4: swat | O4: sair | P4: scoa | Q4: soil | R4: spen | S4: spch | T4: sgas | U4: sgasb | V4: sbiom | W4: sbiof | X4: sesf | Y4: sega | Z4: sepe | AA4: sehy | AB4: sewi | AC4: seso | AD4: sebi | AE4: senu | AF4: shea | AH4: cres | AI4: croa | AL4: sagr | AM4: smet | AN4: schem | AO4: spla | AP4: sgla | AQ4: spap | AR4: sfoo | AS4: sres | AT4: sroa | AU4: swat | AV4: sair | AW4: scoa | AX4: soil | AY4: spen | AZ4: spch | BA4: sgas | BB4: sgasb | BC4: sbiom | BD4: sbiof | BE4: sesf | BF4: sega | BG4: sepe | BH4: sehy | BI4: sewi | BJ4: seso | BK4: sebi | BL4: senu | BM4: shea | BP4: sagr | BQ4: smet | BR4: schem | BS4: spla | BT4: sgla | BU4: spap | BV4: sfoo | BW4: sres | BX4: sroa | BY4: swat | BZ4: sair | CA4: scoa | CB4: soil | CC4: spen | CD4: spch | CE4: sgas | CF4: sgasb | CG4: sbiom | CH4: sbiof | CI4: sesf | CJ4: sega | CK4: sepe | CL4: sehy | CM4: sewi | CN4: seso | CO4: sebi | CP4: senu | CQ4: shea
E5: 1 | F5: 2 | G5: 3 | H5: 4 | I5: 5 | J5: 6 | K5: 7 | L5: 8 | M5: 9 | N5: 10 | O5: 11 | P5: 12 | Q5: 13 | R5: 14 | S5: 15 | T5: 16 | U5: 17 | V5: 18 | W5: 19 | X5: 20 | Y5: 21 | Z5: 22 | AA5: 23 | AB5: 24 | AC5: 25 | AD5: 26 | AE5: 27 | AF5: 28 | AG5: 29 | AH5: 30 | AI5: 31 | AJ5: 32 | AK5: 33 | AL5: 34 | AM5: 35 | AN5: 36 | AO5: 37 | AP5: 38 | AQ5: 39 | AR5: 40 | AS5: 41 | AT5: 42 | AU5: 43 | AV5: 44 | AW5: 45 | AX5: 46 | AY5: 47 | AZ5: 48 | BA5: 49 | BB5: 50 | BC5: 51 | BD5: 52 | BE5: 53 | BF5: 54 | BG5: 55 | BH5: 56 | BI5: 57 | BJ5: 58 | BK5: 59 | BL5: 60 | BM5: 61 | BN5: 62 | BO5: 63 | BP5: 64 | BQ5: 65 | BR5: 66 | BS5: 67 | BT5: 68 | BU5: 69 | BV5: 70 | BW5: 71 | BX5: 72 | BY5: 73 | BZ5: 74 | CA5: 75 | CB5: 76 | CC5: 77 | CD5: 78 | CE5: 79 | CF5: 80 | CG5: 81 | CH5: 82 | CI5: 83 | CJ5: 84 | CK5: 85 | CL5: 86 | CM5: 87 | CN5: 88 | CO5: 89 | CP5: 90 | CQ5: 91 | CR5: 92 | CS5: 93
A6: TOTAL | B6: Products of agriculture, Hunting, Forestry, and Fishing | C6: cagr | D6: 1 | E6: 27141 | F6: 0 | G6: 0 | H6: 0 | I6: 0 | J6: 0 | K6: 59 | L6: 97 | M6: 0 | N6: 0 | O6: 0 | P6: 0 | Q6: 0 | R6: 0 | S6: 0 | T6: 0 | U6: 0 | V6: 0 | W6: 0 | X6: 0 | Y6: 0 | Z6: 0 | AA6: 0 | AB6: 0 | AC6: 0 | AD6: 0 | AE6: 0 | AF6: 0 | AG6: 19866.714 | AH6: 8664.8465 | AI6: 975.15352 | AJ6: 770 | AK6: 0 | AL6: 5512.2958 | AM6: 0 | AN6: 6.7030199 | AO6: 68 | AP6: 0 | AQ6: 6 | AR6: 18522 | AS6: 1888.8902 | AT6: 0 | AU6: 0 | AV6: 0 | AW6: 0 | AX6: 0 | AY6: 0 | AZ6: 2.0929288 | BA6: 0 | BB6: 0 | BC6: 28.672156 | BD6: 0.20405129 | BE6: 0 | BF6: 0 | BG6: 0 | BH6: 0 | BI6: 0 | BJ6: 0 | BK6: 0 | BL6: 0 | BM6: 0 | BN6: 6580 | BO6: 0 | BP6: 364.96406 | BQ6: 0 | BR6: 0 | BS6: 0 | BT6: 0 | BU6: 0 | BV6: 0 | BW6: 0 | BX6: 0 | BY6: 0 | BZ6: 0 | CA6: 0 | CB6: 0 | CC6: 0 | CD6: 0 | CE6: 0 | CF6: 0 | CG6: 0.035938268 | CH6: 0 | CI6: 0 | CJ6: 0 | CK6: 0 | CL6: 0 | CM6: 0 | CN6: 0 | CO6: 0 | CP6: 0 | CQ6: 0 | CR6: 24703.492 | CS6: -109.63527
B7: Basic metals (Steel, Aluminum, Zinc) | C7: cmet | D7: 2 | E7: 0 | F7: 5680.2037 | G7: 74 | H7: 6 | I7: 0 | J7: 0 | K7: 16 | L7: 1194 | M7: 0 | N7: 0 | O7: 0 | P7: 0 | Q7: 0 | R7: 0 | S7: 0 | T7: 0 | U7: 0 | V7: 0 | W7: 0 | X7: 0 | Y7: 0 | Z7: 0 | AA7: 0 | AB7: 0 | AC7: 0 | AD7: 0 | AE7: 0 | AF7: 0 | AG7: 13433 | AH7: 2738.7746 | AI7: 308.22539 | AJ7: 65 | AK7: 0 | AL7: 6 | AM7: 1559.2002 | AN7: 134.80518 | AO7: 78 | AP7: 91 | AQ7: 4 | AR7: 0 | AS7: 9070.0257 | AT7: 0 | AU7: 0 | AV7: 0 | AW7: 0 | AX7: 0 | AY7: 0 | AZ7: 42.091124 | BA7: 64.428495 | BB7: 0 | BC7: 2.9742558 | BD7: 4.1036981 | BE7: 0 | BF7: 0 | BG7: 0 | BH7: 0 | BI7: 0 | BJ7: 0 | BK7: 0 | BL7: 0 | BM7: 0 | BN7: 0 | BO7: 0 | BP7: 0 | BQ7: 0 | BR7: 0 | BS7: 0 | BT7: 0 | BU7: 0 | BV7: 0 | BW7: 0 | BX7: 0 | BY7: 0 | BZ7: 0 | CA7: 0 | CB7: 0 | CC7: 0 | CD7: 0 | CE7: 0 | CF7: 0 | CG7: 0 | CH7: 0 | CI7: 0 | CJ7: 0 | CK7: 0 | CL7: 0 | CM7: 0 | CN7: 0 | CO7: 0 | CP7: 0 | CQ7: 0 | CR7: 12941 | CS7: -482.42498
B8: Chemical products (Nitric Acid, Urea, Chlorine, other) | C8: cchem | D8: 3 | E8: 1 | F8: 45 | G8: 27202.397 | H8: 145 | I8: 18 | J8: 2 | K8: 242 | L8: 1305 | M8: 0 | N8: 0 | O8: 0 | P8: 0 | Q8: 0 | R8: 608 | S8: 0 | T8: 0 | U8: 0 | V8: 0 | W8: 0 | X8: 0 | Y8: 0 | Z8: 0 | AA8: 0 | AB8: 0 | AC8: 0 | AD8: 0 | AE8: 0 | AF8: 0 | AG8: 22860.832 | AH8: 6319.9203 | AI8: 711.25237 | AJ8: 973.69807 | AK8: 0 | AL8: 802.51345 | AM8: 26.977816 | AN8: 12031.503 | AO8: 2737.3353 | AP8: 110.39994 | AQ8: 540.13854 | AR8: 597.48023 | AS8: 5009.017 | AT8: 1.9075392 | AU8: 0 | AV8: 0 | AW8: 0 | AX8: 0 | AY8: 0 | AZ8: 3756.6768 | BA8: 1.1147639 | BB8: 0 | BC8: 8.9133873 | BD8: 366.25933 | BE8: 0 | BF8: 0 | BG8: 0 | BH8: 0 | BI8: 0 | BJ8: 0 | BK8: 0 | BL8: 0 | BM8: 0 | BN8: 4830.2497 | BO8: 0 | BP8: 0 | BQ8: 0 | BR8: 0 | BS8: 0 | BT8: 0 | BU8: 0 | BV8: 0 | BW8: 0 | BX8: 0 | BY8: 0 | BZ8: 0 | CA8: 0 | CB8: 0 | CC8: 0 | CD8: 0 | CE8: 0 | CF8: 0 | CG8: 0 | CH8: 0 | CI8: 0 | CJ8: 0 | CK8: 0 | CL8: 0 | CM8: 0 | CN8: 0 | CO8: 0 | CP8: 0 | CQ8: 0 | CR8: 39306.098 | CS8: -9692.484
B9: Rubber and Plastic (Ethylene, Propylene, other HVC) | C9: cpla | D9: 4 | E9: 0 | F9: 10 | G9: 410 | H9: 7447 | I9: 0 | J9: 70 | K9: 0 | L9: 478 | M9: 0 | N9: 0 | O9: 0 | P9: 0 | Q9: 0 | R9: 0 | S9: 0 | T9: 0 | U9: 0 | V9: 0 | W9: 0 | X9: 0 | Y9: 0 | Z9: 0 | AA9: 0 | AB9: 0 | AC9: 0 | AD9: 0 | AE9: 0 | AF9: 0 | AG9: 9919 | AH9: 2312.723 | AI9: 260.27697 | AJ9: 496 | AK9: 0 | AL9: 189 | AM9: 35.531774 | AN9: 175.0233 | AO9: 870 | AP9: 272 | AQ9: 151 | AR9: 881 | AS9: 6783.9779 | AT9: 341 | AU9: 19 | AV9: 4 | AW9: 0.35342535 | AX9: 5.22368 | AY9: 17.605453 | AZ9: 54.648697 | BA9: 29.525483 | BB9: 0.18775794 | BC9: 29.483927 | BD9: 5.3280058 | BE9: 4.3842563 | BF9: 7.2753329 | BG9: 0.083638041 | BH9: 0.010318029 | BI9: 0.70890725 | BJ9: 0.0013837628 | BK9: 0.29062514 | BL9: 0.45389491 | BM9: 1.9022607 | BN9: 1754 | BO9: 0 | BP9: 71.505328 | BQ9: 25.532581 | BR9: 3.5335706 | BS9: 18.219115 | BT9: 68.388582 | BU9: 11.726059 | BV9: 4.7081328 | BW9: 8.6790108 | BX9: 0.50282946 | BY9: 0.84403555 | BZ9: 19.035428 | CA9: 0.026962011 | CB9: 0.0037046422 | CC9: 1.2118907 | CD9: 64.517871 | CE9: 27.334081 | CF9: 3.1622494 | CG9: 1.726716 | CH9: 34.930276 | CI9: 12.347833 | CJ9: 4.697345 | CK9: 4.6705542 | CL9: 0.38734606 | CM9: 0.82852665 | CN9: 0.24038223 | CO9: 0.027461648 | CP9: 0.0037003596 | CQ9: 1.2084276 | CR9: 9261 | CS9: 119
B10: non-metallic mineral products (Glass, Ceramic) | C10: cgla | D10: 5 | E10: 0 | F10: 30 | G10: 0 | H10: 13 | I10: 4655 | J10: 0 | K10: 0 | L10: 451 | M10: 0 | N10: 0 | O10: 0 | P10: 0 | Q10: 0 | R10: 0 | S10: 0 | T10: 0 | U10: 0 | V10: 0 | W10: 0 | X10: 0 | Y10: 0 | Z10: 0 | AA10: 0 | AB10: 0 | AC10: 0 | AD10: 0 | AE10: 0 | AF10: 0 | AG10: 3578 | AH10: 3109.0979 | AI10: 349.90208 | AJ10: 323 | AK10: 0 | AL10: 63 | AM10: 46.095274 | AN10: 17.12994 | AO10: 35 | AP10: 948 | AQ10: 0 | AR10: 350 | AS10: 7237.2121 | AT10: 2 | AU10: 0 | AV10: 0 | AW10: 0 | AX10: 1.11936 | AY10: 0 | AZ10: 5.3485959 | BA10: 7.9081836 | BB10: 0.11734871 | BC10: 3.1035712 | BD10: 0.5214644 | BE10: 2.7401602 | BF10: 4.5470831 | BG10: 0.052273776 | BH10: 0.0064487683 | BI10: 0.44306703 | BJ10: 0.00086485175 | BK10: 0.18164071 | BL10: 0.28368432 | BM10: 1.1889129 | BN10: 1086 | BO10: 0 | BP10: 0.74698578 | BQ10: 0.71705283 | BR10: 0.422712 | BS10: 149.28825 | BT10: 1.6837242 | BU10: 0.028568192 | BV10: 1.5190507 | BW10: 3.9703838 | BX10: 0.039355 | BY10: 1.8207668 | BZ10: 0.034021249 | CA10: 0.28799276 | CB10: 0.12096352 | CC10: 0.78961389 | CD10: 0.67399078 | CE10: 0.76764587 | CF10: 0.37829179 | CG10: 14.148788 | CH10: 0.85998202 | CI10: 0.030083019 | CJ10: 1.5155701 | CK10: 2.1366367 | CL10: 0.030316451 | CM10: 1.7873108 | CN10: 0.00042962541 | CO10: 0.29332959 | CP10: 0.12082369 | CQ10: 0.78735753 | CR10: 2498 | CS10: 14
B11: Paper and paperboard | C11: cpap | D11: 6 | E11: 0 | F11: 19 | G11: 54 | H11: 36 | I11: 0 | J11: 6202 | K11: 0 | L11: 467 | M11: 0 | N11: 0 | O11: 0 | P11: 0 | Q11: 0 | R11: 0 | S11: 0 | T11: 0 | U11: 0 | V11: 0 | W11: 0 | X11: 0 | Y11: 0 | Z11: 0 | AA11: 0 | AB11: 0 | AC11: 0 | AD11: 0 | AE11: 0 | AF11: 0 | AG11: 5611 | AH11: 2361.2605 | AI11: 265.73945 | AJ11: 396 | AK11: 0 | AL11: 27 | AM11: 30.730183 | AN11: 67.030199 | AO11: 98 | AP11: 37 | AQ11: 2338 | AR11: 1320 | AS11: 3849.9659 | AT11: 54 | AU11: 14 | AV11: 6 | AW11: 0.039269483 | AX11: 2.4874667 | AY11: 1.9561615 | AZ11: 20.929288 | BA11: 14.615403 | BB11: 0.088011533 | BC11: 1.0345237 | BD11: 2.0405129 | BE11: 2.0551202 | BF11: 3.4103123 | BG11: 0.039205332 | BH11: 0.0048365762 | BI11: 0.33230027 | BJ11: 0.00064863881 | BK11: 0.13623053 | BL11: 0.21276324 | BM11: 0.89168471 | BN11: 1788 | BO11: 0 | BP11: 0 | BQ11: 0 | BR11: 0 | BS11: 0 | BT11: 0 | BU11: 0 | BV11: 0 | BW11: 0 | BX11: 0 | BY11: 0 | BZ11: 0 | CA11: 0 | CB11: 0 | CC11: 0 | CD11: 0 | CE11: 0 | CF11: 0 | CG11: 0 | CH11: 0 | CI11: 0 | CJ11: 0 | CK11: 0 | CL11: 0 | CM11: 0 | CN11: 0 | CO11: 0 | CP11: 0 | CQ11: 0 | CR11: 5722 | CS11: 10
B12: Food products and beverages | C12: cfoo | D12: 7 | E12: 329 | F12: 0 | G12: 105 | H12: 0 | I12: 0 | J12: 0 | K12: 63777 | L12: 1540 | M12: 0 | N12: 0 | O12: 0 | P12: 0 | Q12: 0 | R12: 0 | S12: 0 | T12: 0 | U12: 0 | V12: 0 | W12: 0 | X12: 0 | Y12: 0 | Z12: 0 | AA12: 0 | AB12: 0 | AC12: 0 | AD12: 0 | AE12: 0 | AF12: 0 | AG12: 33613 | AH12: 24986.936 | AI12: 2812.0636 | AJ12: 7866 | AK12: 0 | AL12: 4484 | AM12: 1.9206364 | AN12: 307.59413 | AO12: 28 | AP12: 1 | AQ12: 41 | AR12: 18730 | AS12: 10438.677 | AT12: 20 | AU12: 4 | AV12: 5 | AW12: 5.9296919 | AX12: 0.12437333 | AY12: 295.38038 | AZ12: 96.042179 | BA12: 1.4363412 | BB12: 1.0620058 | BC12: 0 | BD12: 9.3636868 | BE12: 24.79845 | BF12: 41.151102 | BG12: 0.47307767 | BH12: 0.058361353 | BI12: 4.0097566 | BJ12: 0.0078269084 | BK12: 1.6438484 | BL12: 2.5673431 | BM12: 10.759662 | BN12: 41288 | BO12: 0 | BP12: 0 | BQ12: 0 | BR12: 0 | BS12: 0 | BT12: 0 | BU12: 0 | BV12: 0 | BW12: 0 | BX12: 0 | BY12: 0 | BZ12: 0 | CA12: 0 | CB12: 0 | CC12: 0 | CD12: 0 | CE12: 0 | CF12: 0 | CG12: 0 | CH12: 0 | CI12: 0 | CJ12: 0 | CK12: 0 | CL12: 0 | CM12: 0 | CN12: 0 | CO12: 0 | CP12: 0 | CQ12: 0 | CR12: 58525 | CS12: 660
B13: Rest of economy | C13: cres | D13: 8 | E13: 2477 | F13: 966 | G13: 2568 | H13: 675 | I13: 340 | J13: 272 | K13: 2265 | L13: 1038958.3 | M13: 5179 | N13: 178 | O13: 1316 | P13: 0 | Q13: 0 | R13: 320 | S13: 0 | T13: 0 | U13: 0 | V13: 0 | W13: 0 | X13: 0 | Y13: 0 | Z13: 0 | AA13: 0 | AB13: 0 | AC13: 0 | AD13: 0 | AE13: 0 | AF13: 0 | AG13: 316063.32 | AH13: 72562.89 | AI13: 8166.3256 | AJ13: 42572.414 | AK13: 130592 | AL13: 4880.4415 | AM13: 1932.8939 | AN13: 6578.6872 | AO13: 1592.6117 | AP13: 1532.9833 | AQ13: 1638.2076 | AR13: 9993.45 | AS13: 449526.2 | AT13: 13014.514 | AU13: 2217 | AV13: 2549 | AW13: 19.948897 | AX13: 658.92205 | AY13: 993.73002 | AZ13: 2054.1076 | BA13: 3616.1843 | BB13: 28.53983 | BC13: 244.29596 | BD13: 200.26639 | BE13: 666.42153 | BF13: 1105.8748 | BG13: 12.71326 | BH13: 1.5683747 | BI13: 107.75626 | BJ13: 0.21033654 | BK13: 44.175987 | BL13: 68.993535 | BM13: 289.14995 | BN13: 222722.88 | BO13: 171490.55 | BP13: 4354.3251 | BQ13: 295.71825 | BR13: 1824.8905 | BS13: 162.85999 | BT13: 162.89901 | BU13: 167.51084 | BV13: 2425.1828 | BW13: 128137.74 | BX13: 6433.9723 | BY13: 1016.3172 | BZ13: 806.50069 | CA13: 12.622476 | CB13: 310.41036 | CC13: 642.46084 | CD13: 505.84123 | CE13: 1652.1986 | CF13: 29.542505 | CG13: 0.7436889 | CH13: 19.882938 | CI13: 760.13032 | CJ13: 1275.7045 | CK13: 7.9298752 | CL13: 1.4003796 | CM13: 122.29399 | CN13: 0.0030078717 | CO13: 50.887509 | CP13: 79.851994 | CQ13: 333.18354 | CR13: 321404.1 | CS13: -8492.0935
B14: Land transport | C14: croa | D14: 9 | E14: 252 | F14: 0 | G14: 0 | H14: 0 | I14: 0 | J14: 0 | K14: 0 | L14: 2901 | M14: 50076 | N14: 905 | O14: 37 | P14: 0 | Q14: 0 | R14: 0 | S14: 0 | T14: 0 | U14: 0 | V14: 0 | W14: 0 | X14: 0 | Y14: 0 | Z14: 0 | AA14: 0 | AB14: 0 | AC14: 0 | AD14: 0 | AE14: 0 | AF14: 0 | AG14: 10351 | AH14: 0 | AI14: 0 | AJ14: 534 | AK14: 14697 | AL14: 287 | AM14: 24.007955 | AN14: 236.84004 | AO14: 24 | AP14: 24 | AQ14: 18 | AR14: 224 | AS14: 9486.6619 | AT14: 14551 | AU14: 1061 | AV14: 1624 | AW14: 18.770813 | AX14: 33.456427 | AY14: 935.04518 | AZ14: 73.950152 | BA14: 182.61273 | BB14: 0.72756201 | BC14: 1.1638392 | BD14: 7.2098121 | BE14: 16.988993 | BF14: 28.191915 | BG14: 0.32409741 | BH14: 0.039982363 | BI14: 2.7470156 | BJ14: 0.0053620809 | BK14: 1.1261724 | BL14: 1.7588428 | BM14: 7.3712602 | BN14: 4878 | BO14: 819 | BP14: 0 | BQ14: 0 | BR14: 0 | BS14: 0 | BT14: 0 | BU14: 0 | BV14: 0 | BW14: 0 | BX14: 0 | BY14: 0 | BZ14: 0 | CA14: 0 | CB14: 0 | CC14: 0 | CD14: 0 | CE14: 0 | CF14: 0 | CG14: 0 | CH14: 0 | CI14: 0 | CJ14: 0 | CK14: 0 | CL14: 0 | CM14: 0 | CN14: 0 | CO14: 0 | CP14: 0 | CQ14: 0 | CR14: 15790 | CS14: 3.1832315e-12
B15: Water transport (navigation) | C15: cwat | D15: 10 | E15: 2 | F15: 0 | G15: 0 | H15: 0 | I15: 0 | J15: 0 | K15: 0 | L15: 126 | M15: 39 | N15: 8324 | O15: 0 | P15: 0 | Q15: 0 | R15: 0 | S15: 0 | T15: 0 | U15: 0 | V15: 0 | W15: 0 | X15: 0 | Y15: 0 | Z15: 0 | AA15: 0 | AB15: 0 | AC15: 0 | AD15: 0 | AE15: 0 | AF15: 0 | AG15: 2291 | AH15: 0 | AI15: 0 | AJ15: 5 | AK15: 0 | AL15: 0 | AM15: 0 | AN15: 0 | AO15: 0 | AP15: 0 | AQ15: 0 | AR15: 0 | AS15: 832 | AT15: 429 | AU15: 2090 | AV15: 0 | AW15: 0 | AX15: 0 | AY15: 0 | AZ15: 0 | BA15: 0 | BB15: 0 | BC15: 0 | BD15: 0 | BE15: 0 | BF15: 0 | BG15: 0 | BH15: 0 | BI15: 0 | BJ15: 0 | BK15: 0 | BL15: 0 | BM15: 0 | BN15: 198 | BO15: 0 | BP15: 0 | BQ15: 0 | BR15: 0 | BS15: 0 | BT15: 0 | BU15: 0 | BV15: 0 | BW15: 0 | BX15: 0 | BY15: 0 | BZ15: 0 | CA15: 0 | CB15: 0 | CC15: 0 | CD15: 0 | CE15: 0 | CF15: 0 | CG15: 0 | CH15: 0 | CI15: 0 | CJ15: 0 | CK15: 0 | CL15: 0 | CM15: 0 | CN15: 0 | CO15: 0 | CP15: 0 | CQ15: 0 | CR15: 7238 | CS15: 1.3642421e-12
B16: Air transport (aviation) | C16: cair | D16: 11 | E16: 0 | F16: 0 | G16: 0 | H16: 0 | I16: 0 | J16: 0 | K16: 0 | L16: 213 | M16: 10 | N16: 0 | O16: 9882 | P16: 0 | Q16: 0 | R16: 0 | S16: 0 | T16: 0 | U16: 0 | V16: 0 | W16: 0 | X16: 0 | Y16: 0 | Z16: 0 | AA16: 0 | AB16: 0 | AC16: 0 | AD16: 0 | AE16: 0 | AF16: 0 | AG16: 1638 | AH16: 0 | AI16: 0 | AJ16: 0 | AK16: 0 | AL16: 20.973908 | AM16: 0 | AN16: 2.23434 | AO16: 0 | AP16: 1 | AQ16: 0 | AR16: 8 | AS16: 1262.0439 | AT16: 139 | AU16: 0 | AV16: 758 | AW16: 0 | AX16: 0 | AY16: 0 | AZ16: 0.69764295 | BA16: 0 | BB16: 0.011734871 | BC16: 3.0260918 | BD16: 0.068017095 | BE16: 0.27401602 | BF16: 0.45470831 | BG16: 0.0052273776 | BH16: 0.00064487683 | BI16: 0.044306703 | BJ16: 8.6485175e-05 | BK16: 0.018164071 | BL16: 0.028368432 | BM16: 0.11889129 | BN16: 2284 | BO16: 0 | BP16: 0 | BQ16: 0 | BR16: 0 | BS16: 0 | BT16: 0 | BU16: 0 | BV16: 0 | BW16: 0 | BX16: 0 | BY16: 0 | BZ16: 0 | CA16: 0 | CB16: 0 | CC16: 0 | CD16: 0 | CE16: 0 | CF16: 0 | CG16: 0 | CH16: 0 | CI16: 0 | CJ16: 0 | CK16: 0 | CL16: 0 | CM16: 0 | CN16: 0 | CO16: 0 | CP16: 0 | CQ16: 0 | CR16: 7263 | CS16: 0
B17: Coal and coal products | C17: ccoa | D17: 12 | E17: 0 | F17: 0 | G17: 0 | H17: 0 | I17: 0 | J17: 0 | K17: 0 | L17: 0 | M17: 0 | N17: 0 | O17: 0 | P17: 685.74406 | Q17: 0 | R17: 0 | S17: 0 | T17: 0 | U17: 0 | V17: 0 | W17: 0 | X17: 0 | Y17: 0 | Z17: 0 | AA17: 0 | AB17: 0 | AC17: 0 | AD17: 0 | AE17: 0 | AF17: 0 | AG17: 5261.6294 | AH17: 296.85896 | AI17: 33.408909 | AJ17: 592.30841 | AK17: 0 | AL17: 2.0240808 | AM17: 1894.7819 | AN17: 6.1330781 | AO17: 0.186632 | AP17: 29.071126 | AQ17: 0.2124099 | AR17: 18.450329 | AS17: 24.539852 | AT17: 0 | AU17: 0 | AV17: 0 | AW17: 1397.786 | AX17: 0.14022454 | AY17: 21.392523 | AZ17: 0.025415026 | BA17: 252.01732 | BB17: 0.0021509817 | BC17: 0.00074192201 | BD17: 0.00046027643 | BE17: 6530.1917 | BF17: 0.028300658 | BG17: 0.00032534753 | BH17: 4.0136585e-05 | BI17: 0.0027576115 | BJ17: 5.3827637e-06 | BK17: 0.0011305163 | BL17: 0.001765627 | BM17: 0.019495612 | BN17: 0.71560225 | BO17: 0.00094528766 | BP17: 0 | BQ17: 0 | BR17: 0 | BS17: 0 | BT17: 0 | BU17: 0 | BV17: 0 | BW17: 0 | BX17: 0 | BY17: 0 | BZ17: 0 | CA17: 0 | CB17: 0 | CC17: 0 | CD17: 0 | CE17: 0 | CF17: 0 | CG17: 0 | CH17: 0 | CI17: 0 | CJ17: 0 | CK17: 0 | CL17: 0 | CM17: 0 | CN17: 0 | CO17: 0 | CP17: 0 | CQ17: 0 | CR17: 56.279533 | CS17: -3364.056
B18: Crude oil | C18: coil | D18: 13 | E18: 0 | F18: 0 | G18: 0 | H18: 0 | I18: 0 | J18: 0 | K18: 0 | L18: 0 | M18: 0 | N18: 0 | O18: 0 | P18: 0 | Q18: 2347.4223 | R18: 0 | S18: 0 | T18: 0 | U18: 0 | V18: 0 | W18: 0 | X18: 0 | Y18: 0 | Z18: 0 | AA18: 0 | AB18: 0 | AC18: 0 | AD18: 0 | AE18: 0 | AF18: 0 | AG18: 25079.294 | AH18: 761.84559 | AI18: 85.739131 | AJ18: 1412.2971 | AK18: 0 | AL18: 39.450975 | AM18: 27.231824 | AN18: 119.53866 | AO18: 3.637609 | AP18: 17.464542 | AQ18: 4.1400411 | AR18: 26.247057 | AS18: 255.09102 | AT18: 0 | AU18: 0 | AV18: 0 | AW18: 0.028005771 | AX18: 1.3101976 | AY18: 26065.195 | AZ18: 520.62985 | BA18: 0.46854635 | BB18: 0.0065979393 | BC18: 0.014460661 | BD18: 0.0089711607 | BE18: 0.054950279 | BF18: 0.091185721 | BG18: 0.0010482812 | BH18: 0.0001293215 | BI18: 0.0088851217 | BJ18: 1.7343455e-05 | BK18: 0.0036425636 | BL18: 0.0056889128 | BM18: 0.059801005 | BN18: 0 | BO18: 0 | BP18: 0 | BQ18: 0 | BR18: 0 | BS18: 0 | BT18: 0 | BU18: 0 | BV18: 0 | BW18: 0 | BX18: 0 | BY18: 0 | BZ18: 0 | CA18: 0 | CB18: 0 | CC18: 0 | CD18: 0 | CE18: 0 | CF18: 0 | CG18: 0 | CH18: 0 | CI18: 0 | CJ18: 0 | CK18: 0 | CL18: 0 | CM18: 0 | CN18: 0 | CO18: 0 | CP18: 0 | CQ18: 0 | CR18: 140.02997 | CS18: 2465.8788
... B28: Waste | C28: cwas | D28: 23 | E28: 0 | F28: 0 | G28: 0 | H28: 0 | I28: 0 | J28: 0 | K28: 0 | L28: 603.81654 | M28: 0 | N28: 0 | O28: 0 | P28: 0 | Q28: 0 | R28: 0 | S28: 0 | T28: 0 | U28: 0 | V28: 0 | W28: 0 | X28: 0 | Y28: 0 | Z28: 0 | AA28: 0 | AB28: 0 | AC28: 0 | AD28: 0 | AE28: 0 | AF28: 0 | AG28: 166.39493 | AH28: 5.1915804 | AI28: 0.58426747 | AJ28: 15.85991 | AK28: 0 | AL28: 0 | AM28: 0 | AN28: 0 | AO28: 0 | AP28: 0 | AQ28: 0 | AR28: 0 | AS28: 33.212964 | AT28: 0 | AU28: 0 | AV28: 0 | AW28: 0 | AX28: 0 | AY28: 0 | AZ28: 0 | BA28: 0 | BB28: 0 | BC28: 0 | BD28: 0 | BE28: 234.01822 | BF28: 388.33506 | BG28: 4.4643433 | BH28: 0.5507449 | BI28: 37.839304 | BJ28: 0.073861033 | BK28: 15.512683 | BL28: 24.227524 | BM28: 0 | BN28: 0 | BO28: 0 | BP28: 0 | BQ28: 0 | BR28: 0 | BS28: 0 | BT28: 0 | BU28: 0 | BV28: 0 | BW28: 0 | BX28: 0 | BY28: 0 | BZ28: 0 | CA28: 0 | CB28: 0 | CC28: 0 | CD28: 0 | CE28: 0 | CF28: 0 | CG28: 0 | CH28: 0 | CI28: 0 | CJ28: 0 | CK28: 0 | CL28: 0 | CM28: 0 | CN28: 0 | CO28: 0 | CP28: 0 | CQ28: 0 | CR28: 26.361178 | CS28: 27.251352
B29: Total | D29: 24 | E29: 30202 | F29: 6771.2037 | G29: 31118.397 | H29: 8322 | I29: 5013 | J29: 6546 | K29: 66359 | L29: 1048382.2 | M29: 55304 | N29: 9407 | O29: 11235 | P29: 685.74406 | Q29: 2347.4223 | R29: 34159.505 | S29: 9716.3059 | T29: 12949.501 | U29: 104.78653 | V29: 671.14728 | W29: 947.29676 | X29: 2446.8261 | Y29: 4060.3178 | Z29: 46.677868 | AA29: 5.7584277 | AB29: 395.63671 | AC29: 0.77226937 | AD29: 162.19607 | AE29: 253.31591 | AF29: 1061.6398
B30: Value added | D30: 25 | E30: 11263.607 | F30: 316.13795 | G30: 9559.3355 | H30: 2730.1462 | I30: 1567.0165 | J30: 1428.8866 | K30: 14500 | L30: 531602.5 | M30: 23954.798 | N30: 3101.7825 | O30: 3533.2079 | P30: -782.21174 | Q30: 1338.8742 | R30: -11714.72 | S30: -5182.1012 | T30: 8619.6599 | U30: 73.908167 | V30: 344.69288 | W30: -20.355598 | X30: -5035.2322 | Y30: -691.48594 | Z30: -289.9213 | AA30: -6.6095799 | AB30: -454.1157 | AC30: -0.88641838 | AD30: -454.98472 | AE30: 154.76527 | AF30: 102.9474 | AK30: Coal and coal products | AL30: =AL17/ENR!AL17 -> 812.17964 | AM30: =AM17/ENR!AM17 -> 812.17964 | AN30: =AN17/ENR!AN17 -> 812.17964 | AO30: =AO17/ENR!AO17 -> 812.17964 | AP30: =AP17/ENR!AP17 -> 812.17964 | AQ30: =AQ17/ENR!AQ17 -> 812.17964 | AR30: =AR17/ENR!AR17 -> 812.17964 | AS30: =AS17/ENR!AS17 -> 812.94982 | ... CS30: =CS17/ENR!CS17 -> #DIV/0!
B31: Taxes on sectors | D31: 26 | E31: -722.21739 | F31: 4.801591 | G31: 11.1717 | H31: -10 | I31: 18 | J31: 12 | K31: 80 | L31: 2893.0535 | M31: -748 | N31: -63 | O31: 39 | P31: 0.82465914 | Q31: 0.74624 | R31: 41.079391 | S31: 3.4882147 | T31: 4.2966641 | U31: 0.68062252 | V31: -4.0412457 | W31: 0.34008548 | X31: 15.892929 | Y31: 26.373082 | Z31: 0.3031879 | AA31: 0.037402856 | AB31: 2.5697888 | AC31: 0.0050161402 | AD31: 1.0535161 | AE31: 1.6453691 | AF31: 6.8956951 | AK31: Crude oil | AL31: =AL18/ENR!AL18 -> 416.9602 | AM31: =AM18/ENR!AM18 -> 416.9602 | AN31: =AN18/ENR!AN18 -> 416.9602 | AO31: =AO18/ENR!AO18 -> 416.9602 | AP31: =AP18/ENR!AP18 -> 416.9602 | AQ31: =AQ18/ENR!AQ18 -> 416.9602 | AR31: =AR18/ENR!AR18 -> 416.9602 | AS31: =AS18/ENR!AS18 -> 417.31557 | ... CS31: =CS18/ENR!CS18 -> #DIV/0!
B32: Wages | D32: 27 | E32: 10320.669 | F32: 978.56425 | G32: 2121.1334 | H32: 1310 | I32: 885 | J32: 809 | K32: 7261 | L32: 291972.36 | M32: 12427 | N32: 1238 | O32: 1599 | P32: 8.4233041 | Q32: 116.16469 | R32: 419.59663 | S32: 662.2957 | T32: 664.44129 | U32: 11.001442 | V32: 125.39319 | W32: 64.570896 | X32: 256.89002 | Y32: 426.28904 | Z32: 4.9006665 | AA32: 0.60457203 | AB32: 41.537534 | AC32: 0.081079852 | AD32: 17.028817 | AE32: 26.595405 | AF32: 111.46059 | AK32: Gasoline and other fuels | AL32: =AL19/ENR!AL19 -> 1105.4274 | AM32: =AM19/ENR!AM19 -> 1001.1077 | AN32: =AN19/ENR!AN19 -> 1001.1077 | AO32: =AO19/ENR!AO19 -> 1001.1077 | AP32: =AP19/ENR!AP19 -> 1001.1077 | AQ32: =AQ19/ENR!AQ19 -> 1001.1077 | AR32: =AR19/ENR!AR19 -> 1004.8123 | AS32: =AS19/ENR!AS19 -> 3189.3746 | ... CS32: =CS19/ENR!CS19 -> #DIV/0!
B33: Employer social contribution | D33: 28 | E33: 603.38259 | F33: 242.00019 | G33: 471.44573 | H33: 332 | I33: 265 | J33: 191 | K33: 1227 | L33: 61630.57 | M33: 3215 | N33: 182 | O33: 410 | P33: 3.4753492 | Q33: 39.426347 | R33: 173.12029 | S33: 147.20266 | T33: 221.85929 | U33: 2.2178906 | V33: 27.454168 | W33: 14.351607 | X33: 51.789028 | Y33: 85.93987 | Z33: 0.98797436 | AA33: 0.12188172 | AB33: 8.3739669 | AC33: 0.016345698 | AD33: 3.4330095 | AE33: 5.3616336 | AF33: 22.470455 | AK33: Petroleum products for chemical use | AL33: =AL20/ENR!AL20 -> 511.5658 | AM33: =AM20/ENR!AM20 -> 511.5658 | AN33: =AN20/ENR!AN20 -> 511.5658 | AO33: =AO20/ENR!AO20 -> 511.5658 | AP33: =AP20/ENR!AP20 -> 511.5658 | AQ33: =AQ20/ENR!AQ20 -> 511.5658 | AR33: =AR20/ENR!AR20 -> 511.5658 | AS33: =AS20/ENR!AS20 -> 511.99139 | ... CS33: =CS20/ENR!CS20 -> #DIV/0!
B34: Labor | D34: 29 | E34: 192.4651 | F34: 18.243975 | G34: 32.021904 | H34: 30.996481 | I34: 20.997616 | J34: 16.99807 | K34: 127.98547 | L34: 7945.8031 | M34: 334.96197 | N34: 20.997616 | O34: 24.997162 | P34: 0.098162562 | Q34: 1.3679514 | R34: 4.8898485 | S34: 9.9984138 | T34: 8.102016 | U34: 0.15840278 | V34: 3.1937844 | W34: 0.97480103 | X34: 3.6987963 | Y34: 6.1378653 | Z34: 0.070561586 | AA34: 0.0087048489 | AB34: 0.59807259 | AC34: 0.0011674173 | AD34: 0.24518712 | AE34: 0.38293036 | AF34: 1.6048503 | AK34: Electricity | AL34: =AL21/ENR!AL21 -> 938.3721 | AM34: =AM21/ENR!AM21 -> 938.3721 | AN34: =AN21/ENR!AN21 -> 938.3721 | AO34: =AO21/ENR!AO21 -> 938.3721 | AP34: =AP21/ENR!AP21 -> 938.3721 | AQ34: =AQ21/ENR!AQ21 -> 938.3721 | AR34: =AR21/ENR!AR21 -> 938.3721 | AS34: =AS21/ENR!AS21 -> 938.37369 | ... CS34: =CS21/ENR!CS21 -> #DIV/0!
B35: Investment | D35: 30 | E35: 4791.5415 | F35: 321.96789 | G35: 1828.8468 | H35: 330.36736 | I35: 232.97132 | J35: 179.26547 | K35: 2431.41 | L35: 128150.39 | M35: 6434.5144 | N35: 1018.982 | O35: 825.57014 | P35: 12.93743 | Q35: 310.53503 | R35: 644.46234 | S35: 571.03309 | T35: 1680.3003 | U35: 33.083046 | V35: 16.655132 | W35: 55.673195 | X35: 772.50824 | Y35: 1281.9174 | Z35: 14.737066 | AA35: 1.8180421 | AB35: 124.90982 | AC35: 0.24381972 | AD35: 51.2083 | AE35: 79.976518 | AF35: 335.17932 | AK35: Natural gas | AL35: =AL22/ENR!AL22 -> 368.9298 | AM35: =AM22/ENR!AM22 -> 368.9298 | AN35: =AN22/ENR!AN22 -> 368.9298 | AO35: =AO22/ENR!AO22 -> 368.9298 | AP35: =AP22/ENR!AP22 -> 368.9298 | AQ35: =AQ22/ENR!AQ22 -> 368.9298 | AR35: =AR22/ENR!AR22 -> 368.9298 | AS35: =AS22/ENR!AS22 -> 368.94655 | ... CS35: =CS22/ENR!CS22 -> #DIV/0!
B36: Depreciation ratio | D36: 31 | E36: 0.053179873 | F36: 0.040171209 | G36: 0.036413814 | H36: 0.030830214 | I36: 0.030830214 | J36: 0.017857143 | K36: 0.048291708 | L36: 0.049223686 | M36: 0.059724671 | N36: 0.059724672 | O36: 0.059724671 | P36: 0.056073966 | Q36: 0.046830189 | R36: 0.056073966 | S36: 0.036413814 | T36: 0.046775704 | U36: 0.058465197 | V36: 0.029535687 | W36: 0.036413814 | X36: 0.058465197 | Y36: 0.058465197 | Z36: 0.058465197 | AA36: 0.058465197 | AB36: 0.058465197 | AC36: 0.058465197 | AD36: 0.058465197 | AE36: 0.058465197 | AF36: 0.058465197 | AK36: Manufactured gas | AL36: =AL23/ENR!AL23 -> #DIV/0! | AM36: =AM23/ENR!AM23 -> 368.9298 | AN36: =AN23/ENR!AN23 -> #DIV/0! | AO36: =AO23/ENR!AO23 -> #DIV/0! | AP36: =AP23/ENR!AP23 -> #DIV/0! | AQ36: =AQ23/ENR!AQ23 -> #DIV/0! | AR36: =AR23/ENR!AR23 -> #DIV/0! | AS36: =AS23/ENR!AS23 -> #DIV/0! | ... CS36: =CS23/ENR!CS23 -> #DIV/0!
B37: Capital stock | D37: 32 | E37: 90100.656 | F37: 8014.8918 | G37: 50223.983 | H37: 10715.701 | I37: 7556.5912 | J37: 10038.866 | K37: 50348.394 | L37: 2603429.3 | M37: 107736.29 | N37: 17061.325 | O37: 13822.933 | P37: 230.7208 | Q37: 6631.0864 | R37: 11493.076 | S37: 15681.771 | T37: 35922.502 | U37: 565.85879 | V37: 563.89856 | W37: 1528.9032 | X37: 13213.13 | Y37: 21926.163 | Z37: 252.06562 | AA37: 31.096142 | AB37: 2136.4817 | AC37: 4.1703395 | AD37: 875.87663 | AE37: 1367.9338 | AF37: 5732.9717 | AK37: Biogas | AL37: =AL24/ENR!AL24 -> 368.9298 | AM37: =AM24/ENR!AM24 -> #DIV/0! | AN37: =AN24/ENR!AN24 -> #DIV/0! | AO37: =AO24/ENR!AO24 -> #DIV/0! | AP37: =AP24/ENR!AP24 -> #DIV/0! | AQ37: =AQ24/ENR!AQ24 -> 368.9298 | AR37: =AR24/ENR!AR24 -> 368.9298 | AS37: =AS24/ENR!AS24 -> 368.9298 | ... CS37: =CS24/ENR!CS24 -> #DIV/0!
B38: Gross Operating Surplus | D38: 33 | E38: 1061.7723 | F38: -909.22809 | G38: 6955.5846 | H38: 1098.1462 | I38: 399.01648 | J38: 416.88659 | K38: 5932 | L38: 175106.52 | M38: 9060.7981 | N38: 1744.7825 | O38: 1485.2079 | P38: -794.93505 | Q38: 1182.5369 | R38: -12348.517 | S38: -5995.0878 | T38: 7729.0627 | U38: 60.008213 | V38: 195.88677 | W38: -99.618186 | X38: -5359.8042 | Y38: -1230.0879 | Z38: -296.11313 | AA38: -7.3734365 | AB38: -506.59699 | AC38: -0.98886007 | AD38: -476.50006 | AE38: 121.16286 | AF38: -37.879342 | AK38: Biomass | AL38: =AL25/ENR!AL25 -> 1001.1077 | AM38: =AM25/ENR!AM25 -> #DIV/0! | AN38: =AN25/ENR!AN25 -> #DIV/0! | AO38: =AO25/ENR!AO25 -> #DIV/0! | AP38: =AP25/ENR!AP25 -> #DIV/0! | AQ38: =AQ25/ENR!AQ25 -> #DIV/0! | AR38: =AR25/ENR!AR25 -> #DIV/0! | AS38: =AS25/ENR!AS25 -> 1001.1077 | ... CS38: =CS25/ENR!CS25 -> #DIV/0!
B39: Net Operating Surplus | D39: 34 | E39: 0 | F39: 0 | G39: 0 | H39: 0 | I39: 0 | J39: 0 | K39: 0 | L39: 0 | M39: 0 | N39: 0 | O39: 0 | P39: 0 | Q39: 0 | R39: 0 | S39: 0 | T39: 0 | U39: 0 | V39: 0 | W39: 0 | X39: 0 | Y39: 0 | Z39: 0 | AA39: 0 | AB39: 0 | AC39: 0 | AD39: 0 | AE39: 0 | AF39: 0 | AK39: Biofuel | AL39: =AL26/ENR!AL26 -> 1001.1077 | AM39: =AM26/ENR!AM26 -> #DIV/0! | AN39: =AN26/ENR!AN26 -> #DIV/0! | AO39: =AO26/ENR!AO26 -> #DIV/0! | AP39: =AP26/ENR!AP26 -> #DIV/0! | AQ39: =AQ26/ENR!AQ26 -> #DIV/0! | AR39: =AR26/ENR!AR26 -> #DIV/0! | AS39: =AS26/ENR!AS26 -> 1001.1077 | ... CS39: =CS26/ENR!CS26 -> #DIV/0!
AK40: Heat | AL40: =AL27/ENR!AL27 -> 368.9298 | AM40: =AM27/ENR!AM27 -> 368.9298 | AN40: =AN27/ENR!AN27 -> 368.9298 | AO40: =AO27/ENR!AO27 -> 368.9298 | AP40: =AP27/ENR!AP27 -> 368.9298 | AQ40: =AQ27/ENR!AQ27 -> 368.9298 | AR40: =AR27/ENR!AR27 -> 368.9298 | AS40: =AS27/ENR!AS27 -> 369.15906 | ... CS40: =CS27/ENR!CS27 -> #DIV/0!
AK41: Waste | AL41: =AL28/ENR!AL28 -> #DIV/0! | AM41: =AM28/ENR!AM28 -> #DIV/0! | AN41: =AN28/ENR!AN28 -> #DIV/0! | AO41: =AO28/ENR!AO28 -> #DIV/0! | AP41: =AP28/ENR!AP28 -> #DIV/0! | AQ41: =AQ28/ENR!AQ28 -> #DIV/0! | AR41: =AR28/ENR!AR28 -> #DIV/0! | AS41: =AS28/ENR!AS28 -> 416.9602 | ... CS41: =CS28/ENR!CS28 -> #DIV/0!
D42: 35
A43: DOMESTIC | B43: Products of agriculture, Hunting, Forestry, and Fishing | C43: cagr | D43: 36 | E43: 27141 | F43: 0 | G43: 0 | H43: 0 | I43: 0 | J43: 0 | K43: 59 | L43: 97 | M43: 0 | N43: 0 | O43: 0 | P43: 0 | Q43: 0 | R43: 0 | S43: 0 | T43: 0 | U43: 0 | V43: 0 | W43: 0 | X43: 0 | Y43: 0 | Z43: 0 | AA43: 0 | AB43: 0 | AC43: 0 | AD43: 0 | AE43: 0 | AF43: 0 | AH43: 5014.9637 | AI43: 564.39078 | AJ43: 445.65383 | AK43: 0 | AL43: 4708.3084 | AM43: 0 | AN43: 0.53542255 | AO43: 25.7259 | AP43: 0 | AQ43: 0.12161159 | AR43: 9866.9443 | AS43: 965.39175 | AT43: 0 | AU43: 0 | AV43: 0 | AW43: 0 | AX43: 0 | AY43: 0 | AZ43: 0.16717857 | BA43: 0 | BB43: 0 | BC43: 0.24834721 | BD43: 0.01629917 | BE43: 0 | BF43: 0 | BG43: 0 | BH43: 0 | BI43: 0 | BJ43: 0 | BK43: 0 | BL43: 0 | BM43: 0 | BN43: 3280.4817 | BO43: 0 | BP43: 311.32013 | BQ43: 0 | BR43: 0 | BS43: 0 | BT43: 0 | BU43: 0 | BV43: 0 | BW43: 0 | BX43: 0 | BY43: 0 | BZ43: 0 | CA43: 0 | CB43: 0 | CC43: 0 | CD43: 0 | CE43: 0 | CF43: 0 | CG43: 0.030861705 | CH43: 0 | CI43: 0 | CJ43: 0 | CK43: 0 | CL43: 0 | CM43: 0 | CN43: 0 | CO43: 0 | CP43: 0 | CQ43: 0 | CR43: 13764.761 | CS43: 397.95529
B44: Basic metals (Steel, Aluminum, Zinc) | C44: cmet | D44: 37 | E44: 0 | F44: 5680.2037 | G44: 74 | H44: 6 | I44: 0 | J44: 0 | K44: 16 | L44: 1194 | M44: 0 | N44: 0 | O44: 0 | P44: 0 | Q44: 0 | R44: 0 | S44: 0 | T44: 0 | U44: 0 | V44: 0 | W44: 0 | X44: 0 | Y44: 0 | Z44: 0 | AA44: 0 | AB44: 0 | AC44: 0 | AD44: 0 | AE44: 0 | AF44: 0 | AH44: 935.6284 | AI44: 105.29688 | AJ44: 22.205495 | AK44: 0 | AL44: 1.9478726 | AM44: 440.61501 | AN44: 47.415553 | AO44: 5.8762937 | AP44: 6.8378153 | AQ44: 2.9701928 | AR44: 0 | AS44: 2843.0556 | AT44: 0 | AU44: 0 | AV44: 0 | AW44: 0 | AX44: 0 | AY44: 0 | AZ44: 14.804876 | BA44: 18.206875 | BB44: 0 | BC44: 0.96557856 | BD44: 1.4434098 | BE44: 0 | BF44: 0 | BG44: 0 | BH44: 0 | BI44: 0 | BJ44: 0 | BK44: 0 | BL44: 0 | BM44: 0 | BN44: 0 | BO44: 0 | BP44: 0 | BQ44: 0 | BR44: 0 | BS44: 0 | BT44: 0 | BU44: 0 | BV44: 0 | BW44: 0 | BX44: 0 | BY44: 0 | BZ44: 0 | CA44: 0 | CB44: 0 | CC44: 0 | CD44: 0 | CE44: 0 | CF44: 0 | CG44: 0 | CH44: 0 | CI44: 0 | CJ44: 0 | CK44: 0 | CL44: 0 | CM44: 0 | CN44: 0 | CO44: 0 | CP44: 0 | CQ44: 0 | CR44: 4930.2952 | CS44: -281.09984
B45: Chemical products (Nitric Acid, Urea, Chlorine, other) | C45: cchem | D45: 38 | E45: 1 | F45: 45 | G45: 27202.397 | H45: 145 | I45: 18 | J45: 2 | K45: 242 | L45: 1305 | M45: 0 | N45: 0 | O45: 0 | P45: 0 | Q45: 0 | R45: 608 | S45: 0 | T45: 0 | U45: 0 | V45: 0 | W45: 0 | X45: 0 | Y45: 0 | Z45: 0 | AA45: 0 | AB45: 0 | AC45: 0 | AD45: 0 | AE45: 0 | AF45: 0 | AH45: 3564.2316 | AI45: 401.12344 | AJ45: 549.13436 | AK45: 0 | AL45: 348.57367 | AM45: 15.350593 | AN45: 5755.4228 | AO45: 1570.7265 | AP45: 58.353438 | AQ45: 356.38895 | AR45: 271.63468 | AS45: 2324.0812 | AT45: 1.115452 | AU45: 0 | AV45: 0 | AW45: 0 | AX45: 0 | AY45: 0 | AZ45: 1797.0542 | BA45: 0.60996598 | BB45: 0 | BC45: 3.9266659 | BD45: 175.20482 | BE45: 0 | BF45: 0 | BG45: 0 | BH45: 0 | BI45: 0 | BJ45: 0 | BK45: 0 | BL45: 0 | BM45: 0 | BN45: 1243.8166 | BO45: 0 | BP45: 0 | BQ45: 0 | BR45: 0 | BS45: 0 | BT45: 0 | BU45: 0 | BV45: 0 | BW45: 0 | BX45: 0 | BY45: 0 | BZ45: 0 | CA45: 0 | CB45: 0 | CC45: 0 | CD45: 0 | CE45: 0 | CF45: 0 | CG45: 0 | CH45: 0 | CI45: 0 | CJ45: 0 | CK45: 0 | CL45: 0 | CM45: 0 | CN45: 0 | CO45: 0 | CP45: 0 | CQ45: 0 | CR45: 24398.12 | CS45: -4237.4922
B46: Rubber and Plastic (Ethylene, Propylene, other HVC) | C46: cpla | D46: 39 | E46: 0 | F46: 10 | G46: 410 | H46: 7447 | I46: 0 | J46: 70 | K46: 0 | L46: 478 | M46: 0 | N46: 0 | O46: 0 | P46: 0 | Q46: 0 | R46: 0 | S46: 0 | T46: 0 | U46: 0 | V46: 0 | W46: 0 | X46: 0 | Y46: 0 | Z46: 0 | AA46: 0 | AB46: 0 | AC46: 0 | AD46: 0 | AE46: 0 | AF46: 0 | AH46: 1061.5013 | AI46: 119.46279 | AJ46: 227.65572 | AK46: 0 | AL46: 73.44 | AM46: 18.810939 | AN46: 84.270476 | AO46: 237.56858 | AP46: 167.71542 | AQ46: 37.489655 | AR46: 422.44224 | AS46: 2824.3958 | AT46: 63.44186 | AU46: 13.0625 | AV46: 4 | AW46: 0.21598216 | AX46: 4.4981689 | AY46: 10.758888 | AZ46: 26.312336 | BA46: 24.892649 | BB46: 0.026822562 | BC46: 20.772766 | BD46: 2.5653361 | BE46: 0.62632233 | BF46: 1.0393333 | BG46: 0.011948292 | BH46: 0.0014740042 | BI46: 0.10127246 | BJ46: 0.0001976804 | BK46: 0.041517877 | BL46: 0.06484213 | BM46: 0.27175153 | BN46: 945.21111 | BO46: 0 | BP46: 29.621376 | BQ46: 11.034933 | BR46: 1.5022265 | BS46: 8.0905985 | BT46: 28.668025 | BU46: 5.4241359 | BV46: 2.01769 | BW46: 3.755792 | BX46: 0.21754904 | BY46: 0.36495536 | BZ46: 8.3500566 | CA46: 0.0033288171 | CB46: 0.0017493789 | CC46: 0.51478346 | CD46: 28.171151 | CE46: 11.726116 | CF46: 1.6393428 | CG46: 0.73482619 | CH46: 7.6678491 | CI46: 5.3257485 | CJ46: 1.9652354 | CK46: 2.9437986 | CL46: 0.17608743 | CM46: 0.30648768 | CN46: 0.070062821 | CO46: 0.013149344 | CP46: 0.001602819 | CQ46: 0.51386667 | CR46: 4595.1117 | CS46: 83.63538
B47: non-metallic mineral products (Glass, Ceramic) | C47: cgla | D47: 40 | E47: 0 | F47: 30 | G47: 0 | H47: 13 | I47: 4655 | J47: 0 | K47: 0 | L47: 451 | M47: 0 | N47: 0 | O47: 0 | P47: 0 | Q47: 0 | R47: 0 | S47: 0 | T47: 0 | U47: 0 | V47: 0 | W47: 0 | X47: 0 | Y47: 0 | Z47: 0 | AA47: 0 | AB47: 0 | AC47: 0 | AD47: 0 | AE47: 0 | AF47: 0 | AH47: 1834.3927 | AI47: 206.44503 | AJ47: 190.57259 | AK47: 0 | AL47: 16.5 | AM47: 10.637371 | AN47: 8.114182 | AO47: 10.208333 | AP47: 306.23938 | AQ47: 0 | AR47: 134.8249 | AS47: 4913.7429 | AT47: 0 | AU47: 0 | AV47: 0 | AW47: 0 | AX47: 1.11936 | AY47: 0 | AZ47: 2.5335454 | BA47: 6.6614258 | BB47: 0.067056406 | BC47: 0 | BD47: 0.24700945 | BE47: 1.5658058 | BF47: 2.5983332 | BG47: 0.029870729 | BH47: 0.0036850105 | BI47: 0.25318116 | BJ47: 0.000494201 | BK47: 0.10379469 | BL47: 0.16210533 | BM47: 0.67937882 | BN47: 240.43284 | BO47: 0 | BP47: 0.32171126 | BQ47: 0.32180015 | BR47: 0.18669543 | BS47: 68.784469 | BT47: 0.73354551 | BU47: 0.013693997 | BV47: 0.67615292 | BW47: 1.7840526 | BX47: 0.01768003 | BY47: 0.81749951 | BZ47: 0.015489852 | CA47: 0.037708583 | CB47: 0.059153248 | CC47: 0.34846068 | CD47: 0.30549772 | CE47: 0.34203035 | CF47: 0.20245869 | CG47: 6.2551501 | CH47: 0.19888906 | CI47: 0.013474023 | CJ47: 0.65902854 | CK47: 1.3799154 | CL47: 0.014289275 | CM47: 0.68944405 | CN47: 0.00013127655 | CO47: 0.14538725 | CP47: 0.054340611 | CQ47: 0.3478293 | CR47: 1501.7886 | CS47: 137.17079
B48: Paper and paperboard | C48: cpap | D48: 41 | E48: 0 | F48: 19 | G48: 54 | H48: 36 | I48: 0 | J48: 6202 | K48: 0 | L48: 467 | M48: 0 | N48: 0 | O48: 0 | P48: 0 | Q48: 0 | R48: 0 | S48: 0 | T48: 0 | U48: 0 | V48: 0 | W48: 0 | X48: 0 | Y48: 0 | Z48: 0 | AA48: 0 | AB48: 0 | AC48: 0 | AD48: 0 | AE48: 0 | AF48: 0 | AH48: 1291.8415 | AI48: 145.38558 | AJ48: 216.6509 | AK48: 0 | AL48: 16.875 | AM48: 19.755117 | AN48: 42.968076 | AO48: 70.512195 | AP48: 25.787879 | AQ48: 755.89474 | AR48: 796.10009 | AS48: 1614.5594 | AT48: 25.714286 | AU48: 9.8 | AV48: 6 | AW48: 0.039269483 | AX48: 2.4874667 | AY48: 1.9561615 | AZ48: 13.416211 | BA48: 14.093918 | BB48: 0.029337178 | BC48: 0.3879464 | BD48: 1.3080211 | BE48: 0.68504005 | BF48: 1.1367708 | BG48: 0.013068444 | BH48: 0.0016121921 | BI48: 0.11076676 | BJ48: 0.00021621294 | BK48: 0.045410178 | BL48: 0.07092108 | BM48: 0.29722824 | BN48: 838.21158 | BO48: 0 | BP48: 0 | BQ48: 0 | BR48: 0 | BS48: 0 | BT48: 0 | BU48: 0 | BV48: 0 | BW48: 0 | BX48: 0 | BY48: 0 | BZ48: 0 | CA48: 0 | CB48: 0 | CC48: 0 | CD48: 0 | CE48: 0 | CF48: 0 | CG48: 0 | CH48: 0 | CI48: 0 | CJ48: 0 | CK48: 0 | CL48: 0 | CM48: 0 | CN48: 0 | CO48: 0 | CP48: 0 | CQ48: 0 | CR48: 4005.4 | CS48: 168.22022
B49: Food products and beverages | C49: cfoo | D49: 42 | E49: 329 | F49: 0 | G49: 105 | H49: 0 | I49: 0 | J49: 0 | K49: 63777 | L49: 1540 | M49: 0 | N49: 0 | O49: 0 | P49: 0 | Q49: 0 | R49: 0 | S49: 0 | T49: 0 | U49: 0 | V49: 0 | W49: 0 | X49: 0 | Y49: 0 | Z49: 0 | AA49: 0 | AB49: 0 | AC49: 0 | AD49: 0 | AE49: 0 | AF49: 0 | AH49: 16534.319 | AI49: 1860.7946 | AJ49: 5205.078 | AK49: 0 | AL49: 4334.6035 | AM49: 0.96031821 | AN49: 215.48968 | AO49: 26.88 | AP49: 1 | AQ49: 30.147059 | AR49: 9017.723 | AS49: 6139.3427 | AT49: 11.10313 | AU49: 1.3333333 | AV49: 1.25 | AW49: 2.9195811 | AX49: 0.12437333 | AY49: 145.43538 | AZ49: 67.283786 | BA49: 1.0694773 | BB49: 0.1157314 | BC49: 0 | BD49: 6.559871 | BE49: 2.7023952 | BF49: 4.484415 | BG49: 0.051553336 | BH49: 0.0063598911 | BI49: 0.43696066 | BJ49: 0.00085293232 | BK49: 0.17913733 | BL49: 0.27977457 | BM49: 1.1725273 | BN49: 23436.199 | BO49: 0 | BP49: 0 | BQ49: 0 | BR49: 0 | BS49: 0 | BT49: 0 | BU49: 0 | BV49: 0 | BW49: 0 | BX49: 0 | BY49: 0 | BZ49: 0 | CA49: 0 | CB49: 0 | CC49: 0 | CD49: 0 | CE49: 0 | CF49: 0 | CG49: 0 | CH49: 0 | CI49: 0 | CJ49: 0 | CK49: 0 | CL49: 0 | CM49: 0 | CN49: 0 | CO49: 0 | CP49: 0 | CQ49: 0 | CR49: 43405.447 | CS49: 2496.8897
...

Sheet GHG
A1: GHG emissions in Mton CO2-eq, NLD 2015
E3: Products of agriculture, Hunting, Forestry, and Fishing | F3: Basic metals (Steel, Aluminum, Zinc) | G3: Chemical products (Nitric Acid, Urea, Chlorine, other) | H3: Rubber and Plastic (Ethylene, Propylene, other HVC) | I3: non-metallic mineral products (Glass, Ceramic) | J3: Paper and paperboard | K3: Food products and beverages | L3: Rest of economy | M3: Land transport | N3: Water transport (navigation) | O3: Air transport (aviation) | P3: Mining and production of coal products | Q3: Crude oil | R3: Production and refining of petroleum products for energy use | S3: Production and refining of petroleum products for chemical use | T3: Production of natural gas | U3: Production of bio gas | V3: Production of biomass | W3: Production of biofuels | X3: Electricity production by solid fossil fuels | Y3: Electricity production by gas | Z3: Electricity production by petroleum | AA3: Electricity production by hydro | AB3: Electricity production by wind | AC3: Electricity production by solar photovoltaic and solar thermal | AD3: Electricity production by biomass and biofuels | AE3: Electricity production by nuclear | AF3: Heat | AG3: Final consumption expenditure by households
E4: sagr | F4: smet | G4: schem | H4: spla | I4: sgla | J4: spap | K4: sfoo | L4: sres | M4: sroa | N4: swat | O4: sair | P4: scoa | Q4: soil | R4: spen | S4: spch | T4: sgas | U4: sgasb | V4: sbiom | W4: sbiof | X4: sesf | Y4: sega | Z4: sepe | AA4: sehy | AB4: sewi | AC4: seso | AD4: sebi | AE4: senu | AF4: shea
E5: 1 | F5: 2 | G5: 3 | H5: 4 | I5: 5 | J5: 6 | K5: 7 | L5: 8 | M5: 9 | N5: 10 | O5: 11 | P5: 12 | Q5: 13 | R5: 14 | S5: 15 | T5: 16 | U5: 17 | V5: 18 | W5: 19 | X5: 20 | Y5: 21 | Z5: 22 | AA5: 23 | AB5: 24 | AC5: 25 | AD5: 26 | AE5: 27 | AF5: 28 | AG5: 29
A6: CO2 | B6: Products of agriculture, Hunting, Forestry, and Fishing | C6: cagr | D6: 1 | E6: 0 | F6: 0 | G6: 0 | H6: 0 | I6: 0 | J6: 0 | K6: 0 | L6: 0 | M6: 0 | N6: 0 | O6: 0 | P6: 0 | Q6: 0 | R6: 0 | S6: 0 | T6: 0 | U6: 0 | V6: 0 | W6: 0 | X6: 0 | Y6: 0 | Z6: 0 | AA6: 0 | AB6: 0 | AC6: 0 | AD6: 0 | AE6: 0 | AF6: 0 | AG6: 0
B7: Basic metals (Steel, Aluminum, Zinc) | C7: cmet | D7: 2 | E7: 0 | F7: 0 | G7: 0 | H7: 0 | I7: 0 | J7: 0 | K7: 0 | L7: 0 | M7: 0 | N7: 0 | O7: 0 | P7: 0 | Q7: 0 | R7: 0 | S7: 0 | T7: 0 | U7: 0 | V7: 0 | W7: 0 | X7: 0 | Y7: 0 | Z7: 0 | AA7: 0 | AB7: 0 | AC7: 0 | AD7: 0 | AE7: 0 | AF7: 0 | AG7: 0
B8: Chemical products (Nitric Acid, Urea, Chlorine, other) | C8: cchem | D8: 3 | E8: 0 | F8: 0 | G8: 0 | H8: 0 | I8: 0 | J8: 0 | K8: 0 | L8: 0 | M8: 0 | N8: 0 | O8: 0 | P8: 0 | Q8: 0 | R8: 0 | S8: 0 | T8: 0 | U8: 0 | V8: 0 | W8: 0 | X8: 0 | Y8: 0 | Z8: 0 | AA8: 0 | AB8: 0 | AC8: 0 | AD8: 0 | AE8: 0 | AF8: 0 | AG8: 0
B9: Rubber and Plastic (Ethylene, Propylene, other HVC) | C9: cpla | D9: 4 | E9: 0 | F9: 0 | G9: 0 | H9: 0 | I9: 0 | J9: 0 | K9: 0 | L9: 0 | M9: 0 | N9: 0 | O9: 0 | P9: 0 | Q9: 0 | R9: 0 | S9: 0 | T9: 0 | U9: 0 | V9: 0 | W9: 0 | X9: 0 | Y9: 0 | Z9: 0 | AA9: 0 | AB9: 0 | AC9: 0 | AD9: 0 | AE9: 0 | AF9: 0 | AG9: 0
B10: non-metallic mineral products (Glass, Ceramic) | C10: cgla | D10: 5 | E10: 0 | F10: 0 | G10: 0 | H10: 0 | I10: 0 | J10: 0 | K10: 0 | L10: 0 | M10: 0 | N10: 0 | O10: 0 | P10: 0 | Q10: 0 | R10: 0 | S10: 0 | T10: 0 | U10: 0 | V10: 0 | W10: 0 | X10: 0 | Y10: 0 | Z10: 0 | AA10: 0 | AB10: 0 | AC10: 0 | AD10: 0 | AE10: 0 | AF10: 0 | AG10: 0
B11: Paper and paperboard | C11: cpap | D11: 6 | E11: 0 | F11: 0 | G11: 0 | H11: 0 | I11: 0 | J11: 0 | K11: 0 | L11: 0 | M11: 0 | N11: 0 | O11: 0 | P11: 0 | Q11: 0 | R11: 0 | S11: 0 | T11: 0 | U11: 0 | V11: 0 | W11: 0 | X11: 0 | Y11: 0 | Z11: 0 | AA11: 0 | AB11: 0 | AC11: 0 | AD11: 0 | AE11: 0 | AF11: 0 | AG11: 0
B12: Food products and beverages | C12: cfoo | D12: 7 | E12: 0 | F12: 0 | G12: 0 | H12: 0 | I12: 0 | J12: 0 | K12: 0 | L12: 0 | M12: 0 | N12: 0 | O12: 0 | P12: 0 | Q12: 0 | R12: 0 | S12: 0 | T12: 0 | U12: 0 | V12: 0 | W12: 0 | X12: 0 | Y12: 0 | Z12: 0 | AA12: 0 | AB12: 0 | AC12: 0 | AD12: 0 | AE12: 0 | AF12: 0 | AG12: 0
B13: Rest of economy | C13: cres | D13: 8 | E13: 0 | F13: 0 | G13: 0 | H13: 0 | I13: 0 | J13: 0 | K13: 0 | L13: 0 | M13: 0 | N13: 0 | O13: 0 | P13: 0 | Q13: 0 | R13: 0 | S13: 0 | T13: 0 | U13: 0 | V13: 0 | W13: 0 | X13: 0 | Y13: 0 | Z13: 0 | AA13: 0 | AB13: 0 | AC13: 0 | AD13: 0 | AE13: 0 | AF13: 0 | AG13: 0
B14: Land transport | C14: croa | D14: 9 | E14: 0 | F14: 0 | G14: 0 | H14: 0 | I14: 0 | J14: 0 | K14: 0 | L14: 0 | M14: 0 | N14: 0 | O14: 0 | P14: 0 | Q14: 0 | R14: 0 | S14: 0 | T14: 0 | U14: 0 | V14: 0 | W14: 0 | X14: 0 | Y14: 0 | Z14: 0 | AA14: 0 | AB14: 0 | AC14: 0 | AD14: 0 | AE14: 0 | AF14: 0 | AG14: 0
B15: Water transport (navigation) | C15: cwat | D15: 10 | E15: 0 | F15: 0 | G15: 0 | H15: 0 | I15: 0 | J15: 0 | K15: 0 | L15: 0 | M15: 0 | N15: 0 | O15: 0 | P15: 0 | Q15: 0 | R15: 0 | S15: 0 | T15: 0 | U15: 0 | V15: 0 | W15: 0 | X15: 0 | Y15: 0 | Z15: 0 | AA15: 0 | AB15: 0 | AC15: 0 | AD15: 0 | AE15: 0 | AF15: 0 | AG15: 0
B16: Air transport (aviation) | C16: cair | D16: 11 | E16: 0 | F16: 0 | G16: 0 | H16: 0 | I16: 0 | J16: 0 | K16: 0 | L16: 0 | M16: 0 | N16: 0 | O16: 0 | P16: 0 | Q16: 0 | R16: 0 | S16: 0 | T16: 0 | U16: 0 | V16: 0 | W16: 0 | X16: 0 | Y16: 0 | Z16: 0 | AA16: 0 | AB16: 0 | AC16: 0 | AD16: 0 | AE16: 0 | AF16: 0 | AG16: 0
B17: Coal and coal products | C17: ccoa | D17: 12 | E17: 0.0115889 | F17: 4.0927267 | G17: 0.0085909056 | H17: 0.0012590613 | I17: 0.032318316 | J17: 0.00091922312 | K17: 0.085383225 | L17: 0.17630241 | M17: 0 | N17: 0 | O17: 0 | P17: 0.25778089 | Q17: 0.00034478167 | R17: 0.0044260539 | S17: 3.5600083e-05 | T17: 0.049007497 | U17: 8.4648009e-06 | V17: 4.9455795e-06 | W17: 6.4473194e-07 | X17: 22.847335 | Y17: 0.000111995 | Z17: 1.2875071e-06 | AA17: 1.5883365e-07 | AB17: 1.0912775e-05 | AC17: 2.1301365e-08 | AD17: 4.4738246e-06 | AE17: 6.9871664e-06 | AF17: 7.6721469e-05 | AG17: 0.0017993877
B18: Crude oil | C18: coil | D18: 13 | E18: 0.30419814 | F18: 0.082688175 | G18: 0.2255035 | H18: 0.033049221 | I18: 0.027058973 | J18: 0.024128775 | K18: 0.18172325 | L18: 1.6638618 | M18: 0 | N18: 0 | O18: 0 | P18: 7.7952105e-06 | Q18: 0.0045962135 | R18: 7.2551273 | S18: 0.98214125 | T18: 0.0016191415 | U18: 3.4840801e-05 | V18: 0.00012981699 | W18: 1.692363e-05 | X18: 0.00029016813 | Y18: 0.00048151148 | Z18: 5.5355098e-06 | AA18: 6.8288965e-07 | AB18: 4.69184e-05 | AC18: 9.1583118e-08 | AD18: 1.9234768e-05 | AE18: 3.0040633e-05 | AF18: 0.00031578267 | AG18: 0
... B28: Waste | C28: cwas | D28: 23 | E28: 0 | F28: 0 | G28: 0 | H28: 0 | I28: 0 | J28: 0 | K28: 0 | L28: 0.3681588 | M28: 0 | N28: 0 | O28: 0 | P28: 0 | Q28: 0 | R28: 0 | S28: 0 | T28: 0 | U28: 0 | V28: 0 | W28: 0 | X28: 1.6229078 | Y28: 2.6930894 | Z28: 0.030960057 | AA28: 0.0038193957 | AB28: 0.26241419 | AC28: 0.00051222356 | AD28: 0.10757988 | AE28: 0.16801699 | AF28: 0 | AG28: 0
B29: Material related emissions | D29: 24 | E29: 0 | F29: 0.6583099 | G29: 0.75593428 | H29: 0 | I29: 1.2853017 | J29: 0 | K29: 0 | L29: 0.15809656 | M29: 0 | N29: 0 | O29: 0 | P29: 0.010722206 | Q29: 0.052681945 | R29: 0.39936156 | S29: 3.5995814 | T29: 0.031345859 | U29: 1.6688793e-06 | V29: 0 | W29: 0.11365806 | X29: 0.12114269 | Y29: 0.10245854 | Z29: 0.0036582839 | AA29: 1.8918418e-05 | AB29: 0.0012998028 | AC29: 2.5371709e-06 | AD29: 0.009210047 | AE29: 0.00083223002 | AF29: 0.0056730466
B30: Production related emissions | D30: 25 | E30: 0.13367282 | F30: 0 | G30: 0 | H30: 0 | I30: 0 | J30: 0 | K30: 0 | L30: 0 | M30: 0 | N30: 0 | O30: 0 | P30: 0 | Q30: 0 | R30: 0 | S30: 0 | T30: 0 | U30: 0 | V30: 0 | W30: 0 | X30: 0 | Y30: 0 | Z30: 0 | AA30: 0 | AB30: 0 | AC30: 0 | AD30: 0 | AE30: 0 | AF30: 0
B31: Total emissions | D31: 26 | E31: 9.2610084 | F31: 6.8062545 | G31: 2.6324064 | H31: 0.275011 | I31: 1.67627 | J31: 0.7689 | K31: 3.782161 | L31: 27.156165 | M31: 6.038496 | N31: 8.385331 | O31: 12.836177 | P31: 0.28818798 | Q31: 0.5190368 | R31: 10.733911 | S31: 12.534901 | T31: 0.33954044 | U31: 0.00033878626 | V31: 0.0068390009 | W31: 0.39579393 | X31: 24.592239 | Y31: 20.799316 | Z31: 0.74263991 | AA31: 0.0038404816 | AB31: 0.26386291 | AC31: 0.00051505142 | AD31: 1.8696604 | AE31: 0.16894457 | AF31: 1.1516413 | AG31: 32.979171
A32: CH4 | B32: Products of agriculture, Hunting, Forestry, and Fishing | C32: cagr | D32: 27 | E32: 0 | F32: 0 | G32: 0 | H32: 0 | I32: 0 | J32: 0 | K32: 0 | L32: 0 | M32: 0 | N32: 0 | O32: 0 | P32: 0 | Q32: 0 | R32: 0 | S32: 0 | T32: 0 | U32: 0 | V32: 0 | W32: 0 | X32: 0 | Y32: 0 | Z32: 0 | AA32: 0 | AB32: 0 | AC32: 0 | AD32: 0 | AE32: 0 | AF32: 0 | AG32: 0
B33: Basic metals (Steel, Aluminum, Zinc) | C33: cmet | D33: 28 | E33: 0 | F33: 0 | G33: 0 | H33: 0 | I33: 0 | J33: 0 | K33: 0 | L33: 0 | M33: 0 | N33: 0 | O33: 0 | P33: 0 | Q33: 0 | R33: 0 | S33: 0 | T33: 0 | U33: 0 | V33: 0 | W33: 0 | X33: 0 | Y33: 0 | Z33: 0 | AA33: 0 | AB33: 0 | AC33: 0 | AD33: 0 | AE33: 0 | AF33: 0 | AG33: 0
B34: Chemical products (Nitric Acid, Urea, Chlorine, other) | C34: cchem | D34: 29 | E34: 0 | F34: 0 | G34: 0 | H34: 0 | I34: 0 | J34: 0 | K34: 0 | L34: 0 | M34: 0 | N34: 0 | O34: 0 | P34: 0 | Q34: 0 | R34: 0 | S34: 0 | T34: 0 | U34: 0 | V34: 0 | W34: 0 | X34: 0 | Y34: 0 | Z34: 0 | AA34: 0 | AB34: 0 | AC34: 0 | AD34: 0 | AE34: 0 | AF34: 0 | AG34: 0
B35: Rubber and Plastic (Ethylene, Propylene, other HVC) | C35: cpla | D35: 30 | E35: 0 | F35: 0 | G35: 0 | H35: 0 | I35: 0 | J35: 0 | K35: 0 | L35: 0 | M35: 0 | N35: 0 | O35: 0 | P35: 0 | Q35: 0 | R35: 0 | S35: 0 | T35: 0 | U35: 0 | V35: 0 | W35: 0 | X35: 0 | Y35: 0 | Z35: 0 | AA35: 0 | AB35: 0 | AC35: 0 | AD35: 0 | AE35: 0 | AF35: 0 | AG35: 0
B36: non-metallic mineral products (Glass, Ceramic) | C36: cgla | D36: 31 | E36: 0 | F36: 0 | G36: 0 | H36: 0 | I36: 0 | J36: 0 | K36: 0 | L36: 0 | M36: 0 | N36: 0 | O36: 0 | P36: 0 | Q36: 0 | R36: 0 | S36: 0 | T36: 0 | U36: 0 | V36: 0 | W36: 0 | X36: 0 | Y36: 0 | Z36: 0 | AA36: 0 | AB36: 0 | AC36: 0 | AD36: 0 | AE36: 0 | AF36: 0 | AG36: 0
B37: Paper and paperboard | C37: cpap | D37: 32 | E37: 0 | F37: 0 | G37: 0 | H37: 0 | I37: 0 | J37: 0 | K37: 0 | L37: 0 | M37: 0 | N37: 0 | O37: 0 | P37: 0 | Q37: 0 | R37: 0 | S37: 0 | T37: 0 | U37: 0 | V37: 0 | W37: 0 | X37: 0 | Y37: 0 | Z37: 0 | AA37: 0 | AB37: 0 | AC37: 0 | AD37: 0 | AE37: 0 | AF37: 0 | AG37: 0
B38: Food products and beverages | C38: cfoo | D38: 33 | E38: 0 | F38: 0 | G38: 0 | H38: 0 | I38: 0 | J38: 0 | K38: 0 | L38: 0 | M38: 0 | N38: 0 | O38: 0 | P38: 0 | Q38: 0 | R38: 0 | S38: 0 | T38: 0 | U38: 0 | V38: 0 | W38: 0 | X38: 0 | Y38: 0 | Z38: 0 | AA38: 0 | AB38: 0 | AC38: 0 | AD38: 0 | AE38: 0 | AF38: 0 | AG38: 0
B39: Rest of economy | C39: cres | D39: 34 | E39: 0 | F39: 0 | G39: 0 | H39: 0 | I39: 0 | J39: 0 | K39: 0 | L39: 0 | M39: 0 | N39: 0 | O39: 0 | P39: 0 | Q39: 0 | R39: 0 | S39: 0 | T39: 0 | U39: 0 | V39: 0 | W39: 0 | X39: 0 | Y39: 0 | Z39: 0 | AA39: 0 | AB39: 0 | AC39: 0 | AD39: 0 | AE39: 0 | AF39: 0 | AG39: 0
B40: Land transport | C40: croa | D40: 35 | E40: 0 | F40: 0 | G40: 0 | H40: 0 | I40: 0 | J40: 0 | K40: 0 | L40: 0 | M40: 0 | N40: 0 | O40: 0 | P40: 0 | Q40: 0 | R40: 0 | S40: 0 | T40: 0 | U40: 0 | V40: 0 | W40: 0 | X40: 0 | Y40: 0 | Z40: 0 | AA40: 0 | AB40: 0 | AC40: 0 | AD40: 0 | AE40: 0 | AF40: 0 | AG40: 0
B41: Water transport (navigation) | C41: cwat | D41: 36 | E41: 0 | F41: 0 | G41: 0 | H41: 0 | I41: 0 | J41: 0 | K41: 0 | L41: 0 | M41: 0 | N41: 0 | O41: 0 | P41: 0 | Q41: 0 | R41: 0 | S41: 0 | T41: 0 | U41: 0 | V41: 0 | W41: 0 | X41: 0 | Y41: 0 | Z41: 0 | AA41: 0 | AB41: 0 | AC41: 0 | AD41: 0 | AE41: 0 | AF41: 0 | AG41: 0
B42: Air transport (aviation) | C42: cair | D42: 37 | E42: 0 | F42: 0 | G42: 0 | H42: 0 | I42: 0 | J42: 0 | K42: 0 | L42: 0 | M42: 0 | N42: 0 | O42: 0 | P42: 0 | Q42: 0 | R42: 0 | S42: 0 | T42: 0 | U42: 0 | V42: 0 | W42: 0 | X42: 0 | Y42: 0 | Z42: 0 | AA42: 0 | AB42: 0 | AC42: 0 | AD42: 0 | AE42: 0 | AF42: 0 | AG42: 0
B43: Coal and coal products | C43: ccoa | D43: 38 | E43: 0.021616945 | F43: 0.0083188706 | G43: 0.00034454054 | H43: 9.2641023e-05 | I43: 0.0031828037 | J43: 0.00010867654 | K43: 0.0081386177 | L43: 0.018000842 | M43: 0 | N43: 0 | O43: 0 | P43: 0.00046828335 | Q43: 0.00032478043 | R43: 7.1749038e-06 | S43: 1.4277507e-06 | T43: 0.00019991939 | U43: 6.8065031e-09 | V43: 2.7539196e-07 | W43: 2.5857145e-08 | X43: 0.020663946 | Y43: 8.9553769e-08 | Z43: 1.0295201e-09 | AA43: 1.2700703e-10 | AB43: 8.7261046e-09 | AC43: 1.7033059e-11 | AD43: 3.5773726e-09 | AE43: 5.5870983e-09 | AF43: 6.1691341e-08 | AG43: 0.00040002477
B44: Crude oil | C44: coil | D44: 39 | E44: 0.027356496 | F44: 7.7627952e-06 | G44: 0.00043602006 | H44: 0.00011723829 | I44: 0.0001241485 | J44: 0.00013753143 | K44: 0.00075173263 | L44: 0.0096198411 | M44: 0 | N44: 0 | O44: 0 | P44: 6.0918866e-10 | Q44: 0.00019703295 | R44: 0.00056698164 | S44: 0.0018990095 | T44: 6.706217e-05 | U44: 1.3556011e-09 | V44: 3.4851173e-07 | W44: 3.2722518e-08 | X44: 1.1289988e-08 | Y44: 1.8734859e-08 | Z44: 2.1537803e-10 | AA44: 2.6570168e-11 | AB44: 1.8255216e-09 | AC44: 3.5633559e-12 | AD44: 7.4839474e-10 | AE44: 1.1688341e-09 | AF44: 1.228661e-08 | AG44: 0
... B54: Waste | C54: cwas | D54: 49 | E54: 0 | F54: 0 | G54: 0 | H54: 0 | I54: 0 | J54: 0 | K54: 0 | L54: 0.11228685 | M54: 0 | N54: 0 | O54: 0 | P54: 0 | Q54: 0 | R54: 0 | S54: 0 | T54: 0 | U54: 0 | V54: 0 | W54: 0 | X54: 0.0014424292 | Y54: 0.0023935992 | Z54: 2.7517085e-05 | AA54: 3.3946525e-06 | AB54: 0.00023323192 | AC54: 4.5526076e-07 | AD54: 9.5616258e-05 | AE54: 0.00014933234 | AF54: 0 | AG54: 0
B55: Material related emissions | D55: 50 | E55: 0 | F55: 0 | G55: 0.050387054 | H55: 0 | I55: 0 | J55: 0 | K55: 0 | L55: 3.5242242 | M55: 0 | N55: 0 | O55: 0 | P55: 0.0073265072 | Q55: 0.097060035 | R55: 0.012599911 | S55: 0.23675948 | T55: 0.061210414 | U55: 1.0600335e-07 | V55: 0 | W55: 0.0077890567 | X55: 0.048539832 | Y55: 0.0060647315 | Z55: 0.00012025752 | AA55: 7.4542103e-06 | AB55: 0.00051214661 | AC55: 9.9969273e-07 | AD55: 0.0016352182 | AE55: 0.00032791418 | AF55: 0.00014429373
B56: Production related emissions | D56: 51 | E56: 12.32971 | F56: 0 | G56: 0 | H56: 0 | I56: 0 | J56: 0 | K56: 0 | L56: 0 | M56: 0 | N56: 0 | O56: 0 | P56: 0 | Q56: 0 | R56: 0 | S56: 0 | T56: 0 | U56: 0 | V56: 0 | W56: 0 | X56: 0 | Y56: 0 | Z56: 0 | AA56: 0 | AB56: 0 | AC56: 0 | AD56: 0 | AE56: 0 | AF56: 0
B57: Total emissions | D57: 52 | E57: 13.235534 | F57: 0.0084049077 | G57: 0.054038905 | H57: 0.00098192 | I57: 0.00445743 | J57: 0.00318531 | K57: 0.01933725 | L57: 3.8285264 | M57: 0.01122917 | N57: 0.007196 | O57: 0.00297883 | P57: 0.0077950101 | Q57: 0.11074046 | R57: 0.013405628 | S57: 0.25391886 | T57: 0.069742251 | U57: 1.5428026e-07 | V57: 2.8573584e-05 | W57: 0.0083535762 | X57: 0.070646241 | Y57: 0.0088267813 | Z57: 0.00017502619 | AA57: 1.0849068e-05 | AB57: 0.00074539262 | AC57: 1.454981e-06 | AD57: 0.0023799427 | AE57: 0.00047725555 | AF57: 0.00021000917 | AG57: 0.43642448
A58: N2O | B58: Products of agriculture, Hunting, Forestry, and Fishing | C58: cagr | D58: 53 | E58: 0 | F58: 0 | G58: 0 | H58: 0 | I58: 0 | J58: 0 | K58: 0 | L58: 0 | M58: 0 | N58: 0 | O58: 0 | P58: 0 | Q58: 0 | R58: 0 | S58: 0 | T58: 0 | U58: 0 | V58: 0 | W58: 0 | X58: 0 | Y58: 0 | Z58: 0 | AA58: 0 | AB58: 0 | AC58: 0 | AD58: 0 | AE58: 0 | AF58: 0 | AG58: 0
B59: Basic metals (Steel, Aluminum, Zinc) | C59: cmet | D59: 54 | E59: 0 | F59: 0 | G59: 0 | H59: 0 | I59: 0 | J59: 0 | K59: 0 | L59: 0 | M59: 0 | N59: 0 | O59: 0 | P59: 0 | Q59: 0 | R59: 0 | S59: 0 | T59: 0 | U59: 0 | V59: 0 | W59: 0 | X59: 0 | Y59: 0 | Z59: 0 | AA59: 0 | AB59: 0 | AC59: 0 | AD59: 0 | AE59: 0 | AF59: 0 | AG59: 0
...

Sheet TAX
A1: Product taxes in mln euro, NLD 2015
E4: Taxes on domestic products | F4: Taxes on imported products
E5: 1 | F5: 2
A6: VAT | B6: Products of agriculture, Hunting, Forestry, and Fishing | C6: cagr | D6: 1 | E6: 472.26795 | F6: 475.00851
B7: Basic metals (Steel, Aluminum, Zinc) | C7: cmet | D7: 2 | E7: 0 | F7: 0
B8: Chemical products (Nitric Acid, Urea, Chlorine, other) | C8: cchem | D8: 3 | E8: 179.06355 | F8: 516.31362
B9: Rubber and Plastic (Ethylene, Propylene, other HVC) | C9: cpla | D9: 4 | E9: 136.07542 | F9: 116.43566
B10: non-metallic mineral products (Glass, Ceramic) | C10: cgla | D10: 5 | E10: 34.613429 | F10: 121.73038
B11: Paper and paperboard | C11: cpap | D11: 6 | E11: 120.67144 | F11: 136.73438
B12: Food products and beverages | C12: cfoo | D12: 7 | E12: 3373.9453 | F12: 2569.9986
B13: Rest of economy | C13: cres | D13: 8 | E13: 29727.601 | F13: 2336.2507
B14: Land transport | C14: croa | D14: 9 | E14: 671.47784 | F14: 30.773611
B15: Water transport (navigation) | C15: cwat | D15: 10 | E15: 28.504672 | F15: 0
B16: Air transport (aviation) | C16: cair | D16: 11 | E16: 233.93986 | F16: 94.871609
B17: Coal and coal products | C17: ccoa | D17: 12 | E17: 0.025861743 | F17: 0.070725436
B18: Crude oil | C18: coil | D18: 13 | E18: 0 | F18: 0
... B28: Waste | C28: cwas | D28: 23 | E28: 0 | F28: 0
B29: Total VAT | D29: 24 | E29: 37524.916 | F29: 6958.0636
A30: Subsidies | B30: Products of agriculture, Hunting, Forestry, and Fishing | C30: cagr | D30: 25 | E30: -14.825524 | F30: 0
B31: Basic metals (Steel, Aluminum, Zinc) | C31: cmet | D31: 26 | E31: -3.9150962 | F31: 0
B32: Chemical products (Nitric Acid, Urea, Chlorine, other) | C32: cchem | D32: 27 | E32: -15.835246 | F32: 0
B33: Rubber and Plastic (Ethylene, Propylene, other HVC) | C33: cpla | D33: 28 | E33: -4.5442116 | F33: 0
B34: non-metallic mineral products (Glass, Ceramic) | C34: cgla | D34: 29 | E34: -2.7805283 | F34: 0
B35: Paper and paperboard | C35: cpap | D35: 30 | E35: -3.6602099 | F35: 0
B36: Food products and beverages | C36: cfoo | D36: 31 | E36: -35.506412 | F36: 0
B37: Rest of economy | C37: cres | D37: 32 | E37: -569.90094 | F37: 0
B38: Land transport | C38: croa | D38: 33 | E38: -29.253059 | F38: 0
B39: Water transport (navigation) | C39: cwat | D39: 34 | E39: -4.5852526 | F39: 0
B40: Air transport (aviation) | C40: cair | D40: 35 | E40: -5.456834 | F40: 0
B41: Coal and coal products | C41: ccoa | D41: 36 | E41: -0.26826024 | F41: 0
B42: Crude oil | C42: coil | D42: 37 | E42: -1.2676392 | F42: 0
... B52: Waste | C52: cwas | D52: 47 | E52: -0.32606894 | F52: 0
B53: Total subsidies | D53: 48 | E53: -723 | F53: 0
A54: Other taxes | B54: Products of agriculture, Hunting, Forestry, and Fishing | C54: cagr | D54: 49 | E54: -11.788594 | F54: -150.66234
B55: Basic metals (Steel, Aluminum, Zinc) | C55: cmet | D55: 50 | E55: 26.120591 | F55: 42.794505
B56: Chemical products (Nitric Acid, Urea, Chlorine, other) | C56: cchem | D56: 51 | E56: 385.90606 | F56: -91.749919
B57: Rubber and Plastic (Ethylene, Propylene, other HVC) | C57: cpla | D57: 52 | E57: 96.124518 | F57: 151.90861
B58: non-metallic mineral products (Glass, Ceramic) | C58: cgla | D58: 53 | E58: 158.73969 | F58: 10.697034
B59: Paper and paperboard | C59: cpap | D59: 54 | E59: 99.639667 | F59: 42.614721
B60: Food products and beverages | C60: cfoo | D60: 55 | E60: 1866.6391 | F60: 90.923488
...

Sheet HH
A1: Household income in mln euro, NLD 2015
E4: Household income
E5: 1
C6: Wages | D6: 1 | E6: 333879
C7: Property income | D7: 2 | E7: 51567
C8: Social benefits | D8: 3 | E8: 122694
C9: Transfers | D9: 4 | E9: 7049
C10: Total household income before tax | D10: 5 | E10: 515189

Sheet OTH
A1: Other indicators, NLD 2015
E4: Other indicators
E5: 1
C6: Government debt in % of GDP | D6: 1 | E6: 0.647
C7: Population | D7: 2 | E7: 16900.726
