Workbook

Sheet Elasticities_WIOD
B1: Code | C1: KL | D1: KE | E1: KM | F1: LE | G1: LM | H1: EM | I1: Std error | J1: KL | K1: KE | L1: KM | M1: LE | N1: LM | O1: EM | P1: Stars | Q1: KL | R1: KE | S1: KM | T1: LE | U1: LM | V1: EM
A2: Crop and animal production, hunting and related service activities | B2: A01 | C2: 2 | D2: -0.079433543 | E2: -0.33299264 | F2: -14.558973 | G2: -0.37345936 | H2: 4.554247 | J2: 0.037716328 | K2: 0.4965005 | L2: 0.037043056 | M2: 7.2518072 | N2: 0.088262694 | O2: 2.4365451 | Q2: *** | S2: *** | T2: * | U2: *** | V2: .
A3: Forestry and logging | B3: A02 | C3: -0.64417518 | D3: 1.8972875 | E3: -0.62980055 | F3: 0.75269494 | G3: -0.41463909 | H3: -6.0545741 | J3: 0.055353152 | K3: 0.80678737 | L3: 0.10000877 | M3: 2.8179851 | N3: 0.14038495 | O3: 3.7606684 | Q3: *** | R3: * | S3: *** | U3: **
A4: Fishing and aquaculture | B4: A03 | C4: -0.64673219 | D4: -1.1395771 | E4: -0.41557411 | F4: -12.262303 | G4: 0.010682621 | H4: 13.26043 | J4: 0.071039329 | K4: 4.7204102 | L4: 0.10222784 | M4: 10.561323 | N4: 0.13748817 | O4: 18.421012 | Q4: *** | S4: ***
A5: Mining and quarrying | B5: B | C5: -1.6232461 | D5: -1.139352 | E5: -0.46016056 | F5: 3.7393599 | G5: 0.51902037 | H5: -1.210715 | J5: 0.32657446 | K5: 0.13984805 | L5: 0.080570408 | M5: 0.9897561 | N5: 0.42444461 | O5: 0.20156466 | Q5: *** | R5: *** | S5: *** | T5: *** | V5: ***
A6: Manufacture of food products, beverages and tobacco products | B6: C10-C12 | C6: -0.40614676 | D6: -1.5187354 | E6: -0.62635141 | F6: -2.0896776 | G6: -0.56421324 | H6: -0.38968347 | J6: 0.037617585 | K6: 0.58800129 | L6: 0.064843413 | M6: 2.2864181 | N6: 0.068369988 | O6: 1.1305015 | Q6: *** | R6: ** | S6: *** | U6: ***
A7: Manufacture of textiles, wearing apparel and leather products | B7: C13-C15 | C7: -0.69112446 | D7: -0.85248274 | E7: -1.0416057 | F7: 0.54931914 | G7: -0.40470944 | H7: -1.8119718 | J7: 0.060036571 | K7: 0.23924969 | L7: 0.11532485 | M7: 0.56168313 | N7: 0.13837962 | O7: 0.58336828 | Q7: *** | R7: *** | S7: *** | U7: ** | V7: **
A8: Manufacture of wood and of products of wood and cork, except furniture; manufacture of articles of straw and plaiting materials | B8: C16 | C8: -0.71522875 | D8: -0.75225287 | E8: -0.60689908 | F8: -3.286614 | G8: -0.37163974 | H8: -0.23105727 | J8: 0.079297898 | K8: 0.69189224 | L8: 0.045522741 | M8: 1.9898966 | N8: 0.070246627 | O8: 1.0013481 | Q8: *** | S8: *** | T8: . | U8: ***
A9: Manufacture of paper and paper products | B9: C17 | C9: -0.55590806 | D9: -2.2579813 | E9: -1.5565364 | F9: 0.45688136 | G9: -0.099162744 | H9: 0.48430505 | J9: 0.09652915 | K9: 0.55876212 | L9: 0.097894337 | M9: 1.0234284 | N9: 0.074364152 | O9: 0.73515384 | Q9: *** | R9: *** | S9: ***
A10: Printing and reproduction of recorded media | B10: C18 | C10: -0.97862796 | D10: -2.1801039 | E10: -0.82565051 | F10: 2.4256042 | G10: -0.56383015 | H10: -0.50884777 | J10: 0.10824979 | K10: 0.91710125 | L10: 0.057617639 | M10: 2.1738537 | N10: 0.098476853 | O10: 1.2399503 | Q10: *** | R10: * | S10: *** | U10: ***
A11: Manufacture of coke and refined petroleum products | B11: C19 | C11: -0.17342704 | D11: -0.19568186 | E11: -0.053895097 | F11: -0.69661571 | G11: -0.11767251 | H11: -0.44548428 | J11: 0.050118807 | K11: 0.10594523 | L11: 0.061769137 | M11: 0.32060003 | N11: 0.073523633 | O11: 0.34391757 | Q11: *** | R11: . | T11: *
A12: Manufacture of chemicals and chemical products | B12: C20 | C12: -0.57986596 | D12: -0.66408955 | E12: -1.0546638 | F12: -0.80633487 | G12: -0.40488528 | H12: -1.5281694 | J12: 0.093363216 | K12: 0.43507473 | L12: 0.063711877 | M12: 1.2319631 | N12: 0.086685584 | O12: 0.87957327 | Q12: *** | S12: *** | U12: *** | V12: .
A13: Manufacture of basic pharmaceutical products and pharmaceutical preparations | B13: C21 | C13: -0.43738635 | D13: -0.88612925 | E13: -1.1550569 | F13: 0.10407744 | G13: -0.44795135 | H13: -2.076004 | J13: 0.071313432 | K13: 0.28755217 | L13: 0.085688065 | M13: 0.65721742 | N13: 0.099860676 | O13: 0.84110968 | Q13: *** | R13: ** | S13: *** | U13: *** | V13: *
A14: Manufacture of rubber and plastic products | B14: C22 | C14: -0.70951635 | D14: -0.6107688 | E14: -0.86938428 | F14: 2.0583658 | G14: -0.69568366 | H14: -2.3974471 | J14: 0.085939918 | K14: 0.48252908 | L14: 0.06312226 | M14: 1.3637197 | N14: 0.093802521 | O14: 0.83221231 | Q14: *** | S14: *** | U14: *** | V14: **
A15: Manufacture of other non-metallic mineral products | B15: C23 | C15: -0.8745595 | D15: -0.8557464 | E15: -0.6520436 | F15: 0.5985235 | G15: -0.41465782 | H15: -1.4270128 | J15: 0.074439637 | K15: 0.29247107 | L15: 0.060010766 | M15: 0.9356857 | N15: 0.086502352 | O15: 0.41776075 | Q15: *** | R15: ** | S15: *** | U15: *** | V15: ***
A16: Manufacture of basic metals | B16: C24 | C16: -0.97355221 | D16: -0.8705577 | E16: -0.53307664 | F16: -0.04506931 | G16: 0.17521536 | H16: -1.2796321 | J16: 0.15301796 | K16: 0.23526801 | L16: 0.06407235 | M16: 0.36144254 | N16: 0.074048673 | O16: 0.26874347 | Q16: *** | R16: *** | S16: *** | U16: * | V16: ***
A17: Manufacture of fabricated metal products, except machinery and equipment | B17: C25 | C17: -0.76481378 | D17: -0.76904792 | E17: -0.78047666 | F17: 0.34116939 | G17: -0.64009021 | H17: -0.8580166 | J17: 0.073508886 | K17: 0.22652698 | L17: 0.062036206 | M17: 0.689252 | N17: 0.084363883 | O17: 0.38358544 | Q17: *** | R17: *** | S17: *** | U17: *** | V17: *
A18: Manufacture of computer, electronic and optical products | B18: C26 | C18: -0.0025300725 | D18: 0.048244444 | E18: 0.051246305 | F18: 0.14776992 | G18: -0.73941473 | H18: -2.5443725 | J18: 0.01001423 | K18: 0.024854948 | L18: 0.017068315 | M18: 0.44529665 | N18: 0.060706565 | O18: 0.6442426 | R18: . | S18: ** | U18: *** | V18: ***
A19: Manufacture of electrical equipment | B19: C27 | C19: -0.064274333 | D19: 0.051552315 | E19: -0.00044797077 | F19: -0.18812035 | G19: -0.88243221 | H19: -2.4761575 | J19: 0.0093764756 | K19: 0.013118017 | L19: 0.0068432092 | M19: 0.32881979 | N19: 0.056947802 | O19: 0.36929251 | Q19: *** | R19: *** | U19: *** | V19: ***
A20: Manufacture of machinery and equipment n.e.c. | B20: C28 | C20: -0.47245456 | D20: -0.42397374 | E20: -0.7885775 | F20: -0.68241679 | G20: -0.52603849 | H20: -2.0634537 | J20: 0.040737939 | K20: 0.13195861 | L20: 0.04401893 | M20: 0.49482911 | N20: 0.08091237 | O20: 0.63143256 | Q20: *** | R20: ** | S20: *** | U20: *** | V20: **
A21: Manufacture of motor vehicles, trailers and semi-trailers | B21: C29 | C21: -0.00056361637 | D21: 0.0012294461 | E21: -0.00049445869 | F21: -1.3057559 | G21: -0.97813444 | H21: -1.9597559 | J21: 0.0015821584 | K21: 0.006101034 | L21: 0.0026540909 | M21: 0.78709346 | N21: 0.09215387 | O21: 1.0081821 | T21: . | U21: *** | V21: .
A22: Manufacture of other transport equipment | B22: C30 | C22: 0.012081462 | D22: 0.021019461 | E22: 0.00225891 | F22: -3.2825638 | G22: -1.2911291 | H22: -1.381564 | J22: 0.012265394 | K22: 0.017614595 | L22: 0.010141539 | M22: 0.44517079 | N22: 0.14093276 | O22: 1.20351 | T22: *** | U22: ***
A23: Manufacture of furniture; other manufacturing | B23: C31_C32 | C23: -0.56622788 | D23: -0.39159638 | E23: -0.63785139 | F23: -1.4212566 | G23: -0.59115365 | H23: -2.4800695 | J23: 0.059555472 | K23: 0.47305732 | L23: 0.072269227 | M23: 1.279158 | N23: 0.099064202 | O23: 1.4560929 | Q23: *** | S23: *** | U23: *** | V23: .
A24: Repair and installation of machinery and equipment | B24: C33 | C24: 0.052362891 | D24: -0.2334942 | E24: 0.036166274 | F24: -0.054879838 | G24: -0.0087246558 | H24: -1.7607216 | J24: 0.031200366 | K24: 0.26961224 | L24: 0.035033582 | M24: 0.19132979 | N24: 0.023126249 | O24: 0.55256717 | Q24: . | V24: **
A25: Electricity, gas, steam and air conditioning supply | B25: D35 | C25: -5.8731935 | D25: -0.68512135 | E25: -0.077267571 | F25: 1.2890339 | G25: -1.4130812 | H25: -0.69859948 | J25: 0.78350487 | K25: 0.15662895 | L25: 0.031741234 | M25: 2.8184065 | N25: 0.44059125 | O25: 0.19257027 | Q25: *** | R25: *** | S25: * | U25: ** | V25: ***
A26: Water collection, treatment and supply | B26: E36 | C26: -1.502141 | D26: -0.22028782 | E26: -0.1244136 | F26: -0.79006801 | G26: 0.14072642 | H26: -4.6556046 | J26: 0.10612678 | K26: 0.13674787 | L26: 0.03177787 | M26: 1.0739274 | N26: 0.2452493 | O26: 1.6138457 | Q26: *** | S26: *** | V26: **
A27: Sewerage; waste collection, treatment and disposal activities; materials recovery; remediation activities and other waste management services | B27: E37-E39 | C27: -0.65689985 | D27: -13.929157 | E27: -0.23966861 | F27: -13.098253 | G27: -0.30050556 | H27: 0.41724338 | J27: 0.050556892 | K27: 2.1117737 | L27: 0.044349666 | M27: 2.597753 | N27: 0.093037534 | O27: 2.5648619 | Q27: *** | R27: *** | S27: *** | T27: *** | U27: **
A28: Construction | B28: F | C28: -0.50548251 | D28: 0.32714918 | E28: -0.66061657 | F28: -0.075969281 | G28: -0.48328179 | H28: -3.5312462 | J28: 0.044485651 | K28: 0.30829587 | L28: 0.052294467 | M28: 0.61285673 | N28: 0.073665169 | O28: 0.57683147 | Q28: *** | S28: *** | U28: *** | V28: ***
A29: Wholesale and retail trade and repair of motor vehicles and motorcycles | B29: G45 | C29: -0.7525459 | D29: -0.97192915 | E29: -0.82529728 | F29: -1.2758003 | G29: -0.076544304 | H29: -1.1467166 | J29: 0.057718284 | K29: 0.32044596 | L29: 0.047249989 | M29: 0.65096035 | N29: 0.066083553 | O29: 0.48627381 | Q29: *** | R29: ** | S29: *** | T29: . | V29: *
A30: Wholesale trade, except of motor vehicles and motorcycles | B30: G46 | C30: -0.32606852 | D30: -0.51951832 | E30: -0.64931202 | F30: -1.1756735 | G30: -0.18345418 | H30: -1.7367437 | J30: 0.036616572 | K30: 0.26714151 | L30: 0.096513448 | M30: 0.55959293 | N30: 0.090355855 | O30: 0.64067385 | Q30: *** | R30: . | S30: *** | T30: * | U30: * | V30: **
A31: Retail trade, except of motor vehicles and motorcycles | B31: G47 | C31: -0.38377851 | D31: -0.49306218 | E31: -0.23889037 | F31: -0.43438208 | G31: -0.55872061 | H31: -2.247249 | J31: 0.048139503 | K31: 0.15091427 | L31: 0.025773966 | M31: 0.75882157 | N31: 0.097022387 | O31: 0.60865422 | Q31: *** | R31: ** | S31: *** | U31: *** | V31: ***
A32: Land transport and transport via pipelines | B32: H49 | C32: -0.40333807 | D32: -0.17358482 | E32: 0.023201449 | F32: -0.09355918 | G32: -0.42325069 | H32: -1.9331279 | J32: 0.11099661 | K32: 0.052896749 | L32: 0.023936576 | M32: 0.49299833 | N32: 0.19001419 | O32: 0.31213651 | Q32: *** | R32: ** | U32: * | V32: ***
A33: Water transport | B33: H50 | C33: -0.16723547 | D33: -0.067303241 | E33: 0.014453684 | F33: 0.058835322 | G33: -0.10764747 | H33: -3.1314893 | J33: 0.043299971 | K33: 0.047442901 | L33: 0.020844822 | M33: 0.19716895 | N33: 0.077345556 | O33: 0.49813017 | Q33: *** | V33: ***
A34: Air transport | B34: H51 | C34: -0.84273523 | D34: -0.76373376 | E34: -0.19220973 | F34: -4.0673996 | G34: -0.29605262 | H34: -0.81062091 | J34: 0.067310182 | K34: 0.20465208 | L34: 0.026693895 | M34: 1.0276721 | N34: 0.098809529 | O34: 0.6698886 | Q34: *** | R34: *** | S34: *** | T34: *** | U34: **
A35: Warehousing and support activities for transportation | B35: H52 | C35: -0.21383473 | D35: -0.082720805 | E35: -0.26486266 | F35: -0.23704143 | G35: -0.0073383486 | H35: -3.2692224 | J35: 0.057160653 | K35: 0.12961004 | L35: 0.036836588 | M35: 0.1228082 | N35: 0.029583551 | O35: 0.35451216 | Q35: *** | S35: *** | T35: . | V35: ***
A36: Postal and courier activities | B36: H53 | C36: -0.48582372 | D36: -0.34423399 | E36: -0.36556059 | F36: -0.14953751 | G36: -0.31706769 | H36: -4.0141808 | J36: 0.035725079 | K36: 0.20910496 | L36: 0.095600294 | M36: 0.5359964 | N36: 0.14329503 | O36: 0.83262454 | Q36: *** | R36: . | S36: *** | U36: * | V36: ***
A37: Accommodation and food service activities | B37: I | C37: -0.45527078 | D37: -0.25185593 | E37: -0.62637323 | F37: -0.24348303 | G37: -0.43495677 | H37: -1.8452374 | J37: 0.065831081 | K37: 0.1860497 | L37: 0.079355598 | M37: 0.28341589 | N37: 0.075552739 | O37: 0.32505992 | Q37: *** | S37: *** | U37: *** | V37: ***
A38: Publishing activities | B38: J58 | C38: -0.61551616 | D38: -1.8560057 | E38: -0.6278893 | F38: -1.3798312 | G38: -0.066649705 | H38: -2.3811178 | J38: 0.057990319 | K38: 0.97584849 | L38: 0.062847663 | M38: 2.3739885 | N38: 0.090403932 | O38: 1.7450267 | Q38: *** | R38: . | S38: ***
A39: Motion picture, video and television programme production, sound recording and music publishing activities; programming and broadcasting activities | B39: J59_J60 | C39: -0.7205982 | D39: -0.6062801 | E39: -0.17591036 | F39: 0.13628406 | G39: -0.024281611 | H39: -0.665707 | J39: 0.054248303 | K39: 0.12752126 | L39: 0.032462363 | M39: 0.62868525 | N39: 0.1144999 | O39: 0.49026609 | Q39: *** | R39: *** | S39: ***
A40: Telecommunications | B40: J61 | C40: -0.99525108 | D40: -0.15270063 | E40: -0.78043517 | F40: -0.0054144292 | G40: -0.15822777 | H40: -1.967712 | J40: 0.064423597 | K40: 0.12549832 | L40: 0.056475628 | M40: 0.14510217 | N40: 0.061550883 | O40: 0.31132262 | Q40: *** | S40: *** | U40: * | V40: ***
...

Sheet Pond.Inputs
A1: Gross output 2014 (source WIOD_SEA16) | B1: Y
A2: Crop and animal production, hunting and related service activities | B2: 79226
A3: Forestry and logging | B3: 5048
A4: Fishing and aquaculture | B4: 2294
A5: Mining and quarrying | B5: 5437
A6: Manufacture of food products, beverages and tobacco products | B6: 155159
A7: Manufacture of textiles, wearing apparel and leather products | B7: 16283
A8: Manufacture of wood and of products of wood and cork, except furniture; manufacture of articles of straw and plaiting materials | B8: 10330
A9: Manufacture of paper and paper products | B9: 16334
A10: Printing and reproduction of recorded media | B10: 9540
A11: Manufacture of coke and refined petroleum products | B11: 48374
A12: Manufacture of chemicals and chemical products | B12: 67379
A13: Manufacture of basic pharmaceutical products and pharmaceutical preparations | B13: 24817
... A57: Activities of extraterritorial organizations and bodies | B57: 0

Sheet WIOD.NAF17
B1: Agriculture, sylviculture et pêche | C1: Industries extractives, énergie, eau, gestion des déchets et dépollution | D1: Fabrication de denrées alimentaires, de boissons et de produits à base de tabac | E1: Cokéfaction et raffinage | F1: Fabrication d'équipements électriques, électroniques, informatiques ; fabrication de machines | G1: Fabrication de matériels de transport | H1: Fabrication d'autres produits industriels | I1: Construction | J1: Commerce ; réparation d'automobiles et de motocycles | K1: Transports et entreposage | L1: Hébergement et restauration | M1: Information et communication | N1: Activités financières et d'assurance | O1: Activités immobilières | P1: Activités spécialisées, scientifiques et techniques et activités de services administratifs et de soutien | Q1: Administration publique, enseignement, santé humaine et action sociale | R1: Autres activités de services
A2: Crop and animal production, hunting and related service activities | B2: 1 | C2: 0 | D2: 0 | E2: 0 | F2: 0 | G2: 0 | H2: 0 | I2: 0 | J2: 0 | K2: 0 | L2: 0 | M2: 0 | N2: 0 | O2: 0 | P2: 0 | Q2: 0 | R2: 0
A3: Forestry and logging | B3: 1 | C3: 0 | D3: 0 | E3: 0 | F3: 0 | G3: 0 | H3: 0 | I3: 0 | J3: 0 | K3: 0 | L3: 0 | M3: 0 | N3: 0 | O3: 0 | P3: 0 | Q3: 0 | R3: 0
A4: Fishing and aquaculture | B4: 1 | C4: 0 | D4: 0 | E4: 0 | F4: 0 | G4: 0 | H4: 0 | I4: 0 | J4: 0 | K4: 0 | L4: 0 | M4: 0 | N4: 0 | O4: 0 | P4: 0 | Q4: 0 | R4: 0
A5: Mining and quarrying | B5: 0 | C5: 1 | D5: 0 | E5: 0 | F5: 0 | G5: 0 | H5: 0 | I5: 0 | J5: 0 | K5: 0 | L5: 0 | M5: 0 | N5: 0 | O5: 0 | P5: 0 | Q5: 0 | R5: 0
A6: Manufacture of food products, beverages and tobacco products | B6: 0 | C6: 0 | D6: 1 | E6: 0 | F6: 0 | G6: 0 | H6: 0 | I6: 0 | J6: 0 | K6: 0 | L6: 0 | M6: 0 | N6: 0 | O6: 0 | P6: 0 | Q6: 0 | R6: 0
A7: Manufacture of textiles, wearing apparel and leather products | B7: 0 | C7: 0 | D7: 0 | E7: 0 | F7: 0 | G7: 0 | H7: 1 | I7: 0 | J7: 0 | K7: 0 | L7: 0 | M7: 0 | N7: 0 | O7: 0 | P7: 0 | Q7: 0 | R7: 0
A8: Manufacture of wood and of products of wood and cork, except furniture; manufacture of articles of straw and plaiting materials | B8: 0 | C8: 0 | D8: 0 | E8: 0 | F8: 0 | G8: 0 | H8: 1 | I8: 0 | J8: 0 | K8: 0 | L8: 0 | M8: 0 | N8: 0 | O8: 0 | P8: 0 | Q8: 0 | R8: 0
A9: Manufacture of paper and paper products | B9: 0 | C9: 0 | D9: 0 | E9: 0 | F9: 0 | G9: 0 | H9: 1 | I9: 0 | J9: 0 | K9: 0 | L9: 0 | M9: 0 | N9: 0 | O9: 0 | P9: 0 | Q9: 0 | R9: 0
A10: Printing and reproduction of recorded media | B10: 0 | C10: 0 | D10: 0 | E10: 0 | F10: 1 | G10: 0 | H10: 0 | I10: 0 | J10: 0 | K10: 0 | L10: 0 | M10: 0 | N10: 0 | O10: 0 | P10: 0 | Q10: 0 | R10: 0
A11: Manufacture of coke and refined petroleum products | B11: 0 | C11: 0 | D11: 0 | E11: 1 | F11: 0 | G11: 0 | H11: 0 | I11: 0 | J11: 0 | K11: 0 | L11: 0 | M11: 0 | N11: 0 | O11: 0 | P11: 0 | Q11: 0 | R11: 0
A12: Manufacture of chemicals and chemical products | B12: 0 | C12: 0 | D12: 0 | E12: 0 | F12: 0 | G12: 0 | H12: 1 | I12: 0 | J12: 0 | K12: 0 | L12: 0 | M12: 0 | N12: 0 | O12: 0 | P12: 0 | Q12: 0 | R12: 0
A13: Manufacture of basic pharmaceutical products and pharmaceutical preparations | B13: 0 | C13: 0 | D13: 0 | E13: 0 | F13: 0 | G13: 0 | H13: 1 | I13: 0 | J13: 0 | K13: 0 | L13: 0 | M13: 0 | N13: 0 | O13: 0 | P13: 0 | Q13: 0 | R13: 0
... A57: Activities of extraterritorial organizations and bodies | B57: 0 | C57: 0 | D57: 0 | E57: 0 | F57: 0 | G57: 0 | H57: 0 | I57: 0 | J57: 0 | K57: 0 | L57: 0 | M57: 0 | N57: 0 | O57: 0 | P57: 0 | Q57: 0 | R57: 1

Sheet WIOD.ThreeME_V3
B1: Agriculture and fishing | C1: Forestry | D1: Manufacture of food products and beverages | E1: Manufacture of motor vehicles, trailers and semi-trailers | F1: Manufacture of glass, ceramic and ciment products | G1: Manufacture of paper and paperboard | H1: Manufacture of chemicals | I1: Manufacture of plastics products | J1: Metallurgy | K1: Manufacture of other goods for industry | L1: Manufacture of other goods for consumers | M1: Construction of buildings and Civil engineering | N1: Rail transport | O1: Road transport | P1: Water transport | Q1: Air transport | R1: Business services | S1: Public services | T1: Mining | U1: Production of refined oil | V1: Production of biofuel | W1: Distribution of natural gas | X1: Production and distribution of biogas | Y1: Nuclear electricity generation | Z1: Oil-fired electricity generation | AA1: Gas-fired electricity generation | AB1: Coal-fired electricity generation | AC1: Wind electricity generation | AD1: Solar electricity generation | AE1: Hydroelectric electricity generation | AF1: Cogeneration (CHP) electricity generation and other heat supply | AG1: Electricity - Others
A2: Crop and animal production, hunting and related service activities | B2: 1 | C2: 0 | D2: 0 | E2: 0 | F2: 0 | G2: 0 | H2: 0 | I2: 0 | J2: 0 | K2: 0 | L2: 0 | M2: 0 | N2: 0 | O2: 0 | P2: 0 | Q2: 0 | R2: 0 | S2: 0 | T2: 0 | U2: 0 | V2: 0 | W2: 0 | X2: 0 | Y2: 0 | Z2: 0 | AA2: 0 | AB2: 0 | AC2: 0 | AD2: 0 | AE2: 0 | AF2: 0 | AG2: 0
A3: Forestry and logging | B3: 0 | C3: 1 | D3: 0 | E3: 0 | F3: 0 | G3: 0 | H3: 0 | I3: 0 | J3: 0 | K3: 0 | L3: 0 | M3: 0 | N3: 0 | O3: 0 | P3: 0 | Q3: 0 | R3: 0 | S3: 0 | T3: 0 | U3: 0 | V3: 0 | W3: 0 | X3: 0 | Y3: 0 | Z3: 0 | AA3: 0 | AB3: 0 | AC3: 0 | AD3: 0 | AE3: 0 | AF3: 0 | AG3: 0
A4: Fishing and aquaculture | B4: 1 | C4: 0 | D4: 0 | E4: 0 | F4: 0 | G4: 0 | H4: 0 | I4: 0 | J4: 0 | K4: 0 | L4: 0 | M4: 0 | N4: 0 | O4: 0 | P4: 0 | Q4: 0 | R4: 0 | S4: 0 | T4: 0 | U4: 0 | V4: 0 | W4: 0 | X4: 0 | Y4: 0 | Z4: 0 | AA4: 0 | AB4: 0 | AC4: 0 | AD4: 0 | AE4: 0 | AF4: 0 | AG4: 0
A5: Mining and quarrying | B5: 0 | C5: 0 | D5: 0 | E5: 0 | F5: 0 | G5: 0 | H5: 0 | I5: 0 | J5: 0 | K5: 0 | L5: 0 | M5: 0 | N5: 0 | O5: 0 | P5: 0 | Q5: 0 | R5: 0 | S5: 0 | T5: 1 | U5: 0 | V5: 0 | W5: 0 | X5: 0 | Y5: 0 | Z5: 0 | AA5: 0 | AB5: 0 | AC5: 0 | AD5: 0 | AE5: 0 | AF5: 0 | AG5: 0
A6: Manufacture of food products, beverages and tobacco products | B6: 0 | C6: 0 | D6: 1 | E6: 0 | F6: 0 | G6: 0 | H6: 0 | I6: 0 | J6: 0 | K6: 1 | L6: 0 | M6: 0 | N6: 0 | O6: 0 | P6: 0 | Q6: 0 | R6: 0 | S6: 0 | T6: 0 | U6: 0 | V6: 0 | W6: 0 | X6: 0 | Y6: 0 | Z6: 0 | AA6: 0 | AB6: 0 | AC6: 0 | AD6: 0 | AE6: 0 | AF6: 0 | AG6: 0
A7: Manufacture of textiles, wearing apparel and leather products | B7: 0 | C7: 0 | D7: 0 | E7: 0 | F7: 0 | G7: 0 | H7: 0 | I7: 0 | J7: 0 | K7: 0 | L7: 0 | M7: 0 | N7: 0 | O7: 0 | P7: 0 | Q7: 0 | R7: 0 | S7: 0 | T7: 0 | U7: 0 | V7: 0 | W7: 0 | X7: 0 | Y7: 0 | Z7: 0 | AA7: 0 | AB7: 0 | AC7: 0 | AD7: 0 | AE7: 0 | AF7: 0 | AG7: 0
A8: Manufacture of wood and of products of wood and cork, except furniture; manufacture of articles of straw and plaiting materials | B8: 0 | C8: 0 | D8: 0 | E8: 0 | F8: 0 | G8: 0 | H8: 0 | I8: 0 | J8: 0 | K8: 1 | L8: 0 | M8: 0 | N8: 0 | O8: 0 | P8: 0 | Q8: 0 | R8: 0 | S8: 0 | T8: 0 | U8: 0 | V8: 0 | W8: 0 | X8: 0 | Y8: 0 | Z8: 0 | AA8: 0 | AB8: 0 | AC8: 0 | AD8: 0 | AE8: 0 | AF8: 0 | AG8: 0
A9: Manufacture of paper and paper products | B9: 0 | C9: 0 | D9: 0 | E9: 0 | F9: 0 | G9: 1 | H9: 0 | I9: 0 | J9: 0 | K9: 0 | L9: 0 | M9: 0 | N9: 0 | O9: 0 | P9: 0 | Q9: 0 | R9: 0 | S9: 0 | T9: 0 | U9: 0 | V9: 0 | W9: 0 | X9: 0 | Y9: 0 | Z9: 0 | AA9: 0 | AB9: 0 | AC9: 0 | AD9: 0 | AE9: 0 | AF9: 0 | AG9: 0
A10: Printing and reproduction of recorded media | B10: 0 | C10: 0 | D10: 0 | E10: 0 | F10: 0 | G10: 1 | H10: 0 | I10: 0 | J10: 0 | K10: 0 | L10: 0 | M10: 0 | N10: 0 | O10: 0 | P10: 0 | Q10: 0 | R10: 0 | S10: 0 | T10: 0 | U10: 0 | V10: 0 | W10: 0 | X10: 0 | Y10: 0 | Z10: 0 | AA10: 0 | AB10: 0 | AC10: 0 | AD10: 0 | AE10: 0 | AF10: 0 | AG10: 0
A11: Manufacture of coke and refined petroleum products | B11: 0 | C11: 0 | D11: 0 | E11: 0 | F11: 0 | G11: 0 | H11: 0 | I11: 0 | J11: 0 | K11: 0 | L11: 0 | M11: 0 | N11: 0 | O11: 0 | P11: 0 | Q11: 0 | R11: 0 | S11: 0 | T11: 0 | U11: 1 | V11: 1 | W11: 1 | X11: 1 | Y11: 0 | Z11: 0 | AA11: 0 | AB11: 0 | AC11: 0 | AD11: 0 | AE11: 0 | AF11: 0 | AG11: 0
A12: Manufacture of chemicals and chemical products | B12: 0 | C12: 0 | D12: 0 | E12: 0 | F12: 0 | G12: 0 | H12: 1 | I12: 0 | J12: 0 | K12: 0 | L12: 0 | M12: 0 | N12: 0 | O12: 0 | P12: 0 | Q12: 0 | R12: 0 | S12: 0 | T12: 0 | U12: 0 | V12: 0 | W12: 0 | X12: 0 | Y12: 0 | Z12: 0 | AA12: 0 | AB12: 0 | AC12: 0 | AD12: 0 | AE12: 0 | AF12: 0 | AG12: 0
A13: Manufacture of basic pharmaceutical products and pharmaceutical preparations | B13: 0 | C13: 0 | D13: 0 | E13: 0 | F13: 0 | G13: 0 | H13: 1 | I13: 0 | J13: 0 | K13: 0 | L13: 0 | M13: 0 | N13: 0 | O13: 0 | P13: 0 | Q13: 0 | R13: 0 | S13: 0 | T13: 0 | U13: 0 | V13: 0 | W13: 0 | X13: 0 | Y13: 0 | Z13: 0 | AA13: 0 | AB13: 0 | AC13: 0 | AD13: 0 | AE13: 0 | AF13: 0 | AG13: 0
... A57: Activities of extraterritorial organizations and bodies | B57: 0 | C57: 0 | D57: 0 | E57: 0 | F57: 0 | G57: 0 | H57: 0 | I57: 0 | J57: 0 | K57: 0 | L57: 0 | M57: 0 | N57: 0 | O57: 0 | P57: 0 | Q57: 0 | R57: 0 | S57: 1 | T57: 0 | U57: 0 | V57: 0 | W57: 0 | X57: 0 | Y57: 0 | Z57: 0 | AA57: 0 | AB57: 0 | AC57: 0 | AD57: 0 | AE57: 0 | AF57: 0 | AG57: 0

Sheet WIOD.ThreeME_V3.pond
B1: Agriculture and fishing | C1: Forestry | D1: Manufacture of food products and beverages | E1: Manufacture of motor vehicles, trailers and semi-trailers | F1: Manufacture of glass, ceramic and ciment products | G1: Manufacture of paper and paperboard | H1: Manufacture of chemicals | I1: Manufacture of plastics products | J1: Metallurgy | K1: Manufacture of other goods for industry | L1: Manufacture of other goods for consumers | M1: Construction of buildings and Civil engineering | N1: Rail transport | O1: Road transport | P1: Water transport | Q1: Air transport | R1: Business services | S1: Public services | T1: Mining | U1: Production of refined oil | V1: Production of biofuel | W1: Distribution of natural gas | X1: Production and distribution of biogas | Y1: Nuclear electricity generation | Z1: Oil-fired electricity generation | AA1: Gas-fired electricity generation | AB1: Coal-fired electricity generation | AC1: Wind electricity generation | AD1: Solar electricity generation | AE1: Hydroelectric electricity generation | AF1: Cogeneration (CHP) electricity generation and other heat supply | AG1: Electricity - Others
A2: Crop and animal production, hunting and related service activities | B2: =WIOD.ThreeME_V3!B2 * Pond.Inputs!$B2/SUMPRODUCT(WIOD.ThreeME_V3!B$2:B$57,Pond.Inputs!$B$2:$B$57) -> 0.97185967 | C2: =WIOD.ThreeME_V3!C2 * Pond.Inputs!$B2/SUMPRODUCT(WIOD.ThreeME_V3!C$2:C$57,Pond.Inputs!$B$2:$B$57) -> 0 | D2: =WIOD.ThreeME_V3!D2 * Pond.Inputs!$B2/SUMPRODUCT(WIOD.ThreeME_V3!D$2:D$57,Pond.Inputs!$B$2:$B$57) -> 0 | E2: =WIOD.ThreeME_V3!E2 * Pond.Inputs!$B2/SUMPRODUCT(WIOD.ThreeME_V3!E$2:E$57,Pond.Inputs!$B$2:$B$57) -> 0 | F2: =WIOD.ThreeME_V3!F2 * Pond.Inputs!$B2/SUMPRODUCT(WIOD.ThreeME_V3!F$2:F$57,Pond.Inputs!$B$2:$B$57) -> 0 | G2: =WIOD.ThreeME_V3!G2 * Pond.Inputs!$B2/SUMPRODUCT(WIOD.ThreeME_V3!G$2:G$57,Pond.Inputs!$B$2:$B$57) -> 0 | H2: =WIOD.ThreeME_V3!H2 * Pond.Inputs!$B2/SUMPRODUCT(WIOD.ThreeME_V3!H$2:H$57,Pond.Inputs!$B$2:$B$57) -> 0 | I2: =WIOD.ThreeME_V3!I2 * Pond.Inputs!$B2/SUMPRODUCT(WIOD.ThreeME_V3!I$2:I$57,Pond.Inputs!$B$2:$B$57) -> 0 | ... AG2: =WIOD.ThreeME_V3!AG2 * Pond.Inputs!$B2/SUMPRODUCT(WIOD.ThreeME_V3!AG$2:AG$57,Pond.Inputs!$B$2:$B$57) -> 0
A3: Forestry and logging | B3: =WIOD.ThreeME_V3!B3 * Pond.Inputs!$B3/SUMPRODUCT(WIOD.ThreeME_V3!B$2:B$57,Pond.Inputs!$B$2:$B$57) -> 0 | C3: =WIOD.ThreeME_V3!C3 * Pond.Inputs!$B3/SUMPRODUCT(WIOD.ThreeME_V3!C$2:C$57,Pond.Inputs!$B$2:$B$57) -> 1 | D3: =WIOD.ThreeME_V3!D3 * Pond.Inputs!$B3/SUMPRODUCT(WIOD.ThreeME_V3!D$2:D$57,Pond.Inputs!$B$2:$B$57) -> 0 | E3: =WIOD.ThreeME_V3!E3 * Pond.Inputs!$B3/SUMPRODUCT(WIOD.ThreeME_V3!E$2:E$57,Pond.Inputs!$B$2:$B$57) -> 0 | F3: =WIOD.ThreeME_V3!F3 * Pond.Inputs!$B3/SUMPRODUCT(WIOD.ThreeME_V3!F$2:F$57,Pond.Inputs!$B$2:$B$57) -> 0 | G3: =WIOD.ThreeME_V3!G3 * Pond.Inputs!$B3/SUMPRODUCT(WIOD.ThreeME_V3!G$2:G$57,Pond.Inputs!$B$2:$B$57) -> 0 | H3: =WIOD.ThreeME_V3!H3 * Pond.Inputs!$B3/SUMPRODUCT(WIOD.ThreeME_V3!H$2:H$57,Pond.Inputs!$B$2:$B$57) -> 0 | I3: =WIOD.ThreeME_V3!I3 * Pond.Inputs!$B3/SUMPRODUCT(WIOD.ThreeME_V3!I$2:I$57,Pond.Inputs!$B$2:$B$57) -> 0 | ... AG3: =WIOD.ThreeME_V3!AG3 * Pond.Inputs!$B3/SUMPRODUCT(WIOD.ThreeME_V3!AG$2:AG$57,Pond.Inputs!$B$2:$B$57) -> 0
A4: Fishing and aquaculture | B4: =WIOD.ThreeME_V3!B4 * Pond.Inputs!$B4/SUMPRODUCT(WIOD.ThreeME_V3!B$2:B$57,Pond.Inputs!$B$2:$B$57) -> 0.028140334 | C4: =WIOD.ThreeME_V3!C4 * Pond.Inputs!$B4/SUMPRODUCT(WIOD.ThreeME_V3!C$2:C$57,Pond.Inputs!$B$2:$B$57) -> 0 | D4: =WIOD.ThreeME_V3!D4 * Pond.Inputs!$B4/SUMPRODUCT(WIOD.ThreeME_V3!D$2:D$57,Pond.Inputs!$B$2:$B$57) -> 0 | E4: =WIOD.ThreeME_V3!E4 * Pond.Inputs!$B4/SUMPRODUCT(WIOD.ThreeME_V3!E$2:E$57,Pond.Inputs!$B$2:$B$57) -> 0 | F4: =WIOD.ThreeME_V3!F4 * Pond.Inputs!$B4/SUMPRODUCT(WIOD.ThreeME_V3!F$2:F$57,Pond.Inputs!$B$2:$B$57) -> 0 | G4: =WIOD.ThreeME_V3!G4 * Pond.Inputs!$B4/SUMPRODUCT(WIOD.ThreeME_V3!G$2:G$57,Pond.Inputs!$B$2:$B$57) -> 0 | H4: =WIOD.ThreeME_V3!H4 * Pond.Inputs!$B4/SUMPRODUCT(WIOD.ThreeME_V3!H$2:H$57,Pond.Inputs!$B$2:$B$57) -> 0 | I4: =WIOD.ThreeME_V3!I4 * Pond.Inputs!$B4/SUMPRODUCT(WIOD.ThreeME_V3!I$2:I$57,Pond.Inputs!$B$2:$B$57) -> 0 | ... AG4: =WIOD.ThreeME_V3!AG4 * Pond.Inputs!$B4/SUMPRODUCT(WIOD.ThreeME_V3!AG$2:AG$57,Pond.Inputs!$B$2:$B$57) -> 0
A5: Mining and quarrying | B5: =WIOD.ThreeME_V3!B5 * Pond.Inputs!$B5/SUMPRODUCT(WIOD.ThreeME_V3!B$2:B$57,Pond.Inputs!$B$2:$B$57) -> 0 | C5: =WIOD.ThreeME_V3!C5 * Pond.Inputs!$B5/SUMPRODUCT(WIOD.ThreeME_V3!C$2:C$57,Pond.Inputs!$B$2:$B$57) -> 0 | D5: =WIOD.ThreeME_V3!D5 * Pond.Inputs!$B5/SUMPRODUCT(WIOD.ThreeME_V3!D$2:D$57,Pond.Inputs!$B$2:$B$57) -> 0 | E5: =WIOD.ThreeME_V3!E5 * Pond.Inputs!$B5/SUMPRODUCT(WIOD.ThreeME_V3!E$2:E$57,Pond.Inputs!$B$2:$B$57) -> 0 | F5: =WIOD.ThreeME_V3!F5 * Pond.Inputs!$B5/SUMPRODUCT(WIOD.ThreeME_V3!F$2:F$57,Pond.Inputs!$B$2:$B$57) -> 0 | G5: =WIOD.ThreeME_V3!G5 * Pond.Inputs!$B5/SUMPRODUCT(WIOD.ThreeME_V3!G$2:G$57,Pond.Inputs!$B$2:$B$57) -> 0 | H5: =WIOD.ThreeME_V3!H5 * Pond.Inputs!$B5/SUMPRODUCT(WIOD.ThreeME_V3!H$2:H$57,Pond.Inputs!$B$2:$B$57) -> 0 | I5: =WIOD.ThreeME_V3!I5 * Pond.Inputs!$B5/SUMPRODUCT(WIOD.ThreeME_V3!I$2:I$57,Pond.Inputs!$B$2:$B$57) -> 0 | ... AG5: =WIOD.ThreeME_V3!AG5 * Pond.Inputs!$B5/SUMPRODUCT(WIOD.ThreeME_V3!AG$2:AG$57,Pond.Inputs!$B$2:$B$57) -> 0
A6: Manufacture of food products, beverages and tobacco products | B6: =WIOD.ThreeME_V3!B6 * Pond.Inputs!$B6/SUMPRODUCT(WIOD.ThreeME_V3!B$2:B$57,Pond.Inputs!$B$2:$B$57) -> 0 | C6: =WIOD.ThreeME_V3!C6 * Pond.Inputs!$B6/SUMPRODUCT(WIOD.ThreeME_V3!C$2:C$57,Pond.Inputs!$B$2:$B$57) -> 0 | D6: =WIOD.ThreeME_V3!D6 * Pond.Inputs!$B6/SUMPRODUCT(WIOD.ThreeME_V3!D$2:D$57,Pond.Inputs!$B$2:$B$57) -> 1 | E6: =WIOD.ThreeME_V3!E6 * Pond.Inputs!$B6/SUMPRODUCT(WIOD.ThreeME_V3!E$2:E$57,Pond.Inputs!$B$2:$B$57) -> 0 | F6: =WIOD.ThreeME_V3!F6 * Pond.Inputs!$B6/SUMPRODUCT(WIOD.ThreeME_V3!F$2:F$57,Pond.Inputs!$B$2:$B$57) -> 0 | G6: =WIOD.ThreeME_V3!G6 * Pond.Inputs!$B6/SUMPRODUCT(WIOD.ThreeME_V3!G$2:G$57,Pond.Inputs!$B$2:$B$57) -> 0 | H6: =WIOD.ThreeME_V3!H6 * Pond.Inputs!$B6/SUMPRODUCT(WIOD.ThreeME_V3!H$2:H$57,Pond.Inputs!$B$2:$B$57) -> 0 | I6: =WIOD.ThreeME_V3!I6 * Pond.Inputs!$B6/SUMPRODUCT(WIOD.ThreeME_V3!I$2:I$57,Pond.Inputs!$B$2:$B$57) -> 0 | ... AG6: =WIOD.ThreeME_V3!AG6 * Pond.Inputs!$B6/SUMPRODUCT(WIOD.ThreeME_V3!AG$2:AG$57,Pond.Inputs!$B$2:$B$57) -> 0
A7: Manufacture of textiles, wearing apparel and leather products | B7: =WIOD.ThreeME_V3!B7 * Pond.Inputs!$B7/SUMPRODUCT(WIOD.ThreeME_V3!B$2:B$57,Pond.Inputs!$B$2:$B$57) -> 0 | C7: =WIOD.ThreeME_V3!C7 * Pond.Inputs!$B7/SUMPRODUCT(WIOD.ThreeME_V3!C$2:C$57,Pond.Inputs!$B$2:$B$57) -> 0 | D7: =WIOD.ThreeME_V3!D7 * Pond.Inputs!$B7/SUMPRODUCT(WIOD.ThreeME_V3!D$2:D$57,Pond.Inputs!$B$2:$B$57) -> 0 | E7: =WIOD.ThreeME_V3!E7 * Pond.Inputs!$B7/SUMPRODUCT(WIOD.ThreeME_V3!E$2:E$57,Pond.Inputs!$B$2:$B$57) -> 0 | F7: =WIOD.ThreeME_V3!F7 * Pond.Inputs!$B7/SUMPRODUCT(WIOD.ThreeME_V3!F$2:F$57,Pond.Inputs!$B$2:$B$57) -> 0 | G7: =WIOD.ThreeME_V3!G7 * Pond.Inputs!$B7/SUMPRODUCT(WIOD.ThreeME_V3!G$2:G$57,Pond.Inputs!$B$2:$B$57) -> 0 | H7: =WIOD.ThreeME_V3!H7 * Pond.Inputs!$B7/SUMPRODUCT(WIOD.ThreeME_V3!H$2:H$57,Pond.Inputs!$B$2:$B$57) -> 0 | I7: =WIOD.ThreeME_V3!I7 * Pond.Inputs!$B7/SUMPRODUCT(WIOD.ThreeME_V3!I$2:I$57,Pond.Inputs!$B$2:$B$57) -> 0 | ... AG7: =WIOD.ThreeME_V3!AG7 * Pond.Inputs!$B7/SUMPRODUCT(WIOD.ThreeME_V3!AG$2:AG$57,Pond.Inputs!$B$2:$B$57) -> 0
A8: Manufacture of wood and of products of wood and cork, except furniture; manufacture of articles of straw and plaiting materials | B8: =WIOD.ThreeME_V3!B8 * Pond.Inputs!$B8/SUMPRODUCT(WIOD.ThreeME_V3!B$2:B$57,Pond.Inputs!$B$2:$B$57) -> 0 | C8: =WIOD.ThreeME_V3!C8 * Pond.Inputs!$B8/SUMPRODUCT(WIOD.ThreeME_V3!C$2:C$57,Pond.Inputs!$B$2:$B$57) -> 0 | D8: =WIOD.ThreeME_V3!D8 * Pond.Inputs!$B8/SUMPRODUCT(WIOD.ThreeME_V3!D$2:D$57,Pond.Inputs!$B$2:$B$57) -> 0 | E8: =WIOD.ThreeME_V3!E8 * Pond.Inputs!$B8/SUMPRODUCT(WIOD.ThreeME_V3!E$2:E$57,Pond.Inputs!$B$2:$B$57) -> 0 | F8: =WIOD.ThreeME_V3!F8 * Pond.Inputs!$B8/SUMPRODUCT(WIOD.ThreeME_V3!F$2:F$57,Pond.Inputs!$B$2:$B$57) -> 0 | G8: =WIOD.ThreeME_V3!G8 * Pond.Inputs!$B8/SUMPRODUCT(WIOD.ThreeME_V3!G$2:G$57,Pond.Inputs!$B$2:$B$57) -> 0 | H8: =WIOD.ThreeME_V3!H8 * Pond.Inputs!$B8/SUMPRODUCT(WIOD.ThreeME_V3!H$2:H$57,Pond.Inputs!$B$2:$B$57) -> 0 | I8: =WIOD.ThreeME_V3!I8 * Pond.Inputs!$B8/SUMPRODUCT(WIOD.ThreeME_V3!I$2:I$57,Pond.Inputs!$B$2:$B$57) -> 0 | ... AG8: =WIOD.ThreeME_V3!AG8 * Pond.Inputs!$B8/SUMPRODUCT(WIOD.ThreeME_V3!AG$2:AG$57,Pond.Inputs!$B$2:$B$57) -> 0
A9: Manufacture of paper and paper products | B9: =WIOD.ThreeME_V3!B9 * Pond.Inputs!$B9/SUMPRODUCT(WIOD.ThreeME_V3!B$2:B$57,Pond.Inputs!$B$2:$B$57) -> 0 | C9: =WIOD.ThreeME_V3!C9 * Pond.Inputs!$B9/SUMPRODUCT(WIOD.ThreeME_V3!C$2:C$57,Pond.Inputs!$B$2:$B$57) -> 0 | D9: =WIOD.ThreeME_V3!D9 * Pond.Inputs!$B9/SUMPRODUCT(WIOD.ThreeME_V3!D$2:D$57,Pond.Inputs!$B$2:$B$57) -> 0 | E9: =WIOD.ThreeME_V3!E9 * Pond.Inputs!$B9/SUMPRODUCT(WIOD.ThreeME_V3!E$2:E$57,Pond.Inputs!$B$2:$B$57) -> 0 | F9: =WIOD.ThreeME_V3!F9 * Pond.Inputs!$B9/SUMPRODUCT(WIOD.ThreeME_V3!F$2:F$57,Pond.Inputs!$B$2:$B$57) -> 0 | G9: =WIOD.ThreeME_V3!G9 * Pond.Inputs!$B9/SUMPRODUCT(WIOD.ThreeME_V3!G$2:G$57,Pond.Inputs!$B$2:$B$57) -> 0.6312901 | H9: =WIOD.ThreeME_V3!H9 * Pond.Inputs!$B9/SUMPRODUCT(WIOD.ThreeME_V3!H$2:H$57,Pond.Inputs!$B$2:$B$57) -> 0 | I9: =WIOD.ThreeME_V3!I9 * Pond.Inputs!$B9/SUMPRODUCT(WIOD.ThreeME_V3!I$2:I$57,Pond.Inputs!$B$2:$B$57) -> 0 | ... AG9: =WIOD.ThreeME_V3!AG9 * Pond.Inputs!$B9/SUMPRODUCT(WIOD.ThreeME_V3!AG$2:AG$57,Pond.Inputs!$B$2:$B$57) -> 0
A10: Printing and reproduction of recorded media | B10: =WIOD.ThreeME_V3!B10 * Pond.Inputs!$B10/SUMPRODUCT(WIOD.ThreeME_V3!B$2:B$57,Pond.Inputs!$B$2:$B$57) -> 0 | C10: =WIOD.ThreeME_V3!C10 * Pond.Inputs!$B10/SUMPRODUCT(WIOD.ThreeME_V3!C$2:C$57,Pond.Inputs!$B$2:$B$57) -> 0 | D10: =WIOD.ThreeME_V3!D10 * Pond.Inputs!$B10/SUMPRODUCT(WIOD.ThreeME_V3!D$2:D$57,Pond.Inputs!$B$2:$B$57) -> 0 | E10: =WIOD.ThreeME_V3!E10 * Pond.Inputs!$B10/SUMPRODUCT(WIOD.ThreeME_V3!E$2:E$57,Pond.Inputs!$B$2:$B$57) -> 0 | F10: =WIOD.ThreeME_V3!F10 * Pond.Inputs!$B10/SUMPRODUCT(WIOD.ThreeME_V3!F$2:F$57,Pond.Inputs!$B$2:$B$57) -> 0 | G10: =WIOD.ThreeME_V3!G10 * Pond.Inputs!$B10/SUMPRODUCT(WIOD.ThreeME_V3!G$2:G$57,Pond.Inputs!$B$2:$B$57) -> 0.3687099 | H10: =WIOD.ThreeME_V3!H10 * Pond.Inputs!$B10/SUMPRODUCT(WIOD.ThreeME_V3!H$2:H$57,Pond.Inputs!$B$2:$B$57) -> 0 | I10: =WIOD.ThreeME_V3!I10 * Pond.Inputs!$B10/SUMPRODUCT(WIOD.ThreeME_V3!I$2:I$57,Pond.Inputs!$B$2:$B$57) -> 0 | ... AG10: =WIOD.ThreeME_V3!AG10 * Pond.Inputs!$B10/SUMPRODUCT(WIOD.ThreeME_V3!AG$2:AG$57,Pond.Inputs!$B$2:$B$57) -> 0
A11: Manufacture of coke and refined petroleum products | B11: =WIOD.ThreeME_V3!B11 * Pond.Inputs!$B11/SUMPRODUCT(WIOD.ThreeME_V3!B$2:B$57,Pond.Inputs!$B$2:$B$57) -> 0 | C11: =WIOD.ThreeME_V3!C11 * Pond.Inputs!$B11/SUMPRODUCT(WIOD.ThreeME_V3!C$2:C$57,Pond.Inputs!$B$2:$B$57) -> 0 | D11: =WIOD.ThreeME_V3!D11 * Pond.Inputs!$B11/SUMPRODUCT(WIOD.ThreeME_V3!D$2:D$57,Pond.Inputs!$B$2:$B$57) -> 0 | E11: =WIOD.ThreeME_V3!E11 * Pond.Inputs!$B11/SUMPRODUCT(WIOD.ThreeME_V3!E$2:E$57,Pond.Inputs!$B$2:$B$57) -> 0 | F11: =WIOD.ThreeME_V3!F11 * Pond.Inputs!$B11/SUMPRODUCT(WIOD.ThreeME_V3!F$2:F$57,Pond.Inputs!$B$2:$B$57) -> 0 | G11: =WIOD.ThreeME_V3!G11 * Pond.Inputs!$B11/SUMPRODUCT(WIOD.ThreeME_V3!G$2:G$57,Pond.Inputs!$B$2:$B$57) -> 0 | H11: =WIOD.ThreeME_V3!H11 * Pond.Inputs!$B11/SUMPRODUCT(WIOD.ThreeME_V3!H$2:H$57,Pond.Inputs!$B$2:$B$57) -> 0 | I11: =WIOD.ThreeME_V3!I11 * Pond.Inputs!$B11/SUMPRODUCT(WIOD.ThreeME_V3!I$2:I$57,Pond.Inputs!$B$2:$B$57) -> 0 | ... AG11: =WIOD.ThreeME_V3!AG11 * Pond.Inputs!$B11/SUMPRODUCT(WIOD.ThreeME_V3!AG$2:AG$57,Pond.Inputs!$B$2:$B$57) -> 0
A12: Manufacture of chemicals and chemical products | B12: =WIOD.ThreeME_V3!B12 * Pond.Inputs!$B12/SUMPRODUCT(WIOD.ThreeME_V3!B$2:B$57,Pond.Inputs!$B$2:$B$57) -> 0 | C12: =WIOD.ThreeME_V3!C12 * Pond.Inputs!$B12/SUMPRODUCT(WIOD.ThreeME_V3!C$2:C$57,Pond.Inputs!$B$2:$B$57) -> 0 | D12: =WIOD.ThreeME_V3!D12 * Pond.Inputs!$B12/SUMPRODUCT(WIOD.ThreeME_V3!D$2:D$57,Pond.Inputs!$B$2:$B$57) -> 0 | E12: =WIOD.ThreeME_V3!E12 * Pond.Inputs!$B12/SUMPRODUCT(WIOD.ThreeME_V3!E$2:E$57,Pond.Inputs!$B$2:$B$57) -> 0 | F12: =WIOD.ThreeME_V3!F12 * Pond.Inputs!$B12/SUMPRODUCT(WIOD.ThreeME_V3!F$2:F$57,Pond.Inputs!$B$2:$B$57) -> 0 | G12: =WIOD.ThreeME_V3!G12 * Pond.Inputs!$B12/SUMPRODUCT(WIOD.ThreeME_V3!G$2:G$57,Pond.Inputs!$B$2:$B$57) -> 0 | H12: =WIOD.ThreeME_V3!H12 * Pond.Inputs!$B12/SUMPRODUCT(WIOD.ThreeME_V3!H$2:H$57,Pond.Inputs!$B$2:$B$57) -> 0.73082346 | I12: =WIOD.ThreeME_V3!I12 * Pond.Inputs!$B12/SUMPRODUCT(WIOD.ThreeME_V3!I$2:I$57,Pond.Inputs!$B$2:$B$57) -> 0 | ... AG12: =WIOD.ThreeME_V3!AG12 * Pond.Inputs!$B12/SUMPRODUCT(WIOD.ThreeME_V3!AG$2:AG$57,Pond.Inputs!$B$2:$B$57) -> 0
A13: Manufacture of basic pharmaceutical products and pharmaceutical preparations | B13: =WIOD.ThreeME_V3!B13 * Pond.Inputs!$B13/SUMPRODUCT(WIOD.ThreeME_V3!B$2:B$57,Pond.Inputs!$B$2:$B$57) -> 0 | C13: =WIOD.ThreeME_V3!C13 * Pond.Inputs!$B13/SUMPRODUCT(WIOD.ThreeME_V3!C$2:C$57,Pond.Inputs!$B$2:$B$57) -> 0 | D13: =WIOD.ThreeME_V3!D13 * Pond.Inputs!$B13/SUMPRODUCT(WIOD.ThreeME_V3!D$2:D$57,Pond.Inputs!$B$2:$B$57) -> 0 | E13: =WIOD.ThreeME_V3!E13 * Pond.Inputs!$B13/SUMPRODUCT(WIOD.ThreeME_V3!E$2:E$57,Pond.Inputs!$B$2:$B$57) -> 0 | F13: =WIOD.ThreeME_V3!F13 * Pond.Inputs!$B13/SUMPRODUCT(WIOD.ThreeME_V3!F$2:F$57,Pond.Inputs!$B$2:$B$57) -> 0 | G13: =WIOD.ThreeME_V3!G13 * Pond.Inputs!$B13/SUMPRODUCT(WIOD.ThreeME_V3!G$2:G$57,Pond.Inputs!$B$2:$B$57) -> 0 | H13: =WIOD.ThreeME_V3!H13 * Pond.Inputs!$B13/SUMPRODUCT(WIOD.ThreeME_V3!H$2:H$57,Pond.Inputs!$B$2:$B$57) -> 0.26917654 | I13: =WIOD.ThreeME_V3!I13 * Pond.Inputs!$B13/SUMPRODUCT(WIOD.ThreeME_V3!I$2:I$57,Pond.Inputs!$B$2:$B$57) -> 0 | ... AG13: =WIOD.ThreeME_V3!AG13 * Pond.Inputs!$B13/SUMPRODUCT(WIOD.ThreeME_V3!AG$2:AG$57,Pond.Inputs!$B$2:$B$57) -> 0
... A57: Activities of extraterritorial organizations and bodies | B57: =WIOD.ThreeME_V3!B57 * Pond.Inputs!$B57/SUMPRODUCT(WIOD.ThreeME_V3!B$2:B$57,Pond.Inputs!$B$2:$B$57) -> 0 | C57: =WIOD.ThreeME_V3!C57 * Pond.Inputs!$B57/SUMPRODUCT(WIOD.ThreeME_V3!C$2:C$57,Pond.Inputs!$B$2:$B$57) -> 0 | D57: =WIOD.ThreeME_V3!D57 * Pond.Inputs!$B57/SUMPRODUCT(WIOD.ThreeME_V3!D$2:D$57,Pond.Inputs!$B$2:$B$57) -> 0 | E57: =WIOD.ThreeME_V3!E57 * Pond.Inputs!$B57/SUMPRODUCT(WIOD.ThreeME_V3!E$2:E$57,Pond.Inputs!$B$2:$B$57) -> 0 | F57: =WIOD.ThreeME_V3!F57 * Pond.Inputs!$B57/SUMPRODUCT(WIOD.ThreeME_V3!F$2:F$57,Pond.Inputs!$B$2:$B$57) -> 0 | G57: =WIOD.ThreeME_V3!G57 * Pond.Inputs!$B57/SUMPRODUCT(WIOD.ThreeME_V3!G$2:G$57,Pond.Inputs!$B$2:$B$57) -> 0 | H57: =WIOD.ThreeME_V3!H57 * Pond.Inputs!$B57/SUMPRODUCT(WIOD.ThreeME_V3!H$2:H$57,Pond.Inputs!$B$2:$B$57) -> 0 | I57: =WIOD.ThreeME_V3!I57 * Pond.Inputs!$B57/SUMPRODUCT(WIOD.ThreeME_V3!I$2:I$57,Pond.Inputs!$B$2:$B$57) -> 0 | ... AG57: =WIOD.ThreeME_V3!AG57 * Pond.Inputs!$B57/SUMPRODUCT(WIOD.ThreeME_V3!AG$2:AG$57,Pond.Inputs!$B$2:$B$57) -> 0

Sheet WIOD.NAF17.pond
B1: Agriculture, sylviculture et pêche | C1: Industries extractives, énergie, eau, gestion des déchets et dépollution | D1: Fabrication de denrées alimentaires, de boissons et de produits à base de tabac | E1: Cokéfaction et raffinage | F1: Fabrication d'équipements électriques, électroniques, informatiques ; fabrication de machines | G1: Fabrication de matériels de transport | H1: Fabrication d'autres produits industriels | I1: Construction | J1: Commerce ; réparation d'automobiles et de motocycles | K1: Transports et entreposage | L1: Hébergement et restauration | M1: Information et communication | N1: Activités financières et d'assurance | O1: Activités immobilières | P1: Activités spécialisées, scientifiques et techniques et activités de services administratifs et de soutien | Q1: Administration publique, enseignement, santé humaine et action sociale | R1: Autres activités de services
A2: Crop and animal production, hunting and related service activities | B2: =WIOD.NAF17!B2 * Pond.Inputs!$B2/SUMPRODUCT(WIOD.NAF17!B$2:B$57,Pond.Inputs!$B$2:$B$57) -> 0.91518806 | C2: =WIOD.NAF17!C2 * Pond.Inputs!$B2/SUMPRODUCT(WIOD.NAF17!C$2:C$57,Pond.Inputs!$B$2:$B$57) -> 0 | D2: =WIOD.NAF17!D2 * Pond.Inputs!$B2/SUMPRODUCT(WIOD.NAF17!D$2:D$57,Pond.Inputs!$B$2:$B$57) -> 0 | E2: =WIOD.NAF17!E2 * Pond.Inputs!$B2/SUMPRODUCT(WIOD.NAF17!E$2:E$57,Pond.Inputs!$B$2:$B$57) -> 0 | F2: =WIOD.NAF17!F2 * Pond.Inputs!$B2/SUMPRODUCT(WIOD.NAF17!F$2:F$57,Pond.Inputs!$B$2:$B$57) -> 0 | G2: =WIOD.NAF17!G2 * Pond.Inputs!$B2/SUMPRODUCT(WIOD.NAF17!G$2:G$57,Pond.Inputs!$B$2:$B$57) -> 0 | H2: =WIOD.NAF17!H2 * Pond.Inputs!$B2/SUMPRODUCT(WIOD.NAF17!H$2:H$57,Pond.Inputs!$B$2:$B$57) -> 0 | I2: =WIOD.NAF17!I2 * Pond.Inputs!$B2/SUMPRODUCT(WIOD.NAF17!I$2:I$57,Pond.Inputs!$B$2:$B$57) -> 0 | ... R2: =WIOD.NAF17!R2 * Pond.Inputs!$B2/SUMPRODUCT(WIOD.NAF17!R$2:R$57,Pond.Inputs!$B$2:$B$57) -> 0
A3: Forestry and logging | B3: =WIOD.NAF17!B3 * Pond.Inputs!$B3/SUMPRODUCT(WIOD.NAF17!B$2:B$57,Pond.Inputs!$B$2:$B$57) -> 0.05831254 | C3: =WIOD.NAF17!C3 * Pond.Inputs!$B3/SUMPRODUCT(WIOD.NAF17!C$2:C$57,Pond.Inputs!$B$2:$B$57) -> 0 | D3: =WIOD.NAF17!D3 * Pond.Inputs!$B3/SUMPRODUCT(WIOD.NAF17!D$2:D$57,Pond.Inputs!$B$2:$B$57) -> 0 | E3: =WIOD.NAF17!E3 * Pond.Inputs!$B3/SUMPRODUCT(WIOD.NAF17!E$2:E$57,Pond.Inputs!$B$2:$B$57) -> 0 | F3: =WIOD.NAF17!F3 * Pond.Inputs!$B3/SUMPRODUCT(WIOD.NAF17!F$2:F$57,Pond.Inputs!$B$2:$B$57) -> 0 | G3: =WIOD.NAF17!G3 * Pond.Inputs!$B3/SUMPRODUCT(WIOD.NAF17!G$2:G$57,Pond.Inputs!$B$2:$B$57) -> 0 | H3: =WIOD.NAF17!H3 * Pond.Inputs!$B3/SUMPRODUCT(WIOD.NAF17!H$2:H$57,Pond.Inputs!$B$2:$B$57) -> 0 | I3: =WIOD.NAF17!I3 * Pond.Inputs!$B3/SUMPRODUCT(WIOD.NAF17!I$2:I$57,Pond.Inputs!$B$2:$B$57) -> 0 | ... R3: =WIOD.NAF17!R3 * Pond.Inputs!$B3/SUMPRODUCT(WIOD.NAF17!R$2:R$57,Pond.Inputs!$B$2:$B$57) -> 0
A4: Fishing and aquaculture | B4: =WIOD.NAF17!B4 * Pond.Inputs!$B4/SUMPRODUCT(WIOD.NAF17!B$2:B$57,Pond.Inputs!$B$2:$B$57) -> 0.026499399 | C4: =WIOD.NAF17!C4 * Pond.Inputs!$B4/SUMPRODUCT(WIOD.NAF17!C$2:C$57,Pond.Inputs!$B$2:$B$57) -> 0 | D4: =WIOD.NAF17!D4 * Pond.Inputs!$B4/SUMPRODUCT(WIOD.NAF17!D$2:D$57,Pond.Inputs!$B$2:$B$57) -> 0 | E4: =WIOD.NAF17!E4 * Pond.Inputs!$B4/SUMPRODUCT(WIOD.NAF17!E$2:E$57,Pond.Inputs!$B$2:$B$57) -> 0 | F4: =WIOD.NAF17!F4 * Pond.Inputs!$B4/SUMPRODUCT(WIOD.NAF17!F$2:F$57,Pond.Inputs!$B$2:$B$57) -> 0 | G4: =WIOD.NAF17!G4 * Pond.Inputs!$B4/SUMPRODUCT(WIOD.NAF17!G$2:G$57,Pond.Inputs!$B$2:$B$57) -> 0 | H4: =WIOD.NAF17!H4 * Pond.Inputs!$B4/SUMPRODUCT(WIOD.NAF17!H$2:H$57,Pond.Inputs!$B$2:$B$57) -> 0 | I4: =WIOD.NAF17!I4 * Pond.Inputs!$B4/SUMPRODUCT(WIOD.NAF17!I$2:I$57,Pond.Inputs!$B$2:$B$57) -> 0 | ... R4: =WIOD.NAF17!R4 * Pond.Inputs!$B4/SUMPRODUCT(WIOD.NAF17!R$2:R$57,Pond.Inputs!$B$2:$B$57) -> 0
A5: Mining and quarrying | B5: =WIOD.NAF17!B5 * Pond.Inputs!$B5/SUMPRODUCT(WIOD.NAF17!B$2:B$57,Pond.Inputs!$B$2:$B$57) -> 0 | C5: =WIOD.NAF17!C5 * Pond.Inputs!$B5/SUMPRODUCT(WIOD.NAF17!C$2:C$57,Pond.Inputs!$B$2:$B$57) -> 0.036096266 | D5: =WIOD.NAF17!D5 * Pond.Inputs!$B5/SUMPRODUCT(WIOD.NAF17!D$2:D$57,Pond.Inputs!$B$2:$B$57) -> 0 | E5: =WIOD.NAF17!E5 * Pond.Inputs!$B5/SUMPRODUCT(WIOD.NAF17!E$2:E$57,Pond.Inputs!$B$2:$B$57) -> 0 | F5: =WIOD.NAF17!F5 * Pond.Inputs!$B5/SUMPRODUCT(WIOD.NAF17!F$2:F$57,Pond.Inputs!$B$2:$B$57) -> 0 | G5: =WIOD.NAF17!G5 * Pond.Inputs!$B5/SUMPRODUCT(WIOD.NAF17!G$2:G$57,Pond.Inputs!$B$2:$B$57) -> 0 | H5: =WIOD.NAF17!H5 * Pond.Inputs!$B5/SUMPRODUCT(WIOD.NAF17!H$2:H$57,Pond.Inputs!$B$2:$B$57) -> 0 | I5: =WIOD.NAF17!I5 * Pond.Inputs!$B5/SUMPRODUCT(WIOD.NAF17!I$2:I$57,Pond.Inputs!$B$2:$B$57) -> 0 | ... R5: =WIOD.NAF17!R5 * Pond.Inputs!$B5/SUMPRODUCT(WIOD.NAF17!R$2:R$57,Pond.Inputs!$B$2:$B$57) -> 0
A6: Manufacture of food products, beverages and tobacco products | B6: =WIOD.NAF17!B6 * Pond.Inputs!$B6/SUMPRODUCT(WIOD.NAF17!B$2:B$57,Pond.Inputs!$B$2:$B$57) -> 0 | C6: =WIOD.NAF17!C6 * Pond.Inputs!$B6/SUMPRODUCT(WIOD.NAF17!C$2:C$57,Pond.Inputs!$B$2:$B$57) -> 0 | D6: =WIOD.NAF17!D6 * Pond.Inputs!$B6/SUMPRODUCT(WIOD.NAF17!D$2:D$57,Pond.Inputs!$B$2:$B$57) -> 1 | E6: =WIOD.NAF17!E6 * Pond.Inputs!$B6/SUMPRODUCT(WIOD.NAF17!E$2:E$57,Pond.Inputs!$B$2:$B$57) -> 0 | F6: =WIOD.NAF17!F6 * Pond.Inputs!$B6/SUMPRODUCT(WIOD.NAF17!F$2:F$57,Pond.Inputs!$B$2:$B$57) -> 0 | G6: =WIOD.NAF17!G6 * Pond.Inputs!$B6/SUMPRODUCT(WIOD.NAF17!G$2:G$57,Pond.Inputs!$B$2:$B$57) -> 0 | H6: =WIOD.NAF17!H6 * Pond.Inputs!$B6/SUMPRODUCT(WIOD.NAF17!H$2:H$57,Pond.Inputs!$B$2:$B$57) -> 0 | I6: =WIOD.NAF17!I6 * Pond.Inputs!$B6/SUMPRODUCT(WIOD.NAF17!I$2:I$57,Pond.Inputs!$B$2:$B$57) -> 0 | ... R6: =WIOD.NAF17!R6 * Pond.Inputs!$B6/SUMPRODUCT(WIOD.NAF17!R$2:R$57,Pond.Inputs!$B$2:$B$57) -> 0
A7: Manufacture of textiles, wearing apparel and leather products | B7: =WIOD.NAF17!B7 * Pond.Inputs!$B7/SUMPRODUCT(WIOD.NAF17!B$2:B$57,Pond.Inputs!$B$2:$B$57) -> 0 | C7: =WIOD.NAF17!C7 * Pond.Inputs!$B7/SUMPRODUCT(WIOD.NAF17!C$2:C$57,Pond.Inputs!$B$2:$B$57) -> 0 | D7: =WIOD.NAF17!D7 * Pond.Inputs!$B7/SUMPRODUCT(WIOD.NAF17!D$2:D$57,Pond.Inputs!$B$2:$B$57) -> 0 | E7: =WIOD.NAF17!E7 * Pond.Inputs!$B7/SUMPRODUCT(WIOD.NAF17!E$2:E$57,Pond.Inputs!$B$2:$B$57) -> 0 | F7: =WIOD.NAF17!F7 * Pond.Inputs!$B7/SUMPRODUCT(WIOD.NAF17!F$2:F$57,Pond.Inputs!$B$2:$B$57) -> 0 | G7: =WIOD.NAF17!G7 * Pond.Inputs!$B7/SUMPRODUCT(WIOD.NAF17!G$2:G$57,Pond.Inputs!$B$2:$B$57) -> 0 | H7: =WIOD.NAF17!H7 * Pond.Inputs!$B7/SUMPRODUCT(WIOD.NAF17!H$2:H$57,Pond.Inputs!$B$2:$B$57) -> 0.048090895 | I7: =WIOD.NAF17!I7 * Pond.Inputs!$B7/SUMPRODUCT(WIOD.NAF17!I$2:I$57,Pond.Inputs!$B$2:$B$57) -> 0 | ... R7: =WIOD.NAF17!R7 * Pond.Inputs!$B7/SUMPRODUCT(WIOD.NAF17!R$2:R$57,Pond.Inputs!$B$2:$B$57) -> 0
A8: Manufacture of wood and of products of wood and cork, except furniture; manufacture of articles of straw and plaiting materials | B8: =WIOD.NAF17!B8 * Pond.Inputs!$B8/SUMPRODUCT(WIOD.NAF17!B$2:B$57,Pond.Inputs!$B$2:$B$57) -> 0 | C8: =WIOD.NAF17!C8 * Pond.Inputs!$B8/SUMPRODUCT(WIOD.NAF17!C$2:C$57,Pond.Inputs!$B$2:$B$57) -> 0 | D8: =WIOD.NAF17!D8 * Pond.Inputs!$B8/SUMPRODUCT(WIOD.NAF17!D$2:D$57,Pond.Inputs!$B$2:$B$57) -> 0 | E8: =WIOD.NAF17!E8 * Pond.Inputs!$B8/SUMPRODUCT(WIOD.NAF17!E$2:E$57,Pond.Inputs!$B$2:$B$57) -> 0 | F8: =WIOD.NAF17!F8 * Pond.Inputs!$B8/SUMPRODUCT(WIOD.NAF17!F$2:F$57,Pond.Inputs!$B$2:$B$57) -> 0 | G8: =WIOD.NAF17!G8 * Pond.Inputs!$B8/SUMPRODUCT(WIOD.NAF17!G$2:G$57,Pond.Inputs!$B$2:$B$57) -> 0 | H8: =WIOD.NAF17!H8 * Pond.Inputs!$B8/SUMPRODUCT(WIOD.NAF17!H$2:H$57,Pond.Inputs!$B$2:$B$57) -> 0.030509055 | I8: =WIOD.NAF17!I8 * Pond.Inputs!$B8/SUMPRODUCT(WIOD.NAF17!I$2:I$57,Pond.Inputs!$B$2:$B$57) -> 0 | ... R8: =WIOD.NAF17!R8 * Pond.Inputs!$B8/SUMPRODUCT(WIOD.NAF17!R$2:R$57,Pond.Inputs!$B$2:$B$57) -> 0
A9: Manufacture of paper and paper products | B9: =WIOD.NAF17!B9 * Pond.Inputs!$B9/SUMPRODUCT(WIOD.NAF17!B$2:B$57,Pond.Inputs!$B$2:$B$57) -> 0 | C9: =WIOD.NAF17!C9 * Pond.Inputs!$B9/SUMPRODUCT(WIOD.NAF17!C$2:C$57,Pond.Inputs!$B$2:$B$57) -> 0 | D9: =WIOD.NAF17!D9 * Pond.Inputs!$B9/SUMPRODUCT(WIOD.NAF17!D$2:D$57,Pond.Inputs!$B$2:$B$57) -> 0 | E9: =WIOD.NAF17!E9 * Pond.Inputs!$B9/SUMPRODUCT(WIOD.NAF17!E$2:E$57,Pond.Inputs!$B$2:$B$57) -> 0 | F9: =WIOD.NAF17!F9 * Pond.Inputs!$B9/SUMPRODUCT(WIOD.NAF17!F$2:F$57,Pond.Inputs!$B$2:$B$57) -> 0 | G9: =WIOD.NAF17!G9 * Pond.Inputs!$B9/SUMPRODUCT(WIOD.NAF17!G$2:G$57,Pond.Inputs!$B$2:$B$57) -> 0 | H9: =WIOD.NAF17!H9 * Pond.Inputs!$B9/SUMPRODUCT(WIOD.NAF17!H$2:H$57,Pond.Inputs!$B$2:$B$57) -> 0.048241521 | I9: =WIOD.NAF17!I9 * Pond.Inputs!$B9/SUMPRODUCT(WIOD.NAF17!I$2:I$57,Pond.Inputs!$B$2:$B$57) -> 0 | ... R9: =WIOD.NAF17!R9 * Pond.Inputs!$B9/SUMPRODUCT(WIOD.NAF17!R$2:R$57,Pond.Inputs!$B$2:$B$57) -> 0
A10: Printing and reproduction of recorded media | B10: =WIOD.NAF17!B10 * Pond.Inputs!$B10/SUMPRODUCT(WIOD.NAF17!B$2:B$57,Pond.Inputs!$B$2:$B$57) -> 0 | C10: =WIOD.NAF17!C10 * Pond.Inputs!$B10/SUMPRODUCT(WIOD.NAF17!C$2:C$57,Pond.Inputs!$B$2:$B$57) -> 0 | D10: =WIOD.NAF17!D10 * Pond.Inputs!$B10/SUMPRODUCT(WIOD.NAF17!D$2:D$57,Pond.Inputs!$B$2:$B$57) -> 0 | E10: =WIOD.NAF17!E10 * Pond.Inputs!$B10/SUMPRODUCT(WIOD.NAF17!E$2:E$57,Pond.Inputs!$B$2:$B$57) -> 0 | F10: =WIOD.NAF17!F10 * Pond.Inputs!$B10/SUMPRODUCT(WIOD.NAF17!F$2:F$57,Pond.Inputs!$B$2:$B$57) -> 0.10622662 | G10: =WIOD.NAF17!G10 * Pond.Inputs!$B10/SUMPRODUCT(WIOD.NAF17!G$2:G$57,Pond.Inputs!$B$2:$B$57) -> 0 | H10: =WIOD.NAF17!H10 * Pond.Inputs!$B10/SUMPRODUCT(WIOD.NAF17!H$2:H$57,Pond.Inputs!$B$2:$B$57) -> 0 | I10: =WIOD.NAF17!I10 * Pond.Inputs!$B10/SUMPRODUCT(WIOD.NAF17!I$2:I$57,Pond.Inputs!$B$2:$B$57) -> 0 | ... R10: =WIOD.NAF17!R10 * Pond.Inputs!$B10/SUMPRODUCT(WIOD.NAF17!R$2:R$57,Pond.Inputs!$B$2:$B$57) -> 0
A11: Manufacture of coke and refined petroleum products | B11: =WIOD.NAF17!B11 * Pond.Inputs!$B11/SUMPRODUCT(WIOD.NAF17!B$2:B$57,Pond.Inputs!$B$2:$B$57) -> 0 | C11: =WIOD.NAF17!C11 * Pond.Inputs!$B11/SUMPRODUCT(WIOD.NAF17!C$2:C$57,Pond.Inputs!$B$2:$B$57) -> 0 | D11: =WIOD.NAF17!D11 * Pond.Inputs!$B11/SUMPRODUCT(WIOD.NAF17!D$2:D$57,Pond.Inputs!$B$2:$B$57) -> 0 | E11: =WIOD.NAF17!E11 * Pond.Inputs!$B11/SUMPRODUCT(WIOD.NAF17!E$2:E$57,Pond.Inputs!$B$2:$B$57) -> 1 | F11: =WIOD.NAF17!F11 * Pond.Inputs!$B11/SUMPRODUCT(WIOD.NAF17!F$2:F$57,Pond.Inputs!$B$2:$B$57) -> 0 | G11: =WIOD.NAF17!G11 * Pond.Inputs!$B11/SUMPRODUCT(WIOD.NAF17!G$2:G$57,Pond.Inputs!$B$2:$B$57) -> 0 | H11: =WIOD.NAF17!H11 * Pond.Inputs!$B11/SUMPRODUCT(WIOD.NAF17!H$2:H$57,Pond.Inputs!$B$2:$B$57) -> 0 | I11: =WIOD.NAF17!I11 * Pond.Inputs!$B11/SUMPRODUCT(WIOD.NAF17!I$2:I$57,Pond.Inputs!$B$2:$B$57) -> 0 | ... R11: =WIOD.NAF17!R11 * Pond.Inputs!$B11/SUMPRODUCT(WIOD.NAF17!R$2:R$57,Pond.Inputs!$B$2:$B$57) -> 0
A12: Manufacture of chemicals and chemical products | B12: =WIOD.NAF17!B12 * Pond.Inputs!$B12/SUMPRODUCT(WIOD.NAF17!B$2:B$57,Pond.Inputs!$B$2:$B$57) -> 0 | C12: =WIOD.NAF17!C12 * Pond.Inputs!$B12/SUMPRODUCT(WIOD.NAF17!C$2:C$57,Pond.Inputs!$B$2:$B$57) -> 0 | D12: =WIOD.NAF17!D12 * Pond.Inputs!$B12/SUMPRODUCT(WIOD.NAF17!D$2:D$57,Pond.Inputs!$B$2:$B$57) -> 0 | E12: =WIOD.NAF17!E12 * Pond.Inputs!$B12/SUMPRODUCT(WIOD.NAF17!E$2:E$57,Pond.Inputs!$B$2:$B$57) -> 0 | F12: =WIOD.NAF17!F12 * Pond.Inputs!$B12/SUMPRODUCT(WIOD.NAF17!F$2:F$57,Pond.Inputs!$B$2:$B$57) -> 0 | G12: =WIOD.NAF17!G12 * Pond.Inputs!$B12/SUMPRODUCT(WIOD.NAF17!G$2:G$57,Pond.Inputs!$B$2:$B$57) -> 0 | H12: =WIOD.NAF17!H12 * Pond.Inputs!$B12/SUMPRODUCT(WIOD.NAF17!H$2:H$57,Pond.Inputs!$B$2:$B$57) -> 0.19899996 | I12: =WIOD.NAF17!I12 * Pond.Inputs!$B12/SUMPRODUCT(WIOD.NAF17!I$2:I$57,Pond.Inputs!$B$2:$B$57) -> 0 | ... R12: =WIOD.NAF17!R12 * Pond.Inputs!$B12/SUMPRODUCT(WIOD.NAF17!R$2:R$57,Pond.Inputs!$B$2:$B$57) -> 0
A13: Manufacture of basic pharmaceutical products and pharmaceutical preparations | B13: =WIOD.NAF17!B13 * Pond.Inputs!$B13/SUMPRODUCT(WIOD.NAF17!B$2:B$57,Pond.Inputs!$B$2:$B$57) -> 0 | C13: =WIOD.NAF17!C13 * Pond.Inputs!$B13/SUMPRODUCT(WIOD.NAF17!C$2:C$57,Pond.Inputs!$B$2:$B$57) -> 0 | D13: =WIOD.NAF17!D13 * Pond.Inputs!$B13/SUMPRODUCT(WIOD.NAF17!D$2:D$57,Pond.Inputs!$B$2:$B$57) -> 0 | E13: =WIOD.NAF17!E13 * Pond.Inputs!$B13/SUMPRODUCT(WIOD.NAF17!E$2:E$57,Pond.Inputs!$B$2:$B$57) -> 0 | F13: =WIOD.NAF17!F13 * Pond.Inputs!$B13/SUMPRODUCT(WIOD.NAF17!F$2:F$57,Pond.Inputs!$B$2:$B$57) -> 0 | G13: =WIOD.NAF17!G13 * Pond.Inputs!$B13/SUMPRODUCT(WIOD.NAF17!G$2:G$57,Pond.Inputs!$B$2:$B$57) -> 0 | H13: =WIOD.NAF17!H13 * Pond.Inputs!$B13/SUMPRODUCT(WIOD.NAF17!H$2:H$57,Pond.Inputs!$B$2:$B$57) -> 0.073295569 | I13: =WIOD.NAF17!I13 * Pond.Inputs!$B13/SUMPRODUCT(WIOD.NAF17!I$2:I$57,Pond.Inputs!$B$2:$B$57) -> 0 | ... R13: =WIOD.NAF17!R13 * Pond.Inputs!$B13/SUMPRODUCT(WIOD.NAF17!R$2:R$57,Pond.Inputs!$B$2:$B$57) -> 0
... A57: Activities of extraterritorial organizations and bodies | B57: =WIOD.NAF17!B57 * Pond.Inputs!$B57/SUMPRODUCT(WIOD.NAF17!B$2:B$57,Pond.Inputs!$B$2:$B$57) -> 0 | C57: =WIOD.NAF17!C57 * Pond.Inputs!$B57/SUMPRODUCT(WIOD.NAF17!C$2:C$57,Pond.Inputs!$B$2:$B$57) -> 0 | D57: =WIOD.NAF17!D57 * Pond.Inputs!$B57/SUMPRODUCT(WIOD.NAF17!D$2:D$57,Pond.Inputs!$B$2:$B$57) -> 0 | E57: =WIOD.NAF17!E57 * Pond.Inputs!$B57/SUMPRODUCT(WIOD.NAF17!E$2:E$57,Pond.Inputs!$B$2:$B$57) -> 0 | F57: =WIOD.NAF17!F57 * Pond.Inputs!$B57/SUMPRODUCT(WIOD.NAF17!F$2:F$57,Pond.Inputs!$B$2:$B$57) -> 0 | G57: =WIOD.NAF17!G57 * Pond.Inputs!$B57/SUMPRODUCT(WIOD.NAF17!G$2:G$57,Pond.Inputs!$B$2:$B$57) -> 0 | H57: =WIOD.NAF17!H57 * Pond.Inputs!$B57/SUMPRODUCT(WIOD.NAF17!H$2:H$57,Pond.Inputs!$B$2:$B$57) -> 0 | I57: =WIOD.NAF17!I57 * Pond.Inputs!$B57/SUMPRODUCT(WIOD.NAF17!I$2:I$57,Pond.Inputs!$B$2:$B$57) -> 0 | ... R57: =WIOD.NAF17!R57 * Pond.Inputs!$B57/SUMPRODUCT(WIOD.NAF17!R$2:R$57,Pond.Inputs!$B$2:$B$57) -> 0

Sheet Elasticities_ThreeME_V3
B1: KL | C1: KE | D1: KM | E1: LE | F1: LM | G1: EM
A2: Agriculture and fishing | B2: {=TRANSPOSE(MMULT(TRANSPOSE(Elasticities_WIOD!C2:H57),WIOD.ThreeME_V3!B2:AG57))} -> 1.3532678 | C2: -1.2190107 | D2: -0.74856674 | E2: -26.821276 | F2: -0.36277674 | G2: 17.814677
A3: Forestry | B3: -0.64417518 | C3: 1.8972875 | D3: -0.62980055 | E3: 0.75269494 | F3: -0.41463909 | G3: -6.0545741
A4: Manufacture of food products and beverages | B4: -0.40614676 | C4: -1.5187354 | D4: -0.62635141 | E4: -2.0896776 | F4: -0.56421324 | G4: -0.38968347
A5: Manufacture of motor vehicles, trailers and semi-trailers | B5: 0.011517846 | C5: 0.022248907 | D5: 0.0017644513 | E5: -4.5883197 | F5: -2.2692635 | G5: -3.3413199
A6: Manufacture of glass, ceramic and ciment products | B6: -0.8745595 | C6: -0.8557464 | D6: -0.6520436 | E6: 0.5985235 | F6: -0.41465782 | G6: -1.4270128
A7: Manufacture of paper and paperboard | B7: -1.534536 | C7: -4.4380852 | D7: -2.3821869 | E7: 2.8824855 | F7: -0.66299289 | G7: -0.024542726
A8: Manufacture of chemicals | B8: -1.0172523 | C8: -1.5502188 | D8: -2.2097207 | E8: -0.70225743 | F8: -0.85283663 | G8: -3.6041733
A9: Manufacture of plastics products | B9: -0.70951635 | C9: -0.6107688 | D9: -0.86938428 | E9: 2.0583658 | F9: -0.69568366 | G9: -2.3974471
A10: Metallurgy | B10: -1.738366 | C10: -1.6396056 | D10: -1.3135533 | E10: 0.29610008 | F10: -0.46487485 | G10: -2.1376487
A11: Manufacture of other goods for industry | B11: -1.6082716 | C11: -2.8286595 | D11: -1.9348634 | E11: -6.1539387 | F11: -3.0924631 | G11: -9.4654461
A12: Manufacture of other goods for consumers | B12: -0.56622788 | C12: -0.39159638 | D12: -0.63785139 | E12: -1.4212566 | F12: -0.59115365 | G12: -2.4800695
A13: Construction of buildings and Civil engineering | B13: -2.0076235 | C13: 0.10686136 | D13: -0.78503017 | E13: -0.8660373 | F13: -0.34255537 | G13: -8.1868508
A14: Rail transport | B14: -0.40333807 | C14: -0.17358482 | D14: 0.023201449 | E14: -0.09355918 | F14: -0.42325069 | G14: -1.9331279
... A33: Electricity - Others | B33: -5.8731935 | C33: -0.68512135 | D33: -0.077267571 | E33: 1.2890339 | F33: -1.4130812 | G33: -0.69859948

Sheet Elasticities_NAF17
B1: KL | C1: KE | D1: KM | E1: LE | F1: LM | G1: EM
A2: Agriculture, sylviculture et pêche | B2: {=TRANSPOSE(MMULT(TRANSPOSE(Elasticities_WIOD!C2:H57),'WIOD.NAF17.pond'!B2:R57))} -> 1.7756746 | C2: 0.0077409148 | D2: -0.35248862 | E2: -13.605251 | F2: -0.36568112 | G2: 4.1663283
A3: Industries extractives, énergie, eau, gestion des déchets et dépollution | B3: -4.4665073 | C3: -3.1423883 | D3: -0.12440643 | E3: -1.4397274 | F3: -1.0361908 | G3: -0.76256753
A4: Fabrication de denrées alimentaires, de boissons et de produits à base de tabac | B4: -0.40614676 | C4: -1.5187354 | D4: -0.62635141 | E4: -2.0896776 | F4: -0.56421324 | G4: -0.38968347
A5: Cokéfaction et raffinage | B5: -0.17342704 | C5: -0.19568186 | D5: -0.053895097 | E5: -0.69661571 | F5: -0.11767251 | G5: -0.44548428
A6: Fabrication d'équipements électriques, électroniques, informatiques ; fabrication de machines | B6: -0.31585173 | C6: -0.38436569 | D6: -0.40330645 | E6: -0.031825803 | F6: -0.66420001 | G6: -2.112472
A7: Fabrication de matériels de transport | B7: 0.0060874452 | C7: 0.011638603 | D7: 0.00095375887 | E7: -2.3455178 | F7: -1.1427634 | G7: -1.6556384
A8: Fabrication d'autres produits industriels | B8: -0.57810789 | C8: -0.73426434 | D8: -0.75161479 | E8: -0.0092433593 | F8: -0.34637188 | G8: -1.4766279
A9: Construction | B9: -0.50548251 | C9: 0.32714918 | D9: -0.66061657 | E9: -0.075969281 | F9: -0.48328179 | G9: -3.5312462
A10: Commerce ; réparation d'automobiles et de motocycles | B10: -0.39638313 | C10: -0.56329515 | D10: -0.5257152 | E10: -0.92689317 | F10: -0.30279933 | G10: -1.8469414
A11: Transports et entreposage | B11: -0.3775082 | C11: -0.21026928 | D11: -0.11591266 | E11: -0.54772868 | F11: -0.24850467 | G11: -2.463153
A12: Hébergement et restauration | B12: -0.45527078 | C12: -0.25185593 | D12: -0.62637323 | E12: -0.24348303 | F12: -0.43495677 | G12: -1.8452374
A13: Information et communication | B13: -0.73528379 | C13: -0.61842792 | D13: -0.4666739 | E13: -0.30480015 | F13: -0.16358649 | G13: -1.6768037
A14: Activités financières et d'assurance | B14: -0.55301109 | C14: -0.80646683 | D14: -0.55842953 | E14: -0.35110585 | F14: -0.32145141 | G14: -3.5459146
... A18: Autres activités de services | B18: 0 | C18: 0 | D18: 0 | E18: 0 | F18: 0 | G18: 0
A19: Public services
A20: Mining
A21: Production of refined oil
A22: Production of biofuel
A23: Distribution of natural gas
A24: Production and distribution of biogas
A25: Nuclear electricity generation
A26: Oil-fired electricity generation
A27: Gas-fired electricity generation
A28: Coal-fired electricity generation
A29: Wind electricity generation
A30: Solar electricity generation
... A33: Electricity - Others
