Workbook
Name formatResults: [1]ResultsEXR10!$A$50

Sheet Results
A1: NB : on crée ici une liste : - globale, qui fusionne les reportings 1, 2 et 3 (même si seules les valeurs du scénario de choc présentées ici) - "rationalisée" : suppression des doublons, et regroupements par thématique On pourra continuer par la suite à avoir 3 Excels de reporting (pour éviter un Excel trop gros), mais dans lesquels on copiera toujours les mêmes sorties (et faire des RECHERCHEV)
E2: ThreeME V3 | F2: 2 | G2: 3 | H2: 4 | I2: 5 | J2: 6 | K2: 7 | L2: 8 | M2: 9 | N2: 10 | O2: 11 | P2: 12 | Q2: 13 | R2: 14 | S2: 15 | T2: 16 | U2: 17 | V2: 18 | W2: 19 | X2: 20 | Y2: 21 | Z2: 22 | AA2: 23 | AB2: 24 | AC2: 25 | AD2: 26 | AE2: 27 | AF2: 28 | AG2: 29 | AH2: 30 | AI2: 31 | AJ2: 32 | AK2: 33 | AL2: 34 | AM2: 35 | AN2: 36 | AO2: 37
A3: Nom du bloc de variables utilisé dans le code | B3: Sous-bloc de variables pour plus de lisibilité dans le Excel | E3: Year | F3: =Hybrid!B1 -> 42005 | G3: =Hybrid!C1 -> 42370 | H3: =Hybrid!D1 -> 42736 | I3: =Hybrid!E1 -> 43101 | J3: =Hybrid!F1 -> 43466 | K3: =Hybrid!G1 -> 43831 | L3: =Hybrid!H1 -> 44197 | M3: =Hybrid!I1 -> 44562 | ... AO3: =Hybrid!AK1 -> 54789
A4: HYBRID | B4: AUTOMOBILES (unit) | C4: TOTAL STOCK SHOCK | E4: AUTO_2 | F4: =+VLOOKUP($E4,Hybrid!$1:$1048576,F$2,FALSE) -> 32317.941 | G4: =+VLOOKUP($E4,Hybrid!$1:$1048576,G$2,FALSE) -> 31926.455 | H4: =+VLOOKUP($E4,Hybrid!$1:$1048576,H$2,FALSE) -> 31730.401 | I4: =+VLOOKUP($E4,Hybrid!$1:$1048576,I$2,FALSE) -> 31664.733 | J4: =+VLOOKUP($E4,Hybrid!$1:$1048576,J$2,FALSE) -> 31685.152 | K4: =+VLOOKUP($E4,Hybrid!$1:$1048576,K$2,FALSE) -> 31761.774 | L4: =+VLOOKUP($E4,Hybrid!$1:$1048576,L$2,FALSE) -> 31876.82 | M4: =+VLOOKUP($E4,Hybrid!$1:$1048576,M$2,FALSE) -> 32020.398 | ... AO4: =+VLOOKUP($E4,Hybrid!$1:$1048576,AO$2,FALSE) -> 36554.972
C5: OIL | E5: AUTO_cfut_2 | F5: =+VLOOKUP($E5,Hybrid!$1:$1048576,F$2,FALSE) -> 32271.24 | G5: =+VLOOKUP($E5,Hybrid!$1:$1048576,G$2,FALSE) -> 31862.032 | H5: =+VLOOKUP($E5,Hybrid!$1:$1048576,H$2,FALSE) -> 31647.329 | I5: =+VLOOKUP($E5,Hybrid!$1:$1048576,I$2,FALSE) -> 31562.481 | J5: =+VLOOKUP($E5,Hybrid!$1:$1048576,J$2,FALSE) -> 31563.392 | K5: =+VLOOKUP($E5,Hybrid!$1:$1048576,K$2,FALSE) -> 31620.229 | L5: =+VLOOKUP($E5,Hybrid!$1:$1048576,L$2,FALSE) -> 31715.127 | M5: =+VLOOKUP($E5,Hybrid!$1:$1048576,M$2,FALSE) -> 31838.038 | ... AO5: =+VLOOKUP($E5,Hybrid!$1:$1048576,AO$2,FALSE) -> 32020.075
D6: class A | E6: AUTO_ca_cfut_2 | F6: =+VLOOKUP($E6,Hybrid!$1:$1048576,F$2,FALSE) -> 7095.7005 | G6: =+VLOOKUP($E6,Hybrid!$1:$1048576,G$2,FALSE) -> 7141.744 | H6: =+VLOOKUP($E6,Hybrid!$1:$1048576,H$2,FALSE) -> 7236.2109 | I6: =+VLOOKUP($E6,Hybrid!$1:$1048576,I$2,FALSE) -> 7362.7565 | J6: =+VLOOKUP($E6,Hybrid!$1:$1048576,J$2,FALSE) -> 7510.0299 | K6: =+VLOOKUP($E6,Hybrid!$1:$1048576,K$2,FALSE) -> 7670.2472 | L6: =+VLOOKUP($E6,Hybrid!$1:$1048576,L$2,FALSE) -> 7838.785 | M6: =+VLOOKUP($E6,Hybrid!$1:$1048576,M$2,FALSE) -> 8013.1055 | ... AO6: =+VLOOKUP($E6,Hybrid!$1:$1048576,AO$2,FALSE) -> 11240.43
D7: class B | E7: AUTO_cb_cfut_2 | F7: =+VLOOKUP($E7,Hybrid!$1:$1048576,F$2,FALSE) -> 8251.2564 | G7: =+VLOOKUP($E7,Hybrid!$1:$1048576,G$2,FALSE) -> 8182.7845 | H7: =+VLOOKUP($E7,Hybrid!$1:$1048576,H$2,FALSE) -> 8168.3356 | I7: =+VLOOKUP($E7,Hybrid!$1:$1048576,I$2,FALSE) -> 8191.2663 | J7: =+VLOOKUP($E7,Hybrid!$1:$1048576,J$2,FALSE) -> 8239.913 | K7: =+VLOOKUP($E7,Hybrid!$1:$1048576,K$2,FALSE) -> 8306.1531 | L7: =+VLOOKUP($E7,Hybrid!$1:$1048576,L$2,FALSE) -> 8384.9727 | M7: =+VLOOKUP($E7,Hybrid!$1:$1048576,M$2,FALSE) -> 8473.4298 | ... AO7: =+VLOOKUP($E7,Hybrid!$1:$1048576,AO$2,FALSE) -> 9881.9911
D8: class C | E8: AUTO_cc_cfut_2 | F8: =+VLOOKUP($E8,Hybrid!$1:$1048576,F$2,FALSE) -> 6777.6025 | G8: =+VLOOKUP($E8,Hybrid!$1:$1048576,G$2,FALSE) -> 6646.7629 | H8: =+VLOOKUP($E8,Hybrid!$1:$1048576,H$2,FALSE) -> 6558.9664 | I8: =+VLOOKUP($E8,Hybrid!$1:$1048576,I$2,FALSE) -> 6502.0082 | J8: =+VLOOKUP($E8,Hybrid!$1:$1048576,J$2,FALSE) -> 6467.2622 | K8: =+VLOOKUP($E8,Hybrid!$1:$1048576,K$2,FALSE) -> 6448.6373 | L8: =+VLOOKUP($E8,Hybrid!$1:$1048576,L$2,FALSE) -> 6442.2478 | M8: =+VLOOKUP($E8,Hybrid!$1:$1048576,M$2,FALSE) -> 6445.693 | ... AO8: =+VLOOKUP($E8,Hybrid!$1:$1048576,AO$2,FALSE) -> 6300.9328
D9: class D | E9: AUTO_cd_cfut_2 | F9: =+VLOOKUP($E9,Hybrid!$1:$1048576,F$2,FALSE) -> 4159.6639 | G9: =+VLOOKUP($E9,Hybrid!$1:$1048576,G$2,FALSE) -> 4054.5797 | H9: =+VLOOKUP($E9,Hybrid!$1:$1048576,H$2,FALSE) -> 3973.8285 | I9: =+VLOOKUP($E9,Hybrid!$1:$1048576,I$2,FALSE) -> 3910.0599 | J9: =+VLOOKUP($E9,Hybrid!$1:$1048576,J$2,FALSE) -> 3858.1675 | K9: =+VLOOKUP($E9,Hybrid!$1:$1048576,K$2,FALSE) -> 3814.6035 | L9: =+VLOOKUP($E9,Hybrid!$1:$1048576,L$2,FALSE) -> 3777.117 | M9: =+VLOOKUP($E9,Hybrid!$1:$1048576,M$2,FALSE) -> 3744.3156 | ... AO9: =+VLOOKUP($E9,Hybrid!$1:$1048576,AO$2,FALSE) -> 2689.2394
D10: class E | E10: AUTO_ce_cfut_2 | F10: =+VLOOKUP($E10,Hybrid!$1:$1048576,F$2,FALSE) -> 2503.7292 | G10: =+VLOOKUP($E10,Hybrid!$1:$1048576,G$2,FALSE) -> 2442.7169 | H10: =+VLOOKUP($E10,Hybrid!$1:$1048576,H$2,FALSE) -> 2395.2655 | I10: =+VLOOKUP($E10,Hybrid!$1:$1048576,I$2,FALSE) -> 2356.6831 | J10: =+VLOOKUP($E10,Hybrid!$1:$1048576,J$2,FALSE) -> 2323.7962 | K10: =+VLOOKUP($E10,Hybrid!$1:$1048576,K$2,FALSE) -> 2294.4653 | L10: =+VLOOKUP($E10,Hybrid!$1:$1048576,L$2,FALSE) -> 2267.3805 | M10: =+VLOOKUP($E10,Hybrid!$1:$1048576,M$2,FALSE) -> 2241.7723 | ... AO10: =+VLOOKUP($E10,Hybrid!$1:$1048576,AO$2,FALSE) -> 1253.0278
D11: class F | E11: AUTO_cf_cfut_2 | F11: =+VLOOKUP($E11,Hybrid!$1:$1048576,F$2,FALSE) -> 1243.6668 | G11: =+VLOOKUP($E11,Hybrid!$1:$1048576,G$2,FALSE) -> 1210.4925 | H11: =+VLOOKUP($E11,Hybrid!$1:$1048576,H$2,FALSE) -> 1182.3239 | I11: =+VLOOKUP($E11,Hybrid!$1:$1048576,I$2,FALSE) -> 1156.6362 | J11: =+VLOOKUP($E11,Hybrid!$1:$1048576,J$2,FALSE) -> 1131.8888 | K11: =+VLOOKUP($E11,Hybrid!$1:$1048576,K$2,FALSE) -> 1107.177 | L11: =+VLOOKUP($E11,Hybrid!$1:$1048576,L$2,FALSE) -> 1082.0509 | M11: =+VLOOKUP($E11,Hybrid!$1:$1048576,M$2,FALSE) -> 1056.3349 | ... AO11: =+VLOOKUP($E11,Hybrid!$1:$1048576,AO$2,FALSE) -> 294.49603
D12: class G | E12: AUTO_cg_cfut_2 | F12: =+VLOOKUP($E12,Hybrid!$1:$1048576,F$2,FALSE) -> 2239.6206 | G12: =+VLOOKUP($E12,Hybrid!$1:$1048576,G$2,FALSE) -> 2182.9512 | H12: =+VLOOKUP($E12,Hybrid!$1:$1048576,H$2,FALSE) -> 2132.3988 | I12: =+VLOOKUP($E12,Hybrid!$1:$1048576,I$2,FALSE) -> 2083.0711 | J12: =+VLOOKUP($E12,Hybrid!$1:$1048576,J$2,FALSE) -> 2032.334 | K12: =+VLOOKUP($E12,Hybrid!$1:$1048576,K$2,FALSE) -> 1978.9456 | L12: =+VLOOKUP($E12,Hybrid!$1:$1048576,L$2,FALSE) -> 1922.5734 | M12: =+VLOOKUP($E12,Hybrid!$1:$1048576,M$2,FALSE) -> 1863.3872 | ... AO12: =+VLOOKUP($E12,Hybrid!$1:$1048576,AO$2,FALSE) -> 359.95743
C13: ELEC | E13: AUTO_cele_2 | F13: =+VLOOKUP($E13,Hybrid!$1:$1048576,F$2,FALSE) -> 44.765 | G13: =+VLOOKUP($E13,Hybrid!$1:$1048576,G$2,FALSE) -> 62.431569 | H13: =+VLOOKUP($E13,Hybrid!$1:$1048576,H$2,FALSE) -> 81.013696 | I13: =+VLOOKUP($E13,Hybrid!$1:$1048576,I$2,FALSE) -> 100.12298 | J13: =+VLOOKUP($E13,Hybrid!$1:$1048576,J$2,FALSE) -> 119.55791 | K13: =+VLOOKUP($E13,Hybrid!$1:$1048576,K$2,FALSE) -> 139.26917 | L13: =+VLOOKUP($E13,Hybrid!$1:$1048576,L$2,FALSE) -> 159.3444 | M13: =+VLOOKUP($E13,Hybrid!$1:$1048576,M$2,FALSE) -> 179.94081 | ... AO13: =+VLOOKUP($E13,Hybrid!$1:$1048576,AO$2,FALSE) -> 4531.6755
D14: class A | E14: AUTO_ca_cele_2 | F14: =+VLOOKUP($E14,Hybrid!$1:$1048576,F$2,FALSE) -> 9.8427899 | G14: =+VLOOKUP($E14,Hybrid!$1:$1048576,G$2,FALSE) -> 14.986776 | H14: =+VLOOKUP($E14,Hybrid!$1:$1048576,H$2,FALSE) -> 20.441889 | I14: =+VLOOKUP($E14,Hybrid!$1:$1048576,I$2,FALSE) -> 26.112449 | J14: =+VLOOKUP($E14,Hybrid!$1:$1048576,J$2,FALSE) -> 31.950416 | K14: =+VLOOKUP($E14,Hybrid!$1:$1048576,K$2,FALSE) -> 37.949262 | L14: =+VLOOKUP($E14,Hybrid!$1:$1048576,L$2,FALSE) -> 44.142141 | M14: =+VLOOKUP($E14,Hybrid!$1:$1048576,M$2,FALSE) -> 50.58278 | ... AO14: =+VLOOKUP($E14,Hybrid!$1:$1048576,AO$2,FALSE) -> 1721.1452
D15: class B | E15: AUTO_cb_cele_2 | F15: =+VLOOKUP($E15,Hybrid!$1:$1048576,F$2,FALSE) -> 11.445717 | G15: =+VLOOKUP($E15,Hybrid!$1:$1048576,G$2,FALSE) -> 16.298726 | H15: =+VLOOKUP($E15,Hybrid!$1:$1048576,H$2,FALSE) -> 21.445143 | I15: =+VLOOKUP($E15,Hybrid!$1:$1048576,I$2,FALSE) -> 26.792131 | J15: =+VLOOKUP($E15,Hybrid!$1:$1048576,J$2,FALSE) -> 32.294 | K15: =+VLOOKUP($E15,Hybrid!$1:$1048576,K$2,FALSE) -> 37.945945 | L15: =+VLOOKUP($E15,Hybrid!$1:$1048576,L$2,FALSE) -> 43.781768 | M15: =+VLOOKUP($E15,Hybrid!$1:$1048576,M$2,FALSE) -> 49.854747 | ... AO15: =+VLOOKUP($E15,Hybrid!$1:$1048576,AO$2,FALSE) -> 1535.9361
D16: class C | E16: AUTO_cc_cele_2 | F16: =+VLOOKUP($E16,Hybrid!$1:$1048576,F$2,FALSE) -> 9.4015406 | G16: =+VLOOKUP($E16,Hybrid!$1:$1048576,G$2,FALSE) -> 12.697683 | H16: =+VLOOKUP($E16,Hybrid!$1:$1048576,H$2,FALSE) -> 16.193359 | I16: =+VLOOKUP($E16,Hybrid!$1:$1048576,I$2,FALSE) -> 19.823555 | J16: =+VLOOKUP($E16,Hybrid!$1:$1048576,J$2,FALSE) -> 23.556822 | K16: =+VLOOKUP($E16,Hybrid!$1:$1048576,K$2,FALSE) -> 27.390656 | L16: =+VLOOKUP($E16,Hybrid!$1:$1048576,L$2,FALSE) -> 31.349549 | M16: =+VLOOKUP($E16,Hybrid!$1:$1048576,M$2,FALSE) -> 35.471242 | ... AO16: =+VLOOKUP($E16,Hybrid!$1:$1048576,AO$2,FALSE) -> 985.35071
D17: class D | E17: AUTO_cd_cele_2 | F17: =+VLOOKUP($E17,Hybrid!$1:$1048576,F$2,FALSE) -> 5.7700713 | G17: =+VLOOKUP($E17,Hybrid!$1:$1048576,G$2,FALSE) -> 7.5615055 | H17: =+VLOOKUP($E17,Hybrid!$1:$1048576,H$2,FALSE) -> 9.4379839 | I17: =+VLOOKUP($E17,Hybrid!$1:$1048576,I$2,FALSE) -> 11.352079 | J17: =+VLOOKUP($E17,Hybrid!$1:$1048576,J$2,FALSE) -> 13.275194 | K17: =+VLOOKUP($E17,Hybrid!$1:$1048576,K$2,FALSE) -> 15.192959 | L17: =+VLOOKUP($E17,Hybrid!$1:$1048576,L$2,FALSE) -> 17.103324 | M17: =+VLOOKUP($E17,Hybrid!$1:$1048576,M$2,FALSE) -> 19.010938 | ... AO17: =+VLOOKUP($E17,Hybrid!$1:$1048576,AO$2,FALSE) -> 187.38943
D18: class E | E18: AUTO_ce_cele_2 | F18: =+VLOOKUP($E18,Hybrid!$1:$1048576,F$2,FALSE) -> 3.4730441 | G18: =+VLOOKUP($E18,Hybrid!$1:$1048576,G$2,FALSE) -> 4.5722155 | H18: =+VLOOKUP($E18,Hybrid!$1:$1048576,H$2,FALSE) -> 5.7140433 | I18: =+VLOOKUP($E18,Hybrid!$1:$1048576,I$2,FALSE) -> 6.8675525 | J18: =+VLOOKUP($E18,Hybrid!$1:$1048576,J$2,FALSE) -> 8.014519 | K18: =+VLOOKUP($E18,Hybrid!$1:$1048576,K$2,FALSE) -> 9.146111 | L18: =+VLOOKUP($E18,Hybrid!$1:$1048576,L$2,FALSE) -> 10.261244 | M18: =+VLOOKUP($E18,Hybrid!$1:$1048576,M$2,FALSE) -> 11.362807 | ... AO18: =+VLOOKUP($E18,Hybrid!$1:$1048576,AO$2,FALSE) -> 82.980357
D19: class F | E19: AUTO_cf_cele_2 | F19: =+VLOOKUP($E19,Hybrid!$1:$1048576,F$2,FALSE) -> 1.7251505 | G19: =+VLOOKUP($E19,Hybrid!$1:$1048576,G$2,FALSE) -> 2.2443945 | H19: =+VLOOKUP($E19,Hybrid!$1:$1048576,H$2,FALSE) -> 2.7668951 | I19: =+VLOOKUP($E19,Hybrid!$1:$1048576,I$2,FALSE) -> 3.2740042 | J19: =+VLOOKUP($E19,Hybrid!$1:$1048576,J$2,FALSE) -> 3.7551966 | K19: =+VLOOKUP($E19,Hybrid!$1:$1048576,K$2,FALSE) -> 4.2053456 | L19: =+VLOOKUP($E19,Hybrid!$1:$1048576,L$2,FALSE) -> 4.6232035 | M19: =+VLOOKUP($E19,Hybrid!$1:$1048576,M$2,FALSE) -> 5.0095094 | ... AO19: =+VLOOKUP($E19,Hybrid!$1:$1048576,AO$2,FALSE) -> 9.6175149
D20: class G | E20: AUTO_cg_cele_2 | F20: =+VLOOKUP($E20,Hybrid!$1:$1048576,F$2,FALSE) -> 3.1066862 | G20: =+VLOOKUP($E20,Hybrid!$1:$1048576,G$2,FALSE) -> 4.0702695 | H20: =+VLOOKUP($E20,Hybrid!$1:$1048576,H$2,FALSE) -> 5.014383 | I20: =+VLOOKUP($E20,Hybrid!$1:$1048576,I$2,FALSE) -> 5.9012135 | J20: =+VLOOKUP($E20,Hybrid!$1:$1048576,J$2,FALSE) -> 6.7117634 | K20: =+VLOOKUP($E20,Hybrid!$1:$1048576,K$2,FALSE) -> 7.4388891 | L20: =+VLOOKUP($E20,Hybrid!$1:$1048576,L$2,FALSE) -> 8.0831672 | M20: =+VLOOKUP($E20,Hybrid!$1:$1048576,M$2,FALSE) -> 8.6487844 | ... AO20: =+VLOOKUP($E20,Hybrid!$1:$1048576,AO$2,FALSE) -> 9.2561619
C21: GAS | E21: AUTO_cgas_2 | F21: =+VLOOKUP($E21,Hybrid!$1:$1048576,F$2,FALSE) -> 1.936 | G21: =+VLOOKUP($E21,Hybrid!$1:$1048576,G$2,FALSE) -> 1.9916056 | H21: =+VLOOKUP($E21,Hybrid!$1:$1048576,H$2,FALSE) -> 2.0574011 | I21: =+VLOOKUP($E21,Hybrid!$1:$1048576,I$2,FALSE) -> 2.1285899 | J21: =+VLOOKUP($E21,Hybrid!$1:$1048576,J$2,FALSE) -> 2.2019794 | K21: =+VLOOKUP($E21,Hybrid!$1:$1048576,K$2,FALSE) -> 2.2754864 | L21: =+VLOOKUP($E21,Hybrid!$1:$1048576,L$2,FALSE) -> 2.3479684 | M21: =+VLOOKUP($E21,Hybrid!$1:$1048576,M$2,FALSE) -> 2.4188941 | ... AO21: =+VLOOKUP($E21,Hybrid!$1:$1048576,AO$2,FALSE) -> 3.2214115
D22: class A | E22: AUTO_ca_cgas_2 | F22: =+VLOOKUP($E22,Hybrid!$1:$1048576,F$2,FALSE) -> 0.4256817 | G22: =+VLOOKUP($E22,Hybrid!$1:$1048576,G$2,FALSE) -> 0.44933517 | H22: =+VLOOKUP($E22,Hybrid!$1:$1048576,H$2,FALSE) -> 0.47587941 | I22: =+VLOOKUP($E22,Hybrid!$1:$1048576,I$2,FALSE) -> 0.50407723 | J22: =+VLOOKUP($E22,Hybrid!$1:$1048576,J$2,FALSE) -> 0.53308137 | K22: =+VLOOKUP($E22,Hybrid!$1:$1048576,K$2,FALSE) -> 0.56232302 | L22: =+VLOOKUP($E22,Hybrid!$1:$1048576,L$2,FALSE) -> 0.59148357 | M22: =+VLOOKUP($E22,Hybrid!$1:$1048576,M$2,FALSE) -> 0.62040925 | ... AO22: =+VLOOKUP($E22,Hybrid!$1:$1048576,AO$2,FALSE) -> 1.1175435
D23: class B | E23: AUTO_cb_cgas_2 | F23: =+VLOOKUP($E23,Hybrid!$1:$1048576,F$2,FALSE) -> 0.49500523 | G23: =+VLOOKUP($E23,Hybrid!$1:$1048576,G$2,FALSE) -> 0.51226024 | H23: =+VLOOKUP($E23,Hybrid!$1:$1048576,H$2,FALSE) -> 0.53252768 | I23: =+VLOOKUP($E23,Hybrid!$1:$1048576,I$2,FALSE) -> 0.55457425 | J23: =+VLOOKUP($E23,Hybrid!$1:$1048576,J$2,FALSE) -> 0.57755325 | K23: =+VLOOKUP($E23,Hybrid!$1:$1048576,K$2,FALSE) -> 0.60089214 | L23: =+VLOOKUP($E23,Hybrid!$1:$1048576,L$2,FALSE) -> 0.62426223 | M23: =+VLOOKUP($E23,Hybrid!$1:$1048576,M$2,FALSE) -> 0.64749666 | ... AO23: =+VLOOKUP($E23,Hybrid!$1:$1048576,AO$2,FALSE) -> 0.98903502
D24: class C | E24: AUTO_cc_cgas_2 | F24: =+VLOOKUP($E24,Hybrid!$1:$1048576,F$2,FALSE) -> 0.40659852 | G24: =+VLOOKUP($E24,Hybrid!$1:$1048576,G$2,FALSE) -> 0.4145049 | H24: =+VLOOKUP($E24,Hybrid!$1:$1048576,H$2,FALSE) -> 0.42467781 | I24: =+VLOOKUP($E24,Hybrid!$1:$1048576,I$2,FALSE) -> 0.43623168 | J24: =+VLOOKUP($E24,Hybrid!$1:$1048576,J$2,FALSE) -> 0.44855712 | K24: =+VLOOKUP($E24,Hybrid!$1:$1048576,K$2,FALSE) -> 0.4612394 | L24: =+VLOOKUP($E24,Hybrid!$1:$1048576,L$2,FALSE) -> 0.47403519 | M24: =+VLOOKUP($E24,Hybrid!$1:$1048576,M$2,FALSE) -> 0.48681568 | ... AO24: =+VLOOKUP($E24,Hybrid!$1:$1048576,AO$2,FALSE) -> 0.63482943
D25: class D | E25: AUTO_cd_cgas_2 | F25: =+VLOOKUP($E25,Hybrid!$1:$1048576,F$2,FALSE) -> 0.24954447 | G25: =+VLOOKUP($E25,Hybrid!$1:$1048576,G$2,FALSE) -> 0.25231485 | H25: =+VLOOKUP($E25,Hybrid!$1:$1048576,H$2,FALSE) -> 0.25626929 | I25: =+VLOOKUP($E25,Hybrid!$1:$1048576,I$2,FALSE) -> 0.26087537 | J25: =+VLOOKUP($E25,Hybrid!$1:$1048576,J$2,FALSE) -> 0.2657744 | K25: =+VLOOKUP($E25,Hybrid!$1:$1048576,K$2,FALSE) -> 0.27072766 | L25: =+VLOOKUP($E25,Hybrid!$1:$1048576,L$2,FALSE) -> 0.27559709 | M25: =+VLOOKUP($E25,Hybrid!$1:$1048576,M$2,FALSE) -> 0.28031071 | ... AO25: =+VLOOKUP($E25,Hybrid!$1:$1048576,AO$2,FALSE) -> 0.27521423
D26: class E | E26: AUTO_ce_cgas_2 | F26: =+VLOOKUP($E26,Hybrid!$1:$1048576,F$2,FALSE) -> 0.15020247 | G26: =+VLOOKUP($E26,Hybrid!$1:$1048576,G$2,FALSE) -> 0.15205804 | H26: =+VLOOKUP($E26,Hybrid!$1:$1048576,H$2,FALSE) -> 0.15453801 | I26: =+VLOOKUP($E26,Hybrid!$1:$1048576,I$2,FALSE) -> 0.15729786 | J26: =+VLOOKUP($E26,Hybrid!$1:$1048576,J$2,FALSE) -> 0.16011145 | K26: =+VLOOKUP($E26,Hybrid!$1:$1048576,K$2,FALSE) -> 0.16283293 | L26: =+VLOOKUP($E26,Hybrid!$1:$1048576,L$2,FALSE) -> 0.16538126 | M26: =+VLOOKUP($E26,Hybrid!$1:$1048576,M$2,FALSE) -> 0.16771728 | ... AO26: =+VLOOKUP($E26,Hybrid!$1:$1048576,AO$2,FALSE) -> 0.13087224
D27: class F | E27: AUTO_cf_cgas_2 | F27: =+VLOOKUP($E27,Hybrid!$1:$1048576,F$2,FALSE) -> 0.074609436 | G27: =+VLOOKUP($E27,Hybrid!$1:$1048576,G$2,FALSE) -> 0.075290207 | H27: =+VLOOKUP($E27,Hybrid!$1:$1048576,H$2,FALSE) -> 0.076132076 | I27: =+VLOOKUP($E27,Hybrid!$1:$1048576,I$2,FALSE) -> 0.076945597 | J27: =+VLOOKUP($E27,Hybrid!$1:$1048576,J$2,FALSE) -> 0.077619324 | K27: =+VLOOKUP($E27,Hybrid!$1:$1048576,K$2,FALSE) -> 0.078092136 | L27: =+VLOOKUP($E27,Hybrid!$1:$1048576,L$2,FALSE) -> 0.078339035 | M27: =+VLOOKUP($E27,Hybrid!$1:$1048576,M$2,FALSE) -> 0.078356678 | ... AO27: =+VLOOKUP($E27,Hybrid!$1:$1048576,AO$2,FALSE) -> 0.032639717
D28: class G | E28: AUTO_cg_cgas_2 | F28: =+VLOOKUP($E28,Hybrid!$1:$1048576,F$2,FALSE) -> 0.13435819 | G28: =+VLOOKUP($E28,Hybrid!$1:$1048576,G$2,FALSE) -> 0.13584219 | H28: =+VLOOKUP($E28,Hybrid!$1:$1048576,H$2,FALSE) -> 0.13737684 | I28: =+VLOOKUP($E28,Hybrid!$1:$1048576,I$2,FALSE) -> 0.13858796 | J28: =+VLOOKUP($E28,Hybrid!$1:$1048576,J$2,FALSE) -> 0.13928248 | K28: =+VLOOKUP($E28,Hybrid!$1:$1048576,K$2,FALSE) -> 0.13937915 | L28: =+VLOOKUP($E28,Hybrid!$1:$1048576,L$2,FALSE) -> 0.13887006 | M28: =+VLOOKUP($E28,Hybrid!$1:$1048576,M$2,FALSE) -> 0.13778783 | ... AO28: =+VLOOKUP($E28,Hybrid!$1:$1048576,AO$2,FALSE) -> 0.041277351
C29: TOTAL STOCK BASELINE | E29: AUTO_0 | F29: =+VLOOKUP($E29,Hybrid!$1:$1048576,F$2,FALSE) -> 32317.941 | G29: =+VLOOKUP($E29,Hybrid!$1:$1048576,G$2,FALSE) -> 31931.625 | H29: =+VLOOKUP($E29,Hybrid!$1:$1048576,H$2,FALSE) -> 31743.508 | I29: =+VLOOKUP($E29,Hybrid!$1:$1048576,I$2,FALSE) -> 31687.792 | J29: =+VLOOKUP($E29,Hybrid!$1:$1048576,J$2,FALSE) -> 31720.643 | K29: =+VLOOKUP($E29,Hybrid!$1:$1048576,K$2,FALSE) -> 31813.337 | L29: =+VLOOKUP($E29,Hybrid!$1:$1048576,L$2,FALSE) -> 31947.162 | M29: =+VLOOKUP($E29,Hybrid!$1:$1048576,M$2,FALSE) -> 32109.877 | ... AO29: =+VLOOKUP($E29,Hybrid!$1:$1048576,AO$2,FALSE) -> 38673.292
C30: OIL | E30: AUTO_cfut_0 | F30: =+VLOOKUP($E30,Hybrid!$1:$1048576,F$2,FALSE) -> 32271.24 | G30: =+VLOOKUP($E30,Hybrid!$1:$1048576,G$2,FALSE) -> 31867.185 | H30: =+VLOOKUP($E30,Hybrid!$1:$1048576,H$2,FALSE) -> 31660.486 | I30: =+VLOOKUP($E30,Hybrid!$1:$1048576,I$2,FALSE) -> 31585.838 | J30: =+VLOOKUP($E30,Hybrid!$1:$1048576,J$2,FALSE) -> 31599.721 | K30: =+VLOOKUP($E30,Hybrid!$1:$1048576,K$2,FALSE) -> 31673.603 | L30: =+VLOOKUP($E30,Hybrid!$1:$1048576,L$2,FALSE) -> 31788.887 | M30: =+VLOOKUP($E30,Hybrid!$1:$1048576,M$2,FALSE) -> 31933.397 | ... AO30: =+VLOOKUP($E30,Hybrid!$1:$1048576,AO$2,FALSE) -> 38101.905
D31: class A | E31: AUTO_ca_cfut_0 | F31: =+VLOOKUP($E31,Hybrid!$1:$1048576,F$2,FALSE) -> 7095.7005 | G31: =+VLOOKUP($E31,Hybrid!$1:$1048576,G$2,FALSE) -> 7143.1788 | H31: =+VLOOKUP($E31,Hybrid!$1:$1048576,H$2,FALSE) -> 7239.81 | I31: =+VLOOKUP($E31,Hybrid!$1:$1048576,I$2,FALSE) -> 7369.0432 | J31: =+VLOOKUP($E31,Hybrid!$1:$1048576,J$2,FALSE) -> 7519.6804 | K31: =+VLOOKUP($E31,Hybrid!$1:$1048576,K$2,FALSE) -> 7684.2986 | L31: =+VLOOKUP($E31,Hybrid!$1:$1048576,L$2,FALSE) -> 7858.0379 | M31: =+VLOOKUP($E31,Hybrid!$1:$1048576,M$2,FALSE) -> 8037.7299 | ... AO31: =+VLOOKUP($E31,Hybrid!$1:$1048576,AO$2,FALSE) -> 13271.9
D32: class B | E32: AUTO_cb_cfut_0 | F32: =+VLOOKUP($E32,Hybrid!$1:$1048576,F$2,FALSE) -> 8251.2564 | G32: =+VLOOKUP($E32,Hybrid!$1:$1048576,G$2,FALSE) -> 8184.1785 | H32: =+VLOOKUP($E32,Hybrid!$1:$1048576,H$2,FALSE) -> 8171.8779 | I32: =+VLOOKUP($E32,Hybrid!$1:$1048576,I$2,FALSE) -> 8197.5342 | J32: =+VLOOKUP($E32,Hybrid!$1:$1048576,J$2,FALSE) -> 8249.6491 | K32: =+VLOOKUP($E32,Hybrid!$1:$1048576,K$2,FALSE) -> 8320.4704 | L32: =+VLOOKUP($E32,Hybrid!$1:$1048576,L$2,FALSE) -> 8404.7877 | M32: =+VLOOKUP($E32,Hybrid!$1:$1048576,M$2,FALSE) -> 8499.0715 | ... AO32: =+VLOOKUP($E32,Hybrid!$1:$1048576,AO$2,FALSE) -> 11875.349
D33: class C | E33: AUTO_cc_cfut_0 | F33: =+VLOOKUP($E33,Hybrid!$1:$1048576,F$2,FALSE) -> 6777.6025 | G33: =+VLOOKUP($E33,Hybrid!$1:$1048576,G$2,FALSE) -> 6647.7392 | H33: =+VLOOKUP($E33,Hybrid!$1:$1048576,H$2,FALSE) -> 6561.4778 | I33: =+VLOOKUP($E33,Hybrid!$1:$1048576,I$2,FALSE) -> 6506.5051 | J33: =+VLOOKUP($E33,Hybrid!$1:$1048576,J$2,FALSE) -> 6474.3214 | K33: =+VLOOKUP($E33,Hybrid!$1:$1048576,K$2,FALSE) -> 6459.1067 | L33: =+VLOOKUP($E33,Hybrid!$1:$1048576,L$2,FALSE) -> 6456.8591 | M33: =+VLOOKUP($E33,Hybrid!$1:$1048576,M$2,FALSE) -> 6464.7815 | ... AO33: =+VLOOKUP($E33,Hybrid!$1:$1048576,AO$2,FALSE) -> 7687.7208
D34: class D | E34: AUTO_cd_cfut_0 | F34: =+VLOOKUP($E34,Hybrid!$1:$1048576,F$2,FALSE) -> 4159.6639 | G34: =+VLOOKUP($E34,Hybrid!$1:$1048576,G$2,FALSE) -> 4055.1231 | H34: =+VLOOKUP($E34,Hybrid!$1:$1048576,H$2,FALSE) -> 3975.2329 | I34: =+VLOOKUP($E34,Hybrid!$1:$1048576,I$2,FALSE) -> 3912.5808 | J34: =+VLOOKUP($E34,Hybrid!$1:$1048576,J$2,FALSE) -> 3862.1234 | K34: =+VLOOKUP($E34,Hybrid!$1:$1048576,K$2,FALSE) -> 3820.4516 | L34: =+VLOOKUP($E34,Hybrid!$1:$1048576,L$2,FALSE) -> 3785.2435 | M34: =+VLOOKUP($E34,Hybrid!$1:$1048576,M$2,FALSE) -> 3754.8857 | ... AO34: =+VLOOKUP($E34,Hybrid!$1:$1048576,AO$2,FALSE) -> 3102.3334
D35: class E | E35: AUTO_ce_cfut_0 | F35: =+VLOOKUP($E35,Hybrid!$1:$1048576,F$2,FALSE) -> 2503.7292 | G35: =+VLOOKUP($E35,Hybrid!$1:$1048576,G$2,FALSE) -> 2443.054 | H35: =+VLOOKUP($E35,Hybrid!$1:$1048576,H$2,FALSE) -> 2396.145 | I35: =+VLOOKUP($E35,Hybrid!$1:$1048576,I$2,FALSE) -> 2358.2745 | J35: =+VLOOKUP($E35,Hybrid!$1:$1048576,J$2,FALSE) -> 2326.3079 | K35: =+VLOOKUP($E35,Hybrid!$1:$1048576,K$2,FALSE) -> 2298.1904 | L35: =+VLOOKUP($E35,Hybrid!$1:$1048576,L$2,FALSE) -> 2272.5718 | M35: =+VLOOKUP($E35,Hybrid!$1:$1048576,M$2,FALSE) -> 2248.5516 | ... AO35: =+VLOOKUP($E35,Hybrid!$1:$1048576,AO$2,FALSE) -> 1454.1661
D36: class F | E36: AUTO_cf_cfut_0 | F36: =+VLOOKUP($E36,Hybrid!$1:$1048576,F$2,FALSE) -> 1243.6668 | G36: =+VLOOKUP($E36,Hybrid!$1:$1048576,G$2,FALSE) -> 1210.6549 | H36: =+VLOOKUP($E36,Hybrid!$1:$1048576,H$2,FALSE) -> 1182.7476 | I36: =+VLOOKUP($E36,Hybrid!$1:$1048576,I$2,FALSE) -> 1157.3995 | J36: =+VLOOKUP($E36,Hybrid!$1:$1048576,J$2,FALSE) -> 1133.0829 | K36: =+VLOOKUP($E36,Hybrid!$1:$1048576,K$2,FALSE) -> 1108.9242 | L36: =+VLOOKUP($E36,Hybrid!$1:$1048576,L$2,FALSE) -> 1084.4506 | M36: =+VLOOKUP($E36,Hybrid!$1:$1048576,M$2,FALSE) -> 1059.4277 | ... AO36: =+VLOOKUP($E36,Hybrid!$1:$1048576,AO$2,FALSE) -> 325.27338
D37: class G | E37: AUTO_cg_cfut_0 | F37: =+VLOOKUP($E37,Hybrid!$1:$1048576,F$2,FALSE) -> 2239.6206 | G37: =+VLOOKUP($E37,Hybrid!$1:$1048576,G$2,FALSE) -> 2183.2559 | H37: =+VLOOKUP($E37,Hybrid!$1:$1048576,H$2,FALSE) -> 2133.1946 | I37: =+VLOOKUP($E37,Hybrid!$1:$1048576,I$2,FALSE) -> 2084.5006 | J37: =+VLOOKUP($E37,Hybrid!$1:$1048576,J$2,FALSE) -> 2034.5555 | K37: =+VLOOKUP($E37,Hybrid!$1:$1048576,K$2,FALSE) -> 1982.161 | L37: =+VLOOKUP($E37,Hybrid!$1:$1048576,L$2,FALSE) -> 1926.9369 | M37: =+VLOOKUP($E37,Hybrid!$1:$1048576,M$2,FALSE) -> 1868.9489 | ... AO37: =+VLOOKUP($E37,Hybrid!$1:$1048576,AO$2,FALSE) -> 385.16287
C38: ELEC | E38: AUTO_cele_0 | F38: =+VLOOKUP($E38,Hybrid!$1:$1048576,F$2,FALSE) -> 44.765 | G38: =+VLOOKUP($E38,Hybrid!$1:$1048576,G$2,FALSE) -> 62.448716 | H38: =+VLOOKUP($E38,Hybrid!$1:$1048576,H$2,FALSE) -> 80.963971 | I38: =+VLOOKUP($E38,Hybrid!$1:$1048576,I$2,FALSE) -> 99.823967 | J38: =+VLOOKUP($E38,Hybrid!$1:$1048576,J$2,FALSE) -> 118.71772 | K38: =+VLOOKUP($E38,Hybrid!$1:$1048576,K$2,FALSE) -> 137.4542 | L38: =+VLOOKUP($E38,Hybrid!$1:$1048576,L$2,FALSE) -> 155.92054 | M38: =+VLOOKUP($E38,Hybrid!$1:$1048576,M$2,FALSE) -> 174.05324 | ... AO38: =+VLOOKUP($E38,Hybrid!$1:$1048576,AO$2,FALSE) -> 567.61282
D39: class A | E39: AUTO_ca_cele_0 | F39: =+VLOOKUP($E39,Hybrid!$1:$1048576,F$2,FALSE) -> 9.8427899 | G39: =+VLOOKUP($E39,Hybrid!$1:$1048576,G$2,FALSE) -> 14.990816 | H39: =+VLOOKUP($E39,Hybrid!$1:$1048576,H$2,FALSE) -> 20.422984 | I39: =+VLOOKUP($E39,Hybrid!$1:$1048576,I$2,FALSE) -> 26.012773 | J39: =+VLOOKUP($E39,Hybrid!$1:$1048576,J$2,FALSE) -> 31.67695 | K39: =+VLOOKUP($E39,Hybrid!$1:$1048576,K$2,FALSE) -> 37.362607 | L39: =+VLOOKUP($E39,Hybrid!$1:$1048576,L$2,FALSE) -> 43.037132 | M39: =+VLOOKUP($E39,Hybrid!$1:$1048576,M$2,FALSE) -> 48.681062 | ... AO39: =+VLOOKUP($E39,Hybrid!$1:$1048576,AO$2,FALSE) -> 195.65639
D40: class B | E40: AUTO_cb_cele_0 | F40: =+VLOOKUP($E40,Hybrid!$1:$1048576,F$2,FALSE) -> 11.445717 | G40: =+VLOOKUP($E40,Hybrid!$1:$1048576,G$2,FALSE) -> 16.302056 | H40: =+VLOOKUP($E40,Hybrid!$1:$1048576,H$2,FALSE) -> 21.423897 | I40: =+VLOOKUP($E40,Hybrid!$1:$1048576,I$2,FALSE) -> 26.687145 | J40: =+VLOOKUP($E40,Hybrid!$1:$1048576,J$2,FALSE) -> 32.010429 | K40: =+VLOOKUP($E40,Hybrid!$1:$1048576,K$2,FALSE) -> 37.342129 | L40: =+VLOOKUP($E40,Hybrid!$1:$1048576,L$2,FALSE) -> 42.650406 | M40: =+VLOOKUP($E40,Hybrid!$1:$1048576,M$2,FALSE) -> 47.916154 | ... AO40: =+VLOOKUP($E40,Hybrid!$1:$1048576,AO$2,FALSE) -> 177.032
...

Sheet Consumption
A1: _date_ | B1: 42005 | C1: 42370 | D1: 42736 | E1: 43101 | F1: 43466 | G1: 43831 | H1: 44197 | I1: 44562 | J1: 44927 | K1: 45292 | L1: 45658 | M1: 46023 | N1: 46388 | O1: 46753 | P1: 47119 | Q1: 47484 | R1: 47849 | S1: 48214 | T1: 48580 | U1: 48945 | V1: 49310 | W1: 49675 | X1: 50041 | Y1: 50406 | Z1: 50771 | AA1: 51136 | AB1: 51502 | AC1: 51867 | AD1: 52232 | AE1: 52597 | AF1: 52963 | AG1: 53328 | AH1: 53693 | AI1: 54058 | AJ1: 54424 | AK1: 54789
A2: ch_2 | B2: 1202071.8 | C2: 1215690.3 | D2: 1229310.3 | E2: 1243013.1 | F2: 1256875.5 | G2: 1270997.6 | H2: 1285460.8 | I2: 1300296.3 | J2: 1315499.9 | K2: 1331056.7 | L2: 1346957.4 | M2: 1363202.4 | N2: 1379801.2 | O2: 1396770.3 | P2: 1414130.4 | Q2: 1431905 | R2: 1450101.3 | S2: 1468696.7 | T2: 1487656 | U2: 1506945.7 | V2: 1526542.6 | W2: 1546433.3 | X2: 1566610.7 | Y2: 1587071 | Z2: 1607810.9 | AA2: 1628826.1 | AB2: 1650110.2 | AC2: 1671655.2 | AD2: 1693451 | AE2: 1715486.1 | AF2: 1737748.4 | AG2: 1760225.1 | AH2: 1782903.7 | AI2: 1805772 | AJ2: 1828818.9 | AK2: 1852033.8
A3: ch_0 | B3: 1202071.8 | C3: 1215641.6 | D3: 1229141.5 | E3: 1242648.3 | F3: 1256238.1 | G3: 1270001.2 | H3: 1284016.1 | I3: 1298333 | J3: 1312973.1 | K3: 1327935.9 | L3: 1343208.5 | M3: 1358772.9 | N3: 1374610.8 | O3: 1390705.9 | P3: 1407045.5 | Q3: 1423620.3 | R3: 1440423.8 | S3: 1457451.5 | T3: 1474700.5 | U3: 1492169 | V3: 1509855.2 | W3: 1527757.7 | X3: 1545875.1 | Y3: 1564206 | Z3: 1582749 | AA3: 1601502.9 | AB3: 1620466.6 | AC3: 1639639.4 | AD3: 1659020.8 | AE3: 1678610.9 | AF3: 1698410.1 | AG3: 1718419.4 | AH3: 1738640.1 | AI3: 1759074.1 | AJ3: 1779723.6 | AK3: 1800591.2
A4: pch_2 | B4: 1 | C4: 1.0202623 | D4: 1.0408444 | E4: 1.0618446 | F4: 1.083382 | G4: 1.1055795 | H4: 1.1283896 | I4: 1.151736 | J4: 1.1756836 | K4: 1.2002924 | L4: 1.2256236 | M4: 1.2517441 | N4: 1.2787299 | O4: 1.306668 | P4: 1.3356569 | Q4: 1.3658072 | R4: 1.3970906 | S4: 1.4294313 | T4: 1.4628618 | U4: 1.4974028 | V4: 1.5330655 | W4: 1.5698545 | X4: 1.6077702 | Y4: 1.6468101 | Z4: 1.6869697 | AA4: 1.7282423 | AB4: 1.7706198 | AC4: 1.8140921 | AD4: 1.8586473 | AE4: 1.9042716 | AF4: 1.9509492 | AG4: 1.9986623 | AH4: 2.0473909 | AI4: 2.0971133 | AJ4: 2.1478055 | AK4: 2.1994422
A5: pch_0 | B5: 1 | C5: 1.0198987 | D5: 1.0400695 | E5: 1.0605437 | F5: 1.0813678 | G5: 1.1025858 | H5: 1.1242353 | I5: 1.146347 | J5: 1.1689465 | K5: 1.1920554 | L5: 1.2156926 | M5: 1.2398742 | N5: 1.2646147 | O5: 1.2899264 | P5: 1.3158205 | Q5: 1.3423069 | R5: 1.3693946 | S5: 1.397092 | T5: 1.4254069 | U5: 1.454347 | V5: 1.4839199 | W5: 1.5141329 | X5: 1.5449937 | Y5: 1.5765098 | Z5: 1.6086892 | AA5: 1.64154 | AB5: 1.6750706 | AC5: 1.7092899 | AD5: 1.744207 | AE5: 1.7798315 | AF5: 1.8161737 | AG5: 1.8532442 | AH5: 1.891054 | AI5: 1.9296152 | AJ5: 1.9689399 | AK5: 2.0090411
A6: ch_cagr_2 | B6: 31638 | C6: 31926.31 | D6: 32213.197 | E6: 32523.423 | F6: 32862.586 | G6: 33229.322 | H6: 33619.294 | I6: 34027.869 | J6: 34452.106 | K6: 34890.056 | L6: 35340.462 | M6: 35802.578 | N6: 36276.022 | O6: 36760.672 | P6: 37256.589 | Q6: 37763.954 | R6: 38281.902 | S6: 38809.112 | T6: 39345.253 | U6: 39890.278 | V6: 40444.218 | W6: 41007.104 | X6: 41578.934 | Y6: 42159.649 | Z6: 42749.123 | AA6: 43347.155 | AB6: 43953.48 | AC6: 44567.773 | AD6: 45189.661 | AE6: 45818.735 | AF6: 46454.567 | AG6: 47096.717 | AH6: 47744.75 | AI6: 48398.241 | AJ6: 49056.784 | AK6: 49720
A7: ch_cagr_0 | B7: 31638 | C7: 31923.619 | D7: 32206.85 | E7: 32512.452 | F7: 32845.535 | G7: 33204.073 | H7: 33584.186 | I7: 33982.118 | J7: 34394.806 | K7: 34819.912 | L7: 35255.71 | M7: 35700.938 | N7: 36154.696 | O7: 36616.348 | P7: 37085.46 | Q7: 37561.74 | R7: 38045 | S7: 38535.116 | T7: 39032.007 | U7: 39535.611 | V7: 40045.87 | W7: 40562.729 | X7: 41086.13 | Y7: 41616.009 | Z7: 42152.303 | AA7: 42694.952 | AB7: 43243.898 | AC7: 43799.093 | AD7: 44360.5 | AE7: 44928.092 | AF7: 45501.861 | AG7: 46081.809 | AH7: 46667.955 | AI7: 47260.332 | AJ7: 47858.988 | AK7: 48463.982
A8: pch_cagr_2 | B8: 1 | C8: 1.0200639 | D8: 1.0405389 | E8: 1.0614615 | F8: 1.0829052 | G8: 1.1049599 | H8: 1.1276481 | I8: 1.1509345 | J8: 1.1748158 | K8: 1.199313 | L8: 1.2244675 | M8: 1.2503383 | N8: 1.2769998 | O8: 1.3045398 | P8: 1.3330585 | Q8: 1.3626678 | R8: 1.3934134 | S8: 1.4252695 | T8: 1.4582214 | U8: 1.4922613 | V8: 1.5273867 | W8: 1.5635984 | X8: 1.6008996 | Y8: 1.6392947 | Z8: 1.6787882 | AA8: 1.7193843 | AB8: 1.761086 | AC8: 1.8038952 | AD8: 1.8478127 | AE8: 1.8928376 | AF8: 1.9389678 | AG8: 1.9861998 | AH8: 2.0345289 | AI8: 2.0839489 | AJ8: 2.1344525 | AK8: 2.1860311
A9: pch_cagr_0 | B9: 1 | C9: 1.0199097 | D9: 1.0401102 | E9: 1.0606346 | F9: 1.0815269 | G9: 1.1028261 | H9: 1.1245631 | I9: 1.1467626 | J9: 1.1694451 | K9: 1.1926287 | L9: 1.2163293 | M9: 1.2405618 | N9: 1.2653394 | O9: 1.2906742 | P9: 1.3165769 | Q9: 1.3430574 | R9: 1.3701249 | S9: 1.3977879 | T9: 1.4260546 | U9: 1.454933 | V9: 1.484431 | W9: 1.5145566 | X9: 1.545318 | Y9: 1.5767236 | Z9: 1.6087819 | AA9: 1.6415018 | AB9: 1.6748927 | AC9: 1.7089641 | AD9: 1.743726 | AE9: 1.7791888 | AF9: 1.8153636 | AG9: 1.8522615 | AH9: 1.8898946 | AI9: 1.9282753 | AJ9: 1.9674164 | AK9: 2.0073314
A10: ch_cfoo_2 | B10: 175065 | C10: 176666.16 | D10: 178264.86 | E10: 179996.63 | F10: 181891.89 | G10: 183943.73 | H10: 186127.19 | I10: 188413.71 | J10: 190785.17 | K10: 193230.44 | L10: 195743.51 | M10: 198321.9 | N10: 200965.57 | O10: 203676.02 | P10: 206455.7 | Q10: 209307.62 | R10: 212226.59 | S10: 215202.14 | T10: 218229.36 | U10: 221305.91 | V10: 224430.76 | W10: 227603.65 | X10: 230824.58 | Y10: 234093.49 | Z10: 237410.01 | AA10: 240773.44 | AB10: 244182.66 | AC10: 247636.18 | AD10: 251132.22 | AE10: 254668.74 | AF10: 258243.57 | AG10: 261854.44 | AH10: 265499.09 | AI10: 269175.31 | AJ10: 272880.98 | AK10: 276614.12
A11: ch_cfoo_0 | B11: 175065 | C11: 176646.38 | D11: 178215.6 | E11: 179909.34 | F11: 181755.53 | G11: 183742.79 | H11: 185849.61 | I11: 188055.15 | J11: 190342.38 | K11: 192698.22 | L11: 195112.91 | M11: 197579.31 | N11: 200092.24 | O11: 202648.04 | P11: 205244.23 | Q11: 207879.16 | R11: 210551.78 | S11: 213261.44 | T11: 216007.75 | U11: 218790.43 | V11: 221609.24 | W11: 224463.97 | X11: 227354.36 | Y11: 230280.16 | Z11: 233241.08 | AA11: 236236.84 | AB11: 239267.21 | AC11: 242331.96 | AD11: 245430.95 | AE11: 248564.07 | AF11: 251731.31 | AG11: 254932.73 | AH11: 258168.46 | AI11: 261438.72 | AJ11: 264743.79 | AK11: 268084.01
A12: pch_cfoo_2 | B12: 1 | C12: 1.0199649 | D12: 1.0402867 | E12: 1.061021 | F12: 1.0822382 | G12: 1.104012 | H12: 1.1263853 | I12: 1.1493667 | J12: 1.1729656 | K12: 1.1971968 | L12: 1.2220847 | M12: 1.2476654 | N12: 1.2739879 | O12: 1.3011135 | P12: 1.329116 | Q12: 1.3580812 | R12: 1.3880724 | S12: 1.4191165 | T12: 1.4512298 | U12: 1.484421 | V12: 1.5186944 | W12: 1.5540522 | X12: 1.590496 | Y12: 1.6280268 | Z12: 1.666645 | AA12: 1.7063505 | AB12: 1.7471425 | AC12: 1.7890191 | AD12: 1.8319773 | AE12: 1.8760131 | AF12: 1.9211212 | AG12: 1.9672951 | AH12: 2.014527 | AI12: 2.062808 | AJ12: 2.1121278 | AK12: 2.1624752
... A105: pch_cbio_0 | B105: 1 | C105: 1.0194853 | D105: 1.0388851 | E105: 1.0584794 | F105: 1.0785234 | G105: 1.0991574 | H105: 1.1204202 | I105: 1.1422939 | J105: 1.1647423 | K105: 1.1877351 | L105: 1.2112565 | M105: 1.2353062 | N105: 1.2598952 | O105: 1.2850411 | P105: 1.3107638 | Q105: 1.337083 | R105: 1.3640167 | S105: 1.3915798 | T105: 1.4197853 | U105: 1.4486433 | V105: 1.4781629 | W105: 1.5083515 | X105: 1.5392164 | Y105: 1.5707642 | Z105: 1.6030015 | AA105: 1.635935 | AB105: 1.6695716 | AC105: 1.7039186 | AD105: 1.7389836 | AE105: 1.7747749 | AF105: 1.811301 | AG105: 1.8485712 | AH105: 1.8865955 | AI105: 1.9253844 | AJ105: 1.964949 | AK105: 2.0053012

Sheet Value_Added
A1: _date_ | B1: 42005 | C1: 42370 | D1: 42736 | E1: 43101 | F1: 43466 | G1: 43831 | H1: 44197 | I1: 44562 | J1: 44927 | K1: 45292 | L1: 45658 | M1: 46023 | N1: 46388 | O1: 46753 | P1: 47119 | Q1: 47484 | R1: 47849 | S1: 48214 | T1: 48580 | U1: 48945 | V1: 49310 | W1: 49675 | X1: 50041 | Y1: 50406 | Z1: 50771 | AA1: 51136 | AB1: 51502 | AC1: 51867 | AD1: 52232 | AE1: 52597 | AF1: 52963 | AG1: 53328 | AH1: 53693 | AI1: 54058 | AJ1: 54424 | AK1: 54789
A2: va_2 | B2: 1965592.2 | C2: 1986968.8 | D2: 2008413.6 | E2: 2030342 | F2: 2052886.4 | G2: 2076074.3 | H2: 2099860.4 | I2: 2124162.5 | J2: 2148918.1 | K2: 2174086.1 | L2: 2199645.8 | M2: 2225591.9 | N2: 2251928.9 | O2: 2278665.6 | P2: 2305811.5 | Q2: 2333373.8 | R2: 2361326.1 | S2: 2389613.7 | T2: 2418196.2 | U2: 2447047.2 | V2: 2476153.4 | W2: 2505512.1 | X2: 2535127.5 | Y2: 2565007.8 | Z2: 2595162 | AA2: 2625599.3 | AB2: 2656327.6 | AC2: 2687353.6 | AD2: 2718682.7 | AE2: 2750319.1 | AF2: 2782266.5 | AG2: 2814528 | AH2: 2847106.6 | AI2: 2880005.5 | AJ2: 2913228.1 | AK2: 2946778.5
A3: va_0 | B3: 1965592.2 | C3: 1986885.6 | D3: 2008191.4 | E3: 2029937.4 | F3: 2052257.8 | G3: 2075171.5 | H3: 2098653.7 | I3: 2122664 | J3: 2147158.9 | K3: 2172097.9 | L3: 2197445.8 | M3: 2223174.1 | N3: 2249260.8 | O3: 2275690.3 | P3: 2302452.2 | Q3: 2329540.4 | R3: 2356952 | S3: 2384686.5 | T3: 2412744.9 | U3: 2441129.2 | V3: 2469841.7 | W3: 2498885 | X3: 2528261.8 | Y3: 2557974.8 | Z3: 2588026.6 | AA3: 2618419.7 | AB3: 2649156.8 | AC3: 2680240.9 | AD3: 2711674.8 | AE3: 2743461.8 | AF3: 2775605.2 | AG3: 2808108.9 | AH3: 2840976.6 | AI3: 2874212.5 | AJ3: 2907821.1 | AK3: 2941806.7
A4: va_sagr_2 | B4: 30790.815 | C4: 31102.121 | D4: 31419.057 | E4: 31754.134 | F4: 32109.395 | G4: 32483.963 | H4: 32874.552 | I4: 33277.044 | J4: 33689.089 | K4: 34109.509 | L4: 34537.901 | M4: 34974.344 | N4: 35419.185 | O4: 35872.872 | P4: 36335.826 | Q4: 36808.35 | R4: 37289.07 | S4: 37775.573 | T4: 38266.453 | U4: 38760.893 | V4: 39258.455 | W4: 39758.947 | X4: 40262.325 | Y4: 40768.62 | Z4: 41277.892 | AA4: 41790.209 | AB4: 42305.626 | AC4: 42824.186 | AD4: 43345.921 | AE4: 43870.853 | AF4: 44399 | AG4: 44930.385 | AH4: 45465.039 | AI4: 46003.005 | AJ4: 46544.343 | AK4: 47089.131
A5: va_sagr_0 | B5: 30790.815 | C5: 31097.824 | D5: 31408.103 | E5: 31734.666 | F5: 32079.262 | G5: 32440.277 | H5: 32815.402 | I5: 33202.492 | J5: 33599.776 | K5: 34005.861 | L5: 34419.667 | M5: 34840.377 | N5: 35267.383 | O5: 35700.251 | P5: 36138.684 | Q5: 36582.491 | R5: 37031.564 | S5: 37485.852 | T5: 37945.343 | U5: 38410.05 | V5: 38880 | W5: 39355.225 | X5: 39835.764 | Y5: 40321.654 | Z5: 40812.934 | AA5: 41309.645 | AB5: 41811.83 | AC5: 42319.535 | AD5: 42832.812 | AE5: 43351.717 | AF5: 43876.312 | AG5: 44406.665 | AH5: 44942.85 | AI5: 45484.945 | AJ5: 46033.034 | AK5: 46587.204
A6: va_sfor_2 | B6: 5288.8126 | C6: 5297.6409 | D6: 5287.0242 | E6: 5269.4674 | F6: 5249.0738 | G6: 5226.4599 | H6: 5203.6412 | I6: 5183.1236 | J6: 5164.983 | K6: 5148.4161 | L6: 5132.3637 | M6: 5115.7675 | N6: 5097.6778 | O6: 5077.3026 | P6: 5054.0352 | Q6: 5027.4696 | R6: 4998.888 | S6: 4970.3273 | T6: 4942.6378 | U6: 4916.1591 | V6: 4891.0102 | W6: 4867.2183 | X6: 4844.7753 | Y6: 4823.6611 | Z6: 4803.8527 | AA6: 4785.3279 | AB6: 4768.0666 | AC6: 4752.0504 | AD6: 4737.2637 | AE6: 4723.6927 | AF6: 4711.3259 | AG6: 4700.1536 | AH6: 4690.1678 | AI6: 4681.3618 | AJ6: 4673.7304 | AK6: 4667.2688
A7: va_sfor_0 | B7: 5288.8126 | C7: 5304.0347 | D7: 5302.0192 | E7: 5294.5751 | F7: 5286.4854 | G7: 5279.4506 | H7: 5273.8914 | I7: 5269.7509 | J7: 5266.835 | K7: 5264.9431 | L7: 5263.9093 | M7: 5263.6084 | N7: 5263.9504 | O7: 5264.872 | P7: 5266.329 | Q7: 5268.2912 | R7: 5270.738 | S7: 5273.6553 | T7: 5277.0329 | U7: 5280.8561 | V7: 5285.1182 | W7: 5289.8172 | X7: 5294.9534 | Y7: 5300.5286 | Z7: 5306.5452 | AA7: 5313.0062 | AB7: 5319.9145 | AC7: 5327.2731 | AD7: 5335.0852 | AE7: 5343.3539 | AF7: 5352.0818 | AG7: 5361.2718 | AH7: 5370.9267 | AI7: 5381.049 | AJ7: 5391.6415 | AK7: 5402.7065
A8: va_sfoo_2 | B8: 43654.88 | C8: 44079.936 | D8: 44521.727 | E8: 44993.424 | F8: 45494.719 | G8: 46023.142 | H8: 46573.909 | I8: 47141.713 | J8: 47723.764 | K8: 48318.566 | L8: 48925.513 | M8: 49544.597 | N8: 50176.168 | O8: 50820.758 | P8: 51478.946 | Q8: 52151.259 | R8: 52835.967 | S8: 53530.077 | T8: 54232.126 | U8: 54941.241 | V8: 55656.953 | W8: 56379.069 | X8: 57107.556 | Y8: 57842.463 | Z8: 58583.858 | AA8: 59331.792 | AB8: 60086.291 | AC8: 60847.343 | AD8: 61614.904 | AE8: 62388.908 | AF8: 63169.273 | AG8: 63955.913 | AH8: 64748.748 | AI8: 65547.712 | AJ8: 66352.755 | AK8: 67163.854
A9: va_sfoo_0 | B9: 43654.88 | C9: 44074.319 | D9: 44508.113 | E9: 44969.764 | F9: 45458.475 | G9: 45970.837 | H9: 46503.401 | I9: 47053.24 | J9: 47617.99 | K9: 48195.765 | L9: 48785.077 | M9: 49384.768 | N9: 49993.956 | O9: 50611.993 | P9: 51238.424 | Q9: 51872.946 | R9: 52515.37 | S9: 53165.593 | T9: 53823.57 | U9: 54489.29 | V9: 55162.761 | W9: 55844.004 | X9: 56533.043 | Y9: 57229.907 | Z9: 57934.625 | AA9: 58647.231 | AB9: 59367.763 | AC9: 60096.266 | AD9: 60832.792 | AE9: 61577.404 | AF9: 62330.173 | AG9: 63091.181 | AH9: 63860.521 | AI9: 64638.292 | AJ9: 65424.606 | AK9: 66219.579
A10: va_sveh_2 | B10: 29847.895 | C10: 30404.587 | D10: 30932.187 | E10: 31407.735 | F10: 31839.728 | G10: 32241.105 | H10: 32625.553 | I10: 33003.168 | J10: 33377.546 | K10: 33750.08 | L10: 34121.255 | M10: 34491.104 | N10: 34859.407 | O10: 35225.772 | P10: 35589.677 | Q10: 35950.484 | R10: 36310.352 | S10: 36671.833 | T10: 37034.291 | U10: 37396.91 | V10: 37759.181 | W10: 38120.88 | X10: 38481.977 | Y10: 38842.569 | Z10: 39202.823 | AA10: 39562.948 | AB10: 39923.177 | AC10: 40283.761 | AD10: 40644.964 | AE10: 41007.063 | AF10: 41370.349 | AG10: 41735.131 | AH10: 42101.732 | AI10: 42470.491 | AJ10: 42841.762 | AK10: 43215.914
A11: va_sveh_0 | B11: 29847.895 | C11: 30410.564 | D11: 30943.516 | E11: 31424.184 | F11: 31862.492 | G11: 32272.71 | H11: 32666.675 | I11: 33052.509 | J11: 33435.21 | K11: 33817.628 | L11: 34201.287 | M11: 34586.961 | N11: 34975.033 | O11: 35365.692 | P11: 35759.05 | Q11: 36155.19 | R11: 36554.191 | S11: 36956.134 | T11: 37361.107 | U11: 37769.204 | V11: 38180.52 | W11: 38595.157 | X11: 39013.219 | Y11: 39434.812 | Z11: 39860.048 | AA11: 40289.04 | AB11: 40721.904 | AC11: 41158.757 | AD11: 41599.719 | AE11: 42044.908 | AF11: 42494.445 | AG11: 42948.446 | AH11: 43407.029 | AI11: 43870.308 | AJ11: 44338.393 | AK11: 44811.394
A12: va_sgla_2 | B12: 7902.1978 | C12: 7989.9781 | D12: 8077.9673 | E12: 8167.4463 | F12: 8259.0631 | G12: 8353.0815 | H12: 8449.1995 | I12: 8546.8972 | J12: 8645.9433 | K12: 8746.2661 | L12: 8847.8532 | M12: 8950.6893 | N12: 9054.7153 | O12: 9159.7968 | P12: 9265.6991 | Q12: 9372.0664 | R12: 9478.3521 | S12: 9584.0627 | T12: 9688.973 | U12: 9793.024 | V12: 9896.2505 | W12: 9998.7375 | X12: 10100.594 | Y12: 10201.936 | Z12: 10302.88 | AA12: 10403.535 | AB12: 10504.006 | AC12: 10604.387 | AD12: 10704.768 | AE12: 10805.231 | AF12: 10905.857 | AG12: 11006.72 | AH12: 11107.896 | AI12: 11209.455 | AJ12: 11311.471 | AK12: 11414.014
... A67: va_seot_0 | B67: -1480.3314 | C67: -1490.5267 | D67: -1497.2435 | E67: -1502.8979 | F67: -1508.5963 | G67: -1514.7252 | H67: -1521.3568 | I67: -1528.4495 | J67: -1535.9338 | K67: -1543.7453 | L67: -1551.8335 | M67: -1560.1623 | N67: -1568.707 | O67: -1577.4517 | P67: -1586.3866 | Q67: -1595.5058 | R67: -1604.8064 | S67: -1614.2858 | T67: -1623.9427 | U67: -1633.7773 | V67: -1643.7906 | W67: -1653.9841 | X67: -1664.3595 | Y67: -1674.9185 | Z67: -1685.6629 | AA67: -1696.5943 | AB67: -1707.7147 | AC67: -1719.0257 | AD67: -1730.5295 | AE67: -1742.2279 | AF67: -1754.1229 | AG67: -1766.2169 | AH67: -1778.5121 | AI67: -1791.0109 | AJ67: -1803.7156 | AK67: -1816.6289

Sheet INV
A1: _date_ | B1: 42005 | C1: 42370 | D1: 42736 | E1: 43101 | F1: 43466 | G1: 43831 | H1: 44197 | I1: 44562 | J1: 44927 | K1: 45292 | L1: 45658 | M1: 46023 | N1: 46388 | O1: 46753 | P1: 47119 | Q1: 47484 | R1: 47849 | S1: 48214 | T1: 48580 | U1: 48945 | V1: 49310 | W1: 49675 | X1: 50041 | Y1: 50406 | Z1: 50771 | AA1: 51136 | AB1: 51502 | AC1: 51867 | AD1: 52232 | AE1: 52597 | AF1: 52963 | AG1: 53328 | AH1: 53693 | AI1: 54058 | AJ1: 54424 | AK1: 54789
A2: ia_2 | B2: 472647 | C2: 478019.4 | D2: 483383.02 | E2: 488765.23 | F2: 494190.78 | G2: 499675.43 | H2: 505236.8 | I2: 510891.29 | J2: 516642.91 | K2: 522488.85 | L2: 528423.65 | M2: 534441.35 | N2: 540536.13 | O2: 546702.37 | P2: 552934.37 | Q2: 559226.23 | R2: 565579.52 | S2: 572000.88 | T2: 578492.4 | U2: 585054.38 | V2: 591687.29 | W2: 598392.57 | X2: 605172.52 | Y2: 612029.89 | Z2: 618967.37 | AA2: 625987.28 | AB2: 633091.27 | AC2: 640280.33 | AD2: 647554.73 | AE2: 654914.12 | AF2: 662357.64 | AG2: 669884.02 | AH2: 677491.71 | AI2: 685178.96 | AJ2: 692943.93 | AK2: 700784.7
A3: ia_0 | B3: 472647 | C3: 478041.55 | D3: 483438.29 | E3: 488861.72 | F3: 494339.57 | G3: 499893.34 | H3: 505536.92 | I3: 511277.46 | J3: 517117.16 | K3: 523055.07 | L3: 529088.68 | M3: 535215.11 | N3: 541431.74 | O3: 547736.65 | P3: 554128.65 | Q3: 560607.27 | R3: 567172.56 | S3: 573824.98 | T3: 580565.17 | U3: 587393.88 | V3: 594311.81 | W3: 601319.58 | X3: 608417.66 | Y3: 615606.41 | Z3: 622886.05 | AA3: 630256.67 | AB3: 637718.3 | AC3: 645270.89 | AD3: 652914.38 | AE3: 660648.67 | AF3: 668473.69 | AG3: 676389.4 | AH3: 684395.78 | AI3: 692492.88 | AJ3: 700680.78 | AK3: 708959.66
A4: ia_sagr_2 | B4: 4271.7493 | C4: 4316.7096 | D4: 4359.9715 | E4: 4403.7215 | F4: 4449.0584 | G4: 4496.2419 | H4: 4545.1965 | I4: 4595.7611 | J4: 4647.7303 | K4: 4700.9187 | L4: 4755.1656 | M4: 4810.3252 | N4: 4866.256 | O4: 4922.8133 | P4: 4979.846 | Q4: 5037.1969 | R4: 5094.7575 | S4: 5152.4716 | T4: 5210.3059 | U4: 5268.2618 | V4: 5326.3668 | W4: 5384.6627 | X4: 5443.1973 | Y4: 5502.0171 | Z4: 5561.1639 | AA4: 5620.6724 | AB4: 5680.5697 | AC4: 5740.876 | AD4: 5801.6056 | AE4: 5862.7681 | AF4: 5924.3701 | AG4: 5986.4163 | AH4: 6048.9107 | AI4: 6111.8578 | AJ4: 6175.2633 | AK4: 6239.1344
A5: ia_sagr_0 | B5: 4271.7493 | C5: 4316.9191 | D5: 4360.566 | E5: 4404.9143 | F5: 4451.1227 | G5: 4499.5274 | H5: 4550.0535 | I5: 4602.4822 | J5: 4656.5777 | K5: 4712.1351 | L5: 4768.9905 | M5: 4827.0179 | N5: 4886.1226 | O5: 4946.2347 | P5: 5007.3037 | Q5: 5069.2935 | R5: 5132.1794 | S5: 5195.9442 | T5: 5260.5762 | U5: 5326.0669 | V5: 5392.4095 | W5: 5459.5977 | X5: 5527.6258 | Y5: 5596.4876 | Z5: 5666.1769 | AA5: 5736.6876 | AB5: 5808.0139 | AC5: 5880.1505 | AD5: 5953.0927 | AE5: 6026.8371 | AF5: 6101.3814 | AG5: 6176.7244 | AH5: 6252.8665 | AI5: 6329.8095 | AJ5: 6407.5565 | AK5: 6486.112
A6: ia_sfor_2 | B6: 166.90527 | C6: 167.66273 | D6: 167.53761 | E6: 166.89591 | F6: 165.94733 | G6: 164.77096 | H6: 163.44791 | I6: 162.07868 | J6: 160.70813 | K6: 159.33944 | L6: 157.95352 | M6: 156.52185 | N6: 155.01357 | O6: 153.3995 | P6: 151.6547 | Q6: 149.76011 | R6: 147.74315 | S6: 145.66777 | T6: 143.58093 | U6: 141.51185 | V6: 139.47832 | W6: 137.49155 | X6: 135.55908 | Y6: 133.68627 | Z6: 131.87707 | AA6: 130.13447 | AB6: 128.46073 | AC6: 126.85751 | AD6: 125.32602 | AE6: 123.86707 | AF6: 122.48118 | AG6: 121.16856 | AH6: 119.92923 | AI6: 118.76301 | AJ6: 117.66956 | AK6: 116.64838
A7: ia_sfor_0 | B7: 166.90527 | C7: 167.83885 | D7: 168.02018 | E7: 167.78375 | F7: 167.34781 | G7: 166.825 | H7: 166.26615 | I7: 165.69193 | J7: 165.1102 | K7: 164.52429 | L7: 163.93643 | M7: 163.34897 | N7: 162.76463 | O7: 162.18645 | P7: 161.61757 | Q7: 161.06114 | R7: 160.52017 | S7: 159.99749 | T7: 159.49567 | U7: 159.01687 | V7: 158.56304 | W7: 158.13598 | X7: 157.7373 | Y7: 157.36842 | Z7: 157.03058 | AA7: 156.72481 | AB7: 156.452 | AC7: 156.21287 | AD7: 156.00797 | AE7: 155.83776 | AF7: 155.70255 | AG7: 155.60254 | AH7: 155.53783 | AI7: 155.50847 | AJ7: 155.51438 | AK7: 155.55545
A8: ia_sfoo_2 | B8: 6742.5992 | C8: 6812.5373 | D8: 6879.7436 | E8: 6948.0473 | F8: 7019.2166 | G8: 7093.6077 | H8: 7171.0809 | I8: 7251.3764 | J8: 7334.1298 | K8: 7419.0043 | L8: 7505.7123 | M8: 7594.0036 | N8: 7683.6463 | O8: 7774.4099 | P8: 7866.056 | Q8: 7958.3332 | R8: 8051.0963 | S8: 8144.2918 | T8: 8237.8571 | U8: 8331.7653 | V8: 8426.0239 | W8: 8520.6654 | X8: 8615.7342 | Y8: 8711.2762 | Z8: 8807.331 | AA8: 8903.9278 | AB8: 9001.0839 | AC8: 9098.805 | AD8: 9197.0869 | AE8: 9295.9174 | AF8: 9395.2792 | AG8: 9495.1519 | AH8: 9595.5143 | AI8: 9696.3466 | AJ8: 9797.6313 | AK8: 9899.3546
A9: ia_sfoo_0 | B9: 6742.5992 | C9: 6812.918 | D9: 6880.7425 | E9: 6949.9349 | F9: 7022.3561 | G9: 7098.4844 | H9: 7178.1486 | I9: 7260.9658 | J9: 7346.5408 | K9: 7434.5354 | L9: 7524.6819 | M9: 7616.7752 | N9: 7710.662 | O9: 7806.229 | P9: 7903.3949 | Q9: 8002.1017 | R9: 8102.309 | S9: 8203.9889 | T9: 8307.1212 | U9: 8411.6904 | V9: 8517.6829 | W9: 8625.0857 | X9: 8733.8854 | Y9: 8844.0679 | Z9: 8955.6185 | AA9: 9068.5224 | AB9: 9182.7648 | AC9: 9298.3317 | AD9: 9415.2105 | AE9: 9533.3901 | AF9: 9652.8617 | AG9: 9773.6184 | AH9: 9895.6561 | AI9: 10018.973 | AJ9: 10143.57 | AK9: 10269.45
A10: ia_sveh_2 | B10: 36330.779 | C10: 36892.942 | D10: 37526.468 | E10: 38158.801 | F10: 38755.612 | G10: 39309.742 | H10: 39828.945 | I10: 40325.527 | J10: 40808.622 | K10: 41283.532 | L10: 41752.811 | M10: 42217.352 | N10: 42677.119 | O10: 43131.574 | P10: 43579.903 | Q10: 44021.124 | R10: 44456.363 | S10: 44888.381 | T10: 45318.431 | U10: 45746.632 | V10: 46172.716 | W10: 46596.448 | X10: 47017.775 | Y10: 47436.821 | Z10: 47853.844 | AA10: 48269.188 | AB10: 48683.247 | AC10: 49096.444 | AD10: 49509.218 | AE10: 49922.024 | AF10: 50335.33 | AG10: 50749.622 | AH10: 51165.401 | AI10: 51583.189 | AJ10: 52003.525 | AK10: 52426.966
A11: ia_sveh_0 | B11: 36330.779 | C11: 36897.67 | D11: 37538.383 | E11: 38179.071 | F11: 38785.78 | G11: 39352.655 | H11: 39886.731 | I11: 40398.196 | J11: 40895.934 | K11: 41386.273 | L11: 41873.185 | M11: 42358.932 | N11: 42844.703 | O11: 43331.081 | P11: 43818.353 | Q11: 44306.685 | R11: 44796.209 | S11: 45287.066 | T11: 45779.416 | U11: 46273.439 | V11: 46769.334 | W11: 47267.315 | X11: 47767.605 | Y11: 48270.436 | Z11: 48776.045 | AA11: 49284.675 | AB11: 49796.575 | AC11: 50311.993 | AD11: 50831.181 | AE11: 51354.391 | AF11: 51881.875 | AG11: 52413.881 | AH11: 52950.655 | AI11: 53492.438 | AJ11: 54039.466 | AK11: 54591.969
A12: ia_sgla_2 | B12: 1455.1731 | C12: 1471.1513 | D12: 1486.6169 | E12: 1501.7673 | F12: 1516.7126 | G12: 1531.4382 | H12: 1545.9808 | I12: 1560.4684 | J12: 1574.9832 | K12: 1589.5514 | L12: 1604.1432 | M12: 1618.6789 | N12: 1633.0376 | O12: 1647.0672 | P12: 1660.5936 | Q12: 1673.4295 | R12: 1685.4934 | S12: 1696.8387 | T12: 1707.5528 | U12: 1717.7333 | V12: 1727.4753 | W12: 1736.8655 | X12: 1745.9804 | Y12: 1754.8868 | Z12: 1763.6424 | AA12: 1772.2975 | AB12: 1780.8958 | AC12: 1789.4757 | AD12: 1798.0715 | AE12: 1806.714 | AF12: 1815.4312 | AG12: 1824.2489 | AH12: 1833.191 | AI12: 1842.2802 | AJ12: 1851.5377 | AK12: 1860.9836
... A67: ia_seot_0 | B67: 5.8965451 | C67: 5.9435415 | D67: 5.9746936 | E67: 5.9973905 | F67: 6.0165458 | G67: 6.0346676 | H67: 6.0528256 | I67: 6.0713854 | J67: 6.0904218 | K67: 6.1099175 | L67: 6.1298472 | M67: 6.1502059 | N67: 6.1710133 | O67: 6.1923096 | P67: 6.2141489 | Q67: 6.236594 | R67: 6.2597107 | S67: 6.2835615 | T67: 6.3082054 | U67: 6.3337001 | V67: 6.3601007 | W67: 6.3874582 | X67: 6.4158197 | Y67: 6.4452276 | Z67: 6.4757198 | AA67: 6.5073303 | AB67: 6.5400893 | AC67: 6.5740236 | AD67: 6.6091568 | AE67: 6.6455101 | AF67: 6.6831022 | AG67: 6.7219495 | AH67: 6.7620667 | AI67: 6.8034665 | AJ67: 6.8461602 | AK67: 6.8901578

Sheet Labor
A1: _date_ | B1: 42005 | C1: 42370 | D1: 42736 | E1: 43101 | F1: 43466 | G1: 43831 | H1: 44197 | I1: 44562 | J1: 44927 | K1: 45292 | L1: 45658 | M1: 46023 | N1: 46388 | O1: 46753 | P1: 47119 | Q1: 47484 | R1: 47849 | S1: 48214 | T1: 48580 | U1: 48945 | V1: 49310 | W1: 49675 | X1: 50041 | Y1: 50406 | Z1: 50771 | AA1: 51136 | AB1: 51502 | AC1: 51867 | AD1: 52232 | AE1: 52597 | AF1: 52963 | AG1: 53328 | AH1: 53693 | AI1: 54058 | AJ1: 54424 | AK1: 54789
A2: f_l_2 | B2: 27390.88 | C2: 27450.174 | D2: 27503.566 | E2: 27556.49 | F2: 27613.073 | G2: 27675.654 | H2: 27744.658 | I2: 27819.069 | J2: 27897.548 | K2: 27978.951 | L2: 28062.513 | M2: 28147.869 | N2: 28234.974 | O2: 28324.012 | P2: 28415.29 | Q2: 28509.16 | R2: 28605.493 | S2: 28703.505 | T2: 28802.308 | U2: 28901.143 | V2: 28999.468 | W2: 29096.964 | X2: 29193.491 | Y2: 29289.039 | Z2: 29383.677 | AA2: 29477.506 | AB2: 29570.634 | AC2: 29663.158 | AD2: 29755.155 | AE2: 29846.68 | AF2: 29937.768 | AG2: 30028.438 | AH2: 30118.701 | AI2: 30208.56 | AJ2: 30298.018 | AK2: 30387.076
A3: f_l_0 | B3: 27390.88 | C3: 27448.862 | D3: 27499.539 | E3: 27548.51 | F3: 27599.973 | G3: 27656.135 | H3: 27717.672 | I3: 27784.329 | J3: 27855.384 | K3: 27929.95 | L3: 28007.151 | M3: 28086.22 | N3: 28166.532 | O3: 28247.612 | P3: 28329.119 | Q3: 28410.825 | R3: 28492.59 | S3: 28574.336 | T3: 28656.032 | U3: 28737.669 | V3: 28819.257 | W3: 28900.808 | X3: 28982.338 | Y3: 29063.857 | Z3: 29145.376 | AA3: 29226.899 | AB3: 29308.431 | AC3: 29389.972 | AD3: 29471.523 | AE3: 29553.086 | AF3: 29634.662 | AG3: 29716.255 | AH3: 29797.868 | AI3: 29879.506 | AJ3: 29961.176 | AK3: 30042.885
A4: f_l_sagr_2 | B4: 732.13 | C4: 733.53268 | D4: 734.74367 | E4: 736.10273 | F4: 737.85588 | G4: 740.14183 | H4: 742.95251 | I4: 746.15883 | J4: 749.62816 | K4: 753.26911 | L4: 757.0411 | M4: 760.94855 | N4: 765.02987 | O4: 769.34626 | P4: 773.97192 | Q4: 778.98656 | R4: 784.40725 | S4: 790.16517 | T4: 796.17248 | U4: 802.35009 | V4: 808.63628 | W4: 814.98691 | X4: 821.37235 | Y4: 827.7736 | Z4: 834.17879 | AA4: 840.58038 | AB4: 846.97323 | AC4: 853.35333 | AD4: 859.71706 | AE4: 866.06082 | AF4: 872.38092 | AG4: 878.67356 | AH4: 884.93497 | AI4: 891.16149 | AJ4: 897.34967 | AK4: 903.49638
A5: f_l_sagr_0 | B5: 732.13 | C5: 733.35856 | D5: 734.20074 | E5: 735.0077 | F5: 736.0202 | G5: 737.34214 | H5: 738.98236 | I5: 740.90022 | J5: 743.03725 | K5: 745.33488 | L5: 747.74248 | M5: 750.21993 | N5: 752.73732 | O5: 755.27355 | P5: 757.81456 | Q5: 760.35166 | R5: 762.87995 | S5: 765.39723 | T5: 767.90295 | U5: 770.39754 | V5: 772.8819 | W5: 775.35709 | X5: 777.82412 | Y5: 780.28388 | Z5: 782.73708 | AA5: 785.18432 | AB5: 787.62605 | AC5: 790.06269 | AD5: 792.49463 | AE5: 794.92225 | AF5: 797.34598 | AG5: 799.76628 | AH5: 802.18366 | AI5: 804.59868 | AJ5: 807.01191 | AK5: 809.42398
A6: f_l_sfor_2 | B6: 29.08 | C6: 28.987581 | D6: 28.749051 | E6: 28.421798 | F6: 28.052146 | G6: 27.666529 | H6: 27.283069 | I6: 26.916018 | J6: 26.570698 | K6: 26.245682 | L6: 25.935992 | M6: 25.6355 | N6: 25.338373 | O6: 25.039805 | P6: 24.736325 | Q6: 24.425862 | R6: 24.111142 | S6: 23.798728 | T6: 23.49378 | U6: 23.199184 | V6: 22.916058 | W6: 22.644446 | X6: 22.383852 | Y6: 22.133587 | Z6: 21.892942 | AA6: 21.661276 | AB6: 21.438039 | AC6: 21.222769 | AD6: 21.015082 | AE6: 20.814656 | AF6: 20.621216 | AG6: 20.434524 | AH6: 20.254368 | AI6: 20.080557 | AJ6: 19.912915 | AK6: 19.751277
A7: f_l_sfor_0 | B7: 29.08 | C7: 29.005618 | D7: 28.799733 | E7: 28.51501 | F7: 28.196878 | G7: 27.874071 | H7: 27.561229 | I7: 27.263898 | J7: 26.982674 | K7: 26.715933 | L7: 26.461367 | M7: 26.216745 | N7: 25.980209 | O7: 25.750339 | P7: 25.526105 | Q7: 25.306793 | R7: 25.091918 | S7: 24.881155 | T7: 24.674289 | U7: 24.471151 | V7: 24.271621 | W7: 24.075618 | X7: 23.883085 | Y7: 23.69398 | Z7: 23.508268 | AA7: 23.325914 | AB7: 23.146887 | AC7: 22.97115 | AD7: 22.798668 | AE7: 22.629401 | AF7: 22.463308 | AG7: 22.300347 | AH7: 22.140474 | AI7: 21.983643 | AJ7: 21.829809 | AK7: 21.678924
A8: f_l_sfoo_2 | B8: 618.62 | C8: 619.64984 | D8: 620.40811 | E8: 621.21783 | F8: 622.29155 | G8: 623.72675 | H8: 625.51685 | I8: 627.587 | J8: 629.85655 | K8: 632.26336 | L8: 634.76973 | M8: 637.36009 | N8: 640.03584 | O8: 642.8098 | P8: 645.7014 | Q8: 648.73307 | R8: 651.90265 | S8: 655.17571 | T8: 658.51415 | U8: 661.88657 | V8: 665.27066 | W8: 668.65245 | X8: 672.02438 | Y8: 675.38311 | Z8: 678.72771 | AA8: 682.05832 | AB8: 685.3753 | AC8: 688.67867 | AD8: 691.96795 | AE8: 695.24214 | AF8: 698.4998 | AG8: 701.73917 | AH8: 704.95838 | AI8: 708.15556 | AJ8: 711.32897 | AK8: 714.47708
A9: f_l_sfoo_0 | B9: 618.62 | C9: 619.58096 | D9: 620.19799 | E9: 620.80189 | F9: 621.60558 | G9: 622.69515 | H9: 624.07325 | I9: 625.70096 | J9: 627.52547 | K9: 629.49501 | L9: 631.56538 | M9: 633.70176 | N9: 635.87829 | O9: 638.07672 | P9: 640.28485 | Q9: 642.49501 | R9: 644.7028 | S9: 646.90604 | T9: 649.10393 | U9: 651.29649 | V9: 653.48407 | W9: 655.66713 | X9: 657.84606 | Y9: 660.02113 | Z9: 662.19247 | AA9: 664.3601 | AB9: 666.52395 | AC9: 668.68392 | AD9: 670.83993 | AE9: 672.99195 | AF9: 675.13999 | AG9: 677.28416 | AH9: 679.42464 | AI9: 681.5617 | AJ9: 683.69566 | AK9: 685.82691
A10: f_l_sveh_2 | B10: 185.81 | C10: 186.90529 | D10: 188.36292 | E10: 189.83317 | F10: 191.10318 | G10: 192.10321 | H10: 192.85802 | I10: 193.43216 | J10: 193.88812 | K10: 194.2718 | L10: 194.61157 | M10: 194.9222 | N10: 195.20939 | O10: 195.47338 | P10: 195.71139 | Q10: 195.91906 | R10: 196.09646 | S10: 196.24766 | T10: 196.37331 | U10: 196.47099 | V10: 196.53734 | W10: 196.56976 | X10: 196.56709 | Y10: 196.52967 | Z10: 196.45909 | AA10: 196.35786 | AB10: 196.229 | AC10: 196.07584 | AD10: 195.90182 | AE10: 195.71034 | AF10: 195.50474 | AG10: 195.28827 | AH10: 195.06403 | AI10: 194.83502 | AJ10: 194.60416 | AK10: 194.37422
A11: f_l_sveh_0 | B11: 185.81 | C11: 186.91608 | D11: 188.39081 | E11: 189.88115 | F11: 191.17536 | G11: 192.20807 | H11: 193.00441 | I11: 193.62576 | J11: 194.13548 | K11: 194.58348 | L11: 195.00281 | M11: 195.41213 | N11: 195.81987 | O11: 196.22828 | P11: 196.63639 | Q11: 197.04198 | R11: 197.44272 | S11: 197.83673 | T11: 198.22269 | U11: 198.59992 | V11: 198.96823 | W11: 199.32783 | X11: 199.67917 | Y11: 200.02293 | Z11: 200.35986 | AA11: 200.69079 | AB11: 201.01656 | AC11: 201.33802 | AD11: 201.65597 | AE11: 201.97119 | AF11: 202.28442 | AG11: 202.59635 | AH11: 202.90759 | AI11: 203.21872 | AJ11: 203.53027 | AK11: 203.84269
A12: f_l_sgla_2 | B12: 98.04 | C12: 98.276365 | D12: 98.505875 | E12: 98.739175 | F12: 98.98968 | G12: 99.269662 | H12: 99.580784 | I12: 99.914226 | J12: 100.26179 | K12: 100.61896 | L12: 100.985 | M12: 101.36207 | N12: 101.75423 | O12: 102.16653 | P12: 102.60431 | Q12: 103.07266 | R12: 103.57006 | S12: 104.08751 | T12: 104.61594 | U12: 105.14836 | V12: 105.68007 | W12: 106.2082 | X12: 106.73121 | Y12: 107.24838 | Z12: 107.75949 | AA12: 108.26457 | AB12: 108.76375 | AC12: 109.25722 | AD12: 109.74512 | AE12: 110.22759 | AF12: 110.70471 | AG12: 111.17658 | AH12: 111.64324 | AI12: 112.10477 | AJ12: 112.56122 | AK12: 113.01267
... A67: f_l_seot_0 | B67: 0.14078782 | C67: 0.14071073 | D67: 0.14024241 | E67: 0.13953993 | F67: 0.13874296 | G67: 0.1379414 | H67: 0.13718148 | I67: 0.13648026 | J67: 0.13583848 | K67: 0.13524924 | L67: 0.1347033 | M67: 0.13419175 | N67: 0.13370718 | O67: 0.13324397 | P67: 0.13279812 | Q67: 0.13236698 | R67: 0.13194885 | S67: 0.13154264 | T67: 0.13114766 | U67: 0.13076353 | V67: 0.13039001 | W67: 0.13002698 | X67: 0.12967436 | Y67: 0.12933205 | Z67: 0.12899996 | AA67: 0.12867798 | AB67: 0.128366 | AC67: 0.1280639 | AD67: 0.12777153 | AE67: 0.12748878 | AF67: 0.12721551 | AG67: 0.12695161 | AH67: 0.12669695 | AI67: 0.12645143 | AJ67: 0.12621493 | AK67: 0.12598735

Sheet Final_nrj
A1: _date_ | B1: 42005 | C1: 42370 | D1: 42736 | E1: 43101 | F1: 43466 | G1: 43831 | H1: 44197 | I1: 44562 | J1: 44927 | K1: 45292 | L1: 45658 | M1: 46023 | N1: 46388 | O1: 46753 | P1: 47119 | Q1: 47484 | R1: 47849 | S1: 48214 | T1: 48580 | U1: 48945 | V1: 49310 | W1: 49675 | X1: 50041 | Y1: 50406 | Z1: 50771 | AA1: 51136 | AB1: 51502 | AC1: 51867 | AD1: 52232 | AE1: 52597 | AF1: 52963 | AG1: 53328 | AH1: 53693 | AI1: 54058 | AJ1: 54424 | AK1: 54789
A2: cf_toe_2 | B2: 162.18538 | C2: 163.06009 | D2: 163.61356 | E2: 164.10601 | F2: 164.60712 | G2: 165.1068 | H2: 165.6167 | I2: 166.17199 | J2: 166.77811 | K2: 167.42291 | L2: 168.08481 | M2: 168.73766 | N2: 169.35377 | O2: 169.90593 | P2: 170.369 | Q2: 170.72108 | R2: 170.97353 | S2: 171.16366 | T2: 171.31805 | U2: 171.45431 | V2: 171.58393 | W2: 171.71439 | X2: 171.85049 | Y2: 171.99529 | Z2: 172.15062 | AA2: 172.3175 | AB2: 172.49641 | AC2: 172.68746 | AD2: 172.89052 | AE2: 173.10532 | AF2: 173.33156 | AG2: 173.5689 | AH2: 173.8171 | AI2: 174.07596 | AJ2: 174.34544 | AK2: 174.62564
A3: ch_toe_2 | B3: 64.30144 | C3: 64.184879 | D3: 63.813337 | E3: 63.413869 | F3: 63.052106 | G3: 62.730765 | H3: 62.452108 | I3: 62.222359 | J3: 62.033207 | K3: 61.871749 | L3: 61.724679 | M3: 61.579957 | N3: 61.427415 | O3: 61.258923 | P3: 61.068389 | Q3: 60.851644 | R3: 60.6164 | S3: 60.376608 | T3: 60.139128 | U3: 59.906799 | V3: 59.680288 | W3: 59.459162 | X3: 59.242489 | Y3: 59.029157 | Z3: 58.818029 | AA3: 58.608005 | AB3: 58.39805 | AC3: 58.187196 | AD3: 57.974536 | AE3: 57.759231 | AF3: 57.540503 | AG3: 57.317651 | AH3: 57.090051 | AI3: 56.85718 | AJ3: 56.61862 | AK3: 56.374084
A4: ch_hous_toe_2 | B4: 26581036 | C4: -21493924 | D4: -21337128 | E4: -21266499 | F4: -21252428 | G4: -21275013 | H4: -21322434 | I4: -21388134 | J4: -21467194 | K4: -21555726 | L4: -21650533 | M4: -21748884 | N4: -21848352 | O4: -21946703 | P4: -22041820 | Q4: -22131646 | R4: -22215767 | S4: -22295169 | T4: -22370216 | U4: -22440876 | V4: -22506905 | W4: -22567948 | X4: -22623588 | Y4: -22673368 | Z4: -22716802 | AA4: -22753383 | AB4: -22782591 | AC4: -22803895 | AD4: -22816765 | AE4: -22820679 | AF4: -22815142 | AG4: -22799691 | AH4: -22773922 | AI4: -22737500 | AJ4: -22690177 | AK4: -22631818
A5: ch_auto_toe_2 | B5: 21780563 | C5: 21493972 | D5: 21337176 | E5: 21266546 | F5: 21252476 | G5: 21275060 | H5: 21322481 | I5: 21388180 | J5: 21467241 | K5: 21555773 | L5: 21650580 | M5: 21748931 | N5: 21848398 | O5: 21946749 | P5: 22041866 | Q5: 22131692 | R5: 22215813 | S5: 22295215 | T5: 22370262 | U5: 22440921 | V5: 22506950 | W5: 22567993 | X5: 22623633 | Y5: 22673413 | Z5: 22716846 | AA5: 22753428 | AB5: 22782636 | AC5: 22803940 | AD5: 22816809 | AE5: 22820723 | AF5: 22815186 | AG5: 22799735 | AH5: 22773966 | AI5: 22737543 | AJ5: 22690221 | AK5: 22631862
A6: cf_toe_0 | B6: 162.18538 | C6: 163.18361 | D6: 163.93894 | E6: 164.69725 | F6: 165.53686 | G6: 166.4692 | H6: 167.48335 | I6: 168.56385 | J6: 169.69685 | K6: 170.87166 | L6: 172.08057 | M6: 173.31826 | N6: 174.58111 | O6: 175.8667 | P6: 177.17338 | Q6: 178.50013 | R6: 179.8463 | S6: 181.21149 | T6: 182.59545 | U6: 183.99804 | V6: 185.4192 | W6: 186.8589 | X6: 188.31714 | Y6: 189.79394 | Z6: 191.28931 | AA6: 192.80331 | AB6: 194.33597 | AC6: 195.88737 | AD6: 197.45759 | AE6: 199.04673 | AF6: 200.6549 | AG6: 202.28226 | AH6: 203.92897 | AI6: 205.59519 | AJ6: 207.28114 | AK6: 208.98701
A7: ch_toe_0 | B7: 64.30144 | C7: 64.233784 | D7: 63.931558 | E7: 63.614626 | F7: 63.352024 | G7: 63.15395 | H7: 63.01119 | I7: 62.910661 | J7: 62.840776 | K7: 62.792713 | L7: 62.760233 | M7: 62.739095 | N7: 62.72647 | O7: 62.720453 | P7: 62.719697 | Q7: 62.723315 | R7: 62.730704 | S7: 62.741401 | T7: 62.755059 | U7: 62.771409 | V7: 62.790253 | W7: 62.811437 | X7: 62.834839 | Y7: 62.860359 | Z7: 62.887918 | AA7: 62.917448 | AB7: 62.948899 | AC7: 62.982229 | AD7: 63.017408 | AE7: 63.054413 | AF7: 63.093228 | AG7: 63.133845 | AH7: 63.176261 | AI7: 63.220481 | AJ7: 63.266511 | AK7: 63.314363
