Workbook
Name formatResults: [1]ResultsEXR10!$A$50

Sheet Results
A1: NB : on crée ici une liste : - globale, qui fusionne les reportings 1, 2 et 3 (même si seules les valeurs du scénario de choc présentées ici) - "rationalisée" : suppression des doublons, et regroupements par thématique On pourra continuer par la suite à avoir 3 Excels de reporting (pour éviter un Excel trop gros), mais dans lesquels on copiera toujours les mêmes sorties (et faire des RECHERCHEV)
E2: ThreeME V3 | F2: 2 | G2: 3 | H2: 4 | I2: 5 | J2: 6 | K2: 7 | L2: 8 | M2: 9 | N2: 10 | O2: 11 | P2: 12 | Q2: 13 | R2: 14 | S2: 15 | T2: 16 | U2: 17 | V2: 18 | W2: 19 | X2: 20 | Y2: 21 | Z2: 22 | AA2: 23 | AB2: 24 | AC2: 25 | AD2: 26 | AE2: 27 | AF2: 28 | AG2: 29 | AH2: 30 | AI2: 31 | AJ2: 32 | AK2: 33 | AL2: 34 | AM2: 35 | AN2: 36 | AO2: 37
A3: Nom du bloc de variables utilisé dans le code | B3: Sous-bloc de variables pour plus de lisibilité dans le Excel | E3: Year | F3: =Hybrid!B1 -> 42005 | G3: =Hybrid!C1 -> 42370 | H3: =Hybrid!D1 -> 42736 | I3: =Hybrid!E1 -> 43101 | J3: =Hybrid!F1 -> 43466 | K3: =Hybrid!G1 -> 43831 | L3: =Hybrid!H1 -> 44197 | M3: =Hybrid!I1 -> 44562 | ... AO3: =Hybrid!AK1 -> 54789
A4: HYBRID | B4: AUTOMOBILES (unit) | C4: TOTAL STOCK SHOCK | E4: AUTO_2 | F4: =+VLOOKUP($E4,Hybrid!$1:$1048576,F$2,FALSE) -> 32317.941 | G4: =+VLOOKUP($E4,Hybrid!$1:$1048576,G$2,FALSE) -> 31926.455 | H4: =+VLOOKUP($E4,Hybrid!$1:$1048576,H$2,FALSE) -> 31730.401 | I4: =+VLOOKUP($E4,Hybrid!$1:$1048576,I$2,FALSE) -> 31664.733 | J4: =+VLOOKUP($E4,Hybrid!$1:$1048576,J$2,FALSE) -> 31685.152 | K4: =+VLOOKUP($E4,Hybrid!$1:$1048576,K$2,FALSE) -> 31761.774 | L4: =+VLOOKUP($E4,Hybrid!$1:$1048576,L$2,FALSE) -> 31876.82 | M4: =+VLOOKUP($E4,Hybrid!$1:$1048576,M$2,FALSE) -> 32020.398 | ... AO4: =+VLOOKUP($E4,Hybrid!$1:$1048576,AO$2,FALSE) -> 36554.972
C5: OIL | E5: AUTO_cfut_2 | F5: =+VLOOKUP($E5,Hybrid!$1:$1048576,F$2,FALSE) -> 32271.24 | G5: =+VLOOKUP($E5,Hybrid!$1:$1048576,G$2,FALSE) -> 31862.032 | H5: =+VLOOKUP($E5,Hybrid!$1:$1048576,H$2,FALSE) -> 31647.329 | I5: =+VLOOKUP($E5,Hybrid!$1:$1048576,I$2,FALSE) -> 31562.481 | J5: =+VLOOKUP($E5,Hybrid!$1:$1048576,J$2,FALSE) -> 31563.392 | K5: =+VLOOKUP($E5,Hybrid!$1:$1048576,K$2,FALSE) -> 31620.229 | L5: =+VLOOKUP($E5,Hybrid!$1:$1048576,L$2,FALSE) -> 31715.127 | M5: =+VLOOKUP($E5,Hybrid!$1:$1048576,M$2,FALSE) -> 31838.038 | ... AO5: =+VLOOKUP($E5,Hybrid!$1:$1048576,AO$2,FALSE) -> 32020.075
D6: class A | E6: AUTO_ca_cfut_2 | F6: =+VLOOKUP($E6,Hybrid!$1:$1048576,F$2,FALSE) -> 7095.7005 | G6: =+VLOOKUP($E6,Hybrid!$1:$1048576,G$2,FALSE) -> 7141.744 | H6: =+VLOOKUP($E6,Hybrid!$1:$1048576,H$2,FALSE) -> 7236.2109 | I6: =+VLOOKUP($E6,Hybrid!$1:$1048576,I$2,FALSE) -> 7362.7565 | J6: =+VLOOKUP($E6,Hybrid!$1:$1048576,J$2,FALSE) -> 7510.0299 | K6: =+VLOOKUP($E6,Hybrid!$1:$1048576,K$2,FALSE) -> 7670.2472 | L6: =+VLOOKUP($E6,Hybrid!$1:$1048576,L$2,FALSE) -> 7838.785 | M6: =+VLOOKUP($E6,Hybrid!$1:$1048576,M$2,FALSE) -> 8013.1055 | ... AO6: =+VLOOKUP($E6,Hybrid!$1:$1048576,AO$2,FALSE) -> 11240.43
D7: class B | E7: AUTO_cb_cfut_2 | F7: =+VLOOKUP($E7,Hybrid!$1:$1048576,F$2,FALSE) -> 8251.2564 | G7: =+VLOOKUP($E7,Hybrid!$1:$1048576,G$2,FALSE) -> 8182.7845 | H7: =+VLOOKUP($E7,Hybrid!$1:$1048576,H$2,FALSE) -> 8168.3356 | I7: =+VLOOKUP($E7,Hybrid!$1:$1048576,I$2,FALSE) -> 8191.2663 | J7: =+VLOOKUP($E7,Hybrid!$1:$1048576,J$2,FALSE) -> 8239.913 | K7: =+VLOOKUP($E7,Hybrid!$1:$1048576,K$2,FALSE) -> 8306.1531 | L7: =+VLOOKUP($E7,Hybrid!$1:$1048576,L$2,FALSE) -> 8384.9727 | M7: =+VLOOKUP($E7,Hybrid!$1:$1048576,M$2,FALSE) -> 8473.4298 | ... AO7: =+VLOOKUP($E7,Hybrid!$1:$1048576,AO$2,FALSE) -> 9881.9911
D8: class C | E8: AUTO_cc_cfut_2 | F8: =+VLOOKUP($E8,Hybrid!$1:$1048576,F$2,FALSE) -> 6777.6025 | G8: =+VLOOKUP($E8,Hybrid!$1:$1048576,G$2,FALSE) -> 6646.7629 | H8: =+VLOOKUP($E8,Hybrid!$1:$1048576,H$2,FALSE) -> 6558.9664 | I8: =+VLOOKUP($E8,Hybrid!$1:$1048576,I$2,FALSE) -> 6502.0082 | J8: =+VLOOKUP($E8,Hybrid!$1:$1048576,J$2,FALSE) -> 6467.2622 | K8: =+VLOOKUP($E8,Hybrid!$1:$1048576,K$2,FALSE) -> 6448.6373 | L8: =+VLOOKUP($E8,Hybrid!$1:$1048576,L$2,FALSE) -> 6442.2478 | M8: =+VLOOKUP($E8,Hybrid!$1:$1048576,M$2,FALSE) -> 6445.693 | ... AO8: =+VLOOKUP($E8,Hybrid!$1:$1048576,AO$2,FALSE) -> 6300.9328
D9: class D | E9: AUTO_cd_cfut_2 | F9: =+VLOOKUP($E9,Hybrid!$1:$1048576,F$2,FALSE) -> 4159.6639 | G9: =+VLOOKUP($E9,Hybrid!$1:$1048576,G$2,FALSE) -> 4054.5797 | H9: =+VLOOKUP($E9,Hybrid!$1:$1048576,H$2,FALSE) -> 3973.8285 | I9: =+VLOOKUP($E9,Hybrid!$1:$1048576,I$2,FALSE) -> 3910.0599 | J9: =+VLOOKUP($E9,Hybrid!$1:$1048576,J$2,FALSE) -> 3858.1675 | K9: =+VLOOKUP($E9,Hybrid!$1:$1048576,K$2,FALSE) -> 3814.6035 | L9: =+VLOOKUP($E9,Hybrid!$1:$1048576,L$2,FALSE) -> 3777.117 | M9: =+VLOOKUP($E9,Hybrid!$1:$1048576,M$2,FALSE) -> 3744.3156 | ... AO9: =+VLOOKUP($E9,Hybrid!$1:$1048576,AO$2,FALSE) -> 2689.2394
D10: class E | E10: AUTO_ce_cfut_2 | F10: =+VLOOKUP($E10,Hybrid!$1:$1048576,F$2,FALSE) -> 2503.7292 | G10: =+VLOOKUP($E10,Hybrid!$1:$1048576,G$2,FALSE) -> 2442.7169 | H10: =+VLOOKUP($E10,Hybrid!$1:$1048576,H$2,FALSE) -> 2395.2655 | I10: =+VLOOKUP($E10,Hybrid!$1:$1048576,I$2,FALSE) -> 2356.6831 | J10: =+VLOOKUP($E10,Hybrid!$1:$1048576,J$2,FALSE) -> 2323.7962 | K10: =+VLOOKUP($E10,Hybrid!$1:$1048576,K$2,FALSE) -> 2294.4653 | L10: =+VLOOKUP($E10,Hybrid!$1:$1048576,L$2,FALSE) -> 2267.3805 | M10: =+VLOOKUP($E10,Hybrid!$1:$1048576,M$2,FALSE) -> 2241.7723 | ... AO10: =+VLOOKUP($E10,Hybrid!$1:$1048576,AO$2,FALSE) -> 1253.0278
D11: class F | E11: AUTO_cf_cfut_2 | F11: =+VLOOKUP($E11,Hybrid!$1:$1048576,F$2,FALSE) -> 1243.6668 | G11: =+VLOOKUP($E11,Hybrid!$1:$1048576,G$2,FALSE) -> 1210.4925 | H11: =+VLOOKUP($E11,Hybrid!$1:$1048576,H$2,FALSE) -> 1182.3239 | I11: =+VLOOKUP($E11,Hybrid!$1:$1048576,I$2,FALSE) -> 1156.6362 | J11: =+VLOOKUP($E11,Hybrid!$1:$1048576,J$2,FALSE) -> 1131.8888 | K11: =+VLOOKUP($E11,Hybrid!$1:$1048576,K$2,FALSE) -> 1107.177 | L11: =+VLOOKUP($E11,Hybrid!$1:$1048576,L$2,FALSE) -> 1082.0509 | M11: =+VLOOKUP($E11,Hybrid!$1:$1048576,M$2,FALSE) -> 1056.3349 | ... AO11: =+VLOOKUP($E11,Hybrid!$1:$1048576,AO$2,FALSE) -> 294.49603
D12: class G | E12: AUTO_cg_cfut_2 | F12: =+VLOOKUP($E12,Hybrid!$1:$1048576,F$2,FALSE) -> 2239.6206 | G12: =+VLOOKUP($E12,Hybrid!$1:$1048576,G$2,FALSE) -> 2182.9512 | H12: =+VLOOKUP($E12,Hybrid!$1:$1048576,H$2,FALSE) -> 2132.3988 | I12: =+VLOOKUP($E12,Hybrid!$1:$1048576,I$2,FALSE) -> 2083.0711 | J12: =+VLOOKUP($E12,Hybrid!$1:$1048576,J$2,FALSE) -> 2032.334 | K12: =+VLOOKUP($E12,Hybrid!$1:$1048576,K$2,FALSE) -> 1978.9456 | L12: =+VLOOKUP($E12,Hybrid!$1:$1048576,L$2,FALSE) -> 1922.5734 | M12: =+VLOOKUP($E12,Hybrid!$1:$1048576,M$2,FALSE) -> 1863.3872 | ... AO12: =+VLOOKUP($E12,Hybrid!$1:$1048576,AO$2,FALSE) -> 359.95743
C13: ELEC | E13: AUTO_cele_2 | F13: =+VLOOKUP($E13,Hybrid!$1:$1048576,F$2,FALSE) -> 44.765 | G13: =+VLOOKUP($E13,Hybrid!$1:$1048576,G$2,FALSE) -> 62.431569 | H13: =+VLOOKUP($E13,Hybrid!$1:$1048576,H$2,FALSE) -> 81.013696 | I13: =+VLOOKUP($E13,Hybrid!$1:$1048576,I$2,FALSE) -> 100.12298 | J13: =+VLOOKUP($E13,Hybrid!$1:$1048576,J$2,FALSE) -> 119.55791 | K13: =+VLOOKUP($E13,Hybrid!$1:$1048576,K$2,FALSE) -> 139.26917 | L13: =+VLOOKUP($E13,Hybrid!$1:$1048576,L$2,FALSE) -> 159.3444 | M13: =+VLOOKUP($E13,Hybrid!$1:$1048576,M$2,FALSE) -> 179.94081 | ... AO13: =+VLOOKUP($E13,Hybrid!$1:$1048576,AO$2,FALSE) -> 4531.6755
D14: class A | E14: AUTO_ca_cele_2 | F14: =+VLOOKUP($E14,Hybrid!$1:$1048576,F$2,FALSE) -> 9.8427899 | G14: =+VLOOKUP($E14,Hybrid!$1:$1048576,G$2,FALSE) -> 14.986776 | H14: =+VLOOKUP($E14,Hybrid!$1:$1048576,H$2,FALSE) -> 20.441889 | I14: =+VLOOKUP($E14,Hybrid!$1:$1048576,I$2,FALSE) -> 26.112449 | J14: =+VLOOKUP($E14,Hybrid!$1:$1048576,J$2,FALSE) -> 31.950416 | K14: =+VLOOKUP($E14,Hybrid!$1:$1048576,K$2,FALSE) -> 37.949262 | L14: =+VLOOKUP($E14,Hybrid!$1:$1048576,L$2,FALSE) -> 44.142141 | M14: =+VLOOKUP($E14,Hybrid!$1:$1048576,M$2,FALSE) -> 50.58278 | ... AO14: =+VLOOKUP($E14,Hybrid!$1:$1048576,AO$2,FALSE) -> 1721.1452
D15: class B | E15: AUTO_cb_cele_2 | F15: =+VLOOKUP($E15,Hybrid!$1:$1048576,F$2,FALSE) -> 11.445717 | G15: =+VLOOKUP($E15,Hybrid!$1:$1048576,G$2,FALSE) -> 16.298726 | H15: =+VLOOKUP($E15,Hybrid!$1:$1048576,H$2,FALSE) -> 21.445143 | I15: =+VLOOKUP($E15,Hybrid!$1:$1048576,I$2,FALSE) -> 26.792131 | J15: =+VLOOKUP($E15,Hybrid!$1:$1048576,J$2,FALSE) -> 32.294 | K15: =+VLOOKUP($E15,Hybrid!$1:$1048576,K$2,FALSE) -> 37.945945 | L15: =+VLOOKUP($E15,Hybrid!$1:$1048576,L$2,FALSE) -> 43.781768 | M15: =+VLOOKUP($E15,Hybrid!$1:$1048576,M$2,FALSE) -> 49.854747 | ... AO15: =+VLOOKUP($E15,Hybrid!$1:$1048576,AO$2,FALSE) -> 1535.9361
D16: class C | E16: AUTO_cc_cele_2 | F16: =+VLOOKUP($E16,Hybrid!$1:$1048576,F$2,FALSE) -> 9.4015406 | G16: =+VLOOKUP($E16,Hybrid!$1:$1048576,G$2,FALSE) -> 12.697683 | H16: =+VLOOKUP($E16,Hybrid!$1:$1048576,H$2,FALSE) -> 16.193359 | I16: =+VLOOKUP($E16,Hybrid!$1:$1048576,I$2,FALSE) -> 19.823555 | J16: =+VLOOKUP($E16,Hybrid!$1:$1048576,J$2,FALSE) -> 23.556822 | K16: =+VLOOKUP($E16,Hybrid!$1:$1048576,K$2,FALSE) -> 27.390656 | L16: =+VLOOKUP($E16,Hybrid!$1:$1048576,L$2,FALSE) -> 31.349549 | M16: =+VLOOKUP($E16,Hybrid!$1:$1048576,M$2,FALSE) -> 35.471242 | ... AO16: =+VLOOKUP($E16,Hybrid!$1:$1048576,AO$2,FALSE) -> 985.35071
D17: class D | E17: AUTO_cd_cele_2 | F17: =+VLOOKUP($E17,Hybrid!$1:$1048576,F$2,FALSE) -> 5.7700713 | G17: =+VLOOKUP($E17,Hybrid!$1:$1048576,G$2,FALSE) -> 7.5615055 | H17: =+VLOOKUP($E17,Hybrid!$1:$1048576,H$2,FALSE) -> 9.4379839 | I17: =+VLOOKUP($E17,Hybrid!$1:$1048576,I$2,FALSE) -> 11.352079 | J17: =+VLOOKUP($E17,Hybrid!$1:$1048576,J$2,FALSE) -> 13.275194 | K17: =+VLOOKUP($E17,Hybrid!$1:$1048576,K$2,FALSE) -> 15.192959 | L17: =+VLOOKUP($E17,Hybrid!$1:$1048576,L$2,FALSE) -> 17.103324 | M17: =+VLOOKUP($E17,Hybrid!$1:$1048576,M$2,FALSE) -> 19.010938 | ... AO17: =+VLOOKUP($E17,Hybrid!$1:$1048576,AO$2,FALSE) -> 187.38943
D18: class E | E18: AUTO_ce_cele_2 | F18: =+VLOOKUP($E18,Hybrid!$1:$1048576,F$2,FALSE) -> 3.4730441 | G18: =+VLOOKUP($E18,Hybrid!$1:$1048576,G$2,FALSE) -> 4.5722155 | H18: =+VLOOKUP($E18,Hybrid!$1:$1048576,H$2,FALSE) -> 5.7140433 | I18: =+VLOOKUP($E18,Hybrid!$1:$1048576,I$2,FALSE) -> 6.8675525 | J18: =+VLOOKUP($E18,Hybrid!$1:$1048576,J$2,FALSE) -> 8.014519 | K18: =+VLOOKUP($E18,Hybrid!$1:$1048576,K$2,FALSE) -> 9.146111 | L18: =+VLOOKUP($E18,Hybrid!$1:$1048576,L$2,FALSE) -> 10.261244 | M18: =+VLOOKUP($E18,Hybrid!$1:$1048576,M$2,FALSE) -> 11.362807 | ... AO18: =+VLOOKUP($E18,Hybrid!$1:$1048576,AO$2,FALSE) -> 82.980357
D19: class F | E19: AUTO_cf_cele_2 | F19: =+VLOOKUP($E19,Hybrid!$1:$1048576,F$2,FALSE) -> 1.7251505 | G19: =+VLOOKUP($E19,Hybrid!$1:$1048576,G$2,FALSE) -> 2.2443945 | H19: =+VLOOKUP($E19,Hybrid!$1:$1048576,H$2,FALSE) -> 2.7668951 | I19: =+VLOOKUP($E19,Hybrid!$1:$1048576,I$2,FALSE) -> 3.2740042 | J19: =+VLOOKUP($E19,Hybrid!$1:$1048576,J$2,FALSE) -> 3.7551966 | K19: =+VLOOKUP($E19,Hybrid!$1:$1048576,K$2,FALSE) -> 4.2053456 | L19: =+VLOOKUP($E19,Hybrid!$1:$1048576,L$2,FALSE) -> 4.6232035 | M19: =+VLOOKUP($E19,Hybrid!$1:$1048576,M$2,FALSE) -> 5.0095094 | ... AO19: =+VLOOKUP($E19,Hybrid!$1:$1048576,AO$2,FALSE) -> 9.6175149
D20: class G | E20: AUTO_cg_cele_2 | F20: =+VLOOKUP($E20,Hybrid!$1:$1048576,F$2,FALSE) -> 3.1066862 | G20: =+VLOOKUP($E20,Hybrid!$1:$1048576,G$2,FALSE) -> 4.0702695 | H20: =+VLOOKUP($E20,Hybrid!$1:$1048576,H$2,FALSE) -> 5.014383 | I20: =+VLOOKUP($E20,Hybrid!$1:$1048576,I$2,FALSE) -> 5.9012135 | J20: =+VLOOKUP($E20,Hybrid!$1:$1048576,J$2,FALSE) -> 6.7117634 | K20: =+VLOOKUP($E20,Hybrid!$1:$1048576,K$2,FALSE) -> 7.4388891 | L20: =+VLOOKUP($E20,Hybrid!$1:$1048576,L$2,FALSE) -> 8.0831672 | M20: =+VLOOKUP($E20,Hybrid!$1:$1048576,M$2,FALSE) -> 8.6487844 | ... AO20: =+VLOOKUP($E20,Hybrid!$1:$1048576,AO$2,FALSE) -> 9.2561619
C21: GAS | E21: AUTO_cgas_2 | F21: =+VLOOKUP($E21,Hybrid!$1:$1048576,F$2,FALSE) -> 1.936 | G21: =+VLOOKUP($E21,Hybrid!$1:$1048576,G$2,FALSE) -> 1.9916056 | H21: =+VLOOKUP($E21,Hybrid!$1:$1048576,H$2,FALSE) -> 2.0574011 | I21: =+VLOOKUP($E21,Hybrid!$1:$1048576,I$2,FALSE) -> 2.1285899 | J21: =+VLOOKUP($E21,Hybrid!$1:$1048576,J$2,FALSE) -> 2.2019794 | K21: =+VLOOKUP($E21,Hybrid!$1:$1048576,K$2,FALSE) -> 2.2754864 | L21: =+VLOOKUP($E21,Hybrid!$1:$1048576,L$2,FALSE) -> 2.3479684 | M21: =+VLOOKUP($E21,Hybrid!$1:$1048576,M$2,FALSE) -> 2.4188941 | ... AO21: =+VLOOKUP($E21,Hybrid!$1:$1048576,AO$2,FALSE) -> 3.2214115
D22: class A | E22: AUTO_ca_cgas_2 | F22: =+VLOOKUP($E22,Hybrid!$1:$1048576,F$2,FALSE) -> 0.4256817 | G22: =+VLOOKUP($E22,Hybrid!$1:$1048576,G$2,FALSE) -> 0.44933517 | H22: =+VLOOKUP($E22,Hybrid!$1:$1048576,H$2,FALSE) -> 0.47587941 | I22: =+VLOOKUP($E22,Hybrid!$1:$1048576,I$2,FALSE) -> 0.50407723 | J22: =+VLOOKUP($E22,Hybrid!$1:$1048576,J$2,FALSE) -> 0.53308137 | K22: =+VLOOKUP($E22,Hybrid!$1:$1048576,K$2,FALSE) -> 0.56232302 | L22: =+VLOOKUP($E22,Hybrid!$1:$1048576,L$2,FALSE) -> 0.59148357 | M22: =+VLOOKUP($E22,Hybrid!$1:$1048576,M$2,FALSE) -> 0.62040925 | ... AO22: =+VLOOKUP($E22,Hybrid!$1:$1048576,AO$2,FALSE) -> 1.1175435
D23: class B | E23: AUTO_cb_cgas_2 | F23: =+VLOOKUP($E23,Hybrid!$1:$1048576,F$2,FALSE) -> 0.49500523 | G23: =+VLOOKUP($E23,Hybrid!$1:$1048576,G$2,FALSE) -> 0.51226024 | H23: =+VLOOKUP($E23,Hybrid!$1:$1048576,H$2,FALSE) -> 0.53252768 | I23: =+VLOOKUP($E23,Hybrid!$1:$1048576,I$2,FALSE) -> 0.55457425 | J23: =+VLOOKUP($E23,Hybrid!$1:$1048576,J$2,FALSE) -> 0.57755325 | K23: =+VLOOKUP($E23,Hybrid!$1:$1048576,K$2,FALSE) -> 0.60089214 | L23: =+VLOOKUP($E23,Hybrid!$1:$1048576,L$2,FALSE) -> 0.62426223 | M23: =+VLOOKUP($E23,Hybrid!$1:$1048576,M$2,FALSE) -> 0.64749666 | ... AO23: =+VLOOKUP($E23,Hybrid!$1:$1048576,AO$2,FALSE) -> 0.98903502
D24: class C | E24: AUTO_cc_cgas_2 | F24: =+VLOOKUP($E24,Hybrid!$1:$1048576,F$2,FALSE) -> 0.40659852 | G24: =+VLOOKUP($E24,Hybrid!$1:$1048576,G$2,FALSE) -> 0.4145049 | H24: =+VLOOKUP($E24,Hybrid!$1:$1048576,H$2,FALSE) -> 0.42467781 | I24: =+VLOOKUP($E24,Hybrid!$1:$1048576,I$2,FALSE) -> 0.43623168 | J24: =+VLOOKUP($E24,Hybrid!$1:$1048576,J$2,FALSE) -> 0.44855712 | K24: =+VLOOKUP($E24,Hybrid!$1:$1048576,K$2,FALSE) -> 0.4612394 | L24: =+VLOOKUP($E24,Hybrid!$1:$1048576,L$2,FALSE) -> 0.47403519 | M24: =+VLOOKUP($E24,Hybrid!$1:$1048576,M$2,FALSE) -> 0.48681568 | ... AO24: =+VLOOKUP($E24,Hybrid!$1:$1048576,AO$2,FALSE) -> 0.63482943
D25: class D | E25: AUTO_cd_cgas_2 | F25: =+VLOOKUP($E25,Hybrid!$1:$1048576,F$2,FALSE) -> 0.24954447 | G25: =+VLOOKUP($E25,Hybrid!$1:$1048576,G$2,FALSE) -> 0.25231485 | H25: =+VLOOKUP($E25,Hybrid!$1:$1048576,H$2,FALSE) -> 0.25626929 | I25: =+VLOOKUP($E25,Hybrid!$1:$1048576,I$2,FALSE) -> 0.26087537 | J25: =+VLOOKUP($E25,Hybrid!$1:$1048576,J$2,FALSE) -> 0.2657744 | K25: =+VLOOKUP($E25,Hybrid!$1:$1048576,K$2,FALSE) -> 0.27072766 | L25: =+VLOOKUP($E25,Hybrid!$1:$1048576,L$2,FALSE) -> 0.27559709 | M25: =+VLOOKUP($E25,Hybrid!$1:$1048576,M$2,FALSE) -> 0.28031071 | ... AO25: =+VLOOKUP($E25,Hybrid!$1:$1048576,AO$2,FALSE) -> 0.27521423
D26: class E | E26: AUTO_ce_cgas_2 | F26: =+VLOOKUP($E26,Hybrid!$1:$1048576,F$2,FALSE) -> 0.15020247 | G26: =+VLOOKUP($E26,Hybrid!$1:$1048576,G$2,FALSE) -> 0.15205804 | H26: =+VLOOKUP($E26,Hybrid!$1:$1048576,H$2,FALSE) -> 0.15453801 | I26: =+VLOOKUP($E26,Hybrid!$1:$1048576,I$2,FALSE) -> 0.15729786 | J26: =+VLOOKUP($E26,Hybrid!$1:$1048576,J$2,FALSE) -> 0.16011145 | K26: =+VLOOKUP($E26,Hybrid!$1:$1048576,K$2,FALSE) -> 0.16283293 | L26: =+VLOOKUP($E26,Hybrid!$1:$1048576,L$2,FALSE) -> 0.16538126 | M26: =+VLOOKUP($E26,Hybrid!$1:$1048576,M$2,FALSE) -> 0.16771728 | ... AO26: =+VLOOKUP($E26,Hybrid!$1:$1048576,AO$2,FALSE) -> 0.13087224
D27: class F | E27: AUTO_cf_cgas_2 | F27: =+VLOOKUP($E27,Hybrid!$1:$1048576,F$2,FALSE) -> 0.074609436 | G27: =+VLOOKUP($E27,Hybrid!$1:$1048576,G$2,FALSE) -> 0.075290207 | H27: =+VLOOKUP($E27,Hybrid!$1:$1048576,H$2,FALSE) -> 0.076132076 | I27: =+VLOOKUP($E27,Hybrid!$1:$1048576,I$2,FALSE) -> 0.076945597 | J27: =+VLOOKUP($E27,Hybrid!$1:$1048576,J$2,FALSE) -> 0.077619324 | K27: =+VLOOKUP($E27,Hybrid!$1:$1048576,K$2,FALSE) -> 0.078092136 | L27: =+VLOOKUP($E27,Hybrid!$1:$1048576,L$2,FALSE) -> 0.078339035 | M27: =+VLOOKUP($E27,Hybrid!$1:$1048576,M$2,FALSE) -> 0.078356678 | ... AO27: =+VLOOKUP($E27,Hybrid!$1:$1048576,AO$2,FALSE) -> 0.032639717
D28: class G | E28: AUTO_cg_cgas_2 | F28: =+VLOOKUP($E28,Hybrid!$1:$1048576,F$2,FALSE) -> 0.13435819 | G28: =+VLOOKUP($E28,Hybrid!$1:$1048576,G$2,FALSE) -> 0.13584219 | H28: =+VLOOKUP($E28,Hybrid!$1:$1048576,H$2,FALSE) -> 0.13737684 | I28: =+VLOOKUP($E28,Hybrid!$1:$1048576,I$2,FALSE) -> 0.13858796 | J28: =+VLOOKUP($E28,Hybrid!$1:$1048576,J$2,FALSE) -> 0.13928248 | K28: =+VLOOKUP($E28,Hybrid!$1:$1048576,K$2,FALSE) -> 0.13937915 | L28: =+VLOOKUP($E28,Hybrid!$1:$1048576,L$2,FALSE) -> 0.13887006 | M28: =+VLOOKUP($E28,Hybrid!$1:$1048576,M$2,FALSE) -> 0.13778783 | ... AO28: =+VLOOKUP($E28,Hybrid!$1:$1048576,AO$2,FALSE) -> 0.041277351
C29: TOTAL STOCK BASELINE | E29: AUTO_0 | F29: =+VLOOKUP($E29,Hybrid!$1:$1048576,F$2,FALSE) -> 32317.941 | G29: =+VLOOKUP($E29,Hybrid!$1:$1048576,G$2,FALSE) -> 31931.625 | H29: =+VLOOKUP($E29,Hybrid!$1:$1048576,H$2,FALSE) -> 31743.508 | I29: =+VLOOKUP($E29,Hybrid!$1:$1048576,I$2,FALSE) -> 31687.792 | J29: =+VLOOKUP($E29,Hybrid!$1:$1048576,J$2,FALSE) -> 31720.643 | K29: =+VLOOKUP($E29,Hybrid!$1:$1048576,K$2,FALSE) -> 31813.337 | L29: =+VLOOKUP($E29,Hybrid!$1:$1048576,L$2,FALSE) -> 31947.162 | M29: =+VLOOKUP($E29,Hybrid!$1:$1048576,M$2,FALSE) -> 32109.877 | ... AO29: =+VLOOKUP($E29,Hybrid!$1:$1048576,AO$2,FALSE) -> 38673.292
C30: OIL | E30: AUTO_cfut_0 | F30: =+VLOOKUP($E30,Hybrid!$1:$1048576,F$2,FALSE) -> 32271.24 | G30: =+VLOOKUP($E30,Hybrid!$1:$1048576,G$2,FALSE) -> 31867.185 | H30: =+VLOOKUP($E30,Hybrid!$1:$1048576,H$2,FALSE) -> 31660.486 | I30: =+VLOOKUP($E30,Hybrid!$1:$1048576,I$2,FALSE) -> 31585.838 | J30: =+VLOOKUP($E30,Hybrid!$1:$1048576,J$2,FALSE) -> 31599.721 | K30: =+VLOOKUP($E30,Hybrid!$1:$1048576,K$2,FALSE) -> 31673.603 | L30: =+VLOOKUP($E30,Hybrid!$1:$1048576,L$2,FALSE) -> 31788.887 | M30: =+VLOOKUP($E30,Hybrid!$1:$1048576,M$2,FALSE) -> 31933.397 | ... AO30: =+VLOOKUP($E30,Hybrid!$1:$1048576,AO$2,FALSE) -> 38101.905
D31: class A | E31: AUTO_ca_cfut_0 | F31: =+VLOOKUP($E31,Hybrid!$1:$1048576,F$2,FALSE) -> 7095.7005 | G31: =+VLOOKUP($E31,Hybrid!$1:$1048576,G$2,FALSE) -> 7143.1788 | H31: =+VLOOKUP($E31,Hybrid!$1:$1048576,H$2,FALSE) -> 7239.81 | I31: =+VLOOKUP($E31,Hybrid!$1:$1048576,I$2,FALSE) -> 7369.0432 | J31: =+VLOOKUP($E31,Hybrid!$1:$1048576,J$2,FALSE) -> 7519.6804 | K31: =+VLOOKUP($E31,Hybrid!$1:$1048576,K$2,FALSE) -> 7684.2986 | L31: =+VLOOKUP($E31,Hybrid!$1:$1048576,L$2,FALSE) -> 7858.0379 | M31: =+VLOOKUP($E31,Hybrid!$1:$1048576,M$2,FALSE) -> 8037.7299 | ... AO31: =+VLOOKUP($E31,Hybrid!$1:$1048576,AO$2,FALSE) -> 13271.9
D32: class B | E32: AUTO_cb_cfut_0 | F32: =+VLOOKUP($E32,Hybrid!$1:$1048576,F$2,FALSE) -> 8251.2564 | G32: =+VLOOKUP($E32,Hybrid!$1:$1048576,G$2,FALSE) -> 8184.1785 | H32: =+VLOOKUP($E32,Hybrid!$1:$1048576,H$2,FALSE) -> 8171.8779 | I32: =+VLOOKUP($E32,Hybrid!$1:$1048576,I$2,FALSE) -> 8197.5342 | J32: =+VLOOKUP($E32,Hybrid!$1:$1048576,J$2,FALSE) -> 8249.6491 | K32: =+VLOOKUP($E32,Hybrid!$1:$1048576,K$2,FALSE) -> 8320.4704 | L32: =+VLOOKUP($E32,Hybrid!$1:$1048576,L$2,FALSE) -> 8404.7877 | M32: =+VLOOKUP($E32,Hybrid!$1:$1048576,M$2,FALSE) -> 8499.0715 | ... AO32: =+VLOOKUP($E32,Hybrid!$1:$1048576,AO$2,FALSE) -> 11875.349
D33: class C | E33: AUTO_cc_cfut_0 | F33: =+VLOOKUP($E33,Hybrid!$1:$1048576,F$2,FALSE) -> 6777.6025 | G33: =+VLOOKUP($E33,Hybrid!$1:$1048576,G$2,FALSE) -> 6647.7392 | H33: =+VLOOKUP($E33,Hybrid!$1:$1048576,H$2,FALSE) -> 6561.4778 | I33: =+VLOOKUP($E33,Hybrid!$1:$1048576,I$2,FALSE) -> 6506.5051 | J33: =+VLOOKUP($E33,Hybrid!$1:$1048576,J$2,FALSE) -> 6474.3214 | K33: =+VLOOKUP($E33,Hybrid!$1:$1048576,K$2,FALSE) -> 6459.1067 | L33: =+VLOOKUP($E33,Hybrid!$1:$1048576,L$2,FALSE) -> 6456.8591 | M33: =+VLOOKUP($E33,Hybrid!$1:$1048576,M$2,FALSE) -> 6464.7815 | ... AO33: =+VLOOKUP($E33,Hybrid!$1:$1048576,AO$2,FALSE) -> 7687.7208
D34: class D | E34: AUTO_cd_cfut_0 | F34: =+VLOOKUP($E34,Hybrid!$1:$1048576,F$2,FALSE) -> 4159.6639 | G34: =+VLOOKUP($E34,Hybrid!$1:$1048576,G$2,FALSE) -> 4055.1231 | H34: =+VLOOKUP($E34,Hybrid!$1:$1048576,H$2,FALSE) -> 3975.2329 | I34: =+VLOOKUP($E34,Hybrid!$1:$1048576,I$2,FALSE) -> 3912.5808 | J34: =+VLOOKUP($E34,Hybrid!$1:$1048576,J$2,FALSE) -> 3862.1234 | K34: =+VLOOKUP($E34,Hybrid!$1:$1048576,K$2,FALSE) -> 3820.4516 | L34: =+VLOOKUP($E34,Hybrid!$1:$1048576,L$2,FALSE) -> 3785.2435 | M34: =+VLOOKUP($E34,Hybrid!$1:$1048576,M$2,FALSE) -> 3754.8857 | ... AO34: =+VLOOKUP($E34,Hybrid!$1:$1048576,AO$2,FALSE) -> 3102.3334
D35: class E | E35: AUTO_ce_cfut_0 | F35: =+VLOOKUP($E35,Hybrid!$1:$1048576,F$2,FALSE) -> 2503.7292 | G35: =+VLOOKUP($E35,Hybrid!$1:$1048576,G$2,FALSE) -> 2443.054 | H35: =+VLOOKUP($E35,Hybrid!$1:$1048576,H$2,FALSE) -> 2396.145 | I35: =+VLOOKUP($E35,Hybrid!$1:$1048576,I$2,FALSE) -> 2358.2745 | J35: =+VLOOKUP($E35,Hybrid!$1:$1048576,J$2,FALSE) -> 2326.3079 | K35: =+VLOOKUP($E35,Hybrid!$1:$1048576,K$2,FALSE) -> 2298.1904 | L35: =+VLOOKUP($E35,Hybrid!$1:$1048576,L$2,FALSE) -> 2272.5718 | M35: =+VLOOKUP($E35,Hybrid!$1:$1048576,M$2,FALSE) -> 2248.5516 | ... AO35: =+VLOOKUP($E35,Hybrid!$1:$1048576,AO$2,FALSE) -> 1454.1661
D36: class F | E36: AUTO_cf_cfut_0 | F36: =+VLOOKUP($E36,Hybrid!$1:$1048576,F$2,FALSE) -> 1243.6668 | G36: =+VLOOKUP($E36,Hybrid!$1:$1048576,G$2,FALSE) -> 1210.6549 | H36: =+VLOOKUP($E36,Hybrid!$1:$1048576,H$2,FALSE) -> 1182.7476 | I36: =+VLOOKUP($E36,Hybrid!$1:$1048576,I$2,FALSE) -> 1157.3995 | J36: =+VLOOKUP($E36,Hybrid!$1:$1048576,J$2,FALSE) -> 1133.0829 | K36: =+VLOOKUP($E36,Hybrid!$1:$1048576,K$2,FALSE) -> 1108.9242 | L36: =+VLOOKUP($E36,Hybrid!$1:$1048576,L$2,FALSE) -> 1084.4506 | M36: =+VLOOKUP($E36,Hybrid!$1:$1048576,M$2,FALSE) -> 1059.4277 | ... AO36: =+VLOOKUP($E36,Hybrid!$1:$1048576,AO$2,FALSE) -> 325.27338
D37: class G | E37: AUTO_cg_cfut_0 | F37: =+VLOOKUP($E37,Hybrid!$1:$1048576,F$2,FALSE) -> 2239.6206 | G37: =+VLOOKUP($E37,Hybrid!$1:$1048576,G$2,FALSE) -> 2183.2559 | H37: =+VLOOKUP($E37,Hybrid!$1:$1048576,H$2,FALSE) -> 2133.1946 | I37: =+VLOOKUP($E37,Hybrid!$1:$1048576,I$2,FALSE) -> 2084.5006 | J37: =+VLOOKUP($E37,Hybrid!$1:$1048576,J$2,FALSE) -> 2034.5555 | K37: =+VLOOKUP($E37,Hybrid!$1:$1048576,K$2,FALSE) -> 1982.161 | L37: =+VLOOKUP($E37,Hybrid!$1:$1048576,L$2,FALSE) -> 1926.9369 | M37: =+VLOOKUP($E37,Hybrid!$1:$1048576,M$2,FALSE) -> 1868.9489 | ... AO37: =+VLOOKUP($E37,Hybrid!$1:$1048576,AO$2,FALSE) -> 385.16287
C38: ELEC | E38: AUTO_cele_0 | F38: =+VLOOKUP($E38,Hybrid!$1:$1048576,F$2,FALSE) -> 44.765 | G38: =+VLOOKUP($E38,Hybrid!$1:$1048576,G$2,FALSE) -> 62.448716 | H38: =+VLOOKUP($E38,Hybrid!$1:$1048576,H$2,FALSE) -> 80.963971 | I38: =+VLOOKUP($E38,Hybrid!$1:$1048576,I$2,FALSE) -> 99.823967 | J38: =+VLOOKUP($E38,Hybrid!$1:$1048576,J$2,FALSE) -> 118.71772 | K38: =+VLOOKUP($E38,Hybrid!$1:$1048576,K$2,FALSE) -> 137.4542 | L38: =+VLOOKUP($E38,Hybrid!$1:$1048576,L$2,FALSE) -> 155.92054 | M38: =+VLOOKUP($E38,Hybrid!$1:$1048576,M$2,FALSE) -> 174.05324 | ... AO38: =+VLOOKUP($E38,Hybrid!$1:$1048576,AO$2,FALSE) -> 567.61282
D39: class A | E39: AUTO_ca_cele_0 | F39: =+VLOOKUP($E39,Hybrid!$1:$1048576,F$2,FALSE) -> 9.8427899 | G39: =+VLOOKUP($E39,Hybrid!$1:$1048576,G$2,FALSE) -> 14.990816 | H39: =+VLOOKUP($E39,Hybrid!$1:$1048576,H$2,FALSE) -> 20.422984 | I39: =+VLOOKUP($E39,Hybrid!$1:$1048576,I$2,FALSE) -> 26.012773 | J39: =+VLOOKUP($E39,Hybrid!$1:$1048576,J$2,FALSE) -> 31.67695 | K39: =+VLOOKUP($E39,Hybrid!$1:$1048576,K$2,FALSE) -> 37.362607 | L39: =+VLOOKUP($E39,Hybrid!$1:$1048576,L$2,FALSE) -> 43.037132 | M39: =+VLOOKUP($E39,Hybrid!$1:$1048576,M$2,FALSE) -> 48.681062 | ... AO39: =+VLOOKUP($E39,Hybrid!$1:$1048576,AO$2,FALSE) -> 195.65639
D40: class B | E40: AUTO_cb_cele_0 | F40: =+VLOOKUP($E40,Hybrid!$1:$1048576,F$2,FALSE) -> 11.445717 | G40: =+VLOOKUP($E40,Hybrid!$1:$1048576,G$2,FALSE) -> 16.302056 | H40: =+VLOOKUP($E40,Hybrid!$1:$1048576,H$2,FALSE) -> 21.423897 | I40: =+VLOOKUP($E40,Hybrid!$1:$1048576,I$2,FALSE) -> 26.687145 | J40: =+VLOOKUP($E40,Hybrid!$1:$1048576,J$2,FALSE) -> 32.010429 | K40: =+VLOOKUP($E40,Hybrid!$1:$1048576,K$2,FALSE) -> 37.342129 | L40: =+VLOOKUP($E40,Hybrid!$1:$1048576,L$2,FALSE) -> 42.650406 | M40: =+VLOOKUP($E40,Hybrid!$1:$1048576,M$2,FALSE) -> 47.916154 | ... AO40: =+VLOOKUP($E40,Hybrid!$1:$1048576,AO$2,FALSE) -> 177.032
...

Sheet Primary
A1: _date_ | B1: 42005 | C1: 42370 | D1: 42736 | E1: 43101 | F1: 43466 | G1: 43831 | H1: 44197 | I1: 44562 | J1: 44927 | K1: 45292 | L1: 45658 | M1: 46023 | N1: 46388 | O1: 46753 | P1: 47119 | Q1: 47484 | R1: 47849 | S1: 48214 | T1: 48580 | U1: 48945 | V1: 49310 | W1: 49675 | X1: 50041 | Y1: 50406 | Z1: 50771 | AA1: 51136 | AB1: 51502 | AC1: 51867 | AD1: 52232 | AE1: 52597 | AF1: 52963 | AG1: 53328 | AH1: 53693 | AI1: 54058 | AJ1: 54424 | AK1: 54789
A2: yg_toe_2 | B2: 148.5762 | C2: 149.51833 | D2: 150.20339 | E2: 150.8468 | F2: 151.51552 | G2: 152.21225 | H2: 152.93671 | I2: 153.69789 | J2: 154.49581 | K2: 155.32369 | L2: 156.17039 | M2: 157.02223 | N2: 157.86422 | O2: 158.68104 | P2: 159.4577 | Q2: 160.18012 | R2: 160.84817 | S2: 161.47584 | T2: 162.07635 | U2: 162.65996 | V2: 163.23417 | W2: 163.80436 | X2: 164.37441 | Y2: 164.94717 | Z2: 165.5248 | AA2: 166.10902 | AB2: 166.7013 | AC2: 167.30293 | AD2: 167.91513 | AE2: 168.53913 | AF2: 169.17615 | AG2: 169.82746 | AH2: 170.4944 | AI2: 171.17836 | AJ2: 171.88078 | AK2: 172.60315
A3: yg_toe_0 | B3: 148.5762 | C3: 149.57013 | D3: 150.34484 | E3: 151.10989 | F3: 151.93569 | G3: 152.8347 | H3: 153.7993 | I3: 154.81743 | J3: 155.87806 | K3: 156.9727 | L3: 158.09525 | M3: 159.24155 | N3: 160.40878 | O3: 161.59512 | P3: 162.79935 | Q3: 164.0207 | R3: 165.25873 | S3: 166.51315 | T3: 167.78381 | U3: 169.07065 | V3: 170.37371 | W3: 171.69305 | X3: 173.02878 | Y3: 174.38103 | Z3: 175.74991 | AA3: 177.13559 | AB3: 178.53821 | AC3: 179.95794 | AD3: 181.39497 | AE3: 182.84948 | AF3: 184.32167 | AG3: 185.81175 | AH3: 187.31995 | AI3: 188.8465 | AJ3: 190.39163 | AK3: 191.95559
A4: yg_toe_ccoa_2 | B4: 2.391149 | C4: 2.4113403 | D4: 2.4286402 | E4: 2.4450674 | F4: 2.4608148 | G4: 2.4751913 | H4: 2.4883198 | I4: 2.5011328 | J4: 2.5140191 | K4: 2.5269145 | L4: 2.5394385 | M4: 2.5510018 | N4: 2.5608869 | O4: 2.5683162 | P4: 2.5725126 | Q4: 2.5727552 | R4: 2.5692525 | S4: 2.5630357 | T4: 2.5549306 | U4: 2.5455444 | V4: 2.5353159 | W4: 2.5245599 | X4: 2.5135003 | Y4: 2.5022939 | Z4: 2.4910476 | AA4: 2.4798318 | AB4: 2.468689 | AC4: 2.4576417 | AD4: 2.4466974 | AE4: 2.4358527 | AF4: 2.4250967 | AG4: 2.4144135 | AH4: 2.4037847 | AI4: 2.393191 | AJ4: 2.3826142 | AK4: 2.3720391
A5: yg_toe_ccoa_0 | B5: 2.391149 | C5: 2.4138098 | D5: 2.4355281 | E5: 2.4581598 | F5: 2.4821766 | G5: 2.5075019 | H5: 2.5339147 | I5: 2.5611973 | J5: 2.5891753 | K5: 2.6177206 | L5: 2.6467433 | M5: 2.6761821 | N5: 2.7059965 | O5: 2.7361603 | P5: 2.7666574 | Q5: 2.7974788 | R5: 2.8286204 | S5: 2.8600819 | T5: 2.8918649 | U5: 2.9239721 | V5: 2.9564069 | W5: 2.989173 | X5: 3.0222742 | Y5: 3.0557146 | Z5: 3.0894982 | AA5: 3.1236291 | AB5: 3.1581116 | AC5: 3.1929498 | AD5: 3.2281483 | AE5: 3.2637113 | AF5: 3.2996436 | AG5: 3.3359498 | AH5: 3.3726347 | AI5: 3.4097029 | AJ5: 3.4471595 | AK5: 3.4850092
A6: yg_toe_ccoi_2 | B6: 1.095999 | C6: 1.1024396 | D6: 1.1067161 | E6: 1.1110389 | F6: 1.1160485 | G6: 1.1216751 | H6: 1.127771 | I6: 1.1342991 | J6: 1.1412008 | K6: 1.1483812 | L6: 1.1557181 | M6: 1.1630714 | N6: 1.17029 | O6: 1.1772171 | P6: 1.1836957 | Q6: 1.1895728 | R6: 1.1948205 | S6: 1.1995524 | T6: 1.2038849 | U6: 1.2079064 | V6: 1.2116771 | W6: 1.215235 | X6: 1.2186023 | Y6: 1.2217888 | Z6: 1.2247962 | AA6: 1.2276197 | AB6: 1.2302501 | AC6: 1.2326749 | AD6: 1.2348793 | AE6: 1.2368471 | AF6: 1.2385613 | AG6: 1.2400049 | AH6: 1.2411616 | AI6: 1.2420163 | AJ6: 1.2425564 | AK6: 1.2427718
A7: yg_toe_ccoi_0 | B7: 1.095999 | C7: 1.1028001 | D7: 1.1077768 | E7: 1.1130992 | F7: 1.1194315 | G7: 1.1267863 | H7: 1.1349781 | I7: 1.1438038 | J7: 1.1530986 | K7: 1.1627433 | L7: 1.1726568 | M7: 1.1827858 | N7: 1.1930955 | O7: 1.2035636 | P7: 1.2141752 | Q7: 1.2249212 | R7: 1.2357956 | S7: 1.2467947 | T7: 1.2579163 | U7: 1.2691592 | V7: 1.2805225 | W7: 1.2920062 | X7: 1.3036102 | Y7: 1.3153347 | Z7: 1.3271803 | AA7: 1.3391474 | AB7: 1.3512369 | AC7: 1.3634497 | AD7: 1.3757866 | AE7: 1.3882489 | AF7: 1.4008378 | AG7: 1.4135548 | AH7: 1.4264013 | AI7: 1.439379 | AJ7: 1.4524895 | AK7: 1.4657345
A8: yg_toe_cfut_2 | B8: 42.352189 | C8: 42.550339 | D8: 42.686302 | E8: 42.84323 | F8: 43.038564 | G8: 43.264921 | H8: 43.513952 | I8: 43.78234 | J8: 44.066371 | K8: 44.361627 | L8: 44.663093 | M8: 44.965278 | N8: 45.26234 | O8: 45.548213 | P8: 45.816747 | Q8: 46.061855 | R8: 46.282313 | S8: 46.48215 | T8: 46.665228 | U8: 46.834475 | V8: 46.991904 | W8: 47.138777 | X8: 47.275784 | Y8: 47.403172 | Z8: 47.520858 | AA8: 47.628503 | AB8: 47.725575 | AC8: 47.811398 | AD8: 47.885191 | AE8: 47.946101 | AF8: 47.993243 | AG8: 48.025727 | AH8: 48.042696 | AI8: 48.043357 | AJ8: 48.027023 | AK8: 47.993144
A9: yg_toe_cfut_0 | B9: 42.352189 | C9: 42.563839 | D9: 42.725107 | E9: 42.918049 | F9: 43.161282 | G9: 43.450606 | H9: 43.776175 | I9: 44.128632 | J9: 44.500733 | K9: 44.887349 | L9: 45.285004 | M9: 45.691393 | N9: 46.104998 | O9: 46.524822 | P9: 46.950201 | Q9: 47.380695 | R9: 47.816006 | S9: 48.255934 | T9: 48.700343 | U9: 49.149141 | V9: 49.602269 | W9: 50.059687 | X9: 50.521372 | Y9: 50.987312 | Z9: 51.457506 | AA9: 51.931962 | AB9: 52.410696 | AC9: 52.893729 | AD9: 53.381093 | AE9: 53.872825 | AF9: 54.368969 | AG9: 54.869575 | AH9: 55.3747 | AI9: 55.884403 | AJ9: 56.398749 | AK9: 56.917805
A10: yg_toe_cfuh_2 | B10: 7.935536 | C10: 7.9839831 | D10: 8.0145869 | E10: 8.0387744 | F10: 8.0606898 | G10: 8.0809697 | H10: 8.100653 | I10: 8.1215149 | J10: 8.1440541 | K10: 8.1679441 | L10: 8.1923757 | M10: 8.2162685 | N10: 8.2383993 | O10: 8.2574887 | P10: 8.2722654 | Q10: 8.281521 | R10: 8.285611 | S10: 8.2862247 | T10: 8.284576 | U10: 8.2814961 | V10: 8.2775611 | W10: 8.2731806 | X10: 8.2686547 | Y10: 8.2642093 | Z10: 8.2600185 | AA10: 8.2562197 | AB10: 8.2529234 | AC10: 8.2502205 | AD10: 8.2481875 | AE10: 8.2468902 | AF10: 8.2463867 | AG10: 8.2467297 | AH10: 8.247968 | AI10: 8.2501482 | AJ10: 8.2533149 | AK10: 8.2575121
A11: yg_toe_cfuh_0 | B11: 7.935536 | C11: 7.9882333 | D11: 8.0259842 | E11: 8.0597632 | F11: 8.0940822 | G11: 8.1304841 | H11: 8.1692775 | I11: 8.2103169 | J11: 8.2533318 | K11: 8.2980554 | L11: 8.3442671 | M11: 8.3917989 | N11: 8.4405297 | O11: 8.4903729 | P11: 8.5412592 | Q11: 8.593147 | R11: 8.6460126 | S11: 8.6998426 | T11: 8.7546299 | U11: 8.8103707 | V11: 8.8670632 | W11: 8.9247063 | X11: 8.9832992 | Y11: 9.0428414 | Z11: 9.1033324 | AA11: 9.1647719 | AB11: 9.2271599 | AC11: 9.2904971 | AD11: 9.3547846 | AE11: 9.4200245 | AF11: 9.4862195 | AG11: 9.5533735 | AH11: 9.621491 | AI11: 9.6905774 | AJ11: 9.7606392 | AK11: 9.8316833
A12: yg_toe_cgas_2 | B12: 6.597728 | C12: 6.6023133 | D12: 6.5798666 | E12: 6.5467764 | F12: 6.5080886 | G12: 6.4644391 | H12: 6.4213775 | I12: 6.385027 | J12: 6.3548815 | K12: 6.3284719 | L12: 6.3031778 | M12: 6.2768809 | N12: 6.2481626 | O12: 6.2163283 | P12: 6.181363 | Q12: 6.1438464 | R12: 6.1075439 | S12: 6.076632 | T12: 6.0520068 | U12: 6.0333399 | V12: 6.0199343 | W12: 6.0110661 | X12: 6.0061042 | Y12: 6.0045364 | Z12: 6.005961 | AA12: 6.0100672 | AB12: 6.0166154 | AC12: 6.0254201 | AD12: 6.0363371 | AE12: 6.0492531 | AF12: 6.0640784 | AG12: 6.0807412 | AH12: 6.0991835 | AI12: 6.1193575 | AJ12: 6.1412232 | AK12: 6.1647457
... A29: yg_toe_cgas_sbga_0 | B29: 0.725794 | C29: 0.72814397 | D29: 0.72798387 | E29: 0.72682352 | F29: 0.72533505 | G29: 0.7238027 | H29: 0.72233199 | I29: 0.72094989 | J29: 0.71965249 | K29: 0.71842667 | L29: 0.71725912 | M29: 0.71613927 | N29: 0.71505967 | O29: 0.71401408 | P29: 0.71299577 | Q29: 0.71200142 | R29: 0.71102935 | S29: 0.7100787 | T29: 0.70914903 | U29: 0.70824019 | V29: 0.70735226 | W29: 0.70648549 | X29: 0.70564029 | Y29: 0.70481721 | Z29: 0.7040169 | AA29: 0.70324011 | AB29: 0.70248759 | AC29: 0.70176012 | AD29: 0.70105847 | AE29: 0.70038333 | AF29: 0.69973538 | AG29: 0.69911521 | AH29: 0.69852331 | AI29: 0.69796012 | AJ29: 0.69742595 | AK29: 0.69692106

Sheet Energy_Mix
A1: _date_ | B1: 42005 | C1: 42370 | D1: 42736 | E1: 43101 | F1: 43466 | G1: 43831 | H1: 44197 | I1: 44562 | J1: 44927 | K1: 45292 | L1: 45658 | M1: 46023 | N1: 46388 | O1: 46753 | P1: 47119 | Q1: 47484 | R1: 47849 | S1: 48214 | T1: 48580 | U1: 48945 | V1: 49310 | W1: 49675 | X1: 50041 | Y1: 50406 | Z1: 50771 | AA1: 51136 | AB1: 51502 | AC1: 51867 | AD1: 52232 | AE1: 52597 | AF1: 52963 | AG1: 53328 | AH1: 53693 | AI1: 54058 | AJ1: 54424 | AK1: 54789
A2: phiy_cfut_soil_2 | B2: 0.83809636 | C2: 0.83809636 | D2: 0.83809636 | E2: 0.83809636 | F2: 0.83809636 | G2: 0.83809636 | H2: 0.83809636 | I2: 0.83809636 | J2: 0.83809636 | K2: 0.83809636 | L2: 0.83809636 | M2: 0.83809636 | N2: 0.83809636 | O2: 0.83809636 | P2: 0.83809636 | Q2: 0.83809636 | R2: 0.83809636 | S2: 0.83809636 | T2: 0.83809636 | U2: 0.83809636 | V2: 0.83809636 | W2: 0.83809636 | X2: 0.83809636 | Y2: 0.83809636 | Z2: 0.83809636 | AA2: 0.83809636 | AB2: 0.83809636 | AC2: 0.83809636 | AD2: 0.83809636 | AE2: 0.83809636 | AF2: 0.83809636 | AG2: 0.83809636 | AH2: 0.83809636 | AI2: 0.83809636 | AJ2: 0.83809636 | AK2: 0.83809636
A3: phiy_cfut_sbfu_2 | B3: 0.16190364 | C3: 0.16190364 | D3: 0.16190364 | E3: 0.16190364 | F3: 0.16190364 | G3: 0.16190364 | H3: 0.16190364 | I3: 0.16190364 | J3: 0.16190364 | K3: 0.16190364 | L3: 0.16190364 | M3: 0.16190364 | N3: 0.16190364 | O3: 0.16190364 | P3: 0.16190364 | Q3: 0.16190364 | R3: 0.16190364 | S3: 0.16190364 | T3: 0.16190364 | U3: 0.16190364 | V3: 0.16190364 | W3: 0.16190364 | X3: 0.16190364 | Y3: 0.16190364 | Z3: 0.16190364 | AA3: 0.16190364 | AB3: 0.16190364 | AC3: 0.16190364 | AD3: 0.16190364 | AE3: 0.16190364 | AF3: 0.16190364 | AG3: 0.16190364 | AH3: 0.16190364 | AI3: 0.16190364 | AJ3: 0.16190364 | AK3: 0.16190364
A4: phiy_cgas_sgas_2 | B4: 0.14751432 | C4: 0.14751432 | D4: 0.14751432 | E4: 0.14751432 | F4: 0.14751432 | G4: 0.14751432 | H4: 0.14751432 | I4: 0.14751432 | J4: 0.14751432 | K4: 0.14751432 | L4: 0.14751432 | M4: 0.14751432 | N4: 0.14751432 | O4: 0.14751432 | P4: 0.14751432 | Q4: 0.14751432 | R4: 0.14751432 | S4: 0.14751432 | T4: 0.14751432 | U4: 0.14751432 | V4: 0.14751432 | W4: 0.14751432 | X4: 0.14751432 | Y4: 0.14751432 | Z4: 0.14751432 | AA4: 0.14751432 | AB4: 0.14751432 | AC4: 0.14751432 | AD4: 0.14751432 | AE4: 0.14751432 | AF4: 0.14751432 | AG4: 0.14751432 | AH4: 0.14751432 | AI4: 0.14751432 | AJ4: 0.14751432 | AK4: 0.14751432
A5: phiy_cgas_sbga_2 | B5: 0.20708639 | C5: 0.20708639 | D5: 0.20708639 | E5: 0.20708639 | F5: 0.20708639 | G5: 0.20708639 | H5: 0.20708639 | I5: 0.20708639 | J5: 0.20708639 | K5: 0.20708639 | L5: 0.20708639 | M5: 0.20708639 | N5: 0.20708639 | O5: 0.20708639 | P5: 0.20708639 | Q5: 0.20708639 | R5: 0.20708639 | S5: 0.20708639 | T5: 0.20708639 | U5: 0.20708639 | V5: 0.20708639 | W5: 0.20708639 | X5: 0.20708639 | Y5: 0.20708639 | Z5: 0.20708639 | AA5: 0.20708639 | AB5: 0.20708639 | AC5: 0.20708639 | AD5: 0.20708639 | AE5: 0.20708639 | AF5: 0.20708639 | AG5: 0.20708639 | AH5: 0.20708639 | AI5: 0.20708639 | AJ5: 0.20708639 | AK5: 0.20708639
A6: phiy_cele_senu_2 | B6: 0.72577004 | C6: 0.72577008 | D6: 0.72577008 | E6: 0.72577008 | F6: 0.72577008 | G6: 0.72577008 | H6: 0.72577008 | I6: 0.72577008 | J6: 0.72577008 | K6: 0.72577008 | L6: 0.72577008 | M6: 0.72577008 | N6: 0.72577008 | O6: 0.72577008 | P6: 0.72577008 | Q6: 0.72577008 | R6: 0.72577008 | S6: 0.72577008 | T6: 0.72577008 | U6: 0.72577008 | V6: 0.72577008 | W6: 0.72577008 | X6: 0.72577008 | Y6: 0.72577008 | Z6: 0.72577008 | AA6: 0.72577008 | AB6: 0.72577008 | AC6: 0.72577008 | AD6: 0.72577008 | AE6: 0.72577008 | AF6: 0.72577008 | AG6: 0.72577008 | AH6: 0.72577008 | AI6: 0.72577008 | AJ6: 0.72577008 | AK6: 0.72577008
A7: phiy_cele_seoi_2 | B7: 0.014464495 | C7: 0.014464496 | D7: 0.014464496 | E7: 0.014464496 | F7: 0.014464496 | G7: 0.014464496 | H7: 0.014464496 | I7: 0.014464496 | J7: 0.014464496 | K7: 0.014464496 | L7: 0.014464496 | M7: 0.014464496 | N7: 0.014464496 | O7: 0.014464496 | P7: 0.014464496 | Q7: 0.014464496 | R7: 0.014464496 | S7: 0.014464496 | T7: 0.014464496 | U7: 0.014464496 | V7: 0.014464496 | W7: 0.014464496 | X7: 0.014464496 | Y7: 0.014464496 | Z7: 0.014464496 | AA7: 0.014464496 | AB7: 0.014464496 | AC7: 0.014464496 | AD7: 0.014464496 | AE7: 0.014464496 | AF7: 0.014464496 | AG7: 0.014464496 | AH7: 0.014464496 | AI7: 0.014464496 | AJ7: 0.014464496 | AK7: 0.014464496
A8: phiy_cele_sega_2 | B8: 0.021019341 | C8: 0.021019342 | D8: 0.021019342 | E8: 0.021019342 | F8: 0.021019342 | G8: 0.021019342 | H8: 0.021019342 | I8: 0.021019342 | J8: 0.021019342 | K8: 0.021019342 | L8: 0.021019342 | M8: 0.021019342 | N8: 0.021019342 | O8: 0.021019342 | P8: 0.021019342 | Q8: 0.021019342 | R8: 0.021019342 | S8: 0.021019342 | T8: 0.021019342 | U8: 0.021019342 | V8: 0.021019342 | W8: 0.021019342 | X8: 0.021019342 | Y8: 0.021019342 | Z8: 0.021019342 | AA8: 0.021019342 | AB8: 0.021019342 | AC8: 0.021019342 | AD8: 0.021019342 | AE8: 0.021019342 | AF8: 0.021019342 | AG8: 0.021019342 | AH8: 0.021019342 | AI8: 0.021019342 | AJ8: 0.021019342 | AK8: 0.021019342
A9: phiy_cele_seco_2 | B9: 0.01909619 | C9: 0.019096192 | D9: 0.019096192 | E9: 0.019096192 | F9: 0.019096192 | G9: 0.019096192 | H9: 0.019096192 | I9: 0.019096192 | J9: 0.019096192 | K9: 0.019096192 | L9: 0.019096192 | M9: 0.019096192 | N9: 0.019096192 | O9: 0.019096192 | P9: 0.019096192 | Q9: 0.019096192 | R9: 0.019096192 | S9: 0.019096192 | T9: 0.019096192 | U9: 0.019096192 | V9: 0.019096192 | W9: 0.019096192 | X9: 0.019096192 | Y9: 0.019096192 | Z9: 0.019096192 | AA9: 0.019096192 | AB9: 0.019096192 | AC9: 0.019096192 | AD9: 0.019096192 | AE9: 0.019096192 | AF9: 0.019096192 | AG9: 0.019096192 | AH9: 0.019096192 | AI9: 0.019096192 | AJ9: 0.019096192 | AK9: 0.019096192
A10: phiy_cele_sewi_2 | B10: 0.03758097 | C10: 0.037580914 | D10: 0.037580914 | E10: 0.037580914 | F10: 0.037580914 | G10: 0.037580914 | H10: 0.037580914 | I10: 0.037580914 | J10: 0.037580914 | K10: 0.037580914 | L10: 0.037580914 | M10: 0.037580914 | N10: 0.037580914 | O10: 0.037580914 | P10: 0.037580914 | Q10: 0.037580914 | R10: 0.037580914 | S10: 0.037580914 | T10: 0.037580914 | U10: 0.037580914 | V10: 0.037580914 | W10: 0.037580914 | X10: 0.037580914 | Y10: 0.037580914 | Z10: 0.037580914 | AA10: 0.037580914 | AB10: 0.037580914 | AC10: 0.037580914 | AD10: 0.037580914 | AE10: 0.037580914 | AF10: 0.037580914 | AG10: 0.037580914 | AH10: 0.037580914 | AI10: 0.037580914 | AJ10: 0.037580914 | AK10: 0.037580914
A11: phiy_cele_seso_2 | B11: 0.013662118 | C11: 0.013662119 | D11: 0.013662119 | E11: 0.013662119 | F11: 0.013662119 | G11: 0.013662119 | H11: 0.013662119 | I11: 0.013662119 | J11: 0.013662119 | K11: 0.013662119 | L11: 0.013662119 | M11: 0.013662119 | N11: 0.013662119 | O11: 0.013662119 | P11: 0.013662119 | Q11: 0.013662119 | R11: 0.013662119 | S11: 0.013662119 | T11: 0.013662119 | U11: 0.013662119 | V11: 0.013662119 | W11: 0.013662119 | X11: 0.013662119 | Y11: 0.013662119 | Z11: 0.013662119 | AA11: 0.013662119 | AB11: 0.013662119 | AC11: 0.013662119 | AD11: 0.013662119 | AE11: 0.013662119 | AF11: 0.013662119 | AG11: 0.013662119 | AH11: 0.013662119 | AI11: 0.013662119 | AJ11: 0.013662119 | AK11: 0.013662119
A12: phiy_cele_sehy_2 | B12: 0.10517305 | C12: 0.10517306 | D12: 0.10517306 | E12: 0.10517306 | F12: 0.10517306 | G12: 0.10517306 | H12: 0.10517306 | I12: 0.10517306 | J12: 0.10517306 | K12: 0.10517306 | L12: 0.10517306 | M12: 0.10517306 | N12: 0.10517306 | O12: 0.10517306 | P12: 0.10517306 | Q12: 0.10517306 | R12: 0.10517306 | S12: 0.10517306 | T12: 0.10517306 | U12: 0.10517306 | V12: 0.10517306 | W12: 0.10517306 | X12: 0.10517306 | Y12: 0.10517306 | Z12: 0.10517306 | AA12: 0.10517306 | AB12: 0.10517306 | AC12: 0.10517306 | AD12: 0.10517306 | AE12: 0.10517306 | AF12: 0.10517306 | AG12: 0.10517306 | AH12: 0.10517306 | AI12: 0.10517306 | AJ12: 0.10517306 | AK12: 0.10517306
... A27: phiy_cele_seot_0 | B27: 0.0017180069 | C27: 0.001718007 | D27: 0.001718007 | E27: 0.001718007 | F27: 0.001718007 | G27: 0.001718007 | H27: 0.001718007 | I27: 0.001718007 | J27: 0.001718007 | K27: 0.001718007 | L27: 0.001718007 | M27: 0.001718007 | N27: 0.001718007 | O27: 0.001718007 | P27: 0.001718007 | Q27: 0.001718007 | R27: 0.001718007 | S27: 0.001718007 | T27: 0.001718007 | U27: 0.001718007 | V27: 0.001718007 | W27: 0.001718007 | X27: 0.001718007 | Y27: 0.001718007 | Z27: 0.001718007 | AA27: 0.001718007 | AB27: 0.001718007 | AC27: 0.001718007 | AD27: 0.001718007 | AE27: 0.001718007 | AF27: 0.001718007 | AG27: 0.001718007 | AH27: 0.001718007 | AI27: 0.001718007 | AJ27: 0.001718007 | AK27: 0.001718007

Sheet Transports
A1: _date_ | B1: 42005 | C1: 42370 | D1: 42736 | E1: 43101 | F1: 43466 | G1: 43831 | H1: 44197 | I1: 44562 | J1: 44927 | K1: 45292 | L1: 45658 | M1: 46023 | N1: 46388 | O1: 46753 | P1: 47119 | Q1: 47484 | R1: 47849 | S1: 48214 | T1: 48580 | U1: 48945 | V1: 49310 | W1: 49675 | X1: 50041 | Y1: 50406 | Z1: 50771 | AA1: 51136 | AB1: 51502 | AC1: 51867 | AD1: 52232 | AE1: 52597 | AF1: 52963 | AG1: 53328 | AH1: 53693 | AI1: 54058 | AJ1: 54424 | AK1: 54789
A2: km_traveler_cair_2 | B2: 291099.78 | C2: 295820.99 | D2: 300398.31 | E2: 304939.29 | F2: 309486.94 | G2: 314040.24 | H2: 318658.45 | I2: 323442.27 | J2: 328421.13 | K2: 333574.55 | L2: 338859.98 | M2: 344226.69 | N2: 349622.81 | O2: 354999.02 | P2: 360310.58 | Q2: 365518.72 | R2: 370661.38 | S2: 375836.59 | T2: 381104.41 | U2: 386493 | V2: 392014.59 | W2: 397673.38 | X2: 403469.62 | Y2: 409401.64 | Z2: 415466.73 | AA2: 421661.63 | AB2: 427982.62 | AC2: 434425.61 | AD2: 440986.26 | AE2: 447659.98 | AF2: 454442.11 | AG2: 461327.96 | AH2: 468312.95 | AI2: 475392.66 | AJ2: 482562.95 | AK2: 489820.02
A3: km_trav_auto_ld_2+km_trav_auto_sd_2 | B3: 724102.94 | C3: 715355.49 | D3: 710971.42 | E3: 709498.48 | F3: 709947.49 | G3: 711651.17 | H3: 714212.51 | I3: 717410.6 | J3: 721079.02 | K3: 725085.74 | L3: 729322.26 | M3: 733696.16 | N3: 738125.9 | O3: 742537.43 | P3: 746861.78 | Q3: 751033.63 | R3: 755045.86 | S3: 758941.14 | T3: 762741.97 | U3: 766458.72 | V3: 770096.05 | W3: 773656.44 | X3: 777141.92 | Y3: 780554.97 | Z3: 783898.91 | AA3: 787178.13 | AB3: 790398.23 | AC3: 793566.13 | AD3: 796690.14 | AE3: 799780.09 | AF3: 802847.37 | AG3: 805904.99 | AH3: 808967.65 | AI3: 812051.66 | AJ3: 815174.9 | AK3: 818356.68
A4: km_traveler_sd_2 | B4: 624600.34 | C4: 618861.96 | D4: 616086.94 | E4: 615320.55 | F4: 615893.37 | G4: 617345.72 | H4: 619400.72 | I4: 621904.14 | J4: 624740.22 | K4: 627815.98 | L4: 631054.33 | M4: 634389.27 | N4: 637762.46 | O4: 641120.92 | P4: 644415.42 | Q4: 647599.46 | R4: 650667.15 | S4: 653648.66 | T4: 656561.13 | U4: 659412.6 | V4: 662206.81 | W4: 664945.75 | X4: 667630.94 | Y4: 670264.14 | Z4: 672847.6 | AA4: 675384.29 | AB4: 677878.01 | AC4: 680333.43 | AD4: 682756.21 | AE4: 685153.03 | AF4: 687531.66 | AG4: 689901.02 | AH4: 692271.18 | AI4: 694653.38 | AJ4: 697059.91 | AK4: 699504.11
A5: km_trav_auto_sd_2 | B5: 554271.64 | C5: 547921.8 | D5: 544690.45 | E5: 543539.71 | F5: 543761.34 | G5: 544877.08 | H5: 546602.29 | I5: 548778.6 | J5: 551286.78 | K5: 554032.31 | L5: 556937.57 | M5: 559936.54 | N5: 562971.09 | O5: 565988.51 | P5: 568939.9 | Q5: 571779.04 | R5: 574501.2 | S5: 577137.05 | T5: 579702.89 | U5: 582206.36 | V5: 584650.97 | W5: 587038.66 | X5: 589371.02 | Y5: 591649.95 | Z5: 593877.92 | AA5: 596058.19 | AB5: 598194.86 | AC5: 600292.93 | AD5: 602358.42 | AE5: 604398.34 | AF5: 606420.83 | AG5: 608435.13 | AH5: 610451.63 | AI5: 612481.83 | AJ5: 614538.29 | AK5: 616634.53
A6: km_traveler_croa_2 | B6: 70328.7 | C6: 70321.714 | D6: 70422.251 | E6: 70597.879 | F6: 70825.341 | G6: 71088.354 | H6: 71376.45 | I6: 71684.112 | J6: 72007.76 | K6: 72343.932 | L6: 72689.393 | M6: 73041.122 | N6: 73396.293 | O6: 73752.239 | P6: 74106.43 | Q6: 74456.445 | R6: 74801.305 | S6: 75142.139 | T6: 75480.232 | U6: 75816.213 | V6: 76150.391 | W6: 76482.908 | X6: 76813.819 | Y6: 77143.137 | Z6: 77470.868 | AA6: 77797.019 | AB6: 78121.617 | AC6: 78444.712 | AD6: 78766.388 | AE6: 79086.767 | AF6: 79406.016 | AG6: 79724.355 | AH6: 80042.056 | AI6: 80359.451 | AJ6: 80676.929 | AK6: 80994.935
A7: km_traveler_ld_2 | B7: 275159.81 | C7: 270792.35 | D7: 268629.34 | E7: 267925.6 | F7: 268182.2 | G7: 269066.09 | H7: 270380.45 | I7: 272015.85 | J7: 273889.6 | K7: 275936.38 | L7: 278102.66 | M7: 280342.82 | N7: 282616.53 | O7: 284886.94 | P7: 287119.53 | Q7: 289281.38 | R7: 291368.75 | S7: 293402.59 | T7: 295393.37 | U7: 297345.68 | V7: 299261.42 | W7: 301141.52 | X7: 302986.77 | Y7: 304798.25 | Z7: 306577.46 | AA7: 308326.49 | AB7: 310048.08 | AC7: 311745.62 | AD7: 313423.28 | AE7: 315086 | AF7: 316739.56 | AG7: 318390.62 | AH7: 320046.74 | AI7: 321716.35 | AJ7: 323408.76 | AK7: 325134.06
A8: km_trav_auto_ld_2 | B8: 169831.3 | C8: 167433.69 | D8: 166280.96 | E8: 165958.76 | F8: 166186.15 | G8: 166774.09 | H8: 167610.22 | I8: 168632 | J8: 169792.24 | K8: 171053.44 | L8: 172384.69 | M8: 173759.61 | N8: 175154.82 | O8: 176548.92 | P8: 177921.88 | Q8: 179254.59 | R8: 180544.66 | S8: 181804.09 | T8: 183039.08 | U8: 184252.36 | V8: 185445.08 | W8: 186617.78 | X8: 187770.9 | Y8: 188905.03 | Z8: 190020.99 | AA8: 191119.93 | AB8: 192203.37 | AC8: 193273.19 | AD8: 194331.73 | AE8: 195381.76 | AF8: 196426.54 | AG8: 197469.86 | AH8: 198516.02 | AI8: 199569.83 | AJ8: 200636.61 | AK8: 201722.15
A9: km_traveler_crai_2 | B9: 105328.51 | C9: 106469.68 | D9: 107456.72 | E9: 108342.29 | F9: 109165.34 | G9: 109953.23 | H9: 110720.41 | I9: 111476.07 | J9: 112229.34 | K9: 112985.45 | L9: 113747.47 | M9: 114517.13 | N9: 115295.4 | O9: 116082.8 | P9: 116879.61 | Q9: 117685.97 | R9: 118499.29 | S9: 119317.63 | T9: 120142.3 | U9: 120973.97 | V9: 121813.01 | W9: 122659.55 | X9: 123513.49 | Y9: 124374.54 | Z9: 125242.25 | AA9: 126116.04 | AB9: 126995.22 | AC9: 127878.97 | AD9: 128766.41 | AE9: 129656.57 | AF9: 130548.42 | AG9: 131440.88 | AH9: 132332.84 | AI9: 133223.15 | AJ9: 134110.68 | AK9: 134994.27
A10: km_traveler_cair_0 | B10: 291099.78 | C10: 295997.44 | D10: 300860.61 | E10: 305754.88 | F10: 310735.66 | G10: 315838.96 | H10: 321084.31 | I10: 326479.86 | J10: 332026.96 | K10: 337723.36 | L10: 343565.4 | M10: 349549.33 | N10: 355671.93 | O10: 361930.82 | P10: 368324.44 | Q10: 374851.94 | R10: 381513.03 | S10: 388307.75 | T10: 395236.36 | U10: 402299.23 | V10: 409496.72 | W10: 416829.19 | X10: 424297 | Y10: 431900.48 | Z10: 439640.02 | AA10: 447516.04 | AB10: 455529.1 | AC10: 463679.89 | AD10: 471969.28 | AE10: 480398.31 | AF10: 488968.27 | AG10: 497680.64 | AH10: 506537.12 | AI10: 515539.66 | AJ10: 524690.39 | AK10: 533991.65
A11: km_trav_auto_ld_0+km_trav_auto_sd_0 | B11: 724102.94 | C11: 715470.96 | D11: 711264.17 | E11: 710013.52 | F11: 710740.21 | G11: 712802.83 | H11: 715783.55 | I11: 719409 | J11: 723497.85 | K11: 727927.15 | L11: 732611.22 | M11: 737488.53 | N11: 742513.6 | O11: 747651.94 | P11: 752876.85 | Q11: 758167.34 | R11: 763506.69 | S11: 768881.53 | T11: 774281.06 | U11: 779696.54 | V11: 785120.94 | W11: 790548.57 | X11: 795974.88 | Y11: 801396.29 | Z11: 806810.03 | AA11: 812214.03 | AB11: 817606.83 | AC11: 822987.5 | AD11: 828355.61 | AE11: 833711.09 | AF11: 839054.27 | AG11: 844385.75 | AH11: 849706.42 | AI11: 855017.37 | AJ11: 860319.87 | AK11: 865615.34
A12: km_traveler_sd_0 | B12: 624600.34 | C12: 618939.61 | D12: 616289.44 | E12: 615681.22 | F12: 616451.95 | G12: 618159.91 | H12: 620514.3 | I12: 623323.46 | J12: 626459.54 | K12: 629835.38 | L12: 633389.98 | M12: 637079.36 | N12: 640870.94 | O12: 644739.98 | P12: 648667.38 | Q12: 652638.14 | R12: 656640.39 | S12: 660664.65 | T12: 664703.32 | U12: 668750.31 | V12: 672800.7 | W12: 676850.59 | X12: 680896.84 | Y12: 684937.02 | Z12: 688969.25 | AA12: 692992.16 | AB12: 697004.79 | AC12: 701006.58 | AD12: 704997.26 | AE12: 708976.87 | AF12: 712945.68 | AG12: 716904.19 | AH12: 720853.05 | AI12: 724793.07 | AJ12: 728725.2 | AK12: 732650.46
... A17: km_traveler_crai_0 | B17: 105328.51 | C17: 106459.91 | D17: 107439.19 | E17: 108316.26 | F17: 109128.73 | G17: 109902.85 | H17: 110656.13 | I17: 111399.76 | J17: 112140.59 | K17: 112882.66 | L17: 113628.2 | M17: 114378.45 | N17: 115134.04 | O17: 115895.36 | P17: 116662.67 | Q17: 117436.16 | R17: 118216.02 | S17: 119002.41 | T17: 119795.47 | U17: 120595.32 | V17: 121402.02 | W17: 122215.62 | X17: 123036.12 | Y17: 123863.49 | Z17: 124697.68 | AA17: 125538.64 | AB17: 126386.3 | AC17: 127240.59 | AD17: 128101.43 | AE17: 128968.79 | AF17: 129842.6 | AG17: 130722.83 | AH17: 131609.47 | AI17: 132502.5 | AJ17: 133401.93 | AK17: 134307.77

Sheet Hybrid
A1: _date_ | B1: 42005 | C1: 42370 | D1: 42736 | E1: 43101 | F1: 43466 | G1: 43831 | H1: 44197 | I1: 44562 | J1: 44927 | K1: 45292 | L1: 45658 | M1: 46023 | N1: 46388 | O1: 46753 | P1: 47119 | Q1: 47484 | R1: 47849 | S1: 48214 | T1: 48580 | U1: 48945 | V1: 49310 | W1: 49675 | X1: 50041 | Y1: 50406 | Z1: 50771 | AA1: 51136 | AB1: 51502 | AC1: 51867 | AD1: 52232 | AE1: 52597 | AF1: 52963 | AG1: 53328 | AH1: 53693 | AI1: 54058 | AJ1: 54424 | AK1: 54789
A2: auto_2 | B2: 32317.941 | C2: 31926.455 | D2: 31730.401 | E2: 31664.733 | F2: 31685.152 | G2: 31761.774 | H2: 31876.82 | I2: 32020.398 | J2: 32185.056 | K2: 32364.879 | L2: 32555.008 | M2: 32751.304 | N2: 32950.116 | O2: 33148.124 | P2: 33342.238 | Q2: 33529.533 | R2: 33709.688 | S2: 33884.612 | T2: 34055.315 | U2: 34222.258 | V2: 34385.651 | W2: 34545.604 | X2: 34702.207 | Y2: 34855.571 | Z2: 35005.845 | AA2: 35153.224 | AB2: 35297.96 | AC2: 35440.362 | AD2: 35580.802 | AE2: 35719.72 | AF2: 35857.626 | AG2: 35995.104 | AH2: 36132.812 | AI2: 36271.48 | AJ2: 36411.912 | AK2: 36554.972
A3: auto_cfut_2 | B3: 32271.24 | C3: 31862.032 | D3: 31647.329 | E3: 31562.481 | F3: 31563.392 | G3: 31620.229 | H3: 31715.127 | I3: 31838.038 | J3: 31981.349 | K3: 32138.974 | L3: 32305.854 | M3: 32477.604 | N3: 32650.259 | O3: 32820.093 | P3: 32983.48 | Q3: 33136.779 | R3: 33278.705 | S3: 33409.974 | T3: 33530.266 | U3: 33638.562 | V3: 33733.424 | W3: 33813.135 | X3: 33875.774 | Y3: 33919.241 | Z3: 33941.277 | AA3: 33939.472 | AB3: 33911.279 | AC3: 33854.036 | AD3: 33764.983 | AE3: 33641.306 | AF3: 33480.173 | AG3: 33278.793 | AH3: 33034.477 | AI3: 32744.706 | AJ3: 32407.216 | AK3: 32020.075
A4: auto_cele_2 | B4: 44.765 | C4: 62.431569 | D4: 81.013696 | E4: 100.12298 | F4: 119.55791 | G4: 139.26917 | H4: 159.3444 | I4: 179.94081 | J4: 201.21851 | K4: 223.34991 | L4: 246.53496 | M4: 271.01944 | N4: 297.11658 | O4: 325.23391 | P4: 355.90822 | Q4: 389.85321 | R4: 428.03471 | S4: 471.64532 | T4: 522.01458 | U4: 580.62349 | V4: 649.11914 | W4: 729.32712 | X4: 823.26146 | Y4: 933.13161 | Z4: 1061.3459 | AA4: 1210.5101 | AB4: 1383.4212 | AC4: 1583.0534 | AD4: 1812.5367 | AE4: 2075.1269 | AF4: 2374.165 | AG4: 2713.0263 | AH4: 3095.0588 | AI4: 3523.5113 | AJ4: 4001.4513 | AK4: 4531.6755
A5: auto_cgas_2 | B5: 1.936 | C5: 1.9916056 | D5: 2.0574011 | E5: 2.1285899 | F5: 2.2019794 | G5: 2.2754864 | H5: 2.3479684 | I5: 2.4188941 | J5: 2.4879043 | K5: 2.5547408 | L5: 2.6192081 | M5: 2.6811463 | N5: 2.7404123 | O5: 2.796866 | P5: 2.8503601 | Q5: 2.9007315 | R5: 2.9480014 | S5: 2.9923496 | T5: 3.033862 | U5: 3.0725586 | V5: 3.1084159 | W5: 3.1413797 | X5: 3.17137 | Y5: 3.1982849 | Z5: 3.2220012 | AA5: 3.2423764 | AB5: 3.2592496 | AC5: 3.2724433 | AD5: 3.2817658 | AE5: 3.2870146 | AF5: 3.2879801 | AG5: 3.2844506 | AH5: 3.2762179 | AI5: 3.2630839 | AJ5: 3.2448672 | AK5: 3.2214115
A6: newauto_2 | B6: 1886.229 | C6: 2121.806 | D6: 2286.103 | E6: 2400.5287 | F6: 2480.7808 | G6: 2537.837 | H6: 2581.4774 | I6: 2618.2022 | J6: 2649.6746 | K6: 2676.8483 | L6: 2700.3106 | M6: 2720.3954 | N6: 2737.2597 | O6: 2750.94 | P6: 2761.3918 | Q6: 2768.517 | R6: 2774.6678 | S6: 2782.0126 | T6: 2789.7533 | U6: 2797.3729 | V6: 2804.5969 | W6: 2811.2808 | X6: 2817.3451 | Y6: 2822.7399 | Z6: 2827.4284 | AA6: 2831.3791 | AB6: 2834.5629 | AC6: 2836.9523 | AD6: 2838.522 | AE6: 2839.2497 | AF6: 2839.1172 | AG6: 2838.111 | AH6: 2836.2233 | AI6: 2833.4523 | AJ6: 2829.8021 | AK6: 2825.2831
A7: newauto_cfut_2 | B7: 1868.803 | C7: 2102.1722 | D7: 2264.8333 | E7: 2377.9791 | F7: 2457.1346 | G7: 2513.1323 | H7: 2555.6166 | I7: 2591.0143 | J7: 2620.9791 | K7: 2646.4458 | L7: 2667.9674 | M7: 2685.8239 | N7: 2700.095 | O7: 2710.7103 | P7: 2717.4798 | Q7: 2720.1072 | R7: 2720.6636 | S7: 2721.052 | T7: 2720.2897 | U7: 2717.6551 | V7: 2712.6484 | W7: 2704.8808 | X7: 2694.0114 | Y7: 2679.7142 | Z7: 2661.6653 | AA7: 2639.5392 | AB7: 2613.0118 | AC7: 2581.7664 | AD7: 2545.5027 | AE7: 2503.9477 | AF7: 2456.8677 | AG7: 2404.0812 | AH7: 2345.4727 | AI7: 2281.0058 | AJ7: 2210.7359 | AK7: 2134.8214
A8: newauto_cele_2 | B8: 17.269 | C8: 19.457169 | D8: 21.079389 | E8: 22.349837 | F8: 23.439846 | G8: 24.493574 | H8: 25.645995 | I8: 26.970187 | J8: 28.475336 | K8: 30.180137 | L8: 32.119048 | M8: 34.345876 | N8: 36.937918 | O8: 40.001998 | P8: 43.683666 | Q8: 48.181314 | R8: 53.775634 | S8: 60.731991 | T8: 69.235074 | U8: 79.489497 | V8: 91.720592 | W8: 106.17275 | X8: 123.10742 | Y8: 142.80061 | Z8: 165.53951 | AA8: 191.6181 | AB8: 221.33152 | AC8: 254.96899 | AD8: 292.80546 | AE8: 335.09168 | AF8: 382.04314 | AG8: 433.82787 | AH8: 490.55361 | AI8: 552.25485 | AJ8: 618.8804 | AK8: 690.28232
A9: newauto_cgas_2 | B9: 0.157 | C9: 0.17660558 | D9: 0.1902709 | E9: 0.19977639 | F9: 0.20642632 | G9: 0.21113075 | H9: 0.2146999 | I9: 0.21767369 | J9: 0.22019106 | K9: 0.22233054 | L9: 0.2241386 | M9: 0.22563874 | N9: 0.22683767 | O9: 0.22772947 | P9: 0.22829818 | Q9: 0.22851891 | R9: 0.22856566 | S9: 0.22859828 | T9: 0.22853425 | U9: 0.22831291 | V9: 0.22789229 | W9: 0.22723973 | X9: 0.22632658 | Y9: 0.22512545 | Z9: 0.22360915 | AA9: 0.22175032 | AB9: 0.21952173 | AC9: 0.21689677 | AD9: 0.21385022 | AE9: 0.21035914 | AF9: 0.2064039 | AG9: 0.20196925 | AH9: 0.1970455 | AI9: 0.19162957 | AJ9: 0.18572613 | AK9: 0.17934847
A10: auto_ca_cfut_2 | B10: 7095.7005 | C10: 7141.744 | D10: 7236.2109 | E10: 7362.7565 | F10: 7510.0299 | G10: 7670.2472 | H10: 7838.785 | I10: 8013.1055 | J10: 8191.247 | K10: 8371.6256 | L10: 8552.9219 | M10: 8733.9921 | N10: 8913.8008 | O10: 9091.3684 | P10: 9265.7305 | Q10: 9435.9023 | R10: 9601.6399 | S10: 9763.3044 | T10: 9920.8512 | U10: 10073.962 | V10: 10222.146 | W10: 10364.788 | X10: 10501.176 | Y10: 10630.509 | Z10: 10751.903 | AA10: 10864.388 | AB10: 10966.919 | AC10: 11058.37 | AD10: 11137.548 | AE10: 11203.202 | AF10: 11254.038 | AG10: 11288.736 | AH10: 11305.979 | AI10: 11304.477 | AJ10: 11283.004 | AK10: 11240.43
A11: auto_cb_cfut_2 | B11: 8251.2564 | C11: 8182.7845 | D11: 8168.3356 | E11: 8191.2663 | F11: 8239.913 | G11: 8306.1531 | H11: 8384.9727 | I11: 8473.4298 | J11: 8569.2032 | K11: 8670.3749 | L11: 8775.306 | M11: 8882.5442 | N11: 8990.7536 | O11: 9098.6627 | P11: 9205.023 | Q11: 9308.5738 | R11: 9408.7536 | S11: 9505.5998 | T11: 9598.8301 | U11: 9687.9491 | V11: 9772.3323 | W11: 9851.2702 | X11: 9923.9898 | Y11: 9989.6639 | Z11: 10047.417 | AA11: 10096.329 | AB11: 10135.439 | AC11: 10163.754 | AD11: 10180.258 | AE11: 10183.922 | AF11: 10173.723 | AG11: 10148.662 | AH11: 10107.786 | AI11: 10050.216 | AJ11: 9975.1683 | AK11: 9881.9911
A12: auto_cc_cfut_2 | B12: 6777.6025 | C12: 6646.7629 | D12: 6558.9664 | E12: 6502.0082 | F12: 6467.2622 | G12: 6448.6373 | H12: 6442.2478 | I12: 6445.693 | J12: 6457.0498 | K12: 6474.7042 | L12: 6497.2553 | M12: 6523.4452 | N12: 6552.1089 | O12: 6582.1356 | P12: 6612.4399 | Q12: 6641.9367 | R12: 6670.0211 | S12: 6696.5179 | T12: 6721.0788 | U12: 6743.2423 | V12: 6762.4848 | W12: 6778.2466 | X12: 6789.946 | Y12: 6796.985 | Z12: 6798.7539 | AA12: 6794.6346 | AB12: 6784.0053 | AC12: 6766.2455 | AD12: 6740.7441 | AE12: 6706.9077 | AF12: 6664.1718 | AG12: 6612.0131 | AH12: 6549.9638 | AI12: 6477.6256 | AJ12: 6394.686 | AK12: 6300.9328
... A119: buil_des_0 | B119: 1.1716777 | C119: 1.1716777 | D119: 1.1565402 | E119: 1.1416083 | F119: 1.1268791 | G119: 1.1123494 | H119: 1.0980163 | I119: 1.083877 | J119: 1.0699286 | K119: 1.0561683 | L119: 1.0425934 | M119: 1.0292012 | N119: 1.0159892 | O119: 1.0029547 | P119: 0.99009523 | Q119: 0.97740825 | R119: 0.96489133 | S119: 0.95254204 | T119: 0.940358 | U119: 0.92833689 | V119: 0.91647639 | W119: 0.90477425 | X119: 0.89322823 | Y119: 0.88183615 | Z119: 0.87059586 | AA119: 0.85950523 | AB119: 0.84856218 | AC119: 0.83776466 | AD119: 0.82711064 | AE119: 0.81659814 | AF119: 0.8062252 | AG119: 0.7959899 | AH119: 0.78589034 | AI119: 0.77592465 | AJ119: 0.766091 | AK119: 0.75638758

Sheet Tab-macro
B1: en écart au scénario de référence (%)
B2: ThreeME
B3: 2021 | C3: 2022 | D3: 2023 | E3: 2025 | F3: 2030 | G3: 2050
A4: PIB en volume | B4: =Macro!H2 -> 0.048738572 | C4: =Macro!I2 -> 0.060095859 | D4: =Macro!J2 -> 0.070015107 | E4: =Macro!L2 -> 0.085962983 | F4: =Macro!Q2 -> 0.14265241 | G4: =Macro!AK2 -> 0.14504591
A5: Consommation des ménages | B5: =Macro!H3 -> 0.11251557 | C5: =Macro!I3 -> 0.15121567 | D5: =Macro!J3 -> 0.19244796 | E5: =Macro!L3 -> 0.27910298 | F5: =Macro!Q3 -> 0.58194624 | G5: =Macro!AK3 -> 2.856981
A6: Investissement | B6: =Macro!H4 -> -0.059365516 | C6: =Macro!I4 -> -0.075529889 | D6: =Macro!J4 -> -0.091710764 | E6: =Macro!L4 -> -0.1256935 | F6: =Macro!Q4 -> -0.24634602 | G6: =Macro!AK4 -> -1.1530914
A7: Exportations | B7: =Macro!H5 -> -0.084743657 | C7: =Macro!I5 -> -0.12011476 | D7: =Macro!J5 -> -0.16133863 | E7: =Macro!L5 -> -0.25968197 | F7: =Macro!Q5 -> -0.62273486 | G7: =Macro!AK5 -> -4.3575533
A8: Importations | B8: =Macro!H6 -> -0.081006385 | C8: =Macro!I6 -> -0.093915887 | D8: =Macro!J6 -> -0.10310887 | E8: =Macro!L6 -> -0.11740134 | F8: =Macro!Q6 -> -0.18982161 | G8: =Macro!AK6 -> -0.25427953
A9: Revenu disponible (réel) des ménages | B9: =Macro!H7 -> 0.12157521 | C9: =Macro!I7 -> 0.16017255 | D9: =Macro!J7 -> 0.20029739 | E9: =Macro!L7 -> 0.28453424 | F9: =Macro!Q7 -> 0.59324441 | G9: =Macro!AK7 -> 2.8463131
A10: Taux d'épargne (en pts) | B10: =Macro!H8 -> 0.00802139 | C10: =Macro!I8 -> 0.00792673 | D10: =Macro!J8 -> 0.00694347 | E10: =Macro!L8 -> 0.00480004 | F10: =Macro!Q8 -> 0.0099548 | G10: =Macro!AK8 -> -0.00919449
A11: Prix de la consommation des ménages | B11: =Macro!H9 -> 0.36952058 | C11: =Macro!I9 -> 0.47010293 | D11: =Macro!J9 -> 0.57633973 | E11: =Macro!L9 -> 0.81690358 | F11: =Macro!Q9 -> 1.7507387 | G11: =Macro!AK9 -> 9.4772123
A12: Prix de la production | B12: =Macro!H10 -> 0.16101628 | C12: =Macro!I10 -> 0.22699331 | D12: =Macro!J10 -> 0.30376119 | E12: =Macro!L10 -> 0.48622175 | F12: =Macro!Q10 -> 1.1478252 | G12: =Macro!AK10 -> 7.9308716
A13: Prix de la valeur ajoutée | B13: =Macro!H11 -> -0.11409151 | C13: =Macro!I11 -> -0.099489263 | D13: =Macro!J11 -> -0.068390502 | E13: =Macro!L11 -> 0.021294043 | F13: =Macro!Q11 -> 0.24697079 | G13: =Macro!AK11 -> 4.4747757
A14: Prix des consommations intermédiaires | B14: =Macro!H12 -> 0.44768827 | C14: =Macro!I12 -> 0.56728174 | D14: =Macro!J12 -> 0.69175235 | E14: =Macro!L12 -> 0.97122732 | F14: =Macro!Q12 -> 2.0898956 | G14: =Macro!AK12 -> 11.613078
A15: Prix des exportations | B15: =Macro!H13 -> 0.25431324 | C15: =Macro!I13 -> 0.33938229 | D15: =Macro!J13 -> 0.43168577 | E15: =Macro!L13 -> 0.63899439 | F15: =Macro!Q13 -> 1.4145331 | G15: =Macro!AK13 -> 8.7682091
... A24: Emissions de CO2 | B24: =Macro!H22 -> -1.761206 | C24: =Macro!I22 -> -2.2324391 | D24: =Macro!J22 -> -2.6954212 | E24: =Macro!L22 -> -3.6119939 | F24: =Macro!Q22 -> -6.6014016 | G24: =Macro!AK22 -> -22.746641
B26: % deviation from baseline
B27: ThreeME
B28: 2021 | C28: 2022 | D28: 2023 | E28: 2025 | F28: 2030 | G28: 2050
A29: GDP in volume | B29: =B4 -> 0.048738572 | C29: =C4 -> 0.060095859 | D29: =D4 -> 0.070015107 | E29: =E4 -> 0.085962983 | F29: =F4 -> 0.14265241 | G29: =G4 -> 0.14504591
A30: Household consumption | B30: =B5 -> 0.11251557 | C30: =C5 -> 0.15121567 | D30: =D5 -> 0.19244796 | E30: =E5 -> 0.27910298 | F30: =F5 -> 0.58194624 | G30: =G5 -> 2.856981
