Workbook
Name formatResults: [1]ResultsEXR10!$A$50

Sheet Results
A1: NB : on crée ici une liste : - globale, qui fusionne les sorties des reportings 1, 2 et 3 - "rationalisée" : suppression des doublons, et regroupements par thématique On continue par la suite à avoir 2 Excels de reporting (un "energie", fusion des reportings 1 et 2), et un "économie" (reporting 3)), dans lesquels on copiera cet onglet "results" (généré automatiquement par EViews). --> puis voir à la fin si on peut pas importer les graphs et tableaux dans l'excel automatiquement généré (éviterait les copiés collés, mais à voir si ça prend trop de temps, et si c'est pas trop gros comme excel)
A2: Nom du bloc de variables utilisé dans le code | B2: Sous-bloc de variables pour plus de lisibilité dans le Excel | E2: Year | F2: =date!B3 -> 2015 | G2: =date!C3 -> 2016 | H2: =date!D3 -> 2017 | I2: =date!E3 -> 2018 | J2: =date!F3 -> 2019 | K2: =date!G3 -> 2020 | L2: =date!H3 -> 2021 | M2: =date!I3 -> 2022 | ... AO2: =date!AK3 -> 2050
A3: HYBRID | B3: AUTOMOBILES (thousands) | C3: TOTAL STOCK SHOCK | E3: AUTO_2 | F3: =VLOOKUP($E3,Hybrid!$1:$1048576,MATCH(DATE(F$2,1,1),Hybrid!$A$1:$LI$1),FALSE) -> 32317.941 | G3: =VLOOKUP($E3,Hybrid!$1:$1048576,MATCH(DATE(G$2,1,1),Hybrid!$A$1:$LI$1),FALSE) -> 31926.557 | H3: =VLOOKUP($E3,Hybrid!$1:$1048576,MATCH(DATE(H$2,1,1),Hybrid!$A$1:$LI$1),FALSE) -> 31730.857 | I3: =VLOOKUP($E3,Hybrid!$1:$1048576,MATCH(DATE(I$2,1,1),Hybrid!$A$1:$LI$1),FALSE) -> 31665.91 | J3: =VLOOKUP($E3,Hybrid!$1:$1048576,MATCH(DATE(J$2,1,1),Hybrid!$A$1:$LI$1),FALSE) -> 31687.577 | K3: =VLOOKUP($E3,Hybrid!$1:$1048576,MATCH(DATE(K$2,1,1),Hybrid!$A$1:$LI$1),FALSE) -> 31766.229 | L3: =VLOOKUP($E3,Hybrid!$1:$1048576,MATCH(DATE(L$2,1,1),Hybrid!$A$1:$LI$1),FALSE) -> 31884.17 | M3: =VLOOKUP($E3,Hybrid!$1:$1048576,MATCH(DATE(M$2,1,1),Hybrid!$A$1:$LI$1),FALSE) -> 32031.35 | ... AO3: =VLOOKUP($E3,Hybrid!$1:$1048576,MATCH(DATE(AO$2,1,1),Hybrid!$A$1:$LI$1),FALSE) -> 37602.841
C4: OIL | E4: AUTO_cfut_2 | F4: =VLOOKUP($E4,Hybrid!$1:$1048576,MATCH(DATE(F$2,1,1),Hybrid!$A$1:$LI$1),FALSE) -> 32271.24 | G4: =VLOOKUP($E4,Hybrid!$1:$1048576,MATCH(DATE(G$2,1,1),Hybrid!$A$1:$LI$1),FALSE) -> 31862.134 | H4: =VLOOKUP($E4,Hybrid!$1:$1048576,MATCH(DATE(H$2,1,1),Hybrid!$A$1:$LI$1),FALSE) -> 31647.786 | I4: =VLOOKUP($E4,Hybrid!$1:$1048576,MATCH(DATE(I$2,1,1),Hybrid!$A$1:$LI$1),FALSE) -> 31563.667 | J4: =VLOOKUP($E4,Hybrid!$1:$1048576,MATCH(DATE(J$2,1,1),Hybrid!$A$1:$LI$1),FALSE) -> 31565.852 | K4: =VLOOKUP($E4,Hybrid!$1:$1048576,MATCH(DATE(K$2,1,1),Hybrid!$A$1:$LI$1),FALSE) -> 31624.781 | L4: =VLOOKUP($E4,Hybrid!$1:$1048576,MATCH(DATE(L$2,1,1),Hybrid!$A$1:$LI$1),FALSE) -> 31722.707 | M4: =VLOOKUP($E4,Hybrid!$1:$1048576,MATCH(DATE(M$2,1,1),Hybrid!$A$1:$LI$1),FALSE) -> 31849.465 | ... AO4: =VLOOKUP($E4,Hybrid!$1:$1048576,MATCH(DATE(AO$2,1,1),Hybrid!$A$1:$LI$1),FALSE) -> 35103.736
D5: class A | E5: AUTO_ca_cfut_2 | F5: =VLOOKUP($E5,Hybrid!$1:$1048576,MATCH(DATE(F$2,1,1),Hybrid!$A$1:$LI$1),FALSE) -> 7095.7005 | G5: =VLOOKUP($E5,Hybrid!$1:$1048576,MATCH(DATE(G$2,1,1),Hybrid!$A$1:$LI$1),FALSE) -> 7141.7725 | H5: =VLOOKUP($E5,Hybrid!$1:$1048576,MATCH(DATE(H$2,1,1),Hybrid!$A$1:$LI$1),FALSE) -> 7236.3372 | I5: =VLOOKUP($E5,Hybrid!$1:$1048576,MATCH(DATE(I$2,1,1),Hybrid!$A$1:$LI$1),FALSE) -> 7363.0817 | J5: =VLOOKUP($E5,Hybrid!$1:$1048576,MATCH(DATE(J$2,1,1),Hybrid!$A$1:$LI$1),FALSE) -> 7510.7006 | K5: =VLOOKUP($E5,Hybrid!$1:$1048576,MATCH(DATE(K$2,1,1),Hybrid!$A$1:$LI$1),FALSE) -> 7671.4836 | L5: =VLOOKUP($E5,Hybrid!$1:$1048576,MATCH(DATE(L$2,1,1),Hybrid!$A$1:$LI$1),FALSE) -> 7840.8349 | M5: =VLOOKUP($E5,Hybrid!$1:$1048576,MATCH(DATE(M$2,1,1),Hybrid!$A$1:$LI$1),FALSE) -> 8016.1766 | ... AO5: =VLOOKUP($E5,Hybrid!$1:$1048576,MATCH(DATE(AO$2,1,1),Hybrid!$A$1:$LI$1),FALSE) -> 12307.577
D6: class B | E6: AUTO_cb_cfut_2 | F6: =VLOOKUP($E6,Hybrid!$1:$1048576,MATCH(DATE(F$2,1,1),Hybrid!$A$1:$LI$1),FALSE) -> 8251.2564 | G6: =VLOOKUP($E6,Hybrid!$1:$1048576,MATCH(DATE(G$2,1,1),Hybrid!$A$1:$LI$1),FALSE) -> 8182.8121 | H6: =VLOOKUP($E6,Hybrid!$1:$1048576,MATCH(DATE(H$2,1,1),Hybrid!$A$1:$LI$1),FALSE) -> 8168.4592 | I6: =VLOOKUP($E6,Hybrid!$1:$1048576,MATCH(DATE(I$2,1,1),Hybrid!$A$1:$LI$1),FALSE) -> 8191.5872 | J6: =VLOOKUP($E6,Hybrid!$1:$1048576,MATCH(DATE(J$2,1,1),Hybrid!$A$1:$LI$1),FALSE) -> 8240.58 | K6: =VLOOKUP($E6,Hybrid!$1:$1048576,MATCH(DATE(K$2,1,1),Hybrid!$A$1:$LI$1),FALSE) -> 8307.3911 | L6: =VLOOKUP($E6,Hybrid!$1:$1048576,MATCH(DATE(L$2,1,1),Hybrid!$A$1:$LI$1),FALSE) -> 8387.0405 | M6: =VLOOKUP($E6,Hybrid!$1:$1048576,MATCH(DATE(M$2,1,1),Hybrid!$A$1:$LI$1),FALSE) -> 8476.5554 | ... AO6: =VLOOKUP($E6,Hybrid!$1:$1048576,MATCH(DATE(AO$2,1,1),Hybrid!$A$1:$LI$1),FALSE) -> 10896.479
D7: class C | E7: AUTO_cc_cfut_2 | F7: =VLOOKUP($E7,Hybrid!$1:$1048576,MATCH(DATE(F$2,1,1),Hybrid!$A$1:$LI$1),FALSE) -> 6777.6025 | G7: =VLOOKUP($E7,Hybrid!$1:$1048576,MATCH(DATE(G$2,1,1),Hybrid!$A$1:$LI$1),FALSE) -> 6646.7823 | H7: =VLOOKUP($E7,Hybrid!$1:$1048576,MATCH(DATE(H$2,1,1),Hybrid!$A$1:$LI$1),FALSE) -> 6559.0536 | I7: =VLOOKUP($E7,Hybrid!$1:$1048576,MATCH(DATE(I$2,1,1),Hybrid!$A$1:$LI$1),FALSE) -> 6502.2362 | J7: =VLOOKUP($E7,Hybrid!$1:$1048576,MATCH(DATE(J$2,1,1),Hybrid!$A$1:$LI$1),FALSE) -> 6467.7395 | K7: =VLOOKUP($E7,Hybrid!$1:$1048576,MATCH(DATE(K$2,1,1),Hybrid!$A$1:$LI$1),FALSE) -> 6449.5285 | L7: =VLOOKUP($E7,Hybrid!$1:$1048576,MATCH(DATE(L$2,1,1),Hybrid!$A$1:$LI$1),FALSE) -> 6443.746 | M7: =VLOOKUP($E7,Hybrid!$1:$1048576,MATCH(DATE(M$2,1,1),Hybrid!$A$1:$LI$1),FALSE) -> 6447.9746 | ... AO7: =VLOOKUP($E7,Hybrid!$1:$1048576,MATCH(DATE(AO$2,1,1),Hybrid!$A$1:$LI$1),FALSE) -> 6988.4264
D8: class D | E8: AUTO_cd_cfut_2 | F8: =VLOOKUP($E8,Hybrid!$1:$1048576,MATCH(DATE(F$2,1,1),Hybrid!$A$1:$LI$1),FALSE) -> 4159.6639 | G8: =VLOOKUP($E8,Hybrid!$1:$1048576,MATCH(DATE(G$2,1,1),Hybrid!$A$1:$LI$1),FALSE) -> 4054.5905 | H8: =VLOOKUP($E8,Hybrid!$1:$1048576,MATCH(DATE(H$2,1,1),Hybrid!$A$1:$LI$1),FALSE) -> 3973.877 | I8: =VLOOKUP($E8,Hybrid!$1:$1048576,MATCH(DATE(I$2,1,1),Hybrid!$A$1:$LI$1),FALSE) -> 3910.1866 | J8: =VLOOKUP($E8,Hybrid!$1:$1048576,MATCH(DATE(J$2,1,1),Hybrid!$A$1:$LI$1),FALSE) -> 3858.4319 | K8: =VLOOKUP($E8,Hybrid!$1:$1048576,MATCH(DATE(K$2,1,1),Hybrid!$A$1:$LI$1),FALSE) -> 3815.0948 | L8: =VLOOKUP($E8,Hybrid!$1:$1048576,MATCH(DATE(L$2,1,1),Hybrid!$A$1:$LI$1),FALSE) -> 3777.9381 | M8: =VLOOKUP($E8,Hybrid!$1:$1048576,MATCH(DATE(M$2,1,1),Hybrid!$A$1:$LI$1),FALSE) -> 3745.5592 | ... AO8: =VLOOKUP($E8,Hybrid!$1:$1048576,MATCH(DATE(AO$2,1,1),Hybrid!$A$1:$LI$1),FALSE) -> 2889.4513
D9: class E | E9: AUTO_ce_cfut_2 | F9: =VLOOKUP($E9,Hybrid!$1:$1048576,MATCH(DATE(F$2,1,1),Hybrid!$A$1:$LI$1),FALSE) -> 2503.7292 | G9: =VLOOKUP($E9,Hybrid!$1:$1048576,MATCH(DATE(G$2,1,1),Hybrid!$A$1:$LI$1),FALSE) -> 2442.7236 | H9: =VLOOKUP($E9,Hybrid!$1:$1048576,MATCH(DATE(H$2,1,1),Hybrid!$A$1:$LI$1),FALSE) -> 2395.2956 | I9: =VLOOKUP($E9,Hybrid!$1:$1048576,MATCH(DATE(I$2,1,1),Hybrid!$A$1:$LI$1),FALSE) -> 2356.7622 | J9: =VLOOKUP($E9,Hybrid!$1:$1048576,MATCH(DATE(J$2,1,1),Hybrid!$A$1:$LI$1),FALSE) -> 2323.9614 | K9: =VLOOKUP($E9,Hybrid!$1:$1048576,MATCH(DATE(K$2,1,1),Hybrid!$A$1:$LI$1),FALSE) -> 2294.7723 | L9: =VLOOKUP($E9,Hybrid!$1:$1048576,MATCH(DATE(L$2,1,1),Hybrid!$A$1:$LI$1),FALSE) -> 2267.8937 | M9: =VLOOKUP($E9,Hybrid!$1:$1048576,MATCH(DATE(M$2,1,1),Hybrid!$A$1:$LI$1),FALSE) -> 2242.5503 | ... AO9: =VLOOKUP($E9,Hybrid!$1:$1048576,MATCH(DATE(AO$2,1,1),Hybrid!$A$1:$LI$1),FALSE) -> 1345.3309
D10: class F | E10: AUTO_cf_cfut_2 | F10: =VLOOKUP($E10,Hybrid!$1:$1048576,MATCH(DATE(F$2,1,1),Hybrid!$A$1:$LI$1),FALSE) -> 1243.6668 | G10: =VLOOKUP($E10,Hybrid!$1:$1048576,MATCH(DATE(G$2,1,1),Hybrid!$A$1:$LI$1),FALSE) -> 1210.4957 | H10: =VLOOKUP($E10,Hybrid!$1:$1048576,MATCH(DATE(H$2,1,1),Hybrid!$A$1:$LI$1),FALSE) -> 1182.3382 | I10: =VLOOKUP($E10,Hybrid!$1:$1048576,MATCH(DATE(I$2,1,1),Hybrid!$A$1:$LI$1),FALSE) -> 1156.6734 | J10: =VLOOKUP($E10,Hybrid!$1:$1048576,MATCH(DATE(J$2,1,1),Hybrid!$A$1:$LI$1),FALSE) -> 1131.9653 | K10: =VLOOKUP($E10,Hybrid!$1:$1048576,MATCH(DATE(K$2,1,1),Hybrid!$A$1:$LI$1),FALSE) -> 1107.3163 | L10: =VLOOKUP($E10,Hybrid!$1:$1048576,MATCH(DATE(L$2,1,1),Hybrid!$A$1:$LI$1),FALSE) -> 1082.2791 | M10: =VLOOKUP($E10,Hybrid!$1:$1048576,MATCH(DATE(M$2,1,1),Hybrid!$A$1:$LI$1),FALSE) -> 1056.6745 | ... AO10: =VLOOKUP($E10,Hybrid!$1:$1048576,MATCH(DATE(AO$2,1,1),Hybrid!$A$1:$LI$1),FALSE) -> 307.18098
D11: class G | E11: AUTO_cg_cfut_2 | F11: =VLOOKUP($E11,Hybrid!$1:$1048576,MATCH(DATE(F$2,1,1),Hybrid!$A$1:$LI$1),FALSE) -> 2239.6206 | G11: =VLOOKUP($E11,Hybrid!$1:$1048576,MATCH(DATE(G$2,1,1),Hybrid!$A$1:$LI$1),FALSE) -> 2182.9572 | H11: =VLOOKUP($E11,Hybrid!$1:$1048576,MATCH(DATE(H$2,1,1),Hybrid!$A$1:$LI$1),FALSE) -> 2132.4256 | I11: =VLOOKUP($E11,Hybrid!$1:$1048576,MATCH(DATE(I$2,1,1),Hybrid!$A$1:$LI$1),FALSE) -> 2083.1395 | J11: =VLOOKUP($E11,Hybrid!$1:$1048576,MATCH(DATE(J$2,1,1),Hybrid!$A$1:$LI$1),FALSE) -> 2032.4729 | K11: =VLOOKUP($E11,Hybrid!$1:$1048576,MATCH(DATE(K$2,1,1),Hybrid!$A$1:$LI$1),FALSE) -> 1979.1945 | L11: =VLOOKUP($E11,Hybrid!$1:$1048576,MATCH(DATE(L$2,1,1),Hybrid!$A$1:$LI$1),FALSE) -> 1922.9745 | M11: =VLOOKUP($E11,Hybrid!$1:$1048576,MATCH(DATE(M$2,1,1),Hybrid!$A$1:$LI$1),FALSE) -> 1863.9747 | ... AO11: =VLOOKUP($E11,Hybrid!$1:$1048576,MATCH(DATE(AO$2,1,1),Hybrid!$A$1:$LI$1),FALSE) -> 369.29013
C12: ELEC | E12: AUTO_cele_2 | F12: =VLOOKUP($E12,Hybrid!$1:$1048576,MATCH(DATE(F$2,1,1),Hybrid!$A$1:$LI$1),FALSE) -> 44.765 | G12: =VLOOKUP($E12,Hybrid!$1:$1048576,MATCH(DATE(G$2,1,1),Hybrid!$A$1:$LI$1),FALSE) -> 62.431907 | H12: =VLOOKUP($E12,Hybrid!$1:$1048576,MATCH(DATE(H$2,1,1),Hybrid!$A$1:$LI$1),FALSE) -> 81.013139 | I12: =VLOOKUP($E12,Hybrid!$1:$1048576,MATCH(DATE(I$2,1,1),Hybrid!$A$1:$LI$1),FALSE) -> 100.11448 | J12: =VLOOKUP($E12,Hybrid!$1:$1048576,MATCH(DATE(J$2,1,1),Hybrid!$A$1:$LI$1),FALSE) -> 119.52341 | K12: =VLOOKUP($E12,Hybrid!$1:$1048576,MATCH(DATE(K$2,1,1),Hybrid!$A$1:$LI$1),FALSE) -> 139.17166 | L12: =VLOOKUP($E12,Hybrid!$1:$1048576,MATCH(DATE(L$2,1,1),Hybrid!$A$1:$LI$1),FALSE) -> 159.11464 | M12: =VLOOKUP($E12,Hybrid!$1:$1048576,MATCH(DATE(M$2,1,1),Hybrid!$A$1:$LI$1),FALSE) -> 179.46535 | ... AO12: =VLOOKUP($E12,Hybrid!$1:$1048576,MATCH(DATE(AO$2,1,1),Hybrid!$A$1:$LI$1),FALSE) -> 2495.6066
D13: class A | E13: AUTO_ca_cele_2 | F13: =VLOOKUP($E13,Hybrid!$1:$1048576,MATCH(DATE(F$2,1,1),Hybrid!$A$1:$LI$1),FALSE) -> 9.8427899 | G13: =VLOOKUP($E13,Hybrid!$1:$1048576,MATCH(DATE(G$2,1,1),Hybrid!$A$1:$LI$1),FALSE) -> 14.986855 | H13: =VLOOKUP($E13,Hybrid!$1:$1048576,MATCH(DATE(H$2,1,1),Hybrid!$A$1:$LI$1),FALSE) -> 20.441598 | I13: =VLOOKUP($E13,Hybrid!$1:$1048576,MATCH(DATE(I$2,1,1),Hybrid!$A$1:$LI$1),FALSE) -> 26.109475 | J13: =VLOOKUP($E13,Hybrid!$1:$1048576,MATCH(DATE(J$2,1,1),Hybrid!$A$1:$LI$1),FALSE) -> 31.93889 | K13: =VLOOKUP($E13,Hybrid!$1:$1048576,MATCH(DATE(K$2,1,1),Hybrid!$A$1:$LI$1),FALSE) -> 37.917119 | L13: =VLOOKUP($E13,Hybrid!$1:$1048576,MATCH(DATE(L$2,1,1),Hybrid!$A$1:$LI$1),FALSE) -> 44.066743 | M13: =VLOOKUP($E13,Hybrid!$1:$1048576,MATCH(DATE(M$2,1,1),Hybrid!$A$1:$LI$1),FALSE) -> 50.426862 | ... AO13: =VLOOKUP($E13,Hybrid!$1:$1048576,MATCH(DATE(AO$2,1,1),Hybrid!$A$1:$LI$1),FALSE) -> 915.33384
D14: class B | E14: AUTO_cb_cele_2 | F14: =VLOOKUP($E14,Hybrid!$1:$1048576,MATCH(DATE(F$2,1,1),Hybrid!$A$1:$LI$1),FALSE) -> 11.445717 | G14: =VLOOKUP($E14,Hybrid!$1:$1048576,MATCH(DATE(G$2,1,1),Hybrid!$A$1:$LI$1),FALSE) -> 16.298791 | H14: =VLOOKUP($E14,Hybrid!$1:$1048576,MATCH(DATE(H$2,1,1),Hybrid!$A$1:$LI$1),FALSE) -> 21.444778 | I14: =VLOOKUP($E14,Hybrid!$1:$1048576,MATCH(DATE(I$2,1,1),Hybrid!$A$1:$LI$1),FALSE) -> 26.78893 | J14: =VLOOKUP($E14,Hybrid!$1:$1048576,MATCH(DATE(J$2,1,1),Hybrid!$A$1:$LI$1),FALSE) -> 32.28194 | K14: =VLOOKUP($E14,Hybrid!$1:$1048576,MATCH(DATE(K$2,1,1),Hybrid!$A$1:$LI$1),FALSE) -> 37.912731 | L14: =VLOOKUP($E14,Hybrid!$1:$1048576,MATCH(DATE(L$2,1,1),Hybrid!$A$1:$LI$1),FALSE) -> 43.704512 | M14: =VLOOKUP($E14,Hybrid!$1:$1048576,MATCH(DATE(M$2,1,1),Hybrid!$A$1:$LI$1),FALSE) -> 49.696035 | ... AO14: =VLOOKUP($E14,Hybrid!$1:$1048576,MATCH(DATE(AO$2,1,1),Hybrid!$A$1:$LI$1),FALSE) -> 837.25868
D15: class C | E15: AUTO_cc_cele_2 | F15: =VLOOKUP($E15,Hybrid!$1:$1048576,MATCH(DATE(F$2,1,1),Hybrid!$A$1:$LI$1),FALSE) -> 9.4015406 | G15: =VLOOKUP($E15,Hybrid!$1:$1048576,MATCH(DATE(G$2,1,1),Hybrid!$A$1:$LI$1),FALSE) -> 12.697721 | H15: =VLOOKUP($E15,Hybrid!$1:$1048576,MATCH(DATE(H$2,1,1),Hybrid!$A$1:$LI$1),FALSE) -> 16.193052 | I15: =VLOOKUP($E15,Hybrid!$1:$1048576,MATCH(DATE(I$2,1,1),Hybrid!$A$1:$LI$1),FALSE) -> 19.821122 | J15: =VLOOKUP($E15,Hybrid!$1:$1048576,MATCH(DATE(J$2,1,1),Hybrid!$A$1:$LI$1),FALSE) -> 23.547853 | K15: =VLOOKUP($E15,Hybrid!$1:$1048576,MATCH(DATE(K$2,1,1),Hybrid!$A$1:$LI$1),FALSE) -> 27.366208 | L15: =VLOOKUP($E15,Hybrid!$1:$1048576,MATCH(DATE(L$2,1,1),Hybrid!$A$1:$LI$1),FALSE) -> 31.29309 | M15: =VLOOKUP($E15,Hybrid!$1:$1048576,MATCH(DATE(M$2,1,1),Hybrid!$A$1:$LI$1),FALSE) -> 35.355919 | ... AO15: =VLOOKUP($E15,Hybrid!$1:$1048576,MATCH(DATE(AO$2,1,1),Hybrid!$A$1:$LI$1),FALSE) -> 549.70794
D16: class D | E16: AUTO_cd_cele_2 | F16: =VLOOKUP($E16,Hybrid!$1:$1048576,MATCH(DATE(F$2,1,1),Hybrid!$A$1:$LI$1),FALSE) -> 5.7700713 | G16: =VLOOKUP($E16,Hybrid!$1:$1048576,MATCH(DATE(G$2,1,1),Hybrid!$A$1:$LI$1),FALSE) -> 7.5615669 | H16: =VLOOKUP($E16,Hybrid!$1:$1048576,MATCH(DATE(H$2,1,1),Hybrid!$A$1:$LI$1),FALSE) -> 9.4381353 | I16: =VLOOKUP($E16,Hybrid!$1:$1048576,MATCH(DATE(I$2,1,1),Hybrid!$A$1:$LI$1),FALSE) -> 11.352056 | J16: =VLOOKUP($E16,Hybrid!$1:$1048576,MATCH(DATE(J$2,1,1),Hybrid!$A$1:$LI$1),FALSE) -> 13.274162 | K16: =VLOOKUP($E16,Hybrid!$1:$1048576,MATCH(DATE(K$2,1,1),Hybrid!$A$1:$LI$1),FALSE) -> 15.18912 | L16: =VLOOKUP($E16,Hybrid!$1:$1048576,MATCH(DATE(L$2,1,1),Hybrid!$A$1:$LI$1),FALSE) -> 17.093136 | M16: =VLOOKUP($E16,Hybrid!$1:$1048576,MATCH(DATE(M$2,1,1),Hybrid!$A$1:$LI$1),FALSE) -> 18.988411 | ... AO16: =VLOOKUP($E16,Hybrid!$1:$1048576,MATCH(DATE(AO$2,1,1),Hybrid!$A$1:$LI$1),FALSE) -> 120.31725
D17: class E | E17: AUTO_ce_cele_2 | F17: =VLOOKUP($E17,Hybrid!$1:$1048576,MATCH(DATE(F$2,1,1),Hybrid!$A$1:$LI$1),FALSE) -> 3.4730441 | G17: =VLOOKUP($E17,Hybrid!$1:$1048576,MATCH(DATE(G$2,1,1),Hybrid!$A$1:$LI$1),FALSE) -> 4.5722504 | H17: =VLOOKUP($E17,Hybrid!$1:$1048576,MATCH(DATE(H$2,1,1),Hybrid!$A$1:$LI$1),FALSE) -> 5.7141145 | I17: =VLOOKUP($E17,Hybrid!$1:$1048576,MATCH(DATE(I$2,1,1),Hybrid!$A$1:$LI$1),FALSE) -> 6.8674553 | J17: =VLOOKUP($E17,Hybrid!$1:$1048576,MATCH(DATE(J$2,1,1),Hybrid!$A$1:$LI$1),FALSE) -> 8.0136634 | K17: =VLOOKUP($E17,Hybrid!$1:$1048576,MATCH(DATE(K$2,1,1),Hybrid!$A$1:$LI$1),FALSE) -> 9.1432705 | L17: =VLOOKUP($E17,Hybrid!$1:$1048576,MATCH(DATE(L$2,1,1),Hybrid!$A$1:$LI$1),FALSE) -> 10.254089 | M17: =VLOOKUP($E17,Hybrid!$1:$1048576,MATCH(DATE(M$2,1,1),Hybrid!$A$1:$LI$1),FALSE) -> 11.347514 | ... AO17: =VLOOKUP($E17,Hybrid!$1:$1048576,MATCH(DATE(AO$2,1,1),Hybrid!$A$1:$LI$1),FALSE) -> 56.507023
D18: class F | E18: AUTO_cf_cele_2 | F18: =VLOOKUP($E18,Hybrid!$1:$1048576,MATCH(DATE(F$2,1,1),Hybrid!$A$1:$LI$1),FALSE) -> 1.7251505 | G18: =VLOOKUP($E18,Hybrid!$1:$1048576,MATCH(DATE(G$2,1,1),Hybrid!$A$1:$LI$1),FALSE) -> 2.2444156 | H18: =VLOOKUP($E18,Hybrid!$1:$1048576,MATCH(DATE(H$2,1,1),Hybrid!$A$1:$LI$1),FALSE) -> 2.766963 | I18: =VLOOKUP($E18,Hybrid!$1:$1048576,MATCH(DATE(I$2,1,1),Hybrid!$A$1:$LI$1),FALSE) -> 3.2740974 | J18: =VLOOKUP($E18,Hybrid!$1:$1048576,MATCH(DATE(J$2,1,1),Hybrid!$A$1:$LI$1),FALSE) -> 3.755207 | K18: =VLOOKUP($E18,Hybrid!$1:$1048576,MATCH(DATE(K$2,1,1),Hybrid!$A$1:$LI$1),FALSE) -> 4.205033 | L18: =VLOOKUP($E18,Hybrid!$1:$1048576,MATCH(DATE(L$2,1,1),Hybrid!$A$1:$LI$1),FALSE) -> 4.622085 | M18: =VLOOKUP($E18,Hybrid!$1:$1048576,MATCH(DATE(M$2,1,1),Hybrid!$A$1:$LI$1),FALSE) -> 5.0067778 | ... AO18: =VLOOKUP($E18,Hybrid!$1:$1048576,MATCH(DATE(AO$2,1,1),Hybrid!$A$1:$LI$1),FALSE) -> 8.0802696
D19: class G | E19: AUTO_cg_cele_2 | F19: =VLOOKUP($E19,Hybrid!$1:$1048576,MATCH(DATE(F$2,1,1),Hybrid!$A$1:$LI$1),FALSE) -> 3.1066862 | G19: =VLOOKUP($E19,Hybrid!$1:$1048576,MATCH(DATE(G$2,1,1),Hybrid!$A$1:$LI$1),FALSE) -> 4.0703072 | H19: =VLOOKUP($E19,Hybrid!$1:$1048576,MATCH(DATE(H$2,1,1),Hybrid!$A$1:$LI$1),FALSE) -> 5.0144974 | I19: =VLOOKUP($E19,Hybrid!$1:$1048576,MATCH(DATE(I$2,1,1),Hybrid!$A$1:$LI$1),FALSE) -> 5.9013474 | J19: =VLOOKUP($E19,Hybrid!$1:$1048576,MATCH(DATE(J$2,1,1),Hybrid!$A$1:$LI$1),FALSE) -> 6.7116982 | K19: =VLOOKUP($E19,Hybrid!$1:$1048576,MATCH(DATE(K$2,1,1),Hybrid!$A$1:$LI$1),FALSE) -> 7.4381797 | L19: =VLOOKUP($E19,Hybrid!$1:$1048576,MATCH(DATE(L$2,1,1),Hybrid!$A$1:$LI$1),FALSE) -> 8.0809851 | M19: =VLOOKUP($E19,Hybrid!$1:$1048576,MATCH(DATE(M$2,1,1),Hybrid!$A$1:$LI$1),FALSE) -> 8.6438338 | ... AO19: =VLOOKUP($E19,Hybrid!$1:$1048576,MATCH(DATE(AO$2,1,1),Hybrid!$A$1:$LI$1),FALSE) -> 8.4015579
C20: GAS | E20: AUTO_cgas_2 | F20: =VLOOKUP($E20,Hybrid!$1:$1048576,MATCH(DATE(F$2,1,1),Hybrid!$A$1:$LI$1),FALSE) -> 1.936 | G20: =VLOOKUP($E20,Hybrid!$1:$1048576,MATCH(DATE(G$2,1,1),Hybrid!$A$1:$LI$1),FALSE) -> 1.9916142 | H20: =VLOOKUP($E20,Hybrid!$1:$1048576,MATCH(DATE(H$2,1,1),Hybrid!$A$1:$LI$1),FALSE) -> 2.0574397 | I20: =VLOOKUP($E20,Hybrid!$1:$1048576,MATCH(DATE(I$2,1,1),Hybrid!$A$1:$LI$1),FALSE) -> 2.1286903 | J20: =VLOOKUP($E20,Hybrid!$1:$1048576,MATCH(DATE(J$2,1,1),Hybrid!$A$1:$LI$1),FALSE) -> 2.2021882 | K20: =VLOOKUP($E20,Hybrid!$1:$1048576,MATCH(DATE(K$2,1,1),Hybrid!$A$1:$LI$1),FALSE) -> 2.2758741 | L20: =VLOOKUP($E20,Hybrid!$1:$1048576,MATCH(DATE(L$2,1,1),Hybrid!$A$1:$LI$1),FALSE) -> 2.3486159 | M20: =VLOOKUP($E20,Hybrid!$1:$1048576,MATCH(DATE(M$2,1,1),Hybrid!$A$1:$LI$1),FALSE) -> 2.4198739 | ... AO20: =VLOOKUP($E20,Hybrid!$1:$1048576,MATCH(DATE(AO$2,1,1),Hybrid!$A$1:$LI$1),FALSE) -> 3.4989915
D21: class A | E21: AUTO_ca_cgas_2 | F21: =VLOOKUP($E21,Hybrid!$1:$1048576,MATCH(DATE(F$2,1,1),Hybrid!$A$1:$LI$1),FALSE) -> 0.4256817 | G21: =VLOOKUP($E21,Hybrid!$1:$1048576,MATCH(DATE(G$2,1,1),Hybrid!$A$1:$LI$1),FALSE) -> 0.44933756 | H21: =VLOOKUP($E21,Hybrid!$1:$1048576,MATCH(DATE(H$2,1,1),Hybrid!$A$1:$LI$1),FALSE) -> 0.47589006 | I21: =VLOOKUP($E21,Hybrid!$1:$1048576,MATCH(DATE(I$2,1,1),Hybrid!$A$1:$LI$1),FALSE) -> 0.50410475 | J21: =VLOOKUP($E21,Hybrid!$1:$1048576,MATCH(DATE(J$2,1,1),Hybrid!$A$1:$LI$1),FALSE) -> 0.53313831 | K21: =VLOOKUP($E21,Hybrid!$1:$1048576,MATCH(DATE(K$2,1,1),Hybrid!$A$1:$LI$1),FALSE) -> 0.56242832 | L21: =VLOOKUP($E21,Hybrid!$1:$1048576,MATCH(DATE(L$2,1,1),Hybrid!$A$1:$LI$1),FALSE) -> 0.59165871 | M21: =VLOOKUP($E21,Hybrid!$1:$1048576,MATCH(DATE(M$2,1,1),Hybrid!$A$1:$LI$1),FALSE) -> 0.62067264 | ... AO21: =VLOOKUP($E21,Hybrid!$1:$1048576,MATCH(DATE(AO$2,1,1),Hybrid!$A$1:$LI$1),FALSE) -> 1.213193
D22: class B | E22: AUTO_cb_cgas_2 | F22: =VLOOKUP($E22,Hybrid!$1:$1048576,MATCH(DATE(F$2,1,1),Hybrid!$A$1:$LI$1),FALSE) -> 0.49500523 | G22: =VLOOKUP($E22,Hybrid!$1:$1048576,MATCH(DATE(G$2,1,1),Hybrid!$A$1:$LI$1),FALSE) -> 0.51226256 | H22: =VLOOKUP($E22,Hybrid!$1:$1048576,MATCH(DATE(H$2,1,1),Hybrid!$A$1:$LI$1),FALSE) -> 0.53253811 | I22: =VLOOKUP($E22,Hybrid!$1:$1048576,MATCH(DATE(I$2,1,1),Hybrid!$A$1:$LI$1),FALSE) -> 0.5546014 | J22: =VLOOKUP($E22,Hybrid!$1:$1048576,MATCH(DATE(J$2,1,1),Hybrid!$A$1:$LI$1),FALSE) -> 0.57760987 | K22: =VLOOKUP($E22,Hybrid!$1:$1048576,MATCH(DATE(K$2,1,1),Hybrid!$A$1:$LI$1),FALSE) -> 0.60099756 | L22: =VLOOKUP($E22,Hybrid!$1:$1048576,MATCH(DATE(L$2,1,1),Hybrid!$A$1:$LI$1),FALSE) -> 0.62443887 | M22: =VLOOKUP($E22,Hybrid!$1:$1048576,MATCH(DATE(M$2,1,1),Hybrid!$A$1:$LI$1),FALSE) -> 0.64776464 | ... AO22: =VLOOKUP($E22,Hybrid!$1:$1048576,MATCH(DATE(AO$2,1,1),Hybrid!$A$1:$LI$1),FALSE) -> 1.0802066
D23: class C | E23: AUTO_cc_cgas_2 | F23: =VLOOKUP($E23,Hybrid!$1:$1048576,MATCH(DATE(F$2,1,1),Hybrid!$A$1:$LI$1),FALSE) -> 0.40659852 | G23: =VLOOKUP($E23,Hybrid!$1:$1048576,MATCH(DATE(G$2,1,1),Hybrid!$A$1:$LI$1),FALSE) -> 0.41450652 | H23: =VLOOKUP($E23,Hybrid!$1:$1048576,MATCH(DATE(H$2,1,1),Hybrid!$A$1:$LI$1),FALSE) -> 0.42468516 | I23: =VLOOKUP($E23,Hybrid!$1:$1048576,MATCH(DATE(I$2,1,1),Hybrid!$A$1:$LI$1),FALSE) -> 0.43625097 | J23: =VLOOKUP($E23,Hybrid!$1:$1048576,MATCH(DATE(J$2,1,1),Hybrid!$A$1:$LI$1),FALSE) -> 0.44859764 | K23: =VLOOKUP($E23,Hybrid!$1:$1048576,MATCH(DATE(K$2,1,1),Hybrid!$A$1:$LI$1),FALSE) -> 0.46131529 | L23: =VLOOKUP($E23,Hybrid!$1:$1048576,MATCH(DATE(L$2,1,1),Hybrid!$A$1:$LI$1),FALSE) -> 0.47416315 | M23: =VLOOKUP($E23,Hybrid!$1:$1048576,MATCH(DATE(M$2,1,1),Hybrid!$A$1:$LI$1),FALSE) -> 0.48701125 | ... AO23: =VLOOKUP($E23,Hybrid!$1:$1048576,MATCH(DATE(AO$2,1,1),Hybrid!$A$1:$LI$1),FALSE) -> 0.69676976
D24: class D | E24: AUTO_cd_cgas_2 | F24: =VLOOKUP($E24,Hybrid!$1:$1048576,MATCH(DATE(F$2,1,1),Hybrid!$A$1:$LI$1),FALSE) -> 0.24954447 | G24: =VLOOKUP($E24,Hybrid!$1:$1048576,MATCH(DATE(G$2,1,1),Hybrid!$A$1:$LI$1),FALSE) -> 0.25231575 | H24: =VLOOKUP($E24,Hybrid!$1:$1048576,MATCH(DATE(H$2,1,1),Hybrid!$A$1:$LI$1),FALSE) -> 0.25627338 | I24: =VLOOKUP($E24,Hybrid!$1:$1048576,MATCH(DATE(I$2,1,1),Hybrid!$A$1:$LI$1),FALSE) -> 0.26088609 | J24: =VLOOKUP($E24,Hybrid!$1:$1048576,MATCH(DATE(J$2,1,1),Hybrid!$A$1:$LI$1),FALSE) -> 0.26579685 | K24: =VLOOKUP($E24,Hybrid!$1:$1048576,MATCH(DATE(K$2,1,1),Hybrid!$A$1:$LI$1),FALSE) -> 0.27076949 | L24: =VLOOKUP($E24,Hybrid!$1:$1048576,MATCH(DATE(L$2,1,1),Hybrid!$A$1:$LI$1),FALSE) -> 0.27566723 | M24: =VLOOKUP($E24,Hybrid!$1:$1048576,MATCH(DATE(M$2,1,1),Hybrid!$A$1:$LI$1),FALSE) -> 0.28041732 | ... AO24: =VLOOKUP($E24,Hybrid!$1:$1048576,MATCH(DATE(AO$2,1,1),Hybrid!$A$1:$LI$1),FALSE) -> 0.29344625
D25: class E | E25: AUTO_ce_cgas_2 | F25: =VLOOKUP($E25,Hybrid!$1:$1048576,MATCH(DATE(F$2,1,1),Hybrid!$A$1:$LI$1),FALSE) -> 0.15020247 | G25: =VLOOKUP($E25,Hybrid!$1:$1048576,MATCH(DATE(G$2,1,1),Hybrid!$A$1:$LI$1),FALSE) -> 0.1520586 | H25: =VLOOKUP($E25,Hybrid!$1:$1048576,MATCH(DATE(H$2,1,1),Hybrid!$A$1:$LI$1),FALSE) -> 0.15454056 | I25: =VLOOKUP($E25,Hybrid!$1:$1048576,MATCH(DATE(I$2,1,1),Hybrid!$A$1:$LI$1),FALSE) -> 0.15730455 | J25: =VLOOKUP($E25,Hybrid!$1:$1048576,MATCH(DATE(J$2,1,1),Hybrid!$A$1:$LI$1),FALSE) -> 0.16012548 | K25: =VLOOKUP($E25,Hybrid!$1:$1048576,MATCH(DATE(K$2,1,1),Hybrid!$A$1:$LI$1),FALSE) -> 0.16285907 | L25: =VLOOKUP($E25,Hybrid!$1:$1048576,MATCH(DATE(L$2,1,1),Hybrid!$A$1:$LI$1),FALSE) -> 0.16542509 | M25: =VLOOKUP($E25,Hybrid!$1:$1048576,MATCH(DATE(M$2,1,1),Hybrid!$A$1:$LI$1),FALSE) -> 0.16778398 | ... AO25: =VLOOKUP($E25,Hybrid!$1:$1048576,MATCH(DATE(AO$2,1,1),Hybrid!$A$1:$LI$1),FALSE) -> 0.13934386
D26: class F | E26: AUTO_cf_cgas_2 | F26: =VLOOKUP($E26,Hybrid!$1:$1048576,MATCH(DATE(F$2,1,1),Hybrid!$A$1:$LI$1),FALSE) -> 0.074609436 | G26: =VLOOKUP($E26,Hybrid!$1:$1048576,MATCH(DATE(G$2,1,1),Hybrid!$A$1:$LI$1),FALSE) -> 0.075290478 | H26: =VLOOKUP($E26,Hybrid!$1:$1048576,MATCH(DATE(H$2,1,1),Hybrid!$A$1:$LI$1),FALSE) -> 0.076133289 | I26: =VLOOKUP($E26,Hybrid!$1:$1048576,MATCH(DATE(I$2,1,1),Hybrid!$A$1:$LI$1),FALSE) -> 0.076948744 | J26: =VLOOKUP($E26,Hybrid!$1:$1048576,MATCH(DATE(J$2,1,1),Hybrid!$A$1:$LI$1),FALSE) -> 0.077625818 | K26: =VLOOKUP($E26,Hybrid!$1:$1048576,MATCH(DATE(K$2,1,1),Hybrid!$A$1:$LI$1),FALSE) -> 0.078104003 | L26: =VLOOKUP($E26,Hybrid!$1:$1048576,MATCH(DATE(L$2,1,1),Hybrid!$A$1:$LI$1),FALSE) -> 0.078358543 | M26: =VLOOKUP($E26,Hybrid!$1:$1048576,MATCH(DATE(M$2,1,1),Hybrid!$A$1:$LI$1),FALSE) -> 0.078385812 | ... AO26: =VLOOKUP($E26,Hybrid!$1:$1048576,MATCH(DATE(AO$2,1,1),Hybrid!$A$1:$LI$1),FALSE) -> 0.033841539
D27: class G | E27: AUTO_cg_cgas_2 | F27: =VLOOKUP($E27,Hybrid!$1:$1048576,MATCH(DATE(F$2,1,1),Hybrid!$A$1:$LI$1),FALSE) -> 0.13435819 | G27: =VLOOKUP($E27,Hybrid!$1:$1048576,MATCH(DATE(G$2,1,1),Hybrid!$A$1:$LI$1),FALSE) -> 0.1358427 | H27: =VLOOKUP($E27,Hybrid!$1:$1048576,MATCH(DATE(H$2,1,1),Hybrid!$A$1:$LI$1),FALSE) -> 0.1373791 | I27: =VLOOKUP($E27,Hybrid!$1:$1048576,MATCH(DATE(I$2,1,1),Hybrid!$A$1:$LI$1),FALSE) -> 0.13859375 | J27: =VLOOKUP($E27,Hybrid!$1:$1048576,MATCH(DATE(J$2,1,1),Hybrid!$A$1:$LI$1),FALSE) -> 0.13929428 | K27: =VLOOKUP($E27,Hybrid!$1:$1048576,MATCH(DATE(K$2,1,1),Hybrid!$A$1:$LI$1),FALSE) -> 0.13940036 | L27: =VLOOKUP($E27,Hybrid!$1:$1048576,MATCH(DATE(L$2,1,1),Hybrid!$A$1:$LI$1),FALSE) -> 0.13890435 | M27: =VLOOKUP($E27,Hybrid!$1:$1048576,MATCH(DATE(M$2,1,1),Hybrid!$A$1:$LI$1),FALSE) -> 0.13783826 | ... AO27: =VLOOKUP($E27,Hybrid!$1:$1048576,MATCH(DATE(AO$2,1,1),Hybrid!$A$1:$LI$1),FALSE) -> 0.042190416
C28: TOTAL STOCK BASELINE | E28: AUTO_0 | F28: =VLOOKUP($E28,Hybrid!$1:$1048576,MATCH(DATE(F$2,1,1),Hybrid!$A$1:$LI$1),FALSE) -> 32317.941 | G28: =VLOOKUP($E28,Hybrid!$1:$1048576,MATCH(DATE(G$2,1,1),Hybrid!$A$1:$LI$1),FALSE) -> 31931.625 | H28: =VLOOKUP($E28,Hybrid!$1:$1048576,MATCH(DATE(H$2,1,1),Hybrid!$A$1:$LI$1),FALSE) -> 31743.508 | I28: =VLOOKUP($E28,Hybrid!$1:$1048576,MATCH(DATE(I$2,1,1),Hybrid!$A$1:$LI$1),FALSE) -> 31687.792 | J28: =VLOOKUP($E28,Hybrid!$1:$1048576,MATCH(DATE(J$2,1,1),Hybrid!$A$1:$LI$1),FALSE) -> 31720.643 | K28: =VLOOKUP($E28,Hybrid!$1:$1048576,MATCH(DATE(K$2,1,1),Hybrid!$A$1:$LI$1),FALSE) -> 31813.337 | L28: =VLOOKUP($E28,Hybrid!$1:$1048576,MATCH(DATE(L$2,1,1),Hybrid!$A$1:$LI$1),FALSE) -> 31947.162 | M28: =VLOOKUP($E28,Hybrid!$1:$1048576,MATCH(DATE(M$2,1,1),Hybrid!$A$1:$LI$1),FALSE) -> 32109.877 | ... AO28: =VLOOKUP($E28,Hybrid!$1:$1048576,MATCH(DATE(AO$2,1,1),Hybrid!$A$1:$LI$1),FALSE) -> 38673.292
C29: OIL | E29: AUTO_cfut_0 | F29: =VLOOKUP($E29,Hybrid!$1:$1048576,MATCH(DATE(F$2,1,1),Hybrid!$A$1:$LI$1),FALSE) -> 32271.24 | G29: =VLOOKUP($E29,Hybrid!$1:$1048576,MATCH(DATE(G$2,1,1),Hybrid!$A$1:$LI$1),FALSE) -> 31867.185 | H29: =VLOOKUP($E29,Hybrid!$1:$1048576,MATCH(DATE(H$2,1,1),Hybrid!$A$1:$LI$1),FALSE) -> 31660.486 | I29: =VLOOKUP($E29,Hybrid!$1:$1048576,MATCH(DATE(I$2,1,1),Hybrid!$A$1:$LI$1),FALSE) -> 31585.838 | J29: =VLOOKUP($E29,Hybrid!$1:$1048576,MATCH(DATE(J$2,1,1),Hybrid!$A$1:$LI$1),FALSE) -> 31599.721 | K29: =VLOOKUP($E29,Hybrid!$1:$1048576,MATCH(DATE(K$2,1,1),Hybrid!$A$1:$LI$1),FALSE) -> 31673.603 | L29: =VLOOKUP($E29,Hybrid!$1:$1048576,MATCH(DATE(L$2,1,1),Hybrid!$A$1:$LI$1),FALSE) -> 31788.887 | M29: =VLOOKUP($E29,Hybrid!$1:$1048576,MATCH(DATE(M$2,1,1),Hybrid!$A$1:$LI$1),FALSE) -> 31933.397 | ... AO29: =VLOOKUP($E29,Hybrid!$1:$1048576,MATCH(DATE(AO$2,1,1),Hybrid!$A$1:$LI$1),FALSE) -> 38101.905
D30: class A | E30: AUTO_ca_cfut_0 | F30: =VLOOKUP($E30,Hybrid!$1:$1048576,MATCH(DATE(F$2,1,1),Hybrid!$A$1:$LI$1),FALSE) -> 7095.7005 | G30: =VLOOKUP($E30,Hybrid!$1:$1048576,MATCH(DATE(G$2,1,1),Hybrid!$A$1:$LI$1),FALSE) -> 7143.1788 | H30: =VLOOKUP($E30,Hybrid!$1:$1048576,MATCH(DATE(H$2,1,1),Hybrid!$A$1:$LI$1),FALSE) -> 7239.81 | I30: =VLOOKUP($E30,Hybrid!$1:$1048576,MATCH(DATE(I$2,1,1),Hybrid!$A$1:$LI$1),FALSE) -> 7369.0432 | J30: =VLOOKUP($E30,Hybrid!$1:$1048576,MATCH(DATE(J$2,1,1),Hybrid!$A$1:$LI$1),FALSE) -> 7519.6803 | K30: =VLOOKUP($E30,Hybrid!$1:$1048576,MATCH(DATE(K$2,1,1),Hybrid!$A$1:$LI$1),FALSE) -> 7684.2986 | L30: =VLOOKUP($E30,Hybrid!$1:$1048576,MATCH(DATE(L$2,1,1),Hybrid!$A$1:$LI$1),FALSE) -> 7858.0379 | M30: =VLOOKUP($E30,Hybrid!$1:$1048576,MATCH(DATE(M$2,1,1),Hybrid!$A$1:$LI$1),FALSE) -> 8037.7298 | ... AO30: =VLOOKUP($E30,Hybrid!$1:$1048576,MATCH(DATE(AO$2,1,1),Hybrid!$A$1:$LI$1),FALSE) -> 13271.9
D31: class B | E31: AUTO_cb_cfut_0 | F31: =VLOOKUP($E31,Hybrid!$1:$1048576,MATCH(DATE(F$2,1,1),Hybrid!$A$1:$LI$1),FALSE) -> 8251.2564 | G31: =VLOOKUP($E31,Hybrid!$1:$1048576,MATCH(DATE(G$2,1,1),Hybrid!$A$1:$LI$1),FALSE) -> 8184.1785 | H31: =VLOOKUP($E31,Hybrid!$1:$1048576,MATCH(DATE(H$2,1,1),Hybrid!$A$1:$LI$1),FALSE) -> 8171.8779 | I31: =VLOOKUP($E31,Hybrid!$1:$1048576,MATCH(DATE(I$2,1,1),Hybrid!$A$1:$LI$1),FALSE) -> 8197.5342 | J31: =VLOOKUP($E31,Hybrid!$1:$1048576,MATCH(DATE(J$2,1,1),Hybrid!$A$1:$LI$1),FALSE) -> 8249.6491 | K31: =VLOOKUP($E31,Hybrid!$1:$1048576,MATCH(DATE(K$2,1,1),Hybrid!$A$1:$LI$1),FALSE) -> 8320.4704 | L31: =VLOOKUP($E31,Hybrid!$1:$1048576,MATCH(DATE(L$2,1,1),Hybrid!$A$1:$LI$1),FALSE) -> 8404.7877 | M31: =VLOOKUP($E31,Hybrid!$1:$1048576,MATCH(DATE(M$2,1,1),Hybrid!$A$1:$LI$1),FALSE) -> 8499.0715 | ... AO31: =VLOOKUP($E31,Hybrid!$1:$1048576,MATCH(DATE(AO$2,1,1),Hybrid!$A$1:$LI$1),FALSE) -> 11875.349
D32: class C | E32: AUTO_cc_cfut_0 | F32: =VLOOKUP($E32,Hybrid!$1:$1048576,MATCH(DATE(F$2,1,1),Hybrid!$A$1:$LI$1),FALSE) -> 6777.6025 | G32: =VLOOKUP($E32,Hybrid!$1:$1048576,MATCH(DATE(G$2,1,1),Hybrid!$A$1:$LI$1),FALSE) -> 6647.7392 | H32: =VLOOKUP($E32,Hybrid!$1:$1048576,MATCH(DATE(H$2,1,1),Hybrid!$A$1:$LI$1),FALSE) -> 6561.4778 | I32: =VLOOKUP($E32,Hybrid!$1:$1048576,MATCH(DATE(I$2,1,1),Hybrid!$A$1:$LI$1),FALSE) -> 6506.5051 | J32: =VLOOKUP($E32,Hybrid!$1:$1048576,MATCH(DATE(J$2,1,1),Hybrid!$A$1:$LI$1),FALSE) -> 6474.3214 | K32: =VLOOKUP($E32,Hybrid!$1:$1048576,MATCH(DATE(K$2,1,1),Hybrid!$A$1:$LI$1),FALSE) -> 6459.1067 | L32: =VLOOKUP($E32,Hybrid!$1:$1048576,MATCH(DATE(L$2,1,1),Hybrid!$A$1:$LI$1),FALSE) -> 6456.8591 | M32: =VLOOKUP($E32,Hybrid!$1:$1048576,MATCH(DATE(M$2,1,1),Hybrid!$A$1:$LI$1),FALSE) -> 6464.7815 | ... AO32: =VLOOKUP($E32,Hybrid!$1:$1048576,MATCH(DATE(AO$2,1,1),Hybrid!$A$1:$LI$1),FALSE) -> 7687.7208
D33: class D | E33: AUTO_cd_cfut_0 | F33: =VLOOKUP($E33,Hybrid!$1:$1048576,MATCH(DATE(F$2,1,1),Hybrid!$A$1:$LI$1),FALSE) -> 4159.6639 | G33: =VLOOKUP($E33,Hybrid!$1:$1048576,MATCH(DATE(G$2,1,1),Hybrid!$A$1:$LI$1),FALSE) -> 4055.1231 | H33: =VLOOKUP($E33,Hybrid!$1:$1048576,MATCH(DATE(H$2,1,1),Hybrid!$A$1:$LI$1),FALSE) -> 3975.2329 | I33: =VLOOKUP($E33,Hybrid!$1:$1048576,MATCH(DATE(I$2,1,1),Hybrid!$A$1:$LI$1),FALSE) -> 3912.5808 | J33: =VLOOKUP($E33,Hybrid!$1:$1048576,MATCH(DATE(J$2,1,1),Hybrid!$A$1:$LI$1),FALSE) -> 3862.1234 | K33: =VLOOKUP($E33,Hybrid!$1:$1048576,MATCH(DATE(K$2,1,1),Hybrid!$A$1:$LI$1),FALSE) -> 3820.4516 | L33: =VLOOKUP($E33,Hybrid!$1:$1048576,MATCH(DATE(L$2,1,1),Hybrid!$A$1:$LI$1),FALSE) -> 3785.2435 | M33: =VLOOKUP($E33,Hybrid!$1:$1048576,MATCH(DATE(M$2,1,1),Hybrid!$A$1:$LI$1),FALSE) -> 3754.8857 | ... AO33: =VLOOKUP($E33,Hybrid!$1:$1048576,MATCH(DATE(AO$2,1,1),Hybrid!$A$1:$LI$1),FALSE) -> 3102.3334
D34: class E | E34: AUTO_ce_cfut_0 | F34: =VLOOKUP($E34,Hybrid!$1:$1048576,MATCH(DATE(F$2,1,1),Hybrid!$A$1:$LI$1),FALSE) -> 2503.7292 | G34: =VLOOKUP($E34,Hybrid!$1:$1048576,MATCH(DATE(G$2,1,1),Hybrid!$A$1:$LI$1),FALSE) -> 2443.054 | H34: =VLOOKUP($E34,Hybrid!$1:$1048576,MATCH(DATE(H$2,1,1),Hybrid!$A$1:$LI$1),FALSE) -> 2396.145 | I34: =VLOOKUP($E34,Hybrid!$1:$1048576,MATCH(DATE(I$2,1,1),Hybrid!$A$1:$LI$1),FALSE) -> 2358.2745 | J34: =VLOOKUP($E34,Hybrid!$1:$1048576,MATCH(DATE(J$2,1,1),Hybrid!$A$1:$LI$1),FALSE) -> 2326.3079 | K34: =VLOOKUP($E34,Hybrid!$1:$1048576,MATCH(DATE(K$2,1,1),Hybrid!$A$1:$LI$1),FALSE) -> 2298.1904 | L34: =VLOOKUP($E34,Hybrid!$1:$1048576,MATCH(DATE(L$2,1,1),Hybrid!$A$1:$LI$1),FALSE) -> 2272.5718 | M34: =VLOOKUP($E34,Hybrid!$1:$1048576,MATCH(DATE(M$2,1,1),Hybrid!$A$1:$LI$1),FALSE) -> 2248.5516 | ... AO34: =VLOOKUP($E34,Hybrid!$1:$1048576,MATCH(DATE(AO$2,1,1),Hybrid!$A$1:$LI$1),FALSE) -> 1454.1661
D35: class F | E35: AUTO_cf_cfut_0 | F35: =VLOOKUP($E35,Hybrid!$1:$1048576,MATCH(DATE(F$2,1,1),Hybrid!$A$1:$LI$1),FALSE) -> 1243.6668 | G35: =VLOOKUP($E35,Hybrid!$1:$1048576,MATCH(DATE(G$2,1,1),Hybrid!$A$1:$LI$1),FALSE) -> 1210.6549 | H35: =VLOOKUP($E35,Hybrid!$1:$1048576,MATCH(DATE(H$2,1,1),Hybrid!$A$1:$LI$1),FALSE) -> 1182.7476 | I35: =VLOOKUP($E35,Hybrid!$1:$1048576,MATCH(DATE(I$2,1,1),Hybrid!$A$1:$LI$1),FALSE) -> 1157.3995 | J35: =VLOOKUP($E35,Hybrid!$1:$1048576,MATCH(DATE(J$2,1,1),Hybrid!$A$1:$LI$1),FALSE) -> 1133.0829 | K35: =VLOOKUP($E35,Hybrid!$1:$1048576,MATCH(DATE(K$2,1,1),Hybrid!$A$1:$LI$1),FALSE) -> 1108.9242 | L35: =VLOOKUP($E35,Hybrid!$1:$1048576,MATCH(DATE(L$2,1,1),Hybrid!$A$1:$LI$1),FALSE) -> 1084.4506 | M35: =VLOOKUP($E35,Hybrid!$1:$1048576,MATCH(DATE(M$2,1,1),Hybrid!$A$1:$LI$1),FALSE) -> 1059.4277 | ... AO35: =VLOOKUP($E35,Hybrid!$1:$1048576,MATCH(DATE(AO$2,1,1),Hybrid!$A$1:$LI$1),FALSE) -> 325.27338
D36: class G | E36: AUTO_cg_cfut_0 | F36: =VLOOKUP($E36,Hybrid!$1:$1048576,MATCH(DATE(F$2,1,1),Hybrid!$A$1:$LI$1),FALSE) -> 2239.6206 | G36: =VLOOKUP($E36,Hybrid!$1:$1048576,MATCH(DATE(G$2,1,1),Hybrid!$A$1:$LI$1),FALSE) -> 2183.2559 | H36: =VLOOKUP($E36,Hybrid!$1:$1048576,MATCH(DATE(H$2,1,1),Hybrid!$A$1:$LI$1),FALSE) -> 2133.1946 | I36: =VLOOKUP($E36,Hybrid!$1:$1048576,MATCH(DATE(I$2,1,1),Hybrid!$A$1:$LI$1),FALSE) -> 2084.5006 | J36: =VLOOKUP($E36,Hybrid!$1:$1048576,MATCH(DATE(J$2,1,1),Hybrid!$A$1:$LI$1),FALSE) -> 2034.5555 | K36: =VLOOKUP($E36,Hybrid!$1:$1048576,MATCH(DATE(K$2,1,1),Hybrid!$A$1:$LI$1),FALSE) -> 1982.161 | L36: =VLOOKUP($E36,Hybrid!$1:$1048576,MATCH(DATE(L$2,1,1),Hybrid!$A$1:$LI$1),FALSE) -> 1926.9369 | M36: =VLOOKUP($E36,Hybrid!$1:$1048576,MATCH(DATE(M$2,1,1),Hybrid!$A$1:$LI$1),FALSE) -> 1868.9489 | ... AO36: =VLOOKUP($E36,Hybrid!$1:$1048576,MATCH(DATE(AO$2,1,1),Hybrid!$A$1:$LI$1),FALSE) -> 385.16287
C37: ELEC | E37: AUTO_cele_0 | F37: =VLOOKUP($E37,Hybrid!$1:$1048576,MATCH(DATE(F$2,1,1),Hybrid!$A$1:$LI$1),FALSE) -> 44.765 | G37: =VLOOKUP($E37,Hybrid!$1:$1048576,MATCH(DATE(G$2,1,1),Hybrid!$A$1:$LI$1),FALSE) -> 62.448716 | H37: =VLOOKUP($E37,Hybrid!$1:$1048576,MATCH(DATE(H$2,1,1),Hybrid!$A$1:$LI$1),FALSE) -> 80.963971 | I37: =VLOOKUP($E37,Hybrid!$1:$1048576,MATCH(DATE(I$2,1,1),Hybrid!$A$1:$LI$1),FALSE) -> 99.823967 | J37: =VLOOKUP($E37,Hybrid!$1:$1048576,MATCH(DATE(J$2,1,1),Hybrid!$A$1:$LI$1),FALSE) -> 118.71772 | K37: =VLOOKUP($E37,Hybrid!$1:$1048576,MATCH(DATE(K$2,1,1),Hybrid!$A$1:$LI$1),FALSE) -> 137.4542 | L37: =VLOOKUP($E37,Hybrid!$1:$1048576,MATCH(DATE(L$2,1,1),Hybrid!$A$1:$LI$1),FALSE) -> 155.92054 | M37: =VLOOKUP($E37,Hybrid!$1:$1048576,MATCH(DATE(M$2,1,1),Hybrid!$A$1:$LI$1),FALSE) -> 174.05324 | ... AO37: =VLOOKUP($E37,Hybrid!$1:$1048576,MATCH(DATE(AO$2,1,1),Hybrid!$A$1:$LI$1),FALSE) -> 567.61281
D38: class A | E38: AUTO_ca_cele_0 | F38: =VLOOKUP($E38,Hybrid!$1:$1048576,MATCH(DATE(F$2,1,1),Hybrid!$A$1:$LI$1),FALSE) -> 9.8427899 | G38: =VLOOKUP($E38,Hybrid!$1:$1048576,MATCH(DATE(G$2,1,1),Hybrid!$A$1:$LI$1),FALSE) -> 14.990816 | H38: =VLOOKUP($E38,Hybrid!$1:$1048576,MATCH(DATE(H$2,1,1),Hybrid!$A$1:$LI$1),FALSE) -> 20.422984 | I38: =VLOOKUP($E38,Hybrid!$1:$1048576,MATCH(DATE(I$2,1,1),Hybrid!$A$1:$LI$1),FALSE) -> 26.012773 | J38: =VLOOKUP($E38,Hybrid!$1:$1048576,MATCH(DATE(J$2,1,1),Hybrid!$A$1:$LI$1),FALSE) -> 31.67695 | K38: =VLOOKUP($E38,Hybrid!$1:$1048576,MATCH(DATE(K$2,1,1),Hybrid!$A$1:$LI$1),FALSE) -> 37.362607 | L38: =VLOOKUP($E38,Hybrid!$1:$1048576,MATCH(DATE(L$2,1,1),Hybrid!$A$1:$LI$1),FALSE) -> 43.037132 | M38: =VLOOKUP($E38,Hybrid!$1:$1048576,MATCH(DATE(M$2,1,1),Hybrid!$A$1:$LI$1),FALSE) -> 48.681062 | ... AO38: =VLOOKUP($E38,Hybrid!$1:$1048576,MATCH(DATE(AO$2,1,1),Hybrid!$A$1:$LI$1),FALSE) -> 195.65638
D39: class B | E39: AUTO_cb_cele_0 | F39: =VLOOKUP($E39,Hybrid!$1:$1048576,MATCH(DATE(F$2,1,1),Hybrid!$A$1:$LI$1),FALSE) -> 11.445717 | G39: =VLOOKUP($E39,Hybrid!$1:$1048576,MATCH(DATE(G$2,1,1),Hybrid!$A$1:$LI$1),FALSE) -> 16.302056 | H39: =VLOOKUP($E39,Hybrid!$1:$1048576,MATCH(DATE(H$2,1,1),Hybrid!$A$1:$LI$1),FALSE) -> 21.423897 | I39: =VLOOKUP($E39,Hybrid!$1:$1048576,MATCH(DATE(I$2,1,1),Hybrid!$A$1:$LI$1),FALSE) -> 26.687145 | J39: =VLOOKUP($E39,Hybrid!$1:$1048576,MATCH(DATE(J$2,1,1),Hybrid!$A$1:$LI$1),FALSE) -> 32.010429 | K39: =VLOOKUP($E39,Hybrid!$1:$1048576,MATCH(DATE(K$2,1,1),Hybrid!$A$1:$LI$1),FALSE) -> 37.342129 | L39: =VLOOKUP($E39,Hybrid!$1:$1048576,MATCH(DATE(L$2,1,1),Hybrid!$A$1:$LI$1),FALSE) -> 42.650406 | M39: =VLOOKUP($E39,Hybrid!$1:$1048576,MATCH(DATE(M$2,1,1),Hybrid!$A$1:$LI$1),FALSE) -> 47.916153 | ... AO39: =VLOOKUP($E39,Hybrid!$1:$1048576,MATCH(DATE(AO$2,1,1),Hybrid!$A$1:$LI$1),FALSE) -> 177.032
D40: class C | E40: AUTO_cc_cele_0 | F40: =VLOOKUP($E40,Hybrid!$1:$1048576,MATCH(DATE(F$2,1,1),Hybrid!$A$1:$LI$1),FALSE) -> 9.4015406 | G40: =VLOOKUP($E40,Hybrid!$1:$1048576,MATCH(DATE(G$2,1,1),Hybrid!$A$1:$LI$1),FALSE) -> 12.69964 | H40: =VLOOKUP($E40,Hybrid!$1:$1048576,MATCH(DATE(H$2,1,1),Hybrid!$A$1:$LI$1),FALSE) -> 16.176695 | I40: =VLOOKUP($E40,Hybrid!$1:$1048576,MATCH(DATE(I$2,1,1),Hybrid!$A$1:$LI$1),FALSE) -> 19.745034 | J40: =VLOOKUP($E40,Hybrid!$1:$1048576,MATCH(DATE(J$2,1,1),Hybrid!$A$1:$LI$1),FALSE) -> 23.347366 | K40: =VLOOKUP($E40,Hybrid!$1:$1048576,MATCH(DATE(K$2,1,1),Hybrid!$A$1:$LI$1),FALSE) -> 26.947438 | L40: =VLOOKUP($E40,Hybrid!$1:$1048576,MATCH(DATE(L$2,1,1),Hybrid!$A$1:$LI$1),FALSE) -> 30.522894 | M40: =VLOOKUP($E40,Hybrid!$1:$1048576,MATCH(DATE(M$2,1,1),Hybrid!$A$1:$LI$1),FALSE) -> 34.060268 | ... AO40: =VLOOKUP($E40,Hybrid!$1:$1048576,MATCH(DATE(AO$2,1,1),Hybrid!$A$1:$LI$1),FALSE) -> 115.62675
...

Sheet date
A1: =Hybrid!A1 -> _date_ | B1: =Hybrid!B1 -> 42005 | C1: =Hybrid!C1 -> 42370 | D1: =Hybrid!D1 -> 42736 | E1: =Hybrid!E1 -> 43101 | F1: =Hybrid!F1 -> 43466 | G1: =Hybrid!G1 -> 43831 | H1: =Hybrid!H1 -> 44197 | ... AK1: =Hybrid!AK1 -> 54789
B2: =TEXT(B1,"jj mm aaaa") -> 01 01 2015 | C2: =TEXT(C1,"jj mm aaaa") -> 01 01 2016 | D2: =TEXT(D1,"jj mm aaaa") -> 01 01 2017 | E2: =TEXT(E1,"jj mm aaaa") -> 01 01 2018 | F2: =TEXT(F1,"jj mm aaaa") -> 01 01 2019 | G2: =TEXT(G1,"jj mm aaaa") -> 01 01 2020 | H2: =TEXT(H1,"jj mm aaaa") -> 01 01 2021 | I2: =TEXT(I1,"jj mm aaaa") -> 01 01 2022 | ... AK2: =TEXT(AK1,"jj mm aaaa") -> 01 01 2050
B3: =RIGHT(B2,4) -> 2015 | C3: =RIGHT(C2,4) -> 2016 | D3: =RIGHT(D2,4) -> 2017 | E3: =RIGHT(E2,4) -> 2018 | F3: =RIGHT(F2,4) -> 2019 | G3: =RIGHT(G2,4) -> 2020 | H3: =RIGHT(H2,4) -> 2021 | I3: =RIGHT(I2,4) -> 2022 | ... AK3: =RIGHT(AK2,4) -> 2050

Sheet Emissions
A1: _date_ | B1: 42005 | C1: 42370 | D1: 42736 | E1: 43101 | F1: 43466 | G1: 43831 | H1: 44197 | I1: 44562 | J1: 44927 | K1: 45292 | L1: 45658 | M1: 46023 | N1: 46388 | O1: 46753 | P1: 47119 | Q1: 47484 | R1: 47849 | S1: 48214 | T1: 48580 | U1: 48945 | V1: 49310 | W1: 49675 | X1: 50041 | Y1: 50406 | Z1: 50771 | AA1: 51136 | AB1: 51502 | AC1: 51867 | AD1: 52232 | AE1: 52597 | AF1: 52963 | AG1: 53328 | AH1: 53693 | AI1: 54058 | AJ1: 54424 | AK1: 54789
A2: ems_2 | B2: 470.0039 | C2: 472.84455 | D2: 474.86665 | E2: 476.76345 | F2: 478.71635 | G2: 480.69338 | H2: 482.74318 | I2: 484.98073 | J2: 487.42448 | K2: 490.03946 | L2: 492.7645 | M2: 495.52795 | N2: 498.25701 | O2: 500.88369 | P2: 503.3488 | Q2: 505.60459 | R2: 507.69101 | S2: 509.71056 | T2: 511.73272 | U2: 513.80209 | V2: 515.94658 | W2: 518.18322 | X2: 520.52194 | Y2: 522.96796 | Z2: 525.5234 | AA2: 528.18829 | AB2: 530.96133 | AC2: 533.84036 | AD2: 536.82271 | AE2: 539.90547 | AF2: 543.08563 | AG2: 546.36026 | AH2: 549.72658 | AI2: 553.182 | AJ2: 556.72421 | AK2: 560.35114
A3: ems_ch_2 | B3: 129.15358 | C3: 128.77123 | D3: 127.86909 | E3: 126.94185 | F3: 126.12206 | G3: 125.40586 | H3: 124.80024 | I3: 124.3226 | J3: 123.94978 | K3: 123.64788 | L3: 123.38375 | M3: 123.12891 | N3: 122.86043 | O3: 122.56074 | P3: 122.21715 | Q3: 121.82125 | R3: 121.39369 | S3: 120.96838 | T3: 120.55918 | U3: 120.17038 | V3: 119.80185 | W3: 119.45162 | X3: 119.11705 | Y3: 118.79536 | Z3: 118.48386 | AA3: 118.17998 | AB3: 117.88131 | AC3: 117.58553 | AD3: 117.29044 | AE3: 116.99392 | AF3: 116.6939 | AG3: 116.38838 | AH3: 116.07539 | AI3: 115.75301 | AJ3: 115.41938 | AK3: 115.07267
A4: ems_ch_2+ems_ci_2 | B4: 349.86054 | C4: 351.44065 | D4: 352.21014 | E4: 352.81448 | F4: 353.42145 | G4: 354.00057 | H4: 354.60775 | I4: 355.36536 | J4: 356.29689 | K4: 357.37086 | L4: 358.52872 | M4: 359.70094 | N4: 360.81661 | O4: 361.80957 | P4: 362.62248 | Q4: 363.20948 | R4: 363.61303 | S4: 363.9376 | T4: 364.25294 | U4: 364.603 | V4: 365.01464 | W4: 365.5037 | X4: 366.07885 | Y4: 366.74417 | Z4: 367.50077 | AA4: 368.34782 | AB4: 369.28331 | AC4: 370.30447 | AD4: 371.40813 | AE4: 372.59096 | AF4: 373.84955 | AG4: 375.18058 | AH4: 376.58089 | AI4: 378.04747 | AJ4: 379.57754 | AK4: 381.16858
A5: ems_ci_2 | B5: 220.70697 | C5: 222.66941 | D5: 224.34104 | E5: 225.87263 | F5: 227.29938 | G5: 228.59471 | H5: 229.8075 | I5: 231.04277 | J5: 232.34711 | K5: 233.72298 | L5: 235.14497 | M5: 236.57203 | N5: 237.95619 | O5: 239.24883 | P5: 240.40533 | Q5: 241.38823 | R5: 242.21934 | S5: 242.96922 | T5: 243.69376 | U5: 244.43262 | V5: 245.21279 | W5: 246.05208 | X5: 246.9618 | Y5: 247.94881 | Z5: 249.01691 | AA5: 250.16784 | AB5: 251.402 | AC5: 252.71894 | AD5: 254.11769 | AE5: 255.59704 | AF5: 257.15564 | AG5: 258.7922 | AH5: 260.5055 | AI5: 262.29446 | AJ5: 264.15817 | AK5: 266.09591
A6: ems_mat_2 | B6: 27.950294 | C6: 28.262141 | D6: 28.572697 | E6: 28.886185 | F6: 29.20448 | G6: 29.527886 | H6: 29.856269 | I6: 30.189684 | J6: 30.528205 | K6: 30.87176 | L6: 31.220109 | M6: 31.572874 | N6: 31.929569 | O6: 32.289639 | P6: 32.652487 | Q6: 33.017498 | R6: 33.384339 | S6: 33.753157 | T6: 34.124371 | U6: 34.498465 | V6: 34.875907 | W6: 35.257118 | X6: 35.642459 | Y6: 36.032235 | Z6: 36.426699 | AA6: 36.826056 | AB6: 37.230474 | AC6: 37.64009 | AD6: 38.055018 | AE6: 38.475351 | AF6: 38.901175 | AG6: 39.332563 | AH6: 39.769589 | AI6: 40.212322 | AJ6: 40.660834 | AK6: 41.115199
A7: ems_y_2 | B7: 92.193058 | C7: 93.141768 | D7: 94.083816 | E7: 95.062789 | F7: 96.090427 | G7: 97.164925 | H7: 98.279169 | I7: 99.42568 | J7: 100.59938 | K7: 101.79684 | L7: 103.01567 | M7: 104.25414 | N7: 105.51083 | O7: 106.78448 | P7: 108.07383 | Q7: 109.37761 | R7: 110.69364 | S7: 112.0198 | T7: 113.35541 | U7: 114.70063 | V7: 116.05603 | W7: 117.42241 | X7: 118.80063 | Y7: 120.19155 | Z7: 121.59593 | AA7: 123.01441 | AB7: 124.44755 | AC7: 125.89581 | AD7: 127.35956 | AE7: 128.83916 | AF7: 130.33491 | AG7: 131.84712 | AH7: 133.3761 | AI7: 134.92221 | AJ7: 136.48583 | AK7: 138.06737
A8: ems_sec_2 | B8: 340.85032 | C8: 344.07332 | D8: 346.99756 | E8: 349.82161 | F8: 352.59429 | G8: 355.28752 | H8: 357.94294 | I8: 360.65813 | J8: 363.4747 | K8: 366.39158 | L8: 369.38075 | M8: 372.39904 | N8: 375.39658 | O8: 378.32295 | P8: 381.13165 | Q8: 383.78334 | R8: 386.29732 | S8: 388.74218 | T8: 391.17354 | U8: 393.63171 | V8: 396.14473 | W8: 398.7316 | X8: 401.40489 | Y8: 404.1726 | Z8: 407.03953 | AA8: 410.0083 | AB8: 413.08002 | AC8: 416.25483 | AD8: 419.53227 | AE8: 422.91155 | AF8: 426.39173 | AG8: 429.97188 | AH8: 433.65119 | AI8: 437.42899 | AJ8: 441.30483 | AK8: 445.27848
A9: ems_ets_2 | B9: 126.91621 | C9: 128.03846 | D9: 128.98332 | E9: 129.84441 | F9: 130.64798 | G9: 131.38233 | H9: 132.06974 | I9: 132.76334 | J9: 133.49 | K9: 134.25326 | L9: 135.04078 | M9: 135.83083 | N9: 136.59722 | O9: 137.31303 | P9: 137.95325 | Q9: 138.49677 | R9: 138.95324 | S9: 139.35951 | T9: 139.74708 | U9: 140.13913 | V9: 140.55168 | W9: 140.99532 | X9: 141.47684 | Y9: 142.00033 | Z9: 142.56814 | AA9: 143.18142 | AB9: 143.84058 | AC9: 144.54557 | AD9: 145.29605 | AE9: 146.09156 | AF9: 146.93157 | AG9: 147.81555 | AH9: 148.74302 | AI9: 149.71356 | AJ9: 150.72684 | AK9: 151.78258
A10: ems_nets_2 | B10: 213.93412 | C10: 216.03486 | D10: 218.01424 | E10: 219.9772 | F10: 221.94631 | G10: 223.90519 | H10: 225.8732 | I10: 227.89479 | J10: 229.98469 | K10: 232.13831 | L10: 234.33997 | M10: 236.56822 | N10: 238.79936 | O10: 241.00992 | P10: 243.1784 | Q10: 245.28657 | R10: 247.34408 | S10: 249.38267 | T10: 251.42646 | U10: 253.49258 | V10: 255.59305 | W10: 257.73627 | X10: 259.92805 | Y10: 262.17227 | Z10: 264.4714 | AA10: 266.82689 | AB10: 269.23944 | AC10: 271.70927 | AD10: 274.23622 | AE10: 276.81998 | AF10: 279.46016 | AG10: 282.15633 | AH10: 284.90817 | AI10: 287.71543 | AJ10: 290.57799 | AK10: 293.4959
A11: ems_netsi_2 | B11: 25.647636 | C11: 25.89121 | D11: 26.113028 | E11: 26.325392 | F11: 26.530869 | G11: 26.727193 | H11: 26.919789 | I11: 27.118545 | J11: 27.327026 | K11: 27.544727 | L11: 27.768832 | M11: 27.99533 | N11: 28.219731 | O11: 28.437561 | P11: 28.644697 | Q11: 28.837619 | R11: 29.018366 | S11: 29.193381 | T11: 29.367467 | U11: 29.543946 | V11: 29.725095 | W11: 29.91247 | X11: 30.107118 | Y11: 30.309723 | Z11: 30.520709 | AA11: 30.740309 | AB11: 30.968619 | AC11: 31.205641 | AD11: 31.451312 | AE11: 31.705531 | AF11: 31.968175 | AG11: 32.239114 | AH11: 32.518221 | AI11: 32.805381 | AJ11: 33.100493 | AK11: 33.403478
A12: ems_trsp_2-ems_sair_2 | B12: 24.99273 | C12: 25.238917 | D12: 25.466326 | E12: 25.68735 | F12: 25.905589 | G12: 26.119952 | H12: 26.33202 | I12: 26.546369 | J12: 26.765242 | K12: 26.988745 | L12: 27.215497 | M12: 27.44316 | N12: 27.668836 | O12: 27.88936 | P12: 28.101522 | Q12: 28.302243 | R12: 28.491883 | S12: 28.674181 | T12: 28.852426 | U12: 29.029165 | V12: 29.206324 | W12: 29.385348 | X12: 29.56732 | Y12: 29.753053 | Z12: 29.943151 | AA12: 30.138068 | AB12: 30.338143 | AC12: 30.543633 | AD12: 30.754736 | AE12: 30.971609 | AF12: 31.194381 | AG12: 31.42316 | AH12: 31.658047 | AI12: 31.899135 | AJ12: 32.146516 | AK12: 32.400284
... A819: ems_ch_cbio_0+ems_ci_cbio_0 | B819: 31.971027 | C819: 32.007879 | D819: 31.913715 | E819: 31.777071 | F819: 31.634471 | G819: 31.499044 | H819: 31.374108 | I819: 31.259284 | J819: 31.153102 | K819: 31.054017 | L819: 30.96074 | M819: 30.872295 | N819: 30.787979 | O819: 30.707301 | P819: 30.629922 | Q819: 30.555608 | R819: 30.484203 | S819: 30.415596 | T819: 30.349705 | U819: 30.286408 | V819: 30.225638 | W819: 30.167359 | X819: 30.111552 | Y819: 30.058202 | Z819: 30.007304 | AA819: 29.958849 | AB819: 29.912833 | AC819: 29.869249 | AD819: 29.828093 | AE819: 29.789358 | AF819: 29.75304 | AG819: 29.719132 | AH819: 29.68763 | AI819: 29.658527 | AJ819: 29.63182 | AK819: 29.607503

Sheet Consumption
A1: _date_ | B1: 42005 | C1: 42370 | D1: 42736 | E1: 43101 | F1: 43466 | G1: 43831 | H1: 44197 | I1: 44562 | J1: 44927 | K1: 45292 | L1: 45658 | M1: 46023 | N1: 46388 | O1: 46753 | P1: 47119 | Q1: 47484 | R1: 47849 | S1: 48214 | T1: 48580 | U1: 48945 | V1: 49310 | W1: 49675 | X1: 50041 | Y1: 50406 | Z1: 50771 | AA1: 51136 | AB1: 51502 | AC1: 51867 | AD1: 52232 | AE1: 52597 | AF1: 52963 | AG1: 53328 | AH1: 53693 | AI1: 54058 | AJ1: 54424 | AK1: 54789
A2: ch_2 | B2: 1202071.8 | C2: 1215689.3 | D2: 1229305.1 | E2: 1242997.6 | F2: 1256839.9 | G2: 1270927.5 | H2: 1285337.6 | I2: 1300100 | J2: 1315211 | K2: 1330655.9 | L2: 1346423.6 | M2: 1362510.2 | N2: 1378918.7 | O2: 1395656.2 | P2: 1412732.6 | Q2: 1430158.4 | R2: 1447931.2 | S2: 1466027.1 | T2: 1484413 | U2: 1503059 | V2: 1521943.6 | W2: 1541053.6 | X2: 1560381.5 | Y2: 1579922.5 | Z2: 1599673.1 | AA2: 1619629.3 | AB2: 1639786.4 | AC2: 1660138.8 | AD2: 1680680.3 | AE2: 1701404.5 | AF2: 1722305.2 | AG2: 1743376.7 | AH2: 1764614.2 | AI2: 1786014.2 | AJ2: 1807574.5 | AK2: 1829294.5
A3: ch_0 | B3: 1202071.8 | C3: 1215641.6 | D3: 1229141.5 | E3: 1242648.3 | F3: 1256238.1 | G3: 1270001.2 | H3: 1284016.1 | I3: 1298333 | J3: 1312973.1 | K3: 1327935.9 | L3: 1343208.5 | M3: 1358772.9 | N3: 1374610.8 | O3: 1390705.9 | P3: 1407045.5 | Q3: 1423620.3 | R3: 1440423.8 | S3: 1457451.5 | T3: 1474700.5 | U3: 1492169 | V3: 1509855.2 | W3: 1527757.7 | X3: 1545875.1 | Y3: 1564206 | Z3: 1582749 | AA3: 1601502.9 | AB3: 1620466.6 | AC3: 1639639.4 | AD3: 1659020.8 | AE3: 1678610.9 | AF3: 1698410.1 | AG3: 1718419.4 | AH3: 1738640.1 | AI3: 1759074.1 | AJ3: 1779723.6 | AK3: 1800591.2
A4: pch_2 | B4: 1 | C4: 1.0202551 | D4: 1.0408151 | E4: 1.0617736 | F4: 1.0832399 | G4: 1.1053213 | H4: 1.1279684 | I4: 1.1511122 | J4: 1.1748104 | K4: 1.1991128 | L4: 1.2240667 | M4: 1.2497206 | N4: 1.2761268 | O4: 1.3033421 | P4: 1.3314278 | Q4: 1.3604493 | R4: 1.3903664 | S4: 1.4211088 | T4: 1.4526864 | U4: 1.4851 | V4: 1.5183438 | W4: 1.5524079 | X4: 1.5872802 | Y4: 1.6229477 | Z4: 1.6593976 | AA4: 1.6966171 | AB4: 1.7345944 | AC4: 1.7733182 | AD4: 1.8127784 | AE4: 1.8529658 | AF4: 1.8938724 | AG4: 1.9354915 | AH4: 1.9778174 | AI4: 2.0208462 | AJ4: 2.0645753 | AK4: 2.1090035
A5: pch_0 | B5: 1 | C5: 1.0198987 | D5: 1.0400695 | E5: 1.0605437 | F5: 1.0813678 | G5: 1.1025858 | H5: 1.1242353 | I5: 1.146347 | J5: 1.1689465 | K5: 1.1920554 | L5: 1.2156926 | M5: 1.2398742 | N5: 1.2646147 | O5: 1.2899264 | P5: 1.3158205 | Q5: 1.3423069 | R5: 1.3693946 | S5: 1.397092 | T5: 1.4254069 | U5: 1.454347 | V5: 1.4839199 | W5: 1.5141329 | X5: 1.5449937 | Y5: 1.5765098 | Z5: 1.6086892 | AA5: 1.64154 | AB5: 1.6750706 | AC5: 1.7092899 | AD5: 1.744207 | AE5: 1.7798315 | AF5: 1.8161737 | AG5: 1.8532442 | AH5: 1.891054 | AI5: 1.9296152 | AJ5: 1.9689399 | AK5: 2.0090411
A6: ch_cagr_2 | B6: 31638 | C6: 31926.255 | D6: 32212.966 | E6: 32522.845 | F6: 32861.418 | G6: 33227.204 | H6: 33615.841 | I6: 34022.762 | J6: 34445.002 | K6: 34880.533 | L6: 35327.987 | M6: 35786.465 | N6: 36255.406 | O6: 36734.483 | P6: 37223.523 | Q6: 37722.457 | R6: 38230.465 | S6: 38746.447 | T6: 39270.053 | U6: 39801.143 | V6: 40339.637 | W6: 40885.459 | X6: 41438.52 | Y6: 41998.697 | Z6: 42565.832 | AA6: 43139.734 | AB6: 43720.18 | AC6: 44306.929 | AD6: 44899.731 | AE6: 45498.339 | AF6: 46102.521 | AG6: 46712.069 | AH6: 47326.813 | AI6: 47946.622 | AJ6: 48571.409 | AK6: 49201.14
A7: ch_cagr_0 | B7: 31638 | C7: 31923.619 | D7: 32206.85 | E7: 32512.452 | F7: 32845.535 | G7: 33204.073 | H7: 33584.186 | I7: 33982.118 | J7: 34394.806 | K7: 34819.912 | L7: 35255.709 | M7: 35700.938 | N7: 36154.696 | O7: 36616.348 | P7: 37085.459 | Q7: 37561.74 | R7: 38045 | S7: 38535.116 | T7: 39032.007 | U7: 39535.611 | V7: 40045.87 | W7: 40562.729 | X7: 41086.13 | Y7: 41616.009 | Z7: 42152.303 | AA7: 42694.952 | AB7: 43243.898 | AC7: 43799.093 | AD7: 44360.5 | AE7: 44928.092 | AF7: 45501.861 | AG7: 46081.809 | AH7: 46667.955 | AI7: 47260.332 | AJ7: 47858.988 | AK7: 48463.982
A8: pch_cagr_2 | B8: 1 | C8: 1.0200609 | D8: 1.0405244 | E8: 1.0614215 | F8: 1.0828179 | G8: 1.1047918 | H8: 1.1273577 | I8: 1.1504798 | J8: 1.1741521 | K8: 1.1983903 | L8: 1.2232263 | M8: 1.2487049 | N8: 1.2748798 | O8: 1.3018117 | P8: 1.3295662 | Q8: 1.3582127 | R8: 1.3877667 | S8: 1.4181919 | T8: 1.4494613 | U8: 1.481554 | V8: 1.5144543 | W8: 1.5481499 | X8: 1.5826312 | Y8: 1.6178902 | Z8: 1.6539203 | AA8: 1.6907155 | AB8: 1.7282702 | AC8: 1.7665796 | AD8: 1.805639 | AE8: 1.8454446 | AF8: 1.8859932 | AG8: 1.9272826 | AH8: 1.9693114 | AI8: 2.0120793 | AJ8: 2.0555874 | AK8: 2.0998377
A9: pch_cagr_0 | B9: 1 | C9: 1.0199097 | D9: 1.0401102 | E9: 1.0606346 | F9: 1.0815269 | G9: 1.1028261 | H9: 1.1245631 | I9: 1.1467626 | J9: 1.1694451 | K9: 1.1926287 | L9: 1.2163293 | M9: 1.2405618 | N9: 1.2653394 | O9: 1.2906742 | P9: 1.3165769 | Q9: 1.3430574 | R9: 1.3701249 | S9: 1.3977879 | T9: 1.4260546 | U9: 1.454933 | V9: 1.484431 | W9: 1.5145566 | X9: 1.545318 | Y9: 1.5767236 | Z9: 1.6087819 | AA9: 1.6415018 | AB9: 1.6748927 | AC9: 1.7089641 | AD9: 1.743726 | AE9: 1.7791888 | AF9: 1.8153635 | AG9: 1.8522615 | AH9: 1.8898946 | AI9: 1.9282753 | AJ9: 1.9674164 | AK9: 2.0073314
A10: ch_cfoo_2 | B10: 175065 | C10: 176665.76 | D10: 178263.1 | E10: 179992.14 | F10: 181882.67 | G10: 183926.86 | H10: 186099.48 | I10: 188372.56 | J10: 190727.99 | K10: 193154.33 | L10: 195644.8 | M10: 198195.81 | N10: 200805.87 | O10: 203474.71 | P10: 206202.79 | Q10: 208990.92 | R10: 211833.87 | S10: 214722.96 | T10: 217653.83 | U10: 220624.16 | V10: 223632.7 | W10: 226678.84 | X10: 229762.22 | Y10: 232882.49 | Z10: 236039.19 | AA10: 239231.64 | AB10: 242458.98 | AC10: 245720.21 | AD10: 249014.2 | AE10: 252339.81 | AF10: 255695.95 | AG10: 259081.63 | AH10: 262496.03 | AI10: 265938.53 | AJ10: 269408.74 | AK10: 272906.54
A11: ch_cfoo_0 | B11: 175065 | C11: 176646.38 | D11: 178215.6 | E11: 179909.34 | F11: 181755.53 | G11: 183742.79 | H11: 185849.61 | I11: 188055.15 | J11: 190342.38 | K11: 192698.21 | L11: 195112.91 | M11: 197579.31 | N11: 200092.24 | O11: 202648.04 | P11: 205244.23 | Q11: 207879.16 | R11: 210551.78 | S11: 213261.44 | T11: 216007.75 | U11: 218790.43 | V11: 221609.24 | W11: 224463.97 | X11: 227354.36 | Y11: 230280.16 | Z11: 233241.08 | AA11: 236236.84 | AB11: 239267.21 | AC11: 242331.96 | AD11: 245430.95 | AE11: 248564.07 | AF11: 251731.31 | AG11: 254932.73 | AH11: 258168.46 | AI11: 261438.72 | AJ11: 264743.79 | AK11: 268084.01
A12: pch_cfoo_2 | B12: 1 | C12: 1.0199635 | D12: 1.0402796 | E12: 1.0610001 | F12: 1.0821902 | G12: 1.1039157 | H12: 1.1262121 | I12: 1.1490838 | J12: 1.172536 | K12: 1.1965784 | L12: 1.2212286 | M12: 1.2465134 | N12: 1.2724678 | O12: 1.2991348 | P12: 1.3265636 | Q12: 1.3548092 | R12: 1.3839059 | S12: 1.4138598 | T12: 1.4446681 | U12: 1.4763228 | V12: 1.5088127 | W12: 1.542126 | X12: 1.5762509 | Y12: 1.6111762 | Z12: 1.6468915 | AA12: 1.6833871 | AB12: 1.7206539 | AC12: 1.7586839 | AD12: 1.7974697 | AE12: 1.8370048 | AF12: 1.8772839 | AG12: 1.9183026 | AH12: 1.9600579 | AI12: 2.0025481 | AJ12: 2.0457728 | AK12: 2.089733
... A105: pch_cbio_0 | B105: 1 | C105: 1.0194853 | D105: 1.0388851 | E105: 1.0584794 | F105: 1.0785234 | G105: 1.0991574 | H105: 1.1204202 | I105: 1.1422939 | J105: 1.1647423 | K105: 1.1877351 | L105: 1.2112565 | M105: 1.2353062 | N105: 1.2598952 | O105: 1.2850411 | P105: 1.3107638 | Q105: 1.337083 | R105: 1.3640167 | S105: 1.3915798 | T105: 1.4197853 | U105: 1.4486433 | V105: 1.4781629 | W105: 1.5083515 | X105: 1.5392164 | Y105: 1.5707642 | Z105: 1.6030015 | AA105: 1.635935 | AB105: 1.6695716 | AC105: 1.7039186 | AD105: 1.7389836 | AE105: 1.7747749 | AF105: 1.811301 | AG105: 1.8485712 | AH105: 1.8865955 | AI105: 1.9253844 | AJ105: 1.964949 | AK105: 2.0053012

Sheet Value_Added
A1: _date_ | B1: 42005 | C1: 42370 | D1: 42736 | E1: 43101 | F1: 43466 | G1: 43831 | H1: 44197 | I1: 44562 | J1: 44927 | K1: 45292 | L1: 45658 | M1: 46023 | N1: 46388 | O1: 46753 | P1: 47119 | Q1: 47484 | R1: 47849 | S1: 48214 | T1: 48580 | U1: 48945 | V1: 49310 | W1: 49675 | X1: 50041 | Y1: 50406 | Z1: 50771 | AA1: 51136 | AB1: 51502 | AC1: 51867 | AD1: 52232 | AE1: 52597 | AF1: 52963 | AG1: 53328 | AH1: 53693 | AI1: 54058 | AJ1: 54424 | AK1: 54789
A2: va_2 | B2: 1965592.2 | C2: 1986967.1 | D2: 2008406.1 | E2: 2030322.4 | F2: 2052845.9 | G2: 2076000.7 | H2: 2099741.3 | I2: 2123989.1 | J2: 2148684.2 | K2: 2173787.1 | L2: 2199276.1 | M2: 2225143.3 | N2: 2251388.9 | O2: 2278016.7 | P2: 2305030.9 | Q2: 2332434.1 | R2: 2360203.5 | S2: 2388297.5 | T2: 2416686.2 | U2: 2445351.5 | V2: 2474286 | W2: 2503490.7 | X2: 2532972.1 | Y2: 2562739.2 | Z2: 2592802 | AA2: 2623170.1 | AB2: 2653852.3 | AC2: 2684856.1 | AD2: 2716188.2 | AE2: 2747854.3 | AF2: 2779859.8 | AG2: 2812209.7 | AH2: 2844909.2 | AI2: 2877963.8 | AJ2: 2911379.5 | AK2: 2945162.6
A3: va_0 | B3: 1965592.2 | C3: 1986885.6 | D3: 2008191.4 | E3: 2029937.4 | F3: 2052257.8 | G3: 2075171.5 | H3: 2098653.7 | I3: 2122664 | J3: 2147158.9 | K3: 2172097.9 | L3: 2197445.8 | M3: 2223174.1 | N3: 2249260.8 | O3: 2275690.3 | P3: 2302452.2 | Q3: 2329540.4 | R3: 2356952 | S3: 2384686.5 | T3: 2412744.9 | U3: 2441129.2 | V3: 2469841.7 | W3: 2498885 | X3: 2528261.8 | Y3: 2557974.8 | Z3: 2588026.6 | AA3: 2618419.7 | AB3: 2649156.8 | AC3: 2680240.9 | AD3: 2711674.8 | AE3: 2743461.8 | AF3: 2775605.2 | AG3: 2808108.9 | AH3: 2840976.6 | AI3: 2874212.5 | AJ3: 2907821.1 | AK3: 2941806.7
A4: va_sagr_2 | B4: 30790.815 | C4: 31102.036 | D4: 31418.676 | E4: 31753.153 | F4: 32107.39 | G4: 32480.339 | H4: 32868.699 | I4: 33268.522 | J4: 33677.54 | K4: 34094.574 | L4: 34519.146 | M4: 34951.198 | N4: 35390.901 | O4: 35838.51 | P4: 36294.272 | Q4: 36758.36 | R4: 37229.697 | S4: 37706.468 | T4: 38187.665 | U4: 38672.753 | V4: 39161.5 | W4: 39653.871 | X4: 40149.946 | Y4: 40649.858 | Z4: 41153.766 | AA4: 41661.827 | AB4: 42174.188 | AC4: 42690.985 | AD4: 43212.343 | AE4: 43738.38 | AF4: 44269.21 | AG4: 44804.952 | AH4: 45345.729 | AI4: 45891.676 | AJ4: 46442.94 | AK4: 46999.679
A5: va_sagr_0 | B5: 30790.815 | C5: 31097.824 | D5: 31408.103 | E5: 31734.666 | F5: 32079.262 | G5: 32440.277 | H5: 32815.402 | I5: 33202.492 | J5: 33599.776 | K5: 34005.861 | L5: 34419.667 | M5: 34840.376 | N5: 35267.383 | O5: 35700.251 | P5: 36138.684 | Q5: 36582.491 | R5: 37031.564 | S5: 37485.852 | T5: 37945.343 | U5: 38410.05 | V5: 38880 | W5: 39355.225 | X5: 39835.764 | Y5: 40321.654 | Z5: 40812.934 | AA5: 41309.645 | AB5: 41811.83 | AC5: 42319.535 | AD5: 42832.812 | AE5: 43351.717 | AF5: 43876.312 | AG5: 44406.665 | AH5: 44942.85 | AI5: 45484.945 | AJ5: 46033.034 | AK5: 46587.204
A6: va_sfor_2 | B6: 5288.8126 | C6: 5297.7707 | D6: 5287.5755 | E6: 5270.8214 | F6: 5251.7328 | G6: 5231.1034 | H6: 5210.8971 | I6: 5193.3711 | J6: 5178.5243 | K6: 5165.5827 | L6: 5153.5858 | M6: 5141.6185 | N6: 5128.8967 | O6: 5114.7963 | P6: 5098.8603 | Q6: 5080.7971 | R6: 5061.6587 | S6: 5043.0698 | T6: 5025.6819 | U6: 5009.7296 | V6: 4995.2696 | W6: 4982.2874 | X6: 4970.7427 | Y6: 4960.5884 | Z6: 4951.7779 | AA6: 4944.2674 | AB6: 4938.017 | AC6: 4932.9902 | AD6: 4929.1537 | AE6: 4926.4778 | AF6: 4924.9353 | AG6: 4924.5021 | AH6: 4925.1562 | AI6: 4926.878 | AJ6: 4929.6501 | AK6: 4933.4567
A7: va_sfor_0 | B7: 5288.8126 | C7: 5304.0347 | D7: 5302.0192 | E7: 5294.5751 | F7: 5286.4854 | G7: 5279.4506 | H7: 5273.8914 | I7: 5269.7509 | J7: 5266.835 | K7: 5264.9431 | L7: 5263.9093 | M7: 5263.6084 | N7: 5263.9504 | O7: 5264.872 | P7: 5266.329 | Q7: 5268.2912 | R7: 5270.738 | S7: 5273.6553 | T7: 5277.0329 | U7: 5280.8561 | V7: 5285.1182 | W7: 5289.8172 | X7: 5294.9534 | Y7: 5300.5286 | Z7: 5306.5452 | AA7: 5313.0062 | AB7: 5319.9145 | AC7: 5327.2731 | AD7: 5335.0852 | AE7: 5343.3539 | AF7: 5352.0818 | AG7: 5361.2718 | AH7: 5370.9267 | AI7: 5381.049 | AJ7: 5391.6415 | AK7: 5402.7065
A8: va_sfoo_2 | B8: 43654.88 | C8: 44079.824 | D8: 44521.242 | E8: 44992.203 | F8: 45492.252 | G8: 46018.704 | H8: 46566.766 | I8: 47131.347 | J8: 47709.724 | K8: 48300.377 | L8: 48902.576 | M8: 49516.11 | N8: 50141.056 | O8: 50777.632 | P8: 51426.084 | Q8: 52086.614 | R8: 52757.754 | S8: 53437.193 | T8: 54123.817 | U8: 54816.998 | V8: 55516.44 | W8: 56222.071 | X8: 56933.954 | Y8: 57652.216 | Z8: 58377.007 | AA8: 59108.468 | AB8: 59846.722 | AC8: 60591.876 | AD8: 61344.015 | AE8: 62103.217 | AF8: 62869.561 | AG8: 63643.128 | AH8: 64424.017 | AI8: 65212.347 | AJ8: 66008.257 | AK8: 66811.914
A9: va_sfoo_0 | B9: 43654.88 | C9: 44074.319 | D9: 44508.113 | E9: 44969.764 | F9: 45458.475 | G9: 45970.837 | H9: 46503.401 | I9: 47053.24 | J9: 47617.99 | K9: 48195.765 | L9: 48785.077 | M9: 49384.768 | N9: 49993.956 | O9: 50611.993 | P9: 51238.424 | Q9: 51872.946 | R9: 52515.37 | S9: 53165.593 | T9: 53823.57 | U9: 54489.29 | V9: 55162.761 | W9: 55844.004 | X9: 56533.043 | Y9: 57229.907 | Z9: 57934.625 | AA9: 58647.231 | AB9: 59367.763 | AC9: 60096.266 | AD9: 60832.792 | AE9: 61577.404 | AF9: 62330.173 | AG9: 63091.181 | AH9: 63860.521 | AI9: 64638.292 | AJ9: 65424.606 | AK9: 66219.579
A10: va_sveh_2 | B10: 29847.895 | C10: 30404.705 | D10: 30932.64 | E10: 31408.754 | F10: 31841.632 | G10: 32244.379 | H10: 32630.584 | I10: 33010.088 | J10: 33386.587 | K10: 33761.671 | L10: 34136.059 | M10: 34510.043 | N10: 34883.691 | O10: 35256.944 | P10: 35629.658 | Q10: 36001.627 | R10: 36374.675 | S10: 36750.755 | T10: 37129.447 | U10: 37510.229 | V10: 37892.826 | W10: 38277.187 | X10: 38663.408 | Y10: 39051.677 | Z10: 39442.225 | AA10: 39835.305 | AB10: 40231.177 | AC10: 40630.099 | AD10: 41032.322 | AE10: 41438.093 | AF10: 41847.649 | AG10: 42261.223 | AH10: 42679.039 | AI10: 43101.312 | AJ10: 43528.248 | AK10: 43960.042
A11: va_sveh_0 | B11: 29847.895 | C11: 30410.564 | D11: 30943.516 | E11: 31424.184 | F11: 31862.492 | G11: 32272.71 | H11: 32666.675 | I11: 33052.509 | J11: 33435.21 | K11: 33817.628 | L11: 34201.287 | M11: 34586.961 | N11: 34975.033 | O11: 35365.692 | P11: 35759.05 | Q11: 36155.19 | R11: 36554.191 | S11: 36956.134 | T11: 37361.107 | U11: 37769.204 | V11: 38180.52 | W11: 38595.157 | X11: 39013.219 | Y11: 39434.812 | Z11: 39860.048 | AA11: 40289.04 | AB11: 40721.904 | AC11: 41158.757 | AD11: 41599.719 | AE11: 42044.908 | AF11: 42494.445 | AG11: 42948.446 | AH11: 43407.029 | AI11: 43870.308 | AJ11: 44338.393 | AK11: 44811.394
A12: va_sgla_2 | B12: 7902.1978 | C12: 7989.9612 | D12: 8077.8948 | E12: 8167.2693 | F12: 8258.725 | G12: 8352.5211 | H12: 8448.3884 | I12: 8545.8653 | J12: 8644.7552 | K12: 8745.006 | L12: 8846.6209 | M12: 8949.6088 | N12: 9053.9557 | O12: 9159.6058 | P12: 9266.4498 | Q12: 9374.3171 | R12: 9482.8874 | S12: 9591.8568 | T12: 9701.125 | U12: 9810.7156 | V12: 9920.7173 | W12: 10031.249 | X12: 10142.441 | Y12: 10254.419 | Z12: 10367.301 | AA12: 10481.197 | AB12: 10596.201 | AC12: 10712.396 | AD12: 10829.858 | AE12: 10948.651 | AF12: 11068.833 | AG12: 11190.456 | AH12: 11313.567 | AI12: 11438.211 | AJ12: 11564.43 | AK12: 11692.265
