Workbook
Name formatResults: [1]ResultsEXR10!$A$50

Sheet Carbontax
A1: _date_ | B1: 42005 | C1: 42370 | D1: 42736 | E1: 43101 | F1: 43466 | G1: 43831 | H1: 44197 | I1: 44562 | J1: 44927 | K1: 45292 | L1: 45658 | M1: 46023 | N1: 46388 | O1: 46753 | P1: 47119 | Q1: 47484 | R1: 47849 | S1: 48214 | T1: 48580 | U1: 48945 | V1: 49310 | W1: 49675 | X1: 50041 | Y1: 50406 | Z1: 50771 | AA1: 51136 | AB1: 51502 | AC1: 51867 | AD1: 52232 | AE1: 52597 | AF1: 52963 | AG1: 53328 | AH1: 53693 | AI1: 54058 | AJ1: 54424 | AK1: 54789
A2: t2val_ch_0 | B2: 1732.612 | C2: 2615.9682 | D2: 3567.279 | E2: 5115.5759 | F2: 5079.1745 | G2: 5103.7755 | H2: 5088.7002 | I2: 5092.551 | J2: 5104.2054 | K2: 5119.6797 | L2: 5139.079 | M2: 5158.9579 | N2: 5179.4906 | O2: 5200.7738 | P2: 5222.8373 | Q2: 5245.6711 | R2: 5269.128 | S2: 5293.0858 | T2: 5317.4671 | U2: 5342.2313 | V2: 5366.1609 | W2: 5390.9612 | X2: 5416.2398 | Y2: 5441.8279 | Z2: 5467.6651 | AA2: 5490.416 | AB2: 5512.7592 | AC2: 5534.1483 | AD2: 5554.4468 | AE2: 5573.7078 | AF2: 5592.0235 | AG2: 5609.8116 | AH2: 5627.3254 | AI2: 5644.6615 | AJ2: 5661.8296 | AK2: 5678.7958
A3: t2val_ch_2 | B3: 1732.612 | C3: 2615.9682 | D3: 3567.279 | E3: 5115.5759 | F3: 5079.1745 | G3: 5103.7755 | H3: 5088.7002 | I3: 7569.3917 | J3: 11232.675 | K3: 16626.621 | L3: 24553.672 | M3: 25943.06 | N3: 27525.443 | O3: 29261.495 | P3: 31132.872 | Q3: 33132.955 | R3: 36030.744 | S3: 39171.85 | T3: 42577.353 | U3: 46268.496 | V3: 50259.165 | W3: 53371.886 | X3: 56675.216 | Y3: 60176.658 | Z3: 63884.785 | AA3: 67769.06 | AB3: 70975.096 | AC3: 74304.815 | AD3: 77757.164 | AE3: 81333.863 | AF3: 85037.703 | AG3: 88175.325 | AH3: 91401.968 | AI3: 94718.504 | AJ3: 98124.613 | AK3: 101801.73
A4: t2val_sec_0 | B4: 3328.339 | C4: 5086.0564 | D4: 7054.7083 | E4: 10266.712 | F4: 10317.322 | G4: 10570.625 | H4: 10817.961 | I4: 11090.341 | J4: 11377.461 | K4: 11677.661 | L4: 11993.69 | M4: 12356.342 | N4: 12735.048 | O4: 13134.253 | P4: 13556.495 | Q4: 14003.657 | R4: 14461.317 | S4: 14946.603 | T4: 15461.335 | U4: 16006.121 | V4: 16580.456 | W4: 17170.369 | X4: 17788.902 | Y4: 18440.863 | Z4: 19129.968 | AA4: 19855.695 | AB4: 20346.596 | AC4: 20761.778 | AD4: 21161.291 | AE4: 21563.552 | AF4: 21973.051 | AG4: 22445.551 | AH4: 22943.686 | AI4: 23458.204 | AJ4: 23986.036 | AK4: 24525.729
A5: t2val_sec_2 | B5: 3328.339 | C5: 5086.0564 | D5: 7054.7083 | E5: 10266.712 | F5: 10317.322 | G5: 10570.625 | H5: 10817.961 | I5: 16482.564 | J5: 24994.223 | K5: 37711.025 | L5: 56623.026 | M5: 60740.82 | N5: 65481.389 | O5: 70904.953 | P5: 77048.047 | Q5: 83948.931 | R5: 93507.094 | S5: 104268.45 | T5: 116380.64 | U5: 130285.81 | V5: 145958.22 | W5: 159927.29 | X5: 175446.15 | Y5: 192713.42 | Z5: 211935.18 | AA5: 233293.15 | AB5: 250582.3 | AC5: 268194.86 | AD5: 286844 | AE5: 306794.65 | AF5: 328154.74 | AG5: 349115.54 | AH5: 371685.79 | AI5: 395780.87 | AJ5: 421401.23 | AK5: 436882.71
A6: t2val_ci_0 | B6: 3107.2095 | C6: 4745.8395 | D6: 6576.6065 | E6: 9558.8397 | F6: 9599.7992 | G6: 9840.4362 | H6: 10073.275 | I6: 10330.234 | J6: 10601.328 | K6: 10884.974 | L6: 11183.822 | M6: 11528.886 | N6: 11889.519 | O6: 12270.088 | P6: 12673.08 | Q6: 13100.338 | R6: 13538.176 | S6: 14003.218 | T6: 14497.141 | U6: 15020.477 | V6: 15572.723 | W6: 16140.569 | X6: 16736.531 | Y6: 17365.244 | Z6: 18030.32 | AA6: 18731.32 | AB6: 19201.48 | AC6: 19597.629 | AD6: 19978.969 | AE6: 20363.469 | AF6: 20755.365 | AG6: 21207.996 | AH6: 21685.297 | AI6: 22178.317 | AJ6: 22684.092 | AK6: 23201.225
A7: t2val_ci_2 | B7: 3107.2095 | C7: 4745.8395 | D7: 6576.6065 | E7: 9558.8397 | F7: 9599.7992 | G7: 9840.4362 | H7: 10073.275 | I7: 15347.6 | J7: 23264.727 | K7: 35076.698 | L7: 52611.943 | M7: 56411.066 | N7: 60805.749 | O7: 65852.021 | P7: 71583.309 | Q7: 78035.161 | R7: 86968.562 | S7: 97038.66 | T7: 108385.3 | U7: 121441.53 | V7: 136173.04 | W7: 149349.36 | X7: 164010.36 | Y7: 180347.27 | Z7: 198559.01 | AA7: 218821.88 | AB7: 235182.91 | AC7: 251836.64 | AD7: 269483.79 | AE7: 288381.23 | AF7: 308630.66 | AG7: 328544.47 | AH7: 349999.96 | AI7: 372913.66 | AJ7: 397284.21 | AK7: 411844.07
A8: t2val_y_0 | B8: 0.39940733 | C8: 0.61402327 | D8: 0.86245259 | E8: 1.2779238 | F8: 1.2979382 | G8: 1.3256723 | H8: 1.3570559 | I8: 1.3899691 | J8: 1.42405 | K8: 1.4593064 | L8: 1.4961536 | M8: 1.5338708 | N8: 1.5726651 | O8: 1.6125847 | P8: 1.6536551 | Q8: 1.6958998 | R8: 1.7371325 | S8: 1.7789729 | T8: 1.8215694 | U8: 1.8650131 | V8: 1.9091191 | W8: 1.952158 | X8: 1.9957285 | Y8: 2.0400009 | Z8: 2.0850911 | AA8: 2.1303202 | AB8: 2.1657651 | AC8: 2.1990519 | AD8: 2.2309505 | AE8: 2.2619533 | AF8: 2.2924594 | AG8: 2.3291372 | AH8: 2.3675359 | AI8: 2.4074213 | AJ8: 2.4486711 | AK8: 2.4911493
A9: t2val_y_2 | B9: 0.39940733 | C9: 0.61402327 | D9: 0.86245259 | E9: 1.2779238 | F9: 1.2979382 | G9: 1.3256723 | H9: 1.3570559 | I9: 2.0774205 | J9: 3.1823131 | K9: 4.878051 | L9: 7.4854706 | M9: 8.1317442 | N9: 8.8323143 | O9: 9.5968132 | P9: 10.431185 | Q9: 11.340456 | R9: 12.588035 | S9: 13.969563 | T9: 15.499567 | U9: 17.195955 | V9: 19.073631 | W9: 20.655085 | X9: 22.361292 | Y9: 24.20467 | Z9: 26.197195 | AA9: 28.341364 | AB9: 30.124594 | AC9: 31.976948 | AD9: 33.912893 | AE9: 35.943905 | AF9: 38.080927 | AG9: 40.119652 | AH9: 42.286947 | AI9: 44.586451 | AJ9: 47.023247 | AK9: 48.752627
A10: t2val_mat_0 | B10: 220.73011 | C10: 339.60287 | D10: 477.23928 | E10: 706.5943 | F10: 716.22479 | G10: 728.86362 | H10: 743.32846 | I10: 758.71717 | J10: 774.70902 | K10: 791.22737 | L10: 808.37269 | M10: 825.92163 | N10: 843.95679 | O10: 862.55245 | P10: 881.76126 | Q10: 901.623 | R10: 921.40365 | S10: 941.6057 | T10: 962.37312 | U10: 983.77919 | V10: 1005.8233 | W10: 1027.8479 | X10: 1050.3756 | Y10: 1073.5792 | Z10: 1097.5625 | AA10: 1122.2441 | AB10: 1142.9504 | AC10: 1161.9491 | AD10: 1180.0916 | AE10: 1197.8216 | AF10: 1215.3937 | AG10: 1235.2265 | AH10: 1256.0215 | AI10: 1277.4793 | AJ10: 1299.4955 | AK10: 1322.0129
A11: t2val_mat_2 | B11: 220.73011 | C11: 339.60287 | D11: 477.23928 | E11: 706.5943 | F11: 716.22479 | G11: 728.86362 | H11: 743.32846 | I11: 1132.8865 | J11: 1726.3136 | K11: 2629.4491 | L11: 4003.5976 | M11: 4321.6217 | N11: 4666.8071 | O11: 5043.3352 | P11: 5454.3065 | Q11: 5902.4296 | R11: 6525.9434 | S11: 7215.8197 | T11: 7979.8406 | U11: 8827.0896 | V11: 9766.1064 | W11: 10557.272 | X11: 11413.43 | Y11: 12341.95 | Z11: 13349.966 | AA11: 14442.931 | AB11: 15369.256 | AC11: 16326.247 | AD11: 17326.295 | AE11: 18377.469 | AF11: 19485.995 | AG11: 20530.955 | AH11: 21643.544 | AI11: 22822.623 | AJ11: 24069.997 | AK11: 24989.888

Sheet Production
A1: _date_ | B1: 42005 | C1: 42370 | D1: 42736 | E1: 43101 | F1: 43466 | G1: 43831 | H1: 44197 | I1: 44562 | J1: 44927 | K1: 45292 | L1: 45658 | M1: 46023 | N1: 46388 | O1: 46753 | P1: 47119 | Q1: 47484 | R1: 47849 | S1: 48214 | T1: 48580 | U1: 48945 | V1: 49310 | W1: 49675 | X1: 50041 | Y1: 50406 | Z1: 50771 | AA1: 51136 | AB1: 51502 | AC1: 51867 | AD1: 52232 | AE1: 52597 | AF1: 52963 | AG1: 53328 | AH1: 53693 | AI1: 54058 | AJ1: 54424 | AK1: 54789
A2: y_2 | B2: 3853313.2 | C2: 3912706 | D2: 3969876.1 | E2: 4024755.4 | F2: 4088145.3 | G2: 4171936.6 | H2: 4263906.9 | I2: 4360824.3 | J2: 4461076 | K2: 4565013.1 | L2: 4674461.5 | M2: 4781173.6 | N2: 4890805.7 | O2: 5004952.2 | P2: 5123593.1 | Q2: 5246404.6 | R2: 5368117.6 | S2: 5492305 | T2: 5619415 | U2: 5750622.7 | V2: 5885076.1 | W2: 6017792 | X2: 6153485 | Y2: 6293015 | Z2: 6436916.3 | AA2: 6583901.6 | AB2: 6695256.5 | AC2: 6797288.4 | AD2: 6895125 | AE2: 6991049.2 | AF2: 7086276.5 | AG2: 7197899.2 | AH2: 7314531 | AI2: 7435183.8 | AJ2: 7559355.3 | AK2: 7559353.5
A3: y_0 | B3: 3853313.2 | C3: 3912706 | D3: 3969876.1 | E3: 4024755.4 | F3: 4088145.3 | G3: 4171936.6 | H3: 4263906.9 | I3: 4359618.4 | J3: 4458308.3 | K3: 4560188.1 | L3: 4666440.2 | M3: 4774219.1 | N3: 4885003.3 | O3: 4999232.4 | P3: 5117103.2 | Q3: 5238762.4 | R3: 5358927.1 | S3: 5481621.1 | T3: 5607373.8 | U3: 5736558.1 | V3: 5868910.1 | W3: 5999989.6 | X3: 6134079.6 | Y3: 6271945.2 | Z3: 6414179.7 | AA3: 6559560.4 | AB3: 6669485 | AC3: 6770186.9 | AD3: 6866708.2 | AE3: 6961277.5 | AF3: 7055088.6 | AG3: 7165409.7 | AH3: 7280680.5 | AI3: 7399900.6 | AJ3: 7522622.6 | AK3: 7648512.4
A4: y_sagr_2 | B4: 81781.721 | C4: 82864.854 | D4: 83954.428 | E4: 85070.368 | F4: 86402.711 | G4: 88248.951 | H4: 90338.128 | I4: 92595.975 | J4: 94974.047 | K4: 97477.126 | L4: 100154.35 | M4: 102717.07 | N4: 105327.47 | O4: 108044.43 | P4: 110870.8 | Q4: 113794.76 | R4: 116674.3 | S4: 119598.47 | T4: 122571.03 | U4: 125608.81 | V4: 128692.33 | W4: 131684.09 | X4: 134707.01 | Y4: 137777.88 | Z4: 140903.6 | AA4: 144037.33 | AB4: 146493.83 | AC4: 148791.8 | AD4: 150990.86 | AE4: 153128.11 | AF4: 155231.91 | AG4: 157741.17 | AH4: 160364.66 | AI4: 163087.12 | AJ4: 165899.01 | AK4: 165898.95
A5: y_sagr_0 | B5: 81781.721 | C5: 82864.854 | D5: 83954.428 | E5: 85070.368 | F5: 86402.711 | G5: 88248.951 | H5: 90338.128 | I5: 92529.136 | J5: 94797.872 | K5: 97144.867 | L5: 99597.754 | M5: 102108.56 | N5: 104691.06 | O5: 107348.48 | P5: 110082.5 | Q5: 112894.7 | R5: 115639.53 | S5: 118424.81 | T5: 121260.42 | U5: 124152.44 | V5: 127088.54 | W5: 129953.6 | X5: 132854.06 | Y5: 135801.23 | Z5: 138802.85 | AA5: 141813.72 | AB5: 144173.26 | AC5: 146389.13 | AD5: 148512.59 | AE5: 150576.43 | AF5: 152607.2 | AG5: 155048.81 | AH5: 157604.98 | AI5: 160260.12 | AJ5: 163006.08 | AK5: 165833.82
A6: y_sfor_2 | B6: 6531.7299 | C6: 6471.6699 | D6: 6414.2951 | E6: 6352.2464 | F6: 6321.1321 | G6: 6312.5703 | H6: 6348.7268 | I6: 6364.7174 | J6: 6364.3128 | K6: 6349.7594 | L6: 6325.3963 | M6: 6361.02 | N6: 6428.9781 | O6: 6518.0724 | P6: 6622.3473 | Q6: 6739.3596 | R6: 6881.3153 | S6: 7037.6455 | T6: 7206.9837 | U6: 7389.5563 | V6: 7583.8257 | W6: 7787.4116 | X6: 8004.6625 | Y6: 8236.9784 | Z6: 8486.048 | AA6: 8748.8769 | AB6: 8842.7354 | AC6: 8889.9437 | AD6: 8928.8483 | AE6: 8970.0067 | AF6: 9015.322 | AG6: 9080.9683 | AH6: 9153.7639 | AI6: 9231.3991 | AJ6: 9312.8699 | AK6: 9312.7457
A7: y_sfor_0 | B7: 6531.7299 | C7: 6471.6699 | D7: 6414.2951 | E7: 6352.2464 | F7: 6321.1321 | G7: 6312.5703 | H7: 6348.7268 | I7: 6399.2089 | J7: 6458.8663 | K7: 6526.5421 | L7: 6605.0143 | M7: 6685.6809 | N7: 6771.9759 | O7: 6866.9722 | P7: 6971.9881 | Q7: 7087.9427 | R7: 7230.8427 | S7: 7389.0387 | T7: 7560.5856 | U7: 7745.3059 | V7: 7941.4866 | W7: 8147.2778 | X7: 8366.9599 | Y7: 8601.959 | Z7: 8854.0556 | AA7: 9120.0677 | AB7: 9214.8756 | AC7: 9261.199 | AD7: 9298.0476 | AE7: 9336.3971 | AF7: 9378.3678 | AG7: 9440.672 | AH7: 9509.6481 | AI7: 9582.8133 | AJ7: 9659.1426 | AK7: 9738.1991
A8: y_sfoo_2 | B8: 157757.79 | C8: 160031.53 | D8: 162244.69 | E8: 164513.46 | F8: 167179.37 | G8: 170803.28 | H8: 174784.15 | I8: 179103.98 | J8: 183677.79 | K8: 188533.26 | L8: 193791.51 | M8: 198723.72 | N8: 203709.39 | O8: 208867.45 | P8: 214204.15 | Q8: 219700.25 | R8: 225149.14 | S8: 230673.29 | T8: 236277.04 | U8: 242005.2 | V8: 247804.84 | W8: 253459.86 | X8: 259165.21 | Y8: 264949.42 | Z8: 270826.85 | AA8: 276691.04 | AB8: 281470.6 | AC8: 285938.96 | AD8: 290191.08 | AE8: 294303.16 | AF8: 298336.74 | AG8: 302991.16 | AH8: 307851.93 | AI8: 312906.93 | AJ8: 318138.25 | AK8: 318138.21
A9: y_sfoo_0 | B9: 157757.79 | C9: 160031.53 | D9: 162244.69 | E9: 164513.46 | F9: 167179.37 | G9: 170803.28 | H9: 174784.15 | I9: 178926.43 | J9: 183198.6 | K9: 187608.26 | L9: 192218.52 | M9: 196926.61 | N9: 201759.32 | O9: 206722.29 | P9: 211818.46 | Q9: 217050.84 | R9: 222191.11 | S9: 227399.51 | T9: 232690.11 | U9: 238074.92 | V9: 243525.16 | W9: 248881.16 | X9: 254298.19 | Y9: 259793.4 | Z9: 265382.42 | AA9: 270961.92 | AB9: 275520.12 | AC9: 279801.16 | AD9: 283880.48 | AE9: 287824.13 | AF9: 291689.11 | AG9: 296186.85 | AH9: 300891.14 | AI9: 305789.5 | AJ9: 310867.16 | AK9: 316104.64
A10: y_sveh_2 | B10: 125590.98 | C10: 129264.51 | D10: 132710.97 | E10: 135743.06 | F10: 139439.99 | G10: 144264.85 | H10: 148517.26 | I10: 152606.8 | J10: 156674.94 | K10: 160798.26 | L10: 165016.16 | M10: 169583.22 | N10: 174440.45 | O10: 179465.37 | P10: 184606.04 | Q10: 189854.03 | R10: 194682.17 | S10: 199588.04 | T10: 204610.02 | U10: 209744.08 | V10: 215006.12 | W10: 219944.43 | X10: 224995.11 | Y10: 230158.05 | Z10: 235433.62 | AA10: 240792.36 | AB10: 243878.08 | AC10: 246891.77 | AD10: 249898.22 | AE10: 252923.81 | AF10: 255980.44 | AG10: 260550.78 | AH10: 265271 | AI10: 270102.5 | AJ10: 275032.27 | AK10: 275032.21
A11: y_sveh_0 | B11: 125590.98 | C11: 129264.51 | D11: 132710.97 | E11: 135743.06 | F11: 139439.99 | G11: 144264.85 | H11: 148517.26 | I11: 152698.56 | J11: 156934.22 | K11: 161281.18 | L11: 165785.3 | M11: 170377.87 | N11: 175112.56 | O11: 179994.16 | P11: 185024.79 | Q11: 190206.93 | R11: 195026.46 | S11: 199953.98 | T11: 205005.85 | U11: 210190.35 | V11: 215501.7 | W11: 220461.57 | X11: 225524.75 | Y11: 230705.43 | Z11: 236010.23 | AA11: 241411 | AB11: 244541.84 | AC11: 247608.69 | AD11: 250677.1 | AE11: 253771.49 | AF11: 256901.22 | AG11: 261539.42 | AH11: 266324.86 | AI11: 271221.33 | AJ11: 276216.81 | AK11: 281306.77
A12: y_sgla_2 | B12: 22090.808 | C12: 22423.532 | D12: 22739.387 | E12: 23022.685 | F12: 23348.847 | G12: 23806.982 | H12: 24335.49 | I12: 24888.024 | J12: 25443.202 | K12: 25992.842 | L12: 26538.068 | M12: 27084.731 | N12: 27661.836 | O12: 28280.151 | P12: 28940.143 | Q12: 29638.772 | R12: 30336.083 | S12: 31055.07 | T12: 31797.682 | U12: 32569.135 | V12: 33366.655 | W12: 34160.223 | X12: 34979.338 | Y12: 35829.356 | Z12: 36713.537 | AA12: 37628.024 | AB12: 38357.943 | AC12: 39032.274 | AD12: 39676.663 | AE12: 40306.103 | AF12: 40929.327 | AG12: 41656.034 | AH12: 42414.172 | AI12: 43197.392 | AJ12: 44002.454 | AK12: 44002.406
... A67: y_seot_0 | B67: 109.60567 | C67: 110.5762 | D67: 111.04269 | E67: 111.41278 | F67: 111.98891 | G67: 113.20091 | H67: 115.73033 | I67: 119.06262 | J67: 122.70921 | K67: 126.59096 | L67: 130.7574 | M67: 135.64191 | N67: 140.57961 | O67: 145.86704 | P67: 151.58976 | Q67: 157.79219 | R67: 163.73257 | S67: 170.17575 | T67: 177.1992 | U67: 184.9351 | V67: 193.52184 | W67: 203.00727 | X67: 213.69682 | Y67: 225.84724 | Z67: 239.72962 | AA67: 255.57415 | AB67: 261.83088 | AC67: 264.80886 | AD67: 267.15077 | AE67: 269.57115 | AF67: 272.20373 | AG67: 275.59797 | AH67: 279.3564 | AI67: 283.32845 | AJ67: 287.44867 | AK67: 291.68791

Sheet Capital
A1: _date_ | B1: 42005 | C1: 42370 | D1: 42736 | E1: 43101 | F1: 43466 | G1: 43831 | H1: 44197 | I1: 44562 | J1: 44927 | K1: 45292 | L1: 45658 | M1: 46023 | N1: 46388 | O1: 46753 | P1: 47119 | Q1: 47484 | R1: 47849 | S1: 48214 | T1: 48580 | U1: 48945 | V1: 49310 | W1: 49675 | X1: 50041 | Y1: 50406 | Z1: 50771 | AA1: 51136 | AB1: 51502 | AC1: 51867 | AD1: 52232 | AE1: 52597 | AF1: 52963 | AG1: 53328 | AH1: 53693 | AI1: 54058 | AJ1: 54424 | AK1: 54789
A2: f_k_2 | B2: 5223356.6 | C2: 5284516.8 | D2: 5346672.5 | E2: 5408276.4 | F2: 5470776.1 | G2: 5538263.2 | H2: 5610936 | I2: 5688588.3 | J2: 5770561.2 | K2: 5856073.1 | L2: 5944430.8 | M2: 6035909.5 | N2: 6131056 | O2: 6230528 | P2: 6334926.3 | Q2: 6444738 | R2: 6559870.1 | S2: 6680353 | T2: 6806295.8 | U2: 6937856.9 | V2: 7075194.1 | W2: 7218151.5 | X2: 7366806.3 | Y2: 7521365.5 | Z2: 7682100.2 | AA2: 7849189.6 | AB2: 8019780.3 | AC2: 8192058.4 | AD2: 8365016.4 | AE2: 8538123.5 | AF2: 8711119.3 | AG2: 8885212.5 | AH2: 9061119.1 | AI2: 9239284.2 | AJ2: 9420016.1 | AK2: 9591419.1
A3: f_k_0 | B3: 5223356.6 | C3: 5284516.8 | D3: 5346672.5 | E3: 5408276.4 | F3: 5470776.1 | G3: 5538263.2 | H3: 5610936 | I3: 5689113.8 | J3: 5772827.9 | K3: 5862074.2 | L3: 5956965.9 | M3: 6057471.7 | N3: 6163606.9 | O3: 6275447.8 | P3: 6393111.7 | Q3: 6516742.8 | R3: 6646081.9 | S3: 6781084.5 | T3: 6921828 | U3: 7068456.7 | V3: 7221108.1 | W3: 7379556.6 | X3: 7543817.3 | Y3: 7714049.9 | Z3: 7890501.9 | AA3: 8073340.2 | AB3: 8259602.1 | AC3: 8447412.6 | AD3: 8635742.4 | AE3: 8824063.6 | AF3: 9012131.8 | AG3: 9201193.4 | AH3: 9391971.5 | AI3: 9584902.6 | AJ3: 9780286.2 | AK3: 9978349.5
A4: f_k_sagr_2 | B4: 47210.231 | C4: 47758.923 | D4: 48311.58 | E4: 48860.241 | F4: 49420.185 | G4: 50030.867 | H4: 50697.565 | I4: 51423.148 | J4: 52206.101 | K4: 53043.828 | L4: 53935.194 | M4: 54879.384 | N4: 55878.062 | O4: 56935.165 | P4: 58054.767 | Q4: 59240.027 | R4: 60487.805 | S4: 61796.4 | T4: 63164.751 | U4: 64592.432 | V4: 66078.555 | W4: 67617.895 | X4: 69208.047 | Y4: 70848.074 | Z4: 72537.618 | AA4: 74274.646 | AB4: 76032.515 | AC4: 77796.316 | AD4: 79557.621 | AE4: 81311.462 | AF4: 83055.005 | AG4: 84802.289 | AH4: 86561.246 | AI4: 88336.913 | AJ4: 90132.962 | AK4: 91834.34
A5: f_k_sagr_0 | B5: 47210.231 | C5: 47758.923 | D5: 48311.58 | E5: 48860.241 | F5: 49420.185 | G5: 50030.867 | H5: 50697.565 | I5: 51425.216 | J5: 52215.028 | K5: 53067.419 | L5: 53983.791 | M5: 54964.123 | N5: 56008.555 | O5: 57117.414 | P5: 58291.127 | Q5: 59530.176 | R5: 60829.856 | S5: 62187.888 | T5: 63603.212 | U5: 65075.346 | V5: 66603.457 | W5: 68182.425 | X5: 69809.833 | Y5: 71484.609 | Z5: 73206.329 | AA5: 74972.955 | AB5: 76757.872 | AC5: 78546.692 | AD5: 80331.509 | AE5: 82107.784 | AF5: 83873.055 | AG5: 85641.982 | AH5: 87422.754 | AI5: 89220.522 | AJ5: 91039.102 | AK5: 92881.509
A6: f_k_sfor_2 | B6: 1844.3596 | C6: 1862.9368 | D6: 1878.0952 | E6: 1889.0726 | F6: 1897.012 | G6: 1903.8069 | H6: 1909.9698 | I6: 1915.1641 | J6: 1918.771 | K6: 1920.1725 | L6: 1918.8639 | M6: 1916.2022 | N6: 1913.3473 | O6: 1911.1252 | P6: 1910.1044 | Q6: 1910.6956 | R6: 1913.3912 | S6: 1918.5374 | T6: 1926.3985 | U6: 1937.1995 | V6: 1951.124 | W6: 1968.3433 | X6: 1989.0662 | Y6: 2013.5226 | Z6: 2041.9633 | AA6: 2074.5869 | AB6: 2108.739 | AC6: 2142.8078 | AD6: 2176.1872 | AE6: 2208.7647 | AF6: 2240.6071 | AG6: 2272.0944 | AH6: 2303.4692 | AI6: 2334.8819 | AJ6: 2366.434 | AK6: 2396.3514
A7: f_k_sfor_0 | B7: 1844.3596 | C7: 1862.9368 | D7: 1878.0952 | E7: 1889.0726 | F7: 1897.012 | G7: 1903.8069 | H7: 1909.9698 | I7: 1916.0534 | J7: 1922.3459 | K7: 1929.0489 | L7: 1936.3928 | M7: 1944.4666 | N7: 1953.378 | O7: 1963.2924 | P7: 1974.4104 | Q7: 1986.9532 | R7: 2001.4157 | S7: 2018.1719 | T7: 2037.5125 | U7: 2059.6904 | V7: 2084.9088 | W7: 2113.3221 | X7: 2145.1377 | Y7: 2180.5973 | Z7: 2219.9748 | AA7: 2263.4893 | AB7: 2308.2106 | AC7: 2352.3444 | AD7: 2395.208 | AE7: 2436.6722 | AF7: 2476.8148 | AG7: 2516.0475 | AH7: 2554.6294 | AI7: 2592.7176 | AJ7: 2630.4181 | AK7: 2667.8136
A8: f_k_sfoo_2 | B8: 74516.296 | C8: 75380.546 | D8: 76245.432 | E8: 77097.683 | F8: 77967.119 | G8: 78919.202 | H8: 79956.673 | I8: 81080.568 | J8: 82285.343 | K8: 83564.155 | L8: 84912.794 | M8: 86330.893 | N8: 87822.296 | O8: 89394.204 | P8: 91053.572 | Q8: 92805.593 | R8: 94646.924 | S8: 96575.56 | T8: 98590.113 | U8: 100690.38 | V8: 102875.13 | W8: 105138.33 | X8: 107477.41 | Y8: 109891.62 | Z8: 112380.85 | AA8: 114941.85 | AB8: 117541.42 | AC8: 120160 | AD8: 122785.75 | AE8: 125411.35 | AF8: 128032.55 | AG8: 130666.39 | AH8: 133323.33 | AI8: 136010.73 | AJ8: 138734.26 | AK8: 141315.64
A9: f_k_sfoo_0 | B9: 74516.296 | C9: 75380.546 | D9: 76245.432 | E9: 77097.683 | F9: 77967.119 | G9: 78919.202 | H9: 79956.673 | I9: 81084.988 | J9: 82304.365 | K9: 83614.42 | L9: 85016.961 | M9: 86511.437 | N9: 88097.672 | O9: 89775.852 | P9: 91546.371 | Q9: 93409.754 | R9: 95360.103 | S9: 97394.478 | T9: 99511.43 | U9: 101710.29 | V9: 103989.66 | W9: 106343.33 | X9: 108768.44 | Y9: 111263.73 | Z9: 113828.78 | AA9: 116460.1 | AB9: 119124.25 | AC9: 121802.28 | AD9: 124483 | AE9: 127159.6 | AF9: 129828.3 | AG9: 132507 | AH9: 135206.42 | AI9: 137934.02 | AJ9: 140695.67 | AK9: 143496.1
A10: f_k_sveh_2 | B10: 401516.46 | C10: 406575.73 | D10: 412173.26 | E10: 418188.34 | F10: 424751.47 | G10: 432188.8 | H10: 440398.75 | I10: 449272.21 | J10: 458722.59 | K10: 468688.5 | L10: 479125.39 | M10: 490099.35 | N10: 501680.89 | O10: 513910.99 | P10: 526805.92 | Q10: 540369.36 | R10: 554488.29 | S10: 569117.54 | T10: 584243.41 | U10: 599860.31 | V10: 615968.53 | W10: 632479.25 | X10: 649366.43 | Y10: 666624.87 | Z10: 684255 | AA10: 702251.87 | AB10: 720115.27 | AC10: 737665.57 | AD10: 754849.15 | AE10: 771657.73 | AF10: 788099.88 | AG10: 804504.24 | AH10: 820999.96 | AI10: 837638.9 | AJ10: 854445.65 | AK10: 870309.58
A11: f_k_sveh_0 | B11: 401516.46 | C11: 406575.73 | D11: 412173.26 | E11: 418188.34 | F11: 424751.47 | G11: 432188.8 | H11: 440398.75 | I11: 449312.62 | J11: 458889.49 | K11: 469111.44 | L11: 479978.65 | M11: 491482.86 | N11: 503624.56 | O11: 516407.85 | P11: 529837.94 | Q11: 543920.36 | R11: 558554.13 | S11: 573703.98 | T11: 589360.68 | U11: 605524.47 | V11: 622196.57 | W11: 639277.58 | X11: 656734.26 | Y11: 674559.07 | Z11: 692753.45 | AA11: 711314.61 | AB11: 729734.96 | AC11: 747834.11 | AD11: 765560.87 | AE11: 782910.22 | AF11: 799893.73 | AG11: 816844.01 | AH11: 833890.74 | AI11: 851085.67 | AJ11: 868453.42 | AK11: 886009.08
A12: f_k_sgla_2 | B12: 16080.628 | C12: 16265.327 | D12: 16450.515 | E12: 16632.22 | F12: 16815.306 | G12: 17012.677 | H12: 17226.436 | I12: 17456.184 | J12: 17699.289 | K12: 17952.155 | L12: 18211.041 | M12: 18477.243 | N12: 18753.224 | O12: 19041.946 | P12: 19346.225 | Q12: 19668.449 | R12: 20008.659 | S12: 20367.26 | T12: 20744.852 | U12: 21142.254 | V12: 21560.224 | W12: 21998.519 | X12: 22457.712 | Y12: 22938.811 | Z12: 23443.021 | AA12: 23971.356 | AB12: 24515.536 | AC12: 25070.178 | AD12: 25632.14 | AE12: 26199.656 | AF12: 26771.76 | AG12: 27352.727 | AH12: 27944.969 | AI12: 28549.878 | AJ12: 29168.333 | AK12: 29758.135
... A67: f_k_seot_0 | B67: 65.167563 | C67: 65.909608 | D67: 66.627414 | E67: 67.307164 | F67: 67.958237 | G67: 68.612931 | H67: 69.320547 | I67: 70.125007 | J67: 71.047373 | K67: 72.098366 | L67: 73.287308 | M67: 74.639551 | N67: 76.160003 | O67: 77.857679 | P67: 79.745994 | Q67: 81.841046 | R67: 84.131611 | S67: 86.62643 | T67: 89.343617 | U67: 92.308713 | V67: 95.5542 | W67: 99.116085 | X67: 103.04261 | Y67: 107.39513 | Z67: 112.24878 | AA67: 117.69081 | AB67: 123.35009 | AC67: 128.95549 | AD67: 134.38849 | AE67: 139.6135 | AF67: 144.62836 | AG67: 149.4644 | AH67: 154.14672 | AI67: 158.6919 | AJ67: 163.1113 | AK67: 167.41361

Sheet Results
A1: NB : on crée ici une liste : - globale, qui fusionne les sorties des reportings 1, 2 et 3 - "rationalisée" : suppression des doublons, et regroupements par thématique On continue par la suite à avoir 2 Excels de reporting (un "energie", fusion des reportings 1 et 2), et un "économie" (reporting 3)), dans lesquels on copiera cet onglet "results" (généré automatiquement par EViews). --> puis voir à la fin si on peut pas importer les graphs et tableaux dans l'excel automatiquement généré (éviterait les copiés collés, mais à voir si ça prend trop de temps, et si c'est pas trop gros comme excel)
A2: Nom du bloc de variables utilisé dans le code | B2: Sous-bloc de variables pour plus de lisibilité dans le Excel | E2: Year | F2: =date!B3 -> 2015 | G2: =date!C3 -> 2016 | H2: =date!D3 -> 2017 | I2: =date!E3 -> 2018 | J2: =date!F3 -> 2019 | K2: =date!G3 -> 2020 | L2: =date!H3 -> 2021 | M2: =date!I3 -> 2022 | ... AO2: =date!AK3 -> 2050
A3: HYBRID | B3: AUTOMOBILES (thousands) | C3: TOTAL STOCK SHOCK | E3: AUTO_2 | F3: =VLOOKUP($E3,Hybrid!$1:$1048576,MATCH(DATE(F$2,1,1),Hybrid!$A$1:$LI$1),FALSE) -> 32317.941 | G3: =VLOOKUP($E3,Hybrid!$1:$1048576,MATCH(DATE(G$2,1,1),Hybrid!$A$1:$LI$1),FALSE) -> 31989.266 | H3: =VLOOKUP($E3,Hybrid!$1:$1048576,MATCH(DATE(H$2,1,1),Hybrid!$A$1:$LI$1),FALSE) -> 31766.848 | I3: =VLOOKUP($E3,Hybrid!$1:$1048576,MATCH(DATE(I$2,1,1),Hybrid!$A$1:$LI$1),FALSE) -> 31556.566 | J3: =VLOOKUP($E3,Hybrid!$1:$1048576,MATCH(DATE(J$2,1,1),Hybrid!$A$1:$LI$1),FALSE) -> 31558.174 | K3: =VLOOKUP($E3,Hybrid!$1:$1048576,MATCH(DATE(K$2,1,1),Hybrid!$A$1:$LI$1),FALSE) -> 31942.005 | L3: =VLOOKUP($E3,Hybrid!$1:$1048576,MATCH(DATE(L$2,1,1),Hybrid!$A$1:$LI$1),FALSE) -> 32251.021 | M3: =VLOOKUP($E3,Hybrid!$1:$1048576,MATCH(DATE(M$2,1,1),Hybrid!$A$1:$LI$1),FALSE) -> 32560.604 | ... AO3: =VLOOKUP($E3,Hybrid!$1:$1048576,MATCH(DATE(AO$2,1,1),Hybrid!$A$1:$LI$1),FALSE) -> 44134.237
C4: OIL | E4: AUTO_cfut_2 | F4: =VLOOKUP($E4,Hybrid!$1:$1048576,MATCH(DATE(F$2,1,1),Hybrid!$A$1:$LI$1),FALSE) -> 32271.24 | G4: =VLOOKUP($E4,Hybrid!$1:$1048576,MATCH(DATE(G$2,1,1),Hybrid!$A$1:$LI$1),FALSE) -> 31924.248 | H4: =VLOOKUP($E4,Hybrid!$1:$1048576,MATCH(DATE(H$2,1,1),Hybrid!$A$1:$LI$1),FALSE) -> 31683.81 | I4: =VLOOKUP($E4,Hybrid!$1:$1048576,MATCH(DATE(I$2,1,1),Hybrid!$A$1:$LI$1),FALSE) -> 31454.989 | J4: =VLOOKUP($E4,Hybrid!$1:$1048576,MATCH(DATE(J$2,1,1),Hybrid!$A$1:$LI$1),FALSE) -> 31432.993 | K4: =VLOOKUP($E4,Hybrid!$1:$1048576,MATCH(DATE(K$2,1,1),Hybrid!$A$1:$LI$1),FALSE) -> 31788.805 | L4: =VLOOKUP($E4,Hybrid!$1:$1048576,MATCH(DATE(L$2,1,1),Hybrid!$A$1:$LI$1),FALSE) -> 32071.448 | M4: =VLOOKUP($E4,Hybrid!$1:$1048576,MATCH(DATE(M$2,1,1),Hybrid!$A$1:$LI$1),FALSE) -> 32354.504 | ... AO4: =VLOOKUP($E4,Hybrid!$1:$1048576,MATCH(DATE(AO$2,1,1),Hybrid!$A$1:$LI$1),FALSE) -> 39550.518
D5: class A | E5: AUTO_ca_cfut_2 | F5: =VLOOKUP($E5,Hybrid!$1:$1048576,MATCH(DATE(F$2,1,1),Hybrid!$A$1:$LI$1),FALSE) -> 7095.7005 | G5: =VLOOKUP($E5,Hybrid!$1:$1048576,MATCH(DATE(G$2,1,1),Hybrid!$A$1:$LI$1),FALSE) -> 7159.6915 | H5: =VLOOKUP($E5,Hybrid!$1:$1048576,MATCH(DATE(H$2,1,1),Hybrid!$A$1:$LI$1),FALSE) -> 7248.7731 | I5: =VLOOKUP($E5,Hybrid!$1:$1048576,MATCH(DATE(I$2,1,1),Hybrid!$A$1:$LI$1),FALSE) -> 7341.6733 | J5: =VLOOKUP($E5,Hybrid!$1:$1048576,MATCH(DATE(J$2,1,1),Hybrid!$A$1:$LI$1),FALSE) -> 7498.2843 | K5: =VLOOKUP($E5,Hybrid!$1:$1048576,MATCH(DATE(K$2,1,1),Hybrid!$A$1:$LI$1),FALSE) -> 7766.7593 | L5: =VLOOKUP($E5,Hybrid!$1:$1048576,MATCH(DATE(L$2,1,1),Hybrid!$A$1:$LI$1),FALSE) -> 8009.8192 | M5: =VLOOKUP($E5,Hybrid!$1:$1048576,MATCH(DATE(M$2,1,1),Hybrid!$A$1:$LI$1),FALSE) -> 8254.162 | ... AO5: =VLOOKUP($E5,Hybrid!$1:$1048576,MATCH(DATE(AO$2,1,1),Hybrid!$A$1:$LI$1),FALSE) -> 20603.905
D6: class B | E6: AUTO_cb_cfut_2 | F6: =VLOOKUP($E6,Hybrid!$1:$1048576,MATCH(DATE(F$2,1,1),Hybrid!$A$1:$LI$1),FALSE) -> 8251.2564 | G6: =VLOOKUP($E6,Hybrid!$1:$1048576,MATCH(DATE(G$2,1,1),Hybrid!$A$1:$LI$1),FALSE) -> 8200.0167 | H6: =VLOOKUP($E6,Hybrid!$1:$1048576,MATCH(DATE(H$2,1,1),Hybrid!$A$1:$LI$1),FALSE) -> 8180.1563 | I6: =VLOOKUP($E6,Hybrid!$1:$1048576,MATCH(DATE(I$2,1,1),Hybrid!$A$1:$LI$1),FALSE) -> 8168.7824 | J6: =VLOOKUP($E6,Hybrid!$1:$1048576,MATCH(DATE(J$2,1,1),Hybrid!$A$1:$LI$1),FALSE) -> 8221.3545 | K6: =VLOOKUP($E6,Hybrid!$1:$1048576,MATCH(DATE(K$2,1,1),Hybrid!$A$1:$LI$1),FALSE) -> 8384.8744 | L6: =VLOOKUP($E6,Hybrid!$1:$1048576,MATCH(DATE(L$2,1,1),Hybrid!$A$1:$LI$1),FALSE) -> 8529.766 | M6: =VLOOKUP($E6,Hybrid!$1:$1048576,MATCH(DATE(M$2,1,1),Hybrid!$A$1:$LI$1),FALSE) -> 8678.75 | ... AO6: =VLOOKUP($E6,Hybrid!$1:$1048576,MATCH(DATE(AO$2,1,1),Hybrid!$A$1:$LI$1),FALSE) -> 11614.849
D7: class C | E7: AUTO_cc_cfut_2 | F7: =VLOOKUP($E7,Hybrid!$1:$1048576,MATCH(DATE(F$2,1,1),Hybrid!$A$1:$LI$1),FALSE) -> 6777.6025 | G7: =VLOOKUP($E7,Hybrid!$1:$1048576,MATCH(DATE(G$2,1,1),Hybrid!$A$1:$LI$1),FALSE) -> 6658.6926 | H7: =VLOOKUP($E7,Hybrid!$1:$1048576,MATCH(DATE(H$2,1,1),Hybrid!$A$1:$LI$1),FALSE) -> 6566.988 | I7: =VLOOKUP($E7,Hybrid!$1:$1048576,MATCH(DATE(I$2,1,1),Hybrid!$A$1:$LI$1),FALSE) -> 6484.9391 | J7: =VLOOKUP($E7,Hybrid!$1:$1048576,MATCH(DATE(J$2,1,1),Hybrid!$A$1:$LI$1),FALSE) -> 6449.5485 | K7: =VLOOKUP($E7,Hybrid!$1:$1048576,MATCH(DATE(K$2,1,1),Hybrid!$A$1:$LI$1),FALSE) -> 6493.8251 | L7: =VLOOKUP($E7,Hybrid!$1:$1048576,MATCH(DATE(L$2,1,1),Hybrid!$A$1:$LI$1),FALSE) -> 6529.5432 | M7: =VLOOKUP($E7,Hybrid!$1:$1048576,MATCH(DATE(M$2,1,1),Hybrid!$A$1:$LI$1),FALSE) -> 6570.4856 | ... AO7: =VLOOKUP($E7,Hybrid!$1:$1048576,MATCH(DATE(AO$2,1,1),Hybrid!$A$1:$LI$1),FALSE) -> 5357.1708
D8: class D | E8: AUTO_cd_cfut_2 | F8: =VLOOKUP($E8,Hybrid!$1:$1048576,MATCH(DATE(F$2,1,1),Hybrid!$A$1:$LI$1),FALSE) -> 4159.6639 | G8: =VLOOKUP($E8,Hybrid!$1:$1048576,MATCH(DATE(G$2,1,1),Hybrid!$A$1:$LI$1),FALSE) -> 4061.0488 | H8: =VLOOKUP($E8,Hybrid!$1:$1048576,MATCH(DATE(H$2,1,1),Hybrid!$A$1:$LI$1),FALSE) -> 3977.3705 | I8: =VLOOKUP($E8,Hybrid!$1:$1048576,MATCH(DATE(I$2,1,1),Hybrid!$A$1:$LI$1),FALSE) -> 3897.1966 | J8: =VLOOKUP($E8,Hybrid!$1:$1048576,MATCH(DATE(J$2,1,1),Hybrid!$A$1:$LI$1),FALSE) -> 3839.5055 | K8: =VLOOKUP($E8,Hybrid!$1:$1048576,MATCH(DATE(K$2,1,1),Hybrid!$A$1:$LI$1),FALSE) -> 3822.0886 | L8: =VLOOKUP($E8,Hybrid!$1:$1048576,MATCH(DATE(L$2,1,1),Hybrid!$A$1:$LI$1),FALSE) -> 3799.3302 | M8: =VLOOKUP($E8,Hybrid!$1:$1048576,MATCH(DATE(M$2,1,1),Hybrid!$A$1:$LI$1),FALSE) -> 3776.8536 | ... AO8: =VLOOKUP($E8,Hybrid!$1:$1048576,MATCH(DATE(AO$2,1,1),Hybrid!$A$1:$LI$1),FALSE) -> 1140.7951
D9: class E | E9: AUTO_ce_cfut_2 | F9: =VLOOKUP($E9,Hybrid!$1:$1048576,MATCH(DATE(F$2,1,1),Hybrid!$A$1:$LI$1),FALSE) -> 2503.7292 | G9: =VLOOKUP($E9,Hybrid!$1:$1048576,MATCH(DATE(G$2,1,1),Hybrid!$A$1:$LI$1),FALSE) -> 2446.6199 | H9: =VLOOKUP($E9,Hybrid!$1:$1048576,MATCH(DATE(H$2,1,1),Hybrid!$A$1:$LI$1),FALSE) -> 2396.9821 | I9: =VLOOKUP($E9,Hybrid!$1:$1048576,MATCH(DATE(I$2,1,1),Hybrid!$A$1:$LI$1),FALSE) -> 2346.9867 | J9: =VLOOKUP($E9,Hybrid!$1:$1048576,MATCH(DATE(J$2,1,1),Hybrid!$A$1:$LI$1),FALSE) -> 2307.6163 | K9: =VLOOKUP($E9,Hybrid!$1:$1048576,MATCH(DATE(K$2,1,1),Hybrid!$A$1:$LI$1),FALSE) -> 2289.8168 | L9: =VLOOKUP($E9,Hybrid!$1:$1048576,MATCH(DATE(L$2,1,1),Hybrid!$A$1:$LI$1),FALSE) -> 2267.4709 | M9: =VLOOKUP($E9,Hybrid!$1:$1048576,MATCH(DATE(M$2,1,1),Hybrid!$A$1:$LI$1),FALSE) -> 2243.2053 | ... AO9: =VLOOKUP($E9,Hybrid!$1:$1048576,MATCH(DATE(AO$2,1,1),Hybrid!$A$1:$LI$1),FALSE) -> 476.7991
D10: class F | E10: AUTO_cf_cfut_2 | F10: =VLOOKUP($E10,Hybrid!$1:$1048576,MATCH(DATE(F$2,1,1),Hybrid!$A$1:$LI$1),FALSE) -> 1243.6668 | G10: =VLOOKUP($E10,Hybrid!$1:$1048576,MATCH(DATE(G$2,1,1),Hybrid!$A$1:$LI$1),FALSE) -> 1212.2229 | H10: =VLOOKUP($E10,Hybrid!$1:$1048576,MATCH(DATE(H$2,1,1),Hybrid!$A$1:$LI$1),FALSE) -> 1182.327 | I10: =VLOOKUP($E10,Hybrid!$1:$1048576,MATCH(DATE(I$2,1,1),Hybrid!$A$1:$LI$1),FALSE) -> 1149.3589 | J10: =VLOOKUP($E10,Hybrid!$1:$1048576,MATCH(DATE(J$2,1,1),Hybrid!$A$1:$LI$1),FALSE) -> 1117.9241 | K10: =VLOOKUP($E10,Hybrid!$1:$1048576,MATCH(DATE(K$2,1,1),Hybrid!$A$1:$LI$1),FALSE) -> 1092.9672 | L10: =VLOOKUP($E10,Hybrid!$1:$1048576,MATCH(DATE(L$2,1,1),Hybrid!$A$1:$LI$1),FALSE) -> 1064.6737 | M10: =VLOOKUP($E10,Hybrid!$1:$1048576,MATCH(DATE(M$2,1,1),Hybrid!$A$1:$LI$1),FALSE) -> 1033.7777 | ... AO10: =VLOOKUP($E10,Hybrid!$1:$1048576,MATCH(DATE(AO$2,1,1),Hybrid!$A$1:$LI$1),FALSE) -> 140.51472
D11: class G | E11: AUTO_cg_cfut_2 | F11: =VLOOKUP($E11,Hybrid!$1:$1048576,MATCH(DATE(F$2,1,1),Hybrid!$A$1:$LI$1),FALSE) -> 2239.6206 | G11: =VLOOKUP($E11,Hybrid!$1:$1048576,MATCH(DATE(G$2,1,1),Hybrid!$A$1:$LI$1),FALSE) -> 2185.9552 | H11: =VLOOKUP($E11,Hybrid!$1:$1048576,MATCH(DATE(H$2,1,1),Hybrid!$A$1:$LI$1),FALSE) -> 2131.2134 | I11: =VLOOKUP($E11,Hybrid!$1:$1048576,MATCH(DATE(I$2,1,1),Hybrid!$A$1:$LI$1),FALSE) -> 2066.0517 | J11: =VLOOKUP($E11,Hybrid!$1:$1048576,MATCH(DATE(J$2,1,1),Hybrid!$A$1:$LI$1),FALSE) -> 1998.7596 | K11: =VLOOKUP($E11,Hybrid!$1:$1048576,MATCH(DATE(K$2,1,1),Hybrid!$A$1:$LI$1),FALSE) -> 1938.4737 | L11: =VLOOKUP($E11,Hybrid!$1:$1048576,MATCH(DATE(L$2,1,1),Hybrid!$A$1:$LI$1),FALSE) -> 1870.8443 | M11: =VLOOKUP($E11,Hybrid!$1:$1048576,MATCH(DATE(M$2,1,1),Hybrid!$A$1:$LI$1),FALSE) -> 1797.2695 | ... AO11: =VLOOKUP($E11,Hybrid!$1:$1048576,MATCH(DATE(AO$2,1,1),Hybrid!$A$1:$LI$1),FALSE) -> 216.48413
C12: ELEC | E12: AUTO_cele_2 | F12: =VLOOKUP($E12,Hybrid!$1:$1048576,MATCH(DATE(F$2,1,1),Hybrid!$A$1:$LI$1),FALSE) -> 44.765 | G12: =VLOOKUP($E12,Hybrid!$1:$1048576,MATCH(DATE(G$2,1,1),Hybrid!$A$1:$LI$1),FALSE) -> 63.021127 | H12: =VLOOKUP($E12,Hybrid!$1:$1048576,MATCH(DATE(H$2,1,1),Hybrid!$A$1:$LI$1),FALSE) -> 80.977049 | I12: =VLOOKUP($E12,Hybrid!$1:$1048576,MATCH(DATE(I$2,1,1),Hybrid!$A$1:$LI$1),FALSE) -> 99.457266 | J12: =VLOOKUP($E12,Hybrid!$1:$1048576,MATCH(DATE(J$2,1,1),Hybrid!$A$1:$LI$1),FALSE) -> 122.9902 | K12: =VLOOKUP($E12,Hybrid!$1:$1048576,MATCH(DATE(K$2,1,1),Hybrid!$A$1:$LI$1),FALSE) -> 150.91049 | L12: =VLOOKUP($E12,Hybrid!$1:$1048576,MATCH(DATE(L$2,1,1),Hybrid!$A$1:$LI$1),FALSE) -> 177.19542 | M12: =VLOOKUP($E12,Hybrid!$1:$1048576,MATCH(DATE(M$2,1,1),Hybrid!$A$1:$LI$1),FALSE) -> 203.63756 | ... AO12: =VLOOKUP($E12,Hybrid!$1:$1048576,MATCH(DATE(AO$2,1,1),Hybrid!$A$1:$LI$1),FALSE) -> 4798.8813
D13: class A | E13: AUTO_ca_cele_2 | F13: =VLOOKUP($E13,Hybrid!$1:$1048576,MATCH(DATE(F$2,1,1),Hybrid!$A$1:$LI$1),FALSE) -> 9.8427899 | G13: =VLOOKUP($E13,Hybrid!$1:$1048576,MATCH(DATE(G$2,1,1),Hybrid!$A$1:$LI$1),FALSE) -> 15.157168 | H13: =VLOOKUP($E13,Hybrid!$1:$1048576,MATCH(DATE(H$2,1,1),Hybrid!$A$1:$LI$1),FALSE) -> 20.444627 | I13: =VLOOKUP($E13,Hybrid!$1:$1048576,MATCH(DATE(I$2,1,1),Hybrid!$A$1:$LI$1),FALSE) -> 26.028391 | J13: =VLOOKUP($E13,Hybrid!$1:$1048576,MATCH(DATE(J$2,1,1),Hybrid!$A$1:$LI$1),FALSE) -> 33.352976 | K13: =VLOOKUP($E13,Hybrid!$1:$1048576,MATCH(DATE(K$2,1,1),Hybrid!$A$1:$LI$1),FALSE) -> 42.139977 | L13: =VLOOKUP($E13,Hybrid!$1:$1048576,MATCH(DATE(L$2,1,1),Hybrid!$A$1:$LI$1),FALSE) -> 50.520577 | M13: =VLOOKUP($E13,Hybrid!$1:$1048576,MATCH(DATE(M$2,1,1),Hybrid!$A$1:$LI$1),FALSE) -> 59.100915 | ... AO13: =VLOOKUP($E13,Hybrid!$1:$1048576,MATCH(DATE(AO$2,1,1),Hybrid!$A$1:$LI$1),FALSE) -> 2712.0959
D14: class B | E14: AUTO_cb_cele_2 | F14: =VLOOKUP($E14,Hybrid!$1:$1048576,MATCH(DATE(F$2,1,1),Hybrid!$A$1:$LI$1),FALSE) -> 11.445717 | G14: =VLOOKUP($E14,Hybrid!$1:$1048576,MATCH(DATE(G$2,1,1),Hybrid!$A$1:$LI$1),FALSE) -> 16.461946 | H14: =VLOOKUP($E14,Hybrid!$1:$1048576,MATCH(DATE(H$2,1,1),Hybrid!$A$1:$LI$1),FALSE) -> 21.433349 | I14: =VLOOKUP($E14,Hybrid!$1:$1048576,MATCH(DATE(I$2,1,1),Hybrid!$A$1:$LI$1),FALSE) -> 26.683623 | J14: =VLOOKUP($E14,Hybrid!$1:$1048576,MATCH(DATE(J$2,1,1),Hybrid!$A$1:$LI$1),FALSE) -> 33.615652 | K14: =VLOOKUP($E14,Hybrid!$1:$1048576,MATCH(DATE(K$2,1,1),Hybrid!$A$1:$LI$1),FALSE) -> 41.934825 | L14: =VLOOKUP($E14,Hybrid!$1:$1048576,MATCH(DATE(L$2,1,1),Hybrid!$A$1:$LI$1),FALSE) -> 49.840932 | M14: =VLOOKUP($E14,Hybrid!$1:$1048576,MATCH(DATE(M$2,1,1),Hybrid!$A$1:$LI$1),FALSE) -> 57.904057 | ... AO14: =VLOOKUP($E14,Hybrid!$1:$1048576,MATCH(DATE(AO$2,1,1),Hybrid!$A$1:$LI$1),FALSE) -> 1421.4788
D15: class C | E15: AUTO_cc_cele_2 | F15: =VLOOKUP($E15,Hybrid!$1:$1048576,MATCH(DATE(F$2,1,1),Hybrid!$A$1:$LI$1),FALSE) -> 9.4015406 | G15: =VLOOKUP($E15,Hybrid!$1:$1048576,MATCH(DATE(G$2,1,1),Hybrid!$A$1:$LI$1),FALSE) -> 12.810382 | H15: =VLOOKUP($E15,Hybrid!$1:$1048576,MATCH(DATE(H$2,1,1),Hybrid!$A$1:$LI$1),FALSE) -> 16.175633 | I15: =VLOOKUP($E15,Hybrid!$1:$1048576,MATCH(DATE(I$2,1,1),Hybrid!$A$1:$LI$1),FALSE) -> 19.72907 | J15: =VLOOKUP($E15,Hybrid!$1:$1048576,MATCH(DATE(J$2,1,1),Hybrid!$A$1:$LI$1),FALSE) -> 24.449744 | K15: =VLOOKUP($E15,Hybrid!$1:$1048576,MATCH(DATE(K$2,1,1),Hybrid!$A$1:$LI$1),FALSE) -> 30.117195 | L15: =VLOOKUP($E15,Hybrid!$1:$1048576,MATCH(DATE(L$2,1,1),Hybrid!$A$1:$LI$1),FALSE) -> 35.483708 | M15: =VLOOKUP($E15,Hybrid!$1:$1048576,MATCH(DATE(M$2,1,1),Hybrid!$A$1:$LI$1),FALSE) -> 40.934695 | ... AO15: =VLOOKUP($E15,Hybrid!$1:$1048576,MATCH(DATE(AO$2,1,1),Hybrid!$A$1:$LI$1),FALSE) -> 588.56936
D16: class D | E16: AUTO_cd_cele_2 | F16: =VLOOKUP($E16,Hybrid!$1:$1048576,MATCH(DATE(F$2,1,1),Hybrid!$A$1:$LI$1),FALSE) -> 5.7700713 | G16: =VLOOKUP($E16,Hybrid!$1:$1048576,MATCH(DATE(G$2,1,1),Hybrid!$A$1:$LI$1),FALSE) -> 7.6228602 | H16: =VLOOKUP($E16,Hybrid!$1:$1048576,MATCH(DATE(H$2,1,1),Hybrid!$A$1:$LI$1),FALSE) -> 9.4510521 | I16: =VLOOKUP($E16,Hybrid!$1:$1048576,MATCH(DATE(I$2,1,1),Hybrid!$A$1:$LI$1),FALSE) -> 11.261629 | J16: =VLOOKUP($E16,Hybrid!$1:$1048576,MATCH(DATE(J$2,1,1),Hybrid!$A$1:$LI$1),FALSE) -> 13.387628 | K16: =VLOOKUP($E16,Hybrid!$1:$1048576,MATCH(DATE(K$2,1,1),Hybrid!$A$1:$LI$1),FALSE) -> 15.871449 | L16: =VLOOKUP($E16,Hybrid!$1:$1048576,MATCH(DATE(L$2,1,1),Hybrid!$A$1:$LI$1),FALSE) -> 18.187902 | M16: =VLOOKUP($E16,Hybrid!$1:$1048576,MATCH(DATE(M$2,1,1),Hybrid!$A$1:$LI$1),FALSE) -> 20.45637 | ... AO16: =VLOOKUP($E16,Hybrid!$1:$1048576,MATCH(DATE(AO$2,1,1),Hybrid!$A$1:$LI$1),FALSE) -> 52.604655
D17: class E | E17: AUTO_ce_cele_2 | F17: =VLOOKUP($E17,Hybrid!$1:$1048576,MATCH(DATE(F$2,1,1),Hybrid!$A$1:$LI$1),FALSE) -> 3.4730441 | G17: =VLOOKUP($E17,Hybrid!$1:$1048576,MATCH(DATE(G$2,1,1),Hybrid!$A$1:$LI$1),FALSE) -> 4.6091896 | H17: =VLOOKUP($E17,Hybrid!$1:$1048576,MATCH(DATE(H$2,1,1),Hybrid!$A$1:$LI$1),FALSE) -> 5.7149767 | I17: =VLOOKUP($E17,Hybrid!$1:$1048576,MATCH(DATE(I$2,1,1),Hybrid!$A$1:$LI$1),FALSE) -> 6.7928004 | J17: =VLOOKUP($E17,Hybrid!$1:$1048576,MATCH(DATE(J$2,1,1),Hybrid!$A$1:$LI$1),FALSE) -> 8.0398585 | K17: =VLOOKUP($E17,Hybrid!$1:$1048576,MATCH(DATE(K$2,1,1),Hybrid!$A$1:$LI$1),FALSE) -> 9.4759102 | L17: =VLOOKUP($E17,Hybrid!$1:$1048576,MATCH(DATE(L$2,1,1),Hybrid!$A$1:$LI$1),FALSE) -> 10.790746 | M17: =VLOOKUP($E17,Hybrid!$1:$1048576,MATCH(DATE(M$2,1,1),Hybrid!$A$1:$LI$1),FALSE) -> 12.050356 | ... AO17: =VLOOKUP($E17,Hybrid!$1:$1048576,MATCH(DATE(AO$2,1,1),Hybrid!$A$1:$LI$1),FALSE) -> 17.470553
D18: class F | E18: AUTO_cf_cele_2 | F18: =VLOOKUP($E18,Hybrid!$1:$1048576,MATCH(DATE(F$2,1,1),Hybrid!$A$1:$LI$1),FALSE) -> 1.7251505 | G18: =VLOOKUP($E18,Hybrid!$1:$1048576,MATCH(DATE(G$2,1,1),Hybrid!$A$1:$LI$1),FALSE) -> 2.2608175 | H18: =VLOOKUP($E18,Hybrid!$1:$1048576,MATCH(DATE(H$2,1,1),Hybrid!$A$1:$LI$1),FALSE) -> 2.7629561 | I18: =VLOOKUP($E18,Hybrid!$1:$1048576,MATCH(DATE(I$2,1,1),Hybrid!$A$1:$LI$1),FALSE) -> 3.2118073 | J18: =VLOOKUP($E18,Hybrid!$1:$1048576,MATCH(DATE(J$2,1,1),Hybrid!$A$1:$LI$1),FALSE) -> 3.6713826 | K18: =VLOOKUP($E18,Hybrid!$1:$1048576,MATCH(DATE(K$2,1,1),Hybrid!$A$1:$LI$1),FALSE) -> 4.1657074 | L18: =VLOOKUP($E18,Hybrid!$1:$1048576,MATCH(DATE(L$2,1,1),Hybrid!$A$1:$LI$1),FALSE) -> 4.5869138 | M18: =VLOOKUP($E18,Hybrid!$1:$1048576,MATCH(DATE(M$2,1,1),Hybrid!$A$1:$LI$1),FALSE) -> 4.9518074 | ... AO18: =VLOOKUP($E18,Hybrid!$1:$1048576,MATCH(DATE(AO$2,1,1),Hybrid!$A$1:$LI$1),FALSE) -> 2.8904074
D19: class G | E19: AUTO_cg_cele_2 | F19: =VLOOKUP($E19,Hybrid!$1:$1048576,MATCH(DATE(F$2,1,1),Hybrid!$A$1:$LI$1),FALSE) -> 3.1066862 | G19: =VLOOKUP($E19,Hybrid!$1:$1048576,MATCH(DATE(G$2,1,1),Hybrid!$A$1:$LI$1),FALSE) -> 4.0987638 | H19: =VLOOKUP($E19,Hybrid!$1:$1048576,MATCH(DATE(H$2,1,1),Hybrid!$A$1:$LI$1),FALSE) -> 4.9944538 | I19: =VLOOKUP($E19,Hybrid!$1:$1048576,MATCH(DATE(I$2,1,1),Hybrid!$A$1:$LI$1),FALSE) -> 5.7499462 | J19: =VLOOKUP($E19,Hybrid!$1:$1048576,MATCH(DATE(J$2,1,1),Hybrid!$A$1:$LI$1),FALSE) -> 6.4729559 | K19: =VLOOKUP($E19,Hybrid!$1:$1048576,MATCH(DATE(K$2,1,1),Hybrid!$A$1:$LI$1),FALSE) -> 7.205424 | L19: =VLOOKUP($E19,Hybrid!$1:$1048576,MATCH(DATE(L$2,1,1),Hybrid!$A$1:$LI$1),FALSE) -> 7.7846433 | M19: =VLOOKUP($E19,Hybrid!$1:$1048576,MATCH(DATE(M$2,1,1),Hybrid!$A$1:$LI$1),FALSE) -> 8.2393631 | ... AO19: =VLOOKUP($E19,Hybrid!$1:$1048576,MATCH(DATE(AO$2,1,1),Hybrid!$A$1:$LI$1),FALSE) -> 3.7716557
C20: GAS | E20: AUTO_cgas_2 | F20: =VLOOKUP($E20,Hybrid!$1:$1048576,MATCH(DATE(F$2,1,1),Hybrid!$A$1:$LI$1),FALSE) -> 1.936 | G20: =VLOOKUP($E20,Hybrid!$1:$1048576,MATCH(DATE(G$2,1,1),Hybrid!$A$1:$LI$1),FALSE) -> 1.9968324 | H20: =VLOOKUP($E20,Hybrid!$1:$1048576,MATCH(DATE(H$2,1,1),Hybrid!$A$1:$LI$1),FALSE) -> 2.060546 | I20: =VLOOKUP($E20,Hybrid!$1:$1048576,MATCH(DATE(I$2,1,1),Hybrid!$A$1:$LI$1),FALSE) -> 2.1196814 | J20: =VLOOKUP($E20,Hybrid!$1:$1048576,MATCH(DATE(J$2,1,1),Hybrid!$A$1:$LI$1),FALSE) -> 2.1910005 | K20: =VLOOKUP($E20,Hybrid!$1:$1048576,MATCH(DATE(K$2,1,1),Hybrid!$A$1:$LI$1),FALSE) -> 2.2894584 | L20: =VLOOKUP($E20,Hybrid!$1:$1048576,MATCH(DATE(L$2,1,1),Hybrid!$A$1:$LI$1),FALSE) -> 2.3779418 | M20: =VLOOKUP($E20,Hybrid!$1:$1048576,MATCH(DATE(M$2,1,1),Hybrid!$A$1:$LI$1),FALSE) -> 2.4627777 | ... AO20: =VLOOKUP($E20,Hybrid!$1:$1048576,MATCH(DATE(AO$2,1,1),Hybrid!$A$1:$LI$1),FALSE) -> 3.9314241
D21: class A | E21: AUTO_ca_cgas_2 | F21: =VLOOKUP($E21,Hybrid!$1:$1048576,MATCH(DATE(F$2,1,1),Hybrid!$A$1:$LI$1),FALSE) -> 0.4256817 | G21: =VLOOKUP($E21,Hybrid!$1:$1048576,MATCH(DATE(G$2,1,1),Hybrid!$A$1:$LI$1),FALSE) -> 0.45084295 | H21: =VLOOKUP($E21,Hybrid!$1:$1048576,MATCH(DATE(H$2,1,1),Hybrid!$A$1:$LI$1),FALSE) -> 0.47695788 | I21: =VLOOKUP($E21,Hybrid!$1:$1048576,MATCH(DATE(I$2,1,1),Hybrid!$A$1:$LI$1),FALSE) -> 0.50234383 | J21: =VLOOKUP($E21,Hybrid!$1:$1048576,MATCH(DATE(J$2,1,1),Hybrid!$A$1:$LI$1),FALSE) -> 0.53210293 | K21: =VLOOKUP($E21,Hybrid!$1:$1048576,MATCH(DATE(K$2,1,1),Hybrid!$A$1:$LI$1),FALSE) -> 0.57042379 | L21: =VLOOKUP($E21,Hybrid!$1:$1048576,MATCH(DATE(L$2,1,1),Hybrid!$A$1:$LI$1),FALSE) -> 0.60596968 | M21: =VLOOKUP($E21,Hybrid!$1:$1048576,MATCH(DATE(M$2,1,1),Hybrid!$A$1:$LI$1),FALSE) -> 0.64099082 | ... AO21: =VLOOKUP($E21,Hybrid!$1:$1048576,MATCH(DATE(AO$2,1,1),Hybrid!$A$1:$LI$1),FALSE) -> 1.9825822
D22: class B | E22: AUTO_cb_cgas_2 | F22: =VLOOKUP($E22,Hybrid!$1:$1048576,MATCH(DATE(F$2,1,1),Hybrid!$A$1:$LI$1),FALSE) -> 0.49500523 | G22: =VLOOKUP($E22,Hybrid!$1:$1048576,MATCH(DATE(G$2,1,1),Hybrid!$A$1:$LI$1),FALSE) -> 0.51370793 | H22: =VLOOKUP($E22,Hybrid!$1:$1048576,MATCH(DATE(H$2,1,1),Hybrid!$A$1:$LI$1),FALSE) -> 0.53354294 | I22: =VLOOKUP($E22,Hybrid!$1:$1048576,MATCH(DATE(I$2,1,1),Hybrid!$A$1:$LI$1),FALSE) -> 0.55272136 | J22: =VLOOKUP($E22,Hybrid!$1:$1048576,MATCH(DATE(J$2,1,1),Hybrid!$A$1:$LI$1),FALSE) -> 0.57599895 | K22: =VLOOKUP($E22,Hybrid!$1:$1048576,MATCH(DATE(K$2,1,1),Hybrid!$A$1:$LI$1),FALSE) -> 0.60748622 | L22: =VLOOKUP($E22,Hybrid!$1:$1048576,MATCH(DATE(L$2,1,1),Hybrid!$A$1:$LI$1),FALSE) -> 0.63650963 | M22: =VLOOKUP($E22,Hybrid!$1:$1048576,MATCH(DATE(M$2,1,1),Hybrid!$A$1:$LI$1),FALSE) -> 0.66501015 | ... AO22: =VLOOKUP($E22,Hybrid!$1:$1048576,MATCH(DATE(AO$2,1,1),Hybrid!$A$1:$LI$1),FALSE) -> 1.1632447
D23: class C | E23: AUTO_cc_cgas_2 | F23: =VLOOKUP($E23,Hybrid!$1:$1048576,MATCH(DATE(F$2,1,1),Hybrid!$A$1:$LI$1),FALSE) -> 0.40659852 | G23: =VLOOKUP($E23,Hybrid!$1:$1048576,MATCH(DATE(G$2,1,1),Hybrid!$A$1:$LI$1),FALSE) -> 0.41550713 | H23: =VLOOKUP($E23,Hybrid!$1:$1048576,MATCH(DATE(H$2,1,1),Hybrid!$A$1:$LI$1),FALSE) -> 0.42536707 | I23: =VLOOKUP($E23,Hybrid!$1:$1048576,MATCH(DATE(I$2,1,1),Hybrid!$A$1:$LI$1),FALSE) -> 0.43482241 | J23: =VLOOKUP($E23,Hybrid!$1:$1048576,MATCH(DATE(J$2,1,1),Hybrid!$A$1:$LI$1),FALSE) -> 0.44707018 | K23: =VLOOKUP($E23,Hybrid!$1:$1048576,MATCH(DATE(K$2,1,1),Hybrid!$A$1:$LI$1),FALSE) -> 0.46501401 | L23: =VLOOKUP($E23,Hybrid!$1:$1048576,MATCH(DATE(L$2,1,1),Hybrid!$A$1:$LI$1),FALSE) -> 0.48140681 | M23: =VLOOKUP($E23,Hybrid!$1:$1048576,MATCH(DATE(M$2,1,1),Hybrid!$A$1:$LI$1),FALSE) -> 0.49744747 | ... AO23: =VLOOKUP($E23,Hybrid!$1:$1048576,MATCH(DATE(AO$2,1,1),Hybrid!$A$1:$LI$1),FALSE) -> 0.55682411
D24: class D | E24: AUTO_cd_cgas_2 | F24: =VLOOKUP($E24,Hybrid!$1:$1048576,MATCH(DATE(F$2,1,1),Hybrid!$A$1:$LI$1),FALSE) -> 0.24954447 | G24: =VLOOKUP($E24,Hybrid!$1:$1048576,MATCH(DATE(G$2,1,1),Hybrid!$A$1:$LI$1),FALSE) -> 0.25285832 | H24: =VLOOKUP($E24,Hybrid!$1:$1048576,MATCH(DATE(H$2,1,1),Hybrid!$A$1:$LI$1),FALSE) -> 0.25657518 | I24: =VLOOKUP($E24,Hybrid!$1:$1048576,MATCH(DATE(I$2,1,1),Hybrid!$A$1:$LI$1),FALSE) -> 0.25980708 | J24: =VLOOKUP($E24,Hybrid!$1:$1048576,MATCH(DATE(J$2,1,1),Hybrid!$A$1:$LI$1),FALSE) -> 0.26420163 | K24: =VLOOKUP($E24,Hybrid!$1:$1048576,MATCH(DATE(K$2,1,1),Hybrid!$A$1:$LI$1),FALSE) -> 0.27132781 | L24: =VLOOKUP($E24,Hybrid!$1:$1048576,MATCH(DATE(L$2,1,1),Hybrid!$A$1:$LI$1),FALSE) -> 0.277446 | M24: =VLOOKUP($E24,Hybrid!$1:$1048576,MATCH(DATE(M$2,1,1),Hybrid!$A$1:$LI$1),FALSE) -> 0.28305668 | ... AO24: =VLOOKUP($E24,Hybrid!$1:$1048576,MATCH(DATE(AO$2,1,1),Hybrid!$A$1:$LI$1),FALSE) -> 0.13047409
D25: class E | E25: AUTO_ce_cgas_2 | F25: =VLOOKUP($E25,Hybrid!$1:$1048576,MATCH(DATE(F$2,1,1),Hybrid!$A$1:$LI$1),FALSE) -> 0.15020247 | G25: =VLOOKUP($E25,Hybrid!$1:$1048576,MATCH(DATE(G$2,1,1),Hybrid!$A$1:$LI$1),FALSE) -> 0.15238593 | H25: =VLOOKUP($E25,Hybrid!$1:$1048576,MATCH(DATE(H$2,1,1),Hybrid!$A$1:$LI$1),FALSE) -> 0.15468725 | I25: =VLOOKUP($E25,Hybrid!$1:$1048576,MATCH(DATE(I$2,1,1),Hybrid!$A$1:$LI$1),FALSE) -> 0.15649018 | J25: =VLOOKUP($E25,Hybrid!$1:$1048576,MATCH(DATE(J$2,1,1),Hybrid!$A$1:$LI$1),FALSE) -> 0.15874617 | K25: =VLOOKUP($E25,Hybrid!$1:$1048576,MATCH(DATE(K$2,1,1),Hybrid!$A$1:$LI$1),FALSE) -> 0.16241596 | L25: =VLOOKUP($E25,Hybrid!$1:$1048576,MATCH(DATE(L$2,1,1),Hybrid!$A$1:$LI$1),FALSE) -> 0.16535808 | M25: =VLOOKUP($E25,Hybrid!$1:$1048576,MATCH(DATE(M$2,1,1),Hybrid!$A$1:$LI$1),FALSE) -> 0.16780894 | ... AO25: =VLOOKUP($E25,Hybrid!$1:$1048576,MATCH(DATE(AO$2,1,1),Hybrid!$A$1:$LI$1),FALSE) -> 0.056121869
D26: class F | E26: AUTO_cf_cgas_2 | F26: =VLOOKUP($E26,Hybrid!$1:$1048576,MATCH(DATE(F$2,1,1),Hybrid!$A$1:$LI$1),FALSE) -> 0.074609436 | G26: =VLOOKUP($E26,Hybrid!$1:$1048576,MATCH(DATE(G$2,1,1),Hybrid!$A$1:$LI$1),FALSE) -> 0.075435583 | H26: =VLOOKUP($E26,Hybrid!$1:$1048576,MATCH(DATE(H$2,1,1),Hybrid!$A$1:$LI$1),FALSE) -> 0.076134567 | I26: =VLOOKUP($E26,Hybrid!$1:$1048576,MATCH(DATE(I$2,1,1),Hybrid!$A$1:$LI$1),FALSE) -> 0.076336312 | J26: =VLOOKUP($E26,Hybrid!$1:$1048576,MATCH(DATE(J$2,1,1),Hybrid!$A$1:$LI$1),FALSE) -> 0.076438727 | K26: =VLOOKUP($E26,Hybrid!$1:$1048576,MATCH(DATE(K$2,1,1),Hybrid!$A$1:$LI$1),FALSE) -> 0.076873442 | L26: =VLOOKUP($E26,Hybrid!$1:$1048576,MATCH(DATE(L$2,1,1),Hybrid!$A$1:$LI$1),FALSE) -> 0.076837512 | M26: =VLOOKUP($E26,Hybrid!$1:$1048576,MATCH(DATE(M$2,1,1),Hybrid!$A$1:$LI$1),FALSE) -> 0.076400208 | ... AO26: =VLOOKUP($E26,Hybrid!$1:$1048576,MATCH(DATE(AO$2,1,1),Hybrid!$A$1:$LI$1),FALSE) -> 0.016674178
D27: class G | E27: AUTO_cg_cgas_2 | F27: =VLOOKUP($E27,Hybrid!$1:$1048576,MATCH(DATE(F$2,1,1),Hybrid!$A$1:$LI$1),FALSE) -> 0.13435819 | G27: =VLOOKUP($E27,Hybrid!$1:$1048576,MATCH(DATE(G$2,1,1),Hybrid!$A$1:$LI$1),FALSE) -> 0.13609456 | H27: =VLOOKUP($E27,Hybrid!$1:$1048576,MATCH(DATE(H$2,1,1),Hybrid!$A$1:$LI$1),FALSE) -> 0.13728112 | I27: =VLOOKUP($E27,Hybrid!$1:$1048576,MATCH(DATE(I$2,1,1),Hybrid!$A$1:$LI$1),FALSE) -> 0.13716024 | J27: =VLOOKUP($E27,Hybrid!$1:$1048576,MATCH(DATE(J$2,1,1),Hybrid!$A$1:$LI$1),FALSE) -> 0.13644192 | K27: =VLOOKUP($E27,Hybrid!$1:$1048576,MATCH(DATE(K$2,1,1),Hybrid!$A$1:$LI$1),FALSE) -> 0.13591716 | L27: =VLOOKUP($E27,Hybrid!$1:$1048576,MATCH(DATE(L$2,1,1),Hybrid!$A$1:$LI$1),FALSE) -> 0.13441412 | M27: =VLOOKUP($E27,Hybrid!$1:$1048576,MATCH(DATE(M$2,1,1),Hybrid!$A$1:$LI$1),FALSE) -> 0.13206339 | ... AO27: =VLOOKUP($E27,Hybrid!$1:$1048576,MATCH(DATE(AO$2,1,1),Hybrid!$A$1:$LI$1),FALSE) -> 0.025503054
C28: TOTAL STOCK BASELINE | E28: AUTO_0 | F28: =VLOOKUP($E28,Hybrid!$1:$1048576,MATCH(DATE(F$2,1,1),Hybrid!$A$1:$LI$1),FALSE) -> 32317.941 | G28: =VLOOKUP($E28,Hybrid!$1:$1048576,MATCH(DATE(G$2,1,1),Hybrid!$A$1:$LI$1),FALSE) -> 31989.266 | H28: =VLOOKUP($E28,Hybrid!$1:$1048576,MATCH(DATE(H$2,1,1),Hybrid!$A$1:$LI$1),FALSE) -> 31766.848 | I28: =VLOOKUP($E28,Hybrid!$1:$1048576,MATCH(DATE(I$2,1,1),Hybrid!$A$1:$LI$1),FALSE) -> 31556.566 | J28: =VLOOKUP($E28,Hybrid!$1:$1048576,MATCH(DATE(J$2,1,1),Hybrid!$A$1:$LI$1),FALSE) -> 31558.174 | K28: =VLOOKUP($E28,Hybrid!$1:$1048576,MATCH(DATE(K$2,1,1),Hybrid!$A$1:$LI$1),FALSE) -> 31942.005 | L28: =VLOOKUP($E28,Hybrid!$1:$1048576,MATCH(DATE(L$2,1,1),Hybrid!$A$1:$LI$1),FALSE) -> 32251.021 | M28: =VLOOKUP($E28,Hybrid!$1:$1048576,MATCH(DATE(M$2,1,1),Hybrid!$A$1:$LI$1),FALSE) -> 32582.334 | ... AO28: =VLOOKUP($E28,Hybrid!$1:$1048576,MATCH(DATE(AO$2,1,1),Hybrid!$A$1:$LI$1),FALSE) -> 44584.282
C29: OIL | E29: AUTO_cfut_0 | F29: =VLOOKUP($E29,Hybrid!$1:$1048576,MATCH(DATE(F$2,1,1),Hybrid!$A$1:$LI$1),FALSE) -> 32271.24 | G29: =VLOOKUP($E29,Hybrid!$1:$1048576,MATCH(DATE(G$2,1,1),Hybrid!$A$1:$LI$1),FALSE) -> 31924.248 | H29: =VLOOKUP($E29,Hybrid!$1:$1048576,MATCH(DATE(H$2,1,1),Hybrid!$A$1:$LI$1),FALSE) -> 31683.81 | I29: =VLOOKUP($E29,Hybrid!$1:$1048576,MATCH(DATE(I$2,1,1),Hybrid!$A$1:$LI$1),FALSE) -> 31454.989 | J29: =VLOOKUP($E29,Hybrid!$1:$1048576,MATCH(DATE(J$2,1,1),Hybrid!$A$1:$LI$1),FALSE) -> 31432.993 | K29: =VLOOKUP($E29,Hybrid!$1:$1048576,MATCH(DATE(K$2,1,1),Hybrid!$A$1:$LI$1),FALSE) -> 31788.805 | L29: =VLOOKUP($E29,Hybrid!$1:$1048576,MATCH(DATE(L$2,1,1),Hybrid!$A$1:$LI$1),FALSE) -> 32071.448 | M29: =VLOOKUP($E29,Hybrid!$1:$1048576,MATCH(DATE(M$2,1,1),Hybrid!$A$1:$LI$1),FALSE) -> 32376.242 | ... AO29: =VLOOKUP($E29,Hybrid!$1:$1048576,MATCH(DATE(AO$2,1,1),Hybrid!$A$1:$LI$1),FALSE) -> 43277.168
D30: class A | E30: AUTO_ca_cfut_0 | F30: =VLOOKUP($E30,Hybrid!$1:$1048576,MATCH(DATE(F$2,1,1),Hybrid!$A$1:$LI$1),FALSE) -> 7095.7005 | G30: =VLOOKUP($E30,Hybrid!$1:$1048576,MATCH(DATE(G$2,1,1),Hybrid!$A$1:$LI$1),FALSE) -> 7159.6915 | H30: =VLOOKUP($E30,Hybrid!$1:$1048576,MATCH(DATE(H$2,1,1),Hybrid!$A$1:$LI$1),FALSE) -> 7248.7731 | I30: =VLOOKUP($E30,Hybrid!$1:$1048576,MATCH(DATE(I$2,1,1),Hybrid!$A$1:$LI$1),FALSE) -> 7341.6733 | J30: =VLOOKUP($E30,Hybrid!$1:$1048576,MATCH(DATE(J$2,1,1),Hybrid!$A$1:$LI$1),FALSE) -> 7498.2843 | K30: =VLOOKUP($E30,Hybrid!$1:$1048576,MATCH(DATE(K$2,1,1),Hybrid!$A$1:$LI$1),FALSE) -> 7766.7593 | L30: =VLOOKUP($E30,Hybrid!$1:$1048576,MATCH(DATE(L$2,1,1),Hybrid!$A$1:$LI$1),FALSE) -> 8009.8192 | M30: =VLOOKUP($E30,Hybrid!$1:$1048576,MATCH(DATE(M$2,1,1),Hybrid!$A$1:$LI$1),FALSE) -> 8259.9685 | ... AO30: =VLOOKUP($E30,Hybrid!$1:$1048576,MATCH(DATE(AO$2,1,1),Hybrid!$A$1:$LI$1),FALSE) -> 19071.974
D31: class B | E31: AUTO_cb_cfut_0 | F31: =VLOOKUP($E31,Hybrid!$1:$1048576,MATCH(DATE(F$2,1,1),Hybrid!$A$1:$LI$1),FALSE) -> 8251.2564 | G31: =VLOOKUP($E31,Hybrid!$1:$1048576,MATCH(DATE(G$2,1,1),Hybrid!$A$1:$LI$1),FALSE) -> 8200.0167 | H31: =VLOOKUP($E31,Hybrid!$1:$1048576,MATCH(DATE(H$2,1,1),Hybrid!$A$1:$LI$1),FALSE) -> 8180.1563 | I31: =VLOOKUP($E31,Hybrid!$1:$1048576,MATCH(DATE(I$2,1,1),Hybrid!$A$1:$LI$1),FALSE) -> 8168.7824 | J31: =VLOOKUP($E31,Hybrid!$1:$1048576,MATCH(DATE(J$2,1,1),Hybrid!$A$1:$LI$1),FALSE) -> 8221.3545 | K31: =VLOOKUP($E31,Hybrid!$1:$1048576,MATCH(DATE(K$2,1,1),Hybrid!$A$1:$LI$1),FALSE) -> 8384.8744 | L31: =VLOOKUP($E31,Hybrid!$1:$1048576,MATCH(DATE(L$2,1,1),Hybrid!$A$1:$LI$1),FALSE) -> 8529.766 | M31: =VLOOKUP($E31,Hybrid!$1:$1048576,MATCH(DATE(M$2,1,1),Hybrid!$A$1:$LI$1),FALSE) -> 8684.5805 | ... AO31: =VLOOKUP($E31,Hybrid!$1:$1048576,MATCH(DATE(AO$2,1,1),Hybrid!$A$1:$LI$1),FALSE) -> 13897.5
D32: class C | E32: AUTO_cc_cfut_0 | F32: =VLOOKUP($E32,Hybrid!$1:$1048576,MATCH(DATE(F$2,1,1),Hybrid!$A$1:$LI$1),FALSE) -> 6777.6025 | G32: =VLOOKUP($E32,Hybrid!$1:$1048576,MATCH(DATE(G$2,1,1),Hybrid!$A$1:$LI$1),FALSE) -> 6658.6926 | H32: =VLOOKUP($E32,Hybrid!$1:$1048576,MATCH(DATE(H$2,1,1),Hybrid!$A$1:$LI$1),FALSE) -> 6566.988 | I32: =VLOOKUP($E32,Hybrid!$1:$1048576,MATCH(DATE(I$2,1,1),Hybrid!$A$1:$LI$1),FALSE) -> 6484.9391 | J32: =VLOOKUP($E32,Hybrid!$1:$1048576,MATCH(DATE(J$2,1,1),Hybrid!$A$1:$LI$1),FALSE) -> 6449.5485 | K32: =VLOOKUP($E32,Hybrid!$1:$1048576,MATCH(DATE(K$2,1,1),Hybrid!$A$1:$LI$1),FALSE) -> 6493.8251 | L32: =VLOOKUP($E32,Hybrid!$1:$1048576,MATCH(DATE(L$2,1,1),Hybrid!$A$1:$LI$1),FALSE) -> 6529.5432 | M32: =VLOOKUP($E32,Hybrid!$1:$1048576,MATCH(DATE(M$2,1,1),Hybrid!$A$1:$LI$1),FALSE) -> 6574.6851 | ... AO32: =VLOOKUP($E32,Hybrid!$1:$1048576,MATCH(DATE(AO$2,1,1),Hybrid!$A$1:$LI$1),FALSE) -> 7516.2298
D33: class D | E33: AUTO_cd_cfut_0 | F33: =VLOOKUP($E33,Hybrid!$1:$1048576,MATCH(DATE(F$2,1,1),Hybrid!$A$1:$LI$1),FALSE) -> 4159.6639 | G33: =VLOOKUP($E33,Hybrid!$1:$1048576,MATCH(DATE(G$2,1,1),Hybrid!$A$1:$LI$1),FALSE) -> 4061.0488 | H33: =VLOOKUP($E33,Hybrid!$1:$1048576,MATCH(DATE(H$2,1,1),Hybrid!$A$1:$LI$1),FALSE) -> 3977.3705 | I33: =VLOOKUP($E33,Hybrid!$1:$1048576,MATCH(DATE(I$2,1,1),Hybrid!$A$1:$LI$1),FALSE) -> 3897.1966 | J33: =VLOOKUP($E33,Hybrid!$1:$1048576,MATCH(DATE(J$2,1,1),Hybrid!$A$1:$LI$1),FALSE) -> 3839.5055 | K33: =VLOOKUP($E33,Hybrid!$1:$1048576,MATCH(DATE(K$2,1,1),Hybrid!$A$1:$LI$1),FALSE) -> 3822.0886 | L33: =VLOOKUP($E33,Hybrid!$1:$1048576,MATCH(DATE(L$2,1,1),Hybrid!$A$1:$LI$1),FALSE) -> 3799.3302 | M33: =VLOOKUP($E33,Hybrid!$1:$1048576,MATCH(DATE(M$2,1,1),Hybrid!$A$1:$LI$1),FALSE) -> 3779.304 | ... AO33: =VLOOKUP($E33,Hybrid!$1:$1048576,MATCH(DATE(AO$2,1,1),Hybrid!$A$1:$LI$1),FALSE) -> 1739.6729
D34: class E | E34: AUTO_ce_cfut_0 | F34: =VLOOKUP($E34,Hybrid!$1:$1048576,MATCH(DATE(F$2,1,1),Hybrid!$A$1:$LI$1),FALSE) -> 2503.7292 | G34: =VLOOKUP($E34,Hybrid!$1:$1048576,MATCH(DATE(G$2,1,1),Hybrid!$A$1:$LI$1),FALSE) -> 2446.6199 | H34: =VLOOKUP($E34,Hybrid!$1:$1048576,MATCH(DATE(H$2,1,1),Hybrid!$A$1:$LI$1),FALSE) -> 2396.9821 | I34: =VLOOKUP($E34,Hybrid!$1:$1048576,MATCH(DATE(I$2,1,1),Hybrid!$A$1:$LI$1),FALSE) -> 2346.9867 | J34: =VLOOKUP($E34,Hybrid!$1:$1048576,MATCH(DATE(J$2,1,1),Hybrid!$A$1:$LI$1),FALSE) -> 2307.6163 | K34: =VLOOKUP($E34,Hybrid!$1:$1048576,MATCH(DATE(K$2,1,1),Hybrid!$A$1:$LI$1),FALSE) -> 2289.8168 | L34: =VLOOKUP($E34,Hybrid!$1:$1048576,MATCH(DATE(L$2,1,1),Hybrid!$A$1:$LI$1),FALSE) -> 2267.4709 | M34: =VLOOKUP($E34,Hybrid!$1:$1048576,MATCH(DATE(M$2,1,1),Hybrid!$A$1:$LI$1),FALSE) -> 2244.7587 | ... AO34: =VLOOKUP($E34,Hybrid!$1:$1048576,MATCH(DATE(AO$2,1,1),Hybrid!$A$1:$LI$1),FALSE) -> 660.47631
D35: class F | E35: AUTO_cf_cfut_0 | F35: =VLOOKUP($E35,Hybrid!$1:$1048576,MATCH(DATE(F$2,1,1),Hybrid!$A$1:$LI$1),FALSE) -> 1243.6668 | G35: =VLOOKUP($E35,Hybrid!$1:$1048576,MATCH(DATE(G$2,1,1),Hybrid!$A$1:$LI$1),FALSE) -> 1212.2229 | H35: =VLOOKUP($E35,Hybrid!$1:$1048576,MATCH(DATE(H$2,1,1),Hybrid!$A$1:$LI$1),FALSE) -> 1182.327 | I35: =VLOOKUP($E35,Hybrid!$1:$1048576,MATCH(DATE(I$2,1,1),Hybrid!$A$1:$LI$1),FALSE) -> 1149.3589 | J35: =VLOOKUP($E35,Hybrid!$1:$1048576,MATCH(DATE(J$2,1,1),Hybrid!$A$1:$LI$1),FALSE) -> 1117.9241 | K35: =VLOOKUP($E35,Hybrid!$1:$1048576,MATCH(DATE(K$2,1,1),Hybrid!$A$1:$LI$1),FALSE) -> 1092.9672 | L35: =VLOOKUP($E35,Hybrid!$1:$1048576,MATCH(DATE(L$2,1,1),Hybrid!$A$1:$LI$1),FALSE) -> 1064.6737 | M35: =VLOOKUP($E35,Hybrid!$1:$1048576,MATCH(DATE(M$2,1,1),Hybrid!$A$1:$LI$1),FALSE) -> 1034.4912 | ... AO35: =VLOOKUP($E35,Hybrid!$1:$1048576,MATCH(DATE(AO$2,1,1),Hybrid!$A$1:$LI$1),FALSE) -> 159.58538
D36: class G | E36: AUTO_cg_cfut_0 | F36: =VLOOKUP($E36,Hybrid!$1:$1048576,MATCH(DATE(F$2,1,1),Hybrid!$A$1:$LI$1),FALSE) -> 2239.6206 | G36: =VLOOKUP($E36,Hybrid!$1:$1048576,MATCH(DATE(G$2,1,1),Hybrid!$A$1:$LI$1),FALSE) -> 2185.9552 | H36: =VLOOKUP($E36,Hybrid!$1:$1048576,MATCH(DATE(H$2,1,1),Hybrid!$A$1:$LI$1),FALSE) -> 2131.2134 | I36: =VLOOKUP($E36,Hybrid!$1:$1048576,MATCH(DATE(I$2,1,1),Hybrid!$A$1:$LI$1),FALSE) -> 2066.0517 | J36: =VLOOKUP($E36,Hybrid!$1:$1048576,MATCH(DATE(J$2,1,1),Hybrid!$A$1:$LI$1),FALSE) -> 1998.7596 | K36: =VLOOKUP($E36,Hybrid!$1:$1048576,MATCH(DATE(K$2,1,1),Hybrid!$A$1:$LI$1),FALSE) -> 1938.4737 | L36: =VLOOKUP($E36,Hybrid!$1:$1048576,MATCH(DATE(L$2,1,1),Hybrid!$A$1:$LI$1),FALSE) -> 1870.8443 | M36: =VLOOKUP($E36,Hybrid!$1:$1048576,MATCH(DATE(M$2,1,1),Hybrid!$A$1:$LI$1),FALSE) -> 1798.4537 | ... AO36: =VLOOKUP($E36,Hybrid!$1:$1048576,MATCH(DATE(AO$2,1,1),Hybrid!$A$1:$LI$1),FALSE) -> 231.7298
C37: ELEC | E37: AUTO_cele_0 | F37: =VLOOKUP($E37,Hybrid!$1:$1048576,MATCH(DATE(F$2,1,1),Hybrid!$A$1:$LI$1),FALSE) -> 44.765 | G37: =VLOOKUP($E37,Hybrid!$1:$1048576,MATCH(DATE(G$2,1,1),Hybrid!$A$1:$LI$1),FALSE) -> 63.021127 | H37: =VLOOKUP($E37,Hybrid!$1:$1048576,MATCH(DATE(H$2,1,1),Hybrid!$A$1:$LI$1),FALSE) -> 80.977049 | I37: =VLOOKUP($E37,Hybrid!$1:$1048576,MATCH(DATE(I$2,1,1),Hybrid!$A$1:$LI$1),FALSE) -> 99.457266 | J37: =VLOOKUP($E37,Hybrid!$1:$1048576,MATCH(DATE(J$2,1,1),Hybrid!$A$1:$LI$1),FALSE) -> 122.9902 | K37: =VLOOKUP($E37,Hybrid!$1:$1048576,MATCH(DATE(K$2,1,1),Hybrid!$A$1:$LI$1),FALSE) -> 150.91049 | L37: =VLOOKUP($E37,Hybrid!$1:$1048576,MATCH(DATE(L$2,1,1),Hybrid!$A$1:$LI$1),FALSE) -> 177.19542 | M37: =VLOOKUP($E37,Hybrid!$1:$1048576,MATCH(DATE(M$2,1,1),Hybrid!$A$1:$LI$1),FALSE) -> 203.6274 | ... AO37: =VLOOKUP($E37,Hybrid!$1:$1048576,MATCH(DATE(AO$2,1,1),Hybrid!$A$1:$LI$1),FALSE) -> 1302.844
D38: class A | E38: AUTO_ca_cele_0 | F38: =VLOOKUP($E38,Hybrid!$1:$1048576,MATCH(DATE(F$2,1,1),Hybrid!$A$1:$LI$1),FALSE) -> 9.8427899 | G38: =VLOOKUP($E38,Hybrid!$1:$1048576,MATCH(DATE(G$2,1,1),Hybrid!$A$1:$LI$1),FALSE) -> 15.157168 | H38: =VLOOKUP($E38,Hybrid!$1:$1048576,MATCH(DATE(H$2,1,1),Hybrid!$A$1:$LI$1),FALSE) -> 20.444627 | I38: =VLOOKUP($E38,Hybrid!$1:$1048576,MATCH(DATE(I$2,1,1),Hybrid!$A$1:$LI$1),FALSE) -> 26.028391 | J38: =VLOOKUP($E38,Hybrid!$1:$1048576,MATCH(DATE(J$2,1,1),Hybrid!$A$1:$LI$1),FALSE) -> 33.352976 | K38: =VLOOKUP($E38,Hybrid!$1:$1048576,MATCH(DATE(K$2,1,1),Hybrid!$A$1:$LI$1),FALSE) -> 42.139977 | L38: =VLOOKUP($E38,Hybrid!$1:$1048576,MATCH(DATE(L$2,1,1),Hybrid!$A$1:$LI$1),FALSE) -> 50.520577 | M38: =VLOOKUP($E38,Hybrid!$1:$1048576,MATCH(DATE(M$2,1,1),Hybrid!$A$1:$LI$1),FALSE) -> 59.084801 | ... AO38: =VLOOKUP($E38,Hybrid!$1:$1048576,MATCH(DATE(AO$2,1,1),Hybrid!$A$1:$LI$1),FALSE) -> 587.20783
D39: class B | E39: AUTO_cb_cele_0 | F39: =VLOOKUP($E39,Hybrid!$1:$1048576,MATCH(DATE(F$2,1,1),Hybrid!$A$1:$LI$1),FALSE) -> 11.445717 | G39: =VLOOKUP($E39,Hybrid!$1:$1048576,MATCH(DATE(G$2,1,1),Hybrid!$A$1:$LI$1),FALSE) -> 16.461946 | H39: =VLOOKUP($E39,Hybrid!$1:$1048576,MATCH(DATE(H$2,1,1),Hybrid!$A$1:$LI$1),FALSE) -> 21.433349 | I39: =VLOOKUP($E39,Hybrid!$1:$1048576,MATCH(DATE(I$2,1,1),Hybrid!$A$1:$LI$1),FALSE) -> 26.683623 | J39: =VLOOKUP($E39,Hybrid!$1:$1048576,MATCH(DATE(J$2,1,1),Hybrid!$A$1:$LI$1),FALSE) -> 33.615652 | K39: =VLOOKUP($E39,Hybrid!$1:$1048576,MATCH(DATE(K$2,1,1),Hybrid!$A$1:$LI$1),FALSE) -> 41.934825 | L39: =VLOOKUP($E39,Hybrid!$1:$1048576,MATCH(DATE(L$2,1,1),Hybrid!$A$1:$LI$1),FALSE) -> 49.840932 | M39: =VLOOKUP($E39,Hybrid!$1:$1048576,MATCH(DATE(M$2,1,1),Hybrid!$A$1:$LI$1),FALSE) -> 57.888851 | ... AO39: =VLOOKUP($E39,Hybrid!$1:$1048576,MATCH(DATE(AO$2,1,1),Hybrid!$A$1:$LI$1),FALSE) -> 422.2625
D40: class C | E40: AUTO_cc_cele_0 | F40: =VLOOKUP($E40,Hybrid!$1:$1048576,MATCH(DATE(F$2,1,1),Hybrid!$A$1:$LI$1),FALSE) -> 9.4015406 | G40: =VLOOKUP($E40,Hybrid!$1:$1048576,MATCH(DATE(G$2,1,1),Hybrid!$A$1:$LI$1),FALSE) -> 12.810382 | H40: =VLOOKUP($E40,Hybrid!$1:$1048576,MATCH(DATE(H$2,1,1),Hybrid!$A$1:$LI$1),FALSE) -> 16.175633 | I40: =VLOOKUP($E40,Hybrid!$1:$1048576,MATCH(DATE(I$2,1,1),Hybrid!$A$1:$LI$1),FALSE) -> 19.72907 | J40: =VLOOKUP($E40,Hybrid!$1:$1048576,MATCH(DATE(J$2,1,1),Hybrid!$A$1:$LI$1),FALSE) -> 24.449744 | K40: =VLOOKUP($E40,Hybrid!$1:$1048576,MATCH(DATE(K$2,1,1),Hybrid!$A$1:$LI$1),FALSE) -> 30.117195 | L40: =VLOOKUP($E40,Hybrid!$1:$1048576,MATCH(DATE(L$2,1,1),Hybrid!$A$1:$LI$1),FALSE) -> 35.483708 | M40: =VLOOKUP($E40,Hybrid!$1:$1048576,MATCH(DATE(M$2,1,1),Hybrid!$A$1:$LI$1),FALSE) -> 40.924607 | ... AO40: =VLOOKUP($E40,Hybrid!$1:$1048576,MATCH(DATE(AO$2,1,1),Hybrid!$A$1:$LI$1),FALSE) -> 224.12872
...

Sheet date
A1: =Hybrid!A1 -> _date_ | B1: =Hybrid!B1 -> 42005 | C1: =Hybrid!C1 -> 42370 | D1: =Hybrid!D1 -> 42736 | E1: =Hybrid!E1 -> 43101 | F1: =Hybrid!F1 -> 43466 | G1: =Hybrid!G1 -> 43831 | H1: =Hybrid!H1 -> 44197 | ... AK1: =Hybrid!AK1 -> 54789
B2: =TEXT(B1,"jj mm aaaa") -> 01 01 2015 | C2: =TEXT(C1,"jj mm aaaa") -> 01 01 2016 | D2: =TEXT(D1,"jj mm aaaa") -> 01 01 2017 | E2: =TEXT(E1,"jj mm aaaa") -> 01 01 2018 | F2: =TEXT(F1,"jj mm aaaa") -> 01 01 2019 | G2: =TEXT(G1,"jj mm aaaa") -> 01 01 2020 | H2: =TEXT(H1,"jj mm aaaa") -> 01 01 2021 | I2: =TEXT(I1,"jj mm aaaa") -> 01 01 2022 | ... AK2: =TEXT(AK1,"jj mm aaaa") -> 01 01 2050
B3: =RIGHT(B2,4) -> 2015 | C3: =RIGHT(C2,4) -> 2016 | D3: =RIGHT(D2,4) -> 2017 | E3: =RIGHT(E2,4) -> 2018 | F3: =RIGHT(F2,4) -> 2019 | G3: =RIGHT(G2,4) -> 2020 | H3: =RIGHT(H2,4) -> 2021 | I3: =RIGHT(I2,4) -> 2022 | ... AK3: =RIGHT(AK2,4) -> 2050

Sheet Emissions
A1: _date_ | B1: 42005 | C1: 42370 | D1: 42736 | E1: 43101 | F1: 43466 | G1: 43831 | H1: 44197 | I1: 44562 | J1: 44927 | K1: 45292 | L1: 45658 | M1: 46023 | N1: 46388 | O1: 46753 | P1: 47119 | Q1: 47484 | R1: 47849 | S1: 48214 | T1: 48580 | U1: 48945 | V1: 49310 | W1: 49675 | X1: 50041 | Y1: 50406 | Z1: 50771 | AA1: 51136 | AB1: 51502 | AC1: 51867 | AD1: 52232 | AE1: 52597 | AF1: 52963 | AG1: 53328 | AH1: 53693 | AI1: 54058 | AJ1: 54424 | AK1: 54789
