Workbook
Name formatResults: [1]ResultsEXR10!$A$50

Sheet Feuil1
B1: 42005 | C1: 42370 | D1: 42736 | E1: 43101 | F1: 43466 | G1: 43831 | H1: 44197 | I1: 44562 | J1: 44927 | K1: 45292 | L1: 45658 | M1: 46023 | N1: 46388 | O1: 46753 | P1: 47119 | Q1: 47484 | R1: 47849 | S1: 48214 | T1: 48580 | U1: 48945 | V1: 49310 | W1: 49675 | X1: 50041 | Y1: 50406 | Z1: 50771 | AA1: 51136 | AB1: 51502 | AC1: 51867 | AD1: 52232 | AE1: 52597 | AF1: 52963 | AG1: 53328 | AH1: 53693 | AI1: 54058 | AJ1: 54424 | AK1: 54789
A2: y_2 | B2: =Capital!B2/Production!B2 -> 1.3555282 | C2: =Capital!C2/Production!C2 -> 1.3505388 | D2: =Capital!D2/Production!D2 -> 1.3470192 | E2: =Capital!E2/Production!E2 -> 1.3447498 | F2: =Capital!F2/Production!F2 -> 1.3404508 | G2: =Capital!G2/Production!G2 -> 1.33118 | H2: =Capital!H2/Production!H2 -> 1.3232296 | I2: =Capital!I2/Production!I2 -> 1.3160229 | ... AK2: =Capital!AK2/Production!AK2 -> 1.369046
A3: y_0 | B3: =Capital!B3/Production!B3 -> 1.3555282 | C3: =Capital!C3/Production!C3 -> 1.3505388 | D3: =Capital!D3/Production!D3 -> 1.3470192 | E3: =Capital!E3/Production!E3 -> 1.3447498 | F3: =Capital!F3/Production!F3 -> 1.3404508 | G3: =Capital!G3/Production!G3 -> 1.33118 | H3: =Capital!H3/Production!H3 -> 1.322512 | I3: =Capital!I3/Production!I3 -> 1.3151374 | ... AK3: =Capital!AK3/Production!AK3 -> 1.4162897
A4: y_sagr_2 | B4: =Capital!B4/Production!B4 -> 0.57725408 | C4: =Capital!C4/Production!C4 -> 0.5762539 | D4: =Capital!D4/Production!D4 -> 0.57544883 | E4: =Capital!E4/Production!E4 -> 0.57472252 | F4: =Capital!F4/Production!F4 -> 0.57297005 | G4: =Capital!G4/Production!G4 -> 0.56859041 | H4: =Capital!H4/Production!H4 -> 0.56418904 | I4: =Capital!I4/Production!I4 -> 0.5598063 | ... AK4: =Capital!AK4/Production!AK4 -> 0.57446702
A5: y_sagr_0 | B5: =Capital!B5/Production!B5 -> 0.57725408 | C5: =Capital!C5/Production!C5 -> 0.5762539 | D5: =Capital!D5/Production!D5 -> 0.57544883 | E5: =Capital!E5/Production!E5 -> 0.57472252 | F5: =Capital!F5/Production!F5 -> 0.57297005 | G5: =Capital!G5/Production!G5 -> 0.56859041 | H5: =Capital!H5/Production!H5 -> 0.56381042 | I5: =Capital!I5/Production!I5 -> 0.55950462 | ... AK5: =Capital!AK5/Production!AK5 -> 0.58377488
A6: y_sfor_2 | B6: =Capital!B6/Production!B6 -> 0.28237955 | C6: =Capital!C6/Production!C6 -> 0.28802041 | D6: =Capital!D6/Production!D6 -> 0.2931403 | E6: =Capital!E6/Production!E6 -> 0.29800872 | F6: =Capital!F6/Production!F6 -> 0.30097404 | G6: =Capital!G6/Production!G6 -> 0.30275836 | H6: =Capital!H6/Production!H6 -> 0.30377946 | I6: =Capital!I6/Production!I6 -> 0.30598273 | ... AK6: =Capital!AK6/Production!AK6 -> 0.27797914
A7: y_sfor_0 | B7: =Capital!B7/Production!B7 -> 0.28237955 | C7: =Capital!C7/Production!C7 -> 0.28802041 | D7: =Capital!D7/Production!D7 -> 0.2931403 | E7: =Capital!E7/Production!E7 -> 0.29800872 | F7: =Capital!F7/Production!F7 -> 0.30097404 | G7: =Capital!G7/Production!G7 -> 0.30275836 | H7: =Capital!H7/Production!H7 -> 0.30370325 | I7: =Capital!I7/Production!I7 -> 0.30423268 | ... AK7: =Capital!AK7/Production!AK7 -> 0.28951048
A8: y_sfoo_2 | B8: =Capital!B8/Production!B8 -> 0.47229749 | C8: =Capital!C8/Production!C8 -> 0.47080096 | D8: =Capital!D8/Production!D8 -> 0.46966523 | E8: =Capital!E8/Production!E8 -> 0.46846533 | F8: =Capital!F8/Production!F8 -> 0.46652099 | G8: =Capital!G8/Production!G8 -> 0.46270907 | H8: =Capital!H8/Production!H8 -> 0.45918745 | I8: =Capital!I8/Production!I8 -> 0.45570148 | ... AK8: =Capital!AK8/Production!AK8 -> 0.46389281
A9: y_sfoo_0 | B9: =Capital!B9/Production!B9 -> 0.47229749 | C9: =Capital!C9/Production!C9 -> 0.47080096 | D9: =Capital!D9/Production!D9 -> 0.46966523 | E9: =Capital!E9/Production!E9 -> 0.46846533 | F9: =Capital!F9/Production!F9 -> 0.46652099 | G9: =Capital!G9/Production!G9 -> 0.46270907 | H9: =Capital!H9/Production!H9 -> 0.45891989 | I9: =Capital!I9/Production!I9 -> 0.45562924 | ... AK9: =Capital!AK9/Production!AK9 -> 0.47916195
A10: y_sveh_2 | B10: =Capital!B10/Production!B10 -> 3.1979996 | C10: =Capital!C10/Production!C10 -> 3.1499425 | D10: =Capital!D10/Production!D10 -> 3.1157701 | E10: =Capital!E10/Production!E10 -> 3.0995511 | F10: =Capital!F10/Production!F10 -> 3.0736169 | G10: =Capital!G10/Production!G10 -> 3.0290922 | H10: =Capital!H10/Production!H10 -> 3.0091748 | I10: =Capital!I10/Production!I10 -> 2.9956021 | ... AK10: =Capital!AK10/Production!AK10 -> 3.2077483
A11: y_sveh_0 | B11: =Capital!B11/Production!B11 -> 3.1979996 | C11: =Capital!C11/Production!C11 -> 3.1499425 | D11: =Capital!D11/Production!D11 -> 3.1157701 | E11: =Capital!E11/Production!E11 -> 3.0995511 | F11: =Capital!F11/Production!F11 -> 3.0736169 | G11: =Capital!G11/Production!G11 -> 3.0290922 | H11: =Capital!H11/Production!H11 -> 3.005323 | I11: =Capital!I11/Production!I11 -> 2.988729 | ... AK11: =Capital!AK11/Production!AK11 -> 3.2110958
A12: y_sgla_2 | B12: =Capital!B12/Production!B12 -> 0.72812366 | C12: =Capital!C12/Production!C12 -> 0.72608803 | D12: =Capital!D12/Production!D12 -> 0.72477592 | E12: =Capital!E12/Production!E12 -> 0.72454027 | F12: =Capital!F12/Production!F12 -> 0.72288322 | G12: =Capital!G12/Production!G12 -> 0.71752021 | H12: =Capital!H12/Production!H12 -> 0.7117047 | I12: =Capital!I12/Production!I12 -> 0.70653151 | ... AK12: =Capital!AK12/Production!AK12 -> 0.68495569
A13: y_sgla_0 | B13: =Capital!B13/Production!B13 -> 0.72812366 | C13: =Capital!C13/Production!C13 -> 0.72608803 | D13: =Capital!D13/Production!D13 -> 0.72477592 | E13: =Capital!E13/Production!E13 -> 0.72454027 | F13: =Capital!F13/Production!F13 -> 0.72288322 | G13: =Capital!G13/Production!G13 -> 0.71752021 | H13: =Capital!H13/Production!H13 -> 0.7112918 | I13: =Capital!I13/Production!I13 -> 0.70527576 | ... AK13: =Capital!AK13/Production!AK13 -> 0.71328007
... A67: y_seot_0 | B67: =Capital!B67/Production!B67 -> 0.59456653 | C67: =Capital!C67/Production!C67 -> 0.5961179 | D67: =Capital!D67/Production!D67 -> 0.60027416 | E67: =Capital!E67/Production!E67 -> 0.60467611 | F67: =Capital!F67/Production!F67 -> 0.60765956 | G67: =Capital!G67/Production!G67 -> 0.60701893 | H67: =Capital!H67/Production!H67 -> 0.60566075 | I67: =Capital!I67/Production!I67 -> 0.60431762 | ... AK67: =Capital!AK67/Production!AK67 -> 0.5992089

Sheet Carbontax
A1: _date_ | B1: 42005 | C1: 42370 | D1: 42736 | E1: 43101 | F1: 43466 | G1: 43831 | H1: 44197 | I1: 44562 | J1: 44927 | K1: 45292 | L1: 45658 | M1: 46023 | N1: 46388 | O1: 46753 | P1: 47119 | Q1: 47484 | R1: 47849 | S1: 48214 | T1: 48580 | U1: 48945 | V1: 49310 | W1: 49675 | X1: 50041 | Y1: 50406 | Z1: 50771 | AA1: 51136 | AB1: 51502 | AC1: 51867 | AD1: 52232 | AE1: 52597 | AF1: 52963 | AG1: 53328 | AH1: 53693 | AI1: 54058 | AJ1: 54424 | AK1: 54789
A2: t2val_ch_0 | B2: 1732.612 | C2: 2615.9669 | D2: 3567.0639 | E2: 5114.2089 | F2: 5077.8121 | G2: 5101.9503 | H2: 5083.4882 | I2: 5084.4352 | J2: 5092.8628 | K2: 5104.3817 | L2: 5118.9897 | M2: 5133.5219 | N2: 5148.6038 | O2: 5164.7041 | P2: 5182.0087 | Q2: 5200.4646 | R2: 5219.72 | S2: 5239.4286 | T2: 5259.3202 | U2: 5279.1958 | V2: 5297.7286 | W2: 5316.4681 | X2: 5334.9093 | Y2: 5352.7993 | Z2: 5370.0333 | AA2: 5383.3415 | AB2: 5395.4154 | AC2: 5405.6475 | AD2: 5413.7299 | AE2: 5419.65 | AF2: 5423.5061 | AG2: 5426.0594 | AH2: 5428.0281 | AI2: 5429.951 | AJ2: 5432.2002 | AK2: 5435.0165
A3: t2val_ch_2 | B3: 1732.612 | C3: 2615.9669 | D3: 3567.0639 | E3: 5114.2089 | F3: 5077.8121 | G3: 5101.9503 | H3: 5083.4016 | I3: 7558.3488 | J3: 11221.039 | K3: 16630.939 | L3: 24606.033 | M3: 26058.076 | N3: 27718.371 | O3: 29544.396 | P3: 31516.83 | Q3: 33629.412 | R3: 36644.989 | S3: 39887.424 | T3: 43360.432 | U3: 47081.188 | V3: 51065.513 | W3: 54170.42 | X3: 57463.325 | Y3: 60941.538 | Z3: 64608.768 | AA3: 68433.606 | AB3: 71596.391 | AC3: 74895.65 | AD3: 78322.977 | AE3: 81876.745 | AF3: 85559.292 | AG3: 88697.126 | AH3: 91934.184 | AI3: 95264.662 | AJ3: 98687.011 | AK3: 102202
A4: t2val_sec_0 | B4: 3328.0856 | C4: 5086.3384 | D4: 7054.5326 | E4: 10260.969 | F4: 10303.774 | G4: 10552.493 | H4: 10774.329 | I4: 11006.176 | J4: 11242.655 | K4: 11482.985 | L4: 11730.237 | M4: 11983.012 | N4: 12244.607 | O4: 12516.7 | P4: 12799.604 | Q4: 13092.843 | R4: 13380.416 | S4: 13672.192 | T4: 13969.931 | U4: 14273.986 | V4: 14583.123 | W4: 14884.395 | X4: 15188.173 | Y4: 15496.727 | Z4: 15810.826 | AA4: 16126.819 | AB4: 16377.537 | AC4: 16612.474 | AD4: 16842.039 | AE4: 17069.266 | AF4: 17295.577 | AG4: 17565.465 | AH4: 17849.277 | AI4: 18141.272 | AJ4: 18440.2 | AK4: 18745.712
A5: t2val_sec_2 | B5: 3328.0856 | C5: 5086.3384 | D5: 7054.5326 | E5: 10260.969 | F5: 10303.774 | G5: 10552.493 | H5: 10767.177 | I5: 16338.152 | J5: 24677.712 | K5: 37100.433 | L5: 55507.258 | M5: 59200.597 | N5: 63498.026 | O5: 68409.956 | P5: 73921.148 | Q5: 80017.517 | R5: 88467.001 | S5: 97687.653 | T5: 107699.94 | U5: 118554.67 | V5: 130316.85 | W5: 139867.47 | X5: 150085.07 | Y5: 161036.79 | Z5: 172771.17 | AA5: 185288.51 | AB5: 196108.92 | AC5: 207566.76 | AD5: 219710.03 | AE5: 232571.34 | AF5: 246183.1 | AG5: 258528.8 | AH5: 271544.16 | AI5: 285250.17 | AJ5: 299659.38 | AK5: 314785.11
A6: t2val_ci_0 | B6: 3106.9939 | C6: 4746.3343 | D6: 6576.9956 | E6: 9554.4215 | F6: 9587.9691 | G6: 9824.1278 | H6: 10031.748 | I6: 10248.588 | J6: 10469.565 | K6: 10693.971 | L6: 10924.799 | M6: 11160.762 | N6: 11405.067 | O6: 11659.334 | P6: 11923.849 | Q6: 12198.133 | R6: 12466.939 | S6: 12739.693 | T6: 13018.039 | U6: 13302.273 | V6: 13591.177 | W6: 13872.419 | X6: 14155.886 | Y6: 14443.695 | Z6: 14736.54 | AA6: 15030.905 | AB6: 15262.893 | AC6: 15479.882 | AD6: 15691.731 | AE6: 15901.26 | AF6: 16109.78 | AG6: 16359.638 | AH6: 16622.443 | AI6: 16892.785 | AJ6: 17169.558 | AK6: 17452.513
A7: t2val_ci_2 | B7: 3106.9939 | C7: 4746.3343 | D7: 6576.9956 | E7: 9554.4215 | F7: 9587.9691 | G7: 9824.1278 | H7: 10024.929 | I7: 15208.379 | J7: 22959.276 | K7: 34489.258 | L7: 51544.176 | M7: 54936.516 | N7: 58906.306 | O7: 63459.737 | P7: 68579.227 | Q7: 74249.053 | R7: 82101.584 | S7: 90665.222 | T7: 99955.614 | U7: 110017.65 | V7: 120909.79 | W7: 129743.28 | X7: 139191.33 | Y7: 149314.99 | Z7: 160157.46 | AA7: 171715.97 | AB7: 181694.94 | AC7: 192259.79 | AD7: 203453.27 | AE7: 215303.65 | AF7: 227839.05 | AG7: 239196.29 | AH7: 251166.74 | AI7: 263767.71 | AJ7: 277008.8 | AK7: 290900.55
A8: t2val_y_0 | B8: 0.39942416 | C8: 0.61419804 | D8: 0.86273467 | E8: 1.2778673 | F8: 1.2968857 | G8: 1.3235325 | H8: 1.3530777 | I8: 1.3835707 | J8: 1.4147564 | K8: 1.4466901 | L8: 1.4799139 | M8: 1.5139633 | N8: 1.5491788 | O8: 1.5856032 | P8: 1.6231345 | Q8: 1.6616173 | R8: 1.6987733 | S8: 1.7360457 | T8: 1.7735126 | U8: 1.8112386 | V8: 1.8490362 | W8: 1.8853194 | X8: 1.9216464 | Y8: 1.9582347 | Z8: 1.9952588 | AA8: 2.0320802 | AB8: 2.0598471 | AC8: 2.0857687 | AD8: 2.1105976 | AE8: 2.1348494 | AF8: 2.1589778 | AG8: 2.1893307 | AH8: 2.2218603 | AI8: 2.2563992 | AJ8: 2.292854 | AK8: 2.3310978
A9: t2val_y_2 | B9: 0.39942416 | C9: 0.61419804 | D9: 0.86273467 | E9: 1.2778673 | F9: 1.2968857 | G9: 1.3235325 | H9: 1.3520955 | I9: 2.0647454 | J9: 3.1554134 | K9: 4.8272263 | L9: 7.3965186 | M9: 8.0245402 | N9: 8.7074214 | O9: 9.453067 | P9: 10.264827 | Q9: 11.145054 | R9: 12.356291 | S9: 13.688299 | T9: 15.149943 | U9: 16.752915 | V9: 18.508816 | W9: 19.952216 | X9: 21.492627 | Y9: 23.140782 | Z9: 24.906588 | AA9: 26.789793 | AB9: 28.417279 | AC9: 30.131989 | AD9: 31.944696 | AE9: 33.865426 | AF9: 35.904052 | AG9: 37.753373 | AH9: 39.70187 | AI9: 41.757933 | AJ9: 43.928669 | AK9: 46.220744
A10: t2val_mat_0 | B10: 220.69222 | C10: 339.3899 | D10: 476.6742 | E10: 705.26956 | F10: 714.50787 | G10: 727.04198 | H10: 741.22729 | I10: 756.20448 | J10: 771.67569 | K10: 787.56729 | L10: 803.95721 | M10: 820.73648 | N10: 837.99103 | O10: 855.77978 | P10: 874.13184 | Q10: 893.0489 | R10: 911.7783 | S10: 930.76269 | T10: 950.1181 | U10: 969.90166 | V10: 990.09706 | W10: 1010.0901 | X10: 1030.3655 | Y10: 1051.0738 | Z10: 1072.2912 | AA10: 1093.8821 | AB10: 1112.5837 | AC10: 1130.506 | AD10: 1148.1969 | AE10: 1165.8708 | AF10: 1183.6386 | AG10: 1203.6377 | AH10: 1224.6123 | AI10: 1246.2315 | AJ10: 1268.3487 | AK10: 1290.8674
A11: t2val_mat_2 | B11: 220.69222 | C11: 339.3899 | D11: 476.6742 | E11: 705.26956 | F11: 714.50787 | G11: 727.04198 | H11: 740.89542 | I11: 1127.7085 | J11: 1715.2802 | K11: 2606.3481 | L11: 3955.6855 | M11: 4256.0567 | N11: 4583.013 | O11: 4940.7651 | P11: 5331.6562 | Q11: 5757.3185 | R11: 6353.0605 | S11: 7008.7419 | T11: 7729.1742 | U11: 8520.2648 | V11: 9388.5524 | W11: 10104.235 | X11: 10872.244 | Y11: 11698.656 | Z11: 12588.805 | AA11: 13545.744 | AB11: 14385.559 | AC11: 15276.846 | AD11: 16224.81 | AE11: 17233.821 | AF11: 18308.147 | AG11: 19294.761 | AH11: 20337.727 | AI11: 21440.701 | AJ11: 22606.654 | AK11: 23838.341

Sheet Production
A1: _date_ | B1: 42005 | C1: 42370 | D1: 42736 | E1: 43101 | F1: 43466 | G1: 43831 | H1: 44197 | I1: 44562 | J1: 44927 | K1: 45292 | L1: 45658 | M1: 46023 | N1: 46388 | O1: 46753 | P1: 47119 | Q1: 47484 | R1: 47849 | S1: 48214 | T1: 48580 | U1: 48945 | V1: 49310 | W1: 49675 | X1: 50041 | Y1: 50406 | Z1: 50771 | AA1: 51136 | AB1: 51502 | AC1: 51867 | AD1: 52232 | AE1: 52597 | AF1: 52963 | AG1: 53328 | AH1: 53693 | AI1: 54058 | AJ1: 54424 | AK1: 54789
A2: y_2 | B2: 3853438.3 | C2: 3913578.5 | D2: 3971218.3 | E2: 4025747.4 | F2: 4088090.5 | G2: 4171089.1 | H2: 4255554.7 | I2: 4342547 | J2: 4432219.4 | K2: 4525782.4 | L2: 4625280.2 | M2: 4723147.2 | N2: 4824685 | O2: 4930394 | P2: 5039255 | Q2: 5150165.3 | R2: 5259436.7 | S2: 5368036.8 | T2: 5475761.8 | U2: 5582901.7 | V2: 5689329.6 | W2: 5790395.1 | X2: 5890999 | Y2: 5992035.9 | Z2: 6093973.3 | AA2: 6195304.4 | AB2: 6292128.3 | AC2: 6388991.9 | AD2: 6486842.5 | AE2: 6586329.2 | AF2: 6687927.9 | AG2: 6790083.8 | AH2: 6894507 | AI2: 7001529.6 | AJ2: 7111264.5 | AK2: 7223728.3
A3: y_0 | B3: 3853438.3 | C3: 3913578.5 | D3: 3971218.3 | E3: 4025747.4 | F3: 4088090.5 | G3: 4171089.1 | H3: 4258072.3 | I3: 4346779.9 | J3: 4436969.4 | K3: 4528941.7 | L3: 4624036.2 | M3: 4721262.2 | N3: 4821551.4 | O3: 4925135.3 | P3: 5031896.1 | Q3: 5141558.2 | R3: 5248419.3 | S3: 5356236.8 | T3: 5465355.6 | U3: 5576004 | V3: 5687780.2 | W3: 5796504.1 | X3: 5906146.2 | Y3: 6017327 | Z3: 6130467.9 | AA3: 6244053 | AB3: 6335103 | AC3: 6421936.4 | AD3: 6506752.5 | AE3: 6590795.6 | AF3: 6674969.9 | AG3: 6775207.6 | AH3: 6880841.9 | AI3: 6990965.2 | AJ3: 7105125.9 | AK3: 7222951.4
A4: y_sagr_2 | B4: 81785.168 | C4: 82888.439 | D4: 83981.887 | E4: 85066.606 | F4: 86332.648 | G4: 88106.507 | H4: 90007.923 | I4: 92031.014 | J4: 94171.242 | K4: 96461.507 | L4: 98964.19 | M4: 101362.91 | N4: 103838.09 | O4: 106426.08 | P4: 109102.62 | Q4: 111834.02 | R4: 114526.35 | S4: 117190.46 | T4: 119806.2 | U4: 122372.6 | V4: 124881.46 | W4: 127203.03 | X4: 129474.07 | Y4: 131722.01 | Z4: 133961.98 | AA4: 136151.89 | AB4: 138191.28 | AC4: 140207.03 | AD4: 142227.83 | AE4: 144273.37 | AF4: 146358.16 | AG4: 148437.51 | AH4: 150561.28 | AI4: 152741.05 | AJ4: 154981.28 | AK4: 157283.28
A5: y_sagr_0 | B5: 81785.168 | C5: 82888.439 | D5: 83981.887 | E5: 85066.606 | F5: 86332.648 | G5: 88106.507 | H5: 90073.308 | I5: 92103.2 | J5: 94179.208 | K5: 96305.009 | L5: 98516.69 | M5: 100783.33 | N5: 103127.6 | O5: 105552.34 | P5: 108050.77 | Q5: 110612.54 | R5: 113085.98 | S5: 115567.18 | T5: 118061.32 | U5: 120572.71 | V5: 123088.87 | W5: 125504.21 | X5: 127922.47 | Y5: 130358.13 | Z5: 132822.79 | AA5: 135273.96 | AB5: 137122.38 | AC5: 138847.96 | AD5: 140500.8 | AE5: 142115.22 | AF5: 143721.43 | AG5: 145742 | AH5: 147907.47 | AI5: 150206.7 | AJ5: 152633.46 | AK5: 155179.32
A6: y_sfor_2 | B6: 6531.5683 | C6: 6468.742 | D6: 6408.5421 | E6: 6342.2118 | F6: 6308.1592 | G6: 6296.1724 | H6: 6296.7195 | I6: 6267.1529 | J6: 6214.7353 | K6: 6142.0059 | L6: 6051.8174 | M6: 6021.671 | N6: 6020.0963 | O6: 6031.7783 | P6: 6049.3757 | Q6: 6069.4396 | R6: 6083.1864 | S6: 6094.6671 | T6: 6104.7858 | U6: 6113.9856 | V6: 6120.9226 | W6: 6129.9608 | X6: 6141.5491 | Y6: 6154.4644 | Z6: 6168.1328 | AA6: 6177.8469 | AB6: 6187.9339 | AC6: 6200.3986 | AD6: 6214.6582 | AE6: 6230.3696 | AF6: 6247.3611 | AG6: 6266.4559 | AH6: 6287.7335 | AI6: 6310.7141 | AJ6: 6335.0963 | AK6: 6360.6719
A7: y_sfor_0 | B7: 6531.5683 | C7: 6468.742 | D7: 6408.5421 | E7: 6342.2118 | F7: 6308.1592 | G7: 6296.1724 | H7: 6298.4617 | I7: 6306.9025 | J7: 6319.7577 | K7: 6336.3597 | L7: 6359.0959 | M7: 6382.9666 | N7: 6408.7078 | O7: 6436.4219 | P7: 6466.0577 | Q7: 6497.5155 | R7: 6526.4599 | S7: 6556.4533 | T7: 6587.7495 | U7: 6620.4674 | V7: 6652.8847 | W7: 6683.8891 | X7: 6716.5874 | Y7: 6751.1066 | Z7: 6787.5339 | AA7: 6820.9432 | AB7: 6837.7323 | AC7: 6854.5058 | AD7: 6872.4813 | AE7: 6892.0273 | AF7: 6913.2884 | AG7: 6948.0476 | AH7: 6986.0718 | AI7: 7026.5394 | AJ7: 7069.145 | AK7: 7113.708
A8: y_sfoo_2 | B8: 157777.39 | C8: 160141.37 | D8: 162421.55 | E8: 164735.16 | F8: 167388.58 | G8: 170955.55 | H8: 174665.94 | I8: 178598.52 | J8: 182768.8 | K8: 187269.48 | L8: 192279.29 | M8: 196998.68 | N8: 201837.65 | O8: 206872.52 | P8: 212059.05 | Q8: 217337.24 | R8: 222574.11 | S8: 227766.58 | T8: 232884.33 | U8: 237932.5 | V8: 242890.92 | W8: 247538.62 | X8: 252093.09 | Y8: 256598.88 | Z8: 261083.42 | AA8: 265447.39 | AB8: 269540.96 | AC8: 273560.61 | AD8: 277559.8 | AE8: 281581.84 | AF8: 285660.94 | AG8: 289715.86 | AH8: 293835.97 | AI8: 298046.71 | AJ8: 302361.32 | AK8: 306787.27
A9: y_sfoo_0 | B9: 157777.39 | C9: 160141.37 | D9: 162421.55 | E9: 164735.16 | F9: 167388.58 | G9: 170955.55 | H9: 174776.8 | I9: 178674.69 | J9: 182632.66 | K9: 186655 | L9: 190821.51 | M9: 195073.93 | N9: 199468.89 | O9: 204019.4 | P9: 208713.72 | Q9: 213530.24 | R9: 218224.04 | S9: 222931.35 | T9: 227654.96 | U9: 232401.05 | V9: 237138.05 | W9: 241718.54 | X9: 246292.1 | Y9: 250879.64 | Z9: 255502.01 | AA9: 260058.82 | AB9: 263656.13 | AC9: 266996.58 | AD9: 270151.9 | AE9: 273189.37 | AF9: 276172.54 | AG9: 279786.37 | AH9: 283650.31 | AI9: 287762.87 | AJ9: 292116.35 | AK9: 296695.74
A10: y_sveh_2 | B10: 125550.78 | C10: 129068.3 | D10: 132266.42 | E10: 134863.11 | F10: 138072.48 | G10: 142471.63 | H10: 146017.79 | I10: 149474.06 | J10: 152984.99 | K10: 156592.38 | L10: 160229.73 | M10: 164105.04 | N10: 168186.25 | O10: 172313.61 | P10: 176425.62 | Q10: 180517.29 | R10: 184279 | S10: 187942.38 | T10: 191546.59 | U10: 195152.52 | V10: 198792.08 | W10: 202088.71 | X10: 205478.77 | Y10: 208964.77 | Z10: 212549.98 | AA10: 216201.46 | AB10: 219549.56 | AC10: 223038.57 | AD10: 226677.22 | AE10: 230468.38 | AF10: 234410.43 | AG10: 238387.08 | AH10: 242524.91 | AI10: 246813.42 | AJ10: 251242.97 | AK10: 255803.53
A11: y_sveh_0 | B11: 125550.78 | C11: 129068.3 | D11: 132266.42 | E11: 134863.11 | F11: 138072.48 | G11: 142471.63 | H11: 146219.5 | I11: 149876.64 | J11: 153568.41 | K11: 157385.65 | L11: 161387.5 | M11: 165499.06 | N11: 169747.8 | O11: 174112.91 | P11: 178580.37 | Q11: 183144.42 | R11: 187315.58 | S11: 191555.2 | T11: 195887.59 | U11: 200329.69 | V11: 204882.58 | W11: 209108.88 | X11: 213455.42 | Y11: 217948.28 | Z11: 222603.77 | AA11: 227395.81 | AB11: 230148.69 | AC11: 232972.55 | AD11: 235947.06 | AE11: 239101.37 | AF11: 242441.34 | AG11: 247334.61 | AH11: 252461.93 | AI11: 257759.36 | AJ11: 263193.46 | AK11: 268745.32
A12: y_sgla_2 | B12: 22084.892 | C12: 22401.864 | D12: 22699.258 | E12: 22959.581 | F12: 23268.984 | G12: 23724.178 | H12: 24225.888 | I12: 24735.017 | J12: 25227.255 | K12: 25690.641 | L12: 26116.194 | M12: 26540.177 | N12: 27005.878 | O12: 27522.509 | P12: 28084.763 | Q12: 28683.278 | R12: 29285.547 | S12: 29892.43 | T12: 30497.753 | U12: 31100.234 | V12: 31699.218 | W12: 32273.639 | X12: 32854.403 | Y12: 33447.425 | Z12: 34055.141 | AA12: 34671.59 | AB12: 35274.3 | AC12: 35889.652 | AD12: 36521.062 | AE12: 37169.901 | AF12: 37836.749 | AG12: 38515.485 | AH12: 39214.871 | AI12: 39935.103 | AJ12: 40674.943 | AK12: 41432.614
... A26: y_scon_2 | B26: 270916.74 | C26: 275024.44 | D26: 278703.89 | E26: 281671.37 | F26: 285340.34 | G26: 291433.84 | H26: 297854.99 | I26: 304158.65 | J26: 310127.36 | K26: 315671.24 | L26: 320868.95 | M26: 326291.63 | N26: 332325.14 | O26: 339109.9 | P26: 346622.52 | Q26: 354779.02 | R26: 363332.55 | S26: 372119.18 | T26: 381061.26 | U26: 390156.7 | V26: 399413.02 | W26: 408794.51 | X26: 418405.88 | Y26: 428316.47 | Z26: 438565.22 | AA26: 449077.95 | AB26: 459732.74 | AC26: 470538.45 | AD26: 481517.55 | AE26: 492694.92 | AF26: 504092.55 | AG26: 515695.3 | AH26: 527521.66 | AI26: 539579.23 | AJ26: 551865.52 | AK26: 564374.54
A27: y_scon_0 | B27: 270916.74 | C27: 275024.44 | D27: 278703.89 | E27: 281671.37 | F27: 285340.34 | G27: 291433.84 | H27: 297976.12 | I27: 304885.83 | J27: 311979.49 | K27: 319126.64 | L27: 326341.91 | M27: 333660.65 | N27: 341218.27 | O27: 349136.14 | P27: 357482.16 | Q27: 366278.42 | R27: 375373.86 | S27: 384796.61 | T27: 394569.92 | U27: 404708.2 | V27: 415185.93 | W27: 425882.56 | X27: 436836.2 | Y27: 448073.69 | Z27: 459606.84 | AA27: 471332.6 | AB27: 482539.73 | AC27: 493357.96 | AD27: 503888.31 | AE27: 514186.95 | AF27: 524275.97 | AG27: 534610.86 | AH27: 545085.88 | AI27: 555604.82 | AJ27: 566099.64 | AK27: 576524.4 | AL27: =AK26/AK27 -> 0.97892569
A28: y_srai_2 | B28: 6786.595 | C28: 6886.0416 | D28: 6975.4613 | E28: 7050.7087 | F28: 7140.3838 | G28: 7276.5254 | H28: 7409.8002 | I28: 7547.9648 | J28: 7693.0316 | K28: 7847.5528 | L28: 8013.4174 | M28: 8180.7172 | N28: 8355.1971 | O28: 8535.5009 | P28: 8718.8645 | Q28: 8903.1257 | R28: 9081.1149 | S28: 9254.1336 | T28: 9421.327 | U28: 9583.2408 | V28: 9740.1661 | W28: 9884.6068 | X28: 10025.986 | Y28: 10166.116 | Z28: 10306.02 | AA28: 10443.796 | AB28: 10572.903 | AC28: 10702.29 | AD28: 10833.702 | AE28: 10968.147 | AF28: 11106.278 | AG28: 11245.625 | AH28: 11389.171 | AI28: 11537.333 | AJ28: 11690.138 | AK28: 11847.444
A29: y_srai_0 | B29: 6786.595 | C29: 6886.0416 | D29: 6975.4613 | E29: 7050.7087 | F29: 7140.3838 | G29: 7276.5254 | H29: 7413.9829 | I29: 7552.9893 | J29: 7693.8265 | K29: 7838.0142 | L29: 7988.1439 | M29: 8142.368 | N29: 8301.5208 | O29: 8465.2737 | P29: 8633.0154 | Q29: 8804.134 | R29: 8968.244 | S29: 9132.5193 | T29: 9297.648 | U29: 9464.0918 | V29: 9631.4237 | W29: 9791.8675 | X29: 9953.0699 | Y29: 10116.278 | Z29: 10282.351 | AA29: 10449.356 | AB29: 10575.386 | AC29: 10695.253 | AD29: 10813.084 | AE29: 10931.06 | AF29: 11050.763 | AG29: 11200.868 | AH29: 11361.207 | AI29: 11530.103 | AJ29: 11706.78 | AK29: 11890.555
A30: y_sroa_2 | B30: 78075.665 | C30: 79219.737 | D30: 80248.458 | E30: 81114.133 | F30: 82145.791 | G30: 83712.018 | H30: 85245.263 | I30: 86834.763 | J30: 88503.669 | K30: 90281.341 | L30: 92189.513 | M30: 94114.196 | N30: 96121.482 | O30: 98195.768 | P30: 100305.25 | Q30: 102425.07 | R30: 104472.73 | S30: 106463.2 | T30: 108386.66 | U30: 110249.38 | V30: 112054.71 | W30: 113716.41 | X30: 115342.9 | Y30: 116955.01 | Z30: 118564.51 | AA30: 120149.55 | AB30: 121634.84 | AC30: 123123.37 | AD30: 124635.18 | AE30: 126181.89 | AF30: 127771.01 | AG30: 129374.1 | AH30: 131025.51 | AI30: 132730.02 | AJ30: 134487.95 | AK30: 136297.67
A31: y_sroa_0 | B31: 78075.665 | C31: 79219.737 | D31: 80248.458 | E31: 81114.133 | F31: 82145.791 | G31: 83712.018 | H31: 85293.382 | I31: 86892.567 | J31: 88512.813 | K31: 90171.606 | L31: 91898.757 | M31: 93673.012 | N31: 95503.968 | O31: 97387.847 | P31: 99317.614 | Q31: 101286.23 | R31: 103174.22 | S31: 105064.1 | T31: 106963.81 | U31: 108878.64 | V31: 110803.7 | W31: 112649.5 | X31: 114504.04 | Y31: 116381.65 | Z31: 118292.22 | AA31: 120213.51 | AB31: 121663.41 | AC31: 123042.41 | AD31: 124397.98 | AE31: 125755.23 | AF31: 127132.34 | AG31: 128859.21 | AH31: 130703.8 | AI31: 132646.85 | AJ31: 134679.41 | AK31: 136793.64
A32: y_swat_2 | B32: 15431.435 | C32: 15813.187 | D32: 16192.649 | E32: 16537.964 | F32: 16885.228 | G32: 17286.586 | H32: 17740.761 | I32: 18220.407 | J32: 18713.673 | K32: 19216.217 | L32: 19712.465 | M32: 20205.726 | N32: 20719.87 | O32: 21251.644 | P32: 21796.274 | Q32: 22349.811 | R32: 22866.063 | S32: 23381.254 | T32: 23889.744 | U32: 24388.925 | V32: 24878.84 | W32: 25295.624 | X32: 25714.906 | Y32: 26140.123 | Z32: 26573.462 | AA32: 27015.876 | AB32: 27406.904 | AC32: 27820.809 | AD32: 28258.396 | AE32: 28718.779 | AF32: 29200.562 | AG32: 29684.478 | AH32: 30192.469 | AI32: 30723.168 | AJ32: 31274.568 | AK32: 31844.349
A33: y_swat_0 | B33: 15431.435 | C33: 15813.187 | D33: 16192.649 | E33: 16537.964 | F33: 16885.228 | G33: 17286.586 | H33: 17769.065 | I33: 18268.84 | J33: 18783.923 | K33: 19321.096 | L33: 19882.62 | M33: 20457.558 | N33: 21046.506 | O33: 21645.576 | P33: 22254.011 | Q33: 22872.704 | R33: 23430.015 | S33: 23997.826 | T33: 24577.834 | U33: 25171.884 | V33: 25781.703 | W33: 26339.687 | X33: 26915.85 | Y33: 27512.565 | Z33: 28131.925 | AA33: 28775.056 | AB33: 29114.989 | AC33: 29477.767 | AD33: 29866.216 | AE33: 30281.445 | AF33: 30723.443 | AG33: 31393.925 | AH33: 32091.26 | AI33: 32812.559 | AJ33: 33555.566 | AK33: 34318.531
A34: y_sair_2 | B34: 20630.344 | C34: 21087.717 | D34: 21481.476 | E34: 21761.426 | F34: 22113.477 | G34: 22733.766 | H34: 23340.91 | I34: 23930.499 | J34: 24493.261 | K34: 25024.592 | L34: 25515.761 | M34: 26017.499 | N34: 26611.535 | O34: 27290.921 | P34: 28030.247 | Q34: 28806.417 | R34: 29561.637 | S34: 30293.858 | T34: 30992.699 | U34: 31659.903 | V34: 32296.656 | W34: 32873.354 | X34: 33447.07 | Y34: 34021.203 | Z34: 34595.982 | AA34: 35155.791 | AB34: 35670.705 | AC34: 36190.676 | AD34: 36719.544 | AE34: 37259.328 | AF34: 37811.271 | AG34: 38364.967 | AH34: 38938.131 | AI34: 39530.856 | AJ34: 40141.726 | AK34: 40769.052
A35: y_sair_0 | B35: 20630.344 | C35: 21087.717 | D35: 21481.476 | E35: 21761.426 | F35: 22113.477 | G35: 22733.766 | H35: 23365.646 | I35: 24002.699 | J35: 24651.982 | K35: 25320.625 | L35: 26021.768 | M35: 26745.123 | N35: 27497.751 | O35: 28278.265 | P35: 29083.295 | Q35: 29909.421 | R35: 30696.806 | S35: 31491.444 | T35: 32294.148 | U35: 33106.261 | V35: 33924.3 | W35: 34702.983 | X35: 35489.317 | Y35: 36286.799 | Z35: 37098.896 | AA35: 37912.622 | AB35: 38484.673 | AC35: 39034.748 | AD35: 39572.298 | AE35: 40105.872 | AF35: 40643.528 | AG35: 41353.943 | AH35: 42108.719 | AI35: 42907.608 | AJ35: 43749.619 | AK35: 44632.676
A36: y_spri_2 | B36: 2017751.5 | C36: 2049826.6 | D36: 2080796.5 | E36: 2110679.6 | F36: 2144986 | G36: 2190809.1 | H36: 2237065.9 | I36: 2284889.5 | J36: 2334699 | K36: 2387552.7 | L36: 2445206.2 | M36: 2501430.2 | N36: 2559423.6 | O36: 2619575.7 | P36: 2681287 | Q36: 2743913.3 | R36: 2805738.3 | S36: 2866980.2 | T36: 2927552.7 | U36: 2987673.4 | V36: 3047246.7 | W36: 3103832.5 | X36: 3159778.8 | Y36: 3215629.9 | Z36: 3271675.1 | AA36: 3326903.3 | AB36: 3379428 | AC36: 3431429.8 | AD36: 3483559.9 | AE36: 3536289.6 | AF36: 3589975.6 | AG36: 3643773.1 | AH36: 3698587.5 | AI36: 3754679.9 | AJ36: 3812170.9 | AK36: 3871118.5
A37: y_spri_0 | B37: 2017751.5 | C37: 2049826.6 | D37: 2080796.5 | E37: 2110679.6 | F37: 2144986 | G37: 2190809.1 | H37: 2238370.5 | I37: 2286621.2 | J37: 2335478.7 | K37: 2385131.1 | L37: 2436479.3 | M37: 2488990.4 | N37: 2543247.7 | O37: 2599409.5 | P37: 2657368.5 | Q37: 2716903.7 | R37: 2775101.9 | S37: 2833580.5 | T37: 2892523.9 | U37: 2952051 | V37: 3011869.3 | W37: 3070055.1 | X37: 3128401.1 | Y37: 3187278.1 | Z37: 3246941.8 | AA37: 3306378.1 | AB37: 3354452.2 | AC37: 3399424.5 | AD37: 3442676.9 | AE37: 3485032.1 | AF37: 3527122.2 | AG37: 3577047.3 | AH37: 3630196.1 | AI37: 3686086 | AJ37: 3744490.8 | AK37: 3805210.4
A38: y_spub_2 | B38: 539665.66 | C38: 546356.22 | D38: 553045.27 | E38: 559788.36 | F38: 566831.14 | G38: 574571.86 | H38: 582417.29 | I38: 590465.74 | J38: 598745.88 | K38: 607334.14 | L38: 616364.23 | M38: 625286.73 | N38: 634337.03 | O38: 643555.28 | P38: 652912.11 | Q38: 662373.9 | R38: 671869.8 | S38: 681396.84 | T38: 690949.63 | U38: 700539.91 | V38: 710154.81 | W38: 719659.84 | X38: 729174.14 | Y38: 738733.21 | Z38: 748357.91 | AA38: 757975.11 | AB38: 767500.68 | AC38: 777045.97 | AD38: 786656.2 | AE38: 796365.57 | AF38: 806200.54 | AG38: 816112.02 | AH38: 826152.91 | AI38: 836343.02 | AJ38: 846692.91 | AK38: 857208.94
A39: y_spub_0 | B39: 539665.66 | C39: 546356.22 | D39: 553045.27 | E39: 559788.36 | F39: 566831.14 | G39: 574571.86 | H39: 582485.09 | I39: 590502.19 | J39: 598619.48 | K39: 606846.79 | L39: 615244.45 | M39: 623771.79 | N39: 632462.63 | O39: 641325.69 | P39: 650353.4 | Q39: 659531.82 | R39: 668711.05 | S39: 677959.31 | T39: 687287 | U39: 696702.43 | V39: 706184.45 | W39: 715651.55 | X39: 725183.6 | Y39: 734802.93 | Z39: 744526.77 | AA39: 754280.95 | AB39: 763528.48 | AC39: 772632.99 | AD39: 781675.81 | AE39: 790713.41 | AF39: 799793.36 | AG39: 809341.17 | AH39: 819169.96 | AI39: 829259.1 | AJ39: 839596.43 | AK39: 850168.37
... A67: y_seot_0 | B67: 109.60596 | C67: 110.57357 | D67: 111.01736 | E67: 111.35141 | F67: 111.89965 | G67: 113.13275 | H67: 114.53458 | I67: 115.9758 | J67: 117.43804 | K67: 118.91491 | L67: 120.44029 | M67: 121.98248 | N67: 123.57133 | O67: 125.22195 | P67: 126.93886 | Q67: 128.71995 | R67: 130.43776 | S67: 132.18195 | T67: 133.96736 | U67: 135.79866 | V67: 137.66004 | W67: 139.46093 | X67: 141.29093 | Y67: 143.16676 | Z67: 145.09451 | AA67: 147.02478 | AB67: 148.44533 | AC67: 149.78626 | AD67: 151.12248 | AE67: 152.47586 | AF67: 153.85489 | AG67: 155.6097 | AH67: 157.47868 | AI67: 159.41681 | AJ67: 161.41199 | AK67: 163.46017

Sheet Capital
A1: _date_ | B1: 42005 | C1: 42370 | D1: 42736 | E1: 43101 | F1: 43466 | G1: 43831 | H1: 44197 | I1: 44562 | J1: 44927 | K1: 45292 | L1: 45658 | M1: 46023 | N1: 46388 | O1: 46753 | P1: 47119 | Q1: 47484 | R1: 47849 | S1: 48214 | T1: 48580 | U1: 48945 | V1: 49310 | W1: 49675 | X1: 50041 | Y1: 50406 | Z1: 50771 | AA1: 51136 | AB1: 51502 | AC1: 51867 | AD1: 52232 | AE1: 52597 | AF1: 52963 | AG1: 53328 | AH1: 53693 | AI1: 54058 | AJ1: 54424 | AK1: 54789
A2: f_k_2 | B2: 5223444.3 | C2: 5285439.8 | D2: 5349307.5 | E2: 5413622.9 | F2: 5479884 | G2: 5552470.6 | H2: 5631075.8 | I2: 5714891.4 | J2: 5802948.4 | K2: 5894251.9 | L2: 5987994.7 | M2: 6084708.2 | N2: 6185297.3 | O2: 6290708.4 | P2: 6401715.2 | Q2: 6518868.1 | R2: 6642121.7 | S2: 6771223.4 | T2: 6905851 | U2: 7045730.9 | V2: 7190638.6 | W2: 7340174.3 | X2: 7494230.7 | Y2: 7652857.8 | Z2: 7816174.9 | AA2: 7984173.4 | AB2: 8156491.9 | AC2: 8332928.8 | AD2: 8513392.9 | AE2: 8697863.6 | AF2: 8886365.8 | AG2: 9078866.9 | AH2: 9275394 | AI2: 9475998 | AJ2: 9680726.9 | AK2: 9889616.6
A3: f_k_0 | B3: 5223444.3 | C3: 5285439.8 | D3: 5349307.5 | E3: 5413622.9 | F3: 5479884 | G3: 5552470.6 | H3: 5631351.7 | I3: 5716612.8 | J3: 5808051 | K3: 5905304.3 | L3: 6008099.2 | M3: 6116243.3 | N3: 6229773.2 | O3: 6348896.9 | P3: 6473890.1 | Q3: 6605023.3 | R3: 6742099.2 | S3: 6885085.7 | T3: 7034035.5 | U3: 7189036.3 | V3: 7350132.5 | W3: 7516985.3 | X3: 7689461.9 | Y3: 7867535.9 | Z3: 8051223.4 | AA3: 8240382.5 | AB3: 8432834.1 | AC3: 8627344.9 | AD3: 8823192.7 | AE3: 9019898.1 | AF3: 9217097.4 | AG3: 9415780.2 | AH3: 9616361.9 | AI3: 9818939.6 | AJ3: 10023459 | AK3: 10229792
A4: f_k_sagr_2 | B4: 47210.822 | C4: 47764.786 | D4: 48327.278 | E4: 48889.694 | F4: 49466.022 | G4: 50096.515 | H4: 50781.483 | I4: 51519.541 | J4: 52308.192 | K4: 53145.407 | L4: 54031.722 | M4: 54969.325 | N4: 55963.313 | O4: 57020.111 | P4: 58144.815 | Q4: 59340.255 | R4: 60603.411 | S4: 61929.187 | T4: 63311.272 | U4: 64743.341 | V4: 66219.105 | W4: 67729.03 | X4: 69267.282 | Y4: 70830.262 | Z4: 72415.56 | AA4: 74019.389 | AB4: 75634.2 | AC4: 77255.539 | AD4: 78881.081 | AE4: 80509.896 | AF4: 82141.999 | AG4: 83776.501 | AH4: 85413.741 | AI4: 87054.802 | AJ4: 88701.079 | AK4: 90354.056
A5: f_k_sagr_0 | B5: 47210.822 | C5: 47764.786 | D5: 48327.278 | E5: 48889.694 | F5: 49466.022 | G5: 50096.515 | H5: 50784.27 | I5: 51532.167 | J5: 52339.526 | K5: 53204.345 | L5: 54125.857 | M5: 55103.315 | N5: 56137.494 | O5: 57230.089 | P5: 58382.817 | Q5: 59596.889 | R5: 60867.723 | S5: 62192.55 | T5: 63569.421 | U5: 64996.732 | V5: 66472.389 | W5: 67990.145 | X5: 69546.436 | Y5: 71139.089 | Z5: 72766.683 | AA5: 74426.157 | AB5: 76091.519 | AC5: 77748.716 | AD5: 79389.848 | AE5: 81010.233 | AF5: 82607.285 | AG5: 84195.183 | AH5: 85782.23 | AI5: 87374.076 | AJ5: 88975.286 | AK5: 90589.79
A6: f_k_sfor_2 | B6: 1844.3813 | C6: 1863.1297 | D6: 1878.6019 | E6: 1890.0344 | F6: 1898.5921 | G6: 1906.2188 | H6: 1912.8141 | I6: 1917.6406 | J6: 1919.8937 | K6: 1918.8259 | L6: 1913.8086 | M6: 1906.326 | N6: 1897.6112 | O6: 1888.4564 | P6: 1879.3337 | Q6: 1870.5212 | R6: 1862.0097 | S6: 1853.7444 | T6: 1845.6761 | U6: 1837.7761 | V6: 1830.0096 | W6: 1822.4703 | X6: 1815.2672 | Y6: 1808.4826 | Z6: 1802.1712 | AA6: 1796.2969 | AB6: 1790.8835 | AC6: 1785.978 | AD6: 1781.618 | AE6: 1777.826 | AF6: 1774.6127 | AG6: 1772.0149 | AH6: 1770.0616 | AI6: 1768.7658 | AJ6: 1768.1268 | AK6: 1768.1341
A7: f_k_sfor_0 | B7: 1844.3813 | C7: 1863.1297 | D7: 1878.6019 | E7: 1890.0344 | F7: 1898.5921 | G7: 1906.2188 | H7: 1912.8633 | I7: 1918.7659 | J7: 1924.0447 | K7: 1928.7585 | L7: 1933.0064 | M7: 1936.8458 | N7: 1940.3622 | O7: 1943.664 | P7: 1946.8638 | Q7: 1950.0674 | R7: 1953.3031 | S7: 1956.6346 | T7: 1960.1377 | U7: 1963.8865 | V7: 1967.9185 | W7: 1972.2381 | X7: 1976.8896 | Y7: 1981.9258 | Z7: 1987.3962 | AA7: 1993.2562 | AB7: 1999.2145 | AC7: 2005.1922 | AD7: 2011.1956 | AE7: 2017.2545 | AF7: 2023.3989 | AG7: 2029.8397 | AH7: 2036.6574 | AI7: 2043.8733 | AJ7: 2051.487 | AK7: 2059.493
A8: f_k_sfoo_2 | B8: 74517.868 | C8: 75394.71 | D8: 76283.754 | E8: 77172.709 | F8: 78090.286 | G8: 79102.686 | H8: 80204.408 | I8: 81387.608 | J8: 82643.639 | K8: 83965.517 | L8: 85352.119 | M8: 86808.726 | N8: 88345.424 | O8: 89974.103 | P8: 91704.063 | Q8: 93540.69 | R8: 95480.764 | S8: 97517.345 | T8: 99641.767 | U8: 101845.68 | V8: 104120.8 | W8: 106455.47 | X8: 108842.52 | Y8: 111277.41 | Z8: 113756.93 | AA8: 116274.88 | AB8: 118820.47 | AC8: 121386.19 | AD8: 123967.1 | AE8: 126560.31 | AF8: 129164.49 | AG8: 131777.43 | AH8: 134398.44 | AI8: 137027.92 | AJ8: 139666.83 | AK8: 142316.41
A9: f_k_sfoo_0 | B9: 74517.868 | C9: 75394.71 | D9: 76283.754 | E9: 77172.709 | F9: 78090.286 | G9: 79102.686 | H9: 80208.551 | I9: 81409.412 | J9: 82701.775 | K9: 84080.019 | L9: 85540.957 | M9: 87082.103 | N9: 88704.384 | O9: 90410.937 | P9: 92205.242 | Q9: 94089.984 | R9: 96060.228 | S9: 98112.857 | T9: 100245.44 | U9: 102455.78 | V9: 104740.54 | W9: 107091.43 | X9: 109503.33 | Y9: 111972.62 | Z9: 114496.54 | AA9: 117068.91 | AB9: 119655.18 | AC9: 122234.85 | AD9: 124794.56 | AE9: 127325.13 | AF9: 129820.46 | AG9: 132296.26 | AH9: 134762.06 | AI9: 137224.88 | AJ9: 139690.81 | AK9: 142165.31
A10: f_k_sveh_2 | B10: 401511.35 | C10: 406557.73 | D10: 412111.74 | E10: 418015.09 | F10: 424381.92 | G10: 431559.71 | H10: 439393.07 | I10: 447764.82 | J10: 456605.49 | K10: 465868.61 | L10: 475504.41 | M10: 485568.94 | N10: 496124.9 | O10: 507197.95 | P10: 518784.53 | Q10: 530868.12 | R10: 543356.19 | S10: 556178.8 | T10: 569284.69 | U10: 582644.33 | V10: 596243.94 | W10: 610002.18 | X10: 623908.19 | Y10: 637974.49 | Z10: 652220.3 | AA10: 666658.11 | AB10: 681219.25 | AC10: 695902.52 | AD10: 710730.37 | AE10: 725731.87 | AF10: 740936.48 | AG10: 756349.81 | AH10: 771994.77 | AI10: 787896.3 | AJ10: 804076.48 | AK10: 820553.34
A11: f_k_sveh_0 | B11: 401511.35 | C11: 406557.73 | D11: 412111.74 | E11: 418015.09 | F11: 424381.92 | G11: 431559.71 | H11: 439436.83 | I11: 447940.66 | J11: 457027.71 | K11: 466679.79 | L11: 476900.7 | M11: 487690.31 | N11: 499057.13 | O11: 511010.13 | P11: 523555.32 | Q11: 536695.69 | R11: 550330.19 | S11: 564423.35 | T11: 578967.29 | U11: 593965.64 | V11: 609424.69 | W11: 625256.89 | X11: 641442.21 | Y11: 657988.29 | Z11: 674913.43 | AA11: 692230.98 | AB11: 709475.78 | AC11: 726504.59 | AD11: 743301.82 | AE11: 759896.25 | AF11: 776329.37 | AG11: 792946.09 | AH11: 809883.3 | AI11: 827191.29 | AJ11: 844885.58 | AK11: 862966.95
A12: f_k_sgla_2 | B12: 16080.533 | C12: 16265.725 | D12: 16451.876 | E12: 16635.141 | F12: 16820.758 | G12: 17022.577 | H12: 17241.678 | I12: 17476.069 | J12: 17721.745 | K12: 17973.52 | L12: 18225.703 | M12: 18479.569 | N12: 18738.649 | O12: 19007.136 | P12: 19288.781 | Q12: 19586.482 | R12: 19900.727 | S12: 20231.15 | T12: 20576.881 | U12: 20936.934 | V12: 21310.339 | W12: 21695.749 | X12: 22092.892 | Y12: 22502.046 | Z12: 22923.697 | AA12: 23358.023 | AB12: 23804.252 | AC12: 24262.245 | AD12: 24732.18 | AE12: 25214.338 | AF12: 25709 | AG12: 26216.356 | AH12: 26736.774 | AI12: 27270.626 | AJ12: 27818.169 | AK12: 28379.504
... A26: f_k_scon_2 | B26: 1693874.9 | C26: 1713763.9 | D26: 1734105.1 | E26: 1754404.3 | F26: 1775008.3 | G26: 1797328.8 | H26: 1821578.8 | I26: 1847598.4 | J26: 1875031.6 | K26: 1903426.6 | L26: 1932353.9 | M26: 1961896.5 | N26: 1992367.7 | O26: 2024180.9 | P26: 2057745.5 | Q26: 2093415.2 | R26: 2131390 | S26: 2171738.8 | T26: 2214459.9 | U26: 2259535.3 | V26: 2306948.8 | W26: 2356699.4 | X26: 2408822.6 | Y26: 2463389.9 | Z26: 2520494 | AA26: 2580196.5 | AB26: 2642501.7 | AC26: 2707381.7 | AD26: 2774804.1 | AE26: 2844742.5 | AF26: 2917177.8 | AG26: 2992095.7 | AH26: 3069479 | AI26: 3149308.5 | AJ26: 3231559.3 | AK26: 3316199.8
A27: f_k_scon_0 | B27: 1693874.9 | C27: 1713763.9 | D27: 1734105.1 | E27: 1754404.3 | F27: 1775008.3 | G27: 1797328.8 | H27: 1821638.5 | I27: 1848121.2 | J27: 1876803.8 | K27: 1907597.2 | L27: 1940390.1 | M27: 1975100.6 | N27: 2011730.4 | O27: 2050364.9 | P27: 2091141.9 | Q27: 2134218.5 | R27: 2179696 | S27: 2227666.2 | T27: 2278225.2 | U27: 2331470.6 | V27: 2387484.1 | W27: 2446290.1 | X27: 2507908 | Y27: 2572361.5 | Z27: 2639674.3 | AA27: 2709816.7 | AB27: 2782455.8 | AC27: 2857222.6 | AD27: 2933782.6 | AE27: 3011834.7 | AF27: 3091094.8 | AG27: 3171463.6 | AH27: 3252846.5 | AI27: 3335106.5 | AJ27: 3418067.5 | AK27: 3501528.5 | AL27: =AK26/AK27 -> 0.94707204
A28: f_k_srai_2 | B28: 4359.527 | C28: 4411.0816 | D28: 4463.46 | E28: 4514.9853 | F28: 4566.8536 | G28: 4623.6454 | H28: 4684.5312 | I28: 4749.0491 | J28: 4816.8211 | K28: 4887.5664 | L28: 4961.0909 | M28: 5038.1338 | N28: 5119.4996 | O28: 5205.8424 | P28: 5297.568 | Q28: 5394.8594 | R28: 5497.3428 | S28: 5604.3901 | T28: 5715.2611 | U28: 5829.2532 | V28: 5945.7349 | W28: 6063.9676 | X28: 6183.5293 | Y28: 6304.1766 | Z28: 6425.7594 | AA28: 6548.0655 | AB28: 6670.6449 | AC28: 6793.2941 | AD28: 6915.961 | AE28: 7038.6758 | AF28: 7161.5148 | AG28: 7284.5174 | AH28: 7407.7937 | AI28: 7531.4812 | AJ28: 7655.7153 | AK28: 7780.6172
A29: f_k_srai_0 | B29: 4359.527 | C29: 4411.0816 | D29: 4463.46 | E29: 4514.9853 | F29: 4566.8536 | G29: 4623.6454 | H29: 4684.7386 | I29: 4750.0705 | J29: 4819.4073 | K29: 4892.5095 | L29: 4969.2805 | M29: 5049.6684 | N29: 5133.7351 | O29: 5221.5972 | P29: 5313.3642 | Q29: 5409.1093 | R29: 5508.4672 | S29: 5611.2377 | T29: 5717.3051 | U29: 5826.5919 | V29: 5939.0035 | W29: 6054.1119 | X29: 6171.7084 | Y29: 6291.7025 | Z29: 6414.0645 | AA29: 6538.6804 | AB29: 6663.6501 | AC29: 6788.0413 | AD29: 6911.4304 | AE29: 7033.635 | AF29: 7154.5998 | AG29: 7275.5023 | AH29: 7396.9873 | AI29: 7519.4305 | AJ29: 7643.0914 | AK29: 7768.1698
A30: f_k_sroa_2 | B30: 43522.728 | C30: 44038.801 | D30: 44561.784 | E30: 45071.167 | F30: 45581.287 | G30: 46146.232 | H30: 46753.738 | I30: 47398.31 | J30: 48075.411 | K30: 48781.387 | L30: 49513.064 | M30: 50279.893 | N30: 51091.568 | O30: 51955.849 | P30: 52877.703 | Q30: 53859.664 | R30: 54898.115 | S30: 55986.177 | T30: 57115.517 | U30: 58278.15 | V30: 59466.901 | W30: 60674.067 | X30: 61895.13 | Y30: 63127.369 | Z30: 64369.005 | AA30: 65617.65 | AB30: 66868.778 | AC30: 68120.27 | AD30: 69371.473 | AE30: 70622.525 | AF30: 71873.992 | AG30: 73126.251 | AH30: 74380.328 | AI30: 75637.47 | AJ30: 76898.867 | AK30: 78165.537
A31: f_k_sroa_0 | B31: 43522.728 | C31: 44038.801 | D31: 44561.784 | E31: 45071.167 | F31: 45581.287 | G31: 46146.232 | H31: 46755.837 | I31: 47409.271 | J31: 48103.844 | K31: 48836.835 | L31: 49607.005 | M31: 50413.675 | N31: 51257.412 | O31: 52139.407 | P31: 53060.827 | Q31: 54022.483 | R31: 55020.814 | S31: 56053.909 | T31: 57120.691 | U31: 58220.449 | V31: 59352.287 | W31: 60511.95 | X31: 61697.359 | Y31: 62907.6 | Z31: 64142.34 | AA31: 65400.393 | AB31: 66662.671 | AC31: 67919.769 | AD31: 69167.353 | AE31: 70403.466 | AF31: 71627.398 | AG31: 72850.76 | AH31: 74079.797 | AI31: 75318.061 | AJ31: 76567.956 | AK31: 77831.317
A32: f_k_swat_2 | B32: 25745.773 | C32: 26063.336 | D32: 26411.253 | E32: 26786.683 | F32: 27189.686 | G32: 27626.453 | H32: 28101.74 | I32: 28617.3 | J32: 29172.792 | K32: 29766.769 | L32: 30396.208 | M32: 31059.158 | N32: 31756.482 | O32: 32489.471 | P32: 33258.863 | Q32: 34064.665 | R32: 34901.473 | S32: 35766.206 | T32: 36656.165 | U32: 37568.618 | V32: 38500.927 | W32: 39443.497 | X32: 40393.094 | Y32: 41349.017 | Z32: 42311.562 | AA32: 43281.37 | AB32: 44252.232 | AC32: 45224.185 | AD32: 46199.431 | AE32: 47180.683 | AF32: 48170.596 | AG32: 49169.539 | AH32: 50179.616 | AI32: 51203.29 | AJ32: 52242.834 | AK32: 53300.147
A33: f_k_swat_0 | B33: 25745.773 | C33: 26063.336 | D33: 26411.253 | E33: 26786.683 | F33: 27189.686 | G33: 27626.453 | H33: 28104.885 | I33: 28628.004 | J33: 29196.628 | K33: 29811.396 | L33: 30473.196 | M33: 31182.027 | N33: 31937.866 | O33: 32740.357 | P33: 33588.929 | Q33: 34482.985 | R33: 35414.041 | S33: 36379.102 | T33: 37377.232 | U33: 38408.304 | V33: 39472.568 | W33: 40562.763 | X33: 41677.217 | Y33: 42816.383 | Z33: 43981.533 | AA33: 45174.172 | AB33: 46358.404 | AC33: 47524.667 | AD33: 48672.731 | AE33: 49805.283 | AF33: 50925.786 | AG33: 52061.089 | AH33: 53221.29 | AI33: 54410.372 | AJ33: 55630.121 | AK33: 56881.427
A34: f_k_sair_2 | B34: 14913.04 | C34: 15093.019 | D34: 15281.667 | E34: 15469.419 | F34: 15661.654 | G34: 15882.274 | H34: 16128.47 | I34: 16395.883 | J34: 16678.897 | K34: 16971.363 | L34: 17266.996 | M34: 17567.724 | N34: 17879.478 | O34: 18208.584 | P34: 18559.891 | Q34: 18936.426 | R34: 19337.178 | S34: 19759.565 | T34: 20200.137 | U34: 20655.442 | V34: 21122.248 | W34: 21596.785 | X34: 22077.52 | Y34: 22563.769 | Z34: 23055.075 | AA34: 23550.266 | AB34: 24046.821 | AC34: 24543.886 | AD34: 25041.304 | AE34: 25539.191 | AF34: 26037.774 | AG34: 26537.061 | AH34: 27037.632 | AI34: 27540.201 | AJ34: 28045.407 | AK34: 28553.753
A35: f_k_sair_0 | B35: 14913.04 | C35: 15093.019 | D35: 15281.667 | E35: 15469.419 | F35: 15661.654 | G35: 15882.274 | H35: 16129.734 | I35: 16404.243 | J35: 16705.097 | K35: 17031.579 | L35: 17383.686 | M35: 17761.433 | N35: 18165.401 | O35: 18596.403 | P35: 19055.161 | Q35: 19542.162 | R35: 20054.995 | S35: 20592.517 | T35: 21154.052 | U35: 21739.094 | V35: 22346.969 | W35: 22974.736 | X35: 23621.028 | Y35: 24285.144 | Z35: 24966.699 | AA35: 25664.672 | AB35: 26365.822 | AC35: 27064.231 | AD35: 27756.994 | AE35: 28442.54 | AF35: 29120.076 | AG35: 29797.442 | AH35: 30478.412 | AI35: 31165.298 | AJ35: 31859.898 | AK35: 32563.762
A36: f_k_spri_2 | B36: 1988889 | C36: 2012555.3 | D36: 2036863.5 | E36: 2061298.4 | F36: 2086566 | G36: 2114469.6 | H36: 2144747.4 | I36: 2177036 | J36: 2210982.4 | K36: 2246287.2 | L36: 2282799.8 | M36: 2320776.4 | N36: 2360561.4 | O36: 2402490.7 | P36: 2446807.6 | Q36: 2493650 | R36: 2542927.1 | S36: 2594461.4 | T36: 2648058.2 | U36: 2703554.8 | V36: 2760810.3 | W36: 2819619.7 | X36: 2879881.5 | Y36: 2941556.4 | Z36: 3004633.4 | AA36: 3069031.6 | AB36: 3134544.1 | AC36: 3201025.1 | AD36: 3268388.5 | AE36: 3336593.3 | AF36: 3405631.3 | AG36: 3475474.9 | AH36: 3546124.1 | AI36: 3617597.8 | AJ36: 3689922.7 | AK36: 3763129.3
A37: f_k_spri_0 | B37: 1988889 | C37: 2012555.3 | D37: 2036863.5 | E37: 2061298.4 | F37: 2086566 | G37: 2114469.6 | H37: 2144857.2 | I37: 2177687.1 | J37: 2212814.5 | K37: 2250047.9 | L37: 2289262.3 | M37: 2330376 | N37: 2373407.4 | O37: 2418441.2 | P37: 2465576.4 | Q37: 2514895 | R37: 2566292.2 | S37: 2619710.2 | T37: 2675118.7 | U37: 2732498.3 | V37: 2791805.4 | W37: 2852866.2 | X37: 2915582.2 | Y37: 2979898.5 | Z37: 3045780.8 | AA37: 3113117.1 | AB37: 3181068.4 | AC37: 3249133.7 | AD37: 3317019.1 | AE37: 3384540.9 | AF37: 3451579.8 | AG37: 3518538.8 | AH37: 3585647.7 | AI37: 3653035.1 | AJ37: 3720785.2 | AK37: 3788962
A38: f_k_spub_2 | B38: 436500.74 | C38: 441579.28 | D38: 446674.06 | E38: 451679.2 | F38: 456729.32 | G38: 462113.01 | H38: 467728.02 | I38: 473470.44 | J38: 479241.8 | K38: 484946.84 | L38: 490505.05 | M38: 495996.71 | N38: 501503.74 | O38: 507095.73 | P38: 512824.71 | Q38: 518727.26 | R38: 524811.35 | S38: 531070.15 | T38: 537494.55 | U38: 544079.66 | V38: 550824.21 | W38: 557738.45 | X38: 564835.5 | Y38: 572128.81 | Z38: 579630.34 | AA38: 587344.7 | AB38: 595273.58 | AC38: 603414.39 | AD38: 611764.06 | AE38: 620319.71 | AF38: 629078.55 | AG38: 638040.67 | AH38: 647204.21 | AI38: 656566.14 | AJ38: 666122.35 | AK38: 675868.21
A39: f_k_spub_0 | B39: 436500.74 | C39: 441579.28 | D39: 446674.06 | E39: 451679.2 | F39: 456729.32 | G39: 462113.01 | H39: 467738.14 | I39: 473583.66 | J39: 479618.58 | K39: 485803.7 | L39: 492106.48 | M39: 498507.62 | N39: 505005.39 | O39: 511609.77 | P39: 518334.5 | Q39: 525192.55 | R39: 532190.02 | S39: 539334.82 | T39: 546635.52 | U39: 554100.04 | V39: 561733.06 | W39: 569534.29 | X39: 577505.58 | Y39: 585649.06 | Z39: 593965.73 | AA39: 602448.79 | AB39: 611067.43 | AC39: 619804.4 | AD39: 628649.6 | AE39: 637595.08 | AF39: 646632.79 | AG39: 655768.22 | AH39: 664996.98 | AI39: 674309.3 | AJ39: 683694.16 | AK39: 693141.34
... A67: f_k_seot_0 | B67: 65.168033 | C67: 65.914886 | D67: 66.640855 | E67: 67.331537 | F67: 67.996892 | G67: 68.673719 | H67: 69.369097 | I67: 70.08622 | J67: 70.824643 | K67: 71.58232 | L67: 72.358448 | M67: 73.15212 | N67: 73.964127 | O67: 74.796615 | P67: 75.652252 | Q67: 76.53364 | R67: 77.438568 | S67: 78.36677 | T67: 79.319185 | U67: 80.297221 | V67: 81.301667 | W67: 82.329739 | X67: 83.380966 | Y67: 84.456191 | Z67: 85.556759 | AA67: 86.681966 | AB67: 87.811465 | AC67: 88.935625 | AD67: 90.051387 | AE67: 91.158483 | AF67: 92.257677 | AG67: 93.362918 | AH67: 94.481759 | AI67: 95.617669 | AJ67: 96.772341 | AK67: 97.946788

Sheet Results
A1: NB : on crée ici une liste : - globale, qui fusionne les sorties des reportings 1, 2 et 3 - "rationalisée" : suppression des doublons, et regroupements par thématique On continue par la suite à avoir 2 Excels de reporting (un "energie", fusion des reportings 1 et 2), et un "économie" (reporting 3)), dans lesquels on copiera cet onglet "results" (généré automatiquement par EViews). --> puis voir à la fin si on peut pas importer les graphs et tableaux dans l'excel automatiquement généré (éviterait les copiés collés, mais à voir si ça prend trop de temps, et si c'est pas trop gros comme excel)
A2: Nom du bloc de variables utilisé dans le code | B2: Sous-bloc de variables pour plus de lisibilité dans le Excel | E2: Year | F2: =date!B3 -> 2015 | G2: =date!C3 -> 2016 | H2: =date!D3 -> 2017 | I2: =date!E3 -> 2018 | J2: =date!F3 -> 2019 | K2: =date!G3 -> 2020 | L2: =date!H3 -> 2021 | M2: =date!I3 -> 2022 | ... AO2: =date!AK3 -> 2050
A3: HYBRID | B3: AUTOMOBILES (thousands) | C3: TOTAL STOCK SHOCK | E3: AUTO_2 | F3: =VLOOKUP($E3,Hybrid!$1:$1048576,MATCH(DATE(F$2,1,1),Hybrid!$A$1:$LI$1),FALSE) -> 32317.941 | G3: =VLOOKUP($E3,Hybrid!$1:$1048576,MATCH(DATE(G$2,1,1),Hybrid!$A$1:$LI$1),FALSE) -> 32010.864 | H3: =VLOOKUP($E3,Hybrid!$1:$1048576,MATCH(DATE(H$2,1,1),Hybrid!$A$1:$LI$1),FALSE) -> 31809.838 | I3: =VLOOKUP($E3,Hybrid!$1:$1048576,MATCH(DATE(I$2,1,1),Hybrid!$A$1:$LI$1),FALSE) -> 31619.962 | J3: =VLOOKUP($E3,Hybrid!$1:$1048576,MATCH(DATE(J$2,1,1),Hybrid!$A$1:$LI$1),FALSE) -> 31633.548 | K3: =VLOOKUP($E3,Hybrid!$1:$1048576,MATCH(DATE(K$2,1,1),Hybrid!$A$1:$LI$1),FALSE) -> 32018.121 | L3: =VLOOKUP($E3,Hybrid!$1:$1048576,MATCH(DATE(L$2,1,1),Hybrid!$A$1:$LI$1),FALSE) -> 32309.847 | M3: =VLOOKUP($E3,Hybrid!$1:$1048576,MATCH(DATE(M$2,1,1),Hybrid!$A$1:$LI$1),FALSE) -> 32597.019 | ... AO3: =VLOOKUP($E3,Hybrid!$1:$1048576,MATCH(DATE(AO$2,1,1),Hybrid!$A$1:$LI$1),FALSE) -> 44079.584
C4: OIL | E4: AUTO_cfut_2 | F4: =VLOOKUP($E4,Hybrid!$1:$1048576,MATCH(DATE(F$2,1,1),Hybrid!$A$1:$LI$1),FALSE) -> 32271.24 | G4: =VLOOKUP($E4,Hybrid!$1:$1048576,MATCH(DATE(G$2,1,1),Hybrid!$A$1:$LI$1),FALSE) -> 31945.681 | H4: =VLOOKUP($E4,Hybrid!$1:$1048576,MATCH(DATE(H$2,1,1),Hybrid!$A$1:$LI$1),FALSE) -> 31726.506 | I4: =VLOOKUP($E4,Hybrid!$1:$1048576,MATCH(DATE(I$2,1,1),Hybrid!$A$1:$LI$1),FALSE) -> 31518.017 | J4: =VLOOKUP($E4,Hybrid!$1:$1048576,MATCH(DATE(J$2,1,1),Hybrid!$A$1:$LI$1),FALSE) -> 31508.065 | K4: =VLOOKUP($E4,Hybrid!$1:$1048576,MATCH(DATE(K$2,1,1),Hybrid!$A$1:$LI$1),FALSE) -> 31864.988 | L4: =VLOOKUP($E4,Hybrid!$1:$1048576,MATCH(DATE(L$2,1,1),Hybrid!$A$1:$LI$1),FALSE) -> 32131.068 | M4: =VLOOKUP($E4,Hybrid!$1:$1048576,MATCH(DATE(M$2,1,1),Hybrid!$A$1:$LI$1),FALSE) -> 32392.83 | ... AO4: =VLOOKUP($E4,Hybrid!$1:$1048576,MATCH(DATE(AO$2,1,1),Hybrid!$A$1:$LI$1),FALSE) -> 42511.874
D5: class A | E5: AUTO_ca_cfut_2 | F5: =VLOOKUP($E5,Hybrid!$1:$1048576,MATCH(DATE(F$2,1,1),Hybrid!$A$1:$LI$1),FALSE) -> 7095.7005 | G5: =VLOOKUP($E5,Hybrid!$1:$1048576,MATCH(DATE(G$2,1,1),Hybrid!$A$1:$LI$1),FALSE) -> 7163.595 | H5: =VLOOKUP($E5,Hybrid!$1:$1048576,MATCH(DATE(H$2,1,1),Hybrid!$A$1:$LI$1),FALSE) -> 7253.3446 | I5: =VLOOKUP($E5,Hybrid!$1:$1048576,MATCH(DATE(I$2,1,1),Hybrid!$A$1:$LI$1),FALSE) -> 7342.6292 | J5: =VLOOKUP($E5,Hybrid!$1:$1048576,MATCH(DATE(J$2,1,1),Hybrid!$A$1:$LI$1),FALSE) -> 7487.9362 | K5: =VLOOKUP($E5,Hybrid!$1:$1048576,MATCH(DATE(K$2,1,1),Hybrid!$A$1:$LI$1),FALSE) -> 7734.59 | L5: =VLOOKUP($E5,Hybrid!$1:$1048576,MATCH(DATE(L$2,1,1),Hybrid!$A$1:$LI$1),FALSE) -> 7946.437 | M5: =VLOOKUP($E5,Hybrid!$1:$1048576,MATCH(DATE(M$2,1,1),Hybrid!$A$1:$LI$1),FALSE) -> 8154.1169 | ... AO5: =VLOOKUP($E5,Hybrid!$1:$1048576,MATCH(DATE(AO$2,1,1),Hybrid!$A$1:$LI$1),FALSE) -> 15676.456
D6: class B | E6: AUTO_cb_cfut_2 | F6: =VLOOKUP($E6,Hybrid!$1:$1048576,MATCH(DATE(F$2,1,1),Hybrid!$A$1:$LI$1),FALSE) -> 8251.2564 | G6: =VLOOKUP($E6,Hybrid!$1:$1048576,MATCH(DATE(G$2,1,1),Hybrid!$A$1:$LI$1),FALSE) -> 8204.1818 | H6: =VLOOKUP($E6,Hybrid!$1:$1048576,MATCH(DATE(H$2,1,1),Hybrid!$A$1:$LI$1),FALSE) -> 8186.0524 | I6: =VLOOKUP($E6,Hybrid!$1:$1048576,MATCH(DATE(I$2,1,1),Hybrid!$A$1:$LI$1),FALSE) -> 8173.2987 | J6: =VLOOKUP($E6,Hybrid!$1:$1048576,MATCH(DATE(J$2,1,1),Hybrid!$A$1:$LI$1),FALSE) -> 8218.6024 | K6: =VLOOKUP($E6,Hybrid!$1:$1048576,MATCH(DATE(K$2,1,1),Hybrid!$A$1:$LI$1),FALSE) -> 8366.7584 | L6: =VLOOKUP($E6,Hybrid!$1:$1048576,MATCH(DATE(L$2,1,1),Hybrid!$A$1:$LI$1),FALSE) -> 8488.5781 | M6: =VLOOKUP($E6,Hybrid!$1:$1048576,MATCH(DATE(M$2,1,1),Hybrid!$A$1:$LI$1),FALSE) -> 8610.9099 | ... AO6: =VLOOKUP($E6,Hybrid!$1:$1048576,MATCH(DATE(AO$2,1,1),Hybrid!$A$1:$LI$1),FALSE) -> 13505.803
D7: class C | E7: AUTO_cc_cfut_2 | F7: =VLOOKUP($E7,Hybrid!$1:$1048576,MATCH(DATE(F$2,1,1),Hybrid!$A$1:$LI$1),FALSE) -> 6777.6025 | G7: =VLOOKUP($E7,Hybrid!$1:$1048576,MATCH(DATE(G$2,1,1),Hybrid!$A$1:$LI$1),FALSE) -> 6661.8607 | H7: =VLOOKUP($E7,Hybrid!$1:$1048576,MATCH(DATE(H$2,1,1),Hybrid!$A$1:$LI$1),FALSE) -> 6572.095 | I7: =VLOOKUP($E7,Hybrid!$1:$1048576,MATCH(DATE(I$2,1,1),Hybrid!$A$1:$LI$1),FALSE) -> 6490.4961 | J7: =VLOOKUP($E7,Hybrid!$1:$1048576,MATCH(DATE(J$2,1,1),Hybrid!$A$1:$LI$1),FALSE) -> 6452.4548 | K7: =VLOOKUP($E7,Hybrid!$1:$1048576,MATCH(DATE(K$2,1,1),Hybrid!$A$1:$LI$1),FALSE) -> 6489.804 | L7: =VLOOKUP($E7,Hybrid!$1:$1048576,MATCH(DATE(L$2,1,1),Hybrid!$A$1:$LI$1),FALSE) -> 6514.1247 | M7: =VLOOKUP($E7,Hybrid!$1:$1048576,MATCH(DATE(M$2,1,1),Hybrid!$A$1:$LI$1),FALSE) -> 6542.2438 | ... AO7: =VLOOKUP($E7,Hybrid!$1:$1048576,MATCH(DATE(AO$2,1,1),Hybrid!$A$1:$LI$1),FALSE) -> 8434.9071
D8: class D | E8: AUTO_cd_cfut_2 | F8: =VLOOKUP($E8,Hybrid!$1:$1048576,MATCH(DATE(F$2,1,1),Hybrid!$A$1:$LI$1),FALSE) -> 4159.6639 | G8: =VLOOKUP($E8,Hybrid!$1:$1048576,MATCH(DATE(G$2,1,1),Hybrid!$A$1:$LI$1),FALSE) -> 4063.5393 | H8: =VLOOKUP($E8,Hybrid!$1:$1048576,MATCH(DATE(H$2,1,1),Hybrid!$A$1:$LI$1),FALSE) -> 3982.8175 | I8: =VLOOKUP($E8,Hybrid!$1:$1048576,MATCH(DATE(I$2,1,1),Hybrid!$A$1:$LI$1),FALSE) -> 3906.3668 | J8: =VLOOKUP($E8,Hybrid!$1:$1048576,MATCH(DATE(J$2,1,1),Hybrid!$A$1:$LI$1),FALSE) -> 3852.9234 | K8: =VLOOKUP($E8,Hybrid!$1:$1048576,MATCH(DATE(K$2,1,1),Hybrid!$A$1:$LI$1),FALSE) -> 3840.4882 | L8: =VLOOKUP($E8,Hybrid!$1:$1048576,MATCH(DATE(L$2,1,1),Hybrid!$A$1:$LI$1),FALSE) -> 3822.2448 | M8: =VLOOKUP($E8,Hybrid!$1:$1048576,MATCH(DATE(M$2,1,1),Hybrid!$A$1:$LI$1),FALSE) -> 3805.6208 | ... AO8: =VLOOKUP($E8,Hybrid!$1:$1048576,MATCH(DATE(AO$2,1,1),Hybrid!$A$1:$LI$1),FALSE) -> 3028.637
D9: class E | E9: AUTO_ce_cfut_2 | F9: =VLOOKUP($E9,Hybrid!$1:$1048576,MATCH(DATE(F$2,1,1),Hybrid!$A$1:$LI$1),FALSE) -> 2503.7292 | G9: =VLOOKUP($E9,Hybrid!$1:$1048576,MATCH(DATE(G$2,1,1),Hybrid!$A$1:$LI$1),FALSE) -> 2448.5604 | H9: =VLOOKUP($E9,Hybrid!$1:$1048576,MATCH(DATE(H$2,1,1),Hybrid!$A$1:$LI$1),FALSE) -> 2401.7659 | I9: =VLOOKUP($E9,Hybrid!$1:$1048576,MATCH(DATE(I$2,1,1),Hybrid!$A$1:$LI$1),FALSE) -> 2355.8796 | J9: =VLOOKUP($E9,Hybrid!$1:$1048576,MATCH(DATE(J$2,1,1),Hybrid!$A$1:$LI$1),FALSE) -> 2321.9985 | K9: =VLOOKUP($E9,Hybrid!$1:$1048576,MATCH(DATE(K$2,1,1),Hybrid!$A$1:$LI$1),FALSE) -> 2311.6313 | L9: =VLOOKUP($E9,Hybrid!$1:$1048576,MATCH(DATE(L$2,1,1),Hybrid!$A$1:$LI$1),FALSE) -> 2297.3429 | M9: =VLOOKUP($E9,Hybrid!$1:$1048576,MATCH(DATE(M$2,1,1),Hybrid!$A$1:$LI$1),FALSE) -> 2282.7834 | ... AO9: =VLOOKUP($E9,Hybrid!$1:$1048576,MATCH(DATE(AO$2,1,1),Hybrid!$A$1:$LI$1),FALSE) -> 1293.8522
D10: class F | E10: AUTO_cf_cfut_2 | F10: =VLOOKUP($E10,Hybrid!$1:$1048576,MATCH(DATE(F$2,1,1),Hybrid!$A$1:$LI$1),FALSE) -> 1243.6668 | G10: =VLOOKUP($E10,Hybrid!$1:$1048576,MATCH(DATE(G$2,1,1),Hybrid!$A$1:$LI$1),FALSE) -> 1213.8476 | H10: =VLOOKUP($E10,Hybrid!$1:$1048576,MATCH(DATE(H$2,1,1),Hybrid!$A$1:$LI$1),FALSE) -> 1186.9708 | I10: =VLOOKUP($E10,Hybrid!$1:$1048576,MATCH(DATE(I$2,1,1),Hybrid!$A$1:$LI$1),FALSE) -> 1158.6962 | J10: =VLOOKUP($E10,Hybrid!$1:$1048576,MATCH(DATE(J$2,1,1),Hybrid!$A$1:$LI$1),FALSE) -> 1133.8751 | K10: =VLOOKUP($E10,Hybrid!$1:$1048576,MATCH(DATE(K$2,1,1),Hybrid!$A$1:$LI$1),FALSE) -> 1118.247 | L10: =VLOOKUP($E10,Hybrid!$1:$1048576,MATCH(DATE(L$2,1,1),Hybrid!$A$1:$LI$1),FALSE) -> 1100.4708 | M10: =VLOOKUP($E10,Hybrid!$1:$1048576,MATCH(DATE(M$2,1,1),Hybrid!$A$1:$LI$1),FALSE) -> 1081.3056 | ... AO10: =VLOOKUP($E10,Hybrid!$1:$1048576,MATCH(DATE(AO$2,1,1),Hybrid!$A$1:$LI$1),FALSE) -> 255.40576
D11: class G | E11: AUTO_cg_cfut_2 | F11: =VLOOKUP($E11,Hybrid!$1:$1048576,MATCH(DATE(F$2,1,1),Hybrid!$A$1:$LI$1),FALSE) -> 2239.6206 | G11: =VLOOKUP($E11,Hybrid!$1:$1048576,MATCH(DATE(G$2,1,1),Hybrid!$A$1:$LI$1),FALSE) -> 2190.0963 | H11: =VLOOKUP($E11,Hybrid!$1:$1048576,MATCH(DATE(H$2,1,1),Hybrid!$A$1:$LI$1),FALSE) -> 2143.4602 | I11: =VLOOKUP($E11,Hybrid!$1:$1048576,MATCH(DATE(I$2,1,1),Hybrid!$A$1:$LI$1),FALSE) -> 2090.6508 | J11: =VLOOKUP($E11,Hybrid!$1:$1048576,MATCH(DATE(J$2,1,1),Hybrid!$A$1:$LI$1),FALSE) -> 2040.2746 | K11: =VLOOKUP($E11,Hybrid!$1:$1048576,MATCH(DATE(K$2,1,1),Hybrid!$A$1:$LI$1),FALSE) -> 2003.4687 | L11: =VLOOKUP($E11,Hybrid!$1:$1048576,MATCH(DATE(L$2,1,1),Hybrid!$A$1:$LI$1),FALSE) -> 1961.8698 | M11: =VLOOKUP($E11,Hybrid!$1:$1048576,MATCH(DATE(M$2,1,1),Hybrid!$A$1:$LI$1),FALSE) -> 1915.8497 | ... AO11: =VLOOKUP($E11,Hybrid!$1:$1048576,MATCH(DATE(AO$2,1,1),Hybrid!$A$1:$LI$1),FALSE) -> 316.81297
C12: ELEC | E12: AUTO_cele_2 | F12: =VLOOKUP($E12,Hybrid!$1:$1048576,MATCH(DATE(F$2,1,1),Hybrid!$A$1:$LI$1),FALSE) -> 44.765 | G12: =VLOOKUP($E12,Hybrid!$1:$1048576,MATCH(DATE(G$2,1,1),Hybrid!$A$1:$LI$1),FALSE) -> 63.184204 | H12: =VLOOKUP($E12,Hybrid!$1:$1048576,MATCH(DATE(H$2,1,1),Hybrid!$A$1:$LI$1),FALSE) -> 81.267092 | I12: =VLOOKUP($E12,Hybrid!$1:$1048576,MATCH(DATE(I$2,1,1),Hybrid!$A$1:$LI$1),FALSE) -> 99.820025 | J12: =VLOOKUP($E12,Hybrid!$1:$1048576,MATCH(DATE(J$2,1,1),Hybrid!$A$1:$LI$1),FALSE) -> 123.28585 | K12: =VLOOKUP($E12,Hybrid!$1:$1048576,MATCH(DATE(K$2,1,1),Hybrid!$A$1:$LI$1),FALSE) -> 150.83685 | L12: =VLOOKUP($E12,Hybrid!$1:$1048576,MATCH(DATE(L$2,1,1),Hybrid!$A$1:$LI$1),FALSE) -> 176.39535 | M12: =VLOOKUP($E12,Hybrid!$1:$1048576,MATCH(DATE(M$2,1,1),Hybrid!$A$1:$LI$1),FALSE) -> 201.72272 | ... AO12: =VLOOKUP($E12,Hybrid!$1:$1048576,MATCH(DATE(AO$2,1,1),Hybrid!$A$1:$LI$1),FALSE) -> 1563.4995
D13: class A | E13: AUTO_ca_cele_2 | F13: =VLOOKUP($E13,Hybrid!$1:$1048576,MATCH(DATE(F$2,1,1),Hybrid!$A$1:$LI$1),FALSE) -> 9.8427899 | G13: =VLOOKUP($E13,Hybrid!$1:$1048576,MATCH(DATE(G$2,1,1),Hybrid!$A$1:$LI$1),FALSE) -> 15.183587 | H13: =VLOOKUP($E13,Hybrid!$1:$1048576,MATCH(DATE(H$2,1,1),Hybrid!$A$1:$LI$1),FALSE) -> 20.45814 | I13: =VLOOKUP($E13,Hybrid!$1:$1048576,MATCH(DATE(I$2,1,1),Hybrid!$A$1:$LI$1),FALSE) -> 25.97122 | J13: =VLOOKUP($E13,Hybrid!$1:$1048576,MATCH(DATE(J$2,1,1),Hybrid!$A$1:$LI$1),FALSE) -> 33.113699 | K13: =VLOOKUP($E13,Hybrid!$1:$1048576,MATCH(DATE(K$2,1,1),Hybrid!$A$1:$LI$1),FALSE) -> 41.540103 | L13: =VLOOKUP($E13,Hybrid!$1:$1048576,MATCH(DATE(L$2,1,1),Hybrid!$A$1:$LI$1),FALSE) -> 49.400939 | M13: =VLOOKUP($E13,Hybrid!$1:$1048576,MATCH(DATE(M$2,1,1),Hybrid!$A$1:$LI$1),FALSE) -> 57.279668 | ... AO13: =VLOOKUP($E13,Hybrid!$1:$1048576,MATCH(DATE(AO$2,1,1),Hybrid!$A$1:$LI$1),FALSE) -> 593.04452
D14: class B | E14: AUTO_cb_cele_2 | F14: =VLOOKUP($E14,Hybrid!$1:$1048576,MATCH(DATE(F$2,1,1),Hybrid!$A$1:$LI$1),FALSE) -> 11.445717 | G14: =VLOOKUP($E14,Hybrid!$1:$1048576,MATCH(DATE(G$2,1,1),Hybrid!$A$1:$LI$1),FALSE) -> 16.490827 | H14: =VLOOKUP($E14,Hybrid!$1:$1048576,MATCH(DATE(H$2,1,1),Hybrid!$A$1:$LI$1),FALSE) -> 21.459313 | I14: =VLOOKUP($E14,Hybrid!$1:$1048576,MATCH(DATE(I$2,1,1),Hybrid!$A$1:$LI$1),FALSE) -> 26.663425 | J14: =VLOOKUP($E14,Hybrid!$1:$1048576,MATCH(DATE(J$2,1,1),Hybrid!$A$1:$LI$1),FALSE) -> 33.46949 | K14: =VLOOKUP($E14,Hybrid!$1:$1048576,MATCH(DATE(K$2,1,1),Hybrid!$A$1:$LI$1),FALSE) -> 41.519739 | L14: =VLOOKUP($E14,Hybrid!$1:$1048576,MATCH(DATE(L$2,1,1),Hybrid!$A$1:$LI$1),FALSE) -> 49.021052 | M14: =VLOOKUP($E14,Hybrid!$1:$1048576,MATCH(DATE(M$2,1,1),Hybrid!$A$1:$LI$1),FALSE) -> 56.529979 | ... AO14: =VLOOKUP($E14,Hybrid!$1:$1048576,MATCH(DATE(AO$2,1,1),Hybrid!$A$1:$LI$1),FALSE) -> 517.18033
D15: class C | E15: AUTO_cc_cele_2 | F15: =VLOOKUP($E15,Hybrid!$1:$1048576,MATCH(DATE(F$2,1,1),Hybrid!$A$1:$LI$1),FALSE) -> 9.4015406 | G15: =VLOOKUP($E15,Hybrid!$1:$1048576,MATCH(DATE(G$2,1,1),Hybrid!$A$1:$LI$1),FALSE) -> 12.832838 | H15: =VLOOKUP($E15,Hybrid!$1:$1048576,MATCH(DATE(H$2,1,1),Hybrid!$A$1:$LI$1),FALSE) -> 16.202642 | I15: =VLOOKUP($E15,Hybrid!$1:$1048576,MATCH(DATE(I$2,1,1),Hybrid!$A$1:$LI$1),FALSE) -> 19.739118 | J15: =VLOOKUP($E15,Hybrid!$1:$1048576,MATCH(DATE(J$2,1,1),Hybrid!$A$1:$LI$1),FALSE) -> 24.40642 | K15: =VLOOKUP($E15,Hybrid!$1:$1048576,MATCH(DATE(K$2,1,1),Hybrid!$A$1:$LI$1),FALSE) -> 29.941402 | L15: =VLOOKUP($E15,Hybrid!$1:$1048576,MATCH(DATE(L$2,1,1),Hybrid!$A$1:$LI$1),FALSE) -> 35.093184 | M15: =VLOOKUP($E15,Hybrid!$1:$1048576,MATCH(DATE(M$2,1,1),Hybrid!$A$1:$LI$1),FALSE) -> 40.243356 | ... AO15: =VLOOKUP($E15,Hybrid!$1:$1048576,MATCH(DATE(AO$2,1,1),Hybrid!$A$1:$LI$1),FALSE) -> 324.95954
D16: class D | E16: AUTO_cd_cele_2 | F16: =VLOOKUP($E16,Hybrid!$1:$1048576,MATCH(DATE(F$2,1,1),Hybrid!$A$1:$LI$1),FALSE) -> 5.7700713 | G16: =VLOOKUP($E16,Hybrid!$1:$1048576,MATCH(DATE(G$2,1,1),Hybrid!$A$1:$LI$1),FALSE) -> 7.6428377 | H16: =VLOOKUP($E16,Hybrid!$1:$1048576,MATCH(DATE(H$2,1,1),Hybrid!$A$1:$LI$1),FALSE) -> 9.4920994 | I16: =VLOOKUP($E16,Hybrid!$1:$1048576,MATCH(DATE(I$2,1,1),Hybrid!$A$1:$LI$1),FALSE) -> 11.326103 | J16: =VLOOKUP($E16,Hybrid!$1:$1048576,MATCH(DATE(J$2,1,1),Hybrid!$A$1:$LI$1),FALSE) -> 13.474679 | K16: =VLOOKUP($E16,Hybrid!$1:$1048576,MATCH(DATE(K$2,1,1),Hybrid!$A$1:$LI$1),FALSE) -> 15.973369 | L16: =VLOOKUP($E16,Hybrid!$1:$1048576,MATCH(DATE(L$2,1,1),Hybrid!$A$1:$LI$1),FALSE) -> 18.287422 | M16: =VLOOKUP($E16,Hybrid!$1:$1048576,MATCH(DATE(M$2,1,1),Hybrid!$A$1:$LI$1),FALSE) -> 20.543924 | ... AO16: =VLOOKUP($E16,Hybrid!$1:$1048576,MATCH(DATE(AO$2,1,1),Hybrid!$A$1:$LI$1),FALSE) -> 81.879316
