Workbook
Name formatResults: [1]ResultsEXR10!$A$50

Sheet Export
A1: _date_ | B1: 42005 | C1: 42370 | D1: 42736 | E1: 43101 | F1: 43466 | G1: 43831 | H1: 44197 | I1: 44562 | J1: 44927 | K1: 45292 | L1: 45658 | M1: 46023 | N1: 46388 | O1: 46753 | P1: 47119 | Q1: 47484 | R1: 47849 | S1: 48214 | T1: 48580 | U1: 48945 | V1: 49310 | W1: 49675 | X1: 50041 | Y1: 50406 | Z1: 50771 | AA1: 51136 | AB1: 51502 | AC1: 51867 | AD1: 52232 | AE1: 52597 | AF1: 52963 | AG1: 53328 | AH1: 53693 | AI1: 54058 | AJ1: 54424 | AK1: 54789
A2: x_2 | B2: 641440.93 | C2: 656549 | D2: 672089.72 | E2: 688109.81 | F2: 704772.14 | G2: 721948.72 | H2: 739239.18 | I2: 746134.7 | J2: 752317.16 | K2: 767039.96 | L2: 780590.88 | M2: 793499.2 | N2: 805506.71 | O2: 816228.54 | P2: 827765.8 | Q2: 840654.2 | R2: 854029.84 | S2: 868237.84 | T2: 883256.14 | U2: 899190.25 | V2: 916570.48 | W2: 936063.75 | X2: 958404.52 | Y2: 983802.61 | Z2: 1011860.7 | AA2: 1041973.6 | AB2: 1073645.3 | AC2: 1106673.4 | AD2: 1140894 | AE2: 1176124.6 | AF2: 1212454.2 | AG2: 1250277.4 | AH2: 1289830.1 | AI2: 1330776.6 | AJ2: 1372369.7 | AK2: 1413753.1
A3: x_0 | B3: 641440.93 | C3: 656549 | D3: 672089.72 | E3: 688109.81 | F3: 704772.14 | G3: 721948.72 | H3: 738857.91 | I3: 754935.79 | J3: 770047.91 | K3: 784535.12 | L3: 798996.96 | M3: 813973.37 | N3: 829037.75 | O3: 842670.72 | P3: 856062.18 | Q3: 869905.93 | R3: 884459.9 | S3: 900782.21 | T3: 919117.49 | U3: 939316.15 | V3: 961204.04 | W3: 984568.76 | X3: 1009525.2 | Y3: 1036208.3 | Z3: 1064689.9 | AA3: 1095221.7 | AB3: 1128048.2 | AC3: 1163469.4 | AD3: 1201285.8 | AE3: 1240609.4 | AF3: 1280538 | AG3: 1320658.9 | AH3: 1360988.5 | AI3: 1401683 | AJ3: 1442847.2 | AK3: 1484419.3
A4: x_cagr_2 | B4: 15794.537 | C4: 16161.639 | D4: 16546.562 | E4: 16945.424 | F4: 17363.002 | G4: 17792.648 | H4: 18217.526 | I4: 18358.705 | J4: 18439.829 | K4: 18702.695 | L4: 18929.432 | M4: 19158.021 | N4: 19395 | O4: 19631.81 | P4: 19910.952 | Q4: 20233.81 | R4: 20586.363 | S4: 20948.185 | T4: 21316.274 | U4: 21697.167 | V4: 22111.91 | W4: 22584.748 | X4: 23138.482 | Y4: 23778.397 | Z4: 24489.747 | AA4: 25249.525 | AB4: 26024.039 | AC4: 26814.423 | AD4: 27620.543 | AE4: 28449.113 | AF4: 29315.4 | AG4: 30237.583 | AH4: 31222.199 | AI4: 32255.505 | AJ4: 33310.556 | AK4: 34359.14
A5: x_cagr_0 | B5: 15794.537 | C5: 16161.639 | D5: 16546.562 | E5: 16945.424 | F5: 17363.002 | G5: 17792.648 | H5: 18201.852 | I5: 18570.473 | J5: 18896.79 | K5: 19197.309 | L5: 19496.59 | M5: 19815.502 | N5: 20147.363 | O5: 20455.075 | P5: 20764.265 | Q5: 21086.598 | R5: 21443.021 | S5: 21847.628 | T5: 22304.328 | U5: 22805.481 | V5: 23342.502 | W5: 23907.224 | X5: 24502.446 | Y5: 25134.228 | Z5: 25808.439 | AA5: 26534.967 | AB5: 27321.432 | AC5: 28174.209 | AD5: 29085.331 | AE5: 30029.947 | AF5: 30985.197 | AG5: 31943.32 | AH5: 32909.035 | AI5: 33890.377 | AJ5: 34892.283 | AK5: 35913.119
A6: x_cfor_2 | B6: 374.1272 | C6: 383.03443 | D6: 392.59543 | E6: 402.7843 | F6: 413.60973 | G6: 424.80938 | H6: 435.89146 | I6: 440.41118 | J6: 443.57714 | K6: 451.13683 | L6: 457.83734 | M6: 464.51663 | N6: 471.35807 | O6: 478.20034 | P6: 486.10253 | Q6: 495.08059 | R6: 504.76862 | S6: 514.62098 | T6: 524.48654 | U6: 534.46792 | V6: 545.06767 | W6: 556.91147 | X6: 570.61549 | Y6: 586.36171 | Z6: 603.81339 | AA6: 622.38985 | AB6: 641.20057 | AC6: 660.20342 | AD6: 679.32033 | AE6: 698.67977 | AF6: 718.68089 | AG6: 739.84219 | AH6: 762.40748 | AI6: 786.09529 | AJ6: 810.2532 | AK6: 834.1561
A7: x_cfor_0 | B7: 374.1272 | C7: 383.03443 | D7: 392.59543 | E7: 402.7843 | F7: 413.60973 | G7: 424.80938 | H7: 435.54698 | I7: 445.24283 | J7: 453.78537 | K7: 461.54918 | L7: 469.15704 | M7: 477.17334 | N7: 485.50202 | O7: 493.2957 | P7: 501.19187 | Q7: 509.46419 | R7: 518.53622 | S7: 528.70454 | T7: 540.04346 | U7: 552.35523 | V7: 565.41553 | W7: 579.00362 | X7: 593.16427 | Y7: 608.03219 | Z7: 623.75744 | AA7: 640.60506 | AB7: 658.79235 | AC7: 678.49866 | AD7: 699.53848 | AE7: 721.29759 | AF7: 743.20063 | AG7: 765.04253 | AH7: 786.93762 | AI7: 809.10183 | AJ7: 831.6912 | AK7: 854.70598
A8: x_cfoo_2 | B8: 45266.685 | C8: 46330.649 | D8: 47423.04 | E8: 48549.16 | F8: 49718.616 | G8: 50923.949 | H8: 52138.843 | I8: 52582.328 | J8: 52924.573 | K8: 53753.584 | L8: 54450.794 | M8: 55075.85 | N8: 55646.053 | O8: 56158.465 | P8: 56758.361 | Q8: 57483.681 | R8: 58332.46 | S8: 59256.323 | T8: 60245.548 | U8: 61300.473 | V8: 62452.919 | W8: 63746.147 | X8: 65231.842 | Y8: 66930.845 | Z8: 68823.365 | AA8: 70872.907 | AB8: 72956.91 | AC8: 75125.291 | AD8: 77360.583 | AE8: 79647.582 | AF8: 81993.596 | AG8: 84427.183 | AH8: 86967.365 | AI8: 89598.814 | AJ8: 92276.753 | AK8: 94944.692
A9: x_cfoo_0 | B9: 45266.685 | C9: 46330.649 | D9: 47423.04 | E9: 48549.16 | F9: 49718.616 | G9: 50923.949 | H9: 52112.599 | I9: 53240.782 | J9: 54292.205 | K9: 55285.063 | L9: 56260.077 | M9: 57257.901 | N9: 58253.948 | O9: 59147.657 | P9: 60028.358 | Q9: 60948.425 | R9: 61962.698 | S9: 63113.278 | T9: 64419.389 | U9: 65870.865 | V9: 67454.376 | W9: 69151.96 | X9: 70968.159 | Y9: 72908.705 | Z9: 74976.059 | AA9: 77187.936 | AB9: 79563.675 | AC9: 82127.807 | AD9: 84867.965 | AE9: 87719.169 | AF9: 90613.026 | AG9: 93515.732 | AH9: 96425.623 | AI9: 99353.437 | AJ9: 102308.54 | AK9: 105289.66
A10: x_cveh_2 | B10: 111187.03 | C10: 113831.37 | D10: 116551 | E10: 119368.07 | F10: 122297.3 | G10: 125316.63 | H10: 128367.14 | I10: 129899 | J10: 131287.03 | K10: 134290.5 | L10: 136976.14 | M10: 139452.2 | N10: 141727.58 | O10: 143757.05 | P10: 145969.31 | Q10: 148490.45 | R10: 150968.35 | S10: 153635.9 | T10: 156488.3 | U10: 159538.24 | V10: 162868.48 | W10: 166577.92 | X10: 170785.23 | Y10: 175535.86 | Z10: 180779.38 | AA10: 186436.82 | AB10: 192573.46 | AC10: 198989.47 | AD10: 205655.33 | AE10: 212525.05 | AF10: 219594.51 | AG10: 226905.09 | AH10: 234474.36 | AI10: 242245.95 | AJ10: 250101.13 | AK10: 257900.94
A11: x_cveh_0 | B11: 111187.03 | C11: 113831.37 | D11: 116551 | E11: 119368.07 | F11: 122297.3 | G11: 125316.63 | H11: 128316.87 | I11: 131212.87 | J11: 133979.53 | K11: 136661.27 | L11: 139344.57 | M11: 142110.16 | N11: 144877.93 | O11: 147383.47 | P11: 149839.8 | Q11: 152375.2 | R11: 155116 | S11: 158161 | T11: 161558.75 | U11: 165291.67 | V11: 169340.35 | W11: 173676.49 | X11: 178325.88 | Y11: 183311 | Z11: 188638.39 | AA11: 194347.71 | AB11: 200481.69 | AC11: 207099.56 | AD11: 214173.64 | AE11: 221549.74 | AF11: 229066.33 | AG11: 236645.02 | AH11: 244281.4 | AI11: 251995.7 | AJ11: 259801.06 | AK11: 267683.84
A12: x_cgla_2 | B12: 5205.4847 | C12: 5314.2639 | D12: 5419.3546 | E12: 5521.5934 | F12: 5630.2929 | G12: 5747.9847 | H12: 5872.2816 | I12: 5888.9434 | J12: 5883.2053 | K12: 5913.6596 | L12: 5925.2559 | M12: 5932.4503 | N12: 5938.2536 | O12: 5942.6598 | P12: 5958.4224 | Q12: 5988.0512 | R12: 6042.1964 | S12: 6101.2378 | T12: 6164.4073 | U12: 6231.871 | V12: 6306.6599 | W12: 6392.9629 | X12: 6495.7788 | Y12: 6616.8599 | Z12: 6754.326 | AA12: 6905.0914 | AB12: 7056.6098 | AC12: 7217.7049 | AD12: 7386.0247 | AE12: 7558.3549 | AF12: 7733.4523 | AG12: 7913.1957 | AH12: 8099.7878 | AI12: 8292.4933 | AJ12: 8488.0887 | AK12: 8682.0335
... A55: x_cote_0 | B55: 3756.2823 | C55: 3850.1893 | D55: 3946.4441 | E55: 4045.1052 | F55: 4146.2328 | G55: 4249.8886 | H55: 4356.1358 | I55: 4465.0392 | J55: 4576.6652 | K55: 4691.0819 | L55: 4808.3589 | M55: 4928.5679 | N55: 5046.9409 | O55: 5153.074 | P55: 5254.1739 | Q55: 5355.6199 | R55: 5461.6808 | S55: 5576.1005 | T55: 5701.3721 | U55: 5838.2997 | V55: 5988.1004 | W55: 6151.6507 | X55: 6331.0422 | Y55: 6527.163 | Z55: 6739.2829 | AA55: 6967.6224 | AB55: 7213.0106 | AC55: 7477.9745 | AD55: 7762.982 | AE55: 8064.4734 | AF55: 8377.8015 | AG55: 8699.8993 | AH55: 9029.0744 | AI55: 9363.8817 | AJ55: 9702.7829 | AK55: 10043.989

Sheet Import
A1: _date_ | B1: 42005 | C1: 42370 | D1: 42736 | E1: 43101 | F1: 43466 | G1: 43831 | H1: 44197 | I1: 44562 | J1: 44927 | K1: 45292 | L1: 45658 | M1: 46023 | N1: 46388 | O1: 46753 | P1: 47119 | Q1: 47484 | R1: 47849 | S1: 48214 | T1: 48580 | U1: 48945 | V1: 49310 | W1: 49675 | X1: 50041 | Y1: 50406 | Z1: 50771 | AA1: 51136 | AB1: 51502 | AC1: 51867 | AD1: 52232 | AE1: 52597 | AF1: 52963 | AG1: 53328 | AH1: 53693 | AI1: 54058 | AJ1: 54424 | AK1: 54789
A2: m_2 | B2: 663562.85 | C2: 676353.27 | D2: 692053.41 | E2: 708531.73 | F2: 724767.31 | G2: 740386.17 | H2: 755073.21 | I2: 763354.82 | J2: 770526.01 | K2: 781575.84 | L2: 794961.3 | M2: 810910.78 | N2: 828719.24 | O2: 847043 | P2: 865370.4 | Q2: 883221.07 | R2: 900264.59 | S2: 916406.77 | T2: 932177.49 | U2: 948390.91 | V2: 965910.9 | W2: 985313.36 | X2: 1006824.3 | Y2: 1030253.5 | Z2: 1055009.6 | AA2: 1080470.2 | AB2: 1106192 | AC2: 1132291.4 | AD2: 1159575.8 | AE2: 1188968.6 | AF2: 1221021 | AG2: 1255653.2 | AH2: 1292182.3 | AI2: 1329618.8 | AJ2: 1366978.5 | AK2: 1403558.9
A3: m_0 | B3: 663562.85 | C3: 676353.27 | D3: 692053.41 | E3: 708531.73 | F3: 724767.31 | G3: 740386.17 | H3: 754229.69 | I3: 766921.99 | J3: 779329.36 | K3: 792303.99 | L3: 806400.2 | M3: 821840.47 | N3: 838252.36 | O3: 854658.85 | P3: 870836.41 | Q3: 886688.63 | R3: 902860.37 | S3: 919606.64 | T3: 936923.85 | U3: 954722.99 | V3: 972992.65 | W3: 991862.9 | X3: 1011704.5 | Y3: 1032955.7 | Z3: 1055916.2 | AA3: 1080762.7 | AB3: 1107497 | AC3: 1136054.5 | AD3: 1166245.4 | AE3: 1197812.2 | AF3: 1230574.4 | AG3: 1264533.9 | AH3: 1299778.1 | AI3: 1336307.5 | AJ3: 1373950.4 | AK3: 1412373.5
A4: m_cagr_2 | B4: 12976.62 | C4: 13416.446 | D4: 13911.052 | E4: 14482.082 | F4: 15052.528 | G4: 15593.451 | H4: 16091.973 | I4: 16505.41 | J4: 16871.661 | K4: 17284.689 | L4: 17764.743 | M4: 18320.484 | N4: 18955.193 | O4: 19628.33 | P4: 20298.351 | Q4: 20932.545 | R4: 21517.924 | S4: 22048.183 | T4: 22546.321 | U4: 23044.809 | V4: 23572.621 | W4: 24144.524 | X4: 24760.774 | Y4: 25410.983 | Z4: 26076.976 | AA4: 26743.554 | AB4: 27399.433 | AC4: 28055.515 | AD4: 28744.66 | AE4: 29502.278 | AF4: 30346.064 | AG4: 31265.941 | AH4: 32230.611 | AI4: 33204.707 | AJ4: 34160.906 | AK4: 35088.837
A5: m_cagr_0 | B5: 12976.62 | C5: 13416.446 | D5: 13911.052 | E5: 14482.082 | F5: 15052.528 | G5: 15593.451 | H5: 16081.408 | I5: 16522.967 | J5: 16945.944 | K5: 17380.192 | L5: 17845.284 | M5: 18348.093 | N5: 18880.014 | O5: 19419.182 | P5: 19948.531 | Q5: 20456.277 | R5: 20952.282 | S5: 21444.038 | T5: 21932.981 | U5: 22418.279 | V5: 22901.807 | W5: 23390.927 | X5: 23899.405 | Y5: 24442.795 | Z5: 25031.521 | AA5: 25669.328 | AB5: 26352.906 | AC5: 27076.272 | AD5: 27832.88 | AE5: 28620.502 | AF5: 29441.051 | AG5: 30299.43 | AH5: 31199.376 | AI5: 32138.839 | AJ5: 33108.846 | AK5: 34095.703
A6: m_cfor_2 | B6: 212.32328 | C6: 203.11362 | D6: 195.91847 | E6: 190.26107 | F6: 186.04786 | G6: 183.12429 | H6: 181.35982 | I6: 179.44611 | J6: 178.38328 | K6: 179.03118 | L6: 180.4375 | M6: 182.30186 | N6: 184.27275 | O6: 186.13314 | P6: 188.02987 | Q6: 190.09593 | R6: 192.30047 | S6: 194.79263 | T6: 197.65641 | U6: 200.91757 | V6: 204.58656 | W6: 208.66302 | X6: 213.15987 | Y6: 218.07199 | Z6: 223.36714 | AA6: 229.03154 | AB6: 235.06465 | AC6: 241.56336 | AD6: 248.57664 | AE6: 256.06709 | AF6: 263.9428 | AG6: 272.11822 | AH6: 280.53037 | AI6: 289.12157 | AJ6: 297.84086 | AK6: 306.65201
A7: m_cfor_0 | B7: 212.32328 | C7: 203.11362 | D7: 195.91847 | E7: 190.26107 | F7: 186.04786 | G7: 183.12429 | H7: 181.37375 | I7: 180.66343 | J7: 180.85084 | K7: 181.7852 | L7: 183.31829 | M7: 185.32612 | N7: 187.63436 | O7: 189.98694 | P7: 192.39575 | Q7: 194.92244 | R7: 197.62447 | S7: 200.58217 | T7: 203.85143 | U7: 207.45601 | V7: 211.42191 | W7: 215.77369 | X7: 220.55159 | Y7: 225.77547 | Z7: 231.42772 | AA7: 237.49514 | AB7: 243.97476 | AC7: 250.89527 | AD7: 258.26888 | AE7: 266.05002 | AF7: 274.16059 | AG7: 282.53299 | AH7: 291.11564 | AI7: 299.86094 | AJ7: 308.72102 | AK7: 317.64688
A8: m_cfoo_2 | B8: 38715.482 | C8: 38700.694 | D8: 39053.612 | E8: 39759.438 | F8: 40602.85 | G8: 41488.672 | H8: 42360.49 | I8: 43084.095 | J8: 43739.489 | K8: 44564.058 | L8: 45587.149 | M8: 46830.89 | N8: 48298.444 | O8: 49891.141 | P8: 51508.893 | Q8: 53063.648 | R8: 54512.183 | S8: 55829.988 | T8: 57063.063 | U8: 58287.14 | V8: 59577.117 | W8: 60978.152 | X8: 62499.151 | Y8: 64116.283 | Z8: 65780.249 | AA8: 67444.212 | AB8: 69072.669 | AC8: 70690.761 | AD8: 72375.507 | AE8: 74217.749 | AF8: 76271.898 | AG8: 78528.26 | AH8: 80921.142 | AI8: 83363.627 | AJ8: 85780.762 | AK8: 88136.596
A9: m_cfoo_0 | B9: 38715.482 | C9: 38700.694 | D9: 39053.612 | E9: 39759.438 | F9: 40602.85 | G9: 41488.672 | H9: 42331.023 | I9: 43121.305 | J9: 43910.597 | K9: 44764.141 | L9: 45728.177 | M9: 46819.578 | N9: 48015.081 | O9: 49255.429 | P9: 50497.141 | Q9: 51706.262 | R9: 52902.684 | S9: 54102.232 | T9: 55305.046 | U9: 56504.154 | V9: 57698.778 | W9: 58902.232 | X9: 60146.319 | Y9: 61470.007 | Z9: 62901.989 | AA9: 64455.743 | AB9: 66126.554 | AC9: 67901.028 | AD9: 69761.097 | AE9: 71696.574 | AF9: 73708.769 | AG9: 75809.929 | AH9: 78012.718 | AI9: 80317.08 | AJ9: 82705.417 | AK9: 85146.407
A10: m_cveh_2 | B10: 81984.742 | C10: 85343.897 | D10: 89291.6 | E10: 92792.086 | F10: 95880.614 | G10: 98437.143 | H10: 100369.25 | I10: 100564.4 | J10: 100822.09 | K10: 102143.3 | L10: 104140.01 | M10: 106845.11 | N10: 109664.34 | O10: 112120.31 | P10: 114100.6 | Q10: 115640.37 | R10: 116857.29 | S10: 117867.83 | T10: 118842.84 | U10: 119961.82 | V10: 121369.7 | W10: 123130.73 | X10: 125232.91 | Y10: 127598.53 | Z10: 130104.73 | AA10: 132646.74 | AB10: 135199.73 | AC10: 137786.36 | AD10: 140557.35 | AE10: 143671.25 | AF10: 147196.75 | AG10: 151076.33 | AH10: 155152.54 | AI10: 159242.24 | AJ10: 163206.31 | AK10: 166994.25
A11: m_cveh_0 | B11: 81984.742 | C11: 85343.897 | D11: 89291.6 | E11: 92792.086 | F11: 95880.614 | G11: 98437.143 | H11: 99954.404 | I11: 101032.43 | J11: 102081.7 | K11: 103347.21 | L11: 104896 | M11: 106680.23 | N11: 108548.57 | O11: 110280.06 | P11: 111807.13 | Q11: 113127.76 | R11: 114698.67 | S11: 116305.86 | T11: 117866.96 | U11: 119378.33 | V11: 120879.06 | W11: 122430.93 | X11: 124120.78 | Y11: 126028.79 | Z11: 128196.46 | AA11: 130633.52 | AB11: 133317.27 | AC11: 136216.7 | AD11: 139290.2 | AE11: 142496.18 | AF11: 145813.32 | AG11: 149249.41 | AH11: 152820.17 | AI11: 156521.03 | AJ11: 160317.64 | AK11: 164154.3
A12: m_cgla_2 | B12: 6982.6807 | C12: 7254.524 | D12: 7570.3071 | E12: 7822.5186 | F12: 8014.2634 | G12: 8173.0776 | H12: 8314.184 | I12: 8418.3838 | J12: 8523.8827 | K12: 8681.7374 | L12: 8889.016 | M12: 9141.6701 | N12: 9427.7885 | O12: 9731.8141 | P12: 10043.094 | Q12: 10350.108 | R12: 10648.464 | S12: 10934.021 | T12: 11209.732 | U12: 11485.621 | V12: 11776.073 | W12: 12093.306 | X12: 12443.292 | Y12: 12823.567 | Z12: 13222.637 | AA12: 13625.787 | AB12: 14018.476 | AC12: 14398.206 | AD12: 14778.269 | AE12: 15180.128 | AF12: 15622.907 | AG12: 16114.478 | AH12: 16648.432 | AI12: 17208.634 | AJ12: 17776.112 | AK12: 18337.528
... A55: m_cote_0 | B55: 2416.4373 | C55: 2623.8173 | D55: 2786.1625 | E55: 2914.5229 | F55: 3026.0223 | G55: 3129.4035 | H55: 3237.4038 | I55: 3347.2903 | J55: 3451.1002 | K55: 3540.653 | L55: 3610.8103 | M55: 3660.8945 | N55: 3692.944 | O55: 3709.2983 | P55: 3718.5969 | Q55: 3728.9424 | R55: 3730.8869 | S55: 3737.8347 | T55: 3754.7768 | U55: 3784.7534 | V55: 3829.5782 | W55: 3889.1633 | X55: 3961.6522 | Y55: 4043.6567 | Z55: 4131.6767 | AA55: 4223.7663 | AB55: 4320.3683 | AC55: 4424.1231 | AD55: 4537.7771 | AE55: 4661.3161 | AF55: 4791.6924 | AG55: 4924.072 | AH55: 5053.7006 | AI55: 5177.5546 | AJ55: 5295.1044 | AK55: 5407.8464

Sheet Carbontax
A1: _date_ | B1: 42005 | C1: 42370 | D1: 42736 | E1: 43101 | F1: 43466 | G1: 43831 | H1: 44197 | I1: 44562 | J1: 44927 | K1: 45292 | L1: 45658 | M1: 46023 | N1: 46388 | O1: 46753 | P1: 47119 | Q1: 47484 | R1: 47849 | S1: 48214 | T1: 48580 | U1: 48945 | V1: 49310 | W1: 49675 | X1: 50041 | Y1: 50406 | Z1: 50771 | AA1: 51136 | AB1: 51502 | AC1: 51867 | AD1: 52232 | AE1: 52597 | AF1: 52963 | AG1: 53328 | AH1: 53693 | AI1: 54058 | AJ1: 54424 | AK1: 54789
A2: t2val_ch_0 | B2: 1672.0229 | C2: 2522.4473 | D2: 3467.3396 | E2: 5025.2893 | F2: 4989.5769 | G2: 4957.9556 | H2: 4916.4945 | I2: 4816.7927 | J2: 4857.0977 | K2: 4891.386 | L2: 4903.6546 | M2: 4883.2646 | N2: 4826.6627 | O2: 4737.9595 | P2: 4626.0165 | Q2: 4502.2019 | R2: 4381.7028 | S2: 4258.3475 | T2: 4139.0071 | U2: 4028.1189 | V2: 3929.7878 | W2: 3846.7624 | X2: 3779.3423 | Y2: 3725.4331 | Z2: 3681.6018 | AA2: 3644.9574 | AB2: 3614.1768 | AC2: 3590.0664 | AD2: 3574.8851 | AE2: 3570.8578 | AF2: 3578.2693 | AG2: 3595.3533 | AH2: 3618.9144 | AI2: 3645.6984 | AJ2: 3673.5554 | AK2: 3701.8444
A3: t2val_ch_2 | B3: 1672.0229 | C3: 2522.4473 | D3: 3467.3396 | E3: 5025.2893 | F3: 4989.5769 | G3: 4957.9556 | H3: 4924.3047 | I3: 10679.996 | J3: 14316.36 | K3: 17780.573 | L3: 20947.014 | M3: 21559.266 | N3: 21790.436 | O3: 21705.64 | P3: 21396.481 | Q3: 20961.563 | R3: 21395.742 | S3: 21715.565 | T3: 21965.779 | U3: 22148.008 | V3: 22236.586 | W3: 22199.482 | X3: 22022.43 | Y3: 21716.378 | Z3: 21314.875 | AA3: 20867.53 | AB3: 20419.11 | AC3: 20001.327 | AD3: 19609.679 | AE3: 19195.118 | AF3: 18696.1 | AG3: 18070.238 | AH3: 17311.036 | AI3: 16438.679 | AJ3: 15476.69 | AK3: 14436.609
A4: t2val_sec_0 | B4: 3418.5604 | C4: 5212.8645 | D4: 7264.1581 | E4: 10659.357 | F4: 10717.045 | G4: 10805.091 | H4: 10920.64 | I4: 10951.489 | J4: 11339.972 | K4: 11756.444 | L4: 12162.068 | M4: 12531.617 | N4: 12851.505 | O4: 13117.271 | P4: 13349.923 | Q4: 13577.128 | R4: 13817.975 | S4: 14061.807 | T4: 14331.759 | U4: 14644.76 | V4: 15018.637 | W4: 15466.674 | X4: 15993.545 | Y4: 16592.599 | Z4: 17249.735 | AA4: 17954.698 | AB4: 18707.311 | AC4: 19522.096 | AD4: 20421.342 | AE4: 21422.108 | AF4: 22524.731 | AG4: 23713.952 | AH4: 24964.295 | AI4: 26250.453 | AJ4: 27557.044 | AK4: 28882.1
A5: t2val_sec_2 | B5: 3418.5604 | C5: 5212.8645 | D5: 7264.1581 | E5: 10659.357 | F5: 10717.045 | G5: 10805.091 | H5: 10926.716 | I5: 24416.273 | J5: 33819.661 | K5: 43738.441 | L5: 53936.124 | M5: 58404.374 | N5: 62357.131 | O5: 65807.803 | P5: 68932.358 | Q5: 71946.579 | R5: 78432.354 | S5: 85128.657 | T5: 92137.465 | U5: 99403.288 | V5: 106755.98 | W5: 113998 | X5: 121032.59 | Y5: 127905.4 | Z5: 134792.61 | AA5: 141986.69 | AB5: 149801.89 | AC5: 158527.46 | AD5: 168166.58 | AE5: 178300.5 | AF5: 188328.61 | AG5: 197799.65 | AH5: 206620.18 | AI5: 214979.47 | AJ5: 223118.45 | AK5: 231148.95
A6: t2val_ci_0 | B6: 2666.2635 | C6: 4049.2226 | D6: 5615.3361 | E6: 8202.0515 | F6: 8218.4861 | G6: 8266.8185 | H6: 8344.9529 | I6: 8365.8445 | J6: 8663.0201 | K6: 8979.9156 | L6: 9282.8991 | M6: 9550.665 | N6: 9773.3029 | O6: 9949.7639 | P6: 10098.926 | Q6: 10244.724 | R6: 10403.407 | S6: 10567.255 | T6: 10754.836 | U6: 10980.393 | V6: 11258.599 | W6: 11599.741 | X6: 12006.267 | Y6: 12470.964 | Z6: 12980.805 | AA6: 13526.362 | AB6: 14107.328 | AC6: 14736.066 | AD6: 15431.609 | AE6: 16208.219 | AF6: 17065.654 | AG6: 17989.953 | AH6: 18958.522 | AI6: 19949.438 | AJ6: 20949.904 | AK6: 21959.079
A7: t2val_ci_2 | B7: 2666.2635 | C7: 4049.2226 | D7: 5615.3361 | E7: 8202.0515 | F7: 8218.4861 | G7: 8266.8185 | H7: 8349.1077 | I7: 18477.306 | J7: 25337.42 | K7: 32413.767 | L7: 39486.938 | M7: 42192.787 | N7: 44396.646 | O7: 46130.534 | P7: 47553.462 | Q7: 48848.766 | R7: 52409.498 | S7: 56008.52 | T7: 59706.02 | U7: 63431.569 | V7: 67027.357 | W7: 70326.512 | X7: 73250.402 | Y7: 75835.558 | Z7: 78218.289 | AA7: 80601.501 | AB7: 83183.687 | AC7: 86088.981 | AD7: 89206.507 | AE7: 92146.997 | AF7: 94435.772 | AG7: 95744.716 | AH7: 96004.074 | AI7: 95309.39 | AJ7: 93745.339 | AK7: 91250.706
A8: t2val_y_0 | B8: 39.83797 | C8: 59.908039 | D8: 83.025417 | E8: 122.42371 | F8: 124.03777 | G8: 125.96318 | H8: 127.82913 | I8: 128.27261 | J8: 132.74167 | K8: 137.72028 | L8: 143.0496 | M8: 148.58237 | N8: 154.12632 | O8: 159.46306 | P8: 164.59308 | Q8: 169.58953 | R8: 174.74388 | S8: 179.75661 | T8: 184.81858 | U8: 190.03893 | V8: 195.56625 | W8: 201.56806 | X8: 208.2074 | Y8: 215.58322 | Z8: 223.70434 | AA8: 232.56318 | AB8: 242.16022 | AC8: 252.57346 | AD8: 263.92651 | AE8: 276.34976 | AF8: 289.89793 | AG8: 304.55717 | AH8: 320.23396 | AI8: 336.78026 | AJ8: 354.04698 | AK8: 371.92511
A9: t2val_y_2 | B9: 39.83797 | C9: 59.908039 | D9: 83.025417 | E9: 122.42371 | F9: 124.03777 | G9: 125.96318 | H9: 127.96261 | I9: 291.85421 | J9: 412.19863 | K9: 545.23662 | L9: 691.40649 | M9: 774.01454 | N9: 859.27863 | O9: 946.25633 | P9: 1034.893 | Q9: 1125.5001 | R9: 1273.9153 | S9: 1430.0367 | T9: 1596.0857 | U9: 1773.7644 | V9: 1963.9554 | W9: 2166.5049 | X9: 2381.2525 | Y9: 2608.5289 | Z9: 2849.2707 | AA9: 3106.4594 | AB9: 3384.0707 | AC9: 3690.1439 | AD9: 4032.3416 | AE9: 4412.9005 | AF9: 4829.2021 | AG9: 5276.612 | AH9: 5752.4649 | AI9: 6257.9886 | AJ9: 6797.0613 | AK9: 7375.5755
A10: t2val_mat_0 | B10: 712.45889 | C10: 1103.7338 | D10: 1565.7966 | E10: 2334.8818 | F10: 2374.5216 | G10: 2412.3094 | H10: 2447.8581 | I10: 2457.3721 | J10: 2544.2098 | K10: 2638.8081 | L10: 2736.1194 | M10: 2832.3692 | N10: 2924.0755 | O10: 3008.0439 | P10: 3086.4036 | Q10: 3162.8146 | R10: 3239.8242 | S10: 3314.7963 | T10: 3392.1044 | U10: 3474.3273 | V10: 3564.4722 | W10: 3665.3648 | X10: 3779.0708 | Y10: 3906.0517 | Z10: 4045.2254 | AA10: 4195.7735 | AB10: 4357.8226 | AC10: 4533.4562 | AD10: 4725.8066 | AE10: 4937.5396 | AF10: 5169.1788 | AG10: 5419.4415 | AH10: 5685.5392 | AI10: 5964.2354 | AJ10: 6253.0928 | AK10: 6551.095
A11: t2val_mat_2 | B11: 712.45889 | C11: 1103.7338 | D11: 1565.7966 | E11: 2334.8818 | F11: 2374.5216 | G11: 2412.3094 | H11: 2449.6454 | I11: 5647.1133 | J11: 8070.0417 | K11: 10779.438 | L11: 13757.779 | M11: 15437.572 | N11: 17101.207 | O11: 18731.013 | P11: 20344.003 | Q11: 21972.312 | R11: 24748.94 | S11: 27690.101 | T11: 30835.359 | U11: 34197.954 | V11: 37764.666 | W11: 41504.982 | X11: 45400.93 | Y11: 49461.314 | Z11: 53725.046 | AA11: 58278.73 | AB11: 63234.132 | AC11: 68748.338 | AD11: 74927.727 | AE11: 81740.607 | AF11: 89063.634 | AG11: 96778.327 | AH11: 104863.64 | AI11: 113412.09 | AJ11: 122576.05 | AK11: 132522.67

Sheet Production
A1: _date_ | B1: 42005 | C1: 42370 | D1: 42736 | E1: 43101 | F1: 43466 | G1: 43831 | H1: 44197 | I1: 44562 | J1: 44927 | K1: 45292 | L1: 45658 | M1: 46023 | N1: 46388 | O1: 46753 | P1: 47119 | Q1: 47484 | R1: 47849 | S1: 48214 | T1: 48580 | U1: 48945 | V1: 49310 | W1: 49675 | X1: 50041 | Y1: 50406 | Z1: 50771 | AA1: 51136 | AB1: 51502 | AC1: 51867 | AD1: 52232 | AE1: 52597 | AF1: 52963 | AG1: 53328 | AH1: 53693 | AI1: 54058 | AJ1: 54424 | AK1: 54789
A2: y_2 | B2: 3862067 | C2: 3904759.4 | D2: 3966686.3 | E2: 4034936.1 | F2: 4105156.5 | G2: 4176446.6 | H2: 4246260.1 | I2: 4288914.7 | J2: 4320825.3 | K2: 4368704.5 | L2: 4426263.4 | M2: 4497850.2 | N2: 4583461.7 | O2: 4678390.5 | P2: 4779964.3 | Q2: 4883365.4 | R2: 4983107.8 | S2: 5076583.5 | T2: 5164571.7 | U2: 5251195.2 | V2: 5342525.4 | W2: 5443871.8 | X2: 5558208.1 | Y2: 5684891.4 | Z2: 5819666.2 | AA2: 5956795.9 | AB2: 6091257.1 | AC2: 6221717.5 | AD2: 6351840.1 | AE2: 6488046.9 | AF2: 6636356.2 | AG2: 6799621 | AH2: 6976135.1 | AI2: 7160473.1 | AJ2: 7345993.5 | AK2: 7527752
A3: y_0 | B3: 3862067 | C3: 3904759.4 | D3: 3966686.3 | E3: 4034936.1 | F3: 4105156.5 | G3: 4176446.6 | H3: 4242272.2 | I3: 4300967.5 | J3: 4355265.6 | K3: 4410518.5 | L3: 4471966.3 | M3: 4542908.7 | N3: 4622734.6 | O3: 4706868.8 | P3: 4793917.7 | Q3: 4882063.9 | R3: 4973390.7 | S3: 5069593.8 | T3: 5170312.1 | U3: 5273836.5 | V3: 5378459.2 | W3: 5483379.9 | X3: 5589789.5 | Y3: 5700135.5 | Z3: 5816894.6 | AA3: 5942027.8 | AB3: 6076132.6 | AC3: 6218637.3 | AD3: 6367605.9 | AE3: 6520496.2 | AF3: 6675832.3 | AG3: 6834044 | AH3: 6996728.7 | AI3: 7165292 | AJ3: 7340025 | AK3: 7519866.7
A4: y_sagr_2 | B4: 81700.733 | C4: 80785.703 | D4: 80589.843 | E4: 81146.049 | F4: 82136.107 | G4: 83357.704 | H4: 84645.528 | I4: 85321.957 | J4: 85684.211 | K4: 86361.314 | L4: 87222.523 | M4: 88413.381 | N4: 90001.934 | O4: 91879.686 | P4: 93960.418 | Q4: 96103.072 | R4: 98183.229 | S4: 100091.56 | T4: 101846.88 | U4: 103552.63 | V4: 105357.63 | W4: 107389.69 | X4: 109721.47 | Y4: 112341.88 | Z4: 115156.37 | AA4: 118036 | AB4: 120837.42 | AC4: 123548.83 | AD4: 126254.13 | AE4: 129102.99 | AF4: 132236.34 | AG4: 135718 | AH4: 139503.23 | AI4: 143461.56 | AJ4: 147435.15 | AK4: 151305.56
A5: y_sagr_0 | B5: 81700.733 | C5: 80785.703 | D5: 80589.843 | E5: 81146.049 | F5: 82136.107 | G5: 83357.704 | H5: 84558.415 | I5: 85628.631 | J5: 86604.022 | K5: 87603.424 | L5: 88752.211 | M5: 90130.028 | N5: 91719.708 | O5: 93406.635 | P5: 95155.315 | Q5: 96919.104 | R5: 98754.928 | S5: 100702.35 | T5: 102758.55 | U5: 104885.79 | V5: 107045.02 | W5: 109216.99 | X5: 111430.23 | Y5: 113743 | Z5: 116213.87 | AA5: 118888.79 | AB5: 121780.94 | AC5: 124877.31 | AD5: 128129.84 | AE5: 131474.18 | AF5: 134870.44 | AG5: 138325.44 | AH5: 141875.76 | AI5: 145553.07 | AJ5: 149361.32 | AK5: 153271.36
A6: y_sfor_2 | B6: 6530.3134 | C6: 6365.6895 | D6: 6238.3688 | E6: 6137.84 | F6: 6076.1501 | G6: 6044.3111 | H6: 6034.5438 | I6: 5968.6101 | J6: 5901.3911 | K6: 5859.8547 | L6: 5821.2231 | M6: 5794.9838 | N6: 5777.0099 | O6: 5766.5731 | P6: 5769.3378 | Q6: 5786.4739 | R6: 5807.9843 | S6: 5835.2313 | T6: 5867.0404 | U6: 5903.2879 | V6: 5946.1342 | W6: 5998.9667 | X6: 6065.2438 | Y6: 6146.1572 | Z6: 6239.9502 | AA6: 6343.0395 | AB6: 6451.5951 | AC6: 6563.9853 | AD6: 6679.5715 | AE6: 6799.0208 | AF6: 6924.4797 | AG6: 7058.9577 | AH6: 7204.1811 | AI6: 7358.7476 | AJ6: 7518.8906 | AK6: 7680.2954
A7: y_sfor_0 | B7: 6530.3134 | C7: 6365.6895 | D7: 6238.3688 | E7: 6137.84 | F7: 6076.1501 | G7: 6044.3111 | H7: 6032.7572 | I7: 6033.4531 | J7: 6041.7044 | K7: 6056.4537 | L7: 6078.751 | M7: 6110.1875 | N7: 6149.7228 | O7: 6192.5709 | P7: 6239.8525 | Q7: 6292.1619 | R7: 6350.6948 | S7: 6417.7263 | T7: 6493.9785 | U7: 6578.3844 | V7: 6669.3458 | W7: 6765.2731 | X7: 6865.9154 | Y7: 6971.8217 | Z7: 7083.8367 | AA7: 7203.3383 | AB7: 7331.4936 | AC7: 7469.1284 | AD7: 7615.3686 | AE7: 7767.1392 | AF7: 7921.2328 | AG7: 8076.1131 | AH7: 8231.979 | AI7: 8389.8157 | AJ7: 8550.4784 | AK7: 8714.0662
A8: y_sfoo_2 | B8: 157606.73 | C8: 156822 | D8: 157473.36 | E8: 159502.46 | F8: 162186.04 | G8: 165162.83 | H8: 168161.24 | I8: 170138.54 | J8: 171539.46 | K8: 173430.98 | L8: 175691.6 | M8: 178554.49 | N8: 182155.69 | O8: 186273.26 | P8: 190706.52 | Q8: 195186.07 | R8: 199507.56 | S8: 203480.83 | T8: 207164.2 | U8: 210764.01 | V8: 214554.71 | W8: 218759.82 | X8: 223496.13 | Y8: 228734.36 | Z8: 234302.73 | AA8: 239975.57 | AB8: 245493.39 | AC8: 250860.69 | AD8: 256249.39 | AE8: 261944.83 | AF8: 268195.82 | AG8: 275090.44 | AH8: 282516.2 | AI8: 290220.42 | AJ8: 297918.02 | AK8: 305407.8
A9: y_sfoo_0 | B9: 157606.73 | C9: 156822 | D9: 157473.36 | E9: 159502.46 | F9: 162186.04 | G9: 165162.83 | H9: 168002.15 | I9: 170546.2 | J9: 172899.57 | K9: 175296.94 | L9: 177967.26 | M9: 181047.73 | N9: 184503.54 | O9: 188131.38 | P9: 191850.71 | Q9: 195568.72 | R9: 199389.16 | S9: 203385.67 | T9: 207554.9 | U9: 211835.9 | V9: 216168.21 | W9: 220529.36 | X9: 224980.91 | Y9: 229635.09 | Z9: 234599.55 | AA9: 239952.17 | AB9: 245708.73 | AC9: 251838.84 | AD9: 258256.03 | AE9: 264855.3 | AF9: 271576.38 | AG9: 278435.78 | AH9: 285494.81 | AI9: 292799.56 | AJ9: 300344.35 | AK9: 308066.51
A10: y_sveh_2 | B10: 125562.3 | C10: 126911.73 | D10: 128913.4 | E10: 131133.36 | F10: 133535.59 | G10: 136005.43 | H10: 138408.29 | I10: 139084.62 | J10: 139653.44 | K10: 141778.99 | L10: 143928.58 | M10: 146228.44 | N10: 148508.08 | O10: 150585.16 | P10: 152732.14 | Q10: 155031.65 | R10: 157232.91 | S10: 159504.64 | T10: 161877.98 | U10: 164422.79 | V10: 167267.1 | W10: 170529.95 | X10: 174313.25 | Y10: 178629.06 | Z10: 183386.56 | AA10: 188464.1 | AB10: 193862.97 | AC10: 199416.27 | AD10: 205147.72 | AE10: 211097.5 | AF10: 217322.04 | AG10: 223865.95 | AH10: 230704.99 | AI10: 237730.36 | AJ10: 244787.5 | AK10: 251736.27
A11: y_sveh_0 | B11: 125562.3 | C11: 126911.73 | D11: 128913.4 | E11: 131133.36 | F11: 133535.59 | G11: 136005.43 | H11: 138201.6 | I11: 140222.66 | J11: 142171.29 | K11: 144168.29 | L11: 146316.01 | M11: 148670.31 | N11: 151125.57 | O11: 153408.09 | P11: 155642.25 | Q11: 157907 | R11: 160454.61 | S11: 163277.29 | T11: 166372.31 | U11: 169710.56 | V11: 173273.15 | W11: 177044.61 | X11: 181065.87 | Y11: 185383.54 | Z11: 190027.27 | AA11: 195040.69 | AB11: 200453.46 | AC11: 206295.4 | AD11: 212520.98 | AE11: 218988.4 | AF11: 225563.77 | AG11: 232194.85 | AH11: 238895.53 | AI11: 245694.58 | AJ11: 252603.07 | AK11: 259599.15
A12: y_sgla_2 | B12: 22075.609 | C12: 22960.239 | D12: 23926.007 | E12: 24600.446 | F12: 25064.546 | G12: 25442.145 | H12: 25787.554 | I12: 25889.365 | J12: 25889.673 | K12: 25964.918 | L12: 26101.985 | M12: 26347.498 | N12: 26688.313 | O12: 27100.206 | P12: 27569.414 | Q12: 28066.233 | R12: 28560.316 | S12: 29015.54 | T12: 29426.279 | U12: 29812.407 | V12: 30213.19 | W12: 30668.515 | X12: 31203.567 | Y12: 31817.291 | Z12: 32481.318 | AA12: 33153.861 | AB12: 33788.808 | AC12: 34378.904 | AD12: 34943.518 | AE12: 35525.152 | AF12: 36169.733 | AG12: 36906.53 | AH12: 37734.141 | AI12: 38621.974 | AJ12: 39526.13 | AK12: 40409.625
... A67: y_seot_0 | B67: 54.518525 | C67: 55.064713 | D67: 55.509473 | E67: 56.05587 | F67: 56.605373 | G67: 57.262791 | H67: 58.163175 | I67: 59.263851 | J67: 60.510344 | K67: 61.838549 | L67: 63.221722 | M67: 64.665049 | N67: 66.173852 | O67: 67.727354 | P67: 69.356366 | Q67: 71.075633 | R67: 72.807016 | S67: 74.575946 | T67: 76.403249 | U67: 78.303658 | V67: 80.285295 | W67: 82.340618 | X67: 84.452824 | Y67: 86.596693 | Z67: 88.751642 | AA67: 90.916991 | AB67: 93.113523 | AC67: 95.377863 | AD67: 97.734716 | AE67: 100.16867 | AF67: 102.63485 | AG67: 105.08173 | AH67: 107.4706 | AI67: 109.78593 | AJ67: 112.03569 | AK67: 114.24035

Sheet Capital
A1: _date_ | B1: 42005 | C1: 42370 | D1: 42736 | E1: 43101 | F1: 43466 | G1: 43831 | H1: 44197 | I1: 44562 | J1: 44927 | K1: 45292 | L1: 45658 | M1: 46023 | N1: 46388 | O1: 46753 | P1: 47119 | Q1: 47484 | R1: 47849 | S1: 48214 | T1: 48580 | U1: 48945 | V1: 49310 | W1: 49675 | X1: 50041 | Y1: 50406 | Z1: 50771 | AA1: 51136 | AB1: 51502 | AC1: 51867 | AD1: 52232 | AE1: 52597 | AF1: 52963 | AG1: 53328 | AH1: 53693 | AI1: 54058 | AJ1: 54424 | AK1: 54789
A2: f_k_2 | B2: 8840569 | C2: 8941012 | D2: 9043664.2 | E2: 9150399.9 | F2: 9262528.1 | G2: 9380418.9 | H2: 9503400.2 | I2: 9626346.9 | J2: 9746464.2 | K2: 9864717.1 | L2: 9983145.8 | M2: 10105077 | N2: 10234168 | O2: 10373412 | P2: 10524773 | Q2: 10688804 | R2: 10864488 | S2: 11049788 | T2: 11242655 | U2: 11441926 | V2: 11647782 | W2: 11861607 | X2: 12085419 | Y2: 12321077 | Z2: 12569418 | AA2: 12829842 | AB2: 13100434 | AC2: 13378896 | AD2: 13663890 | AE2: 13955803 | AF2: 14256649 | AG2: 14569266 | AH2: 14896201 | AI2: 15238823 | AJ2: 15596996 | AK2: 15969490
A3: f_k_0 | B3: 8840569 | C3: 8941012 | D3: 9043664.2 | E3: 9150399.9 | F3: 9262528.1 | G3: 9380418.9 | H3: 9502537 | I3: 9626950.2 | J3: 9752348.1 | K3: 9878634.2 | L3: 10006884 | M3: 10138963 | N3: 10276876 | O3: 10422093 | P3: 10575490 | Q3: 10737263 | R3: 10907949 | S3: 11088080 | T3: 11277894 | U3: 11477097 | V3: 11684865 | W3: 11900123 | X3: 12122021 | Y3: 12350302 | Z3: 12585358 | AA3: 12828070 | AB3: 13079458 | AC3: 13340348 | AD3: 13611134 | AE3: 13891814 | AF3: 14182274 | AG3: 14482656 | AH3: 14793563 | AI3: 15116001 | AJ3: 15451112 | AK3: 15799857
A4: f_k_sagr_2 | B4: 181347.23 | C4: 183282.38 | D4: 185117.57 | E4: 186941.91 | F4: 188822.34 | G4: 190794.4 | H4: 192862.35 | I4: 194946.78 | J4: 196989 | K4: 199017.72 | L4: 201085.57 | M4: 203268.76 | N4: 205658.71 | O4: 208332.07 | P4: 211338.8 | Q4: 214691.55 | R4: 218367.76 | S4: 222314.43 | T4: 226476.07 | U4: 230819.01 | V4: 235344.25 | W4: 240084.23 | X4: 245088.54 | Y4: 250403.34 | Z4: 256049.32 | AA4: 262010.69 | AB4: 268234.24 | AC4: 274656.76 | AD4: 281238.84 | AE4: 287985.07 | AF4: 294942.03 | AG4: 302176.65 | AH4: 309745.94 | AI4: 317673.21 | AJ4: 325939.37 | AK4: 334493.02
A5: f_k_sagr_0 | B5: 181347.23 | C5: 183282.38 | D5: 185117.57 | E5: 186941.91 | F5: 188822.34 | G5: 190794.4 | H5: 192848.46 | I5: 194954.96 | J5: 197092.69 | K5: 199265.45 | L5: 201503.96 | M5: 203857.74 | N5: 206378.98 | O5: 209105.05 | P5: 212058.19 | Q5: 215243.86 | R5: 218668.83 | S5: 222341.34 | T5: 226264.87 | U5: 230431.96 | V5: 234823.57 | W5: 239415.1 | X5: 244187.53 | Y5: 249136.41 | Z5: 254273.53 | AA5: 259623.24 | AB5: 265213.76 | AC5: 271068.81 | AD5: 277200.94 | AE5: 283611.33 | AF5: 290296.51 | AG5: 297258.17 | AH5: 304509.25 | AI5: 312072.76 | AJ5: 319974.96 | AK5: 328236.78
A6: f_k_sfor_2 | B6: 14496.423 | C6: 14640.969 | D6: 14762.436 | E6: 14862.972 | F6: 14947.093 | G6: 15018.897 | H6: 15081.248 | I6: 15128.209 | J6: 15157.982 | K6: 15173.521 | L6: 15177.406 | M6: 15173.149 | N6: 15164.02 | O6: 15152.654 | P6: 15141.408 | Q6: 15132.091 | R6: 15125.058 | S6: 15120.131 | T6: 15117.12 | U6: 15116.237 | V6: 15118.4 | W6: 15125.23 | X6: 15138.813 | Y6: 15161.22 | Z6: 15193.922 | AA6: 15237.489 | AB6: 15291.62 | AC6: 15355.728 | AD6: 15429.589 | AE6: 15513.697 | AF6: 15609.277 | AG6: 15718.031 | AH6: 15841.665 | AI6: 15981.345 | AJ6: 16137.384 | AK6: 16309.305
A7: f_k_sfor_0 | B7: 14496.423 | C7: 14640.969 | D7: 14762.436 | E7: 14862.972 | F7: 14947.093 | G7: 15018.897 | H7: 15080.6 | I7: 15133.506 | J7: 15178.764 | K7: 15217.888 | L7: 15252.891 | M7: 15286.154 | N7: 15319.956 | O7: 15355.862 | P7: 15395.007 | Q7: 15438.14 | R7: 15486.241 | S7: 15540.365 | T7: 15601.447 | U7: 15670.061 | V7: 15746.379 | W7: 15830.318 | X7: 15921.86 | Y7: 16021.293 | Z7: 16129.259 | AA7: 16246.712 | AB7: 16374.742 | AC7: 16514.411 | AD7: 16666.54 | AE7: 16831.579 | AF7: 17009.677 | AG7: 17200.94 | AH7: 17405.643 | AI7: 17624.286 | AJ7: 17857.495 | AK7: 18105.833
A8: f_k_sfoo_2 | B8: 75628.285 | C8: 76442.345 | D8: 77236.937 | E8: 78063.884 | F8: 78954.822 | G8: 79921.685 | H8: 80957.735 | I8: 82017.738 | J8: 83069.032 | K8: 84126.545 | L8: 85221.893 | M8: 86398.476 | N8: 87706.606 | O8: 89185.155 | P8: 90854.324 | Q8: 92711.446 | R8: 94737.394 | S8: 96896.819 | T8: 99155.001 | U8: 101491.65 | V8: 103907.23 | W8: 106419.56 | X8: 109054.33 | Y8: 111833.19 | Z8: 114761.81 | AA8: 117825 | AB8: 120986.99 | AC8: 124208.83 | AD8: 127468.56 | AE8: 130772.24 | AF8: 134150.33 | AG8: 137642.49 | AH8: 141279.07 | AI8: 145068.65 | AJ8: 148995.57 | AK8: 153028.56
A9: f_k_sfoo_0 | B9: 75628.285 | C9: 76442.345 | D9: 77236.937 | E9: 78063.884 | F9: 78954.822 | G9: 79921.685 | H9: 80949.573 | I9: 82015.573 | J9: 83104.847 | K9: 84218.802 | L9: 85374.454 | M9: 86598.537 | N9: 87917.992 | O9: 89350.506 | P9: 90904.071 | Q9: 92576.542 | R9: 94367.736 | S9: 96277.566 | T9: 98302.974 | U9: 100435.05 | V9: 102659.27 | W9: 104959.26 | X9: 107323.03 | Y9: 109747.7 | Z9: 112239.81 | AA9: 114812.47 | AB9: 117480.07 | AC9: 120253.53 | AD9: 123137.15 | AE9: 126129.48 | AF9: 129227.62 | AG9: 132432.4 | AH9: 135751.04 | AI9: 139195.6 | AJ9: 142778.78 | AK9: 146509.14
A10: f_k_sveh_2 | B10: 124562 | C10: 125994.3 | D10: 127497.58 | E10: 129102.87 | F10: 130828.42 | G10: 132676.53 | H10: 134631.04 | I10: 136534.3 | J10: 138329.43 | K10: 140129.56 | L10: 141981.72 | M10: 143922.02 | N10: 145967.52 | O10: 148109.53 | P10: 150346.68 | Q10: 152681.35 | R10: 155094.87 | S10: 157573.82 | T10: 160111.97 | U10: 162715.13 | V10: 165406.61 | W10: 168225.62 | X10: 171222.29 | Y10: 174446.64 | Z10: 177935.3 | AA10: 181705.7 | AB10: 185765.85 | AC10: 190108.16 | AD10: 194727.76 | AE10: 199630.57 | AF10: 204834.45 | AG10: 210363.72 | AH10: 216237.79 | AI10: 222459.46 | AJ10: 229008.99 | AK10: 235847.25
A11: f_k_sveh_0 | B11: 124562 | C11: 125994.3 | D11: 127497.58 | E11: 129102.87 | F11: 130828.42 | G11: 132676.53 | H11: 134611.65 | I11: 136598.97 | J11: 138618.01 | K11: 140667.65 | L11: 142763.5 | M11: 144930.82 | N11: 147187.65 | O11: 149525.7 | P11: 151935.4 | Q11: 154410.58 | R11: 156968.33 | S11: 159629.64 | T11: 162413.8 | U11: 165334.74 | V11: 168401.55 | W11: 171620.46 | X11: 175001.37 | Y11: 178560.97 | Z11: 182321.58 | AA11: 186310.64 | AB11: 190557.79 | AC11: 195092.93 | AD11: 199939.59 | AE11: 205106.75 | AF11: 210589 | AG11: 216374.54 | AH11: 222453.11 | AI11: 228818.5 | AJ11: 235466.39 | AK11: 242389.79
A12: f_k_sgla_2 | B12: 17701.909 | C12: 17940.264 | D12: 18232.939 | E12: 18570.45 | F12: 18937.368 | G12: 19322.099 | H12: 19716.018 | I12: 20099.405 | J12: 20460.483 | K12: 20803.176 | L12: 21137.259 | M12: 21476.702 | N12: 21835.834 | O12: 22225.678 | P12: 22652.773 | Q12: 23117.985 | R12: 23617.611 | S12: 24143.037 | T12: 24684.983 | U12: 25237.445 | V12: 25800.016 | W12: 26377.516 | X12: 26977.539 | Y12: 27606.861 | Z12: 28267.655 | AA12: 28955.645 | AB12: 29660.18 | AC12: 30369.147 | AD12: 31074.866 | AE12: 31777.58 | AF12: 32485.034 | AG12: 33208.76 | AH12: 33959.032 | AI12: 34740.931 | AJ12: 35552.97 | AK12: 36388.906
... A67: f_k_seot_0 | B67: 102.42834 | C67: 103.61115 | D67: 104.78541 | E67: 105.95663 | F67: 107.12665 | G67: 108.3071 | H67: 109.52682 | I67: 110.81506 | J67: 112.19477 | K67: 113.67974 | L67: 115.27773 | M67: 116.995 | N67: 118.8377 | O67: 120.80962 | P67: 122.91687 | Q67: 125.16772 | R67: 127.56259 | S67: 130.10188 | T67: 132.78814 | U67: 135.62608 | V67: 138.6218 | W67: 141.78079 | X67: 145.10632 | Y67: 148.59792 | Z67: 152.25152 | AA67: 156.0616 | AB67: 160.02444 | AC67: 164.1409 | AD67: 168.41594 | AE67: 172.8539 | AF67: 177.4536 | AG67: 182.20601 | AH67: 187.09503 | AI67: 192.10054 | AJ67: 197.20213 | AK67: 202.38192

Sheet Results
A1: NB : on crée ici une liste : - globale, qui fusionne les sorties des reportings 1, 2 et 3 - "rationalisée" : suppression des doublons, et regroupements par thématique On continue par la suite à avoir 2 Excels de reporting (un "energie", fusion des reportings 1 et 2), et un "économie" (reporting 3)), dans lesquels on copiera cet onglet "results" (généré automatiquement par EViews). --> puis voir à la fin si on peut pas importer les graphs et tableaux dans l'excel automatiquement généré (éviterait les copiés collés, mais à voir si ça prend trop de temps, et si c'est pas trop gros comme excel)
A2: Nom du bloc de variables utilisé dans le code | B2: Sous-bloc de variables pour plus de lisibilité dans le Excel | E2: Year | F2: =date!B3 -> 2015 | G2: =date!C3 -> 2016 | H2: =date!D3 -> 2017 | I2: =date!E3 -> 2018 | J2: =date!F3 -> 2019 | K2: =date!G3 -> 2020 | L2: =date!H3 -> 2021 | M2: =date!I3 -> 2022 | ... AO2: =date!AK3 -> 2050
A3: HYBRID | B3: AUTOMOBILES (thousands) | C3: TOTAL STOCK SHOCK | E3: AUTO_2 | F3: =VLOOKUP($E3,Hybrid!$1:$1048576,MATCH(DATE(F$2,1,1),Hybrid!$A$1:$LI$1),FALSE) -> 32317.941 | G3: =VLOOKUP($E3,Hybrid!$1:$1048576,MATCH(DATE(G$2,1,1),Hybrid!$A$1:$LI$1),FALSE) -> 31929.011 | H3: =VLOOKUP($E3,Hybrid!$1:$1048576,MATCH(DATE(H$2,1,1),Hybrid!$A$1:$LI$1),FALSE) -> 31777.192 | I3: =VLOOKUP($E3,Hybrid!$1:$1048576,MATCH(DATE(I$2,1,1),Hybrid!$A$1:$LI$1),FALSE) -> 31765.1 | J3: =VLOOKUP($E3,Hybrid!$1:$1048576,MATCH(DATE(J$2,1,1),Hybrid!$A$1:$LI$1),FALSE) -> 31863.287 | K3: =VLOOKUP($E3,Hybrid!$1:$1048576,MATCH(DATE(K$2,1,1),Hybrid!$A$1:$LI$1),FALSE) -> 32030.775 | L3: =VLOOKUP($E3,Hybrid!$1:$1048576,MATCH(DATE(L$2,1,1),Hybrid!$A$1:$LI$1),FALSE) -> 32226.803 | M3: =VLOOKUP($E3,Hybrid!$1:$1048576,MATCH(DATE(M$2,1,1),Hybrid!$A$1:$LI$1),FALSE) -> 32345.894 | ... AO3: =VLOOKUP($E3,Hybrid!$1:$1048576,MATCH(DATE(AO$2,1,1),Hybrid!$A$1:$LI$1),FALSE) -> 49426.385
C4: OIL | E4: AUTO_cfut_2 | F4: =VLOOKUP($E4,Hybrid!$1:$1048576,MATCH(DATE(F$2,1,1),Hybrid!$A$1:$LI$1),FALSE) -> 32271.24 | G4: =VLOOKUP($E4,Hybrid!$1:$1048576,MATCH(DATE(G$2,1,1),Hybrid!$A$1:$LI$1),FALSE) -> 31831.204 | H4: =VLOOKUP($E4,Hybrid!$1:$1048576,MATCH(DATE(H$2,1,1),Hybrid!$A$1:$LI$1),FALSE) -> 31580.437 | I4: =VLOOKUP($E4,Hybrid!$1:$1048576,MATCH(DATE(I$2,1,1),Hybrid!$A$1:$LI$1),FALSE) -> 31395.068 | J4: =VLOOKUP($E4,Hybrid!$1:$1048576,MATCH(DATE(J$2,1,1),Hybrid!$A$1:$LI$1),FALSE) -> 31223.074 | K4: =VLOOKUP($E4,Hybrid!$1:$1048576,MATCH(DATE(K$2,1,1),Hybrid!$A$1:$LI$1),FALSE) -> 31025.722 | L4: =VLOOKUP($E4,Hybrid!$1:$1048576,MATCH(DATE(L$2,1,1),Hybrid!$A$1:$LI$1),FALSE) -> 30764.008 | M4: =VLOOKUP($E4,Hybrid!$1:$1048576,MATCH(DATE(M$2,1,1),Hybrid!$A$1:$LI$1),FALSE) -> 30298.828 | ... AO4: =VLOOKUP($E4,Hybrid!$1:$1048576,MATCH(DATE(AO$2,1,1),Hybrid!$A$1:$LI$1),FALSE) -> 3970.1504
D5: class A | E5: AUTO_ca_cfut_2 | F5: =VLOOKUP($E5,Hybrid!$1:$1048576,MATCH(DATE(F$2,1,1),Hybrid!$A$1:$LI$1),FALSE) -> 7095.7005 | G5: =VLOOKUP($E5,Hybrid!$1:$1048576,MATCH(DATE(G$2,1,1),Hybrid!$A$1:$LI$1),FALSE) -> 7132.8398 | H5: =VLOOKUP($E5,Hybrid!$1:$1048576,MATCH(DATE(H$2,1,1),Hybrid!$A$1:$LI$1),FALSE) -> 7215.3669 | I5: =VLOOKUP($E5,Hybrid!$1:$1048576,MATCH(DATE(I$2,1,1),Hybrid!$A$1:$LI$1),FALSE) -> 7309.0323 | J5: =VLOOKUP($E5,Hybrid!$1:$1048576,MATCH(DATE(J$2,1,1),Hybrid!$A$1:$LI$1),FALSE) -> 7399.4848 | K5: =VLOOKUP($E5,Hybrid!$1:$1048576,MATCH(DATE(K$2,1,1),Hybrid!$A$1:$LI$1),FALSE) -> 7475.5486 | L5: =VLOOKUP($E5,Hybrid!$1:$1048576,MATCH(DATE(L$2,1,1),Hybrid!$A$1:$LI$1),FALSE) -> 7526.2884 | M5: =VLOOKUP($E5,Hybrid!$1:$1048576,MATCH(DATE(M$2,1,1),Hybrid!$A$1:$LI$1),FALSE) -> 7512.2081 | ... AO5: =VLOOKUP($E5,Hybrid!$1:$1048576,MATCH(DATE(AO$2,1,1),Hybrid!$A$1:$LI$1),FALSE) -> 990.41518
D6: class B | E6: AUTO_cb_cfut_2 | F6: =VLOOKUP($E6,Hybrid!$1:$1048576,MATCH(DATE(F$2,1,1),Hybrid!$A$1:$LI$1),FALSE) -> 8251.2564 | G6: =VLOOKUP($E6,Hybrid!$1:$1048576,MATCH(DATE(G$2,1,1),Hybrid!$A$1:$LI$1),FALSE) -> 8172.8155 | H6: =VLOOKUP($E6,Hybrid!$1:$1048576,MATCH(DATE(H$2,1,1),Hybrid!$A$1:$LI$1),FALSE) -> 8143.908 | I6: =VLOOKUP($E6,Hybrid!$1:$1048576,MATCH(DATE(I$2,1,1),Hybrid!$A$1:$LI$1),FALSE) -> 8130.1181 | J6: =VLOOKUP($E6,Hybrid!$1:$1048576,MATCH(DATE(J$2,1,1),Hybrid!$A$1:$LI$1),FALSE) -> 8116.6371 | K6: =VLOOKUP($E6,Hybrid!$1:$1048576,MATCH(DATE(K$2,1,1),Hybrid!$A$1:$LI$1),FALSE) -> 8092.9022 | L6: =VLOOKUP($E6,Hybrid!$1:$1048576,MATCH(DATE(L$2,1,1),Hybrid!$A$1:$LI$1),FALSE) -> 8048.4436 | M6: =VLOOKUP($E6,Hybrid!$1:$1048576,MATCH(DATE(M$2,1,1),Hybrid!$A$1:$LI$1),FALSE) -> 7944.4223 | ... AO6: =VLOOKUP($E6,Hybrid!$1:$1048576,MATCH(DATE(AO$2,1,1),Hybrid!$A$1:$LI$1),FALSE) -> 998.58361
D7: class C | E7: AUTO_cc_cfut_2 | F7: =VLOOKUP($E7,Hybrid!$1:$1048576,MATCH(DATE(F$2,1,1),Hybrid!$A$1:$LI$1),FALSE) -> 6777.6025 | G7: =VLOOKUP($E7,Hybrid!$1:$1048576,MATCH(DATE(G$2,1,1),Hybrid!$A$1:$LI$1),FALSE) -> 6638.5946 | H7: =VLOOKUP($E7,Hybrid!$1:$1048576,MATCH(DATE(H$2,1,1),Hybrid!$A$1:$LI$1),FALSE) -> 6538.0811 | I7: =VLOOKUP($E7,Hybrid!$1:$1048576,MATCH(DATE(I$2,1,1),Hybrid!$A$1:$LI$1),FALSE) -> 6451.0457 | J7: =VLOOKUP($E7,Hybrid!$1:$1048576,MATCH(DATE(J$2,1,1),Hybrid!$A$1:$LI$1),FALSE) -> 6366.48 | K7: =VLOOKUP($E7,Hybrid!$1:$1048576,MATCH(DATE(K$2,1,1),Hybrid!$A$1:$LI$1),FALSE) -> 6277.287 | L7: =VLOOKUP($E7,Hybrid!$1:$1048576,MATCH(DATE(L$2,1,1),Hybrid!$A$1:$LI$1),FALSE) -> 6176.3486 | M7: =VLOOKUP($E7,Hybrid!$1:$1048576,MATCH(DATE(M$2,1,1),Hybrid!$A$1:$LI$1),FALSE) -> 6036.2982 | ... AO7: =VLOOKUP($E7,Hybrid!$1:$1048576,MATCH(DATE(AO$2,1,1),Hybrid!$A$1:$LI$1),FALSE) -> 728.12782
D8: class D | E8: AUTO_cd_cfut_2 | F8: =VLOOKUP($E8,Hybrid!$1:$1048576,MATCH(DATE(F$2,1,1),Hybrid!$A$1:$LI$1),FALSE) -> 4159.6639 | G8: =VLOOKUP($E8,Hybrid!$1:$1048576,MATCH(DATE(G$2,1,1),Hybrid!$A$1:$LI$1),FALSE) -> 4052.5069 | H8: =VLOOKUP($E8,Hybrid!$1:$1048576,MATCH(DATE(H$2,1,1),Hybrid!$A$1:$LI$1),FALSE) -> 3970.8964 | I8: =VLOOKUP($E8,Hybrid!$1:$1048576,MATCH(DATE(I$2,1,1),Hybrid!$A$1:$LI$1),FALSE) -> 3902.3818 | J8: =VLOOKUP($E8,Hybrid!$1:$1048576,MATCH(DATE(J$2,1,1),Hybrid!$A$1:$LI$1),FALSE) -> 3841.8525 | K8: =VLOOKUP($E8,Hybrid!$1:$1048576,MATCH(DATE(K$2,1,1),Hybrid!$A$1:$LI$1),FALSE) -> 3784.8111 | L8: =VLOOKUP($E8,Hybrid!$1:$1048576,MATCH(DATE(L$2,1,1),Hybrid!$A$1:$LI$1),FALSE) -> 3726.6655 | M8: =VLOOKUP($E8,Hybrid!$1:$1048576,MATCH(DATE(M$2,1,1),Hybrid!$A$1:$LI$1),FALSE) -> 3653.245 | ... AO8: =VLOOKUP($E8,Hybrid!$1:$1048576,MATCH(DATE(AO$2,1,1),Hybrid!$A$1:$LI$1),FALSE) -> 511.06273
D9: class E | E9: AUTO_ce_cfut_2 | F9: =VLOOKUP($E9,Hybrid!$1:$1048576,MATCH(DATE(F$2,1,1),Hybrid!$A$1:$LI$1),FALSE) -> 2503.7292 | G9: =VLOOKUP($E9,Hybrid!$1:$1048576,MATCH(DATE(G$2,1,1),Hybrid!$A$1:$LI$1),FALSE) -> 2441.4545 | H9: =VLOOKUP($E9,Hybrid!$1:$1048576,MATCH(DATE(H$2,1,1),Hybrid!$A$1:$LI$1),FALSE) -> 2393.7453 | I9: =VLOOKUP($E9,Hybrid!$1:$1048576,MATCH(DATE(I$2,1,1),Hybrid!$A$1:$LI$1),FALSE) -> 2352.9276 | J9: =VLOOKUP($E9,Hybrid!$1:$1048576,MATCH(DATE(J$2,1,1),Hybrid!$A$1:$LI$1),FALSE) -> 2315.905 | K9: =VLOOKUP($E9,Hybrid!$1:$1048576,MATCH(DATE(K$2,1,1),Hybrid!$A$1:$LI$1),FALSE) -> 2280.1025 | L9: =VLOOKUP($E9,Hybrid!$1:$1048576,MATCH(DATE(L$2,1,1),Hybrid!$A$1:$LI$1),FALSE) -> 2242.8305 | M9: =VLOOKUP($E9,Hybrid!$1:$1048576,MATCH(DATE(M$2,1,1),Hybrid!$A$1:$LI$1),FALSE) -> 2195.4681 | ... AO9: =VLOOKUP($E9,Hybrid!$1:$1048576,MATCH(DATE(AO$2,1,1),Hybrid!$A$1:$LI$1),FALSE) -> 304.594
D10: class F | E10: AUTO_cf_cfut_2 | F10: =VLOOKUP($E10,Hybrid!$1:$1048576,MATCH(DATE(F$2,1,1),Hybrid!$A$1:$LI$1),FALSE) -> 1243.6668 | G10: =VLOOKUP($E10,Hybrid!$1:$1048576,MATCH(DATE(G$2,1,1),Hybrid!$A$1:$LI$1),FALSE) -> 1210.3024 | H10: =VLOOKUP($E10,Hybrid!$1:$1048576,MATCH(DATE(H$2,1,1),Hybrid!$A$1:$LI$1),FALSE) -> 1183.3249 | I10: =VLOOKUP($E10,Hybrid!$1:$1048576,MATCH(DATE(I$2,1,1),Hybrid!$A$1:$LI$1),FALSE) -> 1159.1944 | J10: =VLOOKUP($E10,Hybrid!$1:$1048576,MATCH(DATE(J$2,1,1),Hybrid!$A$1:$LI$1),FALSE) -> 1136.5697 | K10: =VLOOKUP($E10,Hybrid!$1:$1048576,MATCH(DATE(K$2,1,1),Hybrid!$A$1:$LI$1),FALSE) -> 1114.3086 | L10: =VLOOKUP($E10,Hybrid!$1:$1048576,MATCH(DATE(L$2,1,1),Hybrid!$A$1:$LI$1),FALSE) -> 1091.169 | M10: =VLOOKUP($E10,Hybrid!$1:$1048576,MATCH(DATE(M$2,1,1),Hybrid!$A$1:$LI$1),FALSE) -> 1063.3045 | ... AO10: =VLOOKUP($E10,Hybrid!$1:$1048576,MATCH(DATE(AO$2,1,1),Hybrid!$A$1:$LI$1),FALSE) -> 164.08592
D11: class G | E11: AUTO_cg_cfut_2 | F11: =VLOOKUP($E11,Hybrid!$1:$1048576,MATCH(DATE(F$2,1,1),Hybrid!$A$1:$LI$1),FALSE) -> 2239.6206 | G11: =VLOOKUP($E11,Hybrid!$1:$1048576,MATCH(DATE(G$2,1,1),Hybrid!$A$1:$LI$1),FALSE) -> 2182.69 | H11: =VLOOKUP($E11,Hybrid!$1:$1048576,MATCH(DATE(H$2,1,1),Hybrid!$A$1:$LI$1),FALSE) -> 2135.1141 | I11: =VLOOKUP($E11,Hybrid!$1:$1048576,MATCH(DATE(I$2,1,1),Hybrid!$A$1:$LI$1),FALSE) -> 2090.3679 | J11: =VLOOKUP($E11,Hybrid!$1:$1048576,MATCH(DATE(J$2,1,1),Hybrid!$A$1:$LI$1),FALSE) -> 2046.1446 | K11: =VLOOKUP($E11,Hybrid!$1:$1048576,MATCH(DATE(K$2,1,1),Hybrid!$A$1:$LI$1),FALSE) -> 2000.7616 | L11: =VLOOKUP($E11,Hybrid!$1:$1048576,MATCH(DATE(L$2,1,1),Hybrid!$A$1:$LI$1),FALSE) -> 1952.2623 | M11: =VLOOKUP($E11,Hybrid!$1:$1048576,MATCH(DATE(M$2,1,1),Hybrid!$A$1:$LI$1),FALSE) -> 1893.8814 | ... AO11: =VLOOKUP($E11,Hybrid!$1:$1048576,MATCH(DATE(AO$2,1,1),Hybrid!$A$1:$LI$1),FALSE) -> 273.28115
C12: ELEC | E12: AUTO_cele_2 | F12: =VLOOKUP($E12,Hybrid!$1:$1048576,MATCH(DATE(F$2,1,1),Hybrid!$A$1:$LI$1),FALSE) -> 44.765 | G12: =VLOOKUP($E12,Hybrid!$1:$1048576,MATCH(DATE(G$2,1,1),Hybrid!$A$1:$LI$1),FALSE) -> 95.818005 | H12: =VLOOKUP($E12,Hybrid!$1:$1048576,MATCH(DATE(H$2,1,1),Hybrid!$A$1:$LI$1),FALSE) -> 194.70329 | I12: =VLOOKUP($E12,Hybrid!$1:$1048576,MATCH(DATE(I$2,1,1),Hybrid!$A$1:$LI$1),FALSE) -> 367.91774 | J12: =VLOOKUP($E12,Hybrid!$1:$1048576,MATCH(DATE(J$2,1,1),Hybrid!$A$1:$LI$1),FALSE) -> 638.04027 | K12: =VLOOKUP($E12,Hybrid!$1:$1048576,MATCH(DATE(K$2,1,1),Hybrid!$A$1:$LI$1),FALSE) -> 1002.8291 | L12: =VLOOKUP($E12,Hybrid!$1:$1048576,MATCH(DATE(L$2,1,1),Hybrid!$A$1:$LI$1),FALSE) -> 1460.5286 | M12: =VLOOKUP($E12,Hybrid!$1:$1048576,MATCH(DATE(M$2,1,1),Hybrid!$A$1:$LI$1),FALSE) -> 2044.7799 | ... AO12: =VLOOKUP($E12,Hybrid!$1:$1048576,MATCH(DATE(AO$2,1,1),Hybrid!$A$1:$LI$1),FALSE) -> 45455.755
D13: class A | E13: AUTO_ca_cele_2 | F13: =VLOOKUP($E13,Hybrid!$1:$1048576,MATCH(DATE(F$2,1,1),Hybrid!$A$1:$LI$1),FALSE) -> 9.8427899 | G13: =VLOOKUP($E13,Hybrid!$1:$1048576,MATCH(DATE(G$2,1,1),Hybrid!$A$1:$LI$1),FALSE) -> 24.308529 | H13: =VLOOKUP($E13,Hybrid!$1:$1048576,MATCH(DATE(H$2,1,1),Hybrid!$A$1:$LI$1),FALSE) -> 52.397495 | I13: =VLOOKUP($E13,Hybrid!$1:$1048576,MATCH(DATE(I$2,1,1),Hybrid!$A$1:$LI$1),FALSE) -> 101.94149 | J13: =VLOOKUP($E13,Hybrid!$1:$1048576,MATCH(DATE(J$2,1,1),Hybrid!$A$1:$LI$1),FALSE) -> 179.82206 | K13: =VLOOKUP($E13,Hybrid!$1:$1048576,MATCH(DATE(K$2,1,1),Hybrid!$A$1:$LI$1),FALSE) -> 285.67404 | L13: =VLOOKUP($E13,Hybrid!$1:$1048576,MATCH(DATE(L$2,1,1),Hybrid!$A$1:$LI$1),FALSE) -> 419.35426 | M13: =VLOOKUP($E13,Hybrid!$1:$1048576,MATCH(DATE(M$2,1,1),Hybrid!$A$1:$LI$1),FALSE) -> 592.1942 | ... AO13: =VLOOKUP($E13,Hybrid!$1:$1048576,MATCH(DATE(AO$2,1,1),Hybrid!$A$1:$LI$1),FALSE) -> 14151.931
D14: class B | E14: AUTO_cb_cele_2 | F14: =VLOOKUP($E14,Hybrid!$1:$1048576,MATCH(DATE(F$2,1,1),Hybrid!$A$1:$LI$1),FALSE) -> 11.445717 | G14: =VLOOKUP($E14,Hybrid!$1:$1048576,MATCH(DATE(G$2,1,1),Hybrid!$A$1:$LI$1),FALSE) -> 26.55309 | H14: =VLOOKUP($E14,Hybrid!$1:$1048576,MATCH(DATE(H$2,1,1),Hybrid!$A$1:$LI$1),FALSE) -> 56.492548 | I14: =VLOOKUP($E14,Hybrid!$1:$1048576,MATCH(DATE(I$2,1,1),Hybrid!$A$1:$LI$1),FALSE) -> 109.67056 | J14: =VLOOKUP($E14,Hybrid!$1:$1048576,MATCH(DATE(J$2,1,1),Hybrid!$A$1:$LI$1),FALSE) -> 193.30399 | K14: =VLOOKUP($E14,Hybrid!$1:$1048576,MATCH(DATE(K$2,1,1),Hybrid!$A$1:$LI$1),FALSE) -> 306.82052 | L14: =VLOOKUP($E14,Hybrid!$1:$1048576,MATCH(DATE(L$2,1,1),Hybrid!$A$1:$LI$1),FALSE) -> 449.81011 | M14: =VLOOKUP($E14,Hybrid!$1:$1048576,MATCH(DATE(M$2,1,1),Hybrid!$A$1:$LI$1),FALSE) -> 633.18261 | ... AO14: =VLOOKUP($E14,Hybrid!$1:$1048576,MATCH(DATE(AO$2,1,1),Hybrid!$A$1:$LI$1),FALSE) -> 13801.752
D15: class C | E15: AUTO_cc_cele_2 | F15: =VLOOKUP($E15,Hybrid!$1:$1048576,MATCH(DATE(F$2,1,1),Hybrid!$A$1:$LI$1),FALSE) -> 9.4015406 | G15: =VLOOKUP($E15,Hybrid!$1:$1048576,MATCH(DATE(G$2,1,1),Hybrid!$A$1:$LI$1),FALSE) -> 20.942646 | H15: =VLOOKUP($E15,Hybrid!$1:$1048576,MATCH(DATE(H$2,1,1),Hybrid!$A$1:$LI$1),FALSE) -> 44.274219 | I15: =VLOOKUP($E15,Hybrid!$1:$1048576,MATCH(DATE(I$2,1,1),Hybrid!$A$1:$LI$1),FALSE) -> 85.956733 | J15: =VLOOKUP($E15,Hybrid!$1:$1048576,MATCH(DATE(J$2,1,1),Hybrid!$A$1:$LI$1),FALSE) -> 151.46397 | K15: =VLOOKUP($E15,Hybrid!$1:$1048576,MATCH(DATE(K$2,1,1),Hybrid!$A$1:$LI$1),FALSE) -> 240.16919 | L15: =VLOOKUP($E15,Hybrid!$1:$1048576,MATCH(DATE(L$2,1,1),Hybrid!$A$1:$LI$1),FALSE) -> 351.51294 | M15: =VLOOKUP($E15,Hybrid!$1:$1048576,MATCH(DATE(M$2,1,1),Hybrid!$A$1:$LI$1),FALSE) -> 492.93276 | ... AO15: =VLOOKUP($E15,Hybrid!$1:$1048576,MATCH(DATE(AO$2,1,1),Hybrid!$A$1:$LI$1),FALSE) -> 9795.0789
D16: class D | E16: AUTO_cd_cele_2 | F16: =VLOOKUP($E16,Hybrid!$1:$1048576,MATCH(DATE(F$2,1,1),Hybrid!$A$1:$LI$1),FALSE) -> 5.7700713 | G16: =VLOOKUP($E16,Hybrid!$1:$1048576,MATCH(DATE(G$2,1,1),Hybrid!$A$1:$LI$1),FALSE) -> 9.8900605 | H16: =VLOOKUP($E16,Hybrid!$1:$1048576,MATCH(DATE(H$2,1,1),Hybrid!$A$1:$LI$1),FALSE) -> 17.317962 | I16: =VLOOKUP($E16,Hybrid!$1:$1048576,MATCH(DATE(I$2,1,1),Hybrid!$A$1:$LI$1),FALSE) -> 29.785459 | J16: =VLOOKUP($E16,Hybrid!$1:$1048576,MATCH(DATE(J$2,1,1),Hybrid!$A$1:$LI$1),FALSE) -> 48.781217 | K16: =VLOOKUP($E16,Hybrid!$1:$1048576,MATCH(DATE(K$2,1,1),Hybrid!$A$1:$LI$1),FALSE) -> 74.139577 | L16: =VLOOKUP($E16,Hybrid!$1:$1048576,MATCH(DATE(L$2,1,1),Hybrid!$A$1:$LI$1),FALSE) -> 105.73738 | M16: =VLOOKUP($E16,Hybrid!$1:$1048576,MATCH(DATE(M$2,1,1),Hybrid!$A$1:$LI$1),FALSE) -> 145.87217 | ... AO16: =VLOOKUP($E16,Hybrid!$1:$1048576,MATCH(DATE(AO$2,1,1),Hybrid!$A$1:$LI$1),FALSE) -> 3783.3041
D17: class E | E17: AUTO_ce_cele_2 | F17: =VLOOKUP($E17,Hybrid!$1:$1048576,MATCH(DATE(F$2,1,1),Hybrid!$A$1:$LI$1),FALSE) -> 3.4730441 | G17: =VLOOKUP($E17,Hybrid!$1:$1048576,MATCH(DATE(G$2,1,1),Hybrid!$A$1:$LI$1),FALSE) -> 6.1197834 | H17: =VLOOKUP($E17,Hybrid!$1:$1048576,MATCH(DATE(H$2,1,1),Hybrid!$A$1:$LI$1),FALSE) -> 10.922182 | I17: =VLOOKUP($E17,Hybrid!$1:$1048576,MATCH(DATE(I$2,1,1),Hybrid!$A$1:$LI$1),FALSE) -> 18.974748 | J17: =VLOOKUP($E17,Hybrid!$1:$1048576,MATCH(DATE(J$2,1,1),Hybrid!$A$1:$LI$1),FALSE) -> 31.189098 | K17: =VLOOKUP($E17,Hybrid!$1:$1048576,MATCH(DATE(K$2,1,1),Hybrid!$A$1:$LI$1),FALSE) -> 47.425313 | L17: =VLOOKUP($E17,Hybrid!$1:$1048576,MATCH(DATE(L$2,1,1),Hybrid!$A$1:$LI$1),FALSE) -> 67.555193 | M17: =VLOOKUP($E17,Hybrid!$1:$1048576,MATCH(DATE(M$2,1,1),Hybrid!$A$1:$LI$1),FALSE) -> 92.81412 | ... AO17: =VLOOKUP($E17,Hybrid!$1:$1048576,MATCH(DATE(AO$2,1,1),Hybrid!$A$1:$LI$1),FALSE) -> 2255.55
D18: class F | E18: AUTO_cf_cele_2 | F18: =VLOOKUP($E18,Hybrid!$1:$1048576,MATCH(DATE(F$2,1,1),Hybrid!$A$1:$LI$1),FALSE) -> 1.7251505 | G18: =VLOOKUP($E18,Hybrid!$1:$1048576,MATCH(DATE(G$2,1,1),Hybrid!$A$1:$LI$1),FALSE) -> 2.7749683 | H18: =VLOOKUP($E18,Hybrid!$1:$1048576,MATCH(DATE(H$2,1,1),Hybrid!$A$1:$LI$1),FALSE) -> 4.5165418 | I18: =VLOOKUP($E18,Hybrid!$1:$1048576,MATCH(DATE(I$2,1,1),Hybrid!$A$1:$LI$1),FALSE) -> 7.249672 | J18: =VLOOKUP($E18,Hybrid!$1:$1048576,MATCH(DATE(J$2,1,1),Hybrid!$A$1:$LI$1),FALSE) -> 11.200749 | K18: =VLOOKUP($E18,Hybrid!$1:$1048576,MATCH(DATE(K$2,1,1),Hybrid!$A$1:$LI$1),FALSE) -> 16.271969 | L18: =VLOOKUP($E18,Hybrid!$1:$1048576,MATCH(DATE(L$2,1,1),Hybrid!$A$1:$LI$1),FALSE) -> 22.363051 | M18: =VLOOKUP($E18,Hybrid!$1:$1048576,MATCH(DATE(M$2,1,1),Hybrid!$A$1:$LI$1),FALSE) -> 29.704176 | ... AO18: =VLOOKUP($E18,Hybrid!$1:$1048576,MATCH(DATE(AO$2,1,1),Hybrid!$A$1:$LI$1),FALSE) -> 628.41253
D19: class G | E19: AUTO_cg_cele_2 | F19: =VLOOKUP($E19,Hybrid!$1:$1048576,MATCH(DATE(F$2,1,1),Hybrid!$A$1:$LI$1),FALSE) -> 3.1066862 | G19: =VLOOKUP($E19,Hybrid!$1:$1048576,MATCH(DATE(G$2,1,1),Hybrid!$A$1:$LI$1),FALSE) -> 5.2289267 | H19: =VLOOKUP($E19,Hybrid!$1:$1048576,MATCH(DATE(H$2,1,1),Hybrid!$A$1:$LI$1),FALSE) -> 8.7823369 | I19: =VLOOKUP($E19,Hybrid!$1:$1048576,MATCH(DATE(I$2,1,1),Hybrid!$A$1:$LI$1),FALSE) -> 14.339075 | J19: =VLOOKUP($E19,Hybrid!$1:$1048576,MATCH(DATE(J$2,1,1),Hybrid!$A$1:$LI$1),FALSE) -> 22.279182 | K19: =VLOOKUP($E19,Hybrid!$1:$1048576,MATCH(DATE(K$2,1,1),Hybrid!$A$1:$LI$1),FALSE) -> 32.328482 | L19: =VLOOKUP($E19,Hybrid!$1:$1048576,MATCH(DATE(L$2,1,1),Hybrid!$A$1:$LI$1),FALSE) -> 44.195707 | M19: =VLOOKUP($E19,Hybrid!$1:$1048576,MATCH(DATE(M$2,1,1),Hybrid!$A$1:$LI$1),FALSE) -> 58.079827 | ... AO19: =VLOOKUP($E19,Hybrid!$1:$1048576,MATCH(DATE(AO$2,1,1),Hybrid!$A$1:$LI$1),FALSE) -> 1039.7265
C20: GAS | E20: AUTO_cgas_2 | F20: =VLOOKUP($E20,Hybrid!$1:$1048576,MATCH(DATE(F$2,1,1),Hybrid!$A$1:$LI$1),FALSE) -> 1.936 | G20: =VLOOKUP($E20,Hybrid!$1:$1048576,MATCH(DATE(G$2,1,1),Hybrid!$A$1:$LI$1),FALSE) -> 1.9890157 | H20: =VLOOKUP($E20,Hybrid!$1:$1048576,MATCH(DATE(H$2,1,1),Hybrid!$A$1:$LI$1),FALSE) -> 2.0517417 | I20: =VLOOKUP($E20,Hybrid!$1:$1048576,MATCH(DATE(I$2,1,1),Hybrid!$A$1:$LI$1),FALSE) -> 2.1144021 | J20: =VLOOKUP($E20,Hybrid!$1:$1048576,MATCH(DATE(J$2,1,1),Hybrid!$A$1:$LI$1),FALSE) -> 2.1730579 | K20: =VLOOKUP($E20,Hybrid!$1:$1048576,MATCH(DATE(K$2,1,1),Hybrid!$A$1:$LI$1),FALSE) -> 2.2247929 | L20: =VLOOKUP($E20,Hybrid!$1:$1048576,MATCH(DATE(L$2,1,1),Hybrid!$A$1:$LI$1),FALSE) -> 2.2665971 | M20: =VLOOKUP($E20,Hybrid!$1:$1048576,MATCH(DATE(M$2,1,1),Hybrid!$A$1:$LI$1),FALSE) -> 2.2869841 | ... AO20: =VLOOKUP($E20,Hybrid!$1:$1048576,MATCH(DATE(AO$2,1,1),Hybrid!$A$1:$LI$1),FALSE) -> 0.47873566
D21: class A | E21: AUTO_ca_cgas_2 | F21: =VLOOKUP($E21,Hybrid!$1:$1048576,MATCH(DATE(F$2,1,1),Hybrid!$A$1:$LI$1),FALSE) -> 0.4256817 | G21: =VLOOKUP($E21,Hybrid!$1:$1048576,MATCH(DATE(G$2,1,1),Hybrid!$A$1:$LI$1),FALSE) -> 0.44858712 | H21: =VLOOKUP($E21,Hybrid!$1:$1048576,MATCH(DATE(H$2,1,1),Hybrid!$A$1:$LI$1),FALSE) -> 0.47411683 | I21: =VLOOKUP($E21,Hybrid!$1:$1048576,MATCH(DATE(I$2,1,1),Hybrid!$A$1:$LI$1),FALSE) -> 0.49952623 | J21: =VLOOKUP($E21,Hybrid!$1:$1048576,MATCH(DATE(J$2,1,1),Hybrid!$A$1:$LI$1),FALSE) -> 0.52368998 | K21: =VLOOKUP($E21,Hybrid!$1:$1048576,MATCH(DATE(K$2,1,1),Hybrid!$A$1:$LI$1),FALSE) -> 0.54572606 | L21: =VLOOKUP($E21,Hybrid!$1:$1048576,MATCH(DATE(L$2,1,1),Hybrid!$A$1:$LI$1),FALSE) -> 0.56475468 | M21: =VLOOKUP($E21,Hybrid!$1:$1048576,MATCH(DATE(M$2,1,1),Hybrid!$A$1:$LI$1),FALSE) -> 0.57748014 | ... AO21: =VLOOKUP($E21,Hybrid!$1:$1048576,MATCH(DATE(AO$2,1,1),Hybrid!$A$1:$LI$1),FALSE) -> 0.12169248
D22: class B | E22: AUTO_cb_cgas_2 | F22: =VLOOKUP($E22,Hybrid!$1:$1048576,MATCH(DATE(F$2,1,1),Hybrid!$A$1:$LI$1),FALSE) -> 0.49500523 | G22: =VLOOKUP($E22,Hybrid!$1:$1048576,MATCH(DATE(G$2,1,1),Hybrid!$A$1:$LI$1),FALSE) -> 0.51142274 | H22: =VLOOKUP($E22,Hybrid!$1:$1048576,MATCH(DATE(H$2,1,1),Hybrid!$A$1:$LI$1),FALSE) -> 0.53046267 | I22: =VLOOKUP($E22,Hybrid!$1:$1048576,MATCH(DATE(I$2,1,1),Hybrid!$A$1:$LI$1),FALSE) -> 0.54939366 | J22: =VLOOKUP($E22,Hybrid!$1:$1048576,MATCH(DATE(J$2,1,1),Hybrid!$A$1:$LI$1),FALSE) -> 0.56707726 | K22: =VLOOKUP($E22,Hybrid!$1:$1048576,MATCH(DATE(K$2,1,1),Hybrid!$A$1:$LI$1),FALSE) -> 0.58270605 | L22: =VLOOKUP($E22,Hybrid!$1:$1048576,MATCH(DATE(L$2,1,1),Hybrid!$A$1:$LI$1),FALSE) -> 0.59546186 | M22: =VLOOKUP($E22,Hybrid!$1:$1048576,MATCH(DATE(M$2,1,1),Hybrid!$A$1:$LI$1),FALSE) -> 0.60212583 | ... AO22: =VLOOKUP($E22,Hybrid!$1:$1048576,MATCH(DATE(AO$2,1,1),Hybrid!$A$1:$LI$1),FALSE) -> 0.12119679
D23: class C | E23: AUTO_cc_cgas_2 | F23: =VLOOKUP($E23,Hybrid!$1:$1048576,MATCH(DATE(F$2,1,1),Hybrid!$A$1:$LI$1),FALSE) -> 0.40659852 | G23: =VLOOKUP($E23,Hybrid!$1:$1048576,MATCH(DATE(G$2,1,1),Hybrid!$A$1:$LI$1),FALSE) -> 0.41381867 | H23: =VLOOKUP($E23,Hybrid!$1:$1048576,MATCH(DATE(H$2,1,1),Hybrid!$A$1:$LI$1),FALSE) -> 0.4229127 | I23: =VLOOKUP($E23,Hybrid!$1:$1048576,MATCH(DATE(I$2,1,1),Hybrid!$A$1:$LI$1),FALSE) -> 0.43191353 | J23: =VLOOKUP($E23,Hybrid!$1:$1048576,MATCH(DATE(J$2,1,1),Hybrid!$A$1:$LI$1),FALSE) -> 0.43999027 | K23: =VLOOKUP($E23,Hybrid!$1:$1048576,MATCH(DATE(K$2,1,1),Hybrid!$A$1:$LI$1),FALSE) -> 0.44662059 | L23: =VLOOKUP($E23,Hybrid!$1:$1048576,MATCH(DATE(L$2,1,1),Hybrid!$A$1:$LI$1),FALSE) -> 0.45126665 | M23: =VLOOKUP($E23,Hybrid!$1:$1048576,MATCH(DATE(M$2,1,1),Hybrid!$A$1:$LI$1),FALSE) -> 0.45167657 | ... AO23: =VLOOKUP($E23,Hybrid!$1:$1048576,MATCH(DATE(AO$2,1,1),Hybrid!$A$1:$LI$1),FALSE) -> 0.087294879
D24: class D | E24: AUTO_cd_cgas_2 | F24: =VLOOKUP($E24,Hybrid!$1:$1048576,MATCH(DATE(F$2,1,1),Hybrid!$A$1:$LI$1),FALSE) -> 0.24954447 | G24: =VLOOKUP($E24,Hybrid!$1:$1048576,MATCH(DATE(G$2,1,1),Hybrid!$A$1:$LI$1),FALSE) -> 0.2521407 | H24: =VLOOKUP($E24,Hybrid!$1:$1048576,MATCH(DATE(H$2,1,1),Hybrid!$A$1:$LI$1),FALSE) -> 0.25602029 | I24: =VLOOKUP($E24,Hybrid!$1:$1048576,MATCH(DATE(I$2,1,1),Hybrid!$A$1:$LI$1),FALSE) -> 0.26022406 | J24: =VLOOKUP($E24,Hybrid!$1:$1048576,MATCH(DATE(J$2,1,1),Hybrid!$A$1:$LI$1),FALSE) -> 0.26438799 | K24: =VLOOKUP($E24,Hybrid!$1:$1048576,MATCH(DATE(K$2,1,1),Hybrid!$A$1:$LI$1),FALSE) -> 0.26818899 | L24: =VLOOKUP($E24,Hybrid!$1:$1048576,MATCH(DATE(L$2,1,1),Hybrid!$A$1:$LI$1),FALSE) -> 0.27128672 | M24: =VLOOKUP($E24,Hybrid!$1:$1048576,MATCH(DATE(M$2,1,1),Hybrid!$A$1:$LI$1),FALSE) -> 0.27252744 | ... AO24: =VLOOKUP($E24,Hybrid!$1:$1048576,MATCH(DATE(AO$2,1,1),Hybrid!$A$1:$LI$1),FALSE) -> 0.06096558
D25: class E | E25: AUTO_ce_cgas_2 | F25: =VLOOKUP($E25,Hybrid!$1:$1048576,MATCH(DATE(F$2,1,1),Hybrid!$A$1:$LI$1),FALSE) -> 0.15020247 | G25: =VLOOKUP($E25,Hybrid!$1:$1048576,MATCH(DATE(G$2,1,1),Hybrid!$A$1:$LI$1),FALSE) -> 0.15195198 | H25: =VLOOKUP($E25,Hybrid!$1:$1048576,MATCH(DATE(H$2,1,1),Hybrid!$A$1:$LI$1),FALSE) -> 0.15440868 | I25: =VLOOKUP($E25,Hybrid!$1:$1048576,MATCH(DATE(I$2,1,1),Hybrid!$A$1:$LI$1),FALSE) -> 0.15697887 | J25: =VLOOKUP($E25,Hybrid!$1:$1048576,MATCH(DATE(J$2,1,1),Hybrid!$A$1:$LI$1),FALSE) -> 0.15944041 | K25: =VLOOKUP($E25,Hybrid!$1:$1048576,MATCH(DATE(K$2,1,1),Hybrid!$A$1:$LI$1),FALSE) -> 0.16160855 | L25: =VLOOKUP($E25,Hybrid!$1:$1048576,MATCH(DATE(L$2,1,1),Hybrid!$A$1:$LI$1),FALSE) -> 0.16328366 | M25: =VLOOKUP($E25,Hybrid!$1:$1048576,MATCH(DATE(M$2,1,1),Hybrid!$A$1:$LI$1),FALSE) -> 0.16376269 | ... AO25: =VLOOKUP($E25,Hybrid!$1:$1048576,MATCH(DATE(AO$2,1,1),Hybrid!$A$1:$LI$1),FALSE) -> 0.036307907
