Workbook
Name formatResults: [1]ResultsEXR10!$A$50

Sheet Export
A1: _date_ | B1: 42005 | C1: 42370 | D1: 42736 | E1: 43101 | F1: 43466 | G1: 43831 | H1: 44197 | I1: 44562 | J1: 44927 | K1: 45292 | L1: 45658 | M1: 46023 | N1: 46388 | O1: 46753 | P1: 47119 | Q1: 47484 | R1: 47849 | S1: 48214 | T1: 48580 | U1: 48945 | V1: 49310 | W1: 49675 | X1: 50041 | Y1: 50406 | Z1: 50771 | AA1: 51136 | AB1: 51502 | AC1: 51867 | AD1: 52232 | AE1: 52597 | AF1: 52963 | AG1: 53328 | AH1: 53693 | AI1: 54058 | AJ1: 54424 | AK1: 54789 | AL1: 55154 | AM1: 55519 | AN1: 55885 | AO1: 56250 | AP1: 56615 | AQ1: 56980 | AR1: 57346 | AS1: 57711 | AT1: 58076 | AU1: 58441 | AV1: 58807 | AW1: 59172 | AX1: 59537 | AY1: 59902 | AZ1: 60268 | BA1: 60633 | BB1: 60998 | BC1: 61363 | BD1: 61729 | BE1: 62094
A2: x_2 | B2: 594956.81 | C2: 602646.73 | D2: 611511.06 | E2: 620789.33 | F2: 630339.16 | G2: 640050.09 | H2: 649186.33 | I2: 658341.84 | J2: 667481.26 | K2: 676580.08 | L2: 686684.1 | M2: 695487.73 | N2: 704223.43 | O2: 712900.1 | P2: 721531.21 | Q2: 730134.05 | R2: 738562.1 | S2: 747008.78 | T2: 755498.26 | U2: 764054.59 | V2: 771936.6 | W2: 780708.27 | X2: 789616.47 | Y2: 798677.42 | Z2: 807905.74 | AA2: 815142.41 | AB2: 823812.9 | AC2: 832692.45 | AD2: 841788.88 | AE2: 851107.33 | AF2: 860650.64 | AG2: 870456.83 | AH2: 880487.21 | AI2: 890738.79 | AJ2: 901207.29 | AK2: 911887.54 | AL2: 922588.47 | AM2: 933487.45 | AN2: 944580.32 | AO2: 955862.11 | AP2: 967327.88 | AQ2: 979025.82 | AR2: 990899.73 | AS2: 1002946 | AT2: 1015161.4 | AU2: 1027543.1 | AV2: 1040313.9 | AW2: 1053249.7 | AX2: 1066348 | AY2: 1079606.9 | AZ2: 1093025.3 | BA2: 1106715.1 | BB2: 1120566.8 | BC2: 1134581 | BD2: 1148759 | BE2: 1163102.5
A3: x_0 | B3: 633304.83 | C3: 643304.69 | D3: 654245.97 | E3: 665443.41 | F3: 676840.23 | G3: 688384.13 | H3: 699373.2 | I3: 710430.17 | J3: 721541.69 | K3: 732702.11 | L3: 745064.18 | M3: 756324.52 | N3: 767641.28 | O3: 779029.2 | P3: 790504.74 | Q3: 802085.67 | R3: 813790.63 | S3: 825638.72 | T3: 837648.92 | U3: 849839.59 | V3: 861374.88 | W3: 873980.56 | X3: 886820.02 | Y3: 899904.42 | Z3: 913243.68 | AA3: 924382.53 | AB3: 937093.78 | AC3: 950084.63 | AD3: 963361.56 | AE3: 976928.88 | AF3: 990788.92 | AG3: 1004942.1 | AH3: 1019387.2 | AI3: 1034121.2 | AJ3: 1049140.2 | AK3: 1064439.4 | AL3: 1079413.7 | AM3: 1094651.8 | AN3: 1110152.5 | AO3: 1125913.8 | AP3: 1141933.6 | AQ3: 1158209.5 | AR3: 1174739.1 | AS3: 1191520.1 | AT3: 1208550.2 | AU3: 1225827.1 | AV3: 1243403.8 | AW3: 1261224 | AX3: 1279285.8 | AY3: 1297588.1 | AZ3: 1316129.9 | BA3: 1334911 | BB3: 1353931.8 | BC3: 1373193.1 | BD3: 1392696.5 | BE3: 1412443.6
A4: x_cagr_2 | B4: 14890.888 | C4: 15079.39 | D4: 15299.137 | E4: 15531.921 | F4: 15773.942 | G4: 16021.697 | H4: 16255.888 | I4: 16490.66 | J4: 16724.619 | K4: 16956.83 | L4: 17213.374 | M4: 17436.264 | N4: 17656.33 | O4: 17873.798 | P4: 18089.06 | Q4: 18302.635 | R4: 18510.9 | S4: 18718.822 | T4: 18927.124 | U4: 19136.538 | V4: 19328.599 | W4: 19542.641 | X4: 19759.94 | Y4: 19981.009 | Z4: 20206.293 | AA4: 20381.772 | AB4: 20593.263 | AC4: 20810.244 | AD4: 21032.992 | AE4: 21261.675 | AF4: 21496.375 | AG4: 21738.051 | AH4: 21985.715 | AI4: 22239.271 | AJ4: 22498.58 | AK4: 22763.477 | AL4: 23029.255 | AM4: 23300.288 | AN4: 23576.457 | AO4: 23857.602 | AP4: 24143.555 | AQ4: 24435.488 | AR4: 24731.948 | AS4: 25032.798 | AT4: 25337.917 | AU4: 25647.203 | AV4: 25966.256 | AW4: 26289.452 | AX4: 26616.714 | AY4: 26947.966 | AZ4: 27283.153 | BA4: 27625.09 | BB4: 27971.015 | BC4: 28320.934 | BD4: 28674.86 | BE4: 29032.821
A5: x_cagr_0 | B5: 15858.384 | C5: 16109.495 | D5: 16385.528 | E5: 16669.199 | F5: 16958.621 | G5: 17251.939 | H5: 17531.066 | I5: 17811.277 | J5: 18092.068 | K5: 18373.238 | L5: 18683.757 | M5: 18965.854 | N5: 19248.596 | O5: 19532.42 | P5: 19817.823 | Q5: 20105.343 | R5: 20395.541 | S5: 20688.984 | T5: 20986.236 | U5: 21287.84 | V5: 21572.902 | W5: 21884.764 | X5: 22202.564 | Y5: 22526.648 | Z5: 22857.308 | AA5: 23133.018 | AB5: 23448.298 | AC5: 23770.891 | AD5: 24101.029 | AE5: 24438.856 | AF5: 24784.442 | AG5: 25137.798 | AH5: 25498.878 | AI5: 25867.59 | AJ5: 26243.812 | AK5: 26627.394 | AL5: 27003.139 | AM5: 27385.739 | AN5: 27775.147 | AO5: 28171.305 | AP5: 28574.14 | AQ5: 28983.576 | AR5: 29399.532 | AS5: 29821.926 | AT5: 30250.681 | AU5: 30685.719 | AV5: 31128.345 | AW5: 31577.136 | AX5: 32032.026 | AY5: 32492.964 | AZ5: 32959.913 | BA5: 33432.854 | BB5: 33911.781 | BC5: 34396.706 | BD5: 34887.656 | BE5: 35384.668
A6: x_cfor_2 | B6: 39.330702 | C6: 39.793151 | D6: 40.341458 | E6: 40.932481 | F6: 41.556552 | G6: 42.20284 | H6: 42.818466 | I6: 43.439115 | J6: 44.060067 | K6: 44.678168 | L6: 45.361933 | M6: 45.957977 | N6: 46.546996 | O6: 47.1291 | P6: 47.704904 | Q6: 48.275429 | R6: 48.830743 | S6: 49.383704 | T6: 49.936054 | U6: 50.489595 | V6: 50.995341 | W6: 51.557044 | X6: 52.12534 | Y6: 52.701661 | Z6: 53.287285 | AA6: 53.739383 | AB6: 54.284244 | AC6: 54.841422 | AD6: 55.411799 | AE6: 55.996063 | AF6: 56.594716 | AG6: 57.210577 | AH6: 57.841285 | AI6: 58.486752 | AJ6: 59.146736 | AK6: 59.820883 | AL6: 60.497133 | AM6: 61.187025 | AN6: 61.890206 | AO6: 62.606233 | AP6: 63.334662 | AQ6: 64.07865 | AR6: 64.834422 | AS6: 65.60164 | AT6: 66.379993 | AU6: 67.169197 | AV6: 67.984146 | AW6: 68.810152 | AX6: 69.646988 | AY6: 70.494411 | AZ6: 71.352216 | BA6: 72.22786 | BB6: 73.114098 | BC6: 74.010875 | BD6: 74.918151 | BE6: 75.835928
A7: x_cfor_0 | B7: 41.916677 | C7: 42.587807 | D7: 43.331387 | E7: 44.099879 | F7: 44.885596 | G7: 45.68117 | H7: 46.436894 | I7: 47.192494 | J7: 47.946856 | K7: 48.700229 | L7: 49.530678 | M7: 50.285799 | N7: 51.043044 | O7: 51.803634 | P7: 52.568713 | Q7: 53.339392 | R7: 54.116801 | S7: 54.902119 | T7: 55.696568 | U7: 56.50139 | V7: 57.26078 | W7: 58.089745 | X7: 58.932983 | Y7: 59.79153 | Z7: 60.666316 | AA7: 61.393581 | AB7: 62.224105 | AC7: 63.072315 | AD7: 63.939005 | AE7: 64.824842 | AF7: 65.730335 | AG7: 66.655812 | AH7: 67.601408 | AI7: 68.567077 | AJ7: 69.552628 | AK7: 70.557761 | AL7: 71.542131 | AM7: 72.544584 | AN7: 73.564931 | AO7: 74.602998 | AP7: 75.658637 | AQ7: 76.731722 | AR7: 77.822141 | AS7: 78.929775 | AT7: 80.054496 | AU7: 81.196177 | AV7: 82.358377 | AW7: 83.537433 | AX7: 84.733219 | AY7: 85.945562 | AZ7: 87.174265 | BA7: 88.41916 | BB7: 89.680149 | BC7: 90.957219 | BD7: 92.250436 | BE7: 93.559921
A8: x_cfoo_2 | B8: 42654.999 | C8: 43192.528 | D8: 43819.051 | E8: 44483.698 | F8: 45176.637 | G8: 45888.431 | H8: 46563.885 | I8: 47243.259 | J8: 47922.134 | K8: 48597.355 | L8: 49343.334 | M8: 49993.475 | N8: 50635.777 | O8: 51270.599 | P8: 51898.849 | Q8: 52521.854 | R8: 53129.158 | S8: 53734.967 | T8: 54341.342 | U8: 54950.382 | V8: 55509.019 | W8: 56130.269 | X8: 56760.456 | Y8: 57401.147 | Z8: 58053.711 | AA8: 58562.804 | AB8: 59174.985 | AC8: 59802.639 | AD8: 60446.657 | AE8: 61107.625 | AF8: 61785.878 | AG8: 62484.238 | AH8: 63199.942 | AI8: 63932.765 | AJ8: 64682.36 | AK8: 65448.286 | AL8: 66216.857 | AM8: 67000.574 | AN8: 67799.073 | AO8: 68611.917 | AP8: 69438.646 | AQ8: 70282.638 | AR8: 71139.718 | AS8: 72009.51 | AT8: 72891.676 | AU8: 73785.926 | AV8: 74708.307 | AW8: 75642.61 | AX8: 76588.615 | AY8: 77546.12 | AZ8: 78514.981 | BA8: 79503.253 | BB8: 80502.978 | BC8: 81514.173 | BD8: 82536.885 | BE8: 83571.208
A9: x_cfoo_0 | B9: 45427.619 | C9: 46146.189 | D9: 46935.236 | E9: 47745.879 | F9: 48573.446 | G9: 49413.162 | H9: 50213.395 | I9: 51017.835 | J9: 51824.825 | K9: 52633.517 | L9: 53526.737 | M9: 54338.711 | N9: 55152.48 | O9: 55969.119 | P9: 56789.947 | Q9: 57616.445 | R9: 58450.191 | S9: 59292.816 | T9: 60145.949 | U9: 61011.179 | V9: 61828.582 | W9: 62722.446 | X9: 63633.06 | Y9: 64561.483 | Z9: 65508.617 | AA9: 66297.952 | AB9: 67200.385 | AC9: 68123.52 | AD9: 69068.089 | AE9: 70034.576 | AF9: 71023.252 | AG9: 72034.198 | AH9: 73067.336 | AI9: 74122.45 | AJ9: 75199.216 | AK9: 76297.236 | AL9: 77372.913 | AM9: 78468.312 | AN9: 79583.275 | AO9: 80717.618 | AP9: 81871.133 | AQ9: 83043.596 | AR9: 84234.775 | AS9: 85444.441 | AT9: 86672.368 | AU9: 87918.339 | AV9: 89186.1 | AW9: 90471.576 | AX9: 91774.579 | AY9: 93094.956 | AZ9: 94432.597 | BA9: 95787.437 | BB9: 97159.456 | BC9: 98548.677 | BD9: 99955.164 | BE9: 101379.02
A10: x_cveh_2 | B10: 104832.82 | C10: 106266.98 | D10: 107905.81 | E10: 109590.41 | F10: 111283.03 | G10: 112962.46 | H10: 114505.38 | I10: 116026.49 | J10: 117529.57 | K10: 119019.01 | L10: 120683.84 | M10: 122124.48 | N10: 123562.43 | O10: 125002.26 | P10: 126447.94 | Q10: 127903 | R10: 129341.59 | S10: 130797.04 | T10: 132272.45 | U10: 133770.58 | V10: 135161.2 | W10: 136716.02 | X10: 138300.84 | Y10: 139916.43 | Z10: 141563.62 | AA10: 142866.05 | AB10: 144423.2 | AC10: 146018.61 | AD10: 147651.7 | AE10: 149321.61 | AF10: 151027.44 | AG10: 152774.86 | AH10: 154556.34 | AI10: 156371.01 | AJ10: 158217.98 | AK10: 160096.44 | AL10: 161973.89 | AM10: 163881.75 | AN10: 165819.71 | AO10: 167787.18 | AP10: 169783.53 | AQ10: 171817.47 | AR10: 173879.34 | AS10: 175968.82 | AT10: 178085.7 | AU10: 180229.88 | AV10: 182440.7 | AW10: 184678.83 | AX10: 186944.1 | AY10: 189236.48 | AZ10: 191556.12 | BA10: 193923.03 | BB10: 196318.16 | BC10: 198741.9 | BD10: 201194.7 | BE10: 203677.07
A11: x_cveh_0 | B11: 111565.34 | C11: 113320.18 | D11: 115227.35 | E11: 117163.59 | F11: 119120.43 | G11: 121092.62 | H11: 122962.62 | I11: 124845.38 | J11: 126742.64 | K11: 128656.17 | L11: 130788.16 | M11: 132735.63 | N11: 134703.09 | O11: 136693.68 | P11: 138710.17 | Q11: 140755.13 | R11: 142830.93 | S11: 144939.84 | T11: 147084.03 | U11: 149265.51 | V11: 151337.53 | W11: 153601.62 | X11: 155909.02 | Y11: 158260.13 | Z11: 160655.49 | AA11: 162665.98 | AB11: 164955.11 | AC11: 167294.1 | AD11: 169682.44 | AE11: 172119.3 | AF11: 174603.81 | AG11: 177135.11 | AH11: 179712.33 | AI11: 182334.63 | AJ11: 185001.2 | AK11: 187711.3 | AL11: 190359.37 | AM11: 193050.2 | AN11: 195784.12 | AO11: 198561.02 | AP11: 201380.52 | AQ11: 204242.2 | AR11: 207145.61 | AS11: 210090.4 | AT11: 213076.24 | AU11: 216102.9 | AV11: 219179.79 | AW11: 222297.22 | AX11: 225455.09 | AY11: 228653.47 | AZ11: 231892.53 | BA11: 235172.57 | BB11: 238493.94 | BC11: 241857.1 | BD11: 245262.52 | BE11: 248710.75
A12: x_cgla_2 | B12: 4911.4179 | C12: 4973.7951 | D12: 5046.3349 | E12: 5123.0717 | F12: 5202.8837 | G12: 5284.7535 | H12: 5362.4025 | I12: 5440.5273 | J12: 5518.6532 | K12: 5596.4281 | L12: 5682.4212 | M12: 5757.4369 | N12: 5831.5984 | O12: 5904.9381 | P12: 5977.5526 | Q12: 6049.5889 | R12: 6119.8385 | S12: 6189.9345 | T12: 6260.1094 | U12: 6330.5991 | V12: 6395.2799 | W12: 6467.1666 | X12: 6540.07 | Y12: 6614.1649 | Z12: 6689.6052 | AA12: 6748.4799 | AB12: 6819.2014 | AC12: 6891.6751 | AD12: 6966.0074 | AE12: 7042.2713 | AF12: 7120.5114 | AG12: 7201.0586 | AH12: 7283.5984 | AI12: 7368.1083 | AJ12: 7454.5509 | AK12: 7542.8781 | AL12: 7631.5123 | AM12: 7721.8931 | AN12: 7813.9793 | AO12: 7907.7241 | AP12: 8003.08 | AQ12: 8100.4421 | AR12: 8199.3342 | AS12: 8299.7163 | AT12: 8401.5517 | AU12: 8504.8078 | AV12: 8611.3342 | AW12: 8719.2594 | AX12: 8828.5542 | AY12: 8939.1929 | AZ12: 9051.1571 | BA12: 9165.3746 | BB12: 9280.926 | BC12: 9397.811 | BD12: 9516.0334 | BE12: 9635.6031
... A55: x_cote_0 | B55: 4467.7306 | C55: 4536.5339 | D55: 4611.047 | E55: 4686.784 | F55: 4763.7649 | G55: 4842.0103 | H55: 4916.8504 | I55: 4992.8473 | J55: 5070.0189 | K55: 5148.3832 | L55: 5236.1362 | M55: 5317.0682 | N55: 5399.251 | O55: 5482.7041 | P55: 5567.447 | Q55: 5653.4998 | R55: 5740.8827 | S55: 5829.6162 | T55: 5919.7212 | U55: 6011.2188 | V55: 6098.032 | W55: 6192.2857 | X55: 6287.9963 | Y55: 6385.1862 | Z55: 6483.8783 | AA55: 6566.4246 | AB55: 6659.5192 | AC55: 6753.9337 | AD55: 6849.6867 | AE55: 6946.7972 | AF55: 7045.2846 | AG55: 7145.1682 | AH55: 7246.4679 | AI55: 7349.2037 | AJ55: 7453.3961 | AK55: 7559.0656 | AL55: 7661.9329 | AM55: 7766.2001 | AN55: 7871.8862 | AO55: 7979.0105 | AP55: 8087.5926 | AQ55: 8197.6523 | AR55: 8309.2098 | AS55: 8422.2854 | AT55: 8536.8998 | AU55: 8653.0739 | AV55: 8771.2195 | AW55: 8890.9782 | AX55: 9012.3721 | AY55: 9135.4234 | AZ55: 9260.1548 | BA55: 9386.5892 | BB55: 9514.75 | BC55: 9644.6605 | BD55: 9776.3449 | BE55: 9909.8271

Sheet Import
A1: _date_ | B1: 42005 | C1: 42370 | D1: 42736 | E1: 43101 | F1: 43466 | G1: 43831 | H1: 44197 | I1: 44562 | J1: 44927 | K1: 45292 | L1: 45658 | M1: 46023 | N1: 46388 | O1: 46753 | P1: 47119 | Q1: 47484 | R1: 47849 | S1: 48214 | T1: 48580 | U1: 48945 | V1: 49310 | W1: 49675 | X1: 50041 | Y1: 50406 | Z1: 50771 | AA1: 51136 | AB1: 51502 | AC1: 51867 | AD1: 52232 | AE1: 52597 | AF1: 52963 | AG1: 53328 | AH1: 53693 | AI1: 54058 | AJ1: 54424 | AK1: 54789 | AL1: 55154 | AM1: 55519 | AN1: 55885 | AO1: 56250 | AP1: 56615 | AQ1: 56980 | AR1: 57346 | AS1: 57711 | AT1: 58076 | AU1: 58441 | AV1: 58807 | AW1: 59172 | AX1: 59537 | AY1: 59902 | AZ1: 60268 | BA1: 60633 | BB1: 60998 | BC1: 61363 | BD1: 61729 | BE1: 62094
A2: m_2 | B2: 642620.03 | C2: 645092.66 | D2: 649948.18 | E2: 655825.33 | F2: 662390.66 | G2: 669563.59 | H2: 676901.25 | I2: 684633.64 | J2: 692791.87 | K2: 701366.27 | L2: 711040.7 | M2: 720604.6 | N2: 730376.64 | O2: 740379.68 | P2: 750605.87 | Q2: 761043.36 | R2: 771623.54 | S2: 782378.31 | T2: 793306.27 | U2: 804402.62 | V2: 815142.32 | W2: 826340.26 | X2: 837766.24 | Y2: 849383.41 | Z2: 861177.5 | AA2: 871648.54 | AB2: 882455.8 | AC2: 893331.33 | AD2: 904272.96 | AE2: 915299.74 | AF2: 926430.53 | AG2: 937692.94 | AH2: 949088.26 | AI2: 960622.02 | AJ2: 972298.44 | AK2: 984120.79 | AL2: 995850.25 | AM2: 1007609 | AN2: 1019435 | AO2: 1031352.2 | AP2: 1043380.1 | AQ2: 1055552.9 | AR2: 1067870.7 | AS2: 1080340.9 | AT2: 1092969.6 | AU2: 1105761.1 | AV2: 1118811.8 | AW2: 1132063.1 | AX2: 1145504.8 | AY2: 1159132.4 | AZ2: 1172944.2 | BA2: 1186977.9 | BB2: 1201207.1 | BC2: 1215627.9 | BD2: 1230239.3 | BE2: 1245042
A3: m_0 | B3: 656032.07 | C3: 663598.77 | D3: 672404.68 | E3: 681762.79 | F3: 691480.48 | G3: 701542.06 | H3: 711551.21 | I3: 721782.39 | J3: 732305.06 | K3: 743141.56 | L3: 755043.56 | M3: 766811.84 | N3: 778756.2 | O3: 790903.63 | P3: 803250.77 | Q3: 815789.95 | R3: 828514.53 | S3: 841419.58 | T3: 854501.58 | U3: 867757.99 | V3: 880626.44 | W3: 893988.8 | X3: 907600.87 | Y3: 921428.03 | Z3: 935459.16 | AA3: 948066.4 | AB3: 961029.54 | AC3: 974073.82 | AD3: 987201.4 | AE3: 1000435.2 | AF3: 1013796.9 | AG3: 1027302.9 | AH3: 1040964.6 | AI3: 1054789.7 | AJ3: 1068783.3 | AK3: 1082948.9 | AL3: 1096897.5 | AM3: 1110853.4 | AN3: 1124873 | AO3: 1138989 | AP3: 1153226.3 | AQ3: 1167605.3 | AR3: 1182142.1 | AS3: 1196849.7 | AT3: 1211737.7 | AU3: 1226813.7 | AV3: 1242119 | AW3: 1257638.7 | AX3: 1273372.2 | AY3: 1289321.3 | AZ3: 1305488.4 | BA3: 1321875.9 | BB3: 1338486.6 | BC3: 1355324.1 | BD3: 1372392.2 | BE3: 1389695.1
A4: m_cagr_2 | B4: 12840.617 | C4: 12834.562 | D4: 12857.745 | E4: 12913.147 | F4: 13000.141 | G4: 13116.319 | H4: 13252.19 | I4: 13406.687 | J4: 13577.877 | K4: 13763.767 | L4: 13973.713 | M4: 14191.17 | N4: 14416.312 | O4: 14648.247 | P4: 14886.133 | Q4: 15129.289 | R4: 15376.645 | S4: 15627.923 | T4: 15882.773 | U4: 16140.873 | V4: 16393.579 | W4: 16651.248 | X4: 16912.642 | Y4: 17177.367 | Z4: 17445.149 | AA4: 17691.601 | AB4: 17936.001 | AC4: 18178.269 | AD4: 18419.412 | AE4: 18660.476 | AF4: 18902.341 | AG4: 19145.811 | AH4: 19391.348 | AI4: 19639.302 | AJ4: 19889.93 | AK4: 20143.431 | AL4: 20395.248 | AM4: 20646.684 | AN4: 20898.61 | AO4: 21151.789 | AP4: 21406.926 | AQ4: 21664.815 | AR4: 21925.908 | AS4: 22190.576 | AT4: 22459.088 | AU4: 22731.632 | AV4: 23009.437 | AW4: 23292.233 | AX4: 23579.906 | AY4: 23872.357 | AZ4: 24169.51 | BA4: 24471.681 | BB4: 24778.698 | BC4: 25090.485 | BD4: 25406.992 | BE4: 25728.193
A5: m_cagr_0 | B5: 12985.152 | C5: 13084.944 | D5: 13202.325 | E5: 13342.891 | F5: 13506.662 | G5: 13691.531 | H5: 13888.342 | I5: 14096.709 | J5: 14315.612 | K5: 14544.045 | L5: 14792.842 | M5: 15046.08 | N5: 15304.382 | O5: 15567.221 | P5: 15834.032 | Q5: 16104.377 | R5: 16377.944 | S5: 16654.511 | T5: 16933.915 | U5: 17216.03 | V5: 17491.911 | W5: 17772.734 | X5: 18057.4 | Y5: 18345.708 | Z5: 18637.557 | AA5: 18907.145 | AB5: 19174.819 | AC5: 19440.605 | AD5: 19705.683 | AE5: 19971.251 | AF5: 20238.301 | AG5: 20507.583 | AH5: 20779.642 | AI5: 21054.86 | AJ5: 21333.513 | AK5: 21615.804 | AL5: 21895.676 | AM5: 22174.915 | AN5: 22454.57 | AO5: 22735.563 | AP5: 23018.741 | AQ5: 23304.842 | AR5: 23594.479 | AS5: 23888.136 | AT5: 24186.182 | AU5: 24488.895 | AV5: 24797.06 | AW5: 25110.721 | AX5: 25429.944 | AY5: 25754.705 | AZ5: 26084.969 | BA5: 26420.737 | BB5: 26762.037 | BC5: 27108.914 | BD5: 27461.425 | BE5: 27819.634
A6: m_cfor_2 | B6: 117.112 | C6: 115.20484 | D6: 113.69719 | E6: 112.54321 | F6: 111.71799 | G6: 111.18288 | H6: 110.83224 | I6: 110.65783 | J6: 110.64068 | K6: 110.76468 | L6: 111.10848 | M6: 111.50326 | N6: 111.982 | O6: 112.54441 | P6: 113.18411 | Q6: 113.89346 | R6: 114.65481 | S6: 115.46906 | T6: 116.33243 | U6: 117.24065 | V6: 118.12391 | W6: 119.0829 | X6: 120.08778 | Y6: 121.12948 | Z6: 122.20347 | AA6: 123.11997 | AB6: 124.08853 | AC6: 125.07897 | AD6: 126.08626 | AE6: 127.10929 | AF6: 128.14809 | AG6: 129.20526 | AH6: 130.27957 | AI6: 131.37097 | AJ6: 132.47973 | AK6: 133.60623 | AL6: 134.72695 | AM6: 135.85257 | AN6: 136.987 | AO6: 138.1326 | AP6: 139.2912 | AQ6: 140.46749 | AR6: 141.66046 | AS6: 142.87055 | AT6: 144.0984 | AU6: 145.34463 | AV6: 146.62413 | AW6: 147.92736 | AX6: 149.25201 | AY6: 150.59742 | AZ6: 151.96358 | BA6: 153.35717 | BB6: 154.77367 | BC6: 156.2122 | BD6: 157.67268 | BE6: 159.15533
A7: m_cfor_0 | B7: 118.88216 | C7: 117.4818 | D7: 116.34471 | E7: 115.54394 | F7: 115.06457 | G7: 114.8996 | H7: 114.96629 | I7: 115.25832 | J7: 115.74402 | K7: 116.38956 | L7: 117.26377 | M7: 118.18774 | N7: 119.18297 | O7: 120.24501 | P7: 121.36663 | Q7: 122.54101 | R7: 123.76242 | S7: 125.02614 | T7: 126.32828 | U7: 127.66561 | V7: 128.96375 | W7: 130.33394 | X7: 131.74482 | Y7: 133.18784 | Z7: 134.65911 | AA7: 135.95069 | AB7: 137.28966 | AC7: 138.64609 | AD7: 140.01598 | AE7: 141.39885 | AF7: 142.79509 | AG7: 144.20523 | AH7: 145.62976 | AI7: 147.06919 | AJ7: 148.52399 | AK7: 149.99466 | AL7: 151.43273 | AM7: 152.86712 | AN7: 154.30661 | AO7: 155.75546 | AP7: 157.21635 | AQ7: 158.6912 | AR7: 160.18155 | AS7: 161.68862 | AT7: 163.21325 | AU7: 164.75566 | AV7: 166.31788 | AW7: 167.89698 | AX7: 169.49363 | AY7: 171.11009 | AZ7: 172.74874 | BA7: 174.41107 | BB7: 176.09774 | BC7: 177.80904 | BD7: 179.54517 | BE7: 181.30641
A8: m_cfoo_2 | B8: 38255.786 | C8: 38297.152 | D8: 38418.225 | E8: 38622.572 | F8: 38908.469 | G8: 39270.271 | H8: 39680.18 | I8: 40139.048 | J8: 40642.81 | K8: 41186.93 | L8: 41802.719 | M8: 42435.696 | N8: 43091.206 | O8: 43767.364 | P8: 44462.103 | Q8: 45173.673 | R8: 45898.746 | S8: 46636.902 | T8: 47387.082 | U8: 48148.257 | V8: 48892.974 | W8: 49656.186 | X8: 50431.347 | Y8: 51216.998 | Z8: 52012.172 | AA8: 52739.523 | AB8: 53466.428 | AC8: 54188.128 | AD8: 54907.03 | AE8: 55625.848 | AF8: 56346.902 | AG8: 57072.427 | AH8: 57803.571 | AI8: 58541.288 | AJ8: 59286.301 | AK8: 60039.193 | AL8: 60785.855 | AM8: 61531.321 | AN8: 62278.206 | AO8: 63028.711 | AP8: 63784.854 | AQ8: 64549.017 | AR8: 65322.393 | AS8: 66106.069 | AT8: 66900.852 | AU8: 67707.311 | AV8: 68529.529 | AW8: 69366.221 | AX8: 70217.109 | AY8: 71081.972 | AZ8: 71960.645 | BA8: 72854.301 | BB8: 73762.257 | BC8: 74684.333 | BD8: 75620.419 | BE8: 76570.468
A9: m_cfoo_0 | B9: 38751.185 | C9: 39097.99 | D9: 39493.323 | E9: 39948.706 | F9: 40464.457 | G9: 41035.619 | H9: 41634.966 | I9: 42264.901 | J9: 42923.545 | K9: 43608.761 | L9: 44356.028 | M9: 45112.113 | N9: 45883.256 | O9: 46668.417 | P9: 47466.173 | Q9: 48275.353 | R9: 49095.072 | S9: 49924.654 | T9: 50763.559 | U9: 51611.337 | V9: 52439.357 | W9: 53285.563 | X9: 54143.609 | Y9: 55012.65 | Z9: 55892.274 | AA9: 56700.075 | AB9: 57507.815 | AC9: 58310.866 | AD9: 59112.192 | AE9: 59914.998 | AF9: 60721.968 | AG9: 61535.154 | AH9: 62356.056 | AI9: 63185.756 | AJ9: 64025.047 | AK9: 64874.547 | AL9: 65714.903 | AM9: 66553.485 | AN9: 67393.418 | AO9: 68237.351 | AP9: 69087.691 | AQ9: 69946.546 | AR9: 70815.672 | AS9: 71696.467 | AT9: 72590.011 | AU9: 73497.13 | AV9: 74420.292 | AW9: 75359.467 | AX9: 76314.878 | AY9: 77286.508 | AZ9: 78274.322 | BA9: 79278.373 | BB9: 80298.788 | BC9: 81335.742 | BD9: 82389.437 | BE9: 83460.086
A10: m_cveh_2 | B10: 80281.342 | C10: 81579.014 | D10: 83442.943 | E10: 85220.165 | F10: 86765.23 | G10: 88108.503 | H10: 89252.34 | I10: 90304.48 | J10: 91321.233 | K10: 92332.476 | L10: 93469.145 | M10: 94533.698 | N10: 95584.626 | O10: 96634.362 | P10: 97686.829 | Q10: 98743.437 | R10: 99795.353 | S10: 100849.44 | T10: 101907.41 | U10: 102970.06 | V10: 103953.41 | W10: 104998.18 | X10: 106067 | Y10: 107151.34 | Z10: 108248.08 | AA10: 109116.27 | AB10: 110043.79 | AC10: 110993.69 | AD10: 111962.86 | AE10: 112951.61 | AF10: 113960.23 | AG10: 114990.56 | AH10: 116040.48 | AI10: 117108.83 | AJ10: 118194.7 | AK10: 119297.37 | AL10: 120378.99 | AM10: 121462.68 | AN10: 122556.44 | AO10: 123664.15 | AP10: 124787.95 | AQ10: 125931.87 | AR10: 127094.27 | AS10: 128274.48 | AT10: 129471.83 | AU10: 130685.64 | AV10: 131929.94 | AW10: 133194.17 | AX10: 134475.22 | AY10: 135771.57 | AZ10: 137082.52 | BA10: 138413.88 | BB10: 139761.28 | BC10: 141123.66 | BD10: 142500.6 | BE10: 143892.04
A11: m_cveh_0 | B11: 82103.234 | C11: 84149.12 | D11: 86629.265 | E11: 88919.606 | F11: 90873.939 | G11: 92537.095 | H11: 93933.871 | I11: 95194.732 | J11: 96394.664 | K11: 97577.066 | L11: 98887.549 | M11: 100133.5 | N11: 101372.05 | O11: 102615.54 | P11: 103867.72 | Q11: 105129.87 | R11: 106402.51 | S11: 107685.94 | T11: 108980.43 | U11: 110286.29 | V11: 111513.89 | W11: 112812.65 | X11: 114142.72 | Y11: 115495.17 | Z11: 116866.61 | AA11: 117998.18 | AB11: 119193.77 | AC11: 120415.73 | AD11: 121661.41 | AE11: 122931.33 | AF11: 124225.71 | AG11: 125544.13 | AH11: 126885.75 | AI11: 128249.58 | AJ11: 129634.7 | AK11: 131040.36 | AL11: 132405.41 | AM11: 133769.12 | AN11: 135143.47 | AO11: 136534.18 | AP11: 137944.31 | AQ11: 139375.47 | AR11: 140828.3 | AS11: 142302.85 | AT11: 143798.86 | AU11: 145315.89 | AV11: 146858.86 | AW11: 148423.91 | AX11: 150009.7 | AY11: 151615.53 | AZ11: 153241.01 | BA11: 154885.94 | BB11: 156550.34 | BC11: 158234.29 | BD11: 159937.98 | BE11: 161661.61
A12: m_cgla_2 | B12: 6877.6774 | C12: 6910.4362 | D12: 6961.8034 | E12: 7024.4208 | F12: 7095.959 | G12: 7175.2214 | H12: 7257.8811 | I12: 7344.9781 | J12: 7436.6546 | K12: 7532.8694 | L12: 7639.5515 | M12: 7747.5243 | N12: 7858.5468 | O12: 7972.853 | P12: 8090.4391 | Q12: 8211.2518 | R12: 8334.7713 | S12: 8461.2087 | T12: 8590.556 | U12: 8722.7672 | V12: 8853.3342 | W12: 8988.4625 | X12: 9126.8856 | Y12: 9268.2871 | Z12: 9412.5055 | AA12: 9546.6014 | AB12: 9682.6066 | AC12: 9819.3176 | AD12: 9956.7647 | AE12: 10095.12 | AF12: 10234.549 | AG12: 10375.286 | AH12: 10517.36 | AI12: 10660.814 | AJ12: 10805.672 | AK12: 10951.948 | AL12: 11097.481 | AM12: 11242.953 | AN12: 11388.667 | AO12: 11534.833 | AP12: 11681.629 | AQ12: 11829.361 | AR12: 11978.082 | AS12: 12127.885 | AT12: 12278.852 | AU12: 12431.045 | AV12: 12585.292 | AW12: 12741.246 | AX12: 12898.836 | AY12: 13058.038 | AZ12: 13218.845 | BA12: 13381.581 | BB12: 13546.092 | BC12: 13712.365 | BD12: 13880.414 | BE12: 14050.267
... A55: m_cote_0 | B55: 2286.3479 | C55: 2314.2348 | D55: 2344.0602 | E55: 2375.7199 | F55: 2409.2906 | G55: 2444.5815 | H55: 2479.5575 | I55: 2515.3804 | J55: 2552.0225 | K55: 2589.3822 | L55: 2630.501 | M55: 2669.7107 | N55: 2709.1398 | O55: 2748.9656 | P55: 2789.2215 | Q55: 2829.9247 | R55: 2871.0971 | S55: 2912.7666 | T55: 2954.9654 | U55: 2997.7277 | V55: 3038.766 | W55: 3082.2764 | X55: 3126.6792 | Y55: 3171.8577 | Z55: 3217.8086 | AA55: 3257.8353 | AB55: 3300.793 | AC55: 3344.5152 | AD55: 3388.8935 | AE55: 3433.9555 | AF55: 3479.7428 | AG55: 3526.2895 | AH55: 3573.6187 | AI55: 3621.7435 | AJ55: 3670.6689 | AK55: 3720.3946 | AL55: 3769.2883 | AM55: 3818.6164 | AN55: 3868.5277 | AO55: 3919.0715 | AP55: 3970.2781 | AQ55: 4022.1717 | AR55: 4074.7726 | AS55: 4128.0971 | AT55: 4182.1579 | AU55: 4236.9648 | AV55: 4292.6731 | AW55: 4349.1509 | AX55: 4406.3802 | AY55: 4464.3686 | AZ55: 4523.1277 | BA55: 4582.6655 | BB55: 4642.9876 | BC55: 4704.0995 | BD55: 4766.0076 | BE55: 4828.7205

Sheet Carbontax
A1: _date_ | B1: 42005 | C1: 42370 | D1: 42736 | E1: 43101 | F1: 43466 | G1: 43831 | H1: 44197 | I1: 44562 | J1: 44927 | K1: 45292 | L1: 45658 | M1: 46023 | N1: 46388 | O1: 46753 | P1: 47119 | Q1: 47484 | R1: 47849 | S1: 48214 | T1: 48580 | U1: 48945 | V1: 49310 | W1: 49675 | X1: 50041 | Y1: 50406 | Z1: 50771 | AA1: 51136 | AB1: 51502 | AC1: 51867 | AD1: 52232 | AE1: 52597 | AF1: 52963 | AG1: 53328 | AH1: 53693 | AI1: 54058 | AJ1: 54424 | AK1: 54789 | AL1: 55154 | AM1: 55519 | AN1: 55885 | AO1: 56250 | AP1: 56615 | AQ1: 56980 | AR1: 57346 | AS1: 57711 | AT1: 58076 | AU1: 58441 | AV1: 58807 | AW1: 59172 | AX1: 59537 | AY1: 59902 | AZ1: 60268 | BA1: 60633 | BB1: 60998 | BC1: 61363 | BD1: 61729 | BE1: 62094
A2: t2val_ch_0 | B2: 0 | C2: 0 | D2: 0 | E2: 0 | F2: 0 | G2: 0 | H2: 0 | I2: 0 | J2: 0 | K2: 0 | L2: 0 | M2: 0 | N2: 0 | O2: 0 | P2: 0 | Q2: 0 | R2: 0 | S2: 0 | T2: 0 | U2: 0 | V2: 0 | W2: 0 | X2: 0 | Y2: 0 | Z2: 0 | AA2: 0 | AB2: 0 | AC2: 0 | AD2: 0 | AE2: 0 | AF2: 0 | AG2: 0 | AH2: 0 | AI2: 0 | AJ2: 0 | AK2: 0 | AL2: 0 | AM2: 0 | AN2: 0 | AO2: 0 | AP2: 0 | AQ2: 0 | AR2: 0 | AS2: 0 | AT2: 0 | AU2: 0 | AV2: 0 | AW2: 0 | AX2: 0 | AY2: 0 | AZ2: 0 | BA2: 0 | BB2: 0 | BC2: 0 | BD2: 0 | BE2: 0
A3: t2val_ch_2 | B3: 0 | C3: 0 | D3: 0 | E3: 0 | F3: 0 | G3: 0 | H3: 0 | I3: 0 | J3: 0 | K3: 0 | L3: 0 | M3: 0 | N3: 0 | O3: 0 | P3: 0 | Q3: 0 | R3: 0 | S3: 0 | T3: 0 | U3: 0 | V3: 0 | W3: 0 | X3: 0 | Y3: 0 | Z3: 0 | AA3: 0 | AB3: 0 | AC3: 0 | AD3: 0 | AE3: 0 | AF3: 0 | AG3: 0 | AH3: 0 | AI3: 0 | AJ3: 0 | AK3: 0 | AL3: 0 | AM3: 0 | AN3: 0 | AO3: 0 | AP3: 0 | AQ3: 0 | AR3: 0 | AS3: 0 | AT3: 0 | AU3: 0 | AV3: 0 | AW3: 0 | AX3: 0 | AY3: 0 | AZ3: 0 | BA3: 0 | BB3: 0 | BC3: 0 | BD3: 0 | BE3: 0
A4: t2val_sec_0 | B4: 0 | C4: 0 | D4: 0 | E4: 0 | F4: 0 | G4: 0 | H4: 0 | I4: 0 | J4: 0 | K4: 0 | L4: 0 | M4: 0 | N4: 0 | O4: 0 | P4: 0 | Q4: 0 | R4: 0 | S4: 0 | T4: 0 | U4: 0 | V4: 0 | W4: 0 | X4: 0 | Y4: 0 | Z4: 0 | AA4: 0 | AB4: 0 | AC4: 0 | AD4: 0 | AE4: 0 | AF4: 0 | AG4: 0 | AH4: 0 | AI4: 0 | AJ4: 0 | AK4: 0 | AL4: 0 | AM4: 0 | AN4: 0 | AO4: 0 | AP4: 0 | AQ4: 0 | AR4: 0 | AS4: 0 | AT4: 0 | AU4: 0 | AV4: 0 | AW4: 0 | AX4: 0 | AY4: 0 | AZ4: 0 | BA4: 0 | BB4: 0 | BC4: 0 | BD4: 0 | BE4: 0
A5: t2val_sec_2 | B5: 0 | C5: 0 | D5: 0 | E5: 0 | F5: 0 | G5: 0 | H5: 0 | I5: 0 | J5: 0 | K5: 0 | L5: 0 | M5: 0 | N5: 0 | O5: 0 | P5: 0 | Q5: 0 | R5: 0 | S5: 0 | T5: 0 | U5: 0 | V5: 0 | W5: 0 | X5: 0 | Y5: 0 | Z5: 0 | AA5: 0 | AB5: 0 | AC5: 0 | AD5: 0 | AE5: 0 | AF5: 0 | AG5: 0 | AH5: 0 | AI5: 0 | AJ5: 0 | AK5: 0 | AL5: 0 | AM5: 0 | AN5: 0 | AO5: 0 | AP5: 0 | AQ5: 0 | AR5: 0 | AS5: 0 | AT5: 0 | AU5: 0 | AV5: 0 | AW5: 0 | AX5: 0 | AY5: 0 | AZ5: 0 | BA5: 0 | BB5: 0 | BC5: 0 | BD5: 0 | BE5: 0
A6: t2val_ci_0 | B6: 0 | C6: 0 | D6: 0 | E6: 0 | F6: 0 | G6: 0 | H6: 0 | I6: 0 | J6: 0 | K6: 0 | L6: 0 | M6: 0 | N6: 0 | O6: 0 | P6: 0 | Q6: 0 | R6: 0 | S6: 0 | T6: 0 | U6: 0 | V6: 0 | W6: 0 | X6: 0 | Y6: 0 | Z6: 0 | AA6: 0 | AB6: 0 | AC6: 0 | AD6: 0 | AE6: 0 | AF6: 0 | AG6: 0 | AH6: 0 | AI6: 0 | AJ6: 0 | AK6: 0 | AL6: 0 | AM6: 0 | AN6: 0 | AO6: 0 | AP6: 0 | AQ6: 0 | AR6: 0 | AS6: 0 | AT6: 0 | AU6: 0 | AV6: 0 | AW6: 0 | AX6: 0 | AY6: 0 | AZ6: 0 | BA6: 0 | BB6: 0 | BC6: 0 | BD6: 0 | BE6: 0
A7: t2val_ci_2 | B7: 0 | C7: 0 | D7: 0 | E7: 0 | F7: 0 | G7: 0 | H7: 0 | I7: 0 | J7: 0 | K7: 0 | L7: 0 | M7: 0 | N7: 0 | O7: 0 | P7: 0 | Q7: 0 | R7: 0 | S7: 0 | T7: 0 | U7: 0 | V7: 0 | W7: 0 | X7: 0 | Y7: 0 | Z7: 0 | AA7: 0 | AB7: 0 | AC7: 0 | AD7: 0 | AE7: 0 | AF7: 0 | AG7: 0 | AH7: 0 | AI7: 0 | AJ7: 0 | AK7: 0 | AL7: 0 | AM7: 0 | AN7: 0 | AO7: 0 | AP7: 0 | AQ7: 0 | AR7: 0 | AS7: 0 | AT7: 0 | AU7: 0 | AV7: 0 | AW7: 0 | AX7: 0 | AY7: 0 | AZ7: 0 | BA7: 0 | BB7: 0 | BC7: 0 | BD7: 0 | BE7: 0
A8: t2val_y_0 | B8: 0 | C8: 0 | D8: 0 | E8: 0 | F8: 0 | G8: 0 | H8: 0 | I8: 0 | J8: 0 | K8: 0 | L8: 0 | M8: 0 | N8: 0 | O8: 0 | P8: 0 | Q8: 0 | R8: 0 | S8: 0 | T8: 0 | U8: 0 | V8: 0 | W8: 0 | X8: 0 | Y8: 0 | Z8: 0 | AA8: 0 | AB8: 0 | AC8: 0 | AD8: 0 | AE8: 0 | AF8: 0 | AG8: 0 | AH8: 0 | AI8: 0 | AJ8: 0 | AK8: 0 | AL8: 0 | AM8: 0 | AN8: 0 | AO8: 0 | AP8: 0 | AQ8: 0 | AR8: 0 | AS8: 0 | AT8: 0 | AU8: 0 | AV8: 0 | AW8: 0 | AX8: 0 | AY8: 0 | AZ8: 0 | BA8: 0 | BB8: 0 | BC8: 0 | BD8: 0 | BE8: 0
A9: t2val_y_2 | B9: 0 | C9: 0 | D9: 0 | E9: 0 | F9: 0 | G9: 0 | H9: 0 | I9: 0 | J9: 0 | K9: 0 | L9: 0 | M9: 0 | N9: 0 | O9: 0 | P9: 0 | Q9: 0 | R9: 0 | S9: 0 | T9: 0 | U9: 0 | V9: 0 | W9: 0 | X9: 0 | Y9: 0 | Z9: 0 | AA9: 0 | AB9: 0 | AC9: 0 | AD9: 0 | AE9: 0 | AF9: 0 | AG9: 0 | AH9: 0 | AI9: 0 | AJ9: 0 | AK9: 0 | AL9: 0 | AM9: 0 | AN9: 0 | AO9: 0 | AP9: 0 | AQ9: 0 | AR9: 0 | AS9: 0 | AT9: 0 | AU9: 0 | AV9: 0 | AW9: 0 | AX9: 0 | AY9: 0 | AZ9: 0 | BA9: 0 | BB9: 0 | BC9: 0 | BD9: 0 | BE9: 0
A10: t2val_mat_0 | B10: 0 | C10: 0 | D10: 0 | E10: 0 | F10: 0 | G10: 0 | H10: 0 | I10: 0 | J10: 0 | K10: 0 | L10: 0 | M10: 0 | N10: 0 | O10: 0 | P10: 0 | Q10: 0 | R10: 0 | S10: 0 | T10: 0 | U10: 0 | V10: 0 | W10: 0 | X10: 0 | Y10: 0 | Z10: 0 | AA10: 0 | AB10: 0 | AC10: 0 | AD10: 0 | AE10: 0 | AF10: 0 | AG10: 0 | AH10: 0 | AI10: 0 | AJ10: 0 | AK10: 0 | AL10: 0 | AM10: 0 | AN10: 0 | AO10: 0 | AP10: 0 | AQ10: 0 | AR10: 0 | AS10: 0 | AT10: 0 | AU10: 0 | AV10: 0 | AW10: 0 | AX10: 0 | AY10: 0 | AZ10: 0 | BA10: 0 | BB10: 0 | BC10: 0 | BD10: 0 | BE10: 0
A11: t2val_mat_2 | B11: 0 | C11: 0 | D11: 0 | E11: 0 | F11: 0 | G11: 0 | H11: 0 | I11: 0 | J11: 0 | K11: 0 | L11: 0 | M11: 0 | N11: 0 | O11: 0 | P11: 0 | Q11: 0 | R11: 0 | S11: 0 | T11: 0 | U11: 0 | V11: 0 | W11: 0 | X11: 0 | Y11: 0 | Z11: 0 | AA11: 0 | AB11: 0 | AC11: 0 | AD11: 0 | AE11: 0 | AF11: 0 | AG11: 0 | AH11: 0 | AI11: 0 | AJ11: 0 | AK11: 0 | AL11: 0 | AM11: 0 | AN11: 0 | AO11: 0 | AP11: 0 | AQ11: 0 | AR11: 0 | AS11: 0 | AT11: 0 | AU11: 0 | AV11: 0 | AW11: 0 | AX11: 0 | AY11: 0 | AZ11: 0 | BA11: 0 | BB11: 0 | BC11: 0 | BD11: 0 | BE11: 0

Sheet Production
A1: _date_ | B1: 42005 | C1: 42370 | D1: 42736 | E1: 43101 | F1: 43466 | G1: 43831 | H1: 44197 | I1: 44562 | J1: 44927 | K1: 45292 | L1: 45658 | M1: 46023 | N1: 46388 | O1: 46753 | P1: 47119 | Q1: 47484 | R1: 47849 | S1: 48214 | T1: 48580 | U1: 48945 | V1: 49310 | W1: 49675 | X1: 50041 | Y1: 50406 | Z1: 50771 | AA1: 51136 | AB1: 51502 | AC1: 51867 | AD1: 52232 | AE1: 52597 | AF1: 52963 | AG1: 53328 | AH1: 53693 | AI1: 54058 | AJ1: 54424 | AK1: 54789 | AL1: 55154 | AM1: 55519 | AN1: 55885 | AO1: 56250 | AP1: 56615 | AQ1: 56980 | AR1: 57346 | AS1: 57711 | AT1: 58076 | AU1: 58441 | AV1: 58807 | AW1: 59172 | AX1: 59537 | AY1: 59902 | AZ1: 60268 | BA1: 60633 | BB1: 60998 | BC1: 61363 | BD1: 61729 | BE1: 62094
A2: y_2 | B2: 3788485.2 | C2: 3815695.8 | D2: 3853138.6 | E2: 3896956.9 | F2: 3945914 | G2: 3999170.7 | H2: 4053454 | I2: 4109945.4 | J2: 4168430.4 | K2: 4228648.4 | L2: 4294778.9 | M2: 4358947.2 | N2: 4423709.9 | O2: 4489126.4 | P2: 4555185.8 | Q2: 4621888.1 | R2: 4688949.4 | S2: 4756643.5 | T2: 4825045.3 | U2: 4894220 | V2: 4960970.7 | W2: 5030767.2 | X2: 5101831.4 | Y2: 5174095.3 | Z2: 5247556.3 | AA2: 5312862 | AB2: 5381237.8 | AC2: 5450229.1 | AD2: 5519932.3 | AE2: 5590495.8 | AF2: 5662048.2 | AG2: 5734752.5 | AH2: 5808617.4 | AI2: 5883669.1 | AJ2: 5959916.7 | AK2: 6037357.6 | AL2: 6114349.7 | AM2: 6191878.8 | AN2: 6270091.2 | AO2: 6349082.6 | AP2: 6428932.5 | AQ2: 6509807.3 | AR2: 6591690.2 | AS2: 6674612.5 | AT2: 6758595.9 | AU2: 6843654 | AV2: 6930332.3 | AW2: 7018262.4 | AX2: 7107394.1 | AY2: 7197696.7 | AZ2: 7289151 | BA2: 7381959.5 | BB2: 7475969.8 | BC2: 7571165.5 | BD2: 7667542.7 | BE2: 7765106.1
A3: y_0 | B3: 3859362.9 | C3: 3908270.1 | D3: 3962069.2 | E3: 4019511.4 | F3: 4080255.5 | G3: 4143927.4 | H3: 4207559.5 | I3: 4272581.3 | J3: 4339001.5 | K3: 4406764.2 | L3: 4480406 | M3: 4552217.8 | N3: 4624727.4 | O3: 4698046.1 | P3: 4772200.3 | Q3: 4847214.2 | R3: 4923123.2 | S3: 4999973.1 | T3: 5077815 | U3: 5156701.1 | V3: 5233255.8 | W3: 5313205.6 | X3: 5394678.6 | Y3: 5477598.7 | Z3: 5561956.7 | AA3: 5637837.7 | AB3: 5716951.4 | AC3: 5796788.9 | AD3: 5877455.6 | AE3: 5959108.5 | AF3: 6041880.6 | AG3: 6125866.5 | AH3: 6211124.7 | AI3: 6297684.6 | AJ3: 6385555.4 | AK3: 6474733.5 | AL3: 6562799.7 | AM3: 6651295.6 | AN3: 6740437.6 | AO3: 6830366.7 | AP3: 6921197.2 | AQ3: 7013024.6 | AR3: 7105925.5 | AS3: 7199958.9 | AT3: 7295168.3 | AU3: 7391584.9 | AV3: 7489450.5 | AW3: 7588641.1 | AX3: 7689151.8 | AY3: 7790980.6 | AZ3: 7894128.4 | BA3: 7998601.1 | BB3: 8104409.9 | BC3: 8211571.1 | BD3: 8320104.9 | BE3: 8430035.3
A4: y_sagr_2 | B4: 79996.655 | C4: 80124.427 | D4: 80517.639 | E4: 81126.647 | F4: 81924.542 | G4: 82882.37 | H4: 83921.765 | I4: 85046.843 | J4: 86242.622 | K4: 87495.238 | L4: 88878.317 | M4: 90241.99 | N4: 91621.255 | O4: 93013.834 | P4: 94417.19 | Q4: 95829.873 | R4: 97243.578 | S4: 98664.678 | T4: 100094.44 | U4: 101534.15 | V4: 102922.45 | W4: 104357.62 | X4: 105814.55 | Y4: 107292.37 | Z4: 108791.31 | AA4: 110132.07 | AB4: 111509.95 | AC4: 112893.08 | AD4: 114285.99 | AE4: 115693.85 | AF4: 117120.93 | AG4: 118572.06 | AH4: 120047.94 | AI4: 121549.59 | AJ4: 123077.47 | AK4: 124631.68 | AL4: 126185.07 | AM4: 127748.29 | AN4: 129325.14 | AO4: 130918.51 | AP4: 132530.85 | AQ4: 134166.77 | AR4: 135826.04 | AS4: 137509.63 | AT4: 139218.15 | AU4: 140951.91 | AV4: 142723.53 | AW4: 144524.68 | AX4: 146354.11 | AY4: 148210.88 | AZ4: 150094.26 | BA4: 152009.2 | BB4: 153951.45 | BC4: 155920.41 | BD4: 157915.75 | BE4: 159937.31
A5: y_sagr_0 | B5: 81862.318 | C5: 82566.293 | D5: 83408.247 | E5: 84394.136 | F5: 85513.737 | G5: 86747.141 | H5: 88023.012 | I5: 89352.746 | J5: 90728.792 | K5: 92144.441 | L5: 93684.438 | M5: 95204.282 | N5: 96739.494 | O5: 98290.116 | P5: 99855.244 | Q5: 101434.54 | R5: 103028.35 | S5: 104637.47 | T5: 106263.03 | U5: 107906.26 | V5: 109501.37 | W5: 111153.59 | X5: 112835.39 | Y5: 114545.86 | Z5: 116285.19 | AA5: 117859.65 | AB5: 119477.61 | AC5: 121105.55 | AD5: 122748.32 | AE5: 124411.41 | AF5: 126099.31 | AG5: 127815.22 | AH5: 129561.19 | AI5: 131338.38 | AJ5: 133147.32 | AK5: 134988.12 | AL5: 136813.62 | AM5: 138648.99 | AN5: 140499.52 | AO5: 142369.18 | AP5: 144261.38 | AQ5: 146178.98 | AR5: 148124.3 | AS5: 150099.04 | AT5: 152104.4 | AU5: 154141.17 | AV5: 156214.19 | AW5: 158321.61 | AX5: 160463.21 | AY5: 162638.5 | AZ5: 164847.02 | BA5: 167088.5 | BB5: 169362.87 | BC5: 171670.18 | BD5: 174010.61 | BE5: 176384.41
A6: y_sfor_2 | B6: 6481.5653 | C6: 6456.0119 | D6: 6417.3768 | E6: 6379.6502 | F6: 6347.9714 | G6: 6322.6176 | H6: 6298.5844 | I6: 6275.9983 | J6: 6254.7581 | K6: 6235.0897 | L6: 6221.796 | M6: 6206.9598 | N6: 6193.1236 | O6: 6180.7461 | P6: 6169.8888 | Q6: 6160.4638 | R6: 6151.7212 | S6: 6143.9939 | T6: 6137.3191 | U6: 6131.6833 | V6: 6123.9797 | W6: 6119.3227 | X6: 6116.2496 | Y6: 6114.4263 | Z6: 6113.7228 | AA6: 6105.5578 | AB6: 6100.3561 | AC6: 6096.5044 | AD6: 6093.7812 | AE6: 6092.1087 | AF6: 6091.4658 | AG6: 6091.9895 | AH6: 6093.5815 | AI6: 6096.2098 | AJ6: 6099.8531 | AK6: 6104.4915 | AL6: 6109.42 | AM6: 6115.0059 | AN6: 6121.3198 | AO6: 6128.3824 | AP6: 6136.1991 | AQ6: 6144.9593 | AR6: 6154.5253 | AS6: 6164.8517 | AT6: 6175.9133 | AU6: 6187.6931 | AV6: 6200.9696 | AW6: 6215.1838 | AX6: 6230.1716 | AY6: 6245.8586 | AZ6: 6262.2111 | BA6: 6279.5998 | BB6: 6297.7486 | BC6: 6316.5792 | BD6: 6336.0597 | BE6: 6356.1791
A7: y_sfor_0 | B7: 6537.0436 | C7: 6520.5895 | D7: 6493.4032 | E7: 6466.5479 | F7: 6443.1968 | G7: 6427.5788 | H7: 6417.7671 | I7: 6414.4663 | J7: 6416.5245 | K7: 6422.5833 | L7: 6436.2886 | M7: 6449.061 | N7: 6462.5599 | O7: 6476.9383 | P7: 6492.1744 | Q7: 6508.2038 | R7: 6524.9661 | S7: 6542.4182 | T7: 6560.5348 | U7: 6579.3056 | V7: 6595.4416 | W7: 6614.4166 | X7: 6634.681 | Y7: 6655.905 | Z7: 6677.957 | AA7: 6691.564 | AB7: 6707.7075 | AC7: 6724.8185 | AD7: 6742.7439 | AE7: 6761.4379 | AF7: 6780.8924 | AG7: 6801.1092 | AH7: 6822.0895 | AI7: 6843.8305 | AJ7: 6866.3256 | AK7: 6889.5658 | AL7: 6911.4455 | AM7: 6933.3503 | AN7: 6955.645 | AO7: 6978.4909 | AP7: 7001.9661 | AQ7: 7026.1137 | AR7: 7050.9596 | AS7: 7076.5145 | AT7: 7102.7651 | AU7: 7129.6328 | AV7: 7156.9146 | AW7: 7184.3946 | AX7: 7212.1427 | AY7: 7240.3719 | AZ7: 7269.2772 | BA7: 7298.9347 | BB7: 7329.3326 | BC7: 7360.4266 | BD7: 7392.1751 | BE7: 7424.5521
A8: y_sfoo_2 | B8: 154885.44 | C8: 155474.78 | D8: 156465.47 | E8: 157825.1 | F8: 159521.17 | G8: 161509 | H8: 163647.4 | I8: 165945.05 | J8: 168376.19 | K8: 170916.5 | L8: 173707.65 | M8: 176473.74 | N8: 179273.19 | O8: 182100.33 | P8: 184950.03 | Q8: 187819.39 | R8: 190695.18 | S8: 193586.64 | T8: 196495.6 | U8: 199424.16 | V8: 202254.43 | W8: 205169.64 | X8: 208125.9 | Y8: 211122.14 | Z8: 214158.71 | AA8: 216891.09 | AB8: 219679.83 | AC8: 222471.35 | AD8: 225276.58 | AE8: 228106.81 | AF8: 230971.2 | AG8: 233879.2 | AH8: 236833.31 | AI8: 239836.04 | AJ8: 242888.69 | AK8: 245991.79 | AL8: 249087.76 | AM8: 252199.62 | AN8: 255335.46 | AO8: 258501.57 | AP8: 261703.45 | AQ8: 264949.81 | AR8: 268241.64 | AS8: 271581.36 | AT8: 274970.5 | AU8: 278409.91 | AV8: 281921.02 | AW8: 285490.96 | AX8: 289117.68 | AY8: 292799.46 | AZ8: 296534.9 | BA8: 300331.61 | BB8: 304183.14 | BC8: 308088.47 | BD8: 312046.96 | BE8: 316058.33
A9: y_sfoo_0 | B9: 157864.05 | C9: 159519.2 | D9: 161394.62 | E9: 163504.99 | F9: 165840.05 | G9: 168370.12 | H9: 170966.92 | I9: 173653.3 | J9: 176418.44 | K9: 179252.51 | L9: 182317.94 | M9: 185349.58 | N9: 188408.77 | O9: 191494.79 | P9: 194605.96 | Q9: 197741.83 | R9: 200903.23 | S9: 204091.86 | T9: 207309.9 | U9: 210559.72 | V9: 213716.66 | W9: 216974.95 | X9: 220287.46 | Y9: 223653.41 | Z9: 227073.33 | AA9: 230179.86 | AB9: 233353.09 | AC9: 236537.02 | AD9: 239743.34 | AE9: 242984.07 | AF9: 246268.87 | AG9: 249604.66 | AH9: 252995.94 | AI9: 256445.42 | AJ9: 259954.46 | AK9: 263523.6 | AL9: 267063.73 | AM9: 270619.23 | AN9: 274200.28 | AO9: 277815.17 | AP9: 281471.26 | AQ9: 285174.82 | AR9: 288930.87 | AS9: 292743.22 | AT9: 296614.56 | AU9: 300546.74 | AV9: 304549.22 | AW9: 308619.06 | AX9: 312756.05 | AY9: 316959.22 | AZ9: 321227.69 | BA9: 325560.97 | BB9: 329958.95 | BC9: 334421.79 | BD9: 338949.87 | BE9: 343543.71
A10: y_sveh_2 | B10: 119862.62 | C10: 121740.18 | D10: 124058.97 | E10: 126378.07 | F10: 128586.26 | G10: 130671.48 | H10: 132534.8 | I10: 134316.22 | J10: 136047.43 | K10: 137748.64 | L10: 139630.49 | M10: 141291.14 | N10: 142933.14 | O10: 144568.57 | P10: 146204.32 | Q10: 147845.36 | R10: 149468.81 | S10: 151105.15 | T10: 152758.7 | U10: 154432.85 | V10: 155988.13 | W10: 157702.69 | X10: 159454.71 | Y10: 161240.57 | Z10: 163059.44 | AA10: 164507.16 | AB10: 166186.35 | AC10: 167911.53 | AD10: 169679.95 | AE10: 171490.43 | AF10: 173341.85 | AG10: 175239.01 | AH10: 177174.63 | AI10: 179147.06 | AJ10: 181154.81 | AK10: 183196.58 | AL10: 185229.36 | AM10: 187288.49 | AN10: 189377.34 | AO10: 191496.98 | AP10: 193647.68 | AQ10: 195837.89 | AR10: 198059.17 | AS10: 200310.82 | AT10: 202592.27 | AU10: 204903.09 | AV10: 207280.55 | AW10: 209688.95 | AX10: 212126.49 | AY10: 214592.38 | AZ10: 217086.4 | BA10: 219626.99 | BB10: 222197.32 | BC10: 224797.2 | BD10: 227426.86 | BE10: 230086.74
A11: y_sveh_0 | B11: 125926.72 | C11: 128329.38 | D11: 131029.29 | E11: 133658.57 | F11: 136145.42 | G11: 138504.73 | H11: 140655.03 | I11: 142745.69 | J11: 144813.21 | K11: 146879.68 | L11: 149169.66 | M11: 151281.4 | N11: 153401.56 | O11: 155539.92 | P11: 157701.52 | Q11: 159889.83 | R11: 162107.69 | S11: 164357.63 | T11: 166641.98 | U11: 168962.89 | V11: 171165.93 | W11: 173554.74 | X11: 175995.34 | Y11: 178483.49 | Z11: 181017.9 | AA11: 183147.25 | AB11: 185528.4 | AC11: 187966.57 | AD11: 190459.27 | AE11: 193005.45 | AF11: 195603.95 | AG11: 198253.39 | AH11: 200952.28 | AI11: 203699.06 | AJ11: 206492.3 | AK11: 209330.69 | AL11: 212103.89 | AM11: 214911.71 | AN11: 217760.12 | AO11: 220651.5 | AP11: 223586.76 | AQ11: 226566.02 | AR11: 229589.01 | AS11: 232655.26 | AT11: 235764.22 | AU11: 238915.34 | AV11: 242118.09 | AW11: 245362.93 | AX11: 248649.08 | AY11: 251976.16 | AZ11: 255344.07 | BA11: 258752.95 | BB11: 262203.07 | BC11: 265694.83 | BD11: 269228.73 | BE11: 272805.3
A12: y_sgla_2 | B12: 21685.663 | C12: 21827.758 | D12: 22035.012 | E12: 22283.94 | F12: 22564.4 | G12: 22869.529 | H12: 23182.12 | I12: 23505.504 | J12: 23838.559 | K12: 24180.184 | L12: 24550.133 | M12: 24913.666 | N12: 25280.557 | O12: 25651.463 | P12: 26026.699 | Q12: 26406.594 | R12: 26789.601 | S12: 27177.702 | T12: 27571.591 | U12: 27971.88 | V12: 28363.941 | W12: 28771.683 | X12: 29189.077 | Y12: 29615.872 | Z12: 30052.088 | AA12: 30454.251 | AB12: 30869.45 | AC12: 31289.585 | AD12: 31715.125 | AE12: 32146.687 | AF12: 32584.778 | AG12: 33030.179 | AH12: 33482.73 | AI12: 33942.406 | AJ12: 34409.085 | AK12: 34882.569 | AL12: 35356.136 | AM12: 35832.073 | AN12: 36310.935 | AO12: 36793.025 | AP12: 37278.565 | AQ12: 37768.378 | AR12: 38262.167 | AS12: 38759.987 | AT12: 39261.871 | AU12: 39767.829 | AV12: 40280.977 | AW12: 40799.31 | AX12: 41322.519 | AY12: 41850.405 | AZ12: 42382.846 | BA12: 42921.168 | BB12: 43464.447 | BC12: 44012.625 | BD12: 44565.72 | BE12: 45123.81
... A67: y_seot_0 | B67: 109.765 | C67: 110.57054 | D67: 111.25226 | E67: 111.94529 | F67: 112.6958 | G67: 113.53938 | H67: 114.42397 | I67: 115.3675 | J67: 116.3592 | K67: 117.38543 | L67: 118.53191 | M67: 119.63719 | N67: 120.73875 | O67: 121.84272 | P67: 122.95069 | Q67: 124.06366 | R67: 125.1829 | S67: 126.31004 | T67: 127.44698 | U67: 128.59585 | V67: 129.68866 | W67: 130.84033 | X67: 132.02231 | Y67: 133.23046 | Z67: 134.46464 | AA67: 135.52484 | AB67: 136.63915 | AC67: 137.77696 | AD67: 138.93706 | AE67: 140.12188 | AF67: 141.33408 | AG67: 142.57578 | AH67: 143.84838 | AI67: 145.15263 | AJ67: 146.48876 | AK67: 147.85661 | AL67: 149.20796 | AM67: 150.57074 | AN67: 151.95205 | AO67: 153.355 | AP67: 154.78149 | AQ67: 156.2329 | AR67: 157.71023 | AS67: 159.21414 | AT67: 160.74495 | AU67: 162.30235 | AV67: 163.88833 | AW67: 165.49894 | AX67: 167.13151 | AY67: 168.78967 | AZ67: 170.47677 | BA67: 172.19375 | BB67: 173.94014 | BC67: 175.71517 | BD67: 177.51823 | BE67: 179.34911

Sheet Capital
A1: _date_ | B1: 42005 | C1: 42370 | D1: 42736 | E1: 43101 | F1: 43466 | G1: 43831 | H1: 44197 | I1: 44562 | J1: 44927 | K1: 45292 | L1: 45658 | M1: 46023 | N1: 46388 | O1: 46753 | P1: 47119 | Q1: 47484 | R1: 47849 | S1: 48214 | T1: 48580 | U1: 48945 | V1: 49310 | W1: 49675 | X1: 50041 | Y1: 50406 | Z1: 50771 | AA1: 51136 | AB1: 51502 | AC1: 51867 | AD1: 52232 | AE1: 52597 | AF1: 52963 | AG1: 53328 | AH1: 53693 | AI1: 54058 | AJ1: 54424 | AK1: 54789 | AL1: 55154 | AM1: 55519 | AN1: 55885 | AO1: 56250 | AP1: 56615 | AQ1: 56980 | AR1: 57346 | AS1: 57711 | AT1: 58076 | AU1: 58441 | AV1: 58807 | AW1: 59172 | AX1: 59537 | AY1: 59902 | AZ1: 60268 | BA1: 60633 | BB1: 60998 | BC1: 61363 | BD1: 61729 | BE1: 62094
A2: f_k_2 | B2: 5218727.8 | C2: 5271371 | D2: 5323901.4 | E2: 5377275.8 | F2: 5432055.7 | G2: 5488596.3 | H2: 5546947.6 | I2: 5607165.1 | J2: 5669314.4 | K2: 5733462.8 | L2: 5800006.9 | M2: 5868870.8 | N2: 5940012.6 | O2: 6013416.8 | P2: 6089081.6 | Q2: 6167012.2 | R2: 6247195.3 | S2: 6329633.7 | T2: 6414341.5 | U2: 6501339.4 | V2: 6590406 | W2: 6681646.1 | X2: 6775143.6 | Y2: 6870962.1 | Z2: 6969152.6 | AA2: 7069046.4 | AB2: 7170572.5 | AC2: 7273688.7 | AD2: 7378361.9 | AE2: 7484569 | AF2: 7592296.5 | AG2: 7701543.7 | AH2: 7812311.3 | AI2: 7924599.2 | AJ2: 8038405.5 | AK2: 8153725.2 | AL2: 8270428.8 | AM2: 8388413.1 | AN2: 8507596.1 | AO2: 8627910.3 | AP2: 8749300.4 | AQ2: 8871729.5 | AR2: 8995166.8 | AS2: 9119587.2 | AT2: 9244970.4 | AU2: 9371300.7 | AV2: 9498610.1 | AW2: 9626917.9 | AX2: 9756234.9 | AY2: 9886567.9 | AZ2: 10017922 | BA2: 10150319 | BB2: 10283777 | BC2: 10418311 | BD2: 10553936 | BE2: 10690666
A3: f_k_0 | B3: 5224351.6 | C3: 5285939.2 | D3: 5349468.3 | E3: 5415267.1 | F3: 5483570.5 | G3: 5554548.7 | H3: 5628133 | I3: 5704293 | J3: 5783028.1 | K3: 5864354.1 | L3: 5948646 | M3: 6035819.6 | N3: 6125820.8 | O3: 6218620.3 | P3: 6314200.2 | Q3: 6412547.9 | R3: 6513654.3 | S3: 6617512.9 | T3: 6724119.7 | U3: 6833472.4 | V3: 6945305.2 | W3: 7059698.9 | X3: 7176711.4 | Y3: 7296379.2 | Z3: 7418725.8 | AA3: 7542993.5 | AB3: 7669058.5 | AC3: 7796832.5 | AD3: 7926240.9 | AE3: 8057223.3 | AF3: 8189731.8 | AG3: 8323728.1 | AH3: 8459179.7 | AI3: 8596056.3 | AJ3: 8734328.3 | AK3: 8873964.4 | AL3: 9014742.2 | AM3: 9156493.5 | AN3: 9299090.3 | AO3: 9442431.8 | AP3: 9586438.2 | AQ3: 9731047 | AR3: 9876210.4 | AS3: 10021893 | AT3: 10168070 | AU3: 10314725 | AV3: 10461867 | AW3: 10609508 | AX3: 10757660 | AY3: 10906342 | AZ3: 11055573 | BA3: 11205379 | BB3: 11355791 | BC3: 11506843 | BD3: 11658579 | BE3: 11811044
A4: f_k_sagr_2 | B4: 47150.175 | C4: 47589.294 | D4: 48008.617 | E4: 48421.03 | F4: 48836.534 | G4: 49262.939 | H4: 49704.499 | I4: 50164.599 | J4: 50645.906 | K4: 51150.41 | L4: 51682.555 | M4: 52242.094 | N4: 52828.675 | O4: 53441.918 | P4: 54081.386 | Q4: 54746.601 | R4: 55436.763 | S4: 56151.276 | T4: 56889.657 | U4: 57651.507 | V4: 58434.242 | W4: 59238.187 | X4: 60063.64 | Y4: 60910.793 | Z4: 61779.779 | AA4: 62664.182 | AB4: 63562.833 | AC4: 64475.046 | AD4: 65400.401 | AE4: 66338.724 | AF4: 67290.055 | AG4: 68254.664 | AH4: 69232.877 | AI4: 70225.046 | AJ4: 71231.528 | AK4: 72252.659 | AL4: 73287.867 | AM4: 74336.559 | AN4: 75398.306 | AO4: 76472.836 | AP4: 77560.02 | AQ4: 78659.975 | AR4: 79772.861 | AS4: 80898.892 | AT4: 82038.319 | AU4: 83191.418 | AV4: 84359.021 | AW4: 85541.708 | AX4: 86739.921 | AY4: 87954.011 | AZ4: 89184.267 | BA4: 90431.193 | BB4: 91695.129 | BC4: 92976.337 | BD4: 94275.029 | BE4: 95591.397
A5: f_k_sagr_0 | B5: 47217.394 | C5: 47760.718 | D5: 48305.589 | E5: 48857.213 | F5: 49421.24 | G5: 50002.532 | H5: 50603.051 | I5: 51224.307 | J5: 51867.452 | K5: 52533.322 | L5: 53225.705 | M5: 53944.036 | N5: 54687.691 | O5: 55456.096 | P5: 56248.676 | Q5: 57064.861 | R5: 57904.098 | S5: 58765.877 | T5: 59649.738 | U5: 60555.279 | V5: 61479.729 | W5: 62423.455 | X5: 63386.78 | Y5: 64369.919 | Z5: 65373.034 | AA5: 66389.2 | AB5: 67417.082 | AC5: 68455.929 | AD5: 69505.307 | AE5: 70565.073 | AF5: 71635.327 | AG5: 72716.348 | AH5: 73808.522 | AI5: 74912.293 | AJ5: 76028.12 | AK5: 77156.452 | AL5: 78295.991 | AM5: 79445.869 | AN5: 80605.588 | AO5: 81774.931 | AP5: 82953.898 | AQ5: 84142.67 | AR5: 85341.568 | AS5: 86551.015 | AT5: 87771.499 | AU5: 89003.552 | AV5: 90247.882 | AW5: 91505.165 | AX5: 92776.043 | AY5: 94061.11 | AZ5: 95360.915 | BA5: 96675.967 | BB5: 98006.748 | BC5: 99353.72 | BD5: 100717.33 | BE5: 102098.01
A6: f_k_sfor_2 | B6: 1843.0431 | C6: 1860.8216 | D6: 1876.5864 | E6: 1890.2889 | F6: 1902.0591 | G6: 1912.0791 | H6: 1920.4597 | I6: 1927.3001 | J6: 1932.7012 | K6: 1936.7738 | L6: 1939.7171 | M6: 1941.6157 | N6: 1942.5711 | O6: 1942.6984 | P6: 1942.117 | Q6: 1940.9435 | R6: 1939.2743 | S6: 1937.2078 | T6: 1934.8394 | U6: 1932.2602 | V6: 1929.5039 | W6: 1926.6708 | X6: 1923.8517 | Y6: 1921.1235 | Z6: 1918.5524 | AA6: 1916.0544 | AB6: 1913.6793 | AC6: 1911.4844 | AD6: 1909.5211 | AE6: 1907.8336 | AF6: 1906.4606 | AG6: 1905.4396 | AH6: 1904.8023 | AI6: 1904.5759 | AJ6: 1904.7837 | AK6: 1905.446 | AL6: 1906.5797 | AM6: 1908.1923 | AN6: 1910.2908 | AO6: 1912.8804 | AP6: 1915.965 | AQ6: 1919.5526 | AR6: 1923.6469 | AS6: 1928.2495 | AT6: 1933.3605 | AU6: 1938.9789 | AV6: 1945.1235 | AW6: 1951.8007 | AX6: 1959.0105 | AY6: 1966.7492 | AZ6: 1975.011 | BA6: 1983.8008 | BB6: 1993.1159 | BC6: 2002.9508 | BD6: 2013.2982 | BE6: 2024.1501
A7: f_k_sfor_0 | B7: 1844.7471 | C7: 1864.5142 | D7: 1882.2706 | E7: 1897.8557 | F7: 1911.324 | G7: 1922.8723 | H7: 1932.7095 | I7: 1941.0626 | J7: 1948.144 | K7: 1954.137 | L7: 1959.2754 | M7: 1963.6571 | N7: 1967.3669 | O7: 1970.4882 | P7: 1973.102 | Q7: 1975.2857 | R7: 1977.1116 | S7: 1978.6477 | T7: 1979.9571 | U7: 1981.0989 | V7: 1982.074 | W7: 1982.9551 | X7: 1983.8075 | Y7: 1984.6846 | Z7: 1985.631 | AA7: 1986.5365 | AB7: 1987.426 | AC7: 1988.3386 | AD7: 1989.3111 | AE7: 1990.3766 | AF7: 1991.5643 | AG7: 1992.9003 | AH7: 1994.4077 | AI7: 1996.1073 | AJ7: 1998.0173 | AK7: 2000.1538 | AL7: 2002.4978 | AM7: 2005.0422 | AN7: 2007.7894 | AO7: 2010.7468 | AP7: 2013.924 | AQ7: 2017.331 | AR7: 2020.9777 | AS7: 2024.8736 | AT7: 2029.0272 | AU7: 2033.4446 | AV7: 2038.1275 | AW7: 2043.0724 | AX7: 2048.275 | AY7: 2053.734 | AZ7: 2059.4524 | BA7: 2065.4354 | BB7: 2071.6881 | BC7: 2078.2149 | BD7: 2085.0186 | BE7: 2092.1011
A8: f_k_sfoo_2 | B8: 74442.247 | C8: 75170.07 | D8: 75876.334 | E8: 76577.633 | F8: 77287.282 | G8: 78015.979 | H8: 78769.46 | I8: 79552.358 | J8: 80368.387 | K8: 81220.365 | L8: 82115.04 | M8: 83052.237 | N8: 84031.428 | O8: 85051.95 | P8: 86113.01 | Q8: 87213.732 | R8: 88352.859 | S8: 89529.322 | T8: 90742.177 | U8: 91990.577 | V8: 93270.233 | W8: 94581.24 | X8: 95923.719 | Y8: 97297.676 | Z8: 98703.034 | AA8: 100129.5 | AB8: 101574.5 | AC8: 103036.34 | AD8: 104513.89 | AE8: 106006.45 | AF8: 107513.76 | AG8: 109035.92 | AH8: 110573.2 | AI8: 112125.96 | AJ8: 113694.59 | AK8: 115279.5 | AL8: 116879.41 | AM8: 118493.18 | AN8: 120120.03 | AO8: 121759.46 | AP8: 123411.27 | AQ8: 125075.61 | AR8: 126752.82 | AS8: 128443.32 | AT8: 130147.65 | AU8: 131866.38 | AV8: 133600.79 | AW8: 135351.92 | AX8: 137120.64 | AY8: 138907.72 | AZ8: 140713.82 | BA8: 142539.83 | BB8: 144386.47 | BC8: 146254.35 | BD8: 148144.03 | BE8: 150056.02
A9: f_k_sfoo_0 | B9: 74528.113 | C9: 75393.603 | D9: 76271.233 | E9: 77167.949 | F9: 78091.028 | G9: 79046.729 | H9: 80037.143 | I9: 81063.833 | J9: 82127.996 | K9: 83230.494 | L9: 84376.895 | M9: 85566.315 | N9: 86797.691 | O9: 88069.983 | P9: 89382.128 | Q9: 90733.061 | R9: 92121.749 | S9: 93547.224 | T9: 95008.593 | U9: 96505.05 | V9: 98032.095 | W9: 99589.946 | X9: 101178.85 | Y9: 102798.97 | Z9: 104450.37 | AA9: 106122.12 | AB9: 107811.51 | AC9: 109516.83 | AD9: 111236.98 | AE9: 112971.39 | AF9: 114719.98 | AG9: 116482.96 | AH9: 118260.79 | AI9: 120054.02 | AJ9: 121863.3 | AK9: 123689.24 | AL9: 125529.81 | AM9: 127383.51 | AN9: 129249.44 | AO9: 131127.13 | AP9: 133016.52 | AQ9: 134917.86 | AR9: 136831.65 | AS9: 138758.61 | AT9: 140699.58 | AU9: 142655.48 | AV9: 144627.54 | AW9: 146616.95 | AX9: 148624.88 | AY9: 150652.41 | AZ9: 152700.58 | BA9: 154770.36 | BB9: 156862.66 | BC9: 158978.38 | BD9: 161118.41 | BE9: 163283.59
A10: f_k_sveh_2 | B10: 400375.64 | C10: 403619.02 | D10: 407077.48 | E10: 410856.54 | F10: 414951.41 | G10: 419321.77 | H10: 423898.41 | I10: 428633.72 | J10: 433495.3 | K10: 438460.81 | L10: 443554.17 | M10: 448732.97 | N10: 453975.72 | O10: 459271.32 | P10: 464613.72 | Q10: 469999.75 | R10: 475422.77 | S10: 480881.44 | T10: 486377.13 | U10: 491912.68 | V10: 497463.4 | W10: 503052.32 | X10: 508692.54 | Y10: 514392.47 | Z10: 520158.67 | AA10: 525915.94 | AB10: 531686.27 | AC10: 537484.79 | AD10: 543322.7 | AE10: 549209.32 | AF10: 555152.87 | AG10: 561161.79 | AH10: 567242.86 | AI10: 573401.65 | AJ10: 579642.86 | AK10: 585970.43 | AL10: 592379.36 | AM10: 598868.99 | AN10: 605440.66 | AO10: 612096.45 | AP10: 618838.56 | AQ10: 625670.89 | AR10: 632596.02 | AS10: 639615.86 | AT10: 646731.94 | AU10: 653945.49 | AV10: 661265.16 | AW10: 668694.42 | AX10: 676234.58 | AY10: 683886.06 | AZ10: 691648.9 | BA10: 699526.77 | BB10: 707520.93 | BC10: 715631.75 | BD10: 723859.31 | BE10: 732203.67
A11: f_k_sveh_0 | B11: 401602.76 | C11: 406515.04 | D11: 411794.98 | E11: 417445.86 | F11: 423425.57 | G11: 429681.67 | H11: 436143.54 | I11: 442767.01 | J11: 449525.24 | K11: 456402.17 | L11: 463431.24 | M11: 470579.14 | N11: 477830.08 | O11: 485176.91 | P11: 492616.38 | Q11: 500147.29 | R11: 507769.72 | S11: 515484.71 | T11: 523294.02 | U11: 531200.01 | V11: 539173.48 | W11: 547238.32 | X11: 555407.15 | Y11: 563687.35 | Z11: 572084.17 | AA11: 580509.15 | AB11: 588981.98 | AC11: 597516.39 | AD11: 606122.46 | AE11: 614808.62 | AF11: 623582.25 | AG11: 632449.86 | AH11: 641417.11 | AI11: 650488.87 | AJ11: 659669.26 | AK11: 668961.74 | AL11: 678346.69 | AM11: 687818.35 | AN11: 697376.93 | AO11: 707024.88 | AP11: 716765.45 | AQ11: 726602.07 | AR11: 736538.08 | AS11: 746576.58 | AT11: 756720.44 | AU11: 766972.21 | AV11: 777336.27 | AW11: 787815.44 | AX11: 798411.84 | AY11: 809127.18 | AZ11: 819963.04 | BA11: 830920.91 | BB11: 842002.28 | BC11: 853208.68 | BD11: 864541.69 | BE11: 876002.99
A12: f_k_sgla_2 | B12: 16064.666 | C12: 16222.883 | D12: 16380.432 | E12: 16540.79 | F12: 16705.949 | G12: 16877.086 | H12: 17054.37 | I12: 17237.886 | J12: 17427.7 | K12: 17623.876 | L12: 17827.397 | M12: 18037.967 | N12: 18255.369 | O12: 18479.478 | P12: 18710.232 | Q12: 18947.611 | R12: 19191.547 | S12: 19442.054 | T12: 19699.201 | U12: 19963.096 | V12: 20233.198 | W12: 20509.846 | X12: 20793.363 | Y12: 21084.031 | Z12: 21382.095 | AA12: 21685.817 | AB12: 21995.017 | AC12: 22309.634 | AD12: 22629.637 | AE12: 22955.022 | AF12: 23285.799 | AG12: 23622.012 | AH12: 23963.695 | AI12: 24310.864 | AJ12: 24663.522 | AK12: 25021.648 | AL12: 25384.912 | AM12: 25752.997 | AN12: 26125.618 | AO12: 26502.517 | AP12: 26883.461 | AQ12: 27268.271 | AR12: 27656.777 | AS12: 28048.82 | AT12: 28444.252 | AU12: 28842.939 | AV12: 29244.903 | AW12: 29650.126 | AX12: 30058.558 | AY12: 30470.137 | AZ12: 30884.794 | BA12: 31302.533 | BB12: 31723.338 | BC12: 32147.186 | BD12: 32574.058 | BE12: 33003.941
... A67: f_k_seot_0 | B67: 65.173576 | C67: 65.912331 | D67: 66.632457 | E67: 67.33126 | F67: 68.010473 | G67: 68.674498 | H67: 69.326516 | I67: 69.969922 | J67: 70.607719 | K67: 71.242211 | L67: 71.878645 | M67: 72.517025 | N67: 73.157089 | O67: 73.798765 | P67: 74.442098 | Q67: 75.08721 | R67: 75.734285 | S67: 76.383582 | T67: 77.035448 | U67: 77.690323 | V67: 78.346141 | W67: 79.004361 | X67: 79.666468 | Y67: 80.333741 | Z67: 81.007348 | AA67: 81.681 | AB67: 82.354644 | AC67: 83.029116 | AD67: 83.705418 | AE67: 84.384668 | AF67: 85.068084 | AG67: 85.756961 | AH67: 86.452632 | AI67: 87.156427 | AJ67: 87.869644 | AK67: 88.593521 | AL67: 89.327466 | AM67: 90.071341 | AN67: 90.825414 | AO67: 91.590177 | AP67: 92.366235 | AQ67: 93.154252 | AR67: 93.954921 | AS67: 94.768937 | AT67: 95.596978 | AU67: 96.439678 | AV67: 97.297698 | AW67: 98.171537 | AX67: 99.061516 | AY67: 99.968016 | AZ67: 100.89153 | BA67: 101.83261 | BB67: 102.79175 | BC67: 103.76941 | BD67: 104.76597 | BE67: 105.78175

Sheet Results
A1: NB : on crée ici une liste : - globale, qui fusionne les sorties des reportings 1, 2 et 3 - "rationalisée" : suppression des doublons, et regroupements par thématique On continue par la suite à avoir 2 Excels de reporting (un "energie", fusion des reportings 1 et 2), et un "économie" (reporting 3)), dans lesquels on copiera cet onglet "results" (généré automatiquement par EViews). --> puis voir à la fin si on peut pas importer les graphs et tableaux dans l'excel automatiquement généré (éviterait les copiés collés, mais à voir si ça prend trop de temps, et si c'est pas trop gros comme excel)
A2: Nom du bloc de variables utilisé dans le code | B2: Sous-bloc de variables pour plus de lisibilité dans le Excel | E2: Year | F2: =date!B3 -> 2015 | G2: =date!C3 -> 2016 | H2: =date!D3 -> 2017 | I2: =date!E3 -> 2018 | J2: =date!F3 -> 2019 | K2: =date!G3 -> 2020 | L2: =date!H3 -> 2021 | M2: =date!I3 -> 2022 | ... BI2: =date!BE3 -> 2070
A3: HYBRID | B3: AUTOMOBILES (thousands) | C3: TOTAL STOCK SHOCK | E3: AUTO_2 | F3: =VLOOKUP($E3,Hybrid!$1:$1048576,MATCH(DATE(F$2,1,1),Hybrid!$A$1:$LI$1),FALSE) -> 32317.941 | G3: =VLOOKUP($E3,Hybrid!$1:$1048576,MATCH(DATE(G$2,1,1),Hybrid!$A$1:$LI$1),FALSE) -> 31906.572 | H3: =VLOOKUP($E3,Hybrid!$1:$1048576,MATCH(DATE(H$2,1,1),Hybrid!$A$1:$LI$1),FALSE) -> 31679.015 | I3: =VLOOKUP($E3,Hybrid!$1:$1048576,MATCH(DATE(I$2,1,1),Hybrid!$A$1:$LI$1),FALSE) -> 31579.816 | J3: =VLOOKUP($E3,Hybrid!$1:$1048576,MATCH(DATE(J$2,1,1),Hybrid!$A$1:$LI$1),FALSE) -> 31572.523 | K3: =VLOOKUP($E3,Hybrid!$1:$1048576,MATCH(DATE(K$2,1,1),Hybrid!$A$1:$LI$1),FALSE) -> 31633.573 | L3: =VLOOKUP($E3,Hybrid!$1:$1048576,MATCH(DATE(L$2,1,1),Hybrid!$A$1:$LI$1),FALSE) -> 31743.622 | M3: =VLOOKUP($E3,Hybrid!$1:$1048576,MATCH(DATE(M$2,1,1),Hybrid!$A$1:$LI$1),FALSE) -> 31892.229 | ... BI3: =VLOOKUP($E3,Hybrid!$1:$1048576,MATCH(DATE(BI$2,1,1),Hybrid!$A$1:$LI$1),FALSE) -> 44185.292
C4: OIL | E4: AUTO_cfut_2 | F4: =VLOOKUP($E4,Hybrid!$1:$1048576,MATCH(DATE(F$2,1,1),Hybrid!$A$1:$LI$1),FALSE) -> 32271.24 | G4: =VLOOKUP($E4,Hybrid!$1:$1048576,MATCH(DATE(G$2,1,1),Hybrid!$A$1:$LI$1),FALSE) -> 31842.385 | H4: =VLOOKUP($E4,Hybrid!$1:$1048576,MATCH(DATE(H$2,1,1),Hybrid!$A$1:$LI$1),FALSE) -> 31596.647 | I4: =VLOOKUP($E4,Hybrid!$1:$1048576,MATCH(DATE(I$2,1,1),Hybrid!$A$1:$LI$1),FALSE) -> 31478.956 | J4: =VLOOKUP($E4,Hybrid!$1:$1048576,MATCH(DATE(J$2,1,1),Hybrid!$A$1:$LI$1),FALSE) -> 31453.091 | K4: =VLOOKUP($E4,Hybrid!$1:$1048576,MATCH(DATE(K$2,1,1),Hybrid!$A$1:$LI$1),FALSE) -> 31495.616 | L4: =VLOOKUP($E4,Hybrid!$1:$1048576,MATCH(DATE(L$2,1,1),Hybrid!$A$1:$LI$1),FALSE) -> 31587.292 | M4: =VLOOKUP($E4,Hybrid!$1:$1048576,MATCH(DATE(M$2,1,1),Hybrid!$A$1:$LI$1),FALSE) -> 31717.717 | ... BI4: =VLOOKUP($E4,Hybrid!$1:$1048576,MATCH(DATE(BI$2,1,1),Hybrid!$A$1:$LI$1),FALSE) -> 43190.487
D5: class A | E5: AUTO_ca_cfut_2 | F5: =VLOOKUP($E5,Hybrid!$1:$1048576,MATCH(DATE(F$2,1,1),Hybrid!$A$1:$LI$1),FALSE) -> 7095.7005 | G5: =VLOOKUP($E5,Hybrid!$1:$1048576,MATCH(DATE(G$2,1,1),Hybrid!$A$1:$LI$1),FALSE) -> 7135.4525 | H5: =VLOOKUP($E5,Hybrid!$1:$1048576,MATCH(DATE(H$2,1,1),Hybrid!$A$1:$LI$1),FALSE) -> 7219.1567 | I5: =VLOOKUP($E5,Hybrid!$1:$1048576,MATCH(DATE(I$2,1,1),Hybrid!$A$1:$LI$1),FALSE) -> 7333.1185 | J5: =VLOOKUP($E5,Hybrid!$1:$1048576,MATCH(DATE(J$2,1,1),Hybrid!$A$1:$LI$1),FALSE) -> 7468.4598 | K5: =VLOOKUP($E5,Hybrid!$1:$1048576,MATCH(DATE(K$2,1,1),Hybrid!$A$1:$LI$1),FALSE) -> 7619.5809 | L5: =VLOOKUP($E5,Hybrid!$1:$1048576,MATCH(DATE(L$2,1,1),Hybrid!$A$1:$LI$1),FALSE) -> 7781.7706 | M5: =VLOOKUP($E5,Hybrid!$1:$1048576,MATCH(DATE(M$2,1,1),Hybrid!$A$1:$LI$1),FALSE) -> 7952.6697 | ... BI5: =VLOOKUP($E5,Hybrid!$1:$1048576,MATCH(DATE(BI$2,1,1),Hybrid!$A$1:$LI$1),FALSE) -> 17418.49
D6: class B | E6: AUTO_cb_cfut_2 | F6: =VLOOKUP($E6,Hybrid!$1:$1048576,MATCH(DATE(F$2,1,1),Hybrid!$A$1:$LI$1),FALSE) -> 8251.2564 | G6: =VLOOKUP($E6,Hybrid!$1:$1048576,MATCH(DATE(G$2,1,1),Hybrid!$A$1:$LI$1),FALSE) -> 8176.9035 | H6: =VLOOKUP($E6,Hybrid!$1:$1048576,MATCH(DATE(H$2,1,1),Hybrid!$A$1:$LI$1),FALSE) -> 8152.584 | I6: =VLOOKUP($E6,Hybrid!$1:$1048576,MATCH(DATE(I$2,1,1),Hybrid!$A$1:$LI$1),FALSE) -> 8164.2487 | J6: =VLOOKUP($E6,Hybrid!$1:$1048576,MATCH(DATE(J$2,1,1),Hybrid!$A$1:$LI$1),FALSE) -> 8202.5934 | K6: =VLOOKUP($E6,Hybrid!$1:$1048576,MATCH(DATE(K$2,1,1),Hybrid!$A$1:$LI$1),FALSE) -> 8261.5505 | L6: =VLOOKUP($E6,Hybrid!$1:$1048576,MATCH(DATE(L$2,1,1),Hybrid!$A$1:$LI$1),FALSE) -> 8335.9889 | M6: =VLOOKUP($E6,Hybrid!$1:$1048576,MATCH(DATE(M$2,1,1),Hybrid!$A$1:$LI$1),FALSE) -> 8423.0907 | ... BI6: =VLOOKUP($E6,Hybrid!$1:$1048576,MATCH(DATE(BI$2,1,1),Hybrid!$A$1:$LI$1),FALSE) -> 14149.065
