Workbook
Name formatResults: [1]ResultsEXR10!$A$50

Sheet Carbontax
A1: _date_ | B1: 42005 | C1: 42370 | D1: 42736 | E1: 43101 | F1: 43466 | G1: 43831 | H1: 44197 | I1: 44562 | J1: 44927 | K1: 45292 | L1: 45658 | M1: 46023 | N1: 46388 | O1: 46753 | P1: 47119 | Q1: 47484 | R1: 47849 | S1: 48214 | T1: 48580 | U1: 48945 | V1: 49310 | W1: 49675 | X1: 50041 | Y1: 50406 | Z1: 50771 | AA1: 51136 | AB1: 51502 | AC1: 51867 | AD1: 52232 | AE1: 52597 | AF1: 52963 | AG1: 53328 | AH1: 53693 | AI1: 54058 | AJ1: 54424 | AK1: 54789
A2: t2val_ch_0 | B2: 1732.612 | C2: 2604.4617 | D2: 3573.26 | E2: 5172.311 | F2: 5148.6408 | G2: 5142.9411 | H2: 5135.9657 | I2: 5247.0501 | J2: 5359.135 | K2: 5480.1012 | L2: 5611.1786 | M2: 5747.1604 | N2: 5883.9586 | O2: 6017.1489 | P2: 6143.0168 | Q2: 6259.2574 | R2: 6373.9467 | S2: 6478.3445 | T2: 6571.5626 | U2: 6654.1116 | V2: 6726.1578 | W2: 6792.5557 | X2: 6855.2553 | Y2: 6916.9117 | Z2: 6980.4679 | AA2: 7045.0359 | AB2: 7119.2742 | AC2: 7205.9333 | AD2: 7307.6273 | AE2: 7426.7797 | AF2: 7564.732 | AG2: 7722.2462 | AH2: 7899.2902 | AI2: 8095.5298 | AJ2: 8310.3496 | AK2: 8514.8567
A3: t2val_ch_2 | B3: 1732.6121 | C3: 2604.4619 | D3: 3573.2602 | E3: 5172.3113 | F3: 5148.641 | G3: 5142.9413 | H3: 5147.3724 | I3: 12549.587 | J3: 16944.264 | K3: 21290.993 | L3: 25663.111 | M3: 27428.15 | N3: 29180.109 | O3: 30887.284 | P3: 32501.508 | Q3: 33985.201 | R3: 36850.663 | S3: 39499.251 | T3: 41894.16 | U3: 44017.203 | V3: 45846.502 | W3: 47394.751 | X3: 48654.907 | Y3: 49627.163 | Z3: 50313.014 | AA3: 50685.712 | AB3: 50795.111 | AC3: 50654.853 | AD3: 50275.18 | AE3: 49650.032 | AF3: 48764.531 | AG3: 47596.998 | AH3: 46121.422 | AI3: 44303.893 | AJ3: 42097.29 | AK3: 39539.031
A4: t2val_sec_0 | B4: 3312.8737 | C4: 5053.9623 | D4: 7049.9112 | E4: 10359.555 | F4: 10469.624 | G4: 10629.623 | H4: 10805.266 | I4: 11237.466 | J4: 11683.418 | K4: 12155.894 | L4: 12644.074 | M4: 13107.215 | N4: 13540.085 | O4: 13940.243 | P4: 14309.572 | Q4: 14653.405 | R4: 14999.356 | S4: 15344.623 | T4: 15697.948 | U4: 16066.073 | V4: 16454.879 | W4: 16874.6 | X4: 17333.418 | Y4: 17839.852 | Z4: 18401.969 | AA4: 19025.451 | AB4: 19727.52 | AC4: 20521.048 | AD4: 21417.319 | AE4: 22422.572 | AF4: 23538.064 | AG4: 24764.984 | AH4: 26105.071 | AI4: 27560.115 | AJ4: 29131.616 | AK4: 29870.505
A5: t2val_sec_2 | B5: 3312.8739 | C5: 5053.9627 | D5: 7049.9117 | E5: 10359.556 | F5: 10469.624 | G5: 10629.624 | H5: 10828.996 | I5: 26830.044 | J5: 36677.137 | K5: 46805.797 | L5: 57282.489 | M5: 61988.05 | N5: 66672.93 | O5: 71332.874 | P5: 75940.167 | Q5: 80466.125 | R5: 88582.968 | S5: 96580.577 | T5: 104418.36 | U5: 112101.21 | V5: 119641.53 | W5: 127091.98 | X5: 134500.11 | Y5: 141902.89 | Z5: 149314.61 | AA5: 156720.4 | AB5: 164208.33 | AC5: 171864.59 | AD5: 179723.7 | AE5: 187710.54 | AF5: 195686.28 | AG5: 203490.21 | AH5: 210946.89 | AI5: 217817.47 | AJ5: 223755.07 | AK5: 221562.32
A6: t2val_ci_0 | B6: 3091.7816 | C6: 4713.1329 | D6: 6568.9457 | E6: 9642.9613 | F6: 9738.7494 | G6: 9883.428 | H6: 10043.006 | I6: 10440.519 | J6: 10850.488 | K6: 11284.579 | L6: 11732.441 | M6: 12155.314 | N6: 12548.444 | O6: 12909.699 | P6: 13241.025 | Q6: 13547.605 | R6: 13856.523 | S6: 14165.36 | T6: 14482.257 | U6: 14813.439 | V6: 15164.327 | W6: 15544.464 | X6: 15961.44 | Y6: 16423.147 | Z6: 16937.044 | AA6: 17508.344 | AB6: 18153.175 | AC6: 18883.485 | AD6: 19709.668 | AE6: 20637.28 | AF6: 21667.181 | AG6: 22800.146 | AH6: 24037.441 | AI6: 25380.328 | AJ6: 26829.709 | AK6: 27505.264
A7: t2val_ci_2 | B7: 3091.7818 | C7: 4713.1333 | D7: 6568.9462 | E7: 9642.962 | F7: 9738.75 | G7: 9883.4287 | H7: 10066.551 | I7: 24864.163 | J7: 33877.007 | K7: 43091.897 | L7: 52565.165 | M7: 56704.723 | N7: 60800.063 | O7: 64843.695 | P7: 68808.263 | Q7: 72665.594 | R7: 79705.975 | S7: 86568.838 | T7: 93217.63 | U7: 99655.858 | V7: 105892.78 | W7: 111973.53 | X7: 117936.61 | Y7: 123808.51 | Z7: 129593.13 | AA7: 135266 | AB7: 140897.78 | AC7: 146546.36 | AD7: 152218.49 | AE7: 157818.02 | AF7: 163187.21 | AG7: 168144.18 | AH7: 172486.64 | AI7: 175945.91 | AJ7: 178145.92 | AK7: 173277.94
A8: t2val_y_0 | B8: 0.39920408 | C8: 0.61575367 | D8: 0.87006208 | E8: 1.2997035 | F8: 1.3298811 | G8: 1.3625981 | H8: 1.3967815 | I8: 1.4650001 | J8: 1.5355483 | K8: 1.6104313 | L8: 1.6883979 | M8: 1.7637332 | N8: 1.8360975 | O8: 1.9049038 | P8: 1.970107 | Q8: 2.0321552 | R8: 2.0924774 | S8: 2.1507128 | T8: 2.2082704 | U8: 2.2663161 | V8: 2.3257382 | W8: 2.3883461 | X8: 2.4553975 | Y8: 2.5281311 | Z8: 2.6076268 | AA8: 2.694126 | AB8: 2.7903147 | AC8: 2.8978742 | AD8: 3.0182688 | AE8: 3.1522799 | AF8: 3.299989 | AG8: 3.4614278 | AH8: 3.6366093 | AI8: 3.8254297 | AJ8: 4.0276407 | AK8: 4.1278694
A9: t2val_y_2 | B9: 0.39920408 | C9: 0.61575367 | D9: 0.87006208 | E9: 1.2997035 | F9: 1.3298811 | G9: 1.3625981 | H9: 1.3972479 | I9: 3.6170006 | J9: 5.1766565 | K9: 6.9132345 | L9: 8.8375188 | M9: 9.9386935 | N9: 11.074579 | O9: 12.249664 | P9: 13.462653 | Q9: 14.711281 | R9: 16.717998 | S9: 18.824575 | T9: 21.02501 | U9: 23.323105 | V9: 25.724184 | W9: 28.247467 | X9: 30.912442 | Y9: 33.741564 | Z9: 36.756142 | AA9: 39.967317 | AB9: 43.416807 | AC9: 47.16179 | AD9: 51.256604 | AE9: 55.738132 | AF9: 60.634272 | AG9: 65.972812 | AH9: 71.78735 | AI9: 78.111948 | AJ9: 84.971398 | AK9: 89.727749
A10: t2val_mat_0 | B10: 220.6929 | C10: 340.21364 | D10: 480.09546 | E10: 715.2941 | F10: 729.54429 | G10: 744.83255 | H10: 760.86268 | I10: 795.48244 | J10: 831.395 | K10: 869.7054 | L10: 909.94422 | M10: 950.13736 | N10: 989.80468 | O10: 1028.6393 | P10: 1066.5761 | Q10: 1103.7679 | R10: 1140.7412 | S10: 1177.1119 | T10: 1213.4834 | U10: 1250.3679 | V10: 1288.2258 | W10: 1327.7467 | X10: 1369.5219 | Y10: 1414.1771 | Z10: 1462.3174 | AA10: 1514.4126 | AB10: 1571.5556 | AC10: 1634.665 | AD10: 1704.6325 | AE10: 1782.1397 | AF10: 1867.5831 | AG10: 1961.3765 | AH10: 2063.9932 | AI10: 2175.9614 | AJ10: 2297.8791 | AK10: 2361.1129
A11: t2val_mat_2 | B11: 220.6929 | C11: 340.21364 | D11: 480.09546 | E11: 715.2941 | F11: 729.54429 | G11: 744.83255 | H11: 761.04741 | I11: 1962.2633 | J11: 2794.9535 | K11: 3706.9862 | L11: 4708.4873 | M11: 5273.389 | N11: 5861.793 | O11: 6476.9287 | P11: 7118.4414 | Q11: 7785.8199 | R11: 8860.2745 | S11: 9992.9141 | T11: 11179.702 | U11: 12422.029 | V11: 13723.031 | W11: 15090.199 | X11: 16532.584 | Y11: 18060.643 | Z11: 19684.722 | AA11: 21414.43 | AB11: 23267.137 | AC11: 25271.07 | AD11: 27453.957 | AE11: 29836.788 | AF11: 32438.436 | AG11: 35280.059 | AH11: 38388.46 | AI11: 41793.449 | AJ11: 45524.181 | AK11: 48194.646

Sheet Production
A1: _date_ | B1: 42005 | C1: 42370 | D1: 42736 | E1: 43101 | F1: 43466 | G1: 43831 | H1: 44197 | I1: 44562 | J1: 44927 | K1: 45292 | L1: 45658 | M1: 46023 | N1: 46388 | O1: 46753 | P1: 47119 | Q1: 47484 | R1: 47849 | S1: 48214 | T1: 48580 | U1: 48945 | V1: 49310 | W1: 49675 | X1: 50041 | Y1: 50406 | Z1: 50771 | AA1: 51136 | AB1: 51502 | AC1: 51867 | AD1: 52232 | AE1: 52597 | AF1: 52963 | AG1: 53328 | AH1: 53693 | AI1: 54058 | AJ1: 54424 | AK1: 54789
A2: y_2 | B2: 3852771.8 | C2: 3923398 | D2: 4002771.3 | E2: 4089232.2 | F2: 4181337.9 | G2: 4278574.5 | H2: 4379701.2 | I2: 4473575.9 | J2: 4569000 | K2: 4685094.5 | L2: 4803497.2 | M2: 4908869.2 | N2: 5002799.7 | O2: 5088267.6 | P2: 5169373.6 | Q2: 5248870 | R2: 5327906.3 | S2: 5409262.4 | T2: 5495110.3 | U2: 5587034.1 | V2: 5685837.9 | W2: 5793537.7 | X2: 5911483 | Y2: 6040657.4 | Z2: 6181472.3 | AA2: 6332485.9 | AB2: 6496024.2 | AC2: 6673177.6 | AD2: 6864736.5 | AE2: 7070295.3 | AF2: 7288839.2 | AG2: 7519636.7 | AH2: 7762463.2 | AI2: 8017432 | AJ2: 8285067.4 | AK2: 8285060.7
A3: y_0 | B3: 3852771.8 | C3: 3923398 | D3: 4002771.3 | E3: 4089232.2 | F3: 4181337.9 | G3: 4278574.5 | H3: 4378592 | I3: 4482693.9 | J3: 4589335.3 | K3: 4698310.3 | L3: 4806961.4 | M3: 4903573 | N3: 4990776.7 | O3: 5070732.7 | P3: 5146094.8 | Q3: 5219434.1 | R3: 5294461.8 | S3: 5373946.4 | T3: 5459808.6 | U3: 5553160.8 | V3: 5654359.9 | W3: 5765037 | X3: 5886233.5 | Y3: 6018678.3 | Z3: 6162538 | AA3: 6316193 | AB3: 6481488.1 | AC3: 6659396 | AD3: 6850471.6 | AE3: 7054012.1 | AF3: 7268716.3 | AG3: 7493562.2 | AH3: 7728002.7 | AI3: 7971819.4 | AJ3: 8225147.9 | AK3: 8225136.2
A4: y_sagr_2 | B4: 81740.104 | C4: 83098.378 | D4: 84695.165 | E4: 86520.227 | F4: 88529.128 | G4: 90707.069 | H4: 93013.679 | I4: 95050.672 | J4: 97067.28 | K4: 99534.467 | L4: 102009.47 | M4: 104120.78 | N4: 105932.9 | O4: 107521.93 | P4: 108981.83 | Q4: 110373.88 | R4: 111757.52 | S4: 113164.16 | T4: 114645.01 | U4: 116241.41 | V4: 117974.12 | W4: 119898.54 | X4: 122048.42 | Y4: 124447.47 | Z4: 127104.24 | AA4: 129974.94 | AB4: 133088.91 | AC4: 136492.91 | AD4: 140200.22 | AE4: 144190.98 | AF4: 148426.34 | AG4: 152868.33 | AH4: 157484.5 | AI4: 162243.59 | AJ4: 167114.62 | AK4: 167114.4
A5: y_sagr_0 | B5: 81740.104 | C5: 83098.378 | D5: 84695.165 | E5: 86520.227 | F5: 88529.128 | G5: 90707.069 | H5: 92982.631 | I5: 95327.027 | J5: 97721.461 | K5: 100157.93 | L5: 102564.29 | M5: 104628.4 | N5: 106416.51 | O5: 107979.12 | P5: 109381.38 | Q5: 110689.23 | R5: 112002.13 | S5: 113396.93 | T5: 114928.09 | U5: 116627.18 | V5: 118502.69 | W5: 120598.82 | X5: 122939.57 | Y5: 125539.77 | Z5: 128399.51 | AA5: 131468.27 | AB5: 134794.42 | AC5: 138395.36 | AD5: 142274.68 | AE5: 146401.81 | AF5: 150728.05 | AG5: 155207.59 | AH5: 159801.15 | AI5: 164471 | AJ5: 169179.91 | AK5: 169179.55
A6: y_sfor_2 | B6: 6533.4139 | C6: 6484.9363 | D6: 6440.7805 | E6: 6396.1589 | F6: 6383.4013 | G6: 6389.0043 | H6: 6404.3497 | I6: 6326.8358 | J6: 6264.1712 | K6: 6237.5695 | L6: 6224.6 | M6: 6226.8742 | N6: 6231.8068 | O6: 6236.6067 | P6: 6243.1632 | Q6: 6252.8809 | R6: 6245.4174 | S6: 6238.6386 | T6: 6236.9732 | U6: 6242.4875 | V6: 6254.8592 | W6: 6277.4362 | X6: 6310.7371 | Y6: 6355.1026 | Z6: 6410.6506 | AA6: 6473.4913 | AB6: 6553.1535 | AC6: 6647.3932 | AD6: 6756.8914 | AE6: 6881.3696 | AF6: 7020.3878 | AG6: 7174.258 | AH6: 7344.1523 | AI6: 7531.8131 | AJ6: 7739.7499 | AK6: 7739.1433
A7: y_sfor_0 | B7: 6533.4139 | C7: 6484.9363 | D7: 6440.7805 | E7: 6396.1589 | F7: 6383.4013 | G7: 6389.0043 | H7: 6404.596 | I7: 6430.19 | J7: 6462.2581 | K7: 6498.7425 | L7: 6538.6238 | M7: 6568.535 | N7: 6592.0405 | O7: 6611.5467 | P7: 6629.5259 | Q7: 6648.0933 | R7: 6668.5161 | S7: 6692.9831 | T7: 6723.0678 | U7: 6759.6736 | V7: 6801.8275 | W7: 6853.0125 | X7: 6913.6319 | Y7: 6984.05 | Z7: 7064.2911 | AA7: 7149.7491 | AB7: 7246.4668 | AC7: 7355.4994 | AD7: 7477.5038 | AE7: 7612.119 | AF7: 7758.7187 | AG7: 7917.1826 | AH7: 8088.0622 | AI7: 8272.5711 | AJ7: 8472.6404 | AK7: 8471.6305
A8: y_sfoo_2 | B8: 157672.64 | C8: 160409.07 | D8: 163572.61 | E8: 167180.21 | F8: 171115.96 | G8: 175352.31 | H8: 179808 | I8: 183961.6 | J8: 188111.82 | K8: 192984.35 | L8: 197951.42 | M8: 202354.71 | N8: 206271.79 | O8: 209778.62 | P8: 212994.51 | Q8: 216010.53 | R8: 218942.97 | S8: 221851.69 | T8: 224831.75 | U8: 227964.44 | V8: 231283.82 | W8: 234908.07 | X8: 238896.37 | Y8: 243297.75 | Z8: 248136.03 | AA8: 253312.68 | AB8: 258898.19 | AC8: 264976.65 | AD8: 271577.32 | AE8: 278681.85 | AF8: 286236.16 | AG8: 294176.29 | AH8: 302440.22 | AI8: 310969.42 | AJ8: 319705.52 | AK8: 319705.46
A9: y_sfoo_0 | B9: 157672.64 | C9: 160409.07 | D9: 163572.61 | E9: 167180.21 | F9: 171115.96 | G9: 175352.31 | H9: 179745.74 | I9: 184258.43 | J9: 188862.94 | K9: 193548.6 | L9: 198217.98 | M9: 202344.14 | N9: 206004.69 | O9: 209254.14 | P9: 212182.01 | Q9: 214891.62 | R9: 217562.74 | S9: 220327.86 | T9: 223284.81 | U9: 226496.59 | V9: 229977.51 | W9: 233830.23 | X9: 238100.9 | Y9: 242824.03 | Z9: 248009.09 | AA9: 253547.86 | AB9: 259561.26 | AC9: 266079.14 | AD9: 273115.32 | AE9: 280631.05 | AF9: 288554.14 | AG9: 296810.45 | AH9: 305331.1 | AI9: 314046.82 | AJ9: 322887.99 | AK9: 322887.87
A10: y_sveh_2 | B10: 125569.22 | C10: 130054.02 | D10: 134888.1 | E10: 139652.33 | F10: 144377.28 | G10: 149034.58 | H10: 153617.79 | I10: 156481.46 | J10: 159383.1 | K10: 164123.69 | L10: 168480 | M10: 171508.88 | N10: 173637.14 | O10: 175308.04 | P10: 176985.93 | Q10: 178904.13 | R10: 180862.55 | S10: 183179.51 | T10: 185953.2 | U10: 189208.92 | V10: 192956.89 | W10: 197224.09 | X10: 202042.43 | Y10: 207419.57 | Z10: 213324.57 | AA10: 219707.78 | AB10: 226753.33 | AC10: 234335.99 | AD10: 242429.66 | AE10: 250902.13 | AF10: 259596.99 | AG10: 268404.14 | AH10: 277256.27 | AI10: 286104.99 | AJ10: 294910.08 | AK10: 294909.82
A11: y_sveh_0 | B11: 125569.22 | C11: 130054.02 | D11: 134888.1 | E11: 139652.33 | F11: 144377.28 | G11: 149034.58 | H11: 153552.3 | I11: 157977 | J11: 162389.16 | K11: 166854.74 | L11: 171112.68 | M11: 174262.4 | N11: 176794.17 | O11: 178995.56 | P11: 181130.5 | Q11: 183393.13 | R11: 186008.24 | S11: 189083.59 | T11: 192657.14 | U11: 196717.14 | V11: 201253.31 | W11: 206283.14 | X11: 211835.92 | Y11: 217912.26 | Z11: 224468.67 | AA11: 231442.65 | AB11: 238861.35 | AC11: 246755.39 | AD11: 255103.51 | AE11: 263767.09 | AF11: 272581.75 | AG11: 281436.9 | AH11: 290272.45 | AI11: 299045.8 | AJ11: 307719.07 | AK11: 307718.68
A12: y_sgla_2 | B12: 22086.068 | C12: 22481.821 | D12: 22925.057 | E12: 23401.224 | F12: 23918.547 | G12: 24478.929 | H12: 25077.581 | I12: 25542.894 | J12: 25976.308 | K12: 26495.325 | L12: 27010.798 | M12: 27470.695 | N12: 27888.785 | O12: 28284.036 | P12: 28679.157 | Q12: 29088.194 | R12: 29514.765 | S12: 29958.68 | T12: 30431.876 | U12: 30944.642 | V12: 31504.347 | W12: 32121.686 | X12: 32805.744 | Y12: 33562.133 | Z12: 34393.012 | AA12: 35293.198 | AB12: 36262.665 | AC12: 37316.495 | AD12: 38457.736 | AE12: 39683.297 | AF12: 40987.838 | AG12: 42369.084 | AH12: 43828.268 | AI12: 45367.896 | AJ12: 46993.133 | AK12: 46992.944
... A67: y_seot_0 | B67: 109.82449 | C67: 111.47273 | D67: 113.01877 | E67: 114.69243 | F67: 116.20998 | G67: 117.74585 | H67: 119.39082 | I67: 123.86909 | J67: 129.08415 | K67: 134.6601 | L67: 140.47648 | M67: 146.20079 | N67: 151.88913 | O67: 157.62308 | P67: 163.51585 | Q67: 169.69322 | R67: 176.2291 | S67: 183.29492 | T67: 191.05859 | U67: 199.67423 | V67: 209.27873 | W67: 220.07355 | X67: 232.25186 | Y67: 246.02083 | Z67: 261.60209 | AA67: 279.17341 | AB67: 299.11034 | AC67: 321.80284 | AD67: 347.68712 | AE67: 377.21248 | AF67: 410.88689 | AG67: 449.3538 | AH67: 493.46033 | AI67: 544.32518 | AJ67: 603.44 | AK67: 603.43889

Sheet Capital
A1: _date_ | B1: 42005 | C1: 42370 | D1: 42736 | E1: 43101 | F1: 43466 | G1: 43831 | H1: 44197 | I1: 44562 | J1: 44927 | K1: 45292 | L1: 45658 | M1: 46023 | N1: 46388 | O1: 46753 | P1: 47119 | Q1: 47484 | R1: 47849 | S1: 48214 | T1: 48580 | U1: 48945 | V1: 49310 | W1: 49675 | X1: 50041 | Y1: 50406 | Z1: 50771 | AA1: 51136 | AB1: 51502 | AC1: 51867 | AD1: 52232 | AE1: 52597 | AF1: 52963 | AG1: 53328 | AH1: 53693 | AI1: 54058 | AJ1: 54424 | AK1: 54789
A2: f_k_2 | B2: 5223771.6 | C2: 5286510.5 | D2: 5354071.6 | E2: 5427422.4 | F2: 5507273.2 | G2: 5594113.3 | H2: 5688233.9 | I2: 5788410.3 | J2: 5894390.5 | K2: 6007793.7 | L2: 6129318.9 | M2: 6258283.6 | N2: 6393644.4 | O2: 6534490.6 | P2: 6680291.4 | Q2: 6830849.2 | R2: 6986041.6 | S2: 7146040 | T2: 7311280 | U2: 7482379.1 | V2: 7660031.1 | W2: 7845064.2 | X2: 8038416.7 | Y2: 8241108.2 | Z2: 8454172.4 | AA2: 8678463.6 | AB2: 8914907.3 | AC2: 9164467 | AD2: 9428188.1 | AE2: 9707131.7 | AF2: 10002302 | AG2: 10314638 | AH2: 10645051 | AI2: 10994503 | AJ2: 11364071 | AK2: 11722087
A3: f_k_0 | B3: 5223771.6 | C3: 5286510.5 | D3: 5354071.6 | E3: 5427422.4 | F3: 5507273.2 | G3: 5594113.3 | H3: 5688109.7 | I3: 5789398.7 | J3: 5898078.4 | K3: 6014258.7 | L3: 6137864.2 | M3: 6267848.5 | N3: 6403108.1 | O3: 6542737.5 | P3: 6686121.6 | Q3: 6832936.4 | R3: 6983295.9 | S3: 7137649.9 | T3: 7296651.9 | U3: 7461039.3 | V3: 7631530.7 | W3: 7808910.2 | X3: 7994023.4 | Y3: 8187750.6 | Z3: 8390947 | AA3: 8604267.2 | AB3: 8828417.5 | AC3: 9064206.9 | AD3: 9312540.5 | AE3: 9574332.7 | AF3: 9850433.4 | AG3: 10141636 | AH3: 10448729 | AI3: 10772542 | AJ3: 11113998 | AK3: 11444421
A4: f_k_sagr_2 | B4: 47217.163 | C4: 47790.485 | D4: 48409.369 | E4: 49087.588 | F4: 49831.406 | G4: 50645.318 | H4: 51532 | I4: 52496.763 | J4: 53542.025 | K4: 54687.777 | L4: 55941.702 | M4: 57287.166 | N4: 58705.143 | O4: 60179.387 | P4: 61698.479 | Q4: 63254.989 | R4: 64847.858 | S4: 66477.569 | T4: 68146.567 | U4: 69858.767 | V4: 71618.278 | W4: 73430.625 | X4: 75302.213 | Y4: 77239.831 | Z4: 79249.676 | AA4: 81334.304 | AB4: 83495.062 | AC4: 85733.973 | AD4: 88053.584 | AE4: 90455.575 | AF4: 92939.395 | AG4: 95501.68 | AH4: 98136.346 | AI4: 100834.97 | AJ4: 103586.88 | AK4: 106182.16
A5: f_k_sagr_0 | B5: 47217.163 | C5: 47790.485 | D5: 48409.369 | E5: 49087.588 | F5: 49831.406 | G5: 50645.318 | H5: 51531.69 | I5: 52491.819 | J5: 53526.245 | K5: 54635.199 | L5: 55816.411 | M5: 57055.674 | N5: 58338.179 | O5: 59651.419 | P5: 60986.229 | Q5: 62336.917 | R5: 63701.541 | S5: 65081.964 | T5: 66482.742 | U5: 67909.873 | V5: 69369.408 | W5: 70868.751 | X5: 72416.206 | Y5: 74020.423 | Z5: 75689.533 | AA5: 77428.566 | AB5: 79243.296 | AC5: 81140.34 | AD5: 83126.665 | AE5: 85208.288 | AF5: 87389.181 | AG5: 89671.122 | AH5: 92053.967 | AI5: 94535.81 | AJ5: 97113.042 | AK5: 99584.041
A6: f_k_sfor_2 | B6: 1844.804 | C6: 1864.2896 | D6: 1881.613 | E6: 1896.7243 | F6: 1910.1528 | G6: 1922.3856 | H6: 1933.7374 | I6: 1943.0138 | J6: 1950.2762 | K6: 1956.3681 | L6: 1961.9148 | M6: 1967.3853 | N6: 1973.038 | O6: 1979.0142 | P6: 1985.4453 | Q6: 1992.4706 | R6: 1999.8914 | S6: 2007.6917 | T6: 2015.9799 | U6: 2024.9144 | V6: 2034.6314 | W6: 2045.2965 | X6: 2057.0698 | Y6: 2070.0967 | Z6: 2084.4989 | AA6: 2100.2878 | AB6: 2117.6031 | AC6: 2136.5612 | AD6: 2157.2855 | AE6: 2179.9025 | AF6: 2204.5368 | AG6: 2231.3167 | AH6: 2260.3916 | AI6: 2291.9528 | AJ6: 2326.2494 | AK6: 2359.3275
A7: f_k_sfor_0 | B7: 1844.804 | C7: 1864.2896 | D7: 1881.613 | E7: 1896.7243 | F7: 1910.1528 | G7: 1922.3856 | H7: 1933.7401 | I7: 1944.5075 | J7: 1954.9185 | K7: 1965.1572 | L7: 1975.3856 | M7: 1985.545 | N7: 1995.5926 | O7: 2005.543 | P7: 2015.4646 | Q7: 2025.4642 | R7: 2035.6649 | S7: 2046.2057 | T7: 2057.2286 | U7: 2068.8643 | V7: 2081.1951 | W7: 2094.3355 | X7: 2108.4023 | Y7: 2123.5054 | Z7: 2139.7387 | AA7: 2157.0899 | AB7: 2175.6235 | AC7: 2195.4515 | AD7: 2216.7171 | AE7: 2239.5788 | AF7: 2264.2011 | AG7: 2290.7608 | AH7: 2319.4597 | AI7: 2350.5386 | AJ7: 2384.2907 | AK7: 2416.898
A8: f_k_sfoo_2 | B8: 74526.379 | C8: 75429.933 | D8: 76405.392 | E8: 77473.102 | F8: 78643.982 | G8: 79925.634 | H8: 81321.538 | I8: 82833.476 | J8: 84463.754 | K8: 86237.022 | L8: 88164.629 | M8: 90228.69 | N8: 92406.886 | O8: 94678.333 | P8: 97026.399 | Q8: 99438.476 | R8: 101909.31 | S8: 104436.42 | T8: 107020.58 | U8: 109665.22 | V8: 112374.3 | W8: 115154.71 | X8: 118015.09 | Y8: 120965.31 | Z8: 124015.23 | AA8: 127169.5 | AB8: 130431.99 | AC8: 133808.2 | AD8: 137305.13 | AE8: 140929.8 | AF8: 144687.3 | AG8: 148579.51 | AH8: 152604.67 | AI8: 156757.83 | AJ8: 161030.75 | AK8: 165089.01
A9: f_k_sfoo_0 | B9: 74526.379 | C9: 75429.933 | D9: 76405.392 | E9: 77473.102 | F9: 78643.982 | G9: 79925.634 | H9: 81323.526 | I9: 82840.416 | J9: 84477.726 | K9: 86236.392 | L9: 88114.619 | M9: 90094.376 | N9: 92155.768 | O9: 94280.662 | P9: 96454.292 | Q9: 98665.877 | R9: 100908.11 | S9: 103180.11 | T9: 105485.25 | U9: 107829.37 | V9: 110218.41 | W9: 112661.11 | X9: 115167.95 | Y9: 117750.38 | Z9: 120419.63 | AA9: 123182.09 | AB9: 126046.45 | AC9: 129023.11 | AD9: 132123.58 | AE9: 135358.77 | AF9: 138737.53 | AG9: 142266.06 | AH9: 145948.05 | AI9: 149784.62 | AJ9: 153774.3 | AK9: 157604.7
A10: f_k_sveh_2 | B10: 401529.23 | C10: 406775.67 | D10: 412954.31 | E10: 420105.65 | F10: 428210.08 | G10: 437220.68 | H10: 447079.64 | I10: 457379.8 | J10: 467992.12 | K10: 479251.54 | L10: 491171.66 | M10: 503464.72 | N10: 515838.69 | O10: 528100.39 | P10: 540190.63 | Q10: 552143.14 | R10: 563974.09 | S10: 575762.99 | T10: 587629.01 | U10: 599705.46 | V10: 612127.78 | W10: 625033.46 | X10: 638563.31 | Y10: 652856.82 | Z10: 668041.87 | AA10: 684227.06 | AB10: 701551.02 | AC10: 720129.59 | AD10: 740062.41 | AE10: 761412.4 | AF10: 784193.78 | AG10: 808378.76 | AH10: 833909.84 | AI10: 860709.17 | AJ10: 888683.53 | AK10: 915697.54
A11: f_k_sveh_0 | B11: 401529.23 | C11: 406775.67 | D11: 412954.31 | E11: 420105.65 | F11: 428210.08 | G11: 437220.68 | H11: 447069.64 | I11: 457692.18 | J11: 469043.46 | K11: 481100.03 | L11: 493791.87 | M11: 506846.74 | N11: 520035.17 | O11: 533208.61 | P11: 546302.89 | Q11: 559322.42 | R11: 572340.05 | S11: 585471.83 | T11: 598851 | U11: 612608.61 | V11: 626867.69 | W11: 641748.54 | X11: 657373.13 | Y11: 673860.11 | Z11: 691313.3 | AA11: 709813.56 | AB11: 729437.75 | AC11: 750266.26 | AD11: 772373.95 | AE11: 795801.6 | AF11: 820541.4 | AG11: 846545.5 | AH11: 873741.03 | AI11: 902039.39 | AJ11: 931340.54 | AK11: 959544.64
A12: f_k_sgla_2 | B12: 16084.261 | C12: 16281 | D12: 16494.941 | E12: 16729.633 | F12: 16986.238 | G12: 17265.882 | H12: 17569.401 | I12: 17897.046 | J12: 18248.064 | K12: 18627.534 | L12: 19037.782 | M12: 19475.164 | N12: 19936.212 | O12: 20418.703 | P12: 20922.039 | Q12: 21446.852 | R12: 21995.854 | S12: 22571.518 | T12: 23176.625 | U12: 23814.302 | V12: 24487.798 | W12: 25200.647 | X12: 25956.652 | Y12: 26759.742 | Z12: 27613.67 | AA12: 28521.311 | AB12: 29484.721 | AC12: 30506.219 | AD12: 31588.373 | AE12: 32733.717 | AF12: 33944.497 | AG12: 35222.683 | AH12: 36570.199 | AI12: 37989.239 | AJ12: 39482.504 | AK12: 40940.948
... A67: f_k_seot_0 | B67: 65.175815 | C67: 65.949181 | D67: 66.745822 | E67: 67.569103 | F67: 68.413249 | G67: 69.276228 | H67: 70.160712 | I67: 71.173093 | J67: 72.37154 | K67: 73.783172 | L67: 75.420477 | M67: 77.2786 | N67: 79.349126 | O67: 81.625644 | P67: 84.106695 | Q67: 86.797154 | R67: 89.706612 | S67: 92.852631 | T67: 96.261682 | U67: 99.968849 | V67: 104.017 | W67: 108.45914 | X67: 113.35886 | Y67: 118.79106 | Z67: 124.8429 | AA67: 131.61226 | AB67: 139.21569 | AC67: 147.79196 | AD67: 157.50539 | AE67: 168.54778 | AF67: 181.14199 | AG67: 195.54951 | AH67: 212.08275 | AI67: 231.12255 | AJ67: 253.14272 | AK67: 275.38153

Sheet Results
A1: NB : on crée ici une liste : - globale, qui fusionne les sorties des reportings 1, 2 et 3 - "rationalisée" : suppression des doublons, et regroupements par thématique On continue par la suite à avoir 2 Excels de reporting (un "energie", fusion des reportings 1 et 2), et un "économie" (reporting 3)), dans lesquels on copiera cet onglet "results" (généré automatiquement par EViews). --> puis voir à la fin si on peut pas importer les graphs et tableaux dans l'excel automatiquement généré (éviterait les copiés collés, mais à voir si ça prend trop de temps, et si c'est pas trop gros comme excel)
A2: Nom du bloc de variables utilisé dans le code | B2: Sous-bloc de variables pour plus de lisibilité dans le Excel | E2: Year | F2: =date!B3 -> 2015 | G2: =date!C3 -> 2016 | H2: =date!D3 -> 2017 | I2: =date!E3 -> 2018 | J2: =date!F3 -> 2019 | K2: =date!G3 -> 2020 | L2: =date!H3 -> 2021 | M2: =date!I3 -> 2022 | ... AO2: =date!AK3 -> 2050
A3: HYBRID | B3: AUTOMOBILES (thousands) | C3: TOTAL STOCK SHOCK | E3: AUTO_2 | F3: =VLOOKUP($E3,Hybrid!$1:$1048576,MATCH(DATE(F$2,1,1),Hybrid!$A$1:$LI$1),FALSE) -> 32317.941 | G3: =VLOOKUP($E3,Hybrid!$1:$1048576,MATCH(DATE(G$2,1,1),Hybrid!$A$1:$LI$1),FALSE) -> 31918.631 | H3: =VLOOKUP($E3,Hybrid!$1:$1048576,MATCH(DATE(H$2,1,1),Hybrid!$A$1:$LI$1),FALSE) -> 31759.311 | I3: =VLOOKUP($E3,Hybrid!$1:$1048576,MATCH(DATE(I$2,1,1),Hybrid!$A$1:$LI$1),FALSE) -> 31761.553 | J3: =VLOOKUP($E3,Hybrid!$1:$1048576,MATCH(DATE(J$2,1,1),Hybrid!$A$1:$LI$1),FALSE) -> 31899.124 | K3: =VLOOKUP($E3,Hybrid!$1:$1048576,MATCH(DATE(K$2,1,1),Hybrid!$A$1:$LI$1),FALSE) -> 32133.592 | L3: =VLOOKUP($E3,Hybrid!$1:$1048576,MATCH(DATE(L$2,1,1),Hybrid!$A$1:$LI$1),FALSE) -> 32430.086 | M3: =VLOOKUP($E3,Hybrid!$1:$1048576,MATCH(DATE(M$2,1,1),Hybrid!$A$1:$LI$1),FALSE) -> 32666.633 | ... AO3: =VLOOKUP($E3,Hybrid!$1:$1048576,MATCH(DATE(AO$2,1,1),Hybrid!$A$1:$LI$1),FALSE) -> 42732.091
C4: OIL | E4: AUTO_cfut_2 | F4: =VLOOKUP($E4,Hybrid!$1:$1048576,MATCH(DATE(F$2,1,1),Hybrid!$A$1:$LI$1),FALSE) -> 32271.24 | G4: =VLOOKUP($E4,Hybrid!$1:$1048576,MATCH(DATE(G$2,1,1),Hybrid!$A$1:$LI$1),FALSE) -> 31853.75 | H4: =VLOOKUP($E4,Hybrid!$1:$1048576,MATCH(DATE(H$2,1,1),Hybrid!$A$1:$LI$1),FALSE) -> 31674.362 | I4: =VLOOKUP($E4,Hybrid!$1:$1048576,MATCH(DATE(I$2,1,1),Hybrid!$A$1:$LI$1),FALSE) -> 31654.909 | J4: =VLOOKUP($E4,Hybrid!$1:$1048576,MATCH(DATE(J$2,1,1),Hybrid!$A$1:$LI$1),FALSE) -> 31769.037 | K4: =VLOOKUP($E4,Hybrid!$1:$1048576,MATCH(DATE(K$2,1,1),Hybrid!$A$1:$LI$1),FALSE) -> 31978.673 | L4: =VLOOKUP($E4,Hybrid!$1:$1048576,MATCH(DATE(L$2,1,1),Hybrid!$A$1:$LI$1),FALSE) -> 32249.27 | M4: =VLOOKUP($E4,Hybrid!$1:$1048576,MATCH(DATE(M$2,1,1),Hybrid!$A$1:$LI$1),FALSE) -> 32459.098 | ... AO4: =VLOOKUP($E4,Hybrid!$1:$1048576,MATCH(DATE(AO$2,1,1),Hybrid!$A$1:$LI$1),FALSE) -> 35009.221
D5: class A | E5: AUTO_ca_cfut_2 | F5: =VLOOKUP($E5,Hybrid!$1:$1048576,MATCH(DATE(F$2,1,1),Hybrid!$A$1:$LI$1),FALSE) -> 7095.7005 | G5: =VLOOKUP($E5,Hybrid!$1:$1048576,MATCH(DATE(G$2,1,1),Hybrid!$A$1:$LI$1),FALSE) -> 7138.9134 | H5: =VLOOKUP($E5,Hybrid!$1:$1048576,MATCH(DATE(H$2,1,1),Hybrid!$A$1:$LI$1),FALSE) -> 7241.8937 | I5: =VLOOKUP($E5,Hybrid!$1:$1048576,MATCH(DATE(I$2,1,1),Hybrid!$A$1:$LI$1),FALSE) -> 7384.5407 | J5: =VLOOKUP($E5,Hybrid!$1:$1048576,MATCH(DATE(J$2,1,1),Hybrid!$A$1:$LI$1),FALSE) -> 7560.8902 | K5: =VLOOKUP($E5,Hybrid!$1:$1048576,MATCH(DATE(K$2,1,1),Hybrid!$A$1:$LI$1),FALSE) -> 7760.7036 | L5: =VLOOKUP($E5,Hybrid!$1:$1048576,MATCH(DATE(L$2,1,1),Hybrid!$A$1:$LI$1),FALSE) -> 7974.6489 | M5: =VLOOKUP($E5,Hybrid!$1:$1048576,MATCH(DATE(M$2,1,1),Hybrid!$A$1:$LI$1),FALSE) -> 8168.5328 | ... AO5: =VLOOKUP($E5,Hybrid!$1:$1048576,MATCH(DATE(AO$2,1,1),Hybrid!$A$1:$LI$1),FALSE) -> 11491.393
D6: class B | E6: AUTO_cb_cfut_2 | F6: =VLOOKUP($E6,Hybrid!$1:$1048576,MATCH(DATE(F$2,1,1),Hybrid!$A$1:$LI$1),FALSE) -> 8251.2564 | G6: =VLOOKUP($E6,Hybrid!$1:$1048576,MATCH(DATE(G$2,1,1),Hybrid!$A$1:$LI$1),FALSE) -> 8180.0639 | H6: =VLOOKUP($E6,Hybrid!$1:$1048576,MATCH(DATE(H$2,1,1),Hybrid!$A$1:$LI$1),FALSE) -> 8173.9007 | I6: =VLOOKUP($E6,Hybrid!$1:$1048576,MATCH(DATE(I$2,1,1),Hybrid!$A$1:$LI$1),FALSE) -> 8212.4993 | J6: =VLOOKUP($E6,Hybrid!$1:$1048576,MATCH(DATE(J$2,1,1),Hybrid!$A$1:$LI$1),FALSE) -> 8289.337 | K6: =VLOOKUP($E6,Hybrid!$1:$1048576,MATCH(DATE(K$2,1,1),Hybrid!$A$1:$LI$1),FALSE) -> 8394.1234 | L6: =VLOOKUP($E6,Hybrid!$1:$1048576,MATCH(DATE(L$2,1,1),Hybrid!$A$1:$LI$1),FALSE) -> 8517.4157 | M6: =VLOOKUP($E6,Hybrid!$1:$1048576,MATCH(DATE(M$2,1,1),Hybrid!$A$1:$LI$1),FALSE) -> 8625.5607 | ... AO6: =VLOOKUP($E6,Hybrid!$1:$1048576,MATCH(DATE(AO$2,1,1),Hybrid!$A$1:$LI$1),FALSE) -> 10545.568
D7: class C | E7: AUTO_cc_cfut_2 | F7: =VLOOKUP($E7,Hybrid!$1:$1048576,MATCH(DATE(F$2,1,1),Hybrid!$A$1:$LI$1),FALSE) -> 6777.6025 | G7: =VLOOKUP($E7,Hybrid!$1:$1048576,MATCH(DATE(G$2,1,1),Hybrid!$A$1:$LI$1),FALSE) -> 6644.8772 | H7: =VLOOKUP($E7,Hybrid!$1:$1048576,MATCH(DATE(H$2,1,1),Hybrid!$A$1:$LI$1),FALSE) -> 6562.8912 | I7: =VLOOKUP($E7,Hybrid!$1:$1048576,MATCH(DATE(I$2,1,1),Hybrid!$A$1:$LI$1),FALSE) -> 6516.918 | J7: =VLOOKUP($E7,Hybrid!$1:$1048576,MATCH(DATE(J$2,1,1),Hybrid!$A$1:$LI$1),FALSE) -> 6501.8685 | K7: =VLOOKUP($E7,Hybrid!$1:$1048576,MATCH(DATE(K$2,1,1),Hybrid!$A$1:$LI$1),FALSE) -> 6510.2772 | L7: =VLOOKUP($E7,Hybrid!$1:$1048576,MATCH(DATE(L$2,1,1),Hybrid!$A$1:$LI$1),FALSE) -> 6535.2531 | M7: =VLOOKUP($E7,Hybrid!$1:$1048576,MATCH(DATE(M$2,1,1),Hybrid!$A$1:$LI$1),FALSE) -> 6552.9237 | ... AO7: =VLOOKUP($E7,Hybrid!$1:$1048576,MATCH(DATE(AO$2,1,1),Hybrid!$A$1:$LI$1),FALSE) -> 6882.4965
D8: class D | E8: AUTO_cd_cfut_2 | F8: =VLOOKUP($E8,Hybrid!$1:$1048576,MATCH(DATE(F$2,1,1),Hybrid!$A$1:$LI$1),FALSE) -> 4159.6639 | G8: =VLOOKUP($E8,Hybrid!$1:$1048576,MATCH(DATE(G$2,1,1),Hybrid!$A$1:$LI$1),FALSE) -> 4053.7616 | H8: =VLOOKUP($E8,Hybrid!$1:$1048576,MATCH(DATE(H$2,1,1),Hybrid!$A$1:$LI$1),FALSE) -> 3976.8722 | I8: =VLOOKUP($E8,Hybrid!$1:$1048576,MATCH(DATE(I$2,1,1),Hybrid!$A$1:$LI$1),FALSE) -> 3920.2702 | J8: =VLOOKUP($E8,Hybrid!$1:$1048576,MATCH(DATE(J$2,1,1),Hybrid!$A$1:$LI$1),FALSE) -> 3880.7049 | K8: =VLOOKUP($E8,Hybrid!$1:$1048576,MATCH(DATE(K$2,1,1),Hybrid!$A$1:$LI$1),FALSE) -> 3853.8714 | L8: =VLOOKUP($E8,Hybrid!$1:$1048576,MATCH(DATE(L$2,1,1),Hybrid!$A$1:$LI$1),FALSE) -> 3835.8285 | M8: =VLOOKUP($E8,Hybrid!$1:$1048576,MATCH(DATE(M$2,1,1),Hybrid!$A$1:$LI$1),FALSE) -> 3813.4535 | ... AO8: =VLOOKUP($E8,Hybrid!$1:$1048576,MATCH(DATE(AO$2,1,1),Hybrid!$A$1:$LI$1),FALSE) -> 3412.0546
D9: class E | E9: AUTO_ce_cfut_2 | F9: =VLOOKUP($E9,Hybrid!$1:$1048576,MATCH(DATE(F$2,1,1),Hybrid!$A$1:$LI$1),FALSE) -> 2503.7292 | G9: =VLOOKUP($E9,Hybrid!$1:$1048576,MATCH(DATE(G$2,1,1),Hybrid!$A$1:$LI$1),FALSE) -> 2442.3141 | H9: =VLOOKUP($E9,Hybrid!$1:$1048576,MATCH(DATE(H$2,1,1),Hybrid!$A$1:$LI$1),FALSE) -> 2397.5371 | I9: =VLOOKUP($E9,Hybrid!$1:$1048576,MATCH(DATE(I$2,1,1),Hybrid!$A$1:$LI$1),FALSE) -> 2363.8546 | J9: =VLOOKUP($E9,Hybrid!$1:$1048576,MATCH(DATE(J$2,1,1),Hybrid!$A$1:$LI$1),FALSE) -> 2339.1637 | K9: =VLOOKUP($E9,Hybrid!$1:$1048576,MATCH(DATE(K$2,1,1),Hybrid!$A$1:$LI$1),FALSE) -> 2320.8652 | L9: =VLOOKUP($E9,Hybrid!$1:$1048576,MATCH(DATE(L$2,1,1),Hybrid!$A$1:$LI$1),FALSE) -> 2306.5983 | M9: =VLOOKUP($E9,Hybrid!$1:$1048576,MATCH(DATE(M$2,1,1),Hybrid!$A$1:$LI$1),FALSE) -> 2288.4363 | ... AO9: =VLOOKUP($E9,Hybrid!$1:$1048576,MATCH(DATE(AO$2,1,1),Hybrid!$A$1:$LI$1),FALSE) -> 1677.9123
D10: class F | E10: AUTO_cf_cfut_2 | F10: =VLOOKUP($E10,Hybrid!$1:$1048576,MATCH(DATE(F$2,1,1),Hybrid!$A$1:$LI$1),FALSE) -> 1243.6668 | G10: =VLOOKUP($E10,Hybrid!$1:$1048576,MATCH(DATE(G$2,1,1),Hybrid!$A$1:$LI$1),FALSE) -> 1210.5103 | H10: =VLOOKUP($E10,Hybrid!$1:$1048576,MATCH(DATE(H$2,1,1),Hybrid!$A$1:$LI$1),FALSE) -> 1184.1996 | I10: =VLOOKUP($E10,Hybrid!$1:$1048576,MATCH(DATE(I$2,1,1),Hybrid!$A$1:$LI$1),FALSE) -> 1161.7685 | J10: =VLOOKUP($E10,Hybrid!$1:$1048576,MATCH(DATE(J$2,1,1),Hybrid!$A$1:$LI$1),FALSE) -> 1142.0394 | K10: =VLOOKUP($E10,Hybrid!$1:$1048576,MATCH(DATE(K$2,1,1),Hybrid!$A$1:$LI$1),FALSE) -> 1123.8073 | L10: =VLOOKUP($E10,Hybrid!$1:$1048576,MATCH(DATE(L$2,1,1),Hybrid!$A$1:$LI$1),FALSE) -> 1106.0439 | M10: =VLOOKUP($E10,Hybrid!$1:$1048576,MATCH(DATE(M$2,1,1),Hybrid!$A$1:$LI$1),FALSE) -> 1085.3372 | ... AO10: =VLOOKUP($E10,Hybrid!$1:$1048576,MATCH(DATE(AO$2,1,1),Hybrid!$A$1:$LI$1),FALSE) -> 457.31925
D11: class G | E11: AUTO_cg_cfut_2 | F11: =VLOOKUP($E11,Hybrid!$1:$1048576,MATCH(DATE(F$2,1,1),Hybrid!$A$1:$LI$1),FALSE) -> 2239.6206 | G11: =VLOOKUP($E11,Hybrid!$1:$1048576,MATCH(DATE(G$2,1,1),Hybrid!$A$1:$LI$1),FALSE) -> 2183.3099 | H11: =VLOOKUP($E11,Hybrid!$1:$1048576,MATCH(DATE(H$2,1,1),Hybrid!$A$1:$LI$1),FALSE) -> 2137.0676 | I11: =VLOOKUP($E11,Hybrid!$1:$1048576,MATCH(DATE(I$2,1,1),Hybrid!$A$1:$LI$1),FALSE) -> 2095.0577 | J11: =VLOOKUP($E11,Hybrid!$1:$1048576,MATCH(DATE(J$2,1,1),Hybrid!$A$1:$LI$1),FALSE) -> 2055.0332 | K11: =VLOOKUP($E11,Hybrid!$1:$1048576,MATCH(DATE(K$2,1,1),Hybrid!$A$1:$LI$1),FALSE) -> 2015.0245 | L11: =VLOOKUP($E11,Hybrid!$1:$1048576,MATCH(DATE(L$2,1,1),Hybrid!$A$1:$LI$1),FALSE) -> 1973.4819 | M11: =VLOOKUP($E11,Hybrid!$1:$1048576,MATCH(DATE(M$2,1,1),Hybrid!$A$1:$LI$1),FALSE) -> 1924.8534 | ... AO11: =VLOOKUP($E11,Hybrid!$1:$1048576,MATCH(DATE(AO$2,1,1),Hybrid!$A$1:$LI$1),FALSE) -> 542.47741
C12: ELEC | E12: AUTO_cele_2 | F12: =VLOOKUP($E12,Hybrid!$1:$1048576,MATCH(DATE(F$2,1,1),Hybrid!$A$1:$LI$1),FALSE) -> 44.765 | G12: =VLOOKUP($E12,Hybrid!$1:$1048576,MATCH(DATE(G$2,1,1),Hybrid!$A$1:$LI$1),FALSE) -> 62.889352 | H12: =VLOOKUP($E12,Hybrid!$1:$1048576,MATCH(DATE(H$2,1,1),Hybrid!$A$1:$LI$1),FALSE) -> 82.889294 | I12: =VLOOKUP($E12,Hybrid!$1:$1048576,MATCH(DATE(I$2,1,1),Hybrid!$A$1:$LI$1),FALSE) -> 104.50723 | J12: =VLOOKUP($E12,Hybrid!$1:$1048576,MATCH(DATE(J$2,1,1),Hybrid!$A$1:$LI$1),FALSE) -> 127.86793 | K12: =VLOOKUP($E12,Hybrid!$1:$1048576,MATCH(DATE(K$2,1,1),Hybrid!$A$1:$LI$1),FALSE) -> 152.61341 | L12: =VLOOKUP($E12,Hybrid!$1:$1048576,MATCH(DATE(L$2,1,1),Hybrid!$A$1:$LI$1),FALSE) -> 178.42191 | M12: =VLOOKUP($E12,Hybrid!$1:$1048576,MATCH(DATE(M$2,1,1),Hybrid!$A$1:$LI$1),FALSE) -> 205.06274 | ... AO12: =VLOOKUP($E12,Hybrid!$1:$1048576,MATCH(DATE(AO$2,1,1),Hybrid!$A$1:$LI$1),FALSE) -> 8081.4317
D13: class A | E13: AUTO_ca_cele_2 | F13: =VLOOKUP($E13,Hybrid!$1:$1048576,MATCH(DATE(F$2,1,1),Hybrid!$A$1:$LI$1),FALSE) -> 9.8427899 | G13: =VLOOKUP($E13,Hybrid!$1:$1048576,MATCH(DATE(G$2,1,1),Hybrid!$A$1:$LI$1),FALSE) -> 15.123232 | H13: =VLOOKUP($E13,Hybrid!$1:$1048576,MATCH(DATE(H$2,1,1),Hybrid!$A$1:$LI$1),FALSE) -> 20.991591 | I13: =VLOOKUP($E13,Hybrid!$1:$1048576,MATCH(DATE(I$2,1,1),Hybrid!$A$1:$LI$1),FALSE) -> 27.398546 | J13: =VLOOKUP($E13,Hybrid!$1:$1048576,MATCH(DATE(J$2,1,1),Hybrid!$A$1:$LI$1),FALSE) -> 34.399336 | K13: =VLOOKUP($E13,Hybrid!$1:$1048576,MATCH(DATE(K$2,1,1),Hybrid!$A$1:$LI$1),FALSE) -> 41.894067 | L13: =VLOOKUP($E13,Hybrid!$1:$1048576,MATCH(DATE(L$2,1,1),Hybrid!$A$1:$LI$1),FALSE) -> 49.793243 | M13: =VLOOKUP($E13,Hybrid!$1:$1048576,MATCH(DATE(M$2,1,1),Hybrid!$A$1:$LI$1),FALSE) -> 58.068705 | ... AO13: =VLOOKUP($E13,Hybrid!$1:$1048576,MATCH(DATE(AO$2,1,1),Hybrid!$A$1:$LI$1),FALSE) -> 2886.1679
D14: class B | E14: AUTO_cb_cele_2 | F14: =VLOOKUP($E14,Hybrid!$1:$1048576,MATCH(DATE(F$2,1,1),Hybrid!$A$1:$LI$1),FALSE) -> 11.445717 | G14: =VLOOKUP($E14,Hybrid!$1:$1048576,MATCH(DATE(G$2,1,1),Hybrid!$A$1:$LI$1),FALSE) -> 16.441946 | H14: =VLOOKUP($E14,Hybrid!$1:$1048576,MATCH(DATE(H$2,1,1),Hybrid!$A$1:$LI$1),FALSE) -> 22.010704 | I14: =VLOOKUP($E14,Hybrid!$1:$1048576,MATCH(DATE(I$2,1,1),Hybrid!$A$1:$LI$1),FALSE) -> 28.107951 | J14: =VLOOKUP($E14,Hybrid!$1:$1048576,MATCH(DATE(J$2,1,1),Hybrid!$A$1:$LI$1),FALSE) -> 34.789079 | K14: =VLOOKUP($E14,Hybrid!$1:$1048576,MATCH(DATE(K$2,1,1),Hybrid!$A$1:$LI$1),FALSE) -> 41.955856 | L14: =VLOOKUP($E14,Hybrid!$1:$1048576,MATCH(DATE(L$2,1,1),Hybrid!$A$1:$LI$1),FALSE) -> 49.51981 | M14: =VLOOKUP($E14,Hybrid!$1:$1048576,MATCH(DATE(M$2,1,1),Hybrid!$A$1:$LI$1),FALSE) -> 57.461117 | ... AO14: =VLOOKUP($E14,Hybrid!$1:$1048576,MATCH(DATE(AO$2,1,1),Hybrid!$A$1:$LI$1),FALSE) -> 2706.1264
D15: class C | E15: AUTO_cc_cele_2 | F15: =VLOOKUP($E15,Hybrid!$1:$1048576,MATCH(DATE(F$2,1,1),Hybrid!$A$1:$LI$1),FALSE) -> 9.4015406 | G15: =VLOOKUP($E15,Hybrid!$1:$1048576,MATCH(DATE(G$2,1,1),Hybrid!$A$1:$LI$1),FALSE) -> 12.804718 | H15: =VLOOKUP($E15,Hybrid!$1:$1048576,MATCH(DATE(H$2,1,1),Hybrid!$A$1:$LI$1),FALSE) -> 16.609264 | I15: =VLOOKUP($E15,Hybrid!$1:$1048576,MATCH(DATE(I$2,1,1),Hybrid!$A$1:$LI$1),FALSE) -> 20.786573 | J15: =VLOOKUP($E15,Hybrid!$1:$1048576,MATCH(DATE(J$2,1,1),Hybrid!$A$1:$LI$1),FALSE) -> 25.376235 | K15: =VLOOKUP($E15,Hybrid!$1:$1048576,MATCH(DATE(K$2,1,1),Hybrid!$A$1:$LI$1),FALSE) -> 30.30866 | L15: =VLOOKUP($E15,Hybrid!$1:$1048576,MATCH(DATE(L$2,1,1),Hybrid!$A$1:$LI$1),FALSE) -> 35.520855 | M15: =VLOOKUP($E15,Hybrid!$1:$1048576,MATCH(DATE(M$2,1,1),Hybrid!$A$1:$LI$1),FALSE) -> 41.002841 | ... AO15: =VLOOKUP($E15,Hybrid!$1:$1048576,MATCH(DATE(AO$2,1,1),Hybrid!$A$1:$LI$1),FALSE) -> 1821.9223
D16: class D | E16: AUTO_cd_cele_2 | F16: =VLOOKUP($E16,Hybrid!$1:$1048576,MATCH(DATE(F$2,1,1),Hybrid!$A$1:$LI$1),FALSE) -> 5.7700713 | G16: =VLOOKUP($E16,Hybrid!$1:$1048576,MATCH(DATE(G$2,1,1),Hybrid!$A$1:$LI$1),FALSE) -> 7.5870606 | H16: =VLOOKUP($E16,Hybrid!$1:$1048576,MATCH(DATE(H$2,1,1),Hybrid!$A$1:$LI$1),FALSE) -> 9.5658742 | I16: =VLOOKUP($E16,Hybrid!$1:$1048576,MATCH(DATE(I$2,1,1),Hybrid!$A$1:$LI$1),FALSE) -> 11.661626 | J16: =VLOOKUP($E16,Hybrid!$1:$1048576,MATCH(DATE(J$2,1,1),Hybrid!$A$1:$LI$1),FALSE) -> 13.871889 | K16: =VLOOKUP($E16,Hybrid!$1:$1048576,MATCH(DATE(K$2,1,1),Hybrid!$A$1:$LI$1),FALSE) -> 16.161271 | L16: =VLOOKUP($E16,Hybrid!$1:$1048576,MATCH(DATE(L$2,1,1),Hybrid!$A$1:$LI$1),FALSE) -> 18.496851 | M16: =VLOOKUP($E16,Hybrid!$1:$1048576,MATCH(DATE(M$2,1,1),Hybrid!$A$1:$LI$1),FALSE) -> 20.810544 | ... AO16: =VLOOKUP($E16,Hybrid!$1:$1048576,MATCH(DATE(AO$2,1,1),Hybrid!$A$1:$LI$1),FALSE) -> 404.40471
D17: class E | E17: AUTO_ce_cele_2 | F17: =VLOOKUP($E17,Hybrid!$1:$1048576,MATCH(DATE(F$2,1,1),Hybrid!$A$1:$LI$1),FALSE) -> 3.4730441 | G17: =VLOOKUP($E17,Hybrid!$1:$1048576,MATCH(DATE(G$2,1,1),Hybrid!$A$1:$LI$1),FALSE) -> 4.5917108 | H17: =VLOOKUP($E17,Hybrid!$1:$1048576,MATCH(DATE(H$2,1,1),Hybrid!$A$1:$LI$1),FALSE) -> 5.8046001 | I17: =VLOOKUP($E17,Hybrid!$1:$1048576,MATCH(DATE(I$2,1,1),Hybrid!$A$1:$LI$1),FALSE) -> 7.0827696 | J17: =VLOOKUP($E17,Hybrid!$1:$1048576,MATCH(DATE(J$2,1,1),Hybrid!$A$1:$LI$1),FALSE) -> 8.4233535 | K17: =VLOOKUP($E17,Hybrid!$1:$1048576,MATCH(DATE(K$2,1,1),Hybrid!$A$1:$LI$1),FALSE) -> 9.8032197 | L17: =VLOOKUP($E17,Hybrid!$1:$1048576,MATCH(DATE(L$2,1,1),Hybrid!$A$1:$LI$1),FALSE) -> 11.201005 | M17: =VLOOKUP($E17,Hybrid!$1:$1048576,MATCH(DATE(M$2,1,1),Hybrid!$A$1:$LI$1),FALSE) -> 12.575823 | ... AO17: =VLOOKUP($E17,Hybrid!$1:$1048576,MATCH(DATE(AO$2,1,1),Hybrid!$A$1:$LI$1),FALSE) -> 204.85521
D18: class F | E18: AUTO_cf_cele_2 | F18: =VLOOKUP($E18,Hybrid!$1:$1048576,MATCH(DATE(F$2,1,1),Hybrid!$A$1:$LI$1),FALSE) -> 1.7251505 | G18: =VLOOKUP($E18,Hybrid!$1:$1048576,MATCH(DATE(G$2,1,1),Hybrid!$A$1:$LI$1),FALSE) -> 2.2518855 | H18: =VLOOKUP($E18,Hybrid!$1:$1048576,MATCH(DATE(H$2,1,1),Hybrid!$A$1:$LI$1),FALSE) -> 2.80569 | I18: =VLOOKUP($E18,Hybrid!$1:$1048576,MATCH(DATE(I$2,1,1),Hybrid!$A$1:$LI$1),FALSE) -> 3.3665411 | J18: =VLOOKUP($E18,Hybrid!$1:$1048576,MATCH(DATE(J$2,1,1),Hybrid!$A$1:$LI$1),FALSE) -> 3.9283843 | K18: =VLOOKUP($E18,Hybrid!$1:$1048576,MATCH(DATE(K$2,1,1),Hybrid!$A$1:$LI$1),FALSE) -> 4.4801406 | L18: =VLOOKUP($E18,Hybrid!$1:$1048576,MATCH(DATE(L$2,1,1),Hybrid!$A$1:$LI$1),FALSE) -> 5.0121241 | M18: =VLOOKUP($E18,Hybrid!$1:$1048576,MATCH(DATE(M$2,1,1),Hybrid!$A$1:$LI$1),FALSE) -> 5.5005073 | ... AO18: =VLOOKUP($E18,Hybrid!$1:$1048576,MATCH(DATE(AO$2,1,1),Hybrid!$A$1:$LI$1),FALSE) -> 28.730623
D19: class G | E19: AUTO_cg_cele_2 | F19: =VLOOKUP($E19,Hybrid!$1:$1048576,MATCH(DATE(F$2,1,1),Hybrid!$A$1:$LI$1),FALSE) -> 3.1066862 | G19: =VLOOKUP($E19,Hybrid!$1:$1048576,MATCH(DATE(G$2,1,1),Hybrid!$A$1:$LI$1),FALSE) -> 4.0887993 | H19: =VLOOKUP($E19,Hybrid!$1:$1048576,MATCH(DATE(H$2,1,1),Hybrid!$A$1:$LI$1),FALSE) -> 5.1015716 | I19: =VLOOKUP($E19,Hybrid!$1:$1048576,MATCH(DATE(I$2,1,1),Hybrid!$A$1:$LI$1),FALSE) -> 6.1032213 | J19: =VLOOKUP($E19,Hybrid!$1:$1048576,MATCH(DATE(J$2,1,1),Hybrid!$A$1:$LI$1),FALSE) -> 7.0796515 | K19: =VLOOKUP($E19,Hybrid!$1:$1048576,MATCH(DATE(K$2,1,1),Hybrid!$A$1:$LI$1),FALSE) -> 8.0101921 | L19: =VLOOKUP($E19,Hybrid!$1:$1048576,MATCH(DATE(L$2,1,1),Hybrid!$A$1:$LI$1),FALSE) -> 8.8780269 | M19: =VLOOKUP($E19,Hybrid!$1:$1048576,MATCH(DATE(M$2,1,1),Hybrid!$A$1:$LI$1),FALSE) -> 9.6431996 | ... AO19: =VLOOKUP($E19,Hybrid!$1:$1048576,MATCH(DATE(AO$2,1,1),Hybrid!$A$1:$LI$1),FALSE) -> 29.224625
C20: GAS | E20: AUTO_cgas_2 | F20: =VLOOKUP($E20,Hybrid!$1:$1048576,MATCH(DATE(F$2,1,1),Hybrid!$A$1:$LI$1),FALSE) -> 1.936 | G20: =VLOOKUP($E20,Hybrid!$1:$1048576,MATCH(DATE(G$2,1,1),Hybrid!$A$1:$LI$1),FALSE) -> 1.9909099 | H20: =VLOOKUP($E20,Hybrid!$1:$1048576,MATCH(DATE(H$2,1,1),Hybrid!$A$1:$LI$1),FALSE) -> 2.0596615 | I20: =VLOOKUP($E20,Hybrid!$1:$1048576,MATCH(DATE(I$2,1,1),Hybrid!$A$1:$LI$1),FALSE) -> 2.1363797 | J20: =VLOOKUP($E20,Hybrid!$1:$1048576,MATCH(DATE(J$2,1,1),Hybrid!$A$1:$LI$1),FALSE) -> 2.2193981 | K20: =VLOOKUP($E20,Hybrid!$1:$1048576,MATCH(DATE(K$2,1,1),Hybrid!$A$1:$LI$1),FALSE) -> 2.3059977 | L20: =VLOOKUP($E20,Hybrid!$1:$1048576,MATCH(DATE(L$2,1,1),Hybrid!$A$1:$LI$1),FALSE) -> 2.3936768 | M20: =VLOOKUP($E20,Hybrid!$1:$1048576,MATCH(DATE(M$2,1,1),Hybrid!$A$1:$LI$1),FALSE) -> 2.4725398 | ... AO20: =VLOOKUP($E20,Hybrid!$1:$1048576,MATCH(DATE(AO$2,1,1),Hybrid!$A$1:$LI$1),FALSE) -> 3.5012802
D21: class A | E21: AUTO_ca_cgas_2 | F21: =VLOOKUP($E21,Hybrid!$1:$1048576,MATCH(DATE(F$2,1,1),Hybrid!$A$1:$LI$1),FALSE) -> 0.4256817 | G21: =VLOOKUP($E21,Hybrid!$1:$1048576,MATCH(DATE(G$2,1,1),Hybrid!$A$1:$LI$1),FALSE) -> 0.44909736 | H21: =VLOOKUP($E21,Hybrid!$1:$1048576,MATCH(DATE(H$2,1,1),Hybrid!$A$1:$LI$1),FALSE) -> 0.47635319 | I21: =VLOOKUP($E21,Hybrid!$1:$1048576,MATCH(DATE(I$2,1,1),Hybrid!$A$1:$LI$1),FALSE) -> 0.50591124 | J21: =VLOOKUP($E21,Hybrid!$1:$1048576,MATCH(DATE(J$2,1,1),Hybrid!$A$1:$LI$1),FALSE) -> 0.53738588 | K21: =VLOOKUP($E21,Hybrid!$1:$1048576,MATCH(DATE(K$2,1,1),Hybrid!$A$1:$LI$1),FALSE) -> 0.57001754 | L21: =VLOOKUP($E21,Hybrid!$1:$1048576,MATCH(DATE(L$2,1,1),Hybrid!$A$1:$LI$1),FALSE) -> 0.60310328 | M21: =VLOOKUP($E21,Hybrid!$1:$1048576,MATCH(DATE(M$2,1,1),Hybrid!$A$1:$LI$1),FALSE) -> 0.63383453 | ... AO21: =VLOOKUP($E21,Hybrid!$1:$1048576,MATCH(DATE(AO$2,1,1),Hybrid!$A$1:$LI$1),FALSE) -> 1.1426523
D22: class B | E22: AUTO_cb_cgas_2 | F22: =VLOOKUP($E22,Hybrid!$1:$1048576,MATCH(DATE(F$2,1,1),Hybrid!$A$1:$LI$1),FALSE) -> 0.49500523 | G22: =VLOOKUP($E22,Hybrid!$1:$1048576,MATCH(DATE(G$2,1,1),Hybrid!$A$1:$LI$1),FALSE) -> 0.51203168 | H22: =VLOOKUP($E22,Hybrid!$1:$1048576,MATCH(DATE(H$2,1,1),Hybrid!$A$1:$LI$1),FALSE) -> 0.53299171 | I22: =VLOOKUP($E22,Hybrid!$1:$1048576,MATCH(DATE(I$2,1,1),Hybrid!$A$1:$LI$1),FALSE) -> 0.55636194 | J22: =VLOOKUP($E22,Hybrid!$1:$1048576,MATCH(DATE(J$2,1,1),Hybrid!$A$1:$LI$1),FALSE) -> 0.58173637 | K22: =VLOOKUP($E22,Hybrid!$1:$1048576,MATCH(DATE(K$2,1,1),Hybrid!$A$1:$LI$1),FALSE) -> 0.60837525 | L22: =VLOOKUP($E22,Hybrid!$1:$1048576,MATCH(DATE(L$2,1,1),Hybrid!$A$1:$LI$1),FALSE) -> 0.63558899 | M22: =VLOOKUP($E22,Hybrid!$1:$1048576,MATCH(DATE(M$2,1,1),Hybrid!$A$1:$LI$1),FALSE) -> 0.66063538 | ... AO22: =VLOOKUP($E22,Hybrid!$1:$1048576,MATCH(DATE(AO$2,1,1),Hybrid!$A$1:$LI$1),FALSE) -> 1.0500198
D23: class C | E23: AUTO_cc_cgas_2 | F23: =VLOOKUP($E23,Hybrid!$1:$1048576,MATCH(DATE(F$2,1,1),Hybrid!$A$1:$LI$1),FALSE) -> 0.40659852 | G23: =VLOOKUP($E23,Hybrid!$1:$1048576,MATCH(DATE(G$2,1,1),Hybrid!$A$1:$LI$1),FALSE) -> 0.41434648 | H23: =VLOOKUP($E23,Hybrid!$1:$1048576,MATCH(DATE(H$2,1,1),Hybrid!$A$1:$LI$1),FALSE) -> 0.42500511 | I23: =VLOOKUP($E23,Hybrid!$1:$1048576,MATCH(DATE(I$2,1,1),Hybrid!$A$1:$LI$1),FALSE) -> 0.43748705 | J23: =VLOOKUP($E23,Hybrid!$1:$1048576,MATCH(DATE(J$2,1,1),Hybrid!$A$1:$LI$1),FALSE) -> 0.45148622 | K23: =VLOOKUP($E23,Hybrid!$1:$1048576,MATCH(DATE(K$2,1,1),Hybrid!$A$1:$LI$1),FALSE) -> 0.46648281 | L23: =VLOOKUP($E23,Hybrid!$1:$1048576,MATCH(DATE(L$2,1,1),Hybrid!$A$1:$LI$1),FALSE) -> 0.4819889 | M23: =VLOOKUP($E23,Hybrid!$1:$1048576,MATCH(DATE(M$2,1,1),Hybrid!$A$1:$LI$1),FALSE) -> 0.49607544 | ... AO23: =VLOOKUP($E23,Hybrid!$1:$1048576,MATCH(DATE(AO$2,1,1),Hybrid!$A$1:$LI$1),FALSE) -> 0.68809577
D24: class D | E24: AUTO_cd_cgas_2 | F24: =VLOOKUP($E24,Hybrid!$1:$1048576,MATCH(DATE(F$2,1,1),Hybrid!$A$1:$LI$1),FALSE) -> 0.24954447 | G24: =VLOOKUP($E24,Hybrid!$1:$1048576,MATCH(DATE(G$2,1,1),Hybrid!$A$1:$LI$1),FALSE) -> 0.25224611 | H24: =VLOOKUP($E24,Hybrid!$1:$1048576,MATCH(DATE(H$2,1,1),Hybrid!$A$1:$LI$1),FALSE) -> 0.25652394 | I24: =VLOOKUP($E24,Hybrid!$1:$1048576,MATCH(DATE(I$2,1,1),Hybrid!$A$1:$LI$1),FALSE) -> 0.26173608 | J24: =VLOOKUP($E24,Hybrid!$1:$1048576,MATCH(DATE(J$2,1,1),Hybrid!$A$1:$LI$1),FALSE) -> 0.26768368 | K24: =VLOOKUP($E24,Hybrid!$1:$1048576,MATCH(DATE(K$2,1,1),Hybrid!$A$1:$LI$1),FALSE) -> 0.2740705 | L24: =VLOOKUP($E24,Hybrid!$1:$1048576,MATCH(DATE(L$2,1,1),Hybrid!$A$1:$LI$1),FALSE) -> 0.28062121 | M24: =VLOOKUP($E24,Hybrid!$1:$1048576,MATCH(DATE(M$2,1,1),Hybrid!$A$1:$LI$1),FALSE) -> 0.28628059 | ... AO24: =VLOOKUP($E24,Hybrid!$1:$1048576,MATCH(DATE(AO$2,1,1),Hybrid!$A$1:$LI$1),FALSE) -> 0.34227244
D25: class E | E25: AUTO_ce_cgas_2 | F25: =VLOOKUP($E25,Hybrid!$1:$1048576,MATCH(DATE(F$2,1,1),Hybrid!$A$1:$LI$1),FALSE) -> 0.15020247 | G25: =VLOOKUP($E25,Hybrid!$1:$1048576,MATCH(DATE(G$2,1,1),Hybrid!$A$1:$LI$1),FALSE) -> 0.15202419 | H25: =VLOOKUP($E25,Hybrid!$1:$1048576,MATCH(DATE(H$2,1,1),Hybrid!$A$1:$LI$1),FALSE) -> 0.15472833 | I25: =VLOOKUP($E25,Hybrid!$1:$1048576,MATCH(DATE(I$2,1,1),Hybrid!$A$1:$LI$1),FALSE) -> 0.15790278 | J25: =VLOOKUP($E25,Hybrid!$1:$1048576,MATCH(DATE(J$2,1,1),Hybrid!$A$1:$LI$1),FALSE) -> 0.16141401 | K25: =VLOOKUP($E25,Hybrid!$1:$1048576,MATCH(DATE(K$2,1,1),Hybrid!$A$1:$LI$1),FALSE) -> 0.16508139 | L25: =VLOOKUP($E25,Hybrid!$1:$1048576,MATCH(DATE(L$2,1,1),Hybrid!$A$1:$LI$1),FALSE) -> 0.16873863 | M25: =VLOOKUP($E25,Hybrid!$1:$1048576,MATCH(DATE(M$2,1,1),Hybrid!$A$1:$LI$1),FALSE) -> 0.17174678 | ... AO25: =VLOOKUP($E25,Hybrid!$1:$1048576,MATCH(DATE(AO$2,1,1),Hybrid!$A$1:$LI$1),FALSE) -> 0.17074118
D26: class F | E26: AUTO_cf_cgas_2 | F26: =VLOOKUP($E26,Hybrid!$1:$1048576,MATCH(DATE(F$2,1,1),Hybrid!$A$1:$LI$1),FALSE) -> 0.074609436 | G26: =VLOOKUP($E26,Hybrid!$1:$1048576,MATCH(DATE(G$2,1,1),Hybrid!$A$1:$LI$1),FALSE) -> 0.075291701 | H26: =VLOOKUP($E26,Hybrid!$1:$1048576,MATCH(DATE(H$2,1,1),Hybrid!$A$1:$LI$1),FALSE) -> 0.076289682 | I26: =VLOOKUP($E26,Hybrid!$1:$1048576,MATCH(DATE(I$2,1,1),Hybrid!$A$1:$LI$1),FALSE) -> 0.077379202 | J26: =VLOOKUP($E26,Hybrid!$1:$1048576,MATCH(DATE(J$2,1,1),Hybrid!$A$1:$LI$1),FALSE) -> 0.078480977 | K26: =VLOOKUP($E26,Hybrid!$1:$1048576,MATCH(DATE(K$2,1,1),Hybrid!$A$1:$LI$1),FALSE) -> 0.07951067 | L26: =VLOOKUP($E26,Hybrid!$1:$1048576,MATCH(DATE(L$2,1,1),Hybrid!$A$1:$LI$1),FALSE) -> 0.080396183 | M26: =VLOOKUP($E26,Hybrid!$1:$1048576,MATCH(DATE(M$2,1,1),Hybrid!$A$1:$LI$1),FALSE) -> 0.080862947 | ... AO26: =VLOOKUP($E26,Hybrid!$1:$1048576,MATCH(DATE(AO$2,1,1),Hybrid!$A$1:$LI$1),FALSE) -> 0.048233221
D27: class G | E27: AUTO_cg_cgas_2 | F27: =VLOOKUP($E27,Hybrid!$1:$1048576,MATCH(DATE(F$2,1,1),Hybrid!$A$1:$LI$1),FALSE) -> 0.13435819 | G27: =VLOOKUP($E27,Hybrid!$1:$1048576,MATCH(DATE(G$2,1,1),Hybrid!$A$1:$LI$1),FALSE) -> 0.13587233 | H27: =VLOOKUP($E27,Hybrid!$1:$1048576,MATCH(DATE(H$2,1,1),Hybrid!$A$1:$LI$1),FALSE) -> 0.13776953 | I27: =VLOOKUP($E27,Hybrid!$1:$1048576,MATCH(DATE(I$2,1,1),Hybrid!$A$1:$LI$1),FALSE) -> 0.1396014 | J27: =VLOOKUP($E27,Hybrid!$1:$1048576,MATCH(DATE(J$2,1,1),Hybrid!$A$1:$LI$1),FALSE) -> 0.14121093 | K27: =VLOOKUP($E27,Hybrid!$1:$1048576,MATCH(DATE(K$2,1,1),Hybrid!$A$1:$LI$1),FALSE) -> 0.14245951 | L27: =VLOOKUP($E27,Hybrid!$1:$1048576,MATCH(DATE(L$2,1,1),Hybrid!$A$1:$LI$1),FALSE) -> 0.14323963 | M27: =VLOOKUP($E27,Hybrid!$1:$1048576,MATCH(DATE(M$2,1,1),Hybrid!$A$1:$LI$1),FALSE) -> 0.14310409 | ... AO27: =VLOOKUP($E27,Hybrid!$1:$1048576,MATCH(DATE(AO$2,1,1),Hybrid!$A$1:$LI$1),FALSE) -> 0.059265473
C28: TOTAL STOCK BASELINE | E28: AUTO_0 | F28: =VLOOKUP($E28,Hybrid!$1:$1048576,MATCH(DATE(F$2,1,1),Hybrid!$A$1:$LI$1),FALSE) -> 32317.941 | G28: =VLOOKUP($E28,Hybrid!$1:$1048576,MATCH(DATE(G$2,1,1),Hybrid!$A$1:$LI$1),FALSE) -> 31918.631 | H28: =VLOOKUP($E28,Hybrid!$1:$1048576,MATCH(DATE(H$2,1,1),Hybrid!$A$1:$LI$1),FALSE) -> 31759.311 | I28: =VLOOKUP($E28,Hybrid!$1:$1048576,MATCH(DATE(I$2,1,1),Hybrid!$A$1:$LI$1),FALSE) -> 31761.553 | J28: =VLOOKUP($E28,Hybrid!$1:$1048576,MATCH(DATE(J$2,1,1),Hybrid!$A$1:$LI$1),FALSE) -> 31899.124 | K28: =VLOOKUP($E28,Hybrid!$1:$1048576,MATCH(DATE(K$2,1,1),Hybrid!$A$1:$LI$1),FALSE) -> 32133.592 | L28: =VLOOKUP($E28,Hybrid!$1:$1048576,MATCH(DATE(L$2,1,1),Hybrid!$A$1:$LI$1),FALSE) -> 32419.623 | M28: =VLOOKUP($E28,Hybrid!$1:$1048576,MATCH(DATE(M$2,1,1),Hybrid!$A$1:$LI$1),FALSE) -> 32735.512 | ... AO28: =VLOOKUP($E28,Hybrid!$1:$1048576,MATCH(DATE(AO$2,1,1),Hybrid!$A$1:$LI$1),FALSE) -> 42002.247
C29: OIL | E29: AUTO_cfut_0 | F29: =VLOOKUP($E29,Hybrid!$1:$1048576,MATCH(DATE(F$2,1,1),Hybrid!$A$1:$LI$1),FALSE) -> 32271.24 | G29: =VLOOKUP($E29,Hybrid!$1:$1048576,MATCH(DATE(G$2,1,1),Hybrid!$A$1:$LI$1),FALSE) -> 31853.75 | H29: =VLOOKUP($E29,Hybrid!$1:$1048576,MATCH(DATE(H$2,1,1),Hybrid!$A$1:$LI$1),FALSE) -> 31674.362 | I29: =VLOOKUP($E29,Hybrid!$1:$1048576,MATCH(DATE(I$2,1,1),Hybrid!$A$1:$LI$1),FALSE) -> 31654.909 | J29: =VLOOKUP($E29,Hybrid!$1:$1048576,MATCH(DATE(J$2,1,1),Hybrid!$A$1:$LI$1),FALSE) -> 31769.037 | K29: =VLOOKUP($E29,Hybrid!$1:$1048576,MATCH(DATE(K$2,1,1),Hybrid!$A$1:$LI$1),FALSE) -> 31978.673 | L29: =VLOOKUP($E29,Hybrid!$1:$1048576,MATCH(DATE(L$2,1,1),Hybrid!$A$1:$LI$1),FALSE) -> 32238.864 | M29: =VLOOKUP($E29,Hybrid!$1:$1048576,MATCH(DATE(M$2,1,1),Hybrid!$A$1:$LI$1),FALSE) -> 32527.868 | ... AO29: =VLOOKUP($E29,Hybrid!$1:$1048576,MATCH(DATE(AO$2,1,1),Hybrid!$A$1:$LI$1),FALSE) -> 39537.676
D30: class A | E30: AUTO_ca_cfut_0 | F30: =VLOOKUP($E30,Hybrid!$1:$1048576,MATCH(DATE(F$2,1,1),Hybrid!$A$1:$LI$1),FALSE) -> 7095.7005 | G30: =VLOOKUP($E30,Hybrid!$1:$1048576,MATCH(DATE(G$2,1,1),Hybrid!$A$1:$LI$1),FALSE) -> 7138.9134 | H30: =VLOOKUP($E30,Hybrid!$1:$1048576,MATCH(DATE(H$2,1,1),Hybrid!$A$1:$LI$1),FALSE) -> 7241.8937 | I30: =VLOOKUP($E30,Hybrid!$1:$1048576,MATCH(DATE(I$2,1,1),Hybrid!$A$1:$LI$1),FALSE) -> 7384.5407 | J30: =VLOOKUP($E30,Hybrid!$1:$1048576,MATCH(DATE(J$2,1,1),Hybrid!$A$1:$LI$1),FALSE) -> 7560.8902 | K30: =VLOOKUP($E30,Hybrid!$1:$1048576,MATCH(DATE(K$2,1,1),Hybrid!$A$1:$LI$1),FALSE) -> 7760.7036 | L30: =VLOOKUP($E30,Hybrid!$1:$1048576,MATCH(DATE(L$2,1,1),Hybrid!$A$1:$LI$1),FALSE) -> 7971.6733 | M30: =VLOOKUP($E30,Hybrid!$1:$1048576,MATCH(DATE(M$2,1,1),Hybrid!$A$1:$LI$1),FALSE) -> 8188.3294 | ... AO30: =VLOOKUP($E30,Hybrid!$1:$1048576,MATCH(DATE(AO$2,1,1),Hybrid!$A$1:$LI$1),FALSE) -> 12926.607
D31: class B | E31: AUTO_cb_cfut_0 | F31: =VLOOKUP($E31,Hybrid!$1:$1048576,MATCH(DATE(F$2,1,1),Hybrid!$A$1:$LI$1),FALSE) -> 8251.2564 | G31: =VLOOKUP($E31,Hybrid!$1:$1048576,MATCH(DATE(G$2,1,1),Hybrid!$A$1:$LI$1),FALSE) -> 8180.0639 | H31: =VLOOKUP($E31,Hybrid!$1:$1048576,MATCH(DATE(H$2,1,1),Hybrid!$A$1:$LI$1),FALSE) -> 8173.9007 | I31: =VLOOKUP($E31,Hybrid!$1:$1048576,MATCH(DATE(I$2,1,1),Hybrid!$A$1:$LI$1),FALSE) -> 8212.4993 | J31: =VLOOKUP($E31,Hybrid!$1:$1048576,MATCH(DATE(J$2,1,1),Hybrid!$A$1:$LI$1),FALSE) -> 8289.337 | K31: =VLOOKUP($E31,Hybrid!$1:$1048576,MATCH(DATE(K$2,1,1),Hybrid!$A$1:$LI$1),FALSE) -> 8394.1234 | L31: =VLOOKUP($E31,Hybrid!$1:$1048576,MATCH(DATE(L$2,1,1),Hybrid!$A$1:$LI$1),FALSE) -> 8514.5426 | M31: =VLOOKUP($E31,Hybrid!$1:$1048576,MATCH(DATE(M$2,1,1),Hybrid!$A$1:$LI$1),FALSE) -> 8644.7147 | ... AO31: =VLOOKUP($E31,Hybrid!$1:$1048576,MATCH(DATE(AO$2,1,1),Hybrid!$A$1:$LI$1),FALSE) -> 11971.279
D32: class C | E32: AUTO_cc_cfut_0 | F32: =VLOOKUP($E32,Hybrid!$1:$1048576,MATCH(DATE(F$2,1,1),Hybrid!$A$1:$LI$1),FALSE) -> 6777.6025 | G32: =VLOOKUP($E32,Hybrid!$1:$1048576,MATCH(DATE(G$2,1,1),Hybrid!$A$1:$LI$1),FALSE) -> 6644.8772 | H32: =VLOOKUP($E32,Hybrid!$1:$1048576,MATCH(DATE(H$2,1,1),Hybrid!$A$1:$LI$1),FALSE) -> 6562.8912 | I32: =VLOOKUP($E32,Hybrid!$1:$1048576,MATCH(DATE(I$2,1,1),Hybrid!$A$1:$LI$1),FALSE) -> 6516.918 | J32: =VLOOKUP($E32,Hybrid!$1:$1048576,MATCH(DATE(J$2,1,1),Hybrid!$A$1:$LI$1),FALSE) -> 6501.8685 | K32: =VLOOKUP($E32,Hybrid!$1:$1048576,MATCH(DATE(K$2,1,1),Hybrid!$A$1:$LI$1),FALSE) -> 6510.2772 | L32: =VLOOKUP($E32,Hybrid!$1:$1048576,MATCH(DATE(L$2,1,1),Hybrid!$A$1:$LI$1),FALSE) -> 6533.2536 | M32: =VLOOKUP($E32,Hybrid!$1:$1048576,MATCH(DATE(M$2,1,1),Hybrid!$A$1:$LI$1),FALSE) -> 6566.2781 | ... AO32: =VLOOKUP($E32,Hybrid!$1:$1048576,MATCH(DATE(AO$2,1,1),Hybrid!$A$1:$LI$1),FALSE) -> 7910.2714
D33: class D | E33: AUTO_cd_cfut_0 | F33: =VLOOKUP($E33,Hybrid!$1:$1048576,MATCH(DATE(F$2,1,1),Hybrid!$A$1:$LI$1),FALSE) -> 4159.6639 | G33: =VLOOKUP($E33,Hybrid!$1:$1048576,MATCH(DATE(G$2,1,1),Hybrid!$A$1:$LI$1),FALSE) -> 4053.7616 | H33: =VLOOKUP($E33,Hybrid!$1:$1048576,MATCH(DATE(H$2,1,1),Hybrid!$A$1:$LI$1),FALSE) -> 3976.8722 | I33: =VLOOKUP($E33,Hybrid!$1:$1048576,MATCH(DATE(I$2,1,1),Hybrid!$A$1:$LI$1),FALSE) -> 3920.2702 | J33: =VLOOKUP($E33,Hybrid!$1:$1048576,MATCH(DATE(J$2,1,1),Hybrid!$A$1:$LI$1),FALSE) -> 3880.7049 | K33: =VLOOKUP($E33,Hybrid!$1:$1048576,MATCH(DATE(K$2,1,1),Hybrid!$A$1:$LI$1),FALSE) -> 3853.8714 | L33: =VLOOKUP($E33,Hybrid!$1:$1048576,MATCH(DATE(L$2,1,1),Hybrid!$A$1:$LI$1),FALSE) -> 3834.7399 | M33: =VLOOKUP($E33,Hybrid!$1:$1048576,MATCH(DATE(M$2,1,1),Hybrid!$A$1:$LI$1),FALSE) -> 3820.6377 | ... AO33: =VLOOKUP($E33,Hybrid!$1:$1048576,MATCH(DATE(AO$2,1,1),Hybrid!$A$1:$LI$1),FALSE) -> 3702.557
D34: class E | E34: AUTO_ce_cfut_0 | F34: =VLOOKUP($E34,Hybrid!$1:$1048576,MATCH(DATE(F$2,1,1),Hybrid!$A$1:$LI$1),FALSE) -> 2503.7292 | G34: =VLOOKUP($E34,Hybrid!$1:$1048576,MATCH(DATE(G$2,1,1),Hybrid!$A$1:$LI$1),FALSE) -> 2442.3141 | H34: =VLOOKUP($E34,Hybrid!$1:$1048576,MATCH(DATE(H$2,1,1),Hybrid!$A$1:$LI$1),FALSE) -> 2397.5371 | I34: =VLOOKUP($E34,Hybrid!$1:$1048576,MATCH(DATE(I$2,1,1),Hybrid!$A$1:$LI$1),FALSE) -> 2363.8546 | J34: =VLOOKUP($E34,Hybrid!$1:$1048576,MATCH(DATE(J$2,1,1),Hybrid!$A$1:$LI$1),FALSE) -> 2339.1637 | K34: =VLOOKUP($E34,Hybrid!$1:$1048576,MATCH(DATE(K$2,1,1),Hybrid!$A$1:$LI$1),FALSE) -> 2320.8652 | L34: =VLOOKUP($E34,Hybrid!$1:$1048576,MATCH(DATE(L$2,1,1),Hybrid!$A$1:$LI$1),FALSE) -> 2305.9376 | M34: =VLOOKUP($E34,Hybrid!$1:$1048576,MATCH(DATE(M$2,1,1),Hybrid!$A$1:$LI$1),FALSE) -> 2292.7598 | ... AO34: =VLOOKUP($E34,Hybrid!$1:$1048576,MATCH(DATE(AO$2,1,1),Hybrid!$A$1:$LI$1),FALSE) -> 1870.4198
D35: class F | E35: AUTO_cf_cfut_0 | F35: =VLOOKUP($E35,Hybrid!$1:$1048576,MATCH(DATE(F$2,1,1),Hybrid!$A$1:$LI$1),FALSE) -> 1243.6668 | G35: =VLOOKUP($E35,Hybrid!$1:$1048576,MATCH(DATE(G$2,1,1),Hybrid!$A$1:$LI$1),FALSE) -> 1210.5103 | H35: =VLOOKUP($E35,Hybrid!$1:$1048576,MATCH(DATE(H$2,1,1),Hybrid!$A$1:$LI$1),FALSE) -> 1184.1996 | I35: =VLOOKUP($E35,Hybrid!$1:$1048576,MATCH(DATE(I$2,1,1),Hybrid!$A$1:$LI$1),FALSE) -> 1161.7685 | J35: =VLOOKUP($E35,Hybrid!$1:$1048576,MATCH(DATE(J$2,1,1),Hybrid!$A$1:$LI$1),FALSE) -> 1142.0394 | K35: =VLOOKUP($E35,Hybrid!$1:$1048576,MATCH(DATE(K$2,1,1),Hybrid!$A$1:$LI$1),FALSE) -> 1123.8073 | L35: =VLOOKUP($E35,Hybrid!$1:$1048576,MATCH(DATE(L$2,1,1),Hybrid!$A$1:$LI$1),FALSE) -> 1105.7491 | M35: =VLOOKUP($E35,Hybrid!$1:$1048576,MATCH(DATE(M$2,1,1),Hybrid!$A$1:$LI$1),FALSE) -> 1087.1871 | ... AO35: =VLOOKUP($E35,Hybrid!$1:$1048576,MATCH(DATE(AO$2,1,1),Hybrid!$A$1:$LI$1),FALSE) -> 521.33687
D36: class G | E36: AUTO_cg_cfut_0 | F36: =VLOOKUP($E36,Hybrid!$1:$1048576,MATCH(DATE(F$2,1,1),Hybrid!$A$1:$LI$1),FALSE) -> 2239.6206 | G36: =VLOOKUP($E36,Hybrid!$1:$1048576,MATCH(DATE(G$2,1,1),Hybrid!$A$1:$LI$1),FALSE) -> 2183.3099 | H36: =VLOOKUP($E36,Hybrid!$1:$1048576,MATCH(DATE(H$2,1,1),Hybrid!$A$1:$LI$1),FALSE) -> 2137.0676 | I36: =VLOOKUP($E36,Hybrid!$1:$1048576,MATCH(DATE(I$2,1,1),Hybrid!$A$1:$LI$1),FALSE) -> 2095.0577 | J36: =VLOOKUP($E36,Hybrid!$1:$1048576,MATCH(DATE(J$2,1,1),Hybrid!$A$1:$LI$1),FALSE) -> 2055.0332 | K36: =VLOOKUP($E36,Hybrid!$1:$1048576,MATCH(DATE(K$2,1,1),Hybrid!$A$1:$LI$1),FALSE) -> 2015.0245 | L36: =VLOOKUP($E36,Hybrid!$1:$1048576,MATCH(DATE(L$2,1,1),Hybrid!$A$1:$LI$1),FALSE) -> 1972.968 | M36: =VLOOKUP($E36,Hybrid!$1:$1048576,MATCH(DATE(M$2,1,1),Hybrid!$A$1:$LI$1),FALSE) -> 1927.9616 | ... AO36: =VLOOKUP($E36,Hybrid!$1:$1048576,MATCH(DATE(AO$2,1,1),Hybrid!$A$1:$LI$1),FALSE) -> 635.205
C37: ELEC | E37: AUTO_cele_0 | F37: =VLOOKUP($E37,Hybrid!$1:$1048576,MATCH(DATE(F$2,1,1),Hybrid!$A$1:$LI$1),FALSE) -> 44.765 | G37: =VLOOKUP($E37,Hybrid!$1:$1048576,MATCH(DATE(G$2,1,1),Hybrid!$A$1:$LI$1),FALSE) -> 62.889352 | H37: =VLOOKUP($E37,Hybrid!$1:$1048576,MATCH(DATE(H$2,1,1),Hybrid!$A$1:$LI$1),FALSE) -> 82.889294 | I37: =VLOOKUP($E37,Hybrid!$1:$1048576,MATCH(DATE(I$2,1,1),Hybrid!$A$1:$LI$1),FALSE) -> 104.50723 | J37: =VLOOKUP($E37,Hybrid!$1:$1048576,MATCH(DATE(J$2,1,1),Hybrid!$A$1:$LI$1),FALSE) -> 127.86793 | K37: =VLOOKUP($E37,Hybrid!$1:$1048576,MATCH(DATE(K$2,1,1),Hybrid!$A$1:$LI$1),FALSE) -> 152.61341 | L37: =VLOOKUP($E37,Hybrid!$1:$1048576,MATCH(DATE(L$2,1,1),Hybrid!$A$1:$LI$1),FALSE) -> 178.36635 | M37: =VLOOKUP($E37,Hybrid!$1:$1048576,MATCH(DATE(M$2,1,1),Hybrid!$A$1:$LI$1),FALSE) -> 205.16507 | ... AO37: =VLOOKUP($E37,Hybrid!$1:$1048576,MATCH(DATE(AO$2,1,1),Hybrid!$A$1:$LI$1),FALSE) -> 2766.3372
D38: class A | E38: AUTO_ca_cele_0 | F38: =VLOOKUP($E38,Hybrid!$1:$1048576,MATCH(DATE(F$2,1,1),Hybrid!$A$1:$LI$1),FALSE) -> 9.8427899 | G38: =VLOOKUP($E38,Hybrid!$1:$1048576,MATCH(DATE(G$2,1,1),Hybrid!$A$1:$LI$1),FALSE) -> 15.123232 | H38: =VLOOKUP($E38,Hybrid!$1:$1048576,MATCH(DATE(H$2,1,1),Hybrid!$A$1:$LI$1),FALSE) -> 20.991591 | I38: =VLOOKUP($E38,Hybrid!$1:$1048576,MATCH(DATE(I$2,1,1),Hybrid!$A$1:$LI$1),FALSE) -> 27.398546 | J38: =VLOOKUP($E38,Hybrid!$1:$1048576,MATCH(DATE(J$2,1,1),Hybrid!$A$1:$LI$1),FALSE) -> 34.399336 | K38: =VLOOKUP($E38,Hybrid!$1:$1048576,MATCH(DATE(K$2,1,1),Hybrid!$A$1:$LI$1),FALSE) -> 41.894067 | L38: =VLOOKUP($E38,Hybrid!$1:$1048576,MATCH(DATE(L$2,1,1),Hybrid!$A$1:$LI$1),FALSE) -> 49.778774 | M38: =VLOOKUP($E38,Hybrid!$1:$1048576,MATCH(DATE(M$2,1,1),Hybrid!$A$1:$LI$1),FALSE) -> 58.078159 | ... AO38: =VLOOKUP($E38,Hybrid!$1:$1048576,MATCH(DATE(AO$2,1,1),Hybrid!$A$1:$LI$1),FALSE) -> 949.97974
D39: class B | E39: AUTO_cb_cele_0 | F39: =VLOOKUP($E39,Hybrid!$1:$1048576,MATCH(DATE(F$2,1,1),Hybrid!$A$1:$LI$1),FALSE) -> 11.445717 | G39: =VLOOKUP($E39,Hybrid!$1:$1048576,MATCH(DATE(G$2,1,1),Hybrid!$A$1:$LI$1),FALSE) -> 16.441946 | H39: =VLOOKUP($E39,Hybrid!$1:$1048576,MATCH(DATE(H$2,1,1),Hybrid!$A$1:$LI$1),FALSE) -> 22.010704 | I39: =VLOOKUP($E39,Hybrid!$1:$1048576,MATCH(DATE(I$2,1,1),Hybrid!$A$1:$LI$1),FALSE) -> 28.107951 | J39: =VLOOKUP($E39,Hybrid!$1:$1048576,MATCH(DATE(J$2,1,1),Hybrid!$A$1:$LI$1),FALSE) -> 34.789079 | K39: =VLOOKUP($E39,Hybrid!$1:$1048576,MATCH(DATE(K$2,1,1),Hybrid!$A$1:$LI$1),FALSE) -> 41.955856 | L39: =VLOOKUP($E39,Hybrid!$1:$1048576,MATCH(DATE(L$2,1,1),Hybrid!$A$1:$LI$1),FALSE) -> 49.506371 | M39: =VLOOKUP($E39,Hybrid!$1:$1048576,MATCH(DATE(M$2,1,1),Hybrid!$A$1:$LI$1),FALSE) -> 57.464189 | ... AO39: =VLOOKUP($E39,Hybrid!$1:$1048576,MATCH(DATE(AO$2,1,1),Hybrid!$A$1:$LI$1),FALSE) -> 913.7881
D40: class C | E40: AUTO_cc_cele_0 | F40: =VLOOKUP($E40,Hybrid!$1:$1048576,MATCH(DATE(F$2,1,1),Hybrid!$A$1:$LI$1),FALSE) -> 9.4015406 | G40: =VLOOKUP($E40,Hybrid!$1:$1048576,MATCH(DATE(G$2,1,1),Hybrid!$A$1:$LI$1),FALSE) -> 12.804718 | H40: =VLOOKUP($E40,Hybrid!$1:$1048576,MATCH(DATE(H$2,1,1),Hybrid!$A$1:$LI$1),FALSE) -> 16.609264 | I40: =VLOOKUP($E40,Hybrid!$1:$1048576,MATCH(DATE(I$2,1,1),Hybrid!$A$1:$LI$1),FALSE) -> 20.786573 | J40: =VLOOKUP($E40,Hybrid!$1:$1048576,MATCH(DATE(J$2,1,1),Hybrid!$A$1:$LI$1),FALSE) -> 25.376235 | K40: =VLOOKUP($E40,Hybrid!$1:$1048576,MATCH(DATE(K$2,1,1),Hybrid!$A$1:$LI$1),FALSE) -> 30.30866 | L40: =VLOOKUP($E40,Hybrid!$1:$1048576,MATCH(DATE(L$2,1,1),Hybrid!$A$1:$LI$1),FALSE) -> 35.511808 | M40: =VLOOKUP($E40,Hybrid!$1:$1048576,MATCH(DATE(M$2,1,1),Hybrid!$A$1:$LI$1),FALSE) -> 41.001551 | ... AO40: =VLOOKUP($E40,Hybrid!$1:$1048576,MATCH(DATE(AO$2,1,1),Hybrid!$A$1:$LI$1),FALSE) -> 630.09316
...

Sheet date
A1: =Hybrid!A1 -> _date_ | B1: =Hybrid!B1 -> 42005 | C1: =Hybrid!C1 -> 42370 | D1: =Hybrid!D1 -> 42736 | E1: =Hybrid!E1 -> 43101 | F1: =Hybrid!F1 -> 43466 | G1: =Hybrid!G1 -> 43831 | H1: =Hybrid!H1 -> 44197 | ... AK1: =Hybrid!AK1 -> 54789
B2: =TEXT(B1,"jj mm aaaa") -> 01 01 2015 | C2: =TEXT(C1,"jj mm aaaa") -> 01 01 2016 | D2: =TEXT(D1,"jj mm aaaa") -> 01 01 2017 | E2: =TEXT(E1,"jj mm aaaa") -> 01 01 2018 | F2: =TEXT(F1,"jj mm aaaa") -> 01 01 2019 | G2: =TEXT(G1,"jj mm aaaa") -> 01 01 2020 | H2: =TEXT(H1,"jj mm aaaa") -> 01 01 2021 | I2: =TEXT(I1,"jj mm aaaa") -> 01 01 2022 | ... AK2: =TEXT(AK1,"jj mm aaaa") -> 01 01 2050
B3: =RIGHT(B2,4) -> 2015 | C3: =RIGHT(C2,4) -> 2016 | D3: =RIGHT(D2,4) -> 2017 | E3: =RIGHT(E2,4) -> 2018 | F3: =RIGHT(F2,4) -> 2019 | G3: =RIGHT(G2,4) -> 2020 | H3: =RIGHT(H2,4) -> 2021 | I3: =RIGHT(I2,4) -> 2022 | ... AK3: =RIGHT(AK2,4) -> 2050

Sheet Emissions
A1: _date_ | B1: 42005 | C1: 42370 | D1: 42736 | E1: 43101 | F1: 43466 | G1: 43831 | H1: 44197 | I1: 44562 | J1: 44927 | K1: 45292 | L1: 45658 | M1: 46023 | N1: 46388 | O1: 46753 | P1: 47119 | Q1: 47484 | R1: 47849 | S1: 48214 | T1: 48580 | U1: 48945 | V1: 49310 | W1: 49675 | X1: 50041 | Y1: 50406 | Z1: 50771 | AA1: 51136 | AB1: 51502 | AC1: 51867 | AD1: 52232 | AE1: 52597 | AF1: 52963 | AG1: 53328 | AH1: 53693 | AI1: 54058 | AJ1: 54424 | AK1: 54789
