Workbook
Name formatResults: [1]ResultsEXR10!$A$50

Sheet Export
A1: _date_ | B1: 42005 | C1: 42370 | D1: 42736 | E1: 43101 | F1: 43466 | G1: 43831 | H1: 44197 | I1: 44562 | J1: 44927 | K1: 45292 | L1: 45658 | M1: 46023 | N1: 46388 | O1: 46753 | P1: 47119 | Q1: 47484 | R1: 47849 | S1: 48214 | T1: 48580 | U1: 48945 | V1: 49310 | W1: 49675 | X1: 50041 | Y1: 50406 | Z1: 50771 | AA1: 51136 | AB1: 51502 | AC1: 51867 | AD1: 52232 | AE1: 52597 | AF1: 52963 | AG1: 53328 | AH1: 53693 | AI1: 54058 | AJ1: 54424 | AK1: 54789 | AL1: 55154 | AM1: 55519 | AN1: 55885 | AO1: 56250 | AP1: 56615 | AQ1: 56980 | AR1: 57346 | AS1: 57711 | AT1: 58076 | AU1: 58441 | AV1: 58807 | AW1: 59172 | AX1: 59537 | AY1: 59902 | AZ1: 60268 | BA1: 60633 | BB1: 60998 | BC1: 61363 | BD1: 61729 | BE1: 62094
A2: x_2 | B2: 632182.57 | C2: 640933.12 | D2: 650559.77 | E2: 660455.93 | F2: 670638.53 | G2: 681062.54 | H2: 691091.28 | I2: 701347.5 | J2: 711803.29 | K2: 722437.09 | L2: 734370.39 | M2: 745322.01 | N2: 756428.53 | O2: 767702.3 | P2: 779161.49 | Q2: 790827.42 | R2: 802721.7 | S2: 814868.83 | T2: 827293.16 | U2: 840017.19 | V2: 852220.36 | W2: 865613.96 | X2: 879375.92 | Y2: 893522.04 | Z2: 908068.79 | AA2: 920577.08 | AB2: 934805.24 | AC2: 949477.15 | AD2: 964608.5 | AE2: 980213.61 | AF2: 996306.67 | AG2: 1012901 | AH2: 1030007.7 | AI2: 1047638 | AJ2: 1065803.4 | AK2: 1084512.9 | AL2: 1102970.5 | AM2: 1121769.7 | AN2: 1140907.9 | AO2: 1160387.1 | AP2: 1180214 | AQ2: 1200399.4 | AR2: 1220956.4 | AS2: 1241899 | AT2: 1263241 | AU2: 1284996.4 | AV2: 1307237.1 | AW2: 1329919.7 | AX2: 1353055.8 | AY2: 1376655.8 | AZ2: 1400729.7 | BA2: 1425287.5 | BB2: 1450338.8 | BC2: 1475891.8 | BD2: 1501954.2 | BE2: 1528533.2
A3: x_0 | B3: 632182.57 | C3: 640933.08 | D3: 650559.62 | E3: 660455.58 | F3: 670637.91 | G3: 681061.56 | H3: 691089.46 | I3: 701344.12 | J3: 711797.5 | K3: 722428.06 | L3: 734357.27 | M3: 745305.94 | N3: 756411.84 | O3: 767687.79 | P3: 779152.03 | Q3: 790825.72 | R3: 802733.63 | S3: 814902.11 | T3: 827356.17 | U3: 840118.3 | V3: 852367.46 | W3: 865817.57 | X3: 879647.83 | Y3: 893874.5 | Z3: 908513.99 | AA3: 921125.44 | AB3: 935469.57 | AC3: 950269.9 | AD3: 965542.23 | AE3: 981300.9 | AF3: 997560.08 | AG3: 1014333.9 | AH3: 1031633.9 | AI3: 1049471.6 | AJ3: 1067858.7 | AK3: 1086804.7 | AL3: 1105510.4 | AM3: 1124570.2 | AN3: 1143981.3 | AO3: 1163745.8 | AP3: 1183870.5 | AQ3: 1204366.6 | AR3: 1225247.4 | AS3: 1246527 | AT3: 1268219.8 | AU3: 1290339.7 | AV3: 1312958.1 | AW3: 1336030.6 | AX3: 1359568.9 | AY3: 1383583.7 | AZ3: 1408085.5 | BA3: 1433083.3 | BB3: 1458585.9 | BC3: 1484601.8 | BD3: 1511139.2 | BE3: 1538205.6
A4: x_cagr_2 | B4: 15830.016 | C4: 16048.837 | D4: 16290.019 | E4: 16538.338 | F4: 16794.007 | G4: 17055.655 | H4: 17307.094 | I4: 17563.779 | J4: 17824.953 | K4: 18090.064 | L4: 18387.248 | M4: 18659.315 | N4: 18934.682 | O4: 19213.65 | P4: 19496.691 | Q4: 19784.369 | R4: 20077.245 | S4: 20375.971 | T4: 20681.208 | U4: 20993.577 | V4: 21292.6 | W4: 21621.148 | X4: 21958.759 | Y4: 22305.885 | Z4: 22662.974 | AA4: 22969.079 | AB4: 23318.103 | AC4: 23678.3 | AD4: 24050.13 | AE4: 24433.986 | AF4: 24830.232 | AG4: 25239.204 | AH4: 25661.172 | AI4: 26096.397 | AJ4: 26545.146 | AK4: 27007.622 | AL4: 27464.018 | AM4: 27929.119 | AN4: 28402.825 | AO4: 28885.125 | AP4: 29376.123 | AQ4: 29876.049 | AR4: 30385.2 | AS4: 30903.912 | AT4: 31432.542 | AU4: 31971.446 | AV4: 32522.489 | AW4: 33084.637 | AX4: 33658.204 | AY4: 34243.47 | AZ4: 34840.686 | BA4: 35450.138 | BB4: 36072.068 | BC4: 36706.685 | BD4: 37354.171 | BE4: 38014.692
A5: x_cagr_0 | B5: 15830.016 | C5: 16048.835 | D5: 16290.009 | E5: 16538.316 | F5: 16793.969 | G5: 17055.595 | H5: 17306.984 | I5: 17563.576 | J5: 17824.611 | K5: 18089.537 | L5: 18386.494 | M5: 18658.415 | N5: 18933.784 | O5: 19212.924 | P5: 19496.305 | Q5: 19784.474 | R5: 20078.175 | S5: 20378.147 | T5: 20685.071 | U5: 20999.549 | V5: 21301.056 | W5: 21632.599 | X5: 21973.764 | Y5: 22325.005 | Z5: 22686.745 | AA5: 22997.926 | AB5: 23352.561 | AC5: 23718.871 | AD5: 24097.304 | AE5: 24488.24 | AF5: 24892.032 | AG5: 25309.05 | AH5: 25739.583 | AI5: 26183.901 | AJ5: 26642.273 | AK5: 27114.905 | AL5: 27581.858 | AM5: 28057.94 | AN5: 28543.039 | AO5: 29037.145 | AP5: 29540.372 | AQ5: 30052.956 | AR5: 30575.205 | AS5: 31107.468 | AT5: 31650.114 | AU5: 32203.511 | AV5: 32769.476 | AW5: 33346.937 | AX5: 33936.209 | AY5: 34537.588 | AZ5: 35151.349 | BA5: 35777.716 | BB5: 36416.909 | BC5: 37069.144 | BD5: 37734.626 | BE5: 38413.552
A6: x_cfor_2 | B6: 41.818509 | C6: 42.3722 | D6: 42.991501 | E6: 43.638451 | F6: 44.311845 | G6: 45.005282 | H6: 45.673341 | I6: 46.354934 | J6: 47.04719 | K6: 47.748588 | L6: 48.53412 | M6: 49.253258 | N6: 49.981346 | O6: 50.719312 | P6: 51.468331 | Q6: 52.229694 | R6: 53.004535 | S6: 53.794274 | T6: 54.600392 | U6: 55.424312 | V6: 56.211593 | W6: 57.075331 | X6: 57.961507 | Y6: 58.871369 | Z6: 59.806175 | AA6: 60.604608 | AB6: 61.514369 | AC6: 62.451669 | AD6: 63.417829 | AE6: 64.414084 | AF6: 65.441634 | AG6: 66.501618 | AH6: 67.594932 | AI6: 68.72239 | AJ6: 69.884766 | AK6: 71.082629 | AL6: 72.263905 | AM6: 73.467399 | AN6: 74.692748 | AO6: 75.939877 | AP6: 77.209044 | AQ6: 78.500903 | AR6: 79.81623 | AS6: 81.155876 | AT6: 82.520719 | AU6: 83.911634 | AV6: 85.333715 | AW6: 86.784284 | AX6: 88.264155 | AY6: 89.774026 | AZ6: 91.314517 | BA6: 92.886517 | BB6: 94.490689 | BC6: 96.127562 | BD6: 97.797585 | BE6: 99.50116
A7: x_cfor_0 | B7: 41.818509 | C7: 42.372188 | D7: 42.991459 | E7: 43.638361 | F7: 44.311687 | G7: 45.005042 | H7: 45.672907 | I7: 46.354157 | J7: 47.045894 | K7: 47.746575 | L7: 48.531177 | M7: 49.249725 | N7: 49.977809 | O7: 50.716464 | P7: 51.4669 | Q7: 52.230388 | R7: 53.008954 | S7: 53.804343 | T7: 54.618092 | U7: 55.451554 | V7: 56.250115 | W7: 57.12754 | X7: 58.029941 | Y7: 58.958524 | Z7: 59.914423 | AA7: 60.735809 | AB7: 61.670904 | AC7: 62.635724 | AD7: 63.631512 | AE7: 64.659428 | AF7: 65.720616 | AG7: 66.81638 | AH7: 67.947686 | AI7: 69.115381 | AJ7: 70.320264 | AK7: 71.562925 | AL7: 72.790633 | AM7: 74.042297 | AN7: 75.317508 | AO7: 76.616204 | AP7: 77.938684 | AQ7: 79.285632 | AR7: 80.65788 | AS7: 82.056344 | AT7: 83.481978 | AU7: 84.935729 | AV7: 86.422386 | AW7: 87.939118 | AX7: 89.486758 | AY7: 91.06609 | AZ7: 92.677852 | BA7: 94.322575 | BB7: 96.000842 | BC7: 97.713245 | BD7: 99.460369 | BE7: 101.24277
A8: x_cfoo_2 | B8: 45348.86 | C8: 45979.169 | D8: 46673.414 | E8: 47387.894 | F8: 48123.562 | G8: 48876.922 | H8: 49601.871 | I8: 50342.812 | J8: 51097.552 | K8: 51864.4 | L8: 52723.992 | M8: 53512.213 | N8: 54310.361 | O8: 55119.139 | P8: 55939.765 | Q8: 56773.758 | R8: 57622.72 | S8: 58488.499 | T8: 59372.971 | U8: 60277.91 | V8: 61144.428 | W8: 62095.651 | X8: 63072.887 | Y8: 64077.489 | Z8: 65110.79 | AA8: 65997.48 | AB8: 67007.286 | AC8: 68049.037 | AD8: 69124.124 | AE8: 70233.756 | AF8: 71379.063 | AG8: 72561.066 | AH8: 73780.602 | AI8: 75038.484 | AJ8: 76335.534 | AK8: 77672.383 | AL8: 78991.831 | AM8: 80336.286 | AN8: 81705.431 | AO8: 83099.233 | AP8: 84517.99 | AQ8: 85962.319 | AR8: 87433.053 | AS8: 88931.156 | AT8: 90457.663 | AU8: 92013.626 | AV8: 93604.331 | AW8: 95226.791 | AX8: 96881.96 | AY8: 98570.704 | AZ8: 100293.81 | BA8: 102052.09 | BB8: 103846.25 | BC8: 105676.95 | BD8: 107544.74 | BE8: 109450.18
A9: x_cfoo_0 | B9: 45348.86 | C9: 45979.166 | D9: 46673.402 | E9: 47387.866 | F9: 48123.51 | G9: 48876.839 | H9: 49601.719 | I9: 50342.531 | J9: 51097.069 | K9: 51863.64 | L9: 52722.877 | M9: 53510.811 | N9: 54308.85 | O9: 55117.755 | P9: 55938.767 | Q9: 56773.406 | R9: 57623.503 | S9: 58491.071 | T9: 59378.067 | U9: 60286.283 | V9: 61156.804 | W9: 62112.943 | X9: 63096.109 | Y9: 64107.706 | Z9: 65149.07 | AA9: 66044.741 | AB9: 67064.634 | AC9: 68117.535 | AD9: 69204.836 | AE9: 70327.74 | AF9: 71487.369 | AG9: 72684.79 | AH9: 73920.878 | AI9: 75196.474 | AJ9: 76512.418 | AK9: 77869.356 | AL9: 79209.874 | AM9: 80576.428 | AN9: 81968.676 | AO9: 83386.583 | AP9: 84830.456 | AQ9: 86300.924 | AR9: 87798.837 | AS9: 89325.182 | AT9: 90881.017 | AU9: 92467.422 | AV9: 94089.628 | AW9: 95744.589 | AX9: 97433.25 | AY9: 99156.494 | AZ9: 100915.15 | BA9: 102709.93 | BB9: 104541.53 | BC9: 106410.58 | BD9: 108317.69 | BE9: 110263.42
A10: x_cveh_2 | B10: 111357.6 | C10: 112878.7 | D10: 114544.56 | E10: 116250.45 | F10: 118001.78 | G10: 119792.74 | H10: 121514.05 | I10: 123277.26 | J10: 125078.67 | K10: 126915.13 | L10: 128982.19 | M10: 130879.95 | N10: 132809.25 | O10: 134773.24 | P10: 136775.71 | Q10: 138820.65 | R10: 140911.76 | S10: 143052.97 | T10: 145248.07 | U10: 147500.36 | V10: 149666.34 | W10: 152045.28 | X10: 154491.36 | Y10: 157006.06 | Z10: 159591.32 | AA10: 161821.55 | AB10: 164357.3 | AC10: 166973.11 | AD10: 169670.18 | AE10: 172449.52 | AF10: 175312.37 | AG10: 178260.13 | AH10: 181294.11 | AI10: 184415.85 | AJ10: 187627.16 | AK10: 190929.62 | AL10: 194184.29 | AM10: 197496.68 | AN10: 200867.14 | AO10: 204296.74 | AP10: 207787.39 | AQ10: 211341.67 | AR10: 214962.34 | AS10: 218652.1 | AT10: 222413.38 | AU10: 226248.37 | AV10: 230169.42 | AW10: 234168.41 | AX10: 238246.84 | AY10: 242406.09 | AZ10: 246647.45 | BA10: 250972.41 | BB10: 255382.33 | BC10: 259878.46 | BD10: 264461.91 | BE10: 269133.78
A11: x_cveh_0 | B11: 111357.6 | C11: 112878.69 | D11: 114544.53 | E11: 116250.37 | F11: 118001.64 | G11: 119792.53 | H11: 121513.65 | I11: 123276.52 | J11: 125077.41 | K11: 126913.18 | L11: 128979.4 | M11: 130876.65 | N11: 132806.04 | O11: 134770.78 | P11: 136774.61 | Q11: 138821.43 | R11: 140915.62 | S11: 143061.53 | T11: 145262.98 | U11: 147523.18 | V11: 149698.41 | W11: 152088.53 | X11: 154547.94 | Y11: 157078.19 | Z11: 159681.11 | AA11: 161930.7 | AB11: 164487.95 | AC11: 167127.35 | AD11: 169850.1 | AE11: 172657.22 | AF11: 175549.92 | AG11: 178529.8 | AH11: 181598.28 | AI11: 184756.94 | AJ11: 188007.64 | AK11: 191351.97 | AL11: 194650.4 | AM11: 198008.53 | AN11: 201426.67 | AO11: 204905.95 | AP11: 208448.37 | AQ11: 212056.57 | AR11: 215733.39 | AS11: 219481.57 | AT11: 223303.61 | AU11: 227201.74 | AV11: 231188.06 | AW11: 235254.26 | AX11: 239401.88 | AY11: 243632.37 | AZ11: 247947.16 | BA11: 252347.46 | BB11: 256834.52 | BC11: 261409.6 | BD11: 266073.96 | BE11: 270828.81
A12: x_cgla_2 | B12: 5221.1985 | C12: 5293.7284 | D12: 5373.6419 | E12: 5455.9248 | F12: 5540.6932 | G12: 5627.5384 | H12: 5711.1403 | I12: 5796.5992 | J12: 5883.6522 | K12: 5972.0968 | L12: 6071.2176 | M12: 6162.114 | N12: 6254.1489 | O12: 6347.4058 | P12: 6442.0279 | Q12: 6538.1927 | R12: 6636.086 | S12: 6735.9217 | T12: 6837.9147 | U12: 6942.2669 | V12: 7042.1898 | W12: 7151.8624 | X12: 7264.5224 | Y12: 7380.3227 | Z12: 7499.4149 | AA12: 7601.5967 | AB12: 7717.9369 | AC12: 7837.9377 | AD12: 7961.7642 | AE12: 8089.5611 | AF12: 8221.4642 | AG12: 8357.5955 | AH12: 8498.0544 | AI12: 8642.9359 | AJ12: 8792.3358 | AK12: 8946.3274 | AL12: 9098.3098 | AM12: 9253.16 | AN12: 9410.8454 | AO12: 9571.374 | AP12: 9734.7955 | AQ12: 9901.1949 | AR12: 10070.678 | AS12: 10243.361 | AT12: 10419.365 | AU12: 10598.81 | AV12: 10782.301 | AW12: 10969.49 | AX12: 11160.482 | AY12: 11355.373 | AZ12: 11554.254 | BA12: 11757.217 | BB12: 11964.342 | BC12: 12175.706 | BD12: 12391.375 | BE12: 12611.411
... A55: x_cote_0 | B55: 4461.1306 | C55: 4523.3374 | D55: 4591.1779 | E55: 4660.3034 | F55: 4730.9845 | G55: 4803.1653 | H55: 4872.5758 | I55: 4943.7961 | J55: 5016.7866 | K55: 5091.5243 | L55: 5176.0925 | M55: 5254.4811 | N55: 5334.7212 | O55: 5416.8932 | P55: 5501.0973 | Q55: 5587.4382 | R55: 5676.0146 | S55: 5766.9349 | T55: 5860.3011 | U55: 5956.202 | V55: 6048.6867 | W55: 6149.8373 | X55: 6253.7839 | Y55: 6360.6045 | Z55: 6470.3857 | AA55: 6565.5355 | AB55: 6672.7441 | AC55: 6782.8668 | AD55: 6895.9829 | AE55: 7012.174 | AF55: 7131.5316 | AG55: 7254.15 | AH55: 7380.1199 | AI55: 7509.542 | AJ55: 7642.5281 | AK55: 7779.179 | AL55: 7913.8314 | AM55: 8050.8146 | AN55: 8190.1689 | AO55: 8331.9353 | AP55: 8476.1556 | AQ55: 8622.8723 | AR55: 8772.1285 | AS55: 8923.9682 | AT55: 9078.4363 | AU55: 9235.578 | AV55: 9395.8581 | AW55: 9558.9198 | AX55: 9724.8114 | AY55: 9893.5819 | AZ55: 10065.281 | BA55: 10239.961 | BB55: 10417.672 | BC55: 10598.466 | BD55: 10782.399 | BE55: 10969.524

Sheet Import
A1: _date_ | B1: 42005 | C1: 42370 | D1: 42736 | E1: 43101 | F1: 43466 | G1: 43831 | H1: 44197 | I1: 44562 | J1: 44927 | K1: 45292 | L1: 45658 | M1: 46023 | N1: 46388 | O1: 46753 | P1: 47119 | Q1: 47484 | R1: 47849 | S1: 48214 | T1: 48580 | U1: 48945 | V1: 49310 | W1: 49675 | X1: 50041 | Y1: 50406 | Z1: 50771 | AA1: 51136 | AB1: 51502 | AC1: 51867 | AD1: 52232 | AE1: 52597 | AF1: 52963 | AG1: 53328 | AH1: 53693 | AI1: 54058 | AJ1: 54424 | AK1: 54789 | AL1: 55154 | AM1: 55519 | AN1: 55885 | AO1: 56250 | AP1: 56615 | AQ1: 56980 | AR1: 57346 | AS1: 57711 | AT1: 58076 | AU1: 58441 | AV1: 58807 | AW1: 59172 | AX1: 59537 | AY1: 59902 | AZ1: 60268 | BA1: 60633 | BB1: 60998 | BC1: 61363 | BD1: 61729 | BE1: 62094
A2: m_2 | B2: 655454.5 | C2: 662236.08 | D2: 670200.99 | E2: 678711.23 | F2: 687595.77 | G2: 696828.93 | H2: 706038.37 | I2: 715511.08 | J2: 725325.2 | K2: 735511.93 | L2: 746824.87 | M2: 758087.44 | N2: 769619.33 | O2: 781461.33 | P2: 793624.78 | Q2: 806116.41 | R2: 818942.17 | S2: 832109.89 | T2: 845628.05 | U2: 859504.68 | V2: 873193.03 | W2: 887575.87 | X2: 902419.76 | Y2: 917698.49 | Z2: 933409.66 | AA2: 947937.32 | AB2: 963059.96 | AC2: 978509.8 | AD2: 994295.31 | AE2: 1010446.3 | AF2: 1026992.5 | AG2: 1043959.3 | AH2: 1061367 | AI2: 1079233 | AJ2: 1097573 | AK2: 1116401 | AL2: 1135231.3 | AM2: 1154258.9 | AN2: 1173520.4 | AO2: 1193035.8 | AP2: 1212821.3 | AQ2: 1232890 | AR2: 1253251.1 | AS2: 1273910 | AT2: 1294869.9 | AU2: 1316132.4 | AV2: 1337737.6 | AW2: 1359666.1 | AX2: 1381914.7 | AY2: 1404483.4 | AZ2: 1427374.2 | BA2: 1450591.3 | BB2: 1474139.4 | BC2: 1498024.2 | BD2: 1522251.9 | BE2: 1546830
A3: m_0 | B3: 655454.5 | C3: 662236.05 | D3: 670200.92 | E3: 678711.09 | F3: 687595.57 | G3: 696828.69 | H3: 706037.88 | I3: 715510.19 | J3: 725323.87 | K3: 735510.22 | L3: 746822.88 | M3: 758086.54 | N3: 769620.9 | O3: 781466.09 | P3: 793632.85 | Q3: 806127.44 | R3: 818957.87 | S3: 832131.9 | T3: 845656.9 | U3: 859539.73 | V3: 873232.81 | W3: 887620.49 | X3: 902469.17 | Y3: 917751.65 | Z3: 933464.52 | AA3: 947990.79 | AB3: 963109.38 | AC3: 978552.39 | AD3: 994327.89 | AE3: 1010465.3 | AF3: 1026994 | AG3: 1043939.8 | AH3: 1061322.6 | AI3: 1079159.3 | AJ3: 1097465.2 | AK3: 1116253.9 | AL3: 1135038.1 | AM3: 1154012.7 | AN3: 1173214.4 | AO3: 1192663.3 | AP3: 1212375.6 | AQ3: 1232364.3 | AR3: 1252638.2 | AS3: 1273202.8 | AT3: 1294060.9 | AU3: 1315214.1 | AV3: 1336701.3 | AW3: 1358502.8 | AX3: 1380616 | AY3: 1403041.3 | AZ3: 1425780.9 | BA3: 1448837.8 | BB3: 1472216.9 | BC3: 1495924.4 | BD3: 1519967.1 | BE3: 1544353
A4: m_cagr_2 | B4: 12975.415 | C4: 13062.869 | D4: 13167.825 | E4: 13296.077 | F4: 13447.344 | G4: 13619.419 | H4: 13803.121 | I4: 13998.293 | J4: 14204.27 | K4: 14420.434 | L4: 14657.936 | M4: 14901.405 | N4: 15151.874 | O4: 15409.244 | P4: 15673.351 | Q4: 15944.118 | R4: 16221.563 | S4: 16505.718 | T4: 16796.651 | U4: 17094.434 | V4: 17390.366 | W4: 17695.673 | X4: 18009.38 | Y4: 18331.398 | Z4: 18661.739 | AA4: 18974.737 | AB4: 19290.673 | AC4: 19609.584 | AD4: 19932.669 | AE4: 20261.157 | AF4: 20596.097 | AG4: 20938.312 | AH4: 21288.438 | AI4: 21646.961 | AJ4: 22014.275 | AK4: 22390.709 | AL4: 22769.007 | AM4: 23150.181 | AN4: 23534.678 | AO4: 23922.971 | AP4: 24315.539 | AQ4: 24712.778 | AR4: 25114.967 | AS4: 25522.254 | AT4: 25934.698 | AU4: 26352.306 | AV4: 26775.666 | AW4: 27204.635 | AX4: 27639.148 | AY4: 28079.182 | AZ4: 28524.767 | BA4: 28975.986 | BB4: 29432.968 | BC4: 29895.864 | BD4: 30364.859 | BE4: 30840.165
A5: m_cagr_0 | B5: 12975.415 | C5: 13062.873 | D5: 13167.834 | E5: 13296.092 | F5: 13447.369 | G5: 13619.458 | H5: 13803.217 | I5: 13998.466 | J5: 14204.528 | K5: 14420.781 | L5: 14658.382 | M5: 14901.864 | N5: 15152.316 | O5: 15409.64 | P5: 15673.661 | Q5: 15944.292 | R5: 16221.415 | S5: 16505.137 | T5: 16795.526 | U5: 17092.632 | V5: 17387.74 | W5: 17691.983 | X5: 18004.441 | Y5: 18325.025 | Z5: 18653.727 | AA5: 18964.88 | AB5: 19278.736 | AC5: 19595.357 | AD5: 19915.947 | AE5: 20241.736 | AF5: 20573.774 | AG5: 20912.87 | AH5: 21259.671 | AI5: 21614.659 | AJ5: 21978.222 | AK5: 22350.687 | AL5: 22724.799 | AM5: 23101.572 | AN5: 23481.465 | AO5: 23864.967 | AP5: 24252.566 | AQ5: 24644.662 | AR5: 25041.534 | AS5: 25443.336 | AT5: 25850.127 | AU5: 26261.919 | AV5: 26679.302 | AW5: 27102.136 | AX5: 27530.374 | AY5: 27964.015 | AZ5: 28403.101 | BA5: 28847.725 | BB5: 29298.014 | BC5: 29754.142 | BD5: 30216.313 | BE5: 30684.753
A6: m_cfor_2 | B6: 118.88748 | C6: 117.52236 | D6: 116.374 | E6: 115.53625 | F6: 115.01168 | G6: 114.76077 | H6: 114.71783 | I6: 114.89266 | J6: 115.26125 | K6: 115.79424 | L6: 116.56245 | M6: 117.38723 | N6: 118.29337 | O6: 119.27923 | P6: 120.33977 | Q6: 121.47004 | R6: 122.66301 | S6: 123.91718 | T6: 125.23127 | U6: 126.60391 | V6: 127.96285 | W6: 129.41995 | X6: 130.94516 | Y6: 132.53114 | Z6: 134.17525 | AA6: 135.67097 | AB6: 137.24723 | AC6: 138.87395 | AD6: 140.54749 | AE6: 142.26813 | AF6: 144.03728 | AG6: 145.85731 | AH6: 147.72951 | AI6: 149.65536 | AJ6: 151.6366 | AK6: 153.67497 | AL6: 155.71645 | AM6: 157.78409 | AN6: 159.88277 | AO6: 162.01459 | AP6: 164.1809 | AQ6: 166.38356 | AR6: 168.62269 | AS6: 170.89832 | AT6: 173.21046 | AU6: 175.5591 | AV6: 177.95164 | AW6: 180.38352 | AX6: 182.85285 | AY6: 185.35889 | AZ6: 187.90156 | BA6: 190.48271 | BB6: 193.1016 | BC6: 195.75804 | BD6: 198.45236 | BE6: 201.18519
A7: m_cfor_0 | B7: 118.88748 | C7: 117.52203 | D7: 116.37317 | E7: 115.53486 | F7: 115.00963 | G7: 114.75792 | H7: 114.70994 | I7: 114.8777 | J7: 115.2392 | K7: 115.76596 | L7: 116.52907 | M7: 117.36013 | N7: 118.27781 | O7: 119.27638 | P7: 120.34892 | Q7: 121.48978 | R7: 122.70758 | S7: 123.99195 | T7: 125.33587 | U7: 126.73558 | V7: 128.11807 | W7: 129.60686 | X7: 131.16567 | Y7: 132.78323 | Z7: 134.45536 | AA7: 135.97494 | AB7: 137.57458 | AC7: 139.22271 | AD7: 140.91479 | AE7: 142.65082 | AF7: 144.43221 | AG7: 146.26392 | AH7: 148.14589 | AI7: 150.0787 | AJ7: 152.0637 | AK7: 154.10246 | AL7: 156.1392 | AM7: 158.19819 | AN7: 160.28515 | AO7: 162.40252 | AP7: 164.55175 | AQ7: 166.73466 | AR7: 168.9513 | AS7: 171.20159 | AT7: 173.48541 | AU7: 175.80262 | AV7: 178.15799 | AW7: 180.54851 | AX7: 182.97327 | AY7: 185.43193 | AZ7: 187.92442 | BA7: 190.44967 | BB7: 193.00873 | BC7: 195.60252 | BD7: 198.23175 | BE7: 200.89707
A8: m_cfoo_2 | B8: 38720.704 | C8: 39029.707 | D8: 39387.145 | E8: 39805.175 | F8: 40283.362 | G8: 40816.319 | H8: 41376.82 | I8: 41967.783 | J8: 42588.151 | K8: 43236.766 | L8: 43949.897 | M8: 44675.956 | N8: 45422.359 | O8: 46189.349 | P8: 46976.759 | Q8: 47784.567 | R8: 48612.952 | S8: 49462.084 | T8: 50332.198 | U8: 51223.508 | V8: 52108.234 | W8: 53024.482 | X8: 53966.386 | Y8: 54933.498 | Z8: 55925.798 | AA8: 56861.368 | AB8: 57811.781 | AC8: 58772.523 | AD8: 59746.658 | AE8: 60737.518 | AF8: 61747.981 | AG8: 62780.339 | AH8: 63836.371 | AI8: 64917.473 | AJ8: 66024.804 | AK8: 67159.358 | AL8: 68297.631 | AM8: 69444.929 | AN8: 70602.759 | AO8: 71772.567 | AP8: 72955.762 | AQ8: 74153.489 | AR8: 75366.539 | AS8: 76595.324 | AT8: 77839.981 | AU8: 79100.497 | AV8: 80378.707 | AW8: 81673.968 | AX8: 82986.045 | AY8: 84314.844 | AZ8: 85660.417 | BA8: 87022.966 | BB8: 88402.847 | BC8: 89800.484 | BD8: 91216.393 | BE8: 92651.174
A9: m_cfoo_0 | B9: 38720.704 | C9: 39029.717 | D9: 39387.168 | E9: 39805.215 | F9: 40283.426 | G9: 40816.416 | H9: 41377.073 | I9: 41968.236 | J9: 42588.816 | K9: 43237.65 | L9: 43951.012 | M9: 44677.06 | N9: 45423.393 | O9: 46190.276 | P9: 46977.514 | Q9: 47785.054 | R9: 48612.69 | S9: 49460.84 | T9: 50329.753 | U9: 51219.582 | V9: 52102.491 | W9: 53016.311 | X9: 53955.349 | Y9: 54919.153 | Z9: 55907.651 | AA9: 56838.891 | AB9: 57784.355 | AC9: 58739.589 | AD9: 59707.664 | AE9: 60691.908 | AF9: 61695.194 | AG9: 62719.764 | AH9: 63767.436 | AI9: 64839.594 | AJ9: 65937.382 | AK9: 67061.774 | AL9: 68189.278 | AM9: 69325.177 | AN9: 70471.009 | AO9: 71628.258 | AP9: 72798.359 | AQ9: 73982.468 | AR9: 75181.383 | AS9: 76395.523 | AT9: 77625.035 | AU9: 78869.916 | AV9: 80132.015 | AW9: 81410.672 | AX9: 82705.703 | AY9: 84017.066 | AZ9: 85344.854 | BA9: 86689.302 | BB9: 88050.749 | BC9: 89429.673 | BD9: 90826.651 | BE9: 92242.328
A10: m_cveh_2 | B10: 82042.191 | C10: 83964.324 | D10: 86327.584 | E10: 88510.103 | F10: 90362.375 | G10: 91924.876 | H10: 93225.379 | I10: 94397.701 | J10: 95519.538 | K10: 96636.199 | L10: 97893.534 | M10: 99101.235 | N10: 100316.74 | O10: 101552.95 | P10: 102814.16 | Q10: 104102.06 | R10: 105417.42 | S10: 106760.85 | T10: 108133.05 | U10: 109534.63 | V10: 110877.01 | W10: 112308.83 | X10: 113790.85 | Y10: 115314.56 | Z10: 116877.1 | AA10: 118220.71 | AB10: 119648.45 | AC10: 121123.15 | AD10: 122642.69 | AE10: 124208.22 | AF10: 125820.8 | AG10: 127481.01 | AH10: 129188.97 | AI10: 130944.71 | AJ10: 132748.48 | AK10: 134600.65 | AL10: 136426.6 | AM10: 138260.95 | AN10: 140113.66 | AO10: 141990.13 | AP10: 143893.76 | AQ10: 145826.56 | AR10: 147789.46 | AS10: 149782.74 | AT10: 151806.48 | AU10: 153860.79 | AV10: 155951.78 | AW10: 158076.34 | AX10: 160233.97 | AY10: 162424.93 | AZ10: 164649.89 | BA10: 166909.9 | BB10: 169205.99 | BC10: 171539.13 | BD10: 173910.34 | BE10: 176320.67
A11: m_cveh_0 | B11: 82042.191 | C11: 83964.322 | D11: 86327.576 | E11: 88510.092 | F11: 90362.365 | G11: 91924.871 | H11: 93225.362 | I11: 94397.649 | J11: 95519.456 | K11: 96636.102 | L11: 97893.437 | M11: 99101.322 | N11: 100317.19 | O11: 101553.76 | P11: 102815.2 | Q11: 104103.24 | R11: 105418.98 | S11: 106763.15 | T11: 108136.13 | U11: 109538.39 | V11: 110881.31 | W11: 112313.9 | X11: 113797.03 | Y11: 115321.99 | Z11: 116885.78 | AA11: 118230.54 | AB11: 119659.54 | AC11: 121135.68 | AD11: 122656.78 | AE11: 124223.98 | AF11: 125838.33 | AG11: 127500.48 | AH11: 129210.54 | AI11: 130968.49 | AJ11: 132774.53 | AK11: 134629 | AL11: 136457.09 | AM11: 138293.4 | AN11: 140148.01 | AO11: 142026.37 | AP11: 143931.89 | AQ11: 145866.54 | AR11: 147831.2 | AS11: 149826.15 | AT11: 151851.44 | AU11: 153907.18 | AV11: 155999.28 | AW11: 158124.6 | AX11: 160282.74 | AY11: 162474.05 | AZ11: 164699.19 | BA11: 166958.96 | BB11: 169254.34 | BC11: 171586.39 | BD11: 173956.18 | BE11: 176364.75
A12: m_cgla_2 | B12: 6981.7019 | C12: 7058.979 | D12: 7142.4194 | E12: 7232.4182 | F12: 7329.1165 | G12: 7432.2248 | H12: 7537.9431 | I12: 7647.5832 | J12: 7761.464 | K12: 7879.7178 | L12: 8008.7448 | M12: 8139.6448 | N12: 8274.2112 | O12: 8412.8539 | P12: 8555.7794 | Q12: 8703.1575 | R12: 8855.1458 | S12: 9011.9047 | T12: 9173.5954 | U12: 9340.3694 | V12: 9507.6272 | W12: 9682.1931 | X12: 9862.9172 | Y12: 10049.679 | Z12: 10242.522 | AA12: 10427.614 | AB12: 10617.922 | AC12: 10812.385 | AD12: 11011.217 | AE12: 11214.775 | AF12: 11423.409 | AG12: 11637.43 | AH12: 11857.099 | AI12: 12082.644 | AJ12: 12314.273 | AK12: 12552.171 | AL12: 12792.135 | AM12: 13035.122 | AN12: 13281.301 | AO12: 13530.759 | AP12: 13783.579 | AQ12: 14039.842 | AR12: 14299.598 | AS12: 14562.858 | AT12: 14829.597 | AU12: 15099.763 | AV12: 15373.634 | AW12: 15651.02 | AX12: 15931.804 | AY12: 16215.89 | AZ12: 16503.194 | BA12: 16793.663 | BB12: 17087.257 | BC12: 17383.943 | BD12: 17683.704 | BE12: 17986.537
... A55: m_cote_0 | B55: 2283.934 | C55: 2308.8687 | D55: 2335.259 | E55: 2363.2665 | F55: 2393.2172 | G55: 2424.9928 | H55: 2456.7352 | I55: 2489.6495 | J55: 2523.7103 | K55: 2558.8173 | L55: 2597.9756 | M55: 2635.6128 | N55: 2673.8403 | O55: 2712.8462 | P55: 2752.6848 | Q55: 2793.3976 | R55: 2835.0592 | S55: 2877.7127 | T55: 2921.4082 | U55: 2966.1979 | V55: 3009.8401 | W55: 3056.5373 | X55: 3104.7365 | Y55: 3154.336 | Z55: 3205.3541 | AA55: 3251.1303 | AB55: 3300.5156 | AC55: 3351.3717 | AD55: 3403.614 | AE55: 3457.2979 | AF55: 3512.4982 | AG55: 3569.2935 | AH55: 3627.7408 | AI55: 3687.8922 | AJ55: 3749.7979 | AK55: 3813.4995 | AL55: 3876.8996 | AM55: 3941.2175 | AN55: 4006.5664 | AO55: 4072.9736 | AP55: 4140.4589 | AQ55: 4209.049 | AR55: 4278.7713 | AS55: 4349.6553 | AT55: 4421.7309 | AU55: 4495.0273 | AV55: 4569.7312 | AW55: 4645.7484 | AX55: 4723.0924 | AY55: 4801.7856 | AZ55: 4881.8527 | BA55: 4963.3152 | BB55: 5046.1997 | BC55: 5130.5326 | BD55: 5216.3404 | BE55: 5303.6498

Sheet Carbontax
A1: _date_ | B1: 42005 | C1: 42370 | D1: 42736 | E1: 43101 | F1: 43466 | G1: 43831 | H1: 44197 | I1: 44562 | J1: 44927 | K1: 45292 | L1: 45658 | M1: 46023 | N1: 46388 | O1: 46753 | P1: 47119 | Q1: 47484 | R1: 47849 | S1: 48214 | T1: 48580 | U1: 48945 | V1: 49310 | W1: 49675 | X1: 50041 | Y1: 50406 | Z1: 50771 | AA1: 51136 | AB1: 51502 | AC1: 51867 | AD1: 52232 | AE1: 52597 | AF1: 52963 | AG1: 53328 | AH1: 53693 | AI1: 54058 | AJ1: 54424 | AK1: 54789 | AL1: 55154 | AM1: 55519 | AN1: 55885 | AO1: 56250 | AP1: 56615 | AQ1: 56980 | AR1: 57346 | AS1: 57711 | AT1: 58076 | AU1: 58441 | AV1: 58807 | AW1: 59172 | AX1: 59537 | AY1: 59902 | AZ1: 60268 | BA1: 60633 | BB1: 60998 | BC1: 61363 | BD1: 61729 | BE1: 62094
A2: t2val_ch_0 | B2: 0 | C2: 0 | D2: 0 | E2: 0 | F2: 0 | G2: 0 | H2: 0 | I2: 0 | J2: 0 | K2: 0 | L2: 0 | M2: 0 | N2: 0 | O2: 0 | P2: 0 | Q2: 0 | R2: 0 | S2: 0 | T2: 0 | U2: 0 | V2: 0 | W2: 0 | X2: 0 | Y2: 0 | Z2: 0 | AA2: 0 | AB2: 0 | AC2: 0 | AD2: 0 | AE2: 0 | AF2: 0 | AG2: 0 | AH2: 0 | AI2: 0 | AJ2: 0 | AK2: 0 | AL2: 0 | AM2: 0 | AN2: 0 | AO2: 0 | AP2: 0 | AQ2: 0 | AR2: 0 | AS2: 0 | AT2: 0 | AU2: 0 | AV2: 0 | AW2: 0 | AX2: 0 | AY2: 0 | AZ2: 0 | BA2: 0 | BB2: 0 | BC2: 0 | BD2: 0 | BE2: 0
A3: t2val_ch_2 | B3: 0 | C3: 0 | D3: 0 | E3: 0 | F3: 0 | G3: 0 | H3: 0 | I3: 0 | J3: 0 | K3: 0 | L3: 0 | M3: 0 | N3: 0 | O3: 0 | P3: 0 | Q3: 0 | R3: 0 | S3: 0 | T3: 0 | U3: 0 | V3: 0 | W3: 0 | X3: 0 | Y3: 0 | Z3: 0 | AA3: 0 | AB3: 0 | AC3: 0 | AD3: 0 | AE3: 0 | AF3: 0 | AG3: 0 | AH3: 0 | AI3: 0 | AJ3: 0 | AK3: 0 | AL3: 0 | AM3: 0 | AN3: 0 | AO3: 0 | AP3: 0 | AQ3: 0 | AR3: 0 | AS3: 0 | AT3: 0 | AU3: 0 | AV3: 0 | AW3: 0 | AX3: 0 | AY3: 0 | AZ3: 0 | BA3: 0 | BB3: 0 | BC3: 0 | BD3: 0 | BE3: 0
A4: t2val_sec_0 | B4: 0 | C4: 0 | D4: 0 | E4: 0 | F4: 0 | G4: 0 | H4: 0 | I4: 0 | J4: 0 | K4: 0 | L4: 0 | M4: 0 | N4: 0 | O4: 0 | P4: 0 | Q4: 0 | R4: 0 | S4: 0 | T4: 0 | U4: 0 | V4: 0 | W4: 0 | X4: 0 | Y4: 0 | Z4: 0 | AA4: 0 | AB4: 0 | AC4: 0 | AD4: 0 | AE4: 0 | AF4: 0 | AG4: 0 | AH4: 0 | AI4: 0 | AJ4: 0 | AK4: 0 | AL4: 0 | AM4: 0 | AN4: 0 | AO4: 0 | AP4: 0 | AQ4: 0 | AR4: 0 | AS4: 0 | AT4: 0 | AU4: 0 | AV4: 0 | AW4: 0 | AX4: 0 | AY4: 0 | AZ4: 0 | BA4: 0 | BB4: 0 | BC4: 0 | BD4: 0 | BE4: 0
A5: t2val_sec_2 | B5: 0 | C5: 0 | D5: 0 | E5: 0 | F5: 0 | G5: 0 | H5: 0 | I5: 0 | J5: 0 | K5: 0 | L5: 0 | M5: 0 | N5: 0 | O5: 0 | P5: 0 | Q5: 0 | R5: 0 | S5: 0 | T5: 0 | U5: 0 | V5: 0 | W5: 0 | X5: 0 | Y5: 0 | Z5: 0 | AA5: 0 | AB5: 0 | AC5: 0 | AD5: 0 | AE5: 0 | AF5: 0 | AG5: 0 | AH5: 0 | AI5: 0 | AJ5: 0 | AK5: 0 | AL5: 0 | AM5: 0 | AN5: 0 | AO5: 0 | AP5: 0 | AQ5: 0 | AR5: 0 | AS5: 0 | AT5: 0 | AU5: 0 | AV5: 0 | AW5: 0 | AX5: 0 | AY5: 0 | AZ5: 0 | BA5: 0 | BB5: 0 | BC5: 0 | BD5: 0 | BE5: 0
A6: t2val_ci_0 | B6: 0 | C6: 0 | D6: 0 | E6: 0 | F6: 0 | G6: 0 | H6: 0 | I6: 0 | J6: 0 | K6: 0 | L6: 0 | M6: 0 | N6: 0 | O6: 0 | P6: 0 | Q6: 0 | R6: 0 | S6: 0 | T6: 0 | U6: 0 | V6: 0 | W6: 0 | X6: 0 | Y6: 0 | Z6: 0 | AA6: 0 | AB6: 0 | AC6: 0 | AD6: 0 | AE6: 0 | AF6: 0 | AG6: 0 | AH6: 0 | AI6: 0 | AJ6: 0 | AK6: 0 | AL6: 0 | AM6: 0 | AN6: 0 | AO6: 0 | AP6: 0 | AQ6: 0 | AR6: 0 | AS6: 0 | AT6: 0 | AU6: 0 | AV6: 0 | AW6: 0 | AX6: 0 | AY6: 0 | AZ6: 0 | BA6: 0 | BB6: 0 | BC6: 0 | BD6: 0 | BE6: 0
A7: t2val_ci_2 | B7: 0 | C7: 0 | D7: 0 | E7: 0 | F7: 0 | G7: 0 | H7: 0 | I7: 0 | J7: 0 | K7: 0 | L7: 0 | M7: 0 | N7: 0 | O7: 0 | P7: 0 | Q7: 0 | R7: 0 | S7: 0 | T7: 0 | U7: 0 | V7: 0 | W7: 0 | X7: 0 | Y7: 0 | Z7: 0 | AA7: 0 | AB7: 0 | AC7: 0 | AD7: 0 | AE7: 0 | AF7: 0 | AG7: 0 | AH7: 0 | AI7: 0 | AJ7: 0 | AK7: 0 | AL7: 0 | AM7: 0 | AN7: 0 | AO7: 0 | AP7: 0 | AQ7: 0 | AR7: 0 | AS7: 0 | AT7: 0 | AU7: 0 | AV7: 0 | AW7: 0 | AX7: 0 | AY7: 0 | AZ7: 0 | BA7: 0 | BB7: 0 | BC7: 0 | BD7: 0 | BE7: 0
A8: t2val_y_0 | B8: 0 | C8: 0 | D8: 0 | E8: 0 | F8: 0 | G8: 0 | H8: 0 | I8: 0 | J8: 0 | K8: 0 | L8: 0 | M8: 0 | N8: 0 | O8: 0 | P8: 0 | Q8: 0 | R8: 0 | S8: 0 | T8: 0 | U8: 0 | V8: 0 | W8: 0 | X8: 0 | Y8: 0 | Z8: 0 | AA8: 0 | AB8: 0 | AC8: 0 | AD8: 0 | AE8: 0 | AF8: 0 | AG8: 0 | AH8: 0 | AI8: 0 | AJ8: 0 | AK8: 0 | AL8: 0 | AM8: 0 | AN8: 0 | AO8: 0 | AP8: 0 | AQ8: 0 | AR8: 0 | AS8: 0 | AT8: 0 | AU8: 0 | AV8: 0 | AW8: 0 | AX8: 0 | AY8: 0 | AZ8: 0 | BA8: 0 | BB8: 0 | BC8: 0 | BD8: 0 | BE8: 0
A9: t2val_y_2 | B9: 0 | C9: 0 | D9: 0 | E9: 0 | F9: 0 | G9: 0 | H9: 0 | I9: 0 | J9: 0 | K9: 0 | L9: 0 | M9: 0 | N9: 0 | O9: 0 | P9: 0 | Q9: 0 | R9: 0 | S9: 0 | T9: 0 | U9: 0 | V9: 0 | W9: 0 | X9: 0 | Y9: 0 | Z9: 0 | AA9: 0 | AB9: 0 | AC9: 0 | AD9: 0 | AE9: 0 | AF9: 0 | AG9: 0 | AH9: 0 | AI9: 0 | AJ9: 0 | AK9: 0 | AL9: 0 | AM9: 0 | AN9: 0 | AO9: 0 | AP9: 0 | AQ9: 0 | AR9: 0 | AS9: 0 | AT9: 0 | AU9: 0 | AV9: 0 | AW9: 0 | AX9: 0 | AY9: 0 | AZ9: 0 | BA9: 0 | BB9: 0 | BC9: 0 | BD9: 0 | BE9: 0
A10: t2val_mat_0 | B10: 0 | C10: 0 | D10: 0 | E10: 0 | F10: 0 | G10: 0 | H10: 0 | I10: 0 | J10: 0 | K10: 0 | L10: 0 | M10: 0 | N10: 0 | O10: 0 | P10: 0 | Q10: 0 | R10: 0 | S10: 0 | T10: 0 | U10: 0 | V10: 0 | W10: 0 | X10: 0 | Y10: 0 | Z10: 0 | AA10: 0 | AB10: 0 | AC10: 0 | AD10: 0 | AE10: 0 | AF10: 0 | AG10: 0 | AH10: 0 | AI10: 0 | AJ10: 0 | AK10: 0 | AL10: 0 | AM10: 0 | AN10: 0 | AO10: 0 | AP10: 0 | AQ10: 0 | AR10: 0 | AS10: 0 | AT10: 0 | AU10: 0 | AV10: 0 | AW10: 0 | AX10: 0 | AY10: 0 | AZ10: 0 | BA10: 0 | BB10: 0 | BC10: 0 | BD10: 0 | BE10: 0
A11: t2val_mat_2 | B11: 0 | C11: 0 | D11: 0 | E11: 0 | F11: 0 | G11: 0 | H11: 0 | I11: 0 | J11: 0 | K11: 0 | L11: 0 | M11: 0 | N11: 0 | O11: 0 | P11: 0 | Q11: 0 | R11: 0 | S11: 0 | T11: 0 | U11: 0 | V11: 0 | W11: 0 | X11: 0 | Y11: 0 | Z11: 0 | AA11: 0 | AB11: 0 | AC11: 0 | AD11: 0 | AE11: 0 | AF11: 0 | AG11: 0 | AH11: 0 | AI11: 0 | AJ11: 0 | AK11: 0 | AL11: 0 | AM11: 0 | AN11: 0 | AO11: 0 | AP11: 0 | AQ11: 0 | AR11: 0 | AS11: 0 | AT11: 0 | AU11: 0 | AV11: 0 | AW11: 0 | AX11: 0 | AY11: 0 | AZ11: 0 | BA11: 0 | BB11: 0 | BC11: 0 | BD11: 0 | BE11: 0

Sheet Production
A1: _date_ | B1: 42005 | C1: 42370 | D1: 42736 | E1: 43101 | F1: 43466 | G1: 43831 | H1: 44197 | I1: 44562 | J1: 44927 | K1: 45292 | L1: 45658 | M1: 46023 | N1: 46388 | O1: 46753 | P1: 47119 | Q1: 47484 | R1: 47849 | S1: 48214 | T1: 48580 | U1: 48945 | V1: 49310 | W1: 49675 | X1: 50041 | Y1: 50406 | Z1: 50771 | AA1: 51136 | AB1: 51502 | AC1: 51867 | AD1: 52232 | AE1: 52597 | AF1: 52963 | AG1: 53328 | AH1: 53693 | AI1: 54058 | AJ1: 54424 | AK1: 54789 | AL1: 55154 | AM1: 55519 | AN1: 55885 | AO1: 56250 | AP1: 56615 | AQ1: 56980 | AR1: 57346 | AS1: 57711 | AT1: 58076 | AU1: 58441 | AV1: 58807 | AW1: 59172 | AX1: 59537 | AY1: 59902 | AZ1: 60268 | BA1: 60633 | BB1: 60998 | BC1: 61363 | BD1: 61729 | BE1: 62094
A2: y_2 | B2: 3854754.7 | C2: 3897709.5 | D2: 3945032.4 | E2: 3995958.7 | F2: 4050429.8 | G2: 4108101.8 | H2: 4166197 | I2: 4226197.2 | J2: 4288121.1 | K2: 4351916.6 | L2: 4422069.3 | M2: 4490979.4 | N2: 4561178.5 | O2: 4632823.6 | P2: 4705999.1 | Q2: 4780790.1 | R2: 4857284.5 | S2: 4935585.1 | T2: 5015798.6 | U2: 5098026 | V2: 5178980.3 | W2: 5264371.9 | X2: 5352392 | Y2: 5443007.9 | Z2: 5536259 | AA2: 5622320.4 | AB2: 5712879.2 | AC2: 5805482.3 | AD2: 5900281.6 | AE2: 5997485.2 | AF2: 6097285.9 | AG2: 6199845.8 | AH2: 6305290.8 | AI2: 6413723.2 | AJ2: 6525231.9 | AK2: 6639889.6 | AL2: 6754635.2 | AM2: 6870848.1 | AN2: 6988621.5 | AO2: 7108026.3 | AP2: 7229144.4 | AQ2: 7352063.7 | AR2: 7476860.8 | AS2: 7603597.2 | AT2: 7732320 | AU2: 7863066 | AV2: 7996109.3 | AW2: 8131334.2 | AX2: 8268746.7 | AY2: 8408359.6 | AZ2: 8550190.9 | BA2: 8694272.5 | BB2: 8840634.7 | BC2: 8989308.8 | BD2: 9140327.6 | BE2: 9293727.1
A3: y_0 | B3: 3854754.7 | C3: 3897709.2 | D3: 3945031.5 | E3: 3995956.9 | F3: 4050426.8 | G3: 4108097.5 | H3: 4166189.4 | I3: 4226182.9 | J3: 4288096.5 | K3: 4351878.4 | L3: 4422014.6 | M3: 4490918.3 | N3: 4561126.7 | O3: 4632796.2 | P3: 4706008.5 | Q3: 4780845.7 | R3: 4857416.3 | S3: 4935830.9 | T3: 5016193.7 | U3: 5098599.9 | V3: 5179756.3 | W3: 5265389.1 | X3: 5353693.9 | Y3: 5444635.3 | Z3: 5538247 | AA3: 5624693.6 | AB3: 5715668.3 | AC3: 5808716.8 | AD3: 5903989.2 | AE3: 6001691.1 | AF3: 6102013 | AG3: 6205120.4 | AH3: 6311139.6 | AI3: 6420171.1 | AJ3: 6532301.7 | AK3: 6647601.8 | AL3: 6762995.1 | AM3: 6879857.7 | AN3: 6998281.9 | AO3: 7118339.1 | AP3: 7240111.8 | AQ3: 7363686.9 | AR3: 7489140.5 | AS3: 7616533.6 | AT3: 7745912.9 | AU3: 7877314.9 | AV3: 8011002.6 | AW3: 8146856.2 | AX3: 8284883.1 | AY3: 8425099 | AZ3: 8567524.9 | BA3: 8712181.9 | BB3: 8859098.2 | BC3: 9008308 | BD3: 9159849.1 | BE3: 9313761.8
A4: y_sagr_2 | B4: 81770.816 | C4: 82352.926 | D4: 83061.719 | E4: 83911.757 | F4: 84897.839 | G4: 86002.299 | H4: 87157.556 | I4: 88376.851 | J4: 89653.773 | K4: 90982.356 | L4: 92446.697 | M4: 93904.671 | N4: 95391.87 | O4: 96909.127 | P4: 98456.509 | Q4: 100034.66 | R4: 101644.72 | S4: 103288.23 | T4: 104967.01 | U4: 106682.9 | V4: 108371.61 | W4: 110137.59 | X4: 111954.16 | Y4: 113820.88 | Z4: 115738.52 | AA4: 117515.19 | AB4: 119357.91 | AC4: 121233.96 | AD4: 123148.64 | AE4: 125108.05 | AF4: 127117.46 | AG4: 129181.05 | AH4: 131301.91 | AI4: 133482.33 | AJ4: 135724.14 | AK4: 138028.71 | AL4: 140337.68 | AM4: 142672.16 | AN4: 145034.28 | AO4: 147425.91 | AP4: 149849.26 | AQ4: 152306.61 | AR4: 154800.01 | AS4: 157331.08 | AT4: 159901.11 | AU4: 162511.14 | AV4: 165166.83 | AW4: 167866.91 | AX4: 170611.79 | AY4: 173402 | AZ4: 176238.18 | BA4: 179121.3 | BB4: 182052.39 | BC4: 185032.44 | BD4: 188062.5 | BE4: 191143.62
A5: y_sagr_0 | B5: 81770.816 | C5: 82352.93 | D5: 83061.719 | E5: 83911.743 | F5: 84897.804 | G5: 86002.242 | H5: 87157.555 | I5: 88376.836 | J5: 89653.6 | K5: 90981.875 | L5: 92445.772 | M5: 93903.212 | N5: 95390.265 | O5: 96907.908 | P5: 98456.17 | Q5: 100035.6 | R5: 101647.42 | S5: 103293.8 | T5: 104976.71 | U5: 106697.86 | V5: 108392.74 | W5: 110165.85 | X5: 111990.92 | Y5: 113867.58 | Z5: 115796.42 | AA5: 117585.22 | AB5: 119441.07 | AC5: 121331.26 | AD5: 123261.1 | AE5: 125236.61 | AF5: 127263.02 | AG5: 129344.55 | AH5: 131484.4 | AI5: 133684.89 | AJ5: 135947.82 | AK5: 138274.55 | AL5: 140606.37 | AM5: 142964.3 | AN5: 145350.46 | AO5: 147766.78 | AP5: 150215.53 | AQ5: 152699.04 | AR5: 155219.39 | AS5: 157778.26 | AT5: 160376.98 | AU5: 163016.65 | AV5: 165702.75 | AW5: 168433.87 | AX5: 171210.47 | AY5: 174033.2 | AZ5: 176902.84 | BA5: 179820.19 | BB5: 182786.15 | BC5: 185801.83 | BD5: 188868.42 | BE5: 191987.15
A6: y_sfor_2 | B6: 6535.3702 | C6: 6519.1746 | D6: 6486.1068 | E6: 6451.9393 | F6: 6421.995 | G6: 6396.1814 | H6: 6374.7714 | I6: 6359.9158 | J6: 6350.8975 | K6: 6346.5173 | L6: 6350.3644 | M6: 6353.5489 | N6: 6357.9272 | O6: 6363.7364 | P6: 6370.9787 | Q6: 6379.5871 | R6: 6389.0767 | S6: 6399.6333 | T6: 6411.3332 | U6: 6424.2039 | V6: 6435.0518 | W6: 6449.2438 | X6: 6465.2453 | Y6: 6482.7325 | Z6: 6501.584 | AA6: 6512.7809 | AB6: 6527.2583 | AC6: 6543.3376 | AD6: 6560.8185 | AE6: 6579.6448 | AF6: 6599.8176 | AG6: 6621.4544 | AH6: 6644.5241 | AI6: 6669.0261 | AJ6: 6694.9735 | AK6: 6722.3815 | AL6: 6749.7467 | AM6: 6777.8944 | AN6: 6806.902 | AO6: 6836.7873 | AP6: 6867.5565 | AQ6: 6899.349 | AR6: 6932.1 | AS6: 6965.7876 | AT6: 7000.4117 | AU6: 7035.9822 | AV6: 7073.1304 | AW6: 7111.5023 | AX6: 7150.9686 | AY6: 7191.483 | AZ6: 7233.0361 | BA6: 7275.901 | BB6: 7319.9399 | BC6: 7365.0971 | BD6: 7411.3575 | BE6: 7458.7241
A7: y_sfor_0 | B7: 6535.3702 | C7: 6519.1283 | D7: 6485.9932 | E7: 6451.7479 | F7: 6421.7099 | G7: 6395.7817 | H7: 6373.6833 | I7: 6357.9025 | J7: 6347.941 | K7: 6342.6872 | L7: 6345.7446 | M7: 6349.6813 | N7: 6355.4627 | O7: 6362.9058 | P7: 6371.8332 | Q7: 6382.1105 | R7: 6395.4748 | S7: 6410.7899 | T7: 6427.5238 | U7: 6445.4534 | V7: 6461.2861 | W7: 6482.0224 | X7: 6505.172 | Y7: 6529.9768 | Z7: 6556.1406 | AA7: 6574.5138 | AB7: 6596.5589 | AC7: 6620.3273 | AD7: 6645.5017 | AE7: 6671.9833 | AF7: 6699.7642 | AG7: 6729.3262 | AH7: 6760.4351 | AI7: 6792.9996 | AJ7: 6826.9982 | AK7: 6862.4365 | AL7: 6897.5022 | AM7: 6933.1917 | AN7: 6969.6648 | AO7: 7006.9759 | AP7: 7045.1466 | AQ7: 7084.3183 | AR7: 7124.4289 | AS7: 7165.457 | AT7: 7207.4021 | AU7: 7250.2738 | AV7: 7294.3121 | AW7: 7339.3801 | AX7: 7385.4511 | AY7: 7432.5237 | AZ7: 7480.6077 | BA7: 7529.532 | BB7: 7579.4214 | BC7: 7630.3427 | BD7: 7682.3332 | BE7: 7735.417
A8: y_sfoo_2 | B8: 157694.98 | C8: 159128.24 | D8: 160764.14 | E8: 162630.67 | F8: 164724.77 | G8: 167020.8 | H8: 169396.48 | I8: 171878.42 | J8: 174458.67 | K8: 177129.59 | L8: 180053.28 | M8: 182969.52 | N8: 185940.54 | O8: 188967.67 | P8: 192051.46 | Q8: 195193.61 | R8: 198396.92 | S8: 201664.56 | T8: 205000.2 | U8: 208407.49 | V8: 211764.47 | W8: 215264.26 | X8: 218861.19 | Y8: 222555.46 | Z8: 226348.66 | AA8: 229876.44 | AB8: 233516.84 | AC8: 237214.98 | AD8: 240983.39 | AE8: 244835.13 | AF8: 248781.26 | AG8: 252830.44 | AH8: 256989.1 | AI8: 261262.03 | AJ8: 265652.97 | AK8: 270164.81 | AL8: 274687.78 | AM8: 279258 | AN8: 283879.12 | AO8: 288555.06 | AP8: 293290.47 | AQ8: 298089.95 | AR8: 302957.47 | AS8: 307896.08 | AT8: 312908.08 | AU8: 317995.28 | AV8: 323168.03 | AW8: 328424.04 | AX8: 333764.01 | AY8: 339188.85 | AZ8: 344699.74 | BA8: 350298.37 | BB8: 355986.73 | BC8: 361766.78 | BD8: 367640.62 | BE8: 373610.45
A9: y_sfoo_0 | B9: 157694.98 | C9: 159128.26 | D9: 160764.18 | E9: 162630.73 | F9: 164724.84 | G9: 167020.9 | H9: 169396.91 | I9: 171879.18 | J9: 174459.58 | K9: 177130.43 | L9: 180053.89 | M9: 182969.23 | N9: 185939.66 | O9: 188966.79 | P9: 192051.15 | Q9: 195194.33 | R9: 198398.44 | S9: 201668.02 | T9: 205007.06 | U9: 208419.05 | V9: 211781.76 | W9: 215287.84 | X9: 218892.57 | Y9: 222596.26 | Z9: 226400.34 | AA9: 229940.04 | AB9: 233593.29 | AC9: 237305.41 | AD9: 241088.91 | AE9: 244956.82 | AF9: 248920.12 | AG9: 252987.43 | AH9: 257165.4 | AI9: 261458.85 | AJ9: 265871.51 | AK9: 270406.22 | AL9: 274952.83 | AM9: 279547.26 | AN9: 284193.18 | AO9: 288894.63 | AP9: 293656.34 | AQ9: 298482.98 | AR9: 303378.58 | AS9: 308346.28 | AT9: 313388.45 | AU9: 318506.98 | AV9: 323712.08 | AW9: 329001.22 | AX9: 334375.21 | AY9: 339835.15 | AZ9: 345382.44 | BA9: 351018.65 | BB9: 356745.56 | BC9: 362565.28 | BD9: 368480.18 | BE9: 374492.71
A10: y_sveh_2 | B10: 125718.96 | C10: 127855.06 | D10: 130282.43 | E10: 132655.27 | F10: 134914.79 | G10: 137074.21 | H10: 139058.94 | I10: 141015.45 | J10: 142975.26 | K10: 144955.77 | L10: 147174.88 | M10: 149233.47 | N10: 151314.67 | O10: 153428.09 | P10: 155579.65 | Q10: 157774.1 | R10: 160015.36 | S10: 162307.46 | T10: 164654.22 | U10: 167059 | V10: 169370.58 | W10: 171890.3 | X10: 174486.82 | Y10: 177157.01 | Z10: 179900.92 | AA10: 182271.3 | AB10: 184921.73 | AC10: 187660.53 | AD10: 190486.95 | AE10: 193401.81 | AF10: 196406.14 | AG10: 199501 | AH10: 202687.18 | AI10: 205965.64 | AJ10: 209337.7 | AK10: 212804.54 | AL10: 216223.58 | AM10: 219692.4 | AN10: 223215.78 | AO10: 226797.12 | AP10: 230439.8 | AQ10: 234147.35 | AR10: 237922.97 | AS10: 241769.47 | AT10: 245689.24 | AU10: 249684.34 | AV10: 253767.5 | AW10: 257931.1 | AX10: 262176.11 | AY10: 266503.67 | AZ10: 270915.04 | BA10: 275411.87 | BB10: 279995.67 | BC10: 284667.76 | BD10: 289429.4 | BE10: 294281.8
A11: y_sveh_0 | B11: 125718.96 | C11: 127855.05 | D11: 130282.38 | E11: 132655.17 | F11: 134914.62 | G11: 137073.95 | H11: 139058.47 | I11: 141014.56 | J11: 142973.75 | K11: 144953.45 | L11: 147171.59 | M11: 149229.67 | N11: 151311.17 | O11: 153425.67 | P11: 155578.96 | Q11: 157775.68 | R11: 160020.75 | S11: 162318.65 | T11: 164673.16 | U11: 167087.41 | V11: 169409.9 | W11: 171942.8 | X11: 174555.08 | Y11: 177243.55 | Z11: 180008.1 | AA11: 182400.92 | AB11: 185076.18 | AC11: 187842.13 | AD11: 190698.03 | AE11: 193644.66 | AF11: 196683.03 | AG11: 199814.43 | AH11: 203039.78 | AI11: 206360.07 | AJ11: 209776.61 | AK11: 213290.57 | AL11: 216758.66 | AM11: 220278.47 | AN11: 223854.79 | AO11: 227491.12 | AP11: 231190.95 | AQ11: 234957.83 | AR11: 238795.06 | AS11: 242705.47 | AT11: 246691.51 | AU11: 250755.3 | AV11: 254909.15 | AW11: 259145.24 | AX11: 263464.6 | AY11: 267868.51 | AZ11: 272358.36 | BA11: 276935.38 | BB11: 281600.92 | BC11: 286356.39 | BD11: 291203.18 | BE11: 296142.67
A12: y_sgla_2 | B12: 22109.365 | C12: 22351.361 | D12: 22617.56 | E12: 22906.274 | F12: 23217.518 | G12: 23549.367 | H12: 23888.128 | I12: 24238.981 | J12: 24601.921 | K12: 24976.692 | L12: 25384.54 | M12: 25792.056 | N12: 26208.598 | O12: 26635.19 | P12: 27072.559 | Q12: 27521.433 | R12: 27982.543 | S12: 28456.69 | T12: 28944.705 | U12: 29447.392 | V12: 29949.514 | W12: 30476.539 | X12: 31022.27 | Y12: 31586.759 | Z12: 32170.379 | AA12: 32726.766 | AB12: 33305.929 | AC12: 33899.938 | AD12: 34509.766 | AE12: 35136.567 | AF12: 35781.419 | AG12: 36445.263 | AH12: 37128.86 | AI12: 37832.844 | AJ12: 38557.765 | AK12: 39304.081 | AL12: 40057.075 | AM12: 40821.261 | AN12: 41596.66 | AO12: 42383.277 | AP12: 43181.275 | AQ12: 43990.938 | AR12: 44812.554 | AS12: 45646.345 | AT12: 46492.451 | AU12: 47350.927 | AV12: 48222.967 | AW12: 49108.006 | AX12: 50005.867 | AY12: 50916.376 | AZ12: 51839.369 | BA12: 52774.763 | BB12: 53722.473 | BC12: 54682.407 | BD12: 55654.486 | BE12: 56638.647
... A67: y_seot_0 | B67: 109.70735 | C67: 110.42493 | D67: 110.92897 | E67: 111.4125 | F67: 111.95372 | G67: 112.56348 | H67: 113.20826 | I67: 113.9177 | J67: 114.68515 | K67: 115.5003 | L67: 116.44954 | M67: 117.38496 | N67: 118.33921 | O67: 119.3162 | P67: 120.31654 | Q67: 121.34076 | R67: 122.40533 | S67: 123.50341 | T67: 124.63282 | U67: 125.79389 | V67: 126.91935 | W67: 128.13563 | X67: 129.40741 | Y67: 130.72726 | Z67: 132.0938 | AA67: 133.30938 | AB67: 134.6044 | AC67: 135.94593 | AD67: 137.33173 | AE67: 138.76411 | AF67: 140.24624 | AG67: 141.78475 | AH67: 143.38014 | AI67: 145.03338 | AJ67: 146.74562 | AK67: 148.51783 | AL67: 150.29687 | AM67: 152.10544 | AN67: 153.94683 | AO67: 155.82109 | AP67: 157.72786 | AQ67: 159.66813 | AR67: 161.64173 | AS67: 163.64911 | AT67: 165.69095 | AU67: 167.76806 | AV67: 169.88618 | AW67: 172.04348 | AX67: 174.24017 | AY67: 176.47687 | AZ67: 178.75427 | BA67: 181.07161 | BB67: 183.43028 | BC67: 185.83128 | BD67: 188.2754 | BE67: 190.76332

Sheet Capital
A1: _date_ | B1: 42005 | C1: 42370 | D1: 42736 | E1: 43101 | F1: 43466 | G1: 43831 | H1: 44197 | I1: 44562 | J1: 44927 | K1: 45292 | L1: 45658 | M1: 46023 | N1: 46388 | O1: 46753 | P1: 47119 | Q1: 47484 | R1: 47849 | S1: 48214 | T1: 48580 | U1: 48945 | V1: 49310 | W1: 49675 | X1: 50041 | Y1: 50406 | Z1: 50771 | AA1: 51136 | AB1: 51502 | AC1: 51867 | AD1: 52232 | AE1: 52597 | AF1: 52963 | AG1: 53328 | AH1: 53693 | AI1: 54058 | AJ1: 54424 | AK1: 54789 | AL1: 55154 | AM1: 55519 | AN1: 55885 | AO1: 56250 | AP1: 56615 | AQ1: 56980 | AR1: 57346 | AS1: 57711 | AT1: 58076 | AU1: 58441 | AV1: 58807 | AW1: 59172 | AX1: 59537 | AY1: 59902 | AZ1: 60268 | BA1: 60633 | BB1: 60998 | BC1: 61363 | BD1: 61729 | BE1: 62094
A2: f_k_2 | B2: 5222033.8 | C2: 5280606.7 | D2: 5340340.3 | E2: 5401585.7 | F2: 5464654.4 | G2: 5529804.6 | H2: 5597063.2 | I2: 5666493.7 | J2: 5738182.2 | K2: 5812222.6 | L2: 5889053 | M2: 5968653.2 | N2: 6051037.6 | O2: 6136248.3 | P2: 6224344.8 | Q2: 6315399.3 | R2: 6409486.3 | S2: 6506698.3 | T2: 6607137.2 | U2: 6710913 | V2: 6817885.1 | W2: 6928255 | X2: 7042207.6 | Y2: 7159910.6 | Z2: 7281523.4 | AA2: 7406444.1 | AB2: 7534694.2 | AC2: 7666331.3 | AD2: 7801428.8 | AE2: 7940076.4 | AF2: 8082379.4 | AG2: 8228458.9 | AH2: 8378441.9 | AI2: 8532461 | AJ2: 8690652.5 | AK2: 8853154.4 | AL2: 9019887.2 | AM2: 9190748.3 | AN2: 9365643.9 | AO2: 9544486.9 | AP2: 9727199.4 | AQ2: 9913719.5 | AR2: 10103989 | AS2: 10297958 | AT2: 10495578 | AU2: 10696805 | AV2: 10901633 | AW2: 11110034 | AX2: 11321969 | AY2: 11537398 | AZ2: 11756275 | BA2: 11978568 | BB2: 12204228 | BC2: 12433207 | BD2: 12665454 | BE2: 12900920
A3: f_k_0 | B3: 5222033.8 | C3: 5280606.1 | D3: 5340338.5 | E3: 5401582 | F3: 5464648.2 | G3: 5529795.1 | H3: 5597044.3 | I3: 5666459 | J3: 5738124.5 | K3: 5812134.5 | L3: 5888926.6 | M3: 5968506.7 | N3: 6050891.7 | O3: 6136126.5 | P3: 6224272.5 | Q3: 6315403.4 | R3: 6409640.5 | S3: 6507081.2 | T3: 6607832 | U3: 6712005.8 | V3: 6819463.6 | W3: 6930445.4 | X3: 7045139.7 | Y3: 7163716.7 | Z3: 7286337 | AA3: 7412396.3 | AB3: 7541926.4 | AC3: 7674983.3 | AD3: 7811637.9 | AE3: 7951977.2 | AF3: 8096102.6 | AG3: 8244141.4 | AH3: 8396216.8 | AI3: 8552457.7 | AJ3: 8712995.8 | AK3: 8877964 | AL3: 9047260.1 | AM3: 9220771.9 | AN3: 9398395.2 | AO3: 9580032.9 | AP3: 9765597.1 | AQ3: 9955014.7 | AR3: 10148218 | AS3: 10345145 | AT3: 10545741 | AU3: 10749950 | AV3: 10957736 | AW3: 11169058 | AX3: 11383868 | AY3: 11602114 | AZ3: 11823740 | BA3: 12048683 | BB3: 12276884 | BC3: 12508283 | BD3: 12742824 | BE3: 12980452
A4: f_k_sagr_2 | B4: 47194.662 | C4: 47708.334 | D4: 48216.502 | E4: 48725.067 | F4: 49240.686 | G4: 49769.239 | H4: 50313.721 | I4: 50876.656 | J4: 51460.159 | K4: 52065.966 | L4: 52698.638 | M4: 53358.36 | N4: 54045.314 | O4: 54759.734 | P4: 55501.882 | Q4: 56272.046 | R4: 57070.45 | S4: 57897.477 | T4: 58753.581 | U4: 59639.276 | V4: 60552.764 | W4: 61495.303 | X4: 62468.114 | Y4: 63472.298 | Z4: 64508.895 | AA4: 65571.939 | AB4: 66660.963 | AC4: 67776.023 | AD4: 68917.472 | AE4: 70085.938 | AF4: 71282.291 | AG4: 72507.62 | AH4: 73763.096 | AI4: 75049.96 | AJ4: 76369.484 | AK4: 77722.95 | AL4: 79109.745 | AM4: 80528.9 | AN4: 81979.563 | AO4: 83461.019 | AP4: 84972.722 | AQ4: 86514.37 | AR4: 88085.749 | AS4: 89686.765 | AT4: 91317.414 | AU4: 92977.754 | AV4: 94668.326 | AW4: 96389.416 | AX4: 98141.293 | AY4: 99924.214 | AZ4: 101738.43 | BA4: 103584.39 | BB4: 105462.39 | BC4: 107372.73 | BD4: 109315.73 | BE4: 111291.75
A5: f_k_sagr_0 | B5: 47194.662 | C5: 47708.327 | D5: 48216.479 | E5: 48725.021 | F5: 49240.61 | G5: 49769.127 | H5: 50313.5 | I5: 50876.254 | J5: 51459.505 | K5: 52064.989 | L5: 52697.274 | M5: 53356.887 | N5: 54044.035 | O5: 54758.968 | P5: 55501.949 | Q5: 56273.254 | R5: 57073.668 | S5: 57903.575 | T5: 58763.399 | U5: 59653.596 | V5: 60572.282 | W5: 61521.095 | X5: 62501.162 | Y5: 63513.467 | Z5: 64558.905 | AA5: 65631.321 | AB5: 66730.215 | AC5: 67855.458 | AD5: 69007.206 | AE5: 70185.888 | AF5: 71392.171 | AG5: 72627.068 | AH5: 73891.556 | AI5: 75186.682 | AJ5: 76513.522 | AK5: 77873.165 | AL5: 79264.619 | AM5: 80686.703 | AN5: 82138.364 | AO5: 83618.704 | AP5: 85127.008 | AQ5: 86662.803 | AR5: 88225.732 | AS5: 89815.569 | AT5: 91432.185 | AU5: 93075.527 | AV5: 94745.784 | AW5: 96443.126 | AX5: 98167.725 | AY5: 99919.762 | AZ5: 101699.43 | BA5: 103506.86 | BB5: 105342.27 | BC5: 107205.96 | BD5: 109098.23 | BE5: 111019.45
A6: f_k_sfor_2 | B6: 1843.172 | C6: 1861.286 | D6: 1877.3589 | E6: 1891.291 | F6: 1903.2201 | G6: 1913.3372 | H6: 1921.8443 | I6: 1928.981 | J6: 1934.9796 | K6: 1940.0435 | L6: 1944.4217 | M6: 1948.2133 | N6: 1951.5093 | O6: 1954.4004 | P6: 1956.976 | Q6: 1959.3217 | R6: 1961.504 | S6: 1963.5938 | T6: 1965.6603 | U6: 1967.7706 | V6: 1969.935 | W6: 1972.2356 | X6: 1974.7472 | Y6: 1977.5323 | Z6: 1980.645 | AA6: 1983.984 | AB6: 1987.5897 | AC6: 1991.5123 | AD6: 1995.7983 | AE6: 2000.4888 | AF6: 2005.6209 | AG6: 2011.2323 | AH6: 2017.3555 | AI6: 2024.0201 | AJ6: 2031.2535 | AK6: 2039.0808 | AL6: 2047.5176 | AM6: 2056.5648 | AN6: 2066.2245 | AO6: 2076.4991 | AP6: 2087.3915 | AQ6: 2098.9104 | AR6: 2111.0612 | AS6: 2123.8483 | AT6: 2137.2753 | AU6: 2151.3452 | AV6: 2166.0836 | AW6: 2181.5008 | AX6: 2197.6017 | AY6: 2214.3876 | AZ6: 2231.858 | BA6: 2250.0237 | BB6: 2268.8863 | BC6: 2288.4448 | BD6: 2308.6961 | BE6: 2329.6365
A7: f_k_sfor_0 | B7: 1843.172 | C7: 1861.2846 | D7: 1877.354 | E7: 1891.2802 | F7: 1903.201 | G7: 1913.3069 | H7: 1921.7847 | I7: 1928.8671 | J7: 1934.7855 | K7: 1939.7456 | L7: 1944.0004 | M7: 1947.7023 | N7: 1950.9634 | O7: 1953.8826 | P7: 1956.5493 | Q7: 1959.0444 | R7: 1961.5047 | S7: 1964.0206 | T7: 1966.6622 | U7: 1969.4851 | V7: 1972.4825 | W7: 1975.7741 | X7: 1979.435 | Y7: 1983.5146 | Z7: 1988.0457 | AA7: 1992.9001 | AB7: 1998.1089 | AC7: 2003.7023 | AD7: 2009.7042 | AE7: 2016.1317 | AF7: 2022.9981 | AG7: 2030.3309 | AH7: 2038.1452 | AI7: 2046.4513 | AJ7: 2055.2563 | AK7: 2064.5655 | AL7: 2074.362 | AM7: 2084.6241 | AN7: 2095.335 | AO7: 2106.4814 | AP7: 2118.0522 | AQ7: 2130.0432 | AR7: 2142.4484 | AS7: 2155.262 | AT7: 2168.4784 | AU7: 2182.092 | AV7: 2196.1027 | AW7: 2210.508 | AX7: 2225.3043 | AY7: 2240.4874 | AZ7: 2256.053 | BA7: 2271.9894 | BB7: 2288.2904 | BC7: 2304.9517 | BD7: 2321.9705 | BE7: 2339.3449
A8: f_k_sfoo_2 | B8: 74494.565 | C8: 75316.819 | D8: 76141.187 | E8: 76975.424 | F8: 77827.974 | G8: 78706.243 | H8: 79613.468 | I8: 80552.333 | J8: 81525.114 | K8: 82533.714 | L8: 83584.602 | M8: 84677.853 | N8: 85813.453 | O8: 86991.456 | P8: 88211.963 | Q8: 89475.146 | R8: 90781.148 | S8: 92130.331 | T8: 93523.164 | U8: 94960.221 | V8: 96438.492 | W8: 97959.54 | X8: 99524.979 | Y8: 101136.3 | Z8: 102794.94 | AA8: 104491.48 | AB8: 106224.54 | AC8: 107993.66 | AD8: 109798.94 | AE8: 111641 | AF8: 113520.9 | AG8: 115440.07 | AH8: 117400.12 | AI8: 119402.79 | AJ8: 121449.89 | AK8: 123543.27 | AL8: 125681.76 | AM8: 127863.73 | AN8: 130087.71 | AO8: 132352.44 | AP8: 134656.97 | AQ8: 137000.71 | AR8: 139383.23 | AS8: 141804.29 | AT8: 144263.8 | AU8: 146761.74 | AV8: 149298.7 | AW8: 151875 | AX8: 154490.93 | AY8: 157146.77 | AZ8: 159842.81 | BA8: 162579.53 | BB8: 165357.27 | BC8: 168176.41 | BD8: 171037.35 | BE8: 173940.54
A9: f_k_sfoo_0 | B9: 74494.565 | C9: 75316.812 | D9: 76141.165 | E9: 76975.38 | F9: 77827.899 | G9: 78706.13 | H9: 79613.245 | I9: 80551.927 | J9: 81524.446 | K9: 82532.697 | L9: 83583.144 | M9: 84676.203 | N9: 85811.881 | O9: 86990.259 | P9: 88211.462 | Q9: 89475.67 | R9: 90783.656 | S9: 92135.821 | T9: 93532.682 | U9: 94974.841 | V9: 96459.298 | W9: 97988.132 | X9: 99562.981 | Y9: 101185.36 | Z9: 102856.71 | AA9: 104567.57 | AB9: 106316.71 | AC9: 108103.63 | AD9: 109928.41 | AE9: 111791.65 | AF9: 113694.36 | AG9: 115638.09 | AH9: 117624.42 | AI9: 119655.07 | AJ9: 121731.83 | AK9: 123856.53 | AL9: 126027.74 | AM9: 128243.76 | AN9: 130503.06 | AO9: 132804.33 | AP9: 135146.57 | AQ9: 137529.13 | AR9: 139951.57 | AS9: 142413.64 | AT9: 144915.2 | AU9: 147456.25 | AV9: 150037.1 | AW9: 152658.03 | AX9: 155319.34 | AY9: 158021.31 | AZ9: 160764.24 | BA9: 163548.34 | BB9: 166373.96 | BC9: 169241.5 | BD9: 172151.43 | BE9: 175104.24
A10: f_k_sveh_2 | B10: 401415.55 | C10: 406073.96 | D10: 411028.57 | E10: 416288.16 | F10: 421821.45 | G10: 427587.44 | H10: 433527.96 | I10: 439610.52 | J10: 445818.19 | K10: 452142.9 | L10: 458623.51 | M10: 465231.74 | N10: 471956.2 | O10: 478793.67 | P10: 485744.78 | Q10: 492812.35 | R10: 500000.09 | S10: 507313.47 | T10: 514759.01 | U10: 522344.02 | V10: 530045.12 | W10: 537891.07 | X10: 545899.77 | Y10: 554084.03 | Z10: 562454.66 | AA10: 570930.3 | AB10: 579536.35 | AC10: 588292.33 | AD10: 597214.34 | AE10: 606316.99 | AF10: 615614.15 | AG10: 625119.34 | AH10: 634845.31 | AI10: 644804.34 | AJ10: 655008.31 | AK10: 665468.73 | AL10: 676169.24 | AM10: 687101.91 | AN10: 698263.53 | AO10: 709653.08 | AP10: 721270.91 | AQ10: 733118.91 | AR10: 745199.5 | AS10: 757515.79 | AT10: 770071.44 | AU10: 782870.46 | AV10: 795920.88 | AW10: 809228.06 | AX10: 822796.83 | AY10: 836631.79 | AZ10: 850737.41 | BA10: 865119.22 | BB10: 879781.68 | BC10: 894729.22 | BD10: 909966.19 | BE10: 925496.89
A11: f_k_sveh_0 | B11: 401415.55 | C11: 406073.92 | D11: 411028.43 | E11: 416287.88 | F11: 421820.96 | G11: 427586.69 | H11: 433526.47 | I11: 439607.76 | J11: 445813.59 | K11: 452135.84 | L11: 458613.34 | M11: 465219.79 | N11: 471944.05 | O11: 478783.09 | P11: 485737.72 | Q11: 492810.88 | R11: 500009.92 | S11: 507340.74 | T11: 514810.25 | U11: 522426.04 | V11: 530164.91 | W11: 538058.67 | X11: 546125.6 | Y11: 554378.79 | Z11: 562829.31 | AA11: 571395.71 | AB11: 580104.37 | AC11: 588974.89 | AD11: 598023.41 | AE11: 607264.59 | AF11: 616712.3 | AG11: 626380.83 | AH11: 636283 | AI11: 646431.15 | AJ11: 656837.23 | AK11: 667512.81 | AL11: 678440.27 | AM11: 689611.42 | AN11: 701022.81 | AO11: 712673.21 | AP11: 724562.79 | AQ11: 736693.2 | AR11: 749066.72 | AS11: 761686.39 | AT11: 774555.79 | AU11: 787678.86 | AV11: 801062.11 | AW11: 814710.72 | AX11: 828629.37 | AY11: 842822.55 | AZ11: 857294.69 | BA11: 872049.65 | BB11: 887091.75 | BC11: 902425.34 | BD11: 918054.74 | BE11: 933984.27
A12: f_k_sgla_2 | B12: 16077.268 | C12: 16256.584 | D12: 16438.552 | E12: 16624.444 | F12: 16815.475 | G12: 17012.662 | H12: 17216.3 | I12: 17426.694 | J12: 17644.159 | K12: 17868.998 | L12: 18102.458 | M12: 18344.538 | N12: 18595.289 | O12: 18854.843 | P12: 19123.385 | Q12: 19401.154 | R12: 19688.402 | S12: 19985.447 | T12: 20292.647 | U12: 20610.393 | V12: 20938.388 | W12: 21277.263 | X12: 21627.642 | Y12: 21990.111 | Z12: 22365.234 | AA12: 22751.457 | AB12: 23148.866 | AC12: 23557.694 | AD12: 23978.231 | AE12: 24410.818 | AF12: 24855.834 | AG12: 25313.703 | AH12: 25784.862 | AI12: 26269.758 | AJ12: 26768.845 | AK12: 27282.575 | AL12: 27810.778 | AM12: 28353.151 | AN12: 28909.385 | AO12: 29479.18 | AP12: 30062.255 | AQ12: 30658.379 | AR12: 31267.336 | AS12: 31888.93 | AT12: 32522.981 | AU12: 33169.317 | AV12: 33827.886 | AW12: 34498.558 | AX12: 35181.183 | AY12: 35875.593 | AZ12: 36581.598 | BA12: 37299.047 | BB12: 38027.734 | BC12: 38767.44 | BD12: 39517.941 | BE12: 40279.008
... A67: f_k_seot_0 | B67: 65.148869 | C67: 65.867158 | D67: 66.567225 | E67: 67.24415 | F67: 67.899242 | G67: 68.536124 | H67: 69.157734 | I67: 69.767989 | J67: 70.370759 | K67: 70.969432 | L67: 71.570408 | M67: 72.175565 | N67: 72.786088 | O67: 73.403206 | P67: 74.028155 | Q67: 74.66215 | R67: 75.307393 | S67: 75.96533 | T67: 76.637241 | U67: 77.324324 | V67: 78.025171 | W67: 78.742736 | X67: 79.479253 | Y67: 80.236536 | Z67: 81.016168 | AA67: 81.81209 | AB67: 82.624842 | AC67: 83.455565 | AD67: 84.305497 | AE67: 85.175955 | AF67: 86.06836 | AG67: 86.984506 | AH67: 87.926037 | AI67: 88.894597 | AJ67: 89.891826 | AK67: 90.919342 | AL67: 91.976819 | AM67: 93.063854 | AN67: 94.180239 | AO67: 95.325816 | AP67: 96.500407 | AQ67: 97.703896 | AR67: 98.93609 | AS67: 100.1968 | AT67: 101.48584 | AU67: 102.80308 | AV67: 104.1486 | AW67: 105.52245 | AX67: 106.92467 | AY67: 108.35532 | AZ67: 109.81445 | BA67: 111.30203 | BB67: 112.81816 | BC67: 114.36297 | BD67: 115.93662 | BE67: 117.53929

Sheet Results
A1: NB : on crée ici une liste : - globale, qui fusionne les sorties des reportings 1, 2 et 3 - "rationalisée" : suppression des doublons, et regroupements par thématique On continue par la suite à avoir 2 Excels de reporting (un "energie", fusion des reportings 1 et 2), et un "économie" (reporting 3)), dans lesquels on copiera cet onglet "results" (généré automatiquement par EViews). --> puis voir à la fin si on peut pas importer les graphs et tableaux dans l'excel automatiquement généré (éviterait les copiés collés, mais à voir si ça prend trop de temps, et si c'est pas trop gros comme excel)
A2: Nom du bloc de variables utilisé dans le code | B2: Sous-bloc de variables pour plus de lisibilité dans le Excel | E2: Year | F2: =date!B3 -> rdag | G2: =date!C3 -> jdag | H2: =date!D3 -> ndag | I2: =date!E3 -> ndag | J2: =date!F3 -> sdag | K2: =date!G3 -> sdag | L2: =date!H3 -> jdag | M2: =date!I3 -> rdag | ... BI2: =date!BE3 -> sdag
A3: HYBRID | B3: AUTOMOBILES (thousands) | C3: TOTAL STOCK SHOCK | E3: AUTO_2 | F3: =VLOOKUP($E3,Hybrid!$1:$1048576,MATCH(DATE(F$2,1,1),Hybrid!$A$1:$LI$1),FALSE) -> #VALUE! | G3: =VLOOKUP($E3,Hybrid!$1:$1048576,MATCH(DATE(G$2,1,1),Hybrid!$A$1:$LI$1),FALSE) -> #VALUE! | H3: =VLOOKUP($E3,Hybrid!$1:$1048576,MATCH(DATE(H$2,1,1),Hybrid!$A$1:$LI$1),FALSE) -> #VALUE! | I3: =VLOOKUP($E3,Hybrid!$1:$1048576,MATCH(DATE(I$2,1,1),Hybrid!$A$1:$LI$1),FALSE) -> #VALUE! | J3: =VLOOKUP($E3,Hybrid!$1:$1048576,MATCH(DATE(J$2,1,1),Hybrid!$A$1:$LI$1),FALSE) -> #VALUE! | K3: =VLOOKUP($E3,Hybrid!$1:$1048576,MATCH(DATE(K$2,1,1),Hybrid!$A$1:$LI$1),FALSE) -> #VALUE! | L3: =VLOOKUP($E3,Hybrid!$1:$1048576,MATCH(DATE(L$2,1,1),Hybrid!$A$1:$LI$1),FALSE) -> #VALUE! | M3: =VLOOKUP($E3,Hybrid!$1:$1048576,MATCH(DATE(M$2,1,1),Hybrid!$A$1:$LI$1),FALSE) -> #VALUE! | ... BI3: =VLOOKUP($E3,Hybrid!$1:$1048576,MATCH(DATE(BI$2,1,1),Hybrid!$A$1:$LI$1),FALSE) -> #VALUE!
C4: OIL | E4: AUTO_cfut_2 | F4: =VLOOKUP($E4,Hybrid!$1:$1048576,MATCH(DATE(F$2,1,1),Hybrid!$A$1:$LI$1),FALSE) -> #VALUE! | G4: =VLOOKUP($E4,Hybrid!$1:$1048576,MATCH(DATE(G$2,1,1),Hybrid!$A$1:$LI$1),FALSE) -> #VALUE! | H4: =VLOOKUP($E4,Hybrid!$1:$1048576,MATCH(DATE(H$2,1,1),Hybrid!$A$1:$LI$1),FALSE) -> #VALUE! | I4: =VLOOKUP($E4,Hybrid!$1:$1048576,MATCH(DATE(I$2,1,1),Hybrid!$A$1:$LI$1),FALSE) -> #VALUE! | J4: =VLOOKUP($E4,Hybrid!$1:$1048576,MATCH(DATE(J$2,1,1),Hybrid!$A$1:$LI$1),FALSE) -> #VALUE! | K4: =VLOOKUP($E4,Hybrid!$1:$1048576,MATCH(DATE(K$2,1,1),Hybrid!$A$1:$LI$1),FALSE) -> #VALUE! | L4: =VLOOKUP($E4,Hybrid!$1:$1048576,MATCH(DATE(L$2,1,1),Hybrid!$A$1:$LI$1),FALSE) -> #VALUE! | M4: =VLOOKUP($E4,Hybrid!$1:$1048576,MATCH(DATE(M$2,1,1),Hybrid!$A$1:$LI$1),FALSE) -> #VALUE! | ... BI4: =VLOOKUP($E4,Hybrid!$1:$1048576,MATCH(DATE(BI$2,1,1),Hybrid!$A$1:$LI$1),FALSE) -> #VALUE!
D5: class A | E5: AUTO_ca_cfut_2 | F5: =VLOOKUP($E5,Hybrid!$1:$1048576,MATCH(DATE(F$2,1,1),Hybrid!$A$1:$LI$1),FALSE) -> #VALUE! | G5: =VLOOKUP($E5,Hybrid!$1:$1048576,MATCH(DATE(G$2,1,1),Hybrid!$A$1:$LI$1),FALSE) -> #VALUE! | H5: =VLOOKUP($E5,Hybrid!$1:$1048576,MATCH(DATE(H$2,1,1),Hybrid!$A$1:$LI$1),FALSE) -> #VALUE! | I5: =VLOOKUP($E5,Hybrid!$1:$1048576,MATCH(DATE(I$2,1,1),Hybrid!$A$1:$LI$1),FALSE) -> #VALUE! | J5: =VLOOKUP($E5,Hybrid!$1:$1048576,MATCH(DATE(J$2,1,1),Hybrid!$A$1:$LI$1),FALSE) -> #VALUE! | K5: =VLOOKUP($E5,Hybrid!$1:$1048576,MATCH(DATE(K$2,1,1),Hybrid!$A$1:$LI$1),FALSE) -> #VALUE! | L5: =VLOOKUP($E5,Hybrid!$1:$1048576,MATCH(DATE(L$2,1,1),Hybrid!$A$1:$LI$1),FALSE) -> #VALUE! | M5: =VLOOKUP($E5,Hybrid!$1:$1048576,MATCH(DATE(M$2,1,1),Hybrid!$A$1:$LI$1),FALSE) -> #VALUE! | ... BI5: =VLOOKUP($E5,Hybrid!$1:$1048576,MATCH(DATE(BI$2,1,1),Hybrid!$A$1:$LI$1),FALSE) -> #VALUE!
D6: class B | E6: AUTO_cb_cfut_2 | F6: =VLOOKUP($E6,Hybrid!$1:$1048576,MATCH(DATE(F$2,1,1),Hybrid!$A$1:$LI$1),FALSE) -> #VALUE! | G6: =VLOOKUP($E6,Hybrid!$1:$1048576,MATCH(DATE(G$2,1,1),Hybrid!$A$1:$LI$1),FALSE) -> #VALUE! | H6: =VLOOKUP($E6,Hybrid!$1:$1048576,MATCH(DATE(H$2,1,1),Hybrid!$A$1:$LI$1),FALSE) -> #VALUE! | I6: =VLOOKUP($E6,Hybrid!$1:$1048576,MATCH(DATE(I$2,1,1),Hybrid!$A$1:$LI$1),FALSE) -> #VALUE! | J6: =VLOOKUP($E6,Hybrid!$1:$1048576,MATCH(DATE(J$2,1,1),Hybrid!$A$1:$LI$1),FALSE) -> #VALUE! | K6: =VLOOKUP($E6,Hybrid!$1:$1048576,MATCH(DATE(K$2,1,1),Hybrid!$A$1:$LI$1),FALSE) -> #VALUE! | L6: =VLOOKUP($E6,Hybrid!$1:$1048576,MATCH(DATE(L$2,1,1),Hybrid!$A$1:$LI$1),FALSE) -> #VALUE! | M6: =VLOOKUP($E6,Hybrid!$1:$1048576,MATCH(DATE(M$2,1,1),Hybrid!$A$1:$LI$1),FALSE) -> #VALUE! | ... BI6: =VLOOKUP($E6,Hybrid!$1:$1048576,MATCH(DATE(BI$2,1,1),Hybrid!$A$1:$LI$1),FALSE) -> #VALUE!
D7: class C | E7: AUTO_cc_cfut_2 | F7: =VLOOKUP($E7,Hybrid!$1:$1048576,MATCH(DATE(F$2,1,1),Hybrid!$A$1:$LI$1),FALSE) -> #VALUE! | G7: =VLOOKUP($E7,Hybrid!$1:$1048576,MATCH(DATE(G$2,1,1),Hybrid!$A$1:$LI$1),FALSE) -> #VALUE! | H7: =VLOOKUP($E7,Hybrid!$1:$1048576,MATCH(DATE(H$2,1,1),Hybrid!$A$1:$LI$1),FALSE) -> #VALUE! | I7: =VLOOKUP($E7,Hybrid!$1:$1048576,MATCH(DATE(I$2,1,1),Hybrid!$A$1:$LI$1),FALSE) -> #VALUE! | J7: =VLOOKUP($E7,Hybrid!$1:$1048576,MATCH(DATE(J$2,1,1),Hybrid!$A$1:$LI$1),FALSE) -> #VALUE! | K7: =VLOOKUP($E7,Hybrid!$1:$1048576,MATCH(DATE(K$2,1,1),Hybrid!$A$1:$LI$1),FALSE) -> #VALUE! | L7: =VLOOKUP($E7,Hybrid!$1:$1048576,MATCH(DATE(L$2,1,1),Hybrid!$A$1:$LI$1),FALSE) -> #VALUE! | M7: =VLOOKUP($E7,Hybrid!$1:$1048576,MATCH(DATE(M$2,1,1),Hybrid!$A$1:$LI$1),FALSE) -> #VALUE! | ... BI7: =VLOOKUP($E7,Hybrid!$1:$1048576,MATCH(DATE(BI$2,1,1),Hybrid!$A$1:$LI$1),FALSE) -> #VALUE!
