Workbook

Sheet baseline
A1: _date_ | B1: 42005 | C1: 42370 | D1: 42736 | E1: 43101 | F1: 43466 | G1: 43831 | H1: 44197 | I1: 44562 | J1: 44927 | K1: 45292 | L1: 45658 | M1: 46023 | N1: 46388 | O1: 46753 | P1: 47119 | Q1: 47484 | R1: 47849 | S1: 48214 | T1: 48580 | U1: 48945 | V1: 49310 | W1: 49675 | X1: 50041 | Y1: 50406 | Z1: 50771 | AA1: 51136 | AB1: 51502 | AC1: 51867 | AD1: 52232 | AE1: 52597 | AF1: 52963 | AG1: 53328 | AH1: 53693 | AI1: 54058 | AJ1: 54424 | AK1: 54789

Sheet shock
A1: _date_ | B1: 42005 | C1: 42370 | D1: 42736 | E1: 43101 | F1: 43466 | G1: 43831 | H1: 44197 | I1: 44562 | J1: 44927 | K1: 45292 | L1: 45658 | M1: 46023 | N1: 46388 | O1: 46753 | P1: 47119 | Q1: 47484 | R1: 47849 | S1: 48214 | T1: 48580 | U1: 48945 | V1: 49310 | W1: 49675 | X1: 50041 | Y1: 50406 | Z1: 50771 | AA1: 51136 | AB1: 51502 | AC1: 51867 | AD1: 52232 | AE1: 52597 | AF1: 52963 | AG1: 53328 | AH1: 53693 | AI1: 54058 | AJ1: 54424 | AK1: 54789

Sheet Check fittarget
A1: Target values | K1: Fitted values | T1: Deviation from the target
L3: 2 | M3: 7 | N3: 17 | O3: 27 | P3: 37
C4: 2015 | D4: 2020 | E4: 2030 | F4: 2040 | G4: 2050 | L4: 2015 | M4: 2020 | N4: 2030 | O4: 2040 | P4: 2050 | U4: 2015 | V4: 2020 | W4: 2030 | X4: 2040 | Y4: 2050
A5: ccoa | B5: sagr | C5: 0.0024942768 | D5: 0.0024942768 | E5: 0 | F5: 0 | G5: 0 | K5: ="CI_toe_"&A5&"_"&B5&"_0" -> CI_toe_ccoa_sagr_0 | L5: =IFERROR(VLOOKUP($K5,baseline!$A:$AK,L$3,FALSE),"") | M5: =IFERROR(VLOOKUP($K5,baseline!$A:$AK,M$3,FALSE),"") | N5: =IFERROR(VLOOKUP($K5,baseline!$A:$AK,N$3,FALSE),"") | O5: =IFERROR(VLOOKUP($K5,baseline!$A:$AK,O$3,FALSE),"") | P5: =IFERROR(VLOOKUP($K5,baseline!$A:$AK,P$3,FALSE),"") | T5: =K5 -> CI_toe_ccoa_sagr_0 | U5: =IFERROR(L5-C5,"") | V5: =IFERROR(M5-D5,"") | W5: =IFERROR(N5-E5,"") | X5: =IFERROR(O5-F5,"") | Y5: =IFERROR(P5-G5,"")
A6: coil | B6: sagr | C6: 0.09469609 | D6: 0.09469609 | E6: 0.09469609 | F6: 0.09469609 | G6: 0.09469609 | K6: ="CI_toe_"&A6&"_"&B6&"_0" -> CI_toe_coil_sagr_0 | L6: =IFERROR(VLOOKUP($K6,baseline!$A:$AK,L$3,FALSE),"") | M6: =IFERROR(VLOOKUP($K6,baseline!$A:$AK,M$3,FALSE),"") | N6: =IFERROR(VLOOKUP($K6,baseline!$A:$AK,N$3,FALSE),"") | O6: =IFERROR(VLOOKUP($K6,baseline!$A:$AK,O$3,FALSE),"") | P6: =IFERROR(VLOOKUP($K6,baseline!$A:$AK,P$3,FALSE),"") | T6: =K6 -> CI_toe_coil_sagr_0 | U6: =IFERROR(L6-C6,"") | V6: =IFERROR(M6-D6,"") | W6: =IFERROR(N6-E6,"") | X6: =IFERROR(O6-F6,"") | Y6: =IFERROR(P6-G6,"")
A7: cfue | B7: sagr | C7: 0.75011452 | D7: 0.67002951 | E7: 0.69045417 | F7: 0.57314367 | G7: 0.001518768 | K7: ="CI_toe_"&A7&"_"&B7&"_0" -> CI_toe_cfue_sagr_0 | L7: =IFERROR(VLOOKUP($K7,baseline!$A:$AK,L$3,FALSE),"") | M7: =IFERROR(VLOOKUP($K7,baseline!$A:$AK,M$3,FALSE),"") | N7: =IFERROR(VLOOKUP($K7,baseline!$A:$AK,N$3,FALSE),"") | O7: =IFERROR(VLOOKUP($K7,baseline!$A:$AK,O$3,FALSE),"") | P7: =IFERROR(VLOOKUP($K7,baseline!$A:$AK,P$3,FALSE),"") | T7: =K7 -> CI_toe_cfue_sagr_0 | U7: =IFERROR(L7-C7,"") | V7: =IFERROR(M7-D7,"") | W7: =IFERROR(N7-E7,"") | X7: =IFERROR(O7-F7,"") | Y7: =IFERROR(P7-G7,"")
A8: cpch | B8: sagr | C8: 0.18384926 | D8: 0.18384926 | E8: 0.18384926 | F8: 0.18384926 | G8: 0.18384926 | K8: ="CI_toe_"&A8&"_"&B8&"_0" -> CI_toe_cpch_sagr_0 | L8: =IFERROR(VLOOKUP($K8,baseline!$A:$AK,L$3,FALSE),"") | M8: =IFERROR(VLOOKUP($K8,baseline!$A:$AK,M$3,FALSE),"") | N8: =IFERROR(VLOOKUP($K8,baseline!$A:$AK,N$3,FALSE),"") | O8: =IFERROR(VLOOKUP($K8,baseline!$A:$AK,O$3,FALSE),"") | P8: =IFERROR(VLOOKUP($K8,baseline!$A:$AK,P$3,FALSE),"") | T8: =K8 -> CI_toe_cpch_sagr_0 | U8: =IFERROR(L8-C8,"") | V8: =IFERROR(M8-D8,"") | W8: =IFERROR(N8-E8,"") | X8: =IFERROR(O8-F8,"") | Y8: =IFERROR(P8-G8,"")
A9: cele | B9: sagr | C9: 0.77203668 | D9: 0.77203668 | E9: 0.77203668 | F9: 0.79161167 | G9: 0.82387486 | K9: ="CI_toe_"&A9&"_"&B9&"_0" -> CI_toe_cele_sagr_0 | L9: =IFERROR(VLOOKUP($K9,baseline!$A:$AK,L$3,FALSE),"") | M9: =IFERROR(VLOOKUP($K9,baseline!$A:$AK,M$3,FALSE),"") | N9: =IFERROR(VLOOKUP($K9,baseline!$A:$AK,N$3,FALSE),"") | O9: =IFERROR(VLOOKUP($K9,baseline!$A:$AK,O$3,FALSE),"") | P9: =IFERROR(VLOOKUP($K9,baseline!$A:$AK,P$3,FALSE),"") | T9: =K9 -> CI_toe_cele_sagr_0 | U9: =IFERROR(L9-C9,"") | V9: =IFERROR(M9-D9,"") | W9: =IFERROR(N9-E9,"") | X9: =IFERROR(O9-F9,"") | Y9: =IFERROR(P9-G9,"")
A10: cgas | B10: sagr | C10: 2.2466481 | D10: 2.0145923 | E10: 1.7248323 | F10: 0.97730816 | G10: 0.79168704 | K10: ="CI_toe_"&A10&"_"&B10&"_0" -> CI_toe_cgas_sagr_0 | L10: =IFERROR(VLOOKUP($K10,baseline!$A:$AK,L$3,FALSE),"") | M10: =IFERROR(VLOOKUP($K10,baseline!$A:$AK,M$3,FALSE),"") | N10: =IFERROR(VLOOKUP($K10,baseline!$A:$AK,N$3,FALSE),"") | O10: =IFERROR(VLOOKUP($K10,baseline!$A:$AK,O$3,FALSE),"") | P10: =IFERROR(VLOOKUP($K10,baseline!$A:$AK,P$3,FALSE),"") | T10: =K10 -> CI_toe_cgas_sagr_0 | U10: =IFERROR(L10-C10,"") | V10: =IFERROR(M10-D10,"") | W10: =IFERROR(N10-E10,"") | X10: =IFERROR(O10-F10,"") | Y10: =IFERROR(P10-G10,"")
A11: cmga | B11: sagr | C11: 0 | D11: 0 | E11: 0 | F11: 0 | G11: 0 | K11: ="CI_toe_"&A11&"_"&B11&"_0" -> CI_toe_cmga_sagr_0 | L11: =IFERROR(VLOOKUP($K11,baseline!$A:$AK,L$3,FALSE),"") | M11: =IFERROR(VLOOKUP($K11,baseline!$A:$AK,M$3,FALSE),"") | N11: =IFERROR(VLOOKUP($K11,baseline!$A:$AK,N$3,FALSE),"") | O11: =IFERROR(VLOOKUP($K11,baseline!$A:$AK,O$3,FALSE),"") | P11: =IFERROR(VLOOKUP($K11,baseline!$A:$AK,P$3,FALSE),"") | T11: =K11 -> CI_toe_cmga_sagr_0 | U11: =IFERROR(L11-C11,"") | V11: =IFERROR(M11-D11,"") | W11: =IFERROR(N11-E11,"") | X11: =IFERROR(O11-F11,"") | Y11: =IFERROR(P11-G11,"")
A12: cbiog | B12: sagr | C12: 0.055541495 | D12: 0.063244181 | E12: 0.054108 | F12: 0.044893488 | G12: 0.00011472432 | K12: ="CI_toe_"&A12&"_"&B12&"_0" -> CI_toe_cbiog_sagr_0 | L12: =IFERROR(VLOOKUP($K12,baseline!$A:$AK,L$3,FALSE),"") | M12: =IFERROR(VLOOKUP($K12,baseline!$A:$AK,M$3,FALSE),"") | N12: =IFERROR(VLOOKUP($K12,baseline!$A:$AK,N$3,FALSE),"") | O12: =IFERROR(VLOOKUP($K12,baseline!$A:$AK,O$3,FALSE),"") | P12: =IFERROR(VLOOKUP($K12,baseline!$A:$AK,P$3,FALSE),"") | T12: =K12 -> CI_toe_cbiog_sagr_0 | U12: =IFERROR(L12-C12,"") | V12: =IFERROR(M12-D12,"") | W12: =IFERROR(N12-E12,"") | X12: =IFERROR(O12-F12,"") | Y12: =IFERROR(P12-G12,"")
A13: cbiom | B13: sagr | C13: 0.064907229 | D13: 0.13061304 | E13: 0.12980875 | F13: 0.10767706 | G13: 0.037814482 | K13: ="CI_toe_"&A13&"_"&B13&"_0" -> CI_toe_cbiom_sagr_0 | L13: =IFERROR(VLOOKUP($K13,baseline!$A:$AK,L$3,FALSE),"") | M13: =IFERROR(VLOOKUP($K13,baseline!$A:$AK,M$3,FALSE),"") | N13: =IFERROR(VLOOKUP($K13,baseline!$A:$AK,N$3,FALSE),"") | O13: =IFERROR(VLOOKUP($K13,baseline!$A:$AK,O$3,FALSE),"") | P13: =IFERROR(VLOOKUP($K13,baseline!$A:$AK,P$3,FALSE),"") | T13: =K13 -> CI_toe_cbiom_sagr_0 | U13: =IFERROR(L13-C13,"") | V13: =IFERROR(M13-D13,"") | W13: =IFERROR(N13-E13,"") | X13: =IFERROR(O13-F13,"") | Y13: =IFERROR(P13-G13,"")
A14: cbiof | B14: sagr | C14: 0.010603567 | D14: 0.0095014971 | E14: 0.0095104151 | F14: 0.0095104151 | G14: 0.0095104151 | K14: ="CI_toe_"&A14&"_"&B14&"_0" -> CI_toe_cbiof_sagr_0 | L14: =IFERROR(VLOOKUP($K14,baseline!$A:$AK,L$3,FALSE),"") | M14: =IFERROR(VLOOKUP($K14,baseline!$A:$AK,M$3,FALSE),"") | N14: =IFERROR(VLOOKUP($K14,baseline!$A:$AK,N$3,FALSE),"") | O14: =IFERROR(VLOOKUP($K14,baseline!$A:$AK,O$3,FALSE),"") | P14: =IFERROR(VLOOKUP($K14,baseline!$A:$AK,P$3,FALSE),"") | T14: =K14 -> CI_toe_cbiof_sagr_0 | U14: =IFERROR(L14-C14,"") | V14: =IFERROR(M14-D14,"") | W14: =IFERROR(N14-E14,"") | X14: =IFERROR(O14-F14,"") | Y14: =IFERROR(P14-G14,"")
A15: chea | B15: sagr | C15: 0.083584705 | D15: 0.15003001 | E15: 0.27890714 | F15: 0.42064873 | G15: 0.51106249 | K15: ="CI_toe_"&A15&"_"&B15&"_0" -> CI_toe_chea_sagr_0 | L15: =IFERROR(VLOOKUP($K15,baseline!$A:$AK,L$3,FALSE),"") | M15: =IFERROR(VLOOKUP($K15,baseline!$A:$AK,M$3,FALSE),"") | N15: =IFERROR(VLOOKUP($K15,baseline!$A:$AK,N$3,FALSE),"") | O15: =IFERROR(VLOOKUP($K15,baseline!$A:$AK,O$3,FALSE),"") | P15: =IFERROR(VLOOKUP($K15,baseline!$A:$AK,P$3,FALSE),"") | T15: =K15 -> CI_toe_chea_sagr_0 | U15: =IFERROR(L15-C15,"") | V15: =IFERROR(M15-D15,"") | W15: =IFERROR(N15-E15,"") | X15: =IFERROR(O15-F15,"") | Y15: =IFERROR(P15-G15,"")
A16: ccoa | B16: smet | C16: 2.3333958 | D16: 2.026232 | E16: 2.5275375 | F16: 2.4720318 | G16: 2.4722894 | K16: ="CI_toe_"&A16&"_"&B16&"_0" -> CI_toe_ccoa_smet_0 | L16: =IFERROR(VLOOKUP($K16,baseline!$A:$AK,L$3,FALSE),"") | M16: =IFERROR(VLOOKUP($K16,baseline!$A:$AK,M$3,FALSE),"") | N16: =IFERROR(VLOOKUP($K16,baseline!$A:$AK,N$3,FALSE),"") | O16: =IFERROR(VLOOKUP($K16,baseline!$A:$AK,O$3,FALSE),"") | P16: =IFERROR(VLOOKUP($K16,baseline!$A:$AK,P$3,FALSE),"") | T16: =K16 -> CI_toe_ccoa_smet_0 | U16: =IFERROR(L16-C16,"") | V16: =IFERROR(M16-D16,"") | W16: =IFERROR(N16-E16,"") | X16: =IFERROR(O16-F16,"") | Y16: =IFERROR(P16-G16,"")
... A124: cbiof | B124: sres | C124: 0.011488 | D124: 0.013510712 | E124: 0.014805228 | F124: 0.014805228 | G124: 0.014805228 | K124: ="CI_toe_"&A124&"_"&B124&"_0" -> CI_toe_cbiof_sres_0 | L124: =IFERROR(VLOOKUP($K124,baseline!$A:$AK,L$3,FALSE),"") | M124: =IFERROR(VLOOKUP($K124,baseline!$A:$AK,M$3,FALSE),"") | N124: =IFERROR(VLOOKUP($K124,baseline!$A:$AK,N$3,FALSE),"") | O124: =IFERROR(VLOOKUP($K124,baseline!$A:$AK,O$3,FALSE),"") | P124: =IFERROR(VLOOKUP($K124,baseline!$A:$AK,P$3,FALSE),"") | T124: =K124 -> CI_toe_cbiof_sres_0 | U124: =IFERROR(L124-C124,"") | V124: =IFERROR(M124-D124,"") | W124: =IFERROR(N124-E124,"") | X124: =IFERROR(O124-F124,"") | Y124: =IFERROR(P124-G124,"")
A125: ccoa | B125: HH | C125: 0.000539 | D125: 0.000539 | E125: 0.000539 | F125: 0.000539 | G125: 0.000539 | K125: ="CH_toe_"&A125&"_0" -> CH_toe_ccoa_0 | L125: =IFERROR(VLOOKUP($K125,baseline!$A:$AK,L$3,FALSE),"") | M125: =IFERROR(VLOOKUP($K125,baseline!$A:$AK,M$3,FALSE),"") | N125: =IFERROR(VLOOKUP($K125,baseline!$A:$AK,N$3,FALSE),"") | O125: =IFERROR(VLOOKUP($K125,baseline!$A:$AK,O$3,FALSE),"") | P125: =IFERROR(VLOOKUP($K125,baseline!$A:$AK,P$3,FALSE),"") | T125: =K125 -> CH_toe_ccoa_0 | U125: =IFERROR(L125-C125,"") | V125: =IFERROR(M125-D125,"") | W125: =IFERROR(N125-E125,"") | X125: =IFERROR(O125-F125,"") | Y125: =IFERROR(P125-G125,"")
A126: coil | B126: HH | C126: 0 | D126: 0 | E126: 0 | F126: 0 | G126: 0 | K126: ="CH_toe_"&A126&"_0" -> CH_toe_coil_0 | L126: =IFERROR(VLOOKUP($K126,baseline!$A:$AK,L$3,FALSE),"") | M126: =IFERROR(VLOOKUP($K126,baseline!$A:$AK,M$3,FALSE),"") | N126: =IFERROR(VLOOKUP($K126,baseline!$A:$AK,N$3,FALSE),"") | O126: =IFERROR(VLOOKUP($K126,baseline!$A:$AK,O$3,FALSE),"") | P126: =IFERROR(VLOOKUP($K126,baseline!$A:$AK,P$3,FALSE),"") | T126: =K126 -> CH_toe_coil_0 | U126: =IFERROR(L126-C126,"") | V126: =IFERROR(M126-D126,"") | W126: =IFERROR(N126-E126,"") | X126: =IFERROR(O126-F126,"") | Y126: =IFERROR(P126-G126,"")
A127: cfue | B127: HH | C127: 7.8688382 | D127: 6.8116024 | E127: 3.4058012 | F127: 1.7029006 | G127: 0.85145029 | K127: ="CH_toe_"&A127&"_0" -> CH_toe_cfue_0 | L127: =IFERROR(VLOOKUP($K127,baseline!$A:$AK,L$3,FALSE),"") | M127: =IFERROR(VLOOKUP($K127,baseline!$A:$AK,M$3,FALSE),"") | N127: =IFERROR(VLOOKUP($K127,baseline!$A:$AK,N$3,FALSE),"") | O127: =IFERROR(VLOOKUP($K127,baseline!$A:$AK,O$3,FALSE),"") | P127: =IFERROR(VLOOKUP($K127,baseline!$A:$AK,P$3,FALSE),"") | T127: =K127 -> CH_toe_cfue_0 | U127: =IFERROR(L127-C127,"") | V127: =IFERROR(M127-D127,"") | W127: =IFERROR(N127-E127,"") | X127: =IFERROR(O127-F127,"") | Y127: =IFERROR(P127-G127,"")
A128: cpch | B128: HH | C128: 0 | D128: 0 | E128: 0 | F128: 0 | G128: 0 | K128: ="CH_toe_"&A128&"_0" -> CH_toe_cpch_0 | L128: =IFERROR(VLOOKUP($K128,baseline!$A:$AK,L$3,FALSE),"") | M128: =IFERROR(VLOOKUP($K128,baseline!$A:$AK,M$3,FALSE),"") | N128: =IFERROR(VLOOKUP($K128,baseline!$A:$AK,N$3,FALSE),"") | O128: =IFERROR(VLOOKUP($K128,baseline!$A:$AK,O$3,FALSE),"") | P128: =IFERROR(VLOOKUP($K128,baseline!$A:$AK,P$3,FALSE),"") | T128: =K128 -> CH_toe_cpch_0 | U128: =IFERROR(L128-C128,"") | V128: =IFERROR(M128-D128,"") | W128: =IFERROR(N128-E128,"") | X128: =IFERROR(O128-F128,"") | Y128: =IFERROR(P128-G128,"")
A129: cele | B129: HH | C129: 1.958241 | D129: 1.9566789 | E129: 1.231842 | F129: 2.3537569 | G129: 3.5073777 | K129: ="CH_toe_"&A129&"_0" -> CH_toe_cele_0 | L129: =IFERROR(VLOOKUP($K129,baseline!$A:$AK,L$3,FALSE),"") | M129: =IFERROR(VLOOKUP($K129,baseline!$A:$AK,M$3,FALSE),"") | N129: =IFERROR(VLOOKUP($K129,baseline!$A:$AK,N$3,FALSE),"") | O129: =IFERROR(VLOOKUP($K129,baseline!$A:$AK,O$3,FALSE),"") | P129: =IFERROR(VLOOKUP($K129,baseline!$A:$AK,P$3,FALSE),"") | T129: =K129 -> CH_toe_cele_0 | U129: =IFERROR(L129-C129,"") | V129: =IFERROR(M129-D129,"") | W129: =IFERROR(N129-E129,"") | X129: =IFERROR(O129-F129,"") | Y129: =IFERROR(P129-G129,"")
A130: cgas | B130: HH | C130: 6.8436445 | D130: 6.0731102 | E130: 5.5016912 | F130: 3.3907406 | G130: 1.8499422 | K130: ="CH_toe_"&A130&"_0" -> CH_toe_cgas_0 | L130: =IFERROR(VLOOKUP($K130,baseline!$A:$AK,L$3,FALSE),"") | M130: =IFERROR(VLOOKUP($K130,baseline!$A:$AK,M$3,FALSE),"") | N130: =IFERROR(VLOOKUP($K130,baseline!$A:$AK,N$3,FALSE),"") | O130: =IFERROR(VLOOKUP($K130,baseline!$A:$AK,O$3,FALSE),"") | P130: =IFERROR(VLOOKUP($K130,baseline!$A:$AK,P$3,FALSE),"") | T130: =K130 -> CH_toe_cgas_0 | U130: =IFERROR(L130-C130,"") | V130: =IFERROR(M130-D130,"") | W130: =IFERROR(N130-E130,"") | X130: =IFERROR(O130-F130,"") | Y130: =IFERROR(P130-G130,"")
A131: cmga | B131: HH | C131: 0 | D131: 0 | E131: 0 | F131: 0 | G131: 0 | K131: ="CH_toe_"&A131&"_0" -> CH_toe_cmga_0 | L131: =IFERROR(VLOOKUP($K131,baseline!$A:$AK,L$3,FALSE),"") | M131: =IFERROR(VLOOKUP($K131,baseline!$A:$AK,M$3,FALSE),"") | N131: =IFERROR(VLOOKUP($K131,baseline!$A:$AK,N$3,FALSE),"") | O131: =IFERROR(VLOOKUP($K131,baseline!$A:$AK,O$3,FALSE),"") | P131: =IFERROR(VLOOKUP($K131,baseline!$A:$AK,P$3,FALSE),"") | T131: =K131 -> CH_toe_cmga_0 | U131: =IFERROR(L131-C131,"") | V131: =IFERROR(M131-D131,"") | W131: =IFERROR(N131-E131,"") | X131: =IFERROR(O131-F131,"") | Y131: =IFERROR(P131-G131,"")
A132: cbiog | B132: HH | C132: 0 | D132: 0 | E132: 0 | F132: 0 | G132: 0 | K132: ="CH_toe_"&A132&"_0" -> CH_toe_cbiog_0 | L132: =IFERROR(VLOOKUP($K132,baseline!$A:$AK,L$3,FALSE),"") | M132: =IFERROR(VLOOKUP($K132,baseline!$A:$AK,M$3,FALSE),"") | N132: =IFERROR(VLOOKUP($K132,baseline!$A:$AK,N$3,FALSE),"") | O132: =IFERROR(VLOOKUP($K132,baseline!$A:$AK,O$3,FALSE),"") | P132: =IFERROR(VLOOKUP($K132,baseline!$A:$AK,P$3,FALSE),"") | T132: =K132 -> CH_toe_cbiog_0 | U132: =IFERROR(L132-C132,"") | V132: =IFERROR(M132-D132,"") | W132: =IFERROR(N132-E132,"") | X132: =IFERROR(O132-F132,"") | Y132: =IFERROR(P132-G132,"")
A133: cbiom | B133: HH | C133: 0.399904 | D133: 0.37531742 | E133: 0.0022081303 | F133: 0.014189979 | G133: 0.44154767 | K133: ="CH_toe_"&A133&"_0" -> CH_toe_cbiom_0 | L133: =IFERROR(VLOOKUP($K133,baseline!$A:$AK,L$3,FALSE),"") | M133: =IFERROR(VLOOKUP($K133,baseline!$A:$AK,M$3,FALSE),"") | N133: =IFERROR(VLOOKUP($K133,baseline!$A:$AK,N$3,FALSE),"") | O133: =IFERROR(VLOOKUP($K133,baseline!$A:$AK,O$3,FALSE),"") | P133: =IFERROR(VLOOKUP($K133,baseline!$A:$AK,P$3,FALSE),"") | T133: =K133 -> CH_toe_cbiom_0 | U133: =IFERROR(L133-C133,"") | V133: =IFERROR(M133-D133,"") | W133: =IFERROR(N133-E133,"") | X133: =IFERROR(O133-F133,"") | Y133: =IFERROR(P133-G133,"")
A134: cbiof | B134: HH | C134: 0.24471335 | D134: 0.24471335 | E134: 0.12235667 | F134: 0.061178337 | G134: 0.030589168 | K134: ="CH_toe_"&A134&"_0" -> CH_toe_cbiof_0 | L134: =IFERROR(VLOOKUP($K134,baseline!$A:$AK,L$3,FALSE),"") | M134: =IFERROR(VLOOKUP($K134,baseline!$A:$AK,M$3,FALSE),"") | N134: =IFERROR(VLOOKUP($K134,baseline!$A:$AK,N$3,FALSE),"") | O134: =IFERROR(VLOOKUP($K134,baseline!$A:$AK,O$3,FALSE),"") | P134: =IFERROR(VLOOKUP($K134,baseline!$A:$AK,P$3,FALSE),"") | T134: =K134 -> CH_toe_cbiof_0 | U134: =IFERROR(L134-C134,"") | V134: =IFERROR(M134-D134,"") | W134: =IFERROR(N134-E134,"") | X134: =IFERROR(O134-F134,"") | Y134: =IFERROR(P134-G134,"")
A135: chea | B135: HH | C135: 0.288478 | D135: 0.39124731 | E135: 0.78102953 | F135: 1.3547291 | G135: 1.5889229 | K135: ="CH_toe_"&A135&"_0" -> CH_toe_chea_0 | L135: =IFERROR(VLOOKUP($K135,baseline!$A:$AK,L$3,FALSE),"") | M135: =IFERROR(VLOOKUP($K135,baseline!$A:$AK,M$3,FALSE),"") | N135: =IFERROR(VLOOKUP($K135,baseline!$A:$AK,N$3,FALSE),"") | O135: =IFERROR(VLOOKUP($K135,baseline!$A:$AK,O$3,FALSE),"") | P135: =IFERROR(VLOOKUP($K135,baseline!$A:$AK,P$3,FALSE),"") | T135: =K135 -> CH_toe_chea_0 | U135: =IFERROR(L135-C135,"") | V135: =IFERROR(M135-D135,"") | W135: =IFERROR(N135-E135,"") | X135: =IFERROR(O135-F135,"") | Y135: =IFERROR(P135-G135,"")
C136: 47.093346 | E136: 39.896538 | F136: 33.820556 | G136: 32.488545 | L136: =SUM(L5:L135) -> 0 | M136: =SUM(M5:M135) -> 0 | N136: =SUM(N5:N135) -> 0 | O136: =SUM(O5:O135) -> 0 | P136: =SUM(P5:P135) -> 0 | U136: =SUM(U5:U135) -> 0 | V136: =SUM(V5:V135) -> 0 | W136: =SUM(W5:W135) -> 0 | X136: =SUM(X5:X135) -> 0 | Y136: =SUM(Y5:Y135) -> 0 | AA136: Should be sum of absolute values
C137: 1971.7042 | E137: 1670.3882 | F137: 1415.999 | G137: 1360.2304

Sheet Emissions
A1: Target values
E2: 2 | F2: 3 | G2: 4 | H2: 5 | I2: 6 | J2: 7 | K2: 8 | L2: 9 | M2: 10 | N2: 11 | O2: 12 | P2: 13 | Q2: 14 | R2: 15 | S2: 16 | T2: 17 | U2: 18 | V2: 19 | W2: 20 | X2: 21 | Y2: 22 | Z2: 23 | AA2: 24 | AB2: 25 | AC2: 26 | AD2: 27 | AE2: 28 | AF2: 29 | AG2: 30 | AH2: 31 | AI2: 32 | AJ2: 33 | AK2: 34 | AL2: 35 | AM2: 36 | AN2: 37
E3: 2015 | F3: 2016 | G3: 2017 | H3: 2018 | I3: 2019 | J3: 2020 | K3: 2021 | L3: 2022 | M3: 2023 | N3: 2024 | O3: 2025 | P3: 2026 | Q3: 2027 | R3: 2028 | S3: 2029 | T3: 2030 | U3: 2031 | V3: 2032 | W3: 2033 | X3: 2034 | Y3: 2035 | Z3: 2036 | AA3: 2037 | AB3: 2038 | AC3: 2039 | AD3: 2040 | AE3: 2041 | AF3: 2042 | AG3: 2043 | AH3: 2044 | AI3: 2045 | AJ3: 2046 | AK3: 2047 | AL3: 2048 | AM3: 2049 | AN3: 2050 | AP3: RATIO
B4: ems_0 | C4: Total greenhouse gas emissions | D4: Mton CO2 eq | E4: =VLOOKUP($B4,baseline!$A:$AK,E$2,FALSE) -> #N/A | F4: =VLOOKUP($B4,baseline!$A:$AK,F$2,FALSE) -> #N/A | G4: =VLOOKUP($B4,baseline!$A:$AK,G$2,FALSE) -> #N/A | H4: =VLOOKUP($B4,baseline!$A:$AK,H$2,FALSE) -> #N/A | I4: =VLOOKUP($B4,baseline!$A:$AK,I$2,FALSE) -> #N/A | J4: =VLOOKUP($B4,baseline!$A:$AK,J$2,FALSE) -> #N/A | K4: =VLOOKUP($B4,baseline!$A:$AK,K$2,FALSE) -> #N/A | L4: =VLOOKUP($B4,baseline!$A:$AK,L$2,FALSE) -> #N/A | ... AN4: =VLOOKUP($B4,baseline!$A:$AK,AN$2,FALSE) -> #N/A | AP4: =AN4/E4 -> #N/A
C5: All non-CO2 emissions | D5: Mton CO2 eq | E5: =E4-SUM(E6:E9) -> #N/A | F5: =F4-SUM(F6:F9) -> #N/A | G5: =G4-SUM(G6:G9) -> #N/A | H5: =H4-SUM(H6:H9) -> #N/A | I5: =I4-SUM(I6:I9) -> #N/A | J5: =J4-SUM(J6:J9) -> #N/A | K5: =K4-SUM(K6:K9) -> #N/A | L5: =L4-SUM(L6:L9) -> #N/A | ... AN5: =AN4-SUM(AN6:AN9) -> #N/A | AP5: =AN5/E5 -> #N/A
B6: ems_y_co2_0 | C6: CO2 emissions connected to total output | D6: Mton CO2 eq | E6: =VLOOKUP($B6,baseline!$A:$AK,E$2,FALSE) -> #N/A | F6: =VLOOKUP($B6,baseline!$A:$AK,F$2,FALSE) -> #N/A | G6: =VLOOKUP($B6,baseline!$A:$AK,G$2,FALSE) -> #N/A | H6: =VLOOKUP($B6,baseline!$A:$AK,H$2,FALSE) -> #N/A | I6: =VLOOKUP($B6,baseline!$A:$AK,I$2,FALSE) -> #N/A | J6: =VLOOKUP($B6,baseline!$A:$AK,J$2,FALSE) -> #N/A | K6: =VLOOKUP($B6,baseline!$A:$AK,K$2,FALSE) -> #N/A | L6: =VLOOKUP($B6,baseline!$A:$AK,L$2,FALSE) -> #N/A | ... AN6: =VLOOKUP($B6,baseline!$A:$AK,AN$2,FALSE) -> #N/A | AP6: =AN6/E6 -> #N/A
B7: ems_ci_co2_0 | C7: CO2 emissions from intermediate consumption | D7: Mton CO2 eq | E7: =VLOOKUP($B7,baseline!$A:$AK,E$2,FALSE) -> #N/A | F7: =VLOOKUP($B7,baseline!$A:$AK,F$2,FALSE) -> #N/A | G7: =VLOOKUP($B7,baseline!$A:$AK,G$2,FALSE) -> #N/A | H7: =VLOOKUP($B7,baseline!$A:$AK,H$2,FALSE) -> #N/A | I7: =VLOOKUP($B7,baseline!$A:$AK,I$2,FALSE) -> #N/A | J7: =VLOOKUP($B7,baseline!$A:$AK,J$2,FALSE) -> #N/A | K7: =VLOOKUP($B7,baseline!$A:$AK,K$2,FALSE) -> #N/A | L7: =VLOOKUP($B7,baseline!$A:$AK,L$2,FALSE) -> #N/A | ... AN7: =VLOOKUP($B7,baseline!$A:$AK,AN$2,FALSE) -> #N/A | AP7: =AN7/E7 -> #N/A
B8: ems_mat_co2_0 | C8: CO2 emissions in materials | D8: Mton CO2 eq | E8: =VLOOKUP($B8,baseline!$A:$AK,E$2,FALSE) -> #N/A | F8: =VLOOKUP($B8,baseline!$A:$AK,F$2,FALSE) -> #N/A | G8: =VLOOKUP($B8,baseline!$A:$AK,G$2,FALSE) -> #N/A | H8: =VLOOKUP($B8,baseline!$A:$AK,H$2,FALSE) -> #N/A | I8: =VLOOKUP($B8,baseline!$A:$AK,I$2,FALSE) -> #N/A | J8: =VLOOKUP($B8,baseline!$A:$AK,J$2,FALSE) -> #N/A | K8: =VLOOKUP($B8,baseline!$A:$AK,K$2,FALSE) -> #N/A | L8: =VLOOKUP($B8,baseline!$A:$AK,L$2,FALSE) -> #N/A | ... AN8: =VLOOKUP($B8,baseline!$A:$AK,AN$2,FALSE) -> #N/A | AP8: =AN8/E8 -> #N/A
B9: ems_ch_co2_0 | C9: CO2 emissions from final consumption | D9: Mton CO2 eq | E9: =VLOOKUP($B9,baseline!$A:$AK,E$2,FALSE) -> #N/A | F9: =VLOOKUP($B9,baseline!$A:$AK,F$2,FALSE) -> #N/A | G9: =VLOOKUP($B9,baseline!$A:$AK,G$2,FALSE) -> #N/A | H9: =VLOOKUP($B9,baseline!$A:$AK,H$2,FALSE) -> #N/A | I9: =VLOOKUP($B9,baseline!$A:$AK,I$2,FALSE) -> #N/A | J9: =VLOOKUP($B9,baseline!$A:$AK,J$2,FALSE) -> #N/A | K9: =VLOOKUP($B9,baseline!$A:$AK,K$2,FALSE) -> #N/A | L9: =VLOOKUP($B9,baseline!$A:$AK,L$2,FALSE) -> #N/A | ... AN9: =VLOOKUP($B9,baseline!$A:$AK,AN$2,FALSE) -> #N/A | AP9: =AN9/E9 -> #N/A
B10: ems_c02_0 | C10: Total CO2 emissions | D10: Mton CO2 eq | E10: =SUM(E6:E9) -> #N/A | F10: =SUM(F6:F9) -> #N/A | G10: =SUM(G6:G9) -> #N/A | H10: =SUM(H6:H9) -> #N/A | I10: =SUM(I6:I9) -> #N/A | J10: =SUM(J6:J9) -> #N/A | K10: =SUM(K6:K9) -> #N/A | L10: =SUM(L6:L9) -> #N/A | ... AN10: =SUM(AN6:AN9) -> #N/A | AP10: =AN10/E10 -> #N/A
B12: ems_ci_co2_sagr_0 | D12: Mton CO2 eq | E12: =VLOOKUP($B12,baseline!$A:$AK,E$2,FALSE) -> #N/A | F12: =VLOOKUP($B12,baseline!$A:$AK,F$2,FALSE) -> #N/A | G12: =VLOOKUP($B12,baseline!$A:$AK,G$2,FALSE) -> #N/A | H12: =VLOOKUP($B12,baseline!$A:$AK,H$2,FALSE) -> #N/A | I12: =VLOOKUP($B12,baseline!$A:$AK,I$2,FALSE) -> #N/A | J12: =VLOOKUP($B12,baseline!$A:$AK,J$2,FALSE) -> #N/A | K12: =VLOOKUP($B12,baseline!$A:$AK,K$2,FALSE) -> #N/A | L12: =VLOOKUP($B12,baseline!$A:$AK,L$2,FALSE) -> #N/A | ... AN12: =VLOOKUP($B12,baseline!$A:$AK,AN$2,FALSE) -> #N/A | AP12: =AN12/E12 -> #N/A
B13: ems_ci_co2_smet_0 | D13: Mton CO2 eq | E13: =VLOOKUP($B13,baseline!$A:$AK,E$2,FALSE) -> #N/A | F13: =VLOOKUP($B13,baseline!$A:$AK,F$2,FALSE) -> #N/A | G13: =VLOOKUP($B13,baseline!$A:$AK,G$2,FALSE) -> #N/A | H13: =VLOOKUP($B13,baseline!$A:$AK,H$2,FALSE) -> #N/A | I13: =VLOOKUP($B13,baseline!$A:$AK,I$2,FALSE) -> #N/A | J13: =VLOOKUP($B13,baseline!$A:$AK,J$2,FALSE) -> #N/A | K13: =VLOOKUP($B13,baseline!$A:$AK,K$2,FALSE) -> #N/A | L13: =VLOOKUP($B13,baseline!$A:$AK,L$2,FALSE) -> #N/A | ... AN13: =VLOOKUP($B13,baseline!$A:$AK,AN$2,FALSE) -> #N/A | AP13: =AN13/E13 -> #N/A
B14: ems_ci_co2_schem_0 | D14: Mton CO2 eq | E14: =VLOOKUP($B14,baseline!$A:$AK,E$2,FALSE) -> #N/A | F14: =VLOOKUP($B14,baseline!$A:$AK,F$2,FALSE) -> #N/A | G14: =VLOOKUP($B14,baseline!$A:$AK,G$2,FALSE) -> #N/A | H14: =VLOOKUP($B14,baseline!$A:$AK,H$2,FALSE) -> #N/A | I14: =VLOOKUP($B14,baseline!$A:$AK,I$2,FALSE) -> #N/A | J14: =VLOOKUP($B14,baseline!$A:$AK,J$2,FALSE) -> #N/A | K14: =VLOOKUP($B14,baseline!$A:$AK,K$2,FALSE) -> #N/A | L14: =VLOOKUP($B14,baseline!$A:$AK,L$2,FALSE) -> #N/A | ... AN14: =VLOOKUP($B14,baseline!$A:$AK,AN$2,FALSE) -> #N/A | AP14: =AN14/E14 -> #N/A
B15: ems_ci_co2_spla_0 | D15: Mton CO2 eq | E15: =VLOOKUP($B15,baseline!$A:$AK,E$2,FALSE) -> #N/A | F15: =VLOOKUP($B15,baseline!$A:$AK,F$2,FALSE) -> #N/A | G15: =VLOOKUP($B15,baseline!$A:$AK,G$2,FALSE) -> #N/A | H15: =VLOOKUP($B15,baseline!$A:$AK,H$2,FALSE) -> #N/A | I15: =VLOOKUP($B15,baseline!$A:$AK,I$2,FALSE) -> #N/A | J15: =VLOOKUP($B15,baseline!$A:$AK,J$2,FALSE) -> #N/A | K15: =VLOOKUP($B15,baseline!$A:$AK,K$2,FALSE) -> #N/A | L15: =VLOOKUP($B15,baseline!$A:$AK,L$2,FALSE) -> #N/A | ... AN15: =VLOOKUP($B15,baseline!$A:$AK,AN$2,FALSE) -> #N/A | AP15: =AN15/E15 -> #N/A
B16: ems_ci_co2_sgla_0 | D16: Mton CO2 eq | E16: =VLOOKUP($B16,baseline!$A:$AK,E$2,FALSE) -> #N/A | F16: =VLOOKUP($B16,baseline!$A:$AK,F$2,FALSE) -> #N/A | G16: =VLOOKUP($B16,baseline!$A:$AK,G$2,FALSE) -> #N/A | H16: =VLOOKUP($B16,baseline!$A:$AK,H$2,FALSE) -> #N/A | I16: =VLOOKUP($B16,baseline!$A:$AK,I$2,FALSE) -> #N/A | J16: =VLOOKUP($B16,baseline!$A:$AK,J$2,FALSE) -> #N/A | K16: =VLOOKUP($B16,baseline!$A:$AK,K$2,FALSE) -> #N/A | L16: =VLOOKUP($B16,baseline!$A:$AK,L$2,FALSE) -> #N/A | ... AN16: =VLOOKUP($B16,baseline!$A:$AK,AN$2,FALSE) -> #N/A | AP16: =AN16/E16 -> #N/A
B17: ems_ci_co2_spap_0 | D17: Mton CO2 eq | E17: =VLOOKUP($B17,baseline!$A:$AK,E$2,FALSE) -> #N/A | F17: =VLOOKUP($B17,baseline!$A:$AK,F$2,FALSE) -> #N/A | G17: =VLOOKUP($B17,baseline!$A:$AK,G$2,FALSE) -> #N/A | H17: =VLOOKUP($B17,baseline!$A:$AK,H$2,FALSE) -> #N/A | I17: =VLOOKUP($B17,baseline!$A:$AK,I$2,FALSE) -> #N/A | J17: =VLOOKUP($B17,baseline!$A:$AK,J$2,FALSE) -> #N/A | K17: =VLOOKUP($B17,baseline!$A:$AK,K$2,FALSE) -> #N/A | L17: =VLOOKUP($B17,baseline!$A:$AK,L$2,FALSE) -> #N/A | ... AN17: =VLOOKUP($B17,baseline!$A:$AK,AN$2,FALSE) -> #N/A | AP17: =AN17/E17 -> #N/A
B18: ems_ci_co2_sfoo_0 | D18: Mton CO2 eq | E18: =VLOOKUP($B18,baseline!$A:$AK,E$2,FALSE) -> #N/A | F18: =VLOOKUP($B18,baseline!$A:$AK,F$2,FALSE) -> #N/A | G18: =VLOOKUP($B18,baseline!$A:$AK,G$2,FALSE) -> #N/A | H18: =VLOOKUP($B18,baseline!$A:$AK,H$2,FALSE) -> #N/A | I18: =VLOOKUP($B18,baseline!$A:$AK,I$2,FALSE) -> #N/A | J18: =VLOOKUP($B18,baseline!$A:$AK,J$2,FALSE) -> #N/A | K18: =VLOOKUP($B18,baseline!$A:$AK,K$2,FALSE) -> #N/A | L18: =VLOOKUP($B18,baseline!$A:$AK,L$2,FALSE) -> #N/A | ... AN18: =VLOOKUP($B18,baseline!$A:$AK,AN$2,FALSE) -> #N/A | AP18: =AN18/E18 -> #N/A
B19: ems_ci_co2_sres_0 | D19: Mton CO2 eq | E19: =VLOOKUP($B19,baseline!$A:$AK,E$2,FALSE) -> #N/A | F19: =VLOOKUP($B19,baseline!$A:$AK,F$2,FALSE) -> #N/A | G19: =VLOOKUP($B19,baseline!$A:$AK,G$2,FALSE) -> #N/A | H19: =VLOOKUP($B19,baseline!$A:$AK,H$2,FALSE) -> #N/A | I19: =VLOOKUP($B19,baseline!$A:$AK,I$2,FALSE) -> #N/A | J19: =VLOOKUP($B19,baseline!$A:$AK,J$2,FALSE) -> #N/A | K19: =VLOOKUP($B19,baseline!$A:$AK,K$2,FALSE) -> #N/A | L19: =VLOOKUP($B19,baseline!$A:$AK,L$2,FALSE) -> #N/A | ... AN19: =VLOOKUP($B19,baseline!$A:$AK,AN$2,FALSE) -> #N/A | AP19: =AN19/E19 -> #N/A
B20: ems_ci_co2_sroa_0 | D20: Mton CO2 eq | E20: =VLOOKUP($B20,baseline!$A:$AK,E$2,FALSE) -> #N/A | F20: =VLOOKUP($B20,baseline!$A:$AK,F$2,FALSE) -> #N/A | G20: =VLOOKUP($B20,baseline!$A:$AK,G$2,FALSE) -> #N/A | H20: =VLOOKUP($B20,baseline!$A:$AK,H$2,FALSE) -> #N/A | I20: =VLOOKUP($B20,baseline!$A:$AK,I$2,FALSE) -> #N/A | J20: =VLOOKUP($B20,baseline!$A:$AK,J$2,FALSE) -> #N/A | K20: =VLOOKUP($B20,baseline!$A:$AK,K$2,FALSE) -> #N/A | L20: =VLOOKUP($B20,baseline!$A:$AK,L$2,FALSE) -> #N/A | ... AN20: =VLOOKUP($B20,baseline!$A:$AK,AN$2,FALSE) -> #N/A | AP20: =AN20/E20 -> #N/A
B21: ems_ci_co2_swat_0 | D21: Mton CO2 eq | E21: =VLOOKUP($B21,baseline!$A:$AK,E$2,FALSE) -> #N/A | F21: =VLOOKUP($B21,baseline!$A:$AK,F$2,FALSE) -> #N/A | G21: =VLOOKUP($B21,baseline!$A:$AK,G$2,FALSE) -> #N/A | H21: =VLOOKUP($B21,baseline!$A:$AK,H$2,FALSE) -> #N/A | I21: =VLOOKUP($B21,baseline!$A:$AK,I$2,FALSE) -> #N/A | J21: =VLOOKUP($B21,baseline!$A:$AK,J$2,FALSE) -> #N/A | K21: =VLOOKUP($B21,baseline!$A:$AK,K$2,FALSE) -> #N/A | L21: =VLOOKUP($B21,baseline!$A:$AK,L$2,FALSE) -> #N/A | ... AN21: =VLOOKUP($B21,baseline!$A:$AK,AN$2,FALSE) -> #N/A | AP21: =AN21/E21 -> #N/A
B22: ems_ci_co2_sair_0 | D22: Mton CO2 eq | E22: =VLOOKUP($B22,baseline!$A:$AK,E$2,FALSE) -> #N/A | F22: =VLOOKUP($B22,baseline!$A:$AK,F$2,FALSE) -> #N/A | G22: =VLOOKUP($B22,baseline!$A:$AK,G$2,FALSE) -> #N/A | H22: =VLOOKUP($B22,baseline!$A:$AK,H$2,FALSE) -> #N/A | I22: =VLOOKUP($B22,baseline!$A:$AK,I$2,FALSE) -> #N/A | J22: =VLOOKUP($B22,baseline!$A:$AK,J$2,FALSE) -> #N/A | K22: =VLOOKUP($B22,baseline!$A:$AK,K$2,FALSE) -> #N/A | L22: =VLOOKUP($B22,baseline!$A:$AK,L$2,FALSE) -> #N/A | ... AN22: =VLOOKUP($B22,baseline!$A:$AK,AN$2,FALSE) -> #N/A | AP22: =AN22/E22 -> #N/A
B23: ems_ci_co2_scoa_0 | D23: Mton CO2 eq | E23: =VLOOKUP($B23,baseline!$A:$AK,E$2,FALSE) -> #N/A | F23: =VLOOKUP($B23,baseline!$A:$AK,F$2,FALSE) -> #N/A | G23: =VLOOKUP($B23,baseline!$A:$AK,G$2,FALSE) -> #N/A | H23: =VLOOKUP($B23,baseline!$A:$AK,H$2,FALSE) -> #N/A | I23: =VLOOKUP($B23,baseline!$A:$AK,I$2,FALSE) -> #N/A | J23: =VLOOKUP($B23,baseline!$A:$AK,J$2,FALSE) -> #N/A | K23: =VLOOKUP($B23,baseline!$A:$AK,K$2,FALSE) -> #N/A | L23: =VLOOKUP($B23,baseline!$A:$AK,L$2,FALSE) -> #N/A | ... AN23: =VLOOKUP($B23,baseline!$A:$AK,AN$2,FALSE) -> #N/A | AP23: =AN23/E23 -> #N/A
... B38: ems_ci_co2_shea_0 | D38: Mton CO2 eq | E38: =VLOOKUP($B38,baseline!$A:$AK,E$2,FALSE) -> #N/A | F38: =VLOOKUP($B38,baseline!$A:$AK,F$2,FALSE) -> #N/A | G38: =VLOOKUP($B38,baseline!$A:$AK,G$2,FALSE) -> #N/A | H38: =VLOOKUP($B38,baseline!$A:$AK,H$2,FALSE) -> #N/A | I38: =VLOOKUP($B38,baseline!$A:$AK,I$2,FALSE) -> #N/A | J38: =VLOOKUP($B38,baseline!$A:$AK,J$2,FALSE) -> #N/A | K38: =VLOOKUP($B38,baseline!$A:$AK,K$2,FALSE) -> #N/A | L38: =VLOOKUP($B38,baseline!$A:$AK,L$2,FALSE) -> #N/A | ... AN38: =VLOOKUP($B38,baseline!$A:$AK,AN$2,FALSE) -> #N/A | AP38: =AN38/E38 -> #N/A
A40: Emission intensity per euro output
B42: y_sagr_0 | D42: mln euro | E42: =VLOOKUP($B42,baseline!$A:$AK,E$2,FALSE) -> #N/A | F42: =VLOOKUP($B42,baseline!$A:$AK,F$2,FALSE) -> #N/A | G42: =VLOOKUP($B42,baseline!$A:$AK,G$2,FALSE) -> #N/A | H42: =VLOOKUP($B42,baseline!$A:$AK,H$2,FALSE) -> #N/A | I42: =VLOOKUP($B42,baseline!$A:$AK,I$2,FALSE) -> #N/A | J42: =VLOOKUP($B42,baseline!$A:$AK,J$2,FALSE) -> #N/A | K42: =VLOOKUP($B42,baseline!$A:$AK,K$2,FALSE) -> #N/A | L42: =VLOOKUP($B42,baseline!$A:$AK,L$2,FALSE) -> #N/A | ... AN42: =VLOOKUP($B42,baseline!$A:$AK,AN$2,FALSE) -> #N/A | AP42: =AN42/E42 -> #N/A
B43: y_smet_0 | D43: mln euro | E43: =VLOOKUP($B43,baseline!$A:$AK,E$2,FALSE) -> #N/A | F43: =VLOOKUP($B43,baseline!$A:$AK,F$2,FALSE) -> #N/A | G43: =VLOOKUP($B43,baseline!$A:$AK,G$2,FALSE) -> #N/A | H43: =VLOOKUP($B43,baseline!$A:$AK,H$2,FALSE) -> #N/A | I43: =VLOOKUP($B43,baseline!$A:$AK,I$2,FALSE) -> #N/A | J43: =VLOOKUP($B43,baseline!$A:$AK,J$2,FALSE) -> #N/A | K43: =VLOOKUP($B43,baseline!$A:$AK,K$2,FALSE) -> #N/A | L43: =VLOOKUP($B43,baseline!$A:$AK,L$2,FALSE) -> #N/A | ... AN43: =VLOOKUP($B43,baseline!$A:$AK,AN$2,FALSE) -> #N/A | AP43: =AN43/E43 -> #N/A
B44: y_schem_0 | D44: mln euro | E44: =VLOOKUP($B44,baseline!$A:$AK,E$2,FALSE) -> #N/A | F44: =VLOOKUP($B44,baseline!$A:$AK,F$2,FALSE) -> #N/A | G44: =VLOOKUP($B44,baseline!$A:$AK,G$2,FALSE) -> #N/A | H44: =VLOOKUP($B44,baseline!$A:$AK,H$2,FALSE) -> #N/A | I44: =VLOOKUP($B44,baseline!$A:$AK,I$2,FALSE) -> #N/A | J44: =VLOOKUP($B44,baseline!$A:$AK,J$2,FALSE) -> #N/A | K44: =VLOOKUP($B44,baseline!$A:$AK,K$2,FALSE) -> #N/A | L44: =VLOOKUP($B44,baseline!$A:$AK,L$2,FALSE) -> #N/A | ... AN44: =VLOOKUP($B44,baseline!$A:$AK,AN$2,FALSE) -> #N/A | AP44: =AN44/E44 -> #N/A
B45: y_spla_0 | D45: mln euro | E45: =VLOOKUP($B45,baseline!$A:$AK,E$2,FALSE) -> #N/A | F45: =VLOOKUP($B45,baseline!$A:$AK,F$2,FALSE) -> #N/A | G45: =VLOOKUP($B45,baseline!$A:$AK,G$2,FALSE) -> #N/A | H45: =VLOOKUP($B45,baseline!$A:$AK,H$2,FALSE) -> #N/A | I45: =VLOOKUP($B45,baseline!$A:$AK,I$2,FALSE) -> #N/A | J45: =VLOOKUP($B45,baseline!$A:$AK,J$2,FALSE) -> #N/A | K45: =VLOOKUP($B45,baseline!$A:$AK,K$2,FALSE) -> #N/A | L45: =VLOOKUP($B45,baseline!$A:$AK,L$2,FALSE) -> #N/A | ... AN45: =VLOOKUP($B45,baseline!$A:$AK,AN$2,FALSE) -> #N/A | AP45: =AN45/E45 -> #N/A
B46: y_sgla_0 | D46: mln euro | E46: =VLOOKUP($B46,baseline!$A:$AK,E$2,FALSE) -> #N/A | F46: =VLOOKUP($B46,baseline!$A:$AK,F$2,FALSE) -> #N/A | G46: =VLOOKUP($B46,baseline!$A:$AK,G$2,FALSE) -> #N/A | H46: =VLOOKUP($B46,baseline!$A:$AK,H$2,FALSE) -> #N/A | I46: =VLOOKUP($B46,baseline!$A:$AK,I$2,FALSE) -> #N/A | J46: =VLOOKUP($B46,baseline!$A:$AK,J$2,FALSE) -> #N/A | K46: =VLOOKUP($B46,baseline!$A:$AK,K$2,FALSE) -> #N/A | L46: =VLOOKUP($B46,baseline!$A:$AK,L$2,FALSE) -> #N/A | ... AN46: =VLOOKUP($B46,baseline!$A:$AK,AN$2,FALSE) -> #N/A | AP46: =AN46/E46 -> #N/A
B47: y_spap_0 | D47: mln euro | E47: =VLOOKUP($B47,baseline!$A:$AK,E$2,FALSE) -> #N/A | F47: =VLOOKUP($B47,baseline!$A:$AK,F$2,FALSE) -> #N/A | G47: =VLOOKUP($B47,baseline!$A:$AK,G$2,FALSE) -> #N/A | H47: =VLOOKUP($B47,baseline!$A:$AK,H$2,FALSE) -> #N/A | I47: =VLOOKUP($B47,baseline!$A:$AK,I$2,FALSE) -> #N/A | J47: =VLOOKUP($B47,baseline!$A:$AK,J$2,FALSE) -> #N/A | K47: =VLOOKUP($B47,baseline!$A:$AK,K$2,FALSE) -> #N/A | L47: =VLOOKUP($B47,baseline!$A:$AK,L$2,FALSE) -> #N/A | ... AN47: =VLOOKUP($B47,baseline!$A:$AK,AN$2,FALSE) -> #N/A | AP47: =AN47/E47 -> #N/A
B48: y_sfoo_0 | D48: mln euro | E48: =VLOOKUP($B48,baseline!$A:$AK,E$2,FALSE) -> #N/A | F48: =VLOOKUP($B48,baseline!$A:$AK,F$2,FALSE) -> #N/A | G48: =VLOOKUP($B48,baseline!$A:$AK,G$2,FALSE) -> #N/A | H48: =VLOOKUP($B48,baseline!$A:$AK,H$2,FALSE) -> #N/A | I48: =VLOOKUP($B48,baseline!$A:$AK,I$2,FALSE) -> #N/A | J48: =VLOOKUP($B48,baseline!$A:$AK,J$2,FALSE) -> #N/A | K48: =VLOOKUP($B48,baseline!$A:$AK,K$2,FALSE) -> #N/A | L48: =VLOOKUP($B48,baseline!$A:$AK,L$2,FALSE) -> #N/A | ... AN48: =VLOOKUP($B48,baseline!$A:$AK,AN$2,FALSE) -> #N/A | AP48: =AN48/E48 -> #N/A
B49: y_sres_0 | D49: mln euro | E49: =VLOOKUP($B49,baseline!$A:$AK,E$2,FALSE) -> #N/A | F49: =VLOOKUP($B49,baseline!$A:$AK,F$2,FALSE) -> #N/A | G49: =VLOOKUP($B49,baseline!$A:$AK,G$2,FALSE) -> #N/A | H49: =VLOOKUP($B49,baseline!$A:$AK,H$2,FALSE) -> #N/A | I49: =VLOOKUP($B49,baseline!$A:$AK,I$2,FALSE) -> #N/A | J49: =VLOOKUP($B49,baseline!$A:$AK,J$2,FALSE) -> #N/A | K49: =VLOOKUP($B49,baseline!$A:$AK,K$2,FALSE) -> #N/A | L49: =VLOOKUP($B49,baseline!$A:$AK,L$2,FALSE) -> #N/A | ... AN49: =VLOOKUP($B49,baseline!$A:$AK,AN$2,FALSE) -> #N/A | AP49: =AN49/E49 -> #N/A
B50: y_sroa_0 | D50: mln euro | E50: =VLOOKUP($B50,baseline!$A:$AK,E$2,FALSE) -> #N/A | F50: =VLOOKUP($B50,baseline!$A:$AK,F$2,FALSE) -> #N/A | G50: =VLOOKUP($B50,baseline!$A:$AK,G$2,FALSE) -> #N/A | H50: =VLOOKUP($B50,baseline!$A:$AK,H$2,FALSE) -> #N/A | I50: =VLOOKUP($B50,baseline!$A:$AK,I$2,FALSE) -> #N/A | J50: =VLOOKUP($B50,baseline!$A:$AK,J$2,FALSE) -> #N/A | K50: =VLOOKUP($B50,baseline!$A:$AK,K$2,FALSE) -> #N/A | L50: =VLOOKUP($B50,baseline!$A:$AK,L$2,FALSE) -> #N/A | ... AN50: =VLOOKUP($B50,baseline!$A:$AK,AN$2,FALSE) -> #N/A | AP50: =AN50/E50 -> #N/A
B51: y_swat_0 | D51: mln euro | E51: =VLOOKUP($B51,baseline!$A:$AK,E$2,FALSE) -> #N/A | F51: =VLOOKUP($B51,baseline!$A:$AK,F$2,FALSE) -> #N/A | G51: =VLOOKUP($B51,baseline!$A:$AK,G$2,FALSE) -> #N/A | H51: =VLOOKUP($B51,baseline!$A:$AK,H$2,FALSE) -> #N/A | I51: =VLOOKUP($B51,baseline!$A:$AK,I$2,FALSE) -> #N/A | J51: =VLOOKUP($B51,baseline!$A:$AK,J$2,FALSE) -> #N/A | K51: =VLOOKUP($B51,baseline!$A:$AK,K$2,FALSE) -> #N/A | L51: =VLOOKUP($B51,baseline!$A:$AK,L$2,FALSE) -> #N/A | ... AN51: =VLOOKUP($B51,baseline!$A:$AK,AN$2,FALSE) -> #N/A | AP51: =AN51/E51 -> #N/A
B52: y_sair_0 | D52: mln euro | E52: =VLOOKUP($B52,baseline!$A:$AK,E$2,FALSE) -> #N/A | F52: =VLOOKUP($B52,baseline!$A:$AK,F$2,FALSE) -> #N/A | G52: =VLOOKUP($B52,baseline!$A:$AK,G$2,FALSE) -> #N/A | H52: =VLOOKUP($B52,baseline!$A:$AK,H$2,FALSE) -> #N/A | I52: =VLOOKUP($B52,baseline!$A:$AK,I$2,FALSE) -> #N/A | J52: =VLOOKUP($B52,baseline!$A:$AK,J$2,FALSE) -> #N/A | K52: =VLOOKUP($B52,baseline!$A:$AK,K$2,FALSE) -> #N/A | L52: =VLOOKUP($B52,baseline!$A:$AK,L$2,FALSE) -> #N/A | ... AN52: =VLOOKUP($B52,baseline!$A:$AK,AN$2,FALSE) -> #N/A | AP52: =AN52/E52 -> #N/A
B53: y_scoa_0 | D53: mln euro | E53: =VLOOKUP($B53,baseline!$A:$AK,E$2,FALSE) -> #N/A | F53: =VLOOKUP($B53,baseline!$A:$AK,F$2,FALSE) -> #N/A | G53: =VLOOKUP($B53,baseline!$A:$AK,G$2,FALSE) -> #N/A | H53: =VLOOKUP($B53,baseline!$A:$AK,H$2,FALSE) -> #N/A | I53: =VLOOKUP($B53,baseline!$A:$AK,I$2,FALSE) -> #N/A | J53: =VLOOKUP($B53,baseline!$A:$AK,J$2,FALSE) -> #N/A | K53: =VLOOKUP($B53,baseline!$A:$AK,K$2,FALSE) -> #N/A | L53: =VLOOKUP($B53,baseline!$A:$AK,L$2,FALSE) -> #N/A | ... AN53: =VLOOKUP($B53,baseline!$A:$AK,AN$2,FALSE) -> #N/A | AP53: =AN53/E53 -> #N/A
... B68: y_shea_0 | D68: mln euro | E68: =VLOOKUP($B68,baseline!$A:$AK,E$2,FALSE) -> #N/A | F68: =VLOOKUP($B68,baseline!$A:$AK,F$2,FALSE) -> #N/A | G68: =VLOOKUP($B68,baseline!$A:$AK,G$2,FALSE) -> #N/A | H68: =VLOOKUP($B68,baseline!$A:$AK,H$2,FALSE) -> #N/A | I68: =VLOOKUP($B68,baseline!$A:$AK,I$2,FALSE) -> #N/A | J68: =VLOOKUP($B68,baseline!$A:$AK,J$2,FALSE) -> #N/A | K68: =VLOOKUP($B68,baseline!$A:$AK,K$2,FALSE) -> #N/A | L68: =VLOOKUP($B68,baseline!$A:$AK,L$2,FALSE) -> #N/A | ... AN68: =VLOOKUP($B68,baseline!$A:$AK,AN$2,FALSE) -> #N/A | AP68: =AN68/E68 -> #N/A
B70: =B42&"/"&B12 -> y_sagr_0/ems_ci_co2_sagr_0 | D70: kton/mln euro | E70: =E12/E42*1000 -> #N/A | F70: =F12/F42*1000 -> #N/A | G70: =G12/G42*1000 -> #N/A | H70: =H12/H42*1000 -> #N/A | I70: =I12/I42*1000 -> #N/A | J70: =J12/J42*1000 -> #N/A | K70: =K12/K42*1000 -> #N/A | L70: =L12/L42*1000 -> #N/A | ... AN70: =AN12/AN42*1000 -> #N/A | AP70: =AN70/E70 -> #N/A
B71: =B43&"/"&B13 -> y_smet_0/ems_ci_co2_smet_0 | D71: kton/mln euro | E71: =E13/E43*1000 -> #N/A | F71: =F13/F43*1000 -> #N/A | G71: =G13/G43*1000 -> #N/A | H71: =H13/H43*1000 -> #N/A | I71: =I13/I43*1000 -> #N/A | J71: =J13/J43*1000 -> #N/A | K71: =K13/K43*1000 -> #N/A | L71: =L13/L43*1000 -> #N/A | ... AN71: =AN13/AN43*1000 -> #N/A | AP71: =AN71/E71 -> #N/A
B72: =B44&"/"&B14 -> y_schem_0/ems_ci_co2_schem_0 | D72: kton/mln euro | E72: =E14/E44*1000 -> #N/A | F72: =F14/F44*1000 -> #N/A | G72: =G14/G44*1000 -> #N/A | H72: =H14/H44*1000 -> #N/A | I72: =I14/I44*1000 -> #N/A | J72: =J14/J44*1000 -> #N/A | K72: =K14/K44*1000 -> #N/A | L72: =L14/L44*1000 -> #N/A | ... AN72: =AN14/AN44*1000 -> #N/A | AP72: =AN72/E72 -> #N/A
...

Sheet va
A1: Total value added
E2: 2 | F2: 3 | G2: 4 | H2: 5 | I2: 6 | J2: 7 | K2: 8 | L2: 9 | M2: 10 | N2: 11 | O2: 12 | P2: 13 | Q2: 14 | R2: 15 | S2: 16 | T2: 17 | U2: 18 | V2: 19 | W2: 20 | X2: 21 | Y2: 22 | Z2: 23 | AA2: 24 | AB2: 25 | AC2: 26 | AD2: 27 | AE2: 28 | AF2: 29 | AG2: 30 | AH2: 31 | AI2: 32 | AJ2: 33 | AK2: 34 | AL2: 35 | AM2: 36 | AN2: 37
E3: 2015 | F3: 2016 | G3: 2017 | H3: 2018 | I3: 2019 | J3: 2020 | K3: 2021 | L3: 2022 | M3: 2023 | N3: 2024 | O3: 2025 | P3: 2026 | Q3: 2027 | R3: 2028 | S3: 2029 | T3: 2030 | U3: 2031 | V3: 2032 | W3: 2033 | X3: 2034 | Y3: 2035 | Z3: 2036 | AA3: 2037 | AB3: 2038 | AC3: 2039 | AD3: 2040 | AE3: 2041 | AF3: 2042 | AG3: 2043 | AH3: 2044 | AI3: 2045 | AJ3: 2046 | AK3: 2047 | AL3: 2048 | AM3: 2049 | AN3: 2050
B4: va_sagr_0 | D4: mln euro | E4: =VLOOKUP($B4,baseline!$A:$AK,E$2,FALSE) -> #N/A | F4: =VLOOKUP($B4,baseline!$A:$AK,F$2,FALSE) -> #N/A | G4: =VLOOKUP($B4,baseline!$A:$AK,G$2,FALSE) -> #N/A | H4: =VLOOKUP($B4,baseline!$A:$AK,H$2,FALSE) -> #N/A | I4: =VLOOKUP($B4,baseline!$A:$AK,I$2,FALSE) -> #N/A | J4: =VLOOKUP($B4,baseline!$A:$AK,J$2,FALSE) -> #N/A | K4: =VLOOKUP($B4,baseline!$A:$AK,K$2,FALSE) -> #N/A | L4: =VLOOKUP($B4,baseline!$A:$AK,L$2,FALSE) -> #N/A | ... AN4: =VLOOKUP($B4,baseline!$A:$AK,AN$2,FALSE) -> #N/A | AP4: =AN4/E4 -> #N/A
B5: va_smet_0 | D5: mln euro | E5: =VLOOKUP($B5,baseline!$A:$AK,E$2,FALSE) -> #N/A | F5: =VLOOKUP($B5,baseline!$A:$AK,F$2,FALSE) -> #N/A | G5: =VLOOKUP($B5,baseline!$A:$AK,G$2,FALSE) -> #N/A | H5: =VLOOKUP($B5,baseline!$A:$AK,H$2,FALSE) -> #N/A | I5: =VLOOKUP($B5,baseline!$A:$AK,I$2,FALSE) -> #N/A | J5: =VLOOKUP($B5,baseline!$A:$AK,J$2,FALSE) -> #N/A | K5: =VLOOKUP($B5,baseline!$A:$AK,K$2,FALSE) -> #N/A | L5: =VLOOKUP($B5,baseline!$A:$AK,L$2,FALSE) -> #N/A | ... AN5: =VLOOKUP($B5,baseline!$A:$AK,AN$2,FALSE) -> #N/A | AP5: =AN5/E5 -> #N/A
B6: va_schem_0 | D6: mln euro | E6: =VLOOKUP($B6,baseline!$A:$AK,E$2,FALSE) -> #N/A | F6: =VLOOKUP($B6,baseline!$A:$AK,F$2,FALSE) -> #N/A | G6: =VLOOKUP($B6,baseline!$A:$AK,G$2,FALSE) -> #N/A | H6: =VLOOKUP($B6,baseline!$A:$AK,H$2,FALSE) -> #N/A | I6: =VLOOKUP($B6,baseline!$A:$AK,I$2,FALSE) -> #N/A | J6: =VLOOKUP($B6,baseline!$A:$AK,J$2,FALSE) -> #N/A | K6: =VLOOKUP($B6,baseline!$A:$AK,K$2,FALSE) -> #N/A | L6: =VLOOKUP($B6,baseline!$A:$AK,L$2,FALSE) -> #N/A | ... AN6: =VLOOKUP($B6,baseline!$A:$AK,AN$2,FALSE) -> #N/A | AP6: =AN6/E6 -> #N/A
B7: va_spla_0 | D7: mln euro | E7: =VLOOKUP($B7,baseline!$A:$AK,E$2,FALSE) -> #N/A | F7: =VLOOKUP($B7,baseline!$A:$AK,F$2,FALSE) -> #N/A | G7: =VLOOKUP($B7,baseline!$A:$AK,G$2,FALSE) -> #N/A | H7: =VLOOKUP($B7,baseline!$A:$AK,H$2,FALSE) -> #N/A | I7: =VLOOKUP($B7,baseline!$A:$AK,I$2,FALSE) -> #N/A | J7: =VLOOKUP($B7,baseline!$A:$AK,J$2,FALSE) -> #N/A | K7: =VLOOKUP($B7,baseline!$A:$AK,K$2,FALSE) -> #N/A | L7: =VLOOKUP($B7,baseline!$A:$AK,L$2,FALSE) -> #N/A | ... AN7: =VLOOKUP($B7,baseline!$A:$AK,AN$2,FALSE) -> #N/A | AP7: =AN7/E7 -> #N/A
B8: va_sgla_0 | D8: mln euro | E8: =VLOOKUP($B8,baseline!$A:$AK,E$2,FALSE) -> #N/A | F8: =VLOOKUP($B8,baseline!$A:$AK,F$2,FALSE) -> #N/A | G8: =VLOOKUP($B8,baseline!$A:$AK,G$2,FALSE) -> #N/A | H8: =VLOOKUP($B8,baseline!$A:$AK,H$2,FALSE) -> #N/A | I8: =VLOOKUP($B8,baseline!$A:$AK,I$2,FALSE) -> #N/A | J8: =VLOOKUP($B8,baseline!$A:$AK,J$2,FALSE) -> #N/A | K8: =VLOOKUP($B8,baseline!$A:$AK,K$2,FALSE) -> #N/A | L8: =VLOOKUP($B8,baseline!$A:$AK,L$2,FALSE) -> #N/A | ... AN8: =VLOOKUP($B8,baseline!$A:$AK,AN$2,FALSE) -> #N/A | AP8: =AN8/E8 -> #N/A
B9: va_spap_0 | D9: mln euro | E9: =VLOOKUP($B9,baseline!$A:$AK,E$2,FALSE) -> #N/A | F9: =VLOOKUP($B9,baseline!$A:$AK,F$2,FALSE) -> #N/A | G9: =VLOOKUP($B9,baseline!$A:$AK,G$2,FALSE) -> #N/A | H9: =VLOOKUP($B9,baseline!$A:$AK,H$2,FALSE) -> #N/A | I9: =VLOOKUP($B9,baseline!$A:$AK,I$2,FALSE) -> #N/A | J9: =VLOOKUP($B9,baseline!$A:$AK,J$2,FALSE) -> #N/A | K9: =VLOOKUP($B9,baseline!$A:$AK,K$2,FALSE) -> #N/A | L9: =VLOOKUP($B9,baseline!$A:$AK,L$2,FALSE) -> #N/A | ... AN9: =VLOOKUP($B9,baseline!$A:$AK,AN$2,FALSE) -> #N/A | AP9: =AN9/E9 -> #N/A
B10: va_sfoo_0 | D10: mln euro | E10: =VLOOKUP($B10,baseline!$A:$AK,E$2,FALSE) -> #N/A | F10: =VLOOKUP($B10,baseline!$A:$AK,F$2,FALSE) -> #N/A | G10: =VLOOKUP($B10,baseline!$A:$AK,G$2,FALSE) -> #N/A | H10: =VLOOKUP($B10,baseline!$A:$AK,H$2,FALSE) -> #N/A | I10: =VLOOKUP($B10,baseline!$A:$AK,I$2,FALSE) -> #N/A | J10: =VLOOKUP($B10,baseline!$A:$AK,J$2,FALSE) -> #N/A | K10: =VLOOKUP($B10,baseline!$A:$AK,K$2,FALSE) -> #N/A | L10: =VLOOKUP($B10,baseline!$A:$AK,L$2,FALSE) -> #N/A | ... AN10: =VLOOKUP($B10,baseline!$A:$AK,AN$2,FALSE) -> #N/A | AP10: =AN10/E10 -> #N/A
B11: va_sres_0 | D11: mln euro | E11: =VLOOKUP($B11,baseline!$A:$AK,E$2,FALSE) -> #N/A | F11: =VLOOKUP($B11,baseline!$A:$AK,F$2,FALSE) -> #N/A | G11: =VLOOKUP($B11,baseline!$A:$AK,G$2,FALSE) -> #N/A | H11: =VLOOKUP($B11,baseline!$A:$AK,H$2,FALSE) -> #N/A | I11: =VLOOKUP($B11,baseline!$A:$AK,I$2,FALSE) -> #N/A | J11: =VLOOKUP($B11,baseline!$A:$AK,J$2,FALSE) -> #N/A | K11: =VLOOKUP($B11,baseline!$A:$AK,K$2,FALSE) -> #N/A | L11: =VLOOKUP($B11,baseline!$A:$AK,L$2,FALSE) -> #N/A | ... AN11: =VLOOKUP($B11,baseline!$A:$AK,AN$2,FALSE) -> #N/A | AP11: =AN11/E11 -> #N/A
B12: va_sroa_0 | D12: mln euro | E12: =VLOOKUP($B12,baseline!$A:$AK,E$2,FALSE) -> #N/A | F12: =VLOOKUP($B12,baseline!$A:$AK,F$2,FALSE) -> #N/A | G12: =VLOOKUP($B12,baseline!$A:$AK,G$2,FALSE) -> #N/A | H12: =VLOOKUP($B12,baseline!$A:$AK,H$2,FALSE) -> #N/A | I12: =VLOOKUP($B12,baseline!$A:$AK,I$2,FALSE) -> #N/A | J12: =VLOOKUP($B12,baseline!$A:$AK,J$2,FALSE) -> #N/A | K12: =VLOOKUP($B12,baseline!$A:$AK,K$2,FALSE) -> #N/A | L12: =VLOOKUP($B12,baseline!$A:$AK,L$2,FALSE) -> #N/A | ... AN12: =VLOOKUP($B12,baseline!$A:$AK,AN$2,FALSE) -> #N/A | AP12: =AN12/E12 -> #N/A
B13: va_swat_0 | D13: mln euro | E13: =VLOOKUP($B13,baseline!$A:$AK,E$2,FALSE) -> #N/A | F13: =VLOOKUP($B13,baseline!$A:$AK,F$2,FALSE) -> #N/A | G13: =VLOOKUP($B13,baseline!$A:$AK,G$2,FALSE) -> #N/A | H13: =VLOOKUP($B13,baseline!$A:$AK,H$2,FALSE) -> #N/A | I13: =VLOOKUP($B13,baseline!$A:$AK,I$2,FALSE) -> #N/A | J13: =VLOOKUP($B13,baseline!$A:$AK,J$2,FALSE) -> #N/A | K13: =VLOOKUP($B13,baseline!$A:$AK,K$2,FALSE) -> #N/A | L13: =VLOOKUP($B13,baseline!$A:$AK,L$2,FALSE) -> #N/A | ... AN13: =VLOOKUP($B13,baseline!$A:$AK,AN$2,FALSE) -> #N/A | AP13: =AN13/E13 -> #N/A
B14: va_sair_0 | D14: mln euro | E14: =VLOOKUP($B14,baseline!$A:$AK,E$2,FALSE) -> #N/A | F14: =VLOOKUP($B14,baseline!$A:$AK,F$2,FALSE) -> #N/A | G14: =VLOOKUP($B14,baseline!$A:$AK,G$2,FALSE) -> #N/A | H14: =VLOOKUP($B14,baseline!$A:$AK,H$2,FALSE) -> #N/A | I14: =VLOOKUP($B14,baseline!$A:$AK,I$2,FALSE) -> #N/A | J14: =VLOOKUP($B14,baseline!$A:$AK,J$2,FALSE) -> #N/A | K14: =VLOOKUP($B14,baseline!$A:$AK,K$2,FALSE) -> #N/A | L14: =VLOOKUP($B14,baseline!$A:$AK,L$2,FALSE) -> #N/A | ... AN14: =VLOOKUP($B14,baseline!$A:$AK,AN$2,FALSE) -> #N/A | AP14: =AN14/E14 -> #N/A
B15: va_scoa_0 | D15: mln euro | E15: =VLOOKUP($B15,baseline!$A:$AK,E$2,FALSE) -> #N/A | F15: =VLOOKUP($B15,baseline!$A:$AK,F$2,FALSE) -> #N/A | G15: =VLOOKUP($B15,baseline!$A:$AK,G$2,FALSE) -> #N/A | H15: =VLOOKUP($B15,baseline!$A:$AK,H$2,FALSE) -> #N/A | I15: =VLOOKUP($B15,baseline!$A:$AK,I$2,FALSE) -> #N/A | J15: =VLOOKUP($B15,baseline!$A:$AK,J$2,FALSE) -> #N/A | K15: =VLOOKUP($B15,baseline!$A:$AK,K$2,FALSE) -> #N/A | L15: =VLOOKUP($B15,baseline!$A:$AK,L$2,FALSE) -> #N/A | ... AN15: =VLOOKUP($B15,baseline!$A:$AK,AN$2,FALSE) -> #N/A | AP15: =AN15/E15 -> #N/A
... B30: va_shea_0 | D30: mln euro | E30: =VLOOKUP($B30,baseline!$A:$AK,E$2,FALSE) -> #N/A | F30: =VLOOKUP($B30,baseline!$A:$AK,F$2,FALSE) -> #N/A | G30: =VLOOKUP($B30,baseline!$A:$AK,G$2,FALSE) -> #N/A | H30: =VLOOKUP($B30,baseline!$A:$AK,H$2,FALSE) -> #N/A | I30: =VLOOKUP($B30,baseline!$A:$AK,I$2,FALSE) -> #N/A | J30: =VLOOKUP($B30,baseline!$A:$AK,J$2,FALSE) -> #N/A | K30: =VLOOKUP($B30,baseline!$A:$AK,K$2,FALSE) -> #N/A | L30: =VLOOKUP($B30,baseline!$A:$AK,L$2,FALSE) -> #N/A | ... AN30: =VLOOKUP($B30,baseline!$A:$AK,AN$2,FALSE) -> #N/A | AP30: =AN30/E30 -> #N/A
A32: Index value added
E33: 2015 | F33: 2016 | G33: 2017 | H33: 2018 | I33: 2019 | J33: 2020 | K33: 2021 | L33: 2022 | M33: 2023 | N33: 2024 | O33: 2025 | P33: 2026 | Q33: 2027 | R33: 2028 | S33: 2029 | T33: 2030 | U33: 2031 | V33: 2032 | W33: 2033 | X33: 2034 | Y33: 2035 | Z33: 2036 | AA33: 2037 | AB33: 2038 | AC33: 2039 | AD33: 2040 | AE33: 2041 | AF33: 2042 | AG33: 2043 | AH33: 2044 | AI33: 2045 | AJ33: 2046 | AK33: 2047 | AL33: 2048 | AM33: 2049 | AN33: 2050
B34: va_sagr_0 | D34: index | E34: =E4/$E4 -> #N/A | F34: =F4/$E4 -> #N/A | G34: =G4/$E4 -> #N/A | H34: =H4/$E4 -> #N/A | I34: =I4/$E4 -> #N/A | J34: =J4/$E4 -> #N/A | K34: =K4/$E4 -> #N/A | L34: =L4/$E4 -> #N/A | ... AN34: =AN4/$E4 -> #N/A
B35: va_smet_0 | D35: index | E35: =E5/$E5 -> #N/A | F35: =F5/$E5 -> #N/A | G35: =G5/$E5 -> #N/A | H35: =H5/$E5 -> #N/A | I35: =I5/$E5 -> #N/A | J35: =J5/$E5 -> #N/A | K35: =K5/$E5 -> #N/A | L35: =L5/$E5 -> #N/A | ... AN35: =AN5/$E5 -> #N/A
B36: va_schem_0 | D36: index | E36: =E6/$E6 -> #N/A | F36: =F6/$E6 -> #N/A | G36: =G6/$E6 -> #N/A | H36: =H6/$E6 -> #N/A | I36: =I6/$E6 -> #N/A | J36: =J6/$E6 -> #N/A | K36: =K6/$E6 -> #N/A | L36: =L6/$E6 -> #N/A | ... AN36: =AN6/$E6 -> #N/A
B37: va_spla_0 | D37: index | E37: =E7/$E7 -> #N/A | F37: =F7/$E7 -> #N/A | G37: =G7/$E7 -> #N/A | H37: =H7/$E7 -> #N/A | I37: =I7/$E7 -> #N/A | J37: =J7/$E7 -> #N/A | K37: =K7/$E7 -> #N/A | L37: =L7/$E7 -> #N/A | ... AN37: =AN7/$E7 -> #N/A
B38: va_sgla_0 | D38: index | E38: =E8/$E8 -> #N/A | F38: =F8/$E8 -> #N/A | G38: =G8/$E8 -> #N/A | H38: =H8/$E8 -> #N/A | I38: =I8/$E8 -> #N/A | J38: =J8/$E8 -> #N/A | K38: =K8/$E8 -> #N/A | L38: =L8/$E8 -> #N/A | ... AN38: =AN8/$E8 -> #N/A
B39: va_spap_0 | D39: index | E39: =E9/$E9 -> #N/A | F39: =F9/$E9 -> #N/A | G39: =G9/$E9 -> #N/A | H39: =H9/$E9 -> #N/A | I39: =I9/$E9 -> #N/A | J39: =J9/$E9 -> #N/A | K39: =K9/$E9 -> #N/A | L39: =L9/$E9 -> #N/A | ... AN39: =AN9/$E9 -> #N/A
B40: va_sfoo_0 | D40: index | E40: =E10/$E10 -> #N/A | F40: =F10/$E10 -> #N/A | G40: =G10/$E10 -> #N/A | H40: =H10/$E10 -> #N/A | I40: =I10/$E10 -> #N/A | J40: =J10/$E10 -> #N/A | K40: =K10/$E10 -> #N/A | L40: =L10/$E10 -> #N/A | ... AN40: =AN10/$E10 -> #N/A
B41: va_sres_0 | D41: index | E41: =E11/$E11 -> #N/A | F41: =F11/$E11 -> #N/A | G41: =G11/$E11 -> #N/A | H41: =H11/$E11 -> #N/A | I41: =I11/$E11 -> #N/A | J41: =J11/$E11 -> #N/A | K41: =K11/$E11 -> #N/A | L41: =L11/$E11 -> #N/A | ... AN41: =AN11/$E11 -> #N/A
B42: va_sroa_0 | D42: index | E42: =E12/$E12 -> #N/A | F42: =F12/$E12 -> #N/A | G42: =G12/$E12 -> #N/A | H42: =H12/$E12 -> #N/A | I42: =I12/$E12 -> #N/A | J42: =J12/$E12 -> #N/A | K42: =K12/$E12 -> #N/A | L42: =L12/$E12 -> #N/A | ... AN42: =AN12/$E12 -> #N/A
B43: va_swat_0 | D43: index | E43: =E13/$E13 -> #N/A | F43: =F13/$E13 -> #N/A | G43: =G13/$E13 -> #N/A | H43: =H13/$E13 -> #N/A | I43: =I13/$E13 -> #N/A | J43: =J13/$E13 -> #N/A | K43: =K13/$E13 -> #N/A | L43: =L13/$E13 -> #N/A | ... AN43: =AN13/$E13 -> #N/A
B44: va_sair_0 | D44: index | E44: =E14/$E14 -> #N/A | F44: =F14/$E14 -> #N/A | G44: =G14/$E14 -> #N/A | H44: =H14/$E14 -> #N/A | I44: =I14/$E14 -> #N/A | J44: =J14/$E14 -> #N/A | K44: =K14/$E14 -> #N/A | L44: =L14/$E14 -> #N/A | ... AN44: =AN14/$E14 -> #N/A
B45: va_scoa_0 | D45: index | E45: =E15/$E15 -> #N/A | F45: =F15/$E15 -> #N/A | G45: =G15/$E15 -> #N/A | H45: =H15/$E15 -> #N/A | I45: =I15/$E15 -> #N/A | J45: =J15/$E15 -> #N/A | K45: =K15/$E15 -> #N/A | L45: =L15/$E15 -> #N/A | ... AN45: =AN15/$E15 -> #N/A
... B56: va_sewi_0 | D56: index | E56: =E26/$E26 -> #N/A | F56: =F26/$E26 -> #N/A | G56: =G26/$E26 -> #N/A | H56: =H26/$E26 -> #N/A | I56: =I26/$E26 -> #N/A | J56: =J26/$E26 -> #N/A | K56: =K26/$E26 -> #N/A | L56: =L26/$E26 -> #N/A | ... AN56: =AN26/$E26 -> #N/A
B57: va_seso_0 | D57: index | E57: =E27/$E27 -> #N/A | F57: =F27/$E27 -> #N/A | G57: =G27/$E27 -> #N/A | H57: =H27/$E27 -> #N/A | I57: =I27/$E27 -> #N/A | J57: =J27/$E27 -> #N/A | K57: =K27/$E27 -> #N/A | L57: =L27/$E27 -> #N/A | ... AN57: =AN27/$E27 -> #N/A | AP57: Is this realistic?
B58: va_sebi_0 | D58: index | E58: =E28/$E28 -> #N/A | F58: =F28/$E28 -> #N/A | G58: =G28/$E28 -> #N/A | H58: =H28/$E28 -> #N/A | I58: =I28/$E28 -> #N/A | J58: =J28/$E28 -> #N/A | K58: =K28/$E28 -> #N/A | L58: =L28/$E28 -> #N/A | ... AN58: =AN28/$E28 -> #N/A
B59: va_senu_0 | D59: index | E59: =E29/$E29 -> #N/A | F59: =F29/$E29 -> #N/A | G59: =G29/$E29 -> #N/A | H59: =H29/$E29 -> #N/A | I59: =I29/$E29 -> #N/A | J59: =J29/$E29 -> #N/A | K59: =K29/$E29 -> #N/A | L59: =L29/$E29 -> #N/A | ... AN59: =AN29/$E29 -> #N/A
B60: va_shea_0 | D60: index | E60: =E30/$E30 -> #N/A | F60: =F30/$E30 -> #N/A | G60: =G30/$E30 -> #N/A | H60: =H30/$E30 -> #N/A | I60: =I30/$E30 -> #N/A | J60: =J30/$E30 -> #N/A | K60: =K30/$E30 -> #N/A | L60: =L30/$E30 -> #N/A | ... AN60: =AN30/$E30 -> #N/A

Sheet Employment
A1: Total employment
E2: 2 | F2: 3 | G2: 4 | H2: 5 | I2: 6 | J2: 7 | K2: 8 | L2: 9 | M2: 10 | N2: 11 | O2: 12 | P2: 13 | Q2: 14 | R2: 15 | S2: 16 | T2: 17 | U2: 18 | V2: 19 | W2: 20 | X2: 21 | Y2: 22 | Z2: 23 | AA2: 24 | AB2: 25 | AC2: 26 | AD2: 27 | AE2: 28 | AF2: 29 | AG2: 30 | AH2: 31 | AI2: 32 | AJ2: 33 | AK2: 34 | AL2: 35 | AM2: 36 | AN2: 37
E3: 2015 | F3: 2016 | G3: 2017 | H3: 2018 | I3: 2019 | J3: 2020 | K3: 2021 | L3: 2022 | M3: 2023 | N3: 2024 | O3: 2025 | P3: 2026 | Q3: 2027 | R3: 2028 | S3: 2029 | T3: 2030 | U3: 2031 | V3: 2032 | W3: 2033 | X3: 2034 | Y3: 2035 | Z3: 2036 | AA3: 2037 | AB3: 2038 | AC3: 2039 | AD3: 2040 | AE3: 2041 | AF3: 2042 | AG3: 2043 | AH3: 2044 | AI3: 2045 | AJ3: 2046 | AK3: 2047 | AL3: 2048 | AM3: 2049 | AN3: 2050
B4: f_l_sagr_0 | D4: 1000 fte?? | E4: =VLOOKUP($B4,baseline!$A:$AK,E$2,FALSE) -> #N/A | F4: =VLOOKUP($B4,baseline!$A:$AK,F$2,FALSE) -> #N/A | G4: =VLOOKUP($B4,baseline!$A:$AK,G$2,FALSE) -> #N/A | H4: =VLOOKUP($B4,baseline!$A:$AK,H$2,FALSE) -> #N/A | I4: =VLOOKUP($B4,baseline!$A:$AK,I$2,FALSE) -> #N/A | J4: =VLOOKUP($B4,baseline!$A:$AK,J$2,FALSE) -> #N/A | K4: =VLOOKUP($B4,baseline!$A:$AK,K$2,FALSE) -> #N/A | L4: =VLOOKUP($B4,baseline!$A:$AK,L$2,FALSE) -> #N/A | ... AN4: =VLOOKUP($B4,baseline!$A:$AK,AN$2,FALSE) -> #N/A | AP4: =AN4/E4 -> #N/A
B5: f_l_smet_0 | D5: 1001 fte?? | E5: =VLOOKUP($B5,baseline!$A:$AK,E$2,FALSE) -> #N/A | F5: =VLOOKUP($B5,baseline!$A:$AK,F$2,FALSE) -> #N/A | G5: =VLOOKUP($B5,baseline!$A:$AK,G$2,FALSE) -> #N/A | H5: =VLOOKUP($B5,baseline!$A:$AK,H$2,FALSE) -> #N/A | I5: =VLOOKUP($B5,baseline!$A:$AK,I$2,FALSE) -> #N/A | J5: =VLOOKUP($B5,baseline!$A:$AK,J$2,FALSE) -> #N/A | K5: =VLOOKUP($B5,baseline!$A:$AK,K$2,FALSE) -> #N/A | L5: =VLOOKUP($B5,baseline!$A:$AK,L$2,FALSE) -> #N/A | ... AN5: =VLOOKUP($B5,baseline!$A:$AK,AN$2,FALSE) -> #N/A | AP5: =AN5/E5 -> #N/A
B6: f_l_schem_0 | D6: 1002 fte?? | E6: =VLOOKUP($B6,baseline!$A:$AK,E$2,FALSE) -> #N/A | F6: =VLOOKUP($B6,baseline!$A:$AK,F$2,FALSE) -> #N/A | G6: =VLOOKUP($B6,baseline!$A:$AK,G$2,FALSE) -> #N/A | H6: =VLOOKUP($B6,baseline!$A:$AK,H$2,FALSE) -> #N/A | I6: =VLOOKUP($B6,baseline!$A:$AK,I$2,FALSE) -> #N/A | J6: =VLOOKUP($B6,baseline!$A:$AK,J$2,FALSE) -> #N/A | K6: =VLOOKUP($B6,baseline!$A:$AK,K$2,FALSE) -> #N/A | L6: =VLOOKUP($B6,baseline!$A:$AK,L$2,FALSE) -> #N/A | ... AN6: =VLOOKUP($B6,baseline!$A:$AK,AN$2,FALSE) -> #N/A | AP6: =AN6/E6 -> #N/A
B7: f_l_spla_0 | D7: 1003 fte?? | E7: =VLOOKUP($B7,baseline!$A:$AK,E$2,FALSE) -> #N/A | F7: =VLOOKUP($B7,baseline!$A:$AK,F$2,FALSE) -> #N/A | G7: =VLOOKUP($B7,baseline!$A:$AK,G$2,FALSE) -> #N/A | H7: =VLOOKUP($B7,baseline!$A:$AK,H$2,FALSE) -> #N/A | I7: =VLOOKUP($B7,baseline!$A:$AK,I$2,FALSE) -> #N/A | J7: =VLOOKUP($B7,baseline!$A:$AK,J$2,FALSE) -> #N/A | K7: =VLOOKUP($B7,baseline!$A:$AK,K$2,FALSE) -> #N/A | L7: =VLOOKUP($B7,baseline!$A:$AK,L$2,FALSE) -> #N/A | ... AN7: =VLOOKUP($B7,baseline!$A:$AK,AN$2,FALSE) -> #N/A | AP7: =AN7/E7 -> #N/A
B8: f_l_sgla_0 | D8: 1004 fte?? | E8: =VLOOKUP($B8,baseline!$A:$AK,E$2,FALSE) -> #N/A | F8: =VLOOKUP($B8,baseline!$A:$AK,F$2,FALSE) -> #N/A | G8: =VLOOKUP($B8,baseline!$A:$AK,G$2,FALSE) -> #N/A | H8: =VLOOKUP($B8,baseline!$A:$AK,H$2,FALSE) -> #N/A | I8: =VLOOKUP($B8,baseline!$A:$AK,I$2,FALSE) -> #N/A | J8: =VLOOKUP($B8,baseline!$A:$AK,J$2,FALSE) -> #N/A | K8: =VLOOKUP($B8,baseline!$A:$AK,K$2,FALSE) -> #N/A | L8: =VLOOKUP($B8,baseline!$A:$AK,L$2,FALSE) -> #N/A | ... AN8: =VLOOKUP($B8,baseline!$A:$AK,AN$2,FALSE) -> #N/A | AP8: =AN8/E8 -> #N/A
B9: f_l_spap_0 | D9: 1005 fte?? | E9: =VLOOKUP($B9,baseline!$A:$AK,E$2,FALSE) -> #N/A | F9: =VLOOKUP($B9,baseline!$A:$AK,F$2,FALSE) -> #N/A | G9: =VLOOKUP($B9,baseline!$A:$AK,G$2,FALSE) -> #N/A | H9: =VLOOKUP($B9,baseline!$A:$AK,H$2,FALSE) -> #N/A | I9: =VLOOKUP($B9,baseline!$A:$AK,I$2,FALSE) -> #N/A | J9: =VLOOKUP($B9,baseline!$A:$AK,J$2,FALSE) -> #N/A | K9: =VLOOKUP($B9,baseline!$A:$AK,K$2,FALSE) -> #N/A | L9: =VLOOKUP($B9,baseline!$A:$AK,L$2,FALSE) -> #N/A | ... AN9: =VLOOKUP($B9,baseline!$A:$AK,AN$2,FALSE) -> #N/A | AP9: =AN9/E9 -> #N/A
B10: f_l_sfoo_0 | D10: 1006 fte?? | E10: =VLOOKUP($B10,baseline!$A:$AK,E$2,FALSE) -> #N/A | F10: =VLOOKUP($B10,baseline!$A:$AK,F$2,FALSE) -> #N/A | G10: =VLOOKUP($B10,baseline!$A:$AK,G$2,FALSE) -> #N/A | H10: =VLOOKUP($B10,baseline!$A:$AK,H$2,FALSE) -> #N/A | I10: =VLOOKUP($B10,baseline!$A:$AK,I$2,FALSE) -> #N/A | J10: =VLOOKUP($B10,baseline!$A:$AK,J$2,FALSE) -> #N/A | K10: =VLOOKUP($B10,baseline!$A:$AK,K$2,FALSE) -> #N/A | L10: =VLOOKUP($B10,baseline!$A:$AK,L$2,FALSE) -> #N/A | ... AN10: =VLOOKUP($B10,baseline!$A:$AK,AN$2,FALSE) -> #N/A | AP10: =AN10/E10 -> #N/A
B11: f_l_sres_0 | D11: 1007 fte?? | E11: =VLOOKUP($B11,baseline!$A:$AK,E$2,FALSE) -> #N/A | F11: =VLOOKUP($B11,baseline!$A:$AK,F$2,FALSE) -> #N/A | G11: =VLOOKUP($B11,baseline!$A:$AK,G$2,FALSE) -> #N/A | H11: =VLOOKUP($B11,baseline!$A:$AK,H$2,FALSE) -> #N/A | I11: =VLOOKUP($B11,baseline!$A:$AK,I$2,FALSE) -> #N/A | J11: =VLOOKUP($B11,baseline!$A:$AK,J$2,FALSE) -> #N/A | K11: =VLOOKUP($B11,baseline!$A:$AK,K$2,FALSE) -> #N/A | L11: =VLOOKUP($B11,baseline!$A:$AK,L$2,FALSE) -> #N/A | ... AN11: =VLOOKUP($B11,baseline!$A:$AK,AN$2,FALSE) -> #N/A | AP11: =AN11/E11 -> #N/A
B12: f_l_sroa_0 | D12: 1008 fte?? | E12: =VLOOKUP($B12,baseline!$A:$AK,E$2,FALSE) -> #N/A | F12: =VLOOKUP($B12,baseline!$A:$AK,F$2,FALSE) -> #N/A | G12: =VLOOKUP($B12,baseline!$A:$AK,G$2,FALSE) -> #N/A | H12: =VLOOKUP($B12,baseline!$A:$AK,H$2,FALSE) -> #N/A | I12: =VLOOKUP($B12,baseline!$A:$AK,I$2,FALSE) -> #N/A | J12: =VLOOKUP($B12,baseline!$A:$AK,J$2,FALSE) -> #N/A | K12: =VLOOKUP($B12,baseline!$A:$AK,K$2,FALSE) -> #N/A | L12: =VLOOKUP($B12,baseline!$A:$AK,L$2,FALSE) -> #N/A | ... AN12: =VLOOKUP($B12,baseline!$A:$AK,AN$2,FALSE) -> #N/A | AP12: =AN12/E12 -> #N/A
B13: f_l_swat_0 | D13: 1009 fte?? | E13: =VLOOKUP($B13,baseline!$A:$AK,E$2,FALSE) -> #N/A | F13: =VLOOKUP($B13,baseline!$A:$AK,F$2,FALSE) -> #N/A | G13: =VLOOKUP($B13,baseline!$A:$AK,G$2,FALSE) -> #N/A | H13: =VLOOKUP($B13,baseline!$A:$AK,H$2,FALSE) -> #N/A | I13: =VLOOKUP($B13,baseline!$A:$AK,I$2,FALSE) -> #N/A | J13: =VLOOKUP($B13,baseline!$A:$AK,J$2,FALSE) -> #N/A | K13: =VLOOKUP($B13,baseline!$A:$AK,K$2,FALSE) -> #N/A | L13: =VLOOKUP($B13,baseline!$A:$AK,L$2,FALSE) -> #N/A | ... AN13: =VLOOKUP($B13,baseline!$A:$AK,AN$2,FALSE) -> #N/A | AP13: =AN13/E13 -> #N/A
B14: f_l_sair_0 | D14: 1010 fte?? | E14: =VLOOKUP($B14,baseline!$A:$AK,E$2,FALSE) -> #N/A | F14: =VLOOKUP($B14,baseline!$A:$AK,F$2,FALSE) -> #N/A | G14: =VLOOKUP($B14,baseline!$A:$AK,G$2,FALSE) -> #N/A | H14: =VLOOKUP($B14,baseline!$A:$AK,H$2,FALSE) -> #N/A | I14: =VLOOKUP($B14,baseline!$A:$AK,I$2,FALSE) -> #N/A | J14: =VLOOKUP($B14,baseline!$A:$AK,J$2,FALSE) -> #N/A | K14: =VLOOKUP($B14,baseline!$A:$AK,K$2,FALSE) -> #N/A | L14: =VLOOKUP($B14,baseline!$A:$AK,L$2,FALSE) -> #N/A | ... AN14: =VLOOKUP($B14,baseline!$A:$AK,AN$2,FALSE) -> #N/A | AP14: =AN14/E14 -> #N/A
B15: f_l_scoa_0 | D15: 1011 fte?? | E15: =VLOOKUP($B15,baseline!$A:$AK,E$2,FALSE) -> #N/A | F15: =VLOOKUP($B15,baseline!$A:$AK,F$2,FALSE) -> #N/A | G15: =VLOOKUP($B15,baseline!$A:$AK,G$2,FALSE) -> #N/A | H15: =VLOOKUP($B15,baseline!$A:$AK,H$2,FALSE) -> #N/A | I15: =VLOOKUP($B15,baseline!$A:$AK,I$2,FALSE) -> #N/A | J15: =VLOOKUP($B15,baseline!$A:$AK,J$2,FALSE) -> #N/A | K15: =VLOOKUP($B15,baseline!$A:$AK,K$2,FALSE) -> #N/A | L15: =VLOOKUP($B15,baseline!$A:$AK,L$2,FALSE) -> #N/A | ... AN15: =VLOOKUP($B15,baseline!$A:$AK,AN$2,FALSE) -> #N/A | AP15: =AN15/E15 -> #N/A
... B30: f_l_shea_0 | D30: 1026 fte?? | E30: =VLOOKUP($B30,baseline!$A:$AK,E$2,FALSE) -> #N/A | F30: =VLOOKUP($B30,baseline!$A:$AK,F$2,FALSE) -> #N/A | G30: =VLOOKUP($B30,baseline!$A:$AK,G$2,FALSE) -> #N/A | H30: =VLOOKUP($B30,baseline!$A:$AK,H$2,FALSE) -> #N/A | I30: =VLOOKUP($B30,baseline!$A:$AK,I$2,FALSE) -> #N/A | J30: =VLOOKUP($B30,baseline!$A:$AK,J$2,FALSE) -> #N/A | K30: =VLOOKUP($B30,baseline!$A:$AK,K$2,FALSE) -> #N/A | L30: =VLOOKUP($B30,baseline!$A:$AK,L$2,FALSE) -> #N/A | ... AN30: =VLOOKUP($B30,baseline!$A:$AK,AN$2,FALSE) -> #N/A | AP30: =AN30/E30 -> #N/A
A32: Index employment
E33: 2015 | F33: 2016 | G33: 2017 | H33: 2018 | I33: 2019 | J33: 2020 | K33: 2021 | L33: 2022 | M33: 2023 | N33: 2024 | O33: 2025 | P33: 2026 | Q33: 2027 | R33: 2028 | S33: 2029 | T33: 2030 | U33: 2031 | V33: 2032 | W33: 2033 | X33: 2034 | Y33: 2035 | Z33: 2036 | AA33: 2037 | AB33: 2038 | AC33: 2039 | AD33: 2040 | AE33: 2041 | AF33: 2042 | AG33: 2043 | AH33: 2044 | AI33: 2045 | AJ33: 2046 | AK33: 2047 | AL33: 2048 | AM33: 2049 | AN33: 2050
B34: f_l_sagr_0 | D34: index | E34: =E4/$E4 -> #N/A | F34: =F4/$E4 -> #N/A | G34: =G4/$E4 -> #N/A | H34: =H4/$E4 -> #N/A | I34: =I4/$E4 -> #N/A | J34: =J4/$E4 -> #N/A | K34: =K4/$E4 -> #N/A | L34: =L4/$E4 -> #N/A | ... AN34: =AN4/$E4 -> #N/A
B35: f_l_smet_0 | D35: index | E35: =E5/$E5 -> #N/A | F35: =F5/$E5 -> #N/A | G35: =G5/$E5 -> #N/A | H35: =H5/$E5 -> #N/A | I35: =I5/$E5 -> #N/A | J35: =J5/$E5 -> #N/A | K35: =K5/$E5 -> #N/A | L35: =L5/$E5 -> #N/A | ... AN35: =AN5/$E5 -> #N/A
B36: f_l_schem_0 | D36: index | E36: =E6/$E6 -> #N/A | F36: =F6/$E6 -> #N/A | G36: =G6/$E6 -> #N/A | H36: =H6/$E6 -> #N/A | I36: =I6/$E6 -> #N/A | J36: =J6/$E6 -> #N/A | K36: =K6/$E6 -> #N/A | L36: =L6/$E6 -> #N/A | ... AN36: =AN6/$E6 -> #N/A
B37: f_l_spla_0 | D37: index | E37: =E7/$E7 -> #N/A | F37: =F7/$E7 -> #N/A | G37: =G7/$E7 -> #N/A | H37: =H7/$E7 -> #N/A | I37: =I7/$E7 -> #N/A | J37: =J7/$E7 -> #N/A | K37: =K7/$E7 -> #N/A | L37: =L7/$E7 -> #N/A | ... AN37: =AN7/$E7 -> #N/A
B38: f_l_sgla_0 | D38: index | E38: =E8/$E8 -> #N/A | F38: =F8/$E8 -> #N/A | G38: =G8/$E8 -> #N/A | H38: =H8/$E8 -> #N/A | I38: =I8/$E8 -> #N/A | J38: =J8/$E8 -> #N/A | K38: =K8/$E8 -> #N/A | L38: =L8/$E8 -> #N/A | ... AN38: =AN8/$E8 -> #N/A
