Workbook

Sheet Données
A1: Scénario 2 | B1: NZ50
A4: Macro | C4: 42005 | D4: 42370 | E4: 42736 | F4: 43101 | G4: 43466 | H4: 43831 | I4: 44197 | J4: 44562 | K4: 44927 | L4: 45292 | M4: 45658 | N4: 46023 | O4: 46388 | P4: 46753 | Q4: 47119 | R4: 47484 | S4: 47849 | T4: 48214 | U4: 48580 | V4: 48945 | W4: 49310 | X4: 49675 | Y4: 50041 | Z4: 50406 | AA4: 50771 | AB4: 51136 | AC4: 51502 | AD4: 51867 | AE4: 52232 | AF4: 52597 | AG4: 52963 | AH4: 53328 | AI4: 53693 | AJ4: 54058 | AK4: 54424 | AL4: 54789 | AM4: 55154 | AN4: 55519 | AO4: 55885 | AP4: 56250 | AQ4: 56615 | AR4: 56980 | AS4: 57346 | AT4: 57711 | AU4: 58076 | AV4: 58441 | AW4: 58807 | AX4: 59172 | AY4: 59537 | AZ4: 59902 | BA4: 60268 | BB4: 60633 | BC4: 60998 | BD4: 61363 | BE4: 61729 | BF4: 62094 | BG4: 62459 | BH4: 62824 | BI4: 63190 | BJ4: 63555 | BK4: 63920 | BL4: 64285 | BM4: 64651 | BN4: 65016 | BO4: 65381 | BP4: 65746 | BQ4: 66112 | BR4: 66477 | BS4: 66842 | BT4: 67207 | BU4: 67573 | BV4: 67938 | BW4: 68303 | BX4: 68668 | BY4: 69034 | BZ4: 69399 | CA4: 69764 | CB4: 70129 | CC4: 70495 | CD4: 70860 | CE4: 71225 | CF4: 71590 | CG4: 71956 | CH4: 72321 | CI4: 72686 | CJ4: 73051
A5: =[1]Results!E1365 -> 100*(GDP_2/GDP_0-1) | B5: PIB | C5: =[1]Results!F1365 -> 0 | D5: =[1]Results!G1365 -> 4.7013424e-05 | E5: =[1]Results!H1365 -> 9.9797017e-05 | F5: =[1]Results!I1365 -> 0.00015668266 | G5: =[1]Results!J1365 -> 0.00021584302 | H5: =[1]Results!K1365 -> 0.00027568373 | I5: =[1]Results!L1365 -> 0.00024921737 | J5: =[1]Results!M1365 -> -0.082360101 | ... CJ5: =[1]Results!CM1365 -> -7.4705744
A6: =[1]Results!E1366 -> 100*((VA_2-VA_spub_2)/(VA_0-VA_spub_0)-1) | B6: =[1]Results!C1366 -> VA du secteur marchand | C6: =[1]Results!F1366 -> 0 | D6: =[1]Results!G1366 -> 6.0803108e-05 | E6: =[1]Results!H1366 -> 0.00012681754 | F6: =[1]Results!I1366 -> 0.00019678698 | G6: =[1]Results!J1366 -> 0.00026874083 | H6: =[1]Results!K1366 -> 0.00034108411 | I6: =[1]Results!L1366 -> 0.00030105937 | J6: =[1]Results!M1366 -> -0.092689585 | ... CJ6: =[1]Results!CM1366 -> -8.9608559
A7: =[1]Results!E1367 -> 100*((CH_2-CH_0)/GDP_0) | B7: Consommation | C7: =[1]Results!F1367 -> 0 | D7: =[1]Results!G1367 -> 9.254611e-06 | E7: =[1]Results!H1367 -> 2.6942445e-05 | F7: =[1]Results!I1367 -> 5.1035076e-05 | G7: =[1]Results!J1367 -> 7.9492858e-05 | H7: =[1]Results!K1367 -> 0.00011034417 | I7: =[1]Results!L1367 -> 0.00012609264 | J7: =[1]Results!M1367 -> -0.084434967 | ... CJ7: =[1]Results!CM1367 -> -5.8921056
A8: =[1]Results!E1368 -> 100*((CH_cveh_2-CH_cveh_0)/GDP_0) | B8: =[1]Results!C1368 -> Consommation des ménages automobile | C8: =[1]Results!F1368 -> 0 | D8: =[1]Results!G1368 -> 8.3939321e-07 | E8: =[1]Results!H1368 -> 2.4042009e-06 | F8: =[1]Results!I1368 -> 4.3418306e-06 | G8: =[1]Results!J1368 -> 6.2990373e-06 | H8: =[1]Results!K1368 -> 8.0690829e-06 | I8: =[1]Results!L1368 -> 7.9609892e-06 | J8: =[1]Results!M1368 -> 0.028779482 | ... CJ8: =[1]Results!CM1368 -> -0.091318039
A9: =[1]Results!E1369 -> 100*((G_2-G_0)/GDP_0) | B9: =[1]Results!C1369 -> Dépenses publiques | C9: =[1]Results!F1369 -> 0 | D9: =[1]Results!G1369 -> 0 | E9: =[1]Results!H1369 -> 0 | F9: =[1]Results!I1369 -> 0 | G9: =[1]Results!J1369 -> 0 | H9: =[1]Results!K1369 -> 0 | I9: =[1]Results!L1369 -> 0 | J9: =[1]Results!M1369 -> 0 | ... CJ9: =[1]Results!CM1369 -> 0
A10: =[1]Results!E1370 -> 100*((I_2-I_0)/GDP_0) | B10: Investissement | C10: =[1]Results!F1370 -> 0 | D10: =[1]Results!G1370 -> 7.1121685e-06 | E10: =[1]Results!H1370 -> 1.8122002e-05 | F10: =[1]Results!I1370 -> 3.1245965e-05 | G10: =[1]Results!J1370 -> 4.5624516e-05 | H10: =[1]Results!K1370 -> 6.07423e-05 | I10: =[1]Results!L1370 -> 6.3426039e-05 | J10: =[1]Results!M1370 -> -0.0074561241 | ... CJ10: =[1]Results!CM1370 -> -2.6033725
A11: =[1]Results!E1371 -> 100*((DS_2-DS_0)/GDP_0) | B11: =[1]Results!C1371 -> Variations de stocks | C11: =[1]Results!F1371 -> 0 | D11: =[1]Results!G1371 -> 0 | E11: =[1]Results!H1371 -> 0 | F11: =[1]Results!I1371 -> 0 | G11: =[1]Results!J1371 -> 0 | H11: =[1]Results!K1371 -> 0 | I11: =[1]Results!L1371 -> 0 | J11: =[1]Results!M1371 -> 0 | ... CJ11: =[1]Results!CM1371 -> 0
A12: =[1]Results!E1372 -> 100*((X_2-X_0)/GDP_0)-100*((M_2-M_0)/GDP_0) | B12: Exportations nettes | C12: =[1]Results!F1372 -> 0 | D12: =[1]Results!G1372 -> 3.0646644e-05 | E12: =[1]Results!H1372 -> 5.477839e-05 | F12: =[1]Results!I1372 -> 7.4392566e-05 | G12: =[1]Results!J1372 -> 9.0716695e-05 | H12: =[1]Results!K1372 -> 0.00010462818 | I12: =[1]Results!L1372 -> 5.9698689e-05 | J12: =[1]Results!M1372 -> 0.0095309983 | ... CJ12: =[1]Results!CM1372 -> 1.0249037
A13: =[1]Results!E1373 -> 100*((CH_2-CH_ccon_2-(CH_0-CH_ccon_0))/GDP_0) | B13: =[1]Results!C1373 -> Consommation des ménages | C13: =[1]Results!F1373 -> 0 | D13: =[1]Results!G1373 -> 9.7589873e-06 | E13: =[1]Results!H1373 -> 2.8303314e-05 | F13: =[1]Results!I1373 -> 5.3270294e-05 | G13: =[1]Results!J1373 -> 8.2432796e-05 | H13: =[1]Results!K1373 -> 0.00011389303 | I13: =[1]Results!L1373 -> 0.00012893442 | J13: =[1]Results!M1373 -> -0.079022591 | ... CJ13: =[1]Results!CM1373 -> -5.900535
A14: =[1]Results!E1374 -> 100*((I_2+CH_ccon_2-(I_0+CH_ccon_0))/GDP_0) | B14: Investissement | C14: =[1]Results!F1374 -> 0 | D14: =[1]Results!G1374 -> 6.6077922e-06 | E14: =[1]Results!H1374 -> 1.6761134e-05 | F14: =[1]Results!I1374 -> 2.9010746e-05 | G14: =[1]Results!J1374 -> 4.2684578e-05 | H14: =[1]Results!K1374 -> 5.719344e-05 | I14: =[1]Results!L1374 -> 6.0584262e-05 | J14: =[1]Results!M1374 -> -0.0128685 | ... CJ14: =[1]Results!CM1374 -> -2.594943
A15: =[1]Results!E1375 -> 100*((I_2-IA_spub_2-(I_0-IA_spub_0))/GDP_0) | B15: =[1]Results!C1375 -> Investissement entreprises | C15: =[1]Results!F1375 -> 0 | D15: =[1]Results!G1375 -> 6.8271265e-06 | E15: =[1]Results!H1375 -> 1.7340304e-05 | F15: =[1]Results!I1375 -> 2.9823141e-05 | G15: =[1]Results!J1375 -> 4.3459823e-05 | H15: =[1]Results!K1375 -> 5.7758413e-05 | I15: =[1]Results!L1375 -> 6.0074916e-05 | J15: =[1]Results!M1375 -> -0.0099703878 | ... CJ15: =[1]Results!CM1375 -> -2.4954148
A16: =[1]Results!E1376 -> 100*((CH_ccon_2-CH_ccon_0)/GDP_0) | B16: =[1]Results!C1376 -> Investissement ménages | C16: =[1]Results!F1376 -> 0 | D16: =[1]Results!G1376 -> -5.043763e-07 | E16: =[1]Results!H1376 -> -1.3608684e-06 | F16: =[1]Results!I1376 -> -2.2352186e-06 | G16: =[1]Results!J1376 -> -2.9399384e-06 | H16: =[1]Results!K1376 -> -3.5488593e-06 | I16: =[1]Results!L1376 -> -2.8417763e-06 | J16: =[1]Results!M1376 -> -0.005412376 | ... CJ16: =[1]Results!CM1376 -> 0.0084294322
A17: =[1]Results!E1377 -> 100*((IA_spub_2-IA_spub_0)/GDP_0) | B17: =[1]Results!C1377 -> Investissement public | C17: =[1]Results!F1377 -> 0 | D17: =[1]Results!G1377 -> 2.8504202e-07 | E17: =[1]Results!H1377 -> 7.8169748e-07 | F17: =[1]Results!I1377 -> 1.4228235e-06 | G17: =[1]Results!J1377 -> 2.164693e-06 | H17: =[1]Results!K1377 -> 2.9838865e-06 | I17: =[1]Results!L1377 -> 3.3511225e-06 | J17: =[1]Results!M1377 -> 0.0025142637 | ... CJ17: =[1]Results!CM1377 -> -0.10795765
A18: =[1]Results!E1378 -> 100*(CH_2/CH_0-1) | B18: =[1]Results!C1378 -> Consommation des ménages | C18: =[1]Results!F1378 -> 0 | D18: =[1]Results!G1378 -> 1.667196e-05 | E18: =[1]Results!H1378 -> 4.8472668e-05 | F18: =[1]Results!I1378 -> 9.1729309e-05 | G18: =[1]Results!J1378 -> 0.0001429503 | H18: =[1]Results!K1378 -> 0.00019872419 | I18: =[1]Results!L1378 -> 0.00022766086 | J18: =[1]Results!M1378 -> -0.15281255 | ... CJ18: =[1]Results!CM1378 -> -10.420639
A19: =[1]Results!E1379 -> 100*(CH_cveh_2/CH_cveh_0-1) | B19: =[1]Results!C1379 -> Consommation des ménages automobile | C19: =[1]Results!F1379 -> 0 | D19: =[1]Results!G1379 -> 2.7803906e-05 | E19: =[1]Results!H1379 -> 7.6078422e-05 | F19: =[1]Results!I1379 -> 0.00013336858 | G19: =[1]Results!J1379 -> 0.00018950595 | H19: =[1]Results!K1379 -> 0.00024021219 | I19: =[1]Results!L1379 -> 0.00023928835 | J19: =[1]Results!M1379 -> 0.88820428 | ... CJ19: =[1]Results!CM1379 -> -5.6892266
A20: =[1]Results!E1380 -> 100*(G_2/G_0-1) | B20: =[1]Results!C1380 -> Dépenses publiques | C20: =[1]Results!F1380 -> 0 | D20: =[1]Results!G1380 -> 0 | E20: =[1]Results!H1380 -> 0 | F20: =[1]Results!I1380 -> 0 | G20: =[1]Results!J1380 -> 0 | H20: =[1]Results!K1380 -> 0 | I20: =[1]Results!L1380 -> 0 | J20: =[1]Results!M1380 -> 0 | ... CJ20: =[1]Results!CM1380 -> 0
A21: =[1]Results!E1381 -> 100*(I_2/I_0-1) | B21: =[1]Results!C1381 -> Investissement | C21: =[1]Results!F1381 -> 0 | D21: =[1]Results!G1381 -> 3.2981357e-05 | E21: =[1]Results!H1381 -> 8.4490632e-05 | F21: =[1]Results!I1381 -> 0.00014610963 | G21: =[1]Results!J1381 -> 0.00021352959 | H21: =[1]Results!K1381 -> 0.0002842929 | I21: =[1]Results!L1381 -> 0.00029679564 | J21: =[1]Results!M1381 -> -0.034908864 | ... CJ21: =[1]Results!CM1381 -> -11.416629
A22: =[1]Results!E1382 -> 100*((I_2-IA_spub_2)/(I_0-IA_spub_0)-1) | B22: =[1]Results!C1382 -> Investissement entreprises | C22: =[1]Results!F1382 -> 0 | D22: =[1]Results!G1382 -> 3.7980434e-05 | E22: =[1]Results!H1382 -> 9.7113709e-05 | F22: =[1]Results!I1382 -> 0.00016767463 | G22: =[1]Results!J1382 -> 0.00024473601 | H22: =[1]Results!K1382 -> 0.0003254536 | I22: =[1]Results!L1382 -> 0.00033859662 | J22: =[1]Results!M1382 -> -0.056235943 | ... CJ22: =[1]Results!CM1382 -> -13.130746
A23: =[1]Results!E1383 -> 100*(X_2/X_0-1) | B23: Exports | C23: =[1]Results!F1383 -> 0 | D23: =[1]Results!G1383 -> 0.00016316138 | E23: =[1]Results!H1383 -> 0.00031624936 | F23: =[1]Results!I1383 -> 0.00045931137 | G23: =[1]Results!J1383 -> 0.00059293092 | H23: =[1]Results!K1383 -> 0.00071788859 | I23: =[1]Results!L1383 -> 0.00054175819 | J23: =[1]Results!M1383 -> 0.22568633 | ... CJ23: =[1]Results!CM1383 -> -1.5521656
A24: =[1]Results!E1384 -> 100*(M_2/M_0-1) | B24: Imports | C24: =[1]Results!F1384 -> 0 | D24: =[1]Results!G1384 -> 5.1103827e-05 | E24: =[1]Results!H1384 -> 0.00011548695 | F24: =[1]Results!I1384 -> 0.0001859978 | G24: =[1]Results!J1384 -> 0.00025950378 | H24: =[1]Results!K1384 -> 0.0003339943 | I24: =[1]Results!L1384 -> 0.00031683749 | J24: =[1]Results!M1384 -> 0.18271424 | ... CJ24: =[1]Results!CM1384 -> -4.9593841
A25: =[1]Results!E1385 -> 100*((CH_2-CH_ccon_2)/(CH_0-CH_ccon_0)-1) | B25: =[1]Results!C1385 -> Consommation des ménages | C25: =[1]Results!F1385 -> 0 | D25: =[1]Results!G1385 -> 1.8135687e-05 | E25: =[1]Results!H1385 -> 5.325649e-05 | F25: =[1]Results!I1385 -> 0.00010066716 | G25: =[1]Results!J1385 -> 0.0001559056 | H25: =[1]Results!K1385 -> 0.00021537263 | I25: =[1]Results!L1385 -> 0.00024394257 | J25: =[1]Results!M1385 -> -0.1495991 | ... CJ25: =[1]Results!CM1385 -> -10.565111
A26: =[1]Results!E1386 -> 100*((I_2+CH_ccon_2)/(I_0+CH_ccon_0)-1) | B26: =[1]Results!C1386 -> Investissement | C26: =[1]Results!F1386 -> 0 | D26: =[1]Results!G1386 -> 2.8404383e-05 | E26: =[1]Results!H1386 -> 7.0171355e-05 | F26: =[1]Results!I1386 -> 0.00012035335 | G26: =[1]Results!J1386 -> 0.0001770994 | H26: =[1]Results!K1386 -> 0.0002382014 | I26: =[1]Results!L1386 -> 0.00025346908 | J26: =[1]Results!M1386 -> -0.054092351 | ... CJ26: =[1]Results!CM1386 -> -11.043842
A27: =[1]Results!E1387 -> 100*((CH_ccon_2)/(CH_ccon_0)-1) | B27: =[1]Results!C1387 -> Investissement ménages | C27: =[1]Results!F1387 -> 0 | D27: =[1]Results!G1387 -> -2.9685339e-05 | E27: =[1]Results!H1387 -> -5.5831163e-05 | F27: =[1]Results!I1387 -> -8.2196618e-05 | G27: =[1]Results!J1387 -> -0.00010748493 | H27: =[1]Results!K1387 -> -0.00013420072 | I27: =[1]Results!L1387 -> -0.0001122451 | J27: =[1]Results!M1387 -> -0.22263599 | ... CJ27: =[1]Results!CM1387 -> 1.2156574
A28: =[1]Results!E1388 -> 100*((IA_spub_2)/(IA_spub_0)-1) | B28: =[1]Results!C1388 -> Investissement public | C28: =[1]Results!F1388 -> 0 | D28: =[1]Results!G1388 -> 7.9424759e-06 | E28: =[1]Results!H1388 -> 2.1756953e-05 | F28: =[1]Results!I1388 -> 3.9534183e-05 | G28: =[1]Results!J1388 -> 5.998045e-05 | H28: =[1]Results!K1388 -> 8.244949e-05 | I28: =[1]Results!L1388 -> 9.236967e-05 | J28: =[1]Results!M1388 -> 0.069277523 | ... CJ28: =[1]Results!CM1388 -> -2.8417592
A29: =[1]Results!E1389 -> 100*(DISPINC_AT_VAL_2/DISPINC_AT_VAL_0-1) | B29: =[1]Results!C1389 -> Revenu disponible des ménages | C29: =[1]Results!F1389 -> 0 | D29: =[1]Results!G1389 -> 2.1614482e-05 | E29: =[1]Results!H1389 -> 5.9297036e-05 | F29: =[1]Results!I1389 -> 0.00010825505 | G29: =[1]Results!J1389 -> 0.00016488343 | H29: =[1]Results!K1389 -> 0.00022617948 | I29: =[1]Results!L1389 -> 0.00025096914 | J29: =[1]Results!M1389 -> -0.84718849 | ... CJ29: =[1]Results!CM1389 -> -12.831545
A30: =[1]Results!E1390 -> 100*(DISPINC_AT_VAL_2/DISPINC_AT_VAL_0-1)-100*(PCH_2/PCH_0-1) | B30: =[1]Results!C1390 -> Revenu disponible réel des ménages | C30: =[1]Results!F1390 -> 0 | D30: =[1]Results!G1390 -> 1.8544169e-05 | E30: =[1]Results!H1390 -> 5.1355397e-05 | F30: =[1]Results!I1390 -> 9.3019723e-05 | G30: =[1]Results!J1390 -> 0.00013967688 | H30: =[1]Results!K1390 -> 0.00018908502 | I30: =[1]Results!L1390 -> 0.0002065904 | J30: =[1]Results!M1390 -> -0.21716967 | ... CJ30: =[1]Results!CM1390 -> -9.3562568
A31: =[1]Results!E1391 -> 100*(DISPINC_AT_VAL_2/DISPINC_AT_VAL_0-1)-100*((F_L_2/F_L_0)-1) | B31: =[1]Results!C1391 -> Revenu disponible par emploi en valeur | C31: =[1]Results!F1391 -> 0 | D31: =[1]Results!G1391 -> 1.7431558e-06 | E31: =[1]Results!H1391 -> 4.7545025e-06 | F31: =[1]Results!I1391 -> 9.840929e-06 | G31: =[1]Results!J1391 -> 1.7720869e-05 | H31: =[1]Results!K1391 -> 2.8433113e-05 | I31: =[1]Results!L1391 -> 3.8069382e-05 | J31: =[1]Results!M1391 -> -0.77044258 | ... CJ31: =[1]Results!CM1391 -> -7.7673007
A32: =[1]Results!E1392 -> 100*(DISPINC_AT_VAL_2/DISPINC_AT_VAL_0-1)-100*((F_L_2/F_L_0)-1)-100*(PCH_2/PCH_0-1) | B32: =[1]Results!C1392 -> Revenu disponible réel par emploi | C32: =[1]Results!F1392 -> 0 | D32: =[1]Results!G1392 -> -1.3271576e-06 | E32: =[1]Results!H1392 -> -3.1871372e-06 | F32: =[1]Results!I1392 -> -5.3943986e-06 | G32: =[1]Results!J1392 -> -7.4856826e-06 | H32: =[1]Results!K1392 -> -8.6613523e-06 | I32: =[1]Results!L1392 -> -6.3093623e-06 | J32: =[1]Results!M1392 -> -0.14042377 | ... CJ32: =[1]Results!CM1392 -> -4.2920125
A33: =[1]Results!E1393 -> 100*(MPS_n_2-MPS_n_0) | B33: =[1]Results!C1393 -> Taux d'épargne | C33: =[1]Results!F1393 -> 0 | D33: =[1]Results!G1393 -> 0 | E33: =[1]Results!H1393 -> 0 | F33: =[1]Results!I1393 -> 0 | G33: =[1]Results!J1393 -> 0 | H33: =[1]Results!K1393 -> 0 | I33: =[1]Results!L1393 -> 0 | J33: =[1]Results!M1393 -> 0 | ... CJ33: =[1]Results!CM1393 -> 0
A34: =[1]Results!E1394 -> 100*(PCH_2/PCH_0-1) | B34: =[1]Results!C1394 -> Prix à la consommation des ménages | C34: =[1]Results!F1394 -> 0 | D34: =[1]Results!G1394 -> 1.8544169e-05 | E34: =[1]Results!H1394 -> 5.1355397e-05 | F34: =[1]Results!I1394 -> 9.3019723e-05 | G34: =[1]Results!J1394 -> 0.00013967688 | H34: =[1]Results!K1394 -> 0.00018908502 | I34: =[1]Results!L1394 -> 0.0002065904 | J34: =[1]Results!M1394 -> -0.21716967 | ... CJ34: =[1]Results!CM1394 -> -9.3562568
A35: =[1]Results!E1395 -> 100*(PY_2/PY_0-1) | B35: =[1]Results!C1395 -> Prix à la production marchande | C35: =[1]Results!F1395 -> 0 | D35: =[1]Results!G1395 -> 4.0622903e-06 | E35: =[1]Results!H1395 -> 1.2459618e-05 | F35: =[1]Results!I1395 -> 2.546611e-05 | G35: =[1]Results!J1395 -> 4.2399638e-05 | H35: =[1]Results!K1395 -> 6.2187075e-05 | I35: =[1]Results!L1395 -> 7.6459675e-05 | J35: =[1]Results!M1395 -> -0.26701343 | ... CJ35: =[1]Results!CM1395 -> -5.6479257
A36: =[1]Results!E1396 -> 100*(PX_2/PX_0-1) | B36: =[1]Results!C1396 -> Prix des exportations | C36: =[1]Results!F1396 -> 0 | D36: =[1]Results!G1396 -> 5.1519673e-06 | E36: =[1]Results!H1396 -> 1.4218898e-05 | F36: =[1]Results!I1396 -> 2.6503143e-05 | G36: =[1]Results!J1396 -> 4.1164026e-05 | H36: =[1]Results!K1396 -> 5.7359497e-05 | I36: =[1]Results!L1396 -> 6.506256e-05 | J36: =[1]Results!M1396 -> -0.32599982 | ... CJ36: =[1]Results!CM1396 -> -2.1237319
... A55: =[1]Results!E1415 -> DEBT_G_VAL_2 | B55: =[1]Results!C1415 -> Dette publique | C55: =[1]Results!F1415 -> 2111098.1 | D55: =[1]Results!G1415 -> 2203198.7 | E55: =[1]Results!H1415 -> 2301624.7 | F55: =[1]Results!I1415 -> 2405582.3 | G55: =[1]Results!J1415 -> 2515115.8 | H55: =[1]Results!K1415 -> 2629448.7 | I55: =[1]Results!L1415 -> 2750556.4 | J55: =[1]Results!M1415 -> 2881178.4 | ... CJ55: =[1]Results!CM1415 -> 59407436
B56: Emissions de CO2 énergétiques (MtCO2) | C56: =C73-C67 -> 0 | D56: =D73-D67 -> 0.0001238 | E56: =E73-E67 -> 0.000285 | F56: =F73-F67 -> 0.00046 | G56: =G73-G67 -> 0.0006415 | H56: =H73-H67 -> 0.0008235 | I56: =I73-I67 -> 0.0007749 | J56: =J73-J67 -> 8.702276 | ... CJ56: =CJ73-CJ67 -> 320.33068
A58: Consommation | B58: Baseline | C58: =[1]Results!F1731 -> 1196741.2 | D58: =[1]Results!G1731 -> 1199619 | E58: =[1]Results!H1731 -> 1213054.7 | F58: =[1]Results!I1731 -> 1228614.9 | G58: =[1]Results!J1731 -> 1243089.4 | H58: =[1]Results!K1731 -> 1257018.6 | I58: =[1]Results!L1731 -> 1268992.8 | J58: =[1]Results!M1731 -> 1281894.7 | ... CJ58: =[1]Results!CM1731 -> 3232059.9
B59: NZ50 | C59: =[1]Results!F1702 -> 1196741.2 | D59: =[1]Results!G1702 -> 1199619.2 | E59: =[1]Results!H1702 -> 1213055.3 | F59: =[1]Results!I1702 -> 1228616.1 | G59: =[1]Results!J1702 -> 1243091.2 | H59: =[1]Results!K1702 -> 1257021.1 | I59: =[1]Results!L1702 -> 1268995.7 | J59: =[1]Results!M1702 -> 1279935.8 | ... CJ59: =[1]Results!CM1702 -> 2895258.6
H60: =H58/G58-1 -> 0.011205299 | I60: =I58/H58-1 -> 0.0095259012 | J60: =J58/I58-1 -> 0.01016704 | K60: =K58/J58-1 -> 0.010912174 | L60: =L58/K58-1 -> 0.012088701 | M60: =M58/L58-1 -> 0.013229824 | N60: =N58/M58-1 -> 0.014086765 | O60: =O58/N58-1 -> 0.015135816 | ... CJ60: =CJ58/CI58-1 -> 0.0095210496
A61: IPC | B61: Baseline | C61: =[1]Results!F1789 -> 0.99804945 | D61: =[1]Results!G1789 -> 1.0096689 | E61: =[1]Results!H1789 -> 1.0199405 | F61: =[1]Results!I1789 -> 1.0304997 | G61: =[1]Results!J1789 -> 1.0394123 | H61: =[1]Results!K1789 -> 1.048674 | I61: =[1]Results!L1789 -> 1.0613189 | J61: =[1]Results!M1789 -> 1.0824302 | ... CJ61: =[1]Results!CM1789 -> 4.536156
...

Sheet Impact macro
A1: Scénario d'inaction (par rapport au scénario de transition ordonnée), en % d'écart | B1: 2030 | C1: 2050 | D1: 2100
A2: =Données!B5 -> PIB | B2: =Données!R5 -> -1.456527 | C2: =Données!AL5 -> -2.8145324 | D2: =Données!CJ5 -> -7.4705744
A3: =Données!B6 -> VA du secteur marchand | B3: =Données!R6 -> -1.595913 | C3: =Données!AL6 -> -3.2775856 | D3: =Données!CJ6 -> -8.9608559
A4: =Données!B18 -> Consommation des ménages | B4: =Données!R18 -> -2.9241921 | C4: =Données!AL18 -> -4.3407085 | D4: =Données!CJ18 -> -10.420639
A5: =Données!B21 -> Investissement | B5: =Données!R21 -> -2.2009279 | C5: =Données!AL21 -> -6.58725 | D5: =Données!CJ21 -> -11.416629
A6: =Données!B23 -> Exports | B6: =Données!R23 -> 2.0473731 | C6: =Données!AL23 -> 3.0643475 | D6: =Données!CJ23 -> -1.5521656
A7: =Données!B24 -> Imports | B7: =Données!R24 -> -0.19723562 | C7: =Données!AL24 -> -1.0315948 | D7: =Données!CJ24 -> -4.9593841
A8: =Données!B30 -> Revenu disponible réel des ménages | B8: =Données!R30 -> -2.8074534 | C8: =Données!AL30 -> -4.0060088 | D8: =Données!CJ30 -> -9.3562568
A9: =Données!B34 -> Prix à la consommation des ménages | B9: =Données!R34 -> -2.8074534 | C9: =Données!AL34 -> -4.0060088 | D9: =Données!CJ34 -> -9.3562568
A10: =Données!B35 -> Prix à la production marchande | B10: =Données!R35 -> -3.1744036 | C10: =Données!AL35 -> -4.747243 | D10: =Données!CJ35 -> -5.6479257
A11: =Données!B36 -> Prix des exportations | B11: =Données!R36 -> -2.7233117 | C11: =Données!AL36 -> -3.6131435 | D11: =Données!CJ36 -> -2.1237319
A12: =Données!B37 -> Prix des importations | B12: =Données!R37 -> 0.31883632 | C12: =Données!AL37 -> -0.74639129 | D12: =Données!CJ37 -> 1.2881515
A13: Salaire net réel | B13: =Données!R39 -> -0.2731383 | C13: =Données!AL39 -> -1.8689531 | D13: =Données!CJ39 -> -3.737534
A14: Coût réel du travail | B14: =Données!R41 -> -0.57653081 | C14: =Données!AL41 -> -1.0366523 | D14: =Données!CJ41 -> -2.9632148
A15: Emploi (en milliers) | B15: =Données!R43 -> -398.78935 | C15: =Données!AL43 -> -653.88165 | D15: =Données!CJ43 -> -1555.2091
A16: Taux de chômage (en points) | B16: =Données!R44 -> 0.92483096 | C16: =Données!AL44 -> 1.4181936 | D16: =Données!CJ44 -> 3.2791174
A17: Balance commerciale (en pts de PIB) | B17: =Données!R45 -> -0.39017979 | C17: =Données!AL45 -> 0.18109684 | D17: =Données!CJ45 -> -0.15643273
A18: Facture énergétique (en pts de PIB) | B18: =Données!R46 -> 1.1839658 | C18: =Données!AL46 -> 1.1696125 | D18: =Données!CJ46 -> 0.66986288
A19: Solde public primaire (en pts de PIB) | B19: =Données!R47 -> 0.83293849 | C19: =Données!AL47 -> 1.3404487 | D19: =Données!CJ47 -> 2.8845707
