Workbook
Name Output_variable: Lists!$A$1:$A$20
Name Redistribution: Lists!$C$1:$C$2

Sheet Raw
A1: critère de recherche | B1: _date_ | C1: redis_ls | D1: wage_eq | E1: flex | F1: expo | G1: 100*(gdp_1/gdp_0-1) | H1: f_l_1-f_l_0 | I1: 100*(ems_1/ems_0-1) | J1: 100*(ch_1/ch_0-1) | K1: 100*(i_1/i_0-1) | L1: 100*(x_1/x_0-1) | M1: 100*(m_1/m_0-1) | N1: 100*((dispinc_at_val_1/pch_1)/(dispinc_at_val_0/pch_0)-1) | O1: 100*(rsav_h_val_1-rsav_h_val_0) | P1: 100*(pch_1/pch_0-1) | Q1: 100*(py_1/py_0-1) | R1: 100*(pva_1/pva_0-1) | S1: 100*(pci_1/pci_0-1) | T1: 100*(px_1/pci_0-1) | U1: 100*(pm_1/pci_0-1) | V1: 100*(w_1/w_0-1) | W1: 100*((c_l_1/pva_1)/(c_l_0/pva_0)-1) | X1: 100*(unr_1-unr_0) | Y1: 100*(rbal_trade_val_1-rbal_trade_val_0) | Z1: 100*(rbal_g_prim_val_1-rbal_g_prim_val_0)
A2: =CONCATENATE(raw[[#This Row],[redis_ls]],raw[[#This Row],[wage_eq]],raw[[#This Row],[flex]],raw[[#This Row],[expo]],raw[[#This Row],[_date_]]) -> 121136526 | B2: 36526 | C2: 1 | D2: 2 | E2: 1 | F2: 1 | G2: 0 | H2: 0 | I2: 0 | J2: 0 | K2: 0 | L2: 0 | M2: 0 | N2: 0 | O2: 0 | P2: 0 | Q2: 0 | R2: 0 | S2: 0 | T2: 0.0055086996 | U2: 0.21447657 | V2: 0 | W2: 0 | X2: 0 | Y2: 0 | Z2: 0
A3: =CONCATENATE(raw[[#This Row],[redis_ls]],raw[[#This Row],[wage_eq]],raw[[#This Row],[flex]],raw[[#This Row],[expo]],raw[[#This Row],[_date_]]) -> 121136892 | B3: 36892 | C3: 1 | D3: 2 | E3: 1 | F3: 1 | G3: 0.2191321 | H3: 42.48462 | I3: -5.3912634 | J3: 0.10142586 | K3: 0.6084626 | L3: -0.15960564 | M3: -0.31293697 | N3: 0.14711122 | O3: 0.04093405 | P3: 0.46701051 | Q3: 0.12575151 | R3: -0.60069292 | S3: 0.84954612 | T3: 0.27341576 | U3: 0.73795858 | V3: 0.032299401 | W3: 0.63681764 | X3: -0.12688384 | Y3: 0.12059088 | Z3: 0.005848027
A4: =CONCATENATE(raw[[#This Row],[redis_ls]],raw[[#This Row],[wage_eq]],raw[[#This Row],[flex]],raw[[#This Row],[expo]],raw[[#This Row],[_date_]]) -> 121137257 | B4: 37257 | C4: 1 | D4: 2 | E4: 1 | F4: 1 | G4: 0.38850495 | H4: 89.19804 | I4: -8.6105152 | J4: 0.2652586 | K4: 1.1489764 | L4: -0.42735736 | M4: -0.450633 | N4: 0.32236317 | O4: 0.05106889 | P4: 0.6126117 | Q4: 0.32638614 | R4: -0.31867176 | S4: 0.97249579 | T4: 0.52513314 | U4: 1.5893091 | V4: 0.22231622 | W4: 0.54271748 | X4: -0.25508499 | Y4: 0.16398938 | Z4: 0.12563921
A5: =CONCATENATE(raw[[#This Row],[redis_ls]],raw[[#This Row],[wage_eq]],raw[[#This Row],[flex]],raw[[#This Row],[expo]],raw[[#This Row],[_date_]]) -> 121137622 | B5: 37622 | C5: 1 | D5: 2 | E5: 1 | F5: 1 | G5: 0.47718577 | H5: 122.82049 | I5: -10.470942 | J5: 0.43065243 | K5: 1.5567284 | L5: -0.78001468 | M5: -0.46213613 | N5: 0.475267 | O5: 0.03982194 | P5: 0.82353958 | Q5: 0.59170603 | R5: 0.031655474 | S5: 1.1564776 | T5: 0.78069352 | U5: 2.7453268 | V5: 0.46183709 | W5: 0.43004547 | X5: -0.33798854 | Y5: 0.15698983 | Z5: 0.22939729
A6: =CONCATENATE(raw[[#This Row],[redis_ls]],raw[[#This Row],[wage_eq]],raw[[#This Row],[flex]],raw[[#This Row],[expo]],raw[[#This Row],[_date_]]) -> 121137987 | B6: 37987 | C6: 1 | D6: 2 | E6: 1 | F6: 1 | G6: 0.49131181 | H6: 137.11021 | I6: -11.557104 | J6: 0.56743685 | K6: 1.8394665 | L6: -1.1935871 | M6: -0.41469935 | N6: 0.58843366 | O6: 0.01871102 | P6: 1.0655295 | Q6: 0.88674164 | R6: 0.41068885 | S6: 1.371792 | T6: 1.0299214 | U6: 4.1615535 | V6: 0.72461909 | W6: 0.31264623 | X6: -0.36376059 | Y6: 0.11733063 | Z6: 0.30239959
A7: =CONCATENATE(raw[[#This Row],[redis_ls]],raw[[#This Row],[wage_eq]],raw[[#This Row],[flex]],raw[[#This Row],[expo]],raw[[#This Row],[_date_]]) -> 121138353 | B7: 38353 | C7: 1 | D7: 2 | E7: 1 | F7: 1 | G7: 0.44784291 | H7: 131.83281 | I7: -12.210065 | J7: 0.66626414 | K7: 2.0278675 | L7: -1.6405607 | M7: -0.34913925 | N7: 0.66472081 | O7: -0.00137365 | P7: 1.3104663 | Q7: 1.179805 | R7: 0.78228129 | S7: 1.5915723 | T7: 1.2586891 | U7: 5.7837128 | V7: 0.99756693 | W7: 0.21361456 | X7: -0.33651862 | Y7: 0.05595967 | Z7: 0.34364206
A8: =CONCATENATE(raw[[#This Row],[redis_ls]],raw[[#This Row],[wage_eq]],raw[[#This Row],[flex]],raw[[#This Row],[expo]],raw[[#This Row],[_date_]]) -> 121138718 | B8: 38718 | C8: 1 | D8: 2 | E8: 1 | F8: 1 | G8: 0.36503783 | H8: 109.71106 | I8: -12.622296 | J8: 0.72693558 | K8: 2.1550164 | L8: -2.0935423 | M8: -0.28750486 | N8: 0.70829521 | O8: -0.0165773 | P8: 1.5390663 | Q8: 1.4486389 | R8: 1.1209256 | S8: 1.7968826 | T8: 1.4564249 | U8: 7.5536469 | V8: 1.2663659 | W8: 0.14382814 | X8: -0.26691475 | Y8: -0.01930862 | Z8: 0.35599175
A9: =CONCATENATE(raw[[#This Row],[redis_ls]],raw[[#This Row],[wage_eq]],raw[[#This Row],[flex]],raw[[#This Row],[expo]],raw[[#This Row],[_date_]]) -> 121139083 | B9: 39083 | C9: 1 | D9: 2 | E9: 1 | F9: 1 | G9: 0.25877544 | H9: 74.61884 | I9: -12.900873 | J9: 0.75232957 | K9: 2.2484844 | L9: -2.528584 | M9: -0.24106168 | N9: 0.72228919 | O9: -0.0267039 | P9: 1.739232 | Q9: 1.6795795 | R9: 1.4110311 | S9: 1.9758116 | T9: 1.6167792 | U9: 9.4125556 | V9: 1.5157663 | W9: 0.10327786 | X9: -0.16729885 | Y9: -0.10204765 | Z9: 0.34370146
A10: =CONCATENATE(raw[[#This Row],[redis_ls]],raw[[#This Row],[wage_eq]],raw[[#This Row],[flex]],raw[[#This Row],[expo]],raw[[#This Row],[_date_]]) -> 121139448 | B10: 39448 | C10: 1 | D10: 2 | E10: 1 | F10: 1 | G10: 0.14183679 | H10: 30.64392 | I10: -13.103971 | J10: 0.74644813 | K10: 2.3283947 | L10: -2.9267873 | M10: -0.21479339 | N10: 0.70983186 | O10: -0.03254692 | P10: 1.9038989 | Q10: 1.8652959 | R10: 1.6444304 | S10: 2.1215156 | T10: 1.736523 | U10: 11.303166 | V10: 1.7321244 | W10: 0.086275264 | X10: -0.0495181 | Y10: -0.18672736 | Z10: 0.31181133
A11: =CONCATENATE(raw[[#This Row],[redis_ls]],raw[[#This Row],[wage_eq]],raw[[#This Row],[flex]],raw[[#This Row],[expo]],raw[[#This Row],[_date_]]) -> 121139814 | B11: 39814 | C11: 1 | D11: 2 | E11: 1 | F11: 1 | G11: 0.024330124 | H11: -18.30444 | I11: -13.261457 | J11: 0.7141567 | K11: 2.4081499 | L11: -3.2745459 | M11: -0.20970028 | N11: 0.67494579 | O11: -0.03486123 | P11: 2.0294462 | Q11: 2.0028588 | R11: 1.8181688 | S11: 2.2306462 | T11: 1.81451 | U11: 13.171604 | V11: 1.9051334 | W11: 0.085411678 | X11: 0.07583821 | Y11: -0.26868048 | Z11: 0.26586029
A12: =CONCATENATE(raw[[#This Row],[redis_ls]],raw[[#This Row],[wage_eq]],raw[[#This Row],[flex]],raw[[#This Row],[expo]],raw[[#This Row],[_date_]]) -> 121140179 | B12: 40179 | C12: 1 | D12: 2 | E12: 1 | F12: 1 | G12: -0.085714113 | H12: -68.61086 | I12: -13.386621 | J12: 0.66122201 | K12: 2.4960072 | L12: -3.563081 | M12: -0.22406346 | N12: 0.6227651 | O12: -0.03420747 | P12: 2.1147355 | Q12: 2.0924386 | R12: 1.9329734 | S12: 2.3023525 | T12: 1.8511114 | U12: 14.969195 | V12: 2.0284908 | W12: 0.09370603 | X12: 0.19954729 | Y12: -0.3441695 | Z12: 0.21155877
A13: =CONCATENATE(raw[[#This Row],[redis_ls]],raw[[#This Row],[wage_eq]],raw[[#This Row],[flex]],raw[[#This Row],[expo]],raw[[#This Row],[_date_]]) -> 121140544 | B13: 40544 | C13: 1 | D13: 2 | E13: 1 | F13: 1 | G13: -0.1819393 | H13: -116.97329 | I13: -13.483101 | J13: 0.59415554 | K13: 2.5966051 | L13: -3.7877434 | M13: -0.25430159 | N13: 0.55925749 | O13: -0.03106269 | P13: 2.1605703 | Q13: 2.1364787 | R13: 1.9922528 | S13: 2.3376923 | T13: 1.8480151 | U13: 16.654153 | V13: 2.0998634 | W13: 0.1055086 | X13: 0.31368749 | Y13: -0.41043595 | Z13: 0.15441554
... A1225: =CONCATENATE(raw[[#This Row],[redis_ls]],raw[[#This Row],[wage_eq]],raw[[#This Row],[flex]],raw[[#This Row],[expo]],raw[[#This Row],[_date_]]) -> 000054789 | B1225: 54789 | C1225: 0 | D1225: 0 | E1225: 0 | F1225: 0 | G1225: -0.03564723 | H1225: 13.90153 | I1225: -1.4672772 | J1225: 0.21116223 | K1225: -0.50339511 | L1225: -0.36279873 | M1225: -0.087764684 | N1225: 0.21101812 | O1225: -0.00012893 | P1225: 0.6414583 | Q1225: 0.57617588 | R1225: 0.37217716 | S1225: 0.77916162 | T1225: 0.60436385 | U1225: -4.8298624e-07 | V1225: 0.65760437 | W1225: -0.12953818 | X1225: -0.03154626 | Y1225: 0.09594789 | Z1225: 0.067577273

Sheet Combinaison
C1: =_xlfn.CONCAT(C4,"_",C5,"_",C2,"_",C3) -> LF_LE_LS_WS | D1: =_xlfn.CONCAT(D4,"_",D5,"_",D2,"_",D3) -> LF_HE_LS_WS | E1: =_xlfn.CONCAT(E4,"_",E5,"_",E2,"_",E3) -> HF_LE_LS_WS | F1: =_xlfn.CONCAT(F4,"_",F5,"_",F2,"_",F3) -> HF_HE_LS_WS | G1: =_xlfn.CONCAT(G4,"_",G5,"_",G2,"_",G3) -> LF_LE_LS_PC | H1: =_xlfn.CONCAT(H4,"_",H5,"_",H2,"_",H3) -> LF_HE_LS_PC | I1: =_xlfn.CONCAT(I4,"_",I5,"_",I2,"_",I3) -> HF_LE_LS_PC | J1: =_xlfn.CONCAT(J4,"_",J5,"_",J2,"_",J3) -> HF_HE_LS_PC | ... Z1: =_xlfn.CONCAT(Z4,"_",Z5,"_",Z2,"_",Z3) -> HF_HE_SSC_PC-TVN
C2: LS | D2: LS | E2: LS | F2: LS | G2: LS | H2: LS | I2: LS | J2: LS | K2: LS | L2: LS | M2: LS | N2: LS | O2: SSC | P2: SSC | Q2: SSC | R2: SSC | S2: SSC | T2: SSC | U2: SSC | V2: SSC | W2: SSC | X2: SSC | Y2: SSC | Z2: SSC
C3: WS | D3: WS | E3: WS | F3: WS | G3: PC | H3: PC | I3: PC | J3: PC | K3: PC-TVN | L3: PC-TVN | M3: PC-TVN | N3: PC-TVN | O3: =C3 -> WS | P3: =D3 -> WS | Q3: =E3 -> WS | R3: =F3 -> WS | S3: =G3 -> PC | T3: =H3 -> PC | U3: =I3 -> PC | V3: =J3 -> PC | ... Z3: =N3 -> PC-TVN
C4: LF | D4: LF | E4: HF | F4: HF | G4: LF | H4: LF | I4: HF | J4: HF | K4: LF | L4: LF | M4: HF | N4: HF | O4: LF | P4: LF | Q4: HF | R4: HF | S4: LF | T4: LF | U4: HF | V4: HF | W4: LF | X4: LF | Y4: HF | Z4: HF
C5: LE | D5: HE | E5: LE | F5: HE | G5: LE | H5: HE | I5: LE | J5: HE | K5: LE | L5: HE | M5: LE | N5: HE | O5: LE | P5: HE | Q5: LE | R5: HE | S5: LE | T5: HE | U5: LE | V5: HE | W5: LE | X5: HE | Y5: LE | Z5: HE

Sheet Table_Dynam_GDP
C1: 1 | D1: 2 | E1: 3 | F1: 4 | G1: 5 | H1: 6 | I1: 7 | J1: 8 | K1: 9 | L1: 10 | M1: 11 | N1: 12 | O1: 13 | P1: 14 | Q1: 15 | R1: 16 | S1: 17 | T1: 18 | U1: 19 | V1: 20 | W1: 21 | X1: 22 | Y1: 23 | Z1: 24
A2: Critères (codes) | C2: 1000 | D2: 1001 | E2: 1010 | F2: 1011 | G2: 1100 | H2: 1101 | I2: 1110 | J2: 1111 | K2: 1200 | L2: 1201 | M2: 1210 | N2: 1211 | O2: 0000 | P2: 0001 | Q2: 0010 | R2: 0011 | S2: 0100 | T2: 0101 | U2: 0110 | V2: 0111 | W2: 0200 | X2: 0201 | Y2: 0210 | Z2: 0211
A3: =C2&A8 -> 100036526 | C3: LS | O3: SSC
C4: WS | G4: Constant NAIRU | K4: TV NAIRU | O4: WS | S4: Constant NAIRU | W4: TV NAIRU
C5: LF | E5: HF | G5: LF | I5: HF | K5: LF | M5: HF | O5: LF | Q5: HF | S5: LF | U5: HF | W5: LF | Y5: HF
C6: LE | D6: HE | E6: LE | F6: HE | G6: LE | H6: HE | I6: LE | J6: HE | K6: LE | L6: HE | M6: LE | N6: HE | O6: LE | P6: HE | Q6: LE | R6: HE | S6: LE | T6: HE | U6: LE | V6: HE | W6: LE | X6: HE | Y6: LE | Z6: HE
C7: =Combinaison!C1 -> LF_LE_LS_WS | D7: =Combinaison!D1 -> LF_HE_LS_WS | E7: =Combinaison!E1 -> HF_LE_LS_WS | F7: =Combinaison!F1 -> HF_HE_LS_WS | G7: =Combinaison!G1 -> LF_LE_LS_PC | H7: =Combinaison!H1 -> LF_HE_LS_PC | I7: =Combinaison!I1 -> HF_LE_LS_PC | J7: =Combinaison!J1 -> HF_HE_LS_PC | ... Z7: =Combinaison!Z1 -> HF_HE_SSC_PC-TVN
A8: 36526 | B8: 36526 | C8: =VLOOKUP(C$2&$A8,'Raw'!$A$2:$Z$1225,7,FALSE) -> 0 | D8: =VLOOKUP(D$2&$A8,'Raw'!$A$2:$Z$1225,7,FALSE) -> 0 | E8: =VLOOKUP(E$2&$A8,'Raw'!$A$2:$Z$1225,7,FALSE) -> 0 | F8: =VLOOKUP(F$2&$A8,'Raw'!$A$2:$Z$1225,7,FALSE) -> 0 | G8: =VLOOKUP(G$2&$A8,'Raw'!$A$2:$Z$1225,7,FALSE) -> 0 | H8: =VLOOKUP(H$2&$A8,'Raw'!$A$2:$Z$1225,7,FALSE) -> 0 | I8: =VLOOKUP(I$2&$A8,'Raw'!$A$2:$Z$1225,7,FALSE) -> 0 | J8: =VLOOKUP(J$2&$A8,'Raw'!$A$2:$Z$1225,7,FALSE) -> 0 | ... Z8: =VLOOKUP(Z$2&$A8,'Raw'!$A$2:$Z$1225,7,FALSE) -> 0
A9: 36892 | B9: 36892 | C9: =VLOOKUP(C$2&$A9,'Raw'!$A$2:$Z$1225,7,FALSE) -> 0.03119858 | D9: =VLOOKUP(D$2&$A9,'Raw'!$A$2:$Z$1225,7,FALSE) -> 0.0015880665 | E9: =VLOOKUP(E$2&$A9,'Raw'!$A$2:$Z$1225,7,FALSE) -> 0.25683059 | F9: =VLOOKUP(F$2&$A9,'Raw'!$A$2:$Z$1225,7,FALSE) -> 0.21895396 | G9: =VLOOKUP(G$2&$A9,'Raw'!$A$2:$Z$1225,7,FALSE) -> 0.032690833 | H9: =VLOOKUP(H$2&$A9,'Raw'!$A$2:$Z$1225,7,FALSE) -> 0.0023494812 | I9: =VLOOKUP(I$2&$A9,'Raw'!$A$2:$Z$1225,7,FALSE) -> 0.25831139 | J9: =VLOOKUP(J$2&$A9,'Raw'!$A$2:$Z$1225,7,FALSE) -> 0.2194539 | ... Z9: =VLOOKUP(Z$2&$A9,'Raw'!$A$2:$Z$1225,7,FALSE) -> 0.21182245
A10: 37257 | B10: 37257 | C10: =VLOOKUP(C$2&$A10,'Raw'!$A$2:$Z$1225,7,FALSE) -> 0.063863963 | D10: =VLOOKUP(D$2&$A10,'Raw'!$A$2:$Z$1225,7,FALSE) -> -0.0098470345 | E10: =VLOOKUP(E$2&$A10,'Raw'!$A$2:$Z$1225,7,FALSE) -> 0.49704621 | F10: =VLOOKUP(F$2&$A10,'Raw'!$A$2:$Z$1225,7,FALSE) -> 0.38987568 | G10: =VLOOKUP(G$2&$A10,'Raw'!$A$2:$Z$1225,7,FALSE) -> 0.067747564 | H10: =VLOOKUP(H$2&$A10,'Raw'!$A$2:$Z$1225,7,FALSE) -> -0.0092354071 | I10: =VLOOKUP(I$2&$A10,'Raw'!$A$2:$Z$1225,7,FALSE) -> 0.50158558 | J10: =VLOOKUP(J$2&$A10,'Raw'!$A$2:$Z$1225,7,FALSE) -> 0.38919889 | ... Z10: =VLOOKUP(Z$2&$A10,'Raw'!$A$2:$Z$1225,7,FALSE) -> 0.37492624
A11: 37622 | B11: 37622 | C11: =VLOOKUP(C$2&$A11,'Raw'!$A$2:$Z$1225,7,FALSE) -> 0.085481766 | D11: =VLOOKUP(D$2&$A11,'Raw'!$A$2:$Z$1225,7,FALSE) -> -0.039937835 | E11: =VLOOKUP(E$2&$A11,'Raw'!$A$2:$Z$1225,7,FALSE) -> 0.68876679 | F11: =VLOOKUP(F$2&$A11,'Raw'!$A$2:$Z$1225,7,FALSE) -> 0.48419046 | G11: =VLOOKUP(G$2&$A11,'Raw'!$A$2:$Z$1225,7,FALSE) -> 0.092372111 | H11: =VLOOKUP(H$2&$A11,'Raw'!$A$2:$Z$1225,7,FALSE) -> -0.041896139 | I11: =VLOOKUP(I$2&$A11,'Raw'!$A$2:$Z$1225,7,FALSE) -> 0.69774205 | J11: =VLOOKUP(J$2&$A11,'Raw'!$A$2:$Z$1225,7,FALSE) -> 0.47730126 | ... Z11: =VLOOKUP(Z$2&$A11,'Raw'!$A$2:$Z$1225,7,FALSE) -> 0.45706931
A12: 37987 | B12: 37987 | C12: =VLOOKUP(C$2&$A12,'Raw'!$A$2:$Z$1225,7,FALSE) -> 0.091518266 | D12: =VLOOKUP(D$2&$A12,'Raw'!$A$2:$Z$1225,7,FALSE) -> -0.088370303 | E12: =VLOOKUP(E$2&$A12,'Raw'!$A$2:$Z$1225,7,FALSE) -> 0.83425832 | F12: =VLOOKUP(F$2&$A12,'Raw'!$A$2:$Z$1225,7,FALSE) -> 0.51029402 | G12: =VLOOKUP(G$2&$A12,'Raw'!$A$2:$Z$1225,7,FALSE) -> 0.10175137 | H12: =VLOOKUP(H$2&$A12,'Raw'!$A$2:$Z$1225,7,FALSE) -> -0.09657746 | I12: =VLOOKUP(I$2&$A12,'Raw'!$A$2:$Z$1225,7,FALSE) -> 0.84870434 | J12: =VLOOKUP(J$2&$A12,'Raw'!$A$2:$Z$1225,7,FALSE) -> 0.48857956 | ... Z12: =VLOOKUP(Z$2&$A12,'Raw'!$A$2:$Z$1225,7,FALSE) -> 0.46392756
A13: 38353 | B13: 38353 | C13: =VLOOKUP(C$2&$A13,'Raw'!$A$2:$Z$1225,7,FALSE) -> 0.084319173 | D13: =VLOOKUP(D$2&$A13,'Raw'!$A$2:$Z$1225,7,FALSE) -> -0.14876528 | E13: =VLOOKUP(E$2&$A13,'Raw'!$A$2:$Z$1225,7,FALSE) -> 0.94370455 | F13: =VLOOKUP(F$2&$A13,'Raw'!$A$2:$Z$1225,7,FALSE) -> 0.48686757 | G13: =VLOOKUP(G$2&$A13,'Raw'!$A$2:$Z$1225,7,FALSE) -> 0.098181937 | H13: =VLOOKUP(H$2&$A13,'Raw'!$A$2:$Z$1225,7,FALSE) -> -0.16737296 | I13: =VLOOKUP(I$2&$A13,'Raw'!$A$2:$Z$1225,7,FALSE) -> 0.96422085 | J13: =VLOOKUP(J$2&$A13,'Raw'!$A$2:$Z$1225,7,FALSE) -> 0.43889934 | ... Z13: =VLOOKUP(Z$2&$A13,'Raw'!$A$2:$Z$1225,7,FALSE) -> 0.41257302
A14: 38718 | B14: 38718 | C14: =VLOOKUP(C$2&$A14,'Raw'!$A$2:$Z$1225,7,FALSE) -> 0.06877892 | D14: =VLOOKUP(D$2&$A14,'Raw'!$A$2:$Z$1225,7,FALSE) -> -0.21295868 | E14: =VLOOKUP(E$2&$A14,'Raw'!$A$2:$Z$1225,7,FALSE) -> 1.0269892 | F14: =VLOOKUP(F$2&$A14,'Raw'!$A$2:$Z$1225,7,FALSE) -> 0.43298585 | G14: =VLOOKUP(G$2&$A14,'Raw'!$A$2:$Z$1225,7,FALSE) -> 0.086697433 | H14: =VLOOKUP(H$2&$A14,'Raw'!$A$2:$Z$1225,7,FALSE) -> -0.24562345 | I14: =VLOOKUP(I$2&$A14,'Raw'!$A$2:$Z$1225,7,FALSE) -> 1.0536773 | J14: =VLOOKUP(J$2&$A14,'Raw'!$A$2:$Z$1225,7,FALSE) -> 0.3460622 | ... Z14: =VLOOKUP(Z$2&$A14,'Raw'!$A$2:$Z$1225,7,FALSE) -> 0.32171201
A15: 39083 | B15: 39083 | C15: =VLOOKUP(C$2&$A15,'Raw'!$A$2:$Z$1225,7,FALSE) -> 0.049608982 | D15: =VLOOKUP(D$2&$A15,'Raw'!$A$2:$Z$1225,7,FALSE) -> -0.27386337 | E15: =VLOOKUP(E$2&$A15,'Raw'!$A$2:$Z$1225,7,FALSE) -> 1.0912238 | F15: =VLOOKUP(F$2&$A15,'Raw'!$A$2:$Z$1225,7,FALSE) -> 0.36420726 | G15: =VLOOKUP(G$2&$A15,'Raw'!$A$2:$Z$1225,7,FALSE) -> 0.072166917 | H15: =VLOOKUP(H$2&$A15,'Raw'!$A$2:$Z$1225,7,FALSE) -> -0.32285191 | I15: =VLOOKUP(I$2&$A15,'Raw'!$A$2:$Z$1225,7,FALSE) -> 1.1236517 | J15: =VLOOKUP(J$2&$A15,'Raw'!$A$2:$Z$1225,7,FALSE) -> 0.22632896 | ... Z15: =VLOOKUP(Z$2&$A15,'Raw'!$A$2:$Z$1225,7,FALSE) -> 0.20777047
A16: 39448 | B16: 39448 | C16: =VLOOKUP(C$2&$A16,'Raw'!$A$2:$Z$1225,7,FALSE) -> 0.030297855 | D16: =VLOOKUP(D$2&$A16,'Raw'!$A$2:$Z$1225,7,FALSE) -> -0.32656275 | E16: =VLOOKUP(E$2&$A16,'Raw'!$A$2:$Z$1225,7,FALSE) -> 1.140839 | F16: =VLOOKUP(F$2&$A16,'Raw'!$A$2:$Z$1225,7,FALSE) -> 0.29178901 | G16: =VLOOKUP(G$2&$A16,'Raw'!$A$2:$Z$1225,7,FALSE) -> 0.058100714 | H16: =VLOOKUP(H$2&$A16,'Raw'!$A$2:$Z$1225,7,FALSE) -> -0.39206983 | I16: =VLOOKUP(I$2&$A16,'Raw'!$A$2:$Z$1225,7,FALSE) -> 1.1780482 | J16: =VLOOKUP(J$2&$A16,'Raw'!$A$2:$Z$1225,7,FALSE) -> 0.09370955 | ... Z16: =VLOOKUP(Z$2&$A16,'Raw'!$A$2:$Z$1225,7,FALSE) -> 0.084000455
A17: 39814 | B17: 39814 | C17: =VLOOKUP(C$2&$A17,'Raw'!$A$2:$Z$1225,7,FALSE) -> 0.012993907 | D17: =VLOOKUP(D$2&$A17,'Raw'!$A$2:$Z$1225,7,FALSE) -> -0.36836754 | E17: =VLOOKUP(E$2&$A17,'Raw'!$A$2:$Z$1225,7,FALSE) -> 1.1784758 | F17: =VLOOKUP(F$2&$A17,'Raw'!$A$2:$Z$1225,7,FALSE) -> 0.22321561 | G17: =VLOOKUP(G$2&$A17,'Raw'!$A$2:$Z$1225,7,FALSE) -> 0.046465464 | H17: =VLOOKUP(H$2&$A17,'Raw'!$A$2:$Z$1225,7,FALSE) -> -0.44811816 | I17: =VLOOKUP(I$2&$A17,'Raw'!$A$2:$Z$1225,7,FALSE) -> 1.2190359 | J17: =VLOOKUP(J$2&$A17,'Raw'!$A$2:$Z$1225,7,FALSE) -> -0.03975143 | ... Z17: =VLOOKUP(Z$2&$A17,'Raw'!$A$2:$Z$1225,7,FALSE) -> -0.039192985
A18: 40179 | B18: 40179 | C18: =VLOOKUP(C$2&$A18,'Raw'!$A$2:$Z$1225,7,FALSE) -> -0.0012550694 | D18: =VLOOKUP(D$2&$A18,'Raw'!$A$2:$Z$1225,7,FALSE) -> -0.39843167 | E18: =VLOOKUP(E$2&$A18,'Raw'!$A$2:$Z$1225,7,FALSE) -> 1.2058317 | F18: =VLOOKUP(F$2&$A18,'Raw'!$A$2:$Z$1225,7,FALSE) -> 0.16304986 | G18: =VLOOKUP(G$2&$A18,'Raw'!$A$2:$Z$1225,7,FALSE) -> 0.0379475 | H18: =VLOOKUP(H$2&$A18,'Raw'!$A$2:$Z$1225,7,FALSE) -> -0.48759968 | I18: =VLOOKUP(I$2&$A18,'Raw'!$A$2:$Z$1225,7,FALSE) -> 1.2479307 | J18: =VLOOKUP(J$2&$A18,'Raw'!$A$2:$Z$1225,7,FALSE) -> -0.16361932 | ... Z18: =VLOOKUP(Z$2&$A18,'Raw'!$A$2:$Z$1225,7,FALSE) -> -0.15368556
A19: 40544 | B19: 40544 | C19: =VLOOKUP(C$2&$A19,'Raw'!$A$2:$Z$1225,7,FALSE) -> -0.012184269 | D19: =VLOOKUP(D$2&$A19,'Raw'!$A$2:$Z$1225,7,FALSE) -> -0.41724841 | E19: =VLOOKUP(E$2&$A19,'Raw'!$A$2:$Z$1225,7,FALSE) -> 1.2242079 | F19: =VLOOKUP(F$2&$A19,'Raw'!$A$2:$Z$1225,7,FALSE) -> 0.11371069 | G19: =VLOOKUP(G$2&$A19,'Raw'!$A$2:$Z$1225,7,FALSE) -> 0.032353039 | H19: =VLOOKUP(H$2&$A19,'Raw'!$A$2:$Z$1225,7,FALSE) -> -0.5087002 | I19: =VLOOKUP(I$2&$A19,'Raw'!$A$2:$Z$1225,7,FALSE) -> 1.2657576 | J19: =VLOOKUP(J$2&$A19,'Raw'!$A$2:$Z$1225,7,FALSE) -> -0.26896422 | ... Z19: =VLOOKUP(Z$2&$A19,'Raw'!$A$2:$Z$1225,7,FALSE) -> -0.25320855
... A58: 54789 | B58: 54789 | C58: =VLOOKUP(C$2&$A58,'Raw'!$A$2:$Z$1225,7,FALSE) -> -0.0020839507 | D58: =VLOOKUP(D$2&$A58,'Raw'!$A$2:$Z$1225,7,FALSE) -> -0.17885163 | E58: =VLOOKUP(E$2&$A58,'Raw'!$A$2:$Z$1225,7,FALSE) -> 0.39419209 | F58: =VLOOKUP(F$2&$A58,'Raw'!$A$2:$Z$1225,7,FALSE) -> 0.22326131 | G58: =VLOOKUP(G$2&$A58,'Raw'!$A$2:$Z$1225,7,FALSE) -> -0.03460935 | H58: =VLOOKUP(H$2&$A58,'Raw'!$A$2:$Z$1225,7,FALSE) -> -0.021464767 | I58: =VLOOKUP(I$2&$A58,'Raw'!$A$2:$Z$1225,7,FALSE) -> 0.25266444 | J58: =VLOOKUP(J$2&$A58,'Raw'!$A$2:$Z$1225,7,FALSE) -> 0.14381471 | ... Z58: =VLOOKUP(Z$2&$A58,'Raw'!$A$2:$Z$1225,7,FALSE) -> 0.064385249

Sheet Table_Dynam_EMS
A2: Critères (codes) | C2: 1000 | D2: 1001 | E2: 1010 | F2: 1011 | G2: 1100 | H2: 1101 | I2: 1110 | J2: 1111 | K2: 1200 | L2: 1201 | M2: 1210 | N2: 1211 | O2: 0000 | P2: 0001 | Q2: 0010 | R2: 0011 | S2: 0100 | T2: 0101 | U2: 0110 | V2: 0111 | W2: 0200 | X2: 0201 | Y2: 0210 | Z2: 0211
A3: =C2&A8 -> 100036526 | C3: LS | O3: SSC
C4: WS | G4: Constant NAIRU | K4: TV NAIRU | O4: WS | S4: Constant NAIRU | W4: TV NAIRU
C5: LF | E5: HF | G5: LF | I5: HF | K5: LF | M5: HF | O5: LF | Q5: HF | S5: LF | U5: HF | W5: LF | Y5: HF
C6: LE | D6: HE | E6: LE | F6: HE | G6: LE | H6: HE | I6: LE | J6: HE | K6: LE | L6: HE | M6: LE | N6: HE | O6: LE | P6: HE | Q6: LE | R6: HE | S6: LE | T6: HE | U6: LE | V6: HE | W6: LE | X6: HE | Y6: LE | Z6: HE
C7: =Combinaison!C1 -> LF_LE_LS_WS | D7: =Combinaison!D1 -> LF_HE_LS_WS | E7: =Combinaison!E1 -> HF_LE_LS_WS | F7: =Combinaison!F1 -> HF_HE_LS_WS | G7: =Combinaison!G1 -> LF_LE_LS_PC | H7: =Combinaison!H1 -> LF_HE_LS_PC | I7: =Combinaison!I1 -> HF_LE_LS_PC | J7: =Combinaison!J1 -> HF_HE_LS_PC | ... Z7: =Combinaison!Z1 -> HF_HE_SSC_PC-TVN
A8: 36526 | B8: 36526 | C8: =VLOOKUP(C$2&$A8,'Raw'!$A$2:$Z$1225,9,FALSE) -> 0 | D8: =VLOOKUP(D$2&$A8,'Raw'!$A$2:$Z$1225,9,FALSE) -> 0 | E8: =VLOOKUP(E$2&$A8,'Raw'!$A$2:$Z$1225,9,FALSE) -> 0 | F8: =VLOOKUP(F$2&$A8,'Raw'!$A$2:$Z$1225,9,FALSE) -> 0 | G8: =VLOOKUP(G$2&$A8,'Raw'!$A$2:$Z$1225,9,FALSE) -> 0 | H8: =VLOOKUP(H$2&$A8,'Raw'!$A$2:$Z$1225,9,FALSE) -> 0 | I8: =VLOOKUP(I$2&$A8,'Raw'!$A$2:$Z$1225,9,FALSE) -> 0 | J8: =VLOOKUP(J$2&$A8,'Raw'!$A$2:$Z$1225,9,FALSE) -> 0 | ... Z8: =VLOOKUP(Z$2&$A8,'Raw'!$A$2:$Z$1225,9,FALSE) -> 0
A9: 36892 | B9: 36892 | C9: =VLOOKUP(C$2&$A9,'Raw'!$A$2:$Z$1225,9,FALSE) -> -1.1929824 | D9: =VLOOKUP(D$2&$A9,'Raw'!$A$2:$Z$1225,9,FALSE) -> -1.2427626 | E9: =VLOOKUP(E$2&$A9,'Raw'!$A$2:$Z$1225,9,FALSE) -> -5.3351141 | F9: =VLOOKUP(F$2&$A9,'Raw'!$A$2:$Z$1225,9,FALSE) -> -5.3968471 | G9: =VLOOKUP(G$2&$A9,'Raw'!$A$2:$Z$1225,9,FALSE) -> -1.1961778 | H9: =VLOOKUP(H$2&$A9,'Raw'!$A$2:$Z$1225,9,FALSE) -> -1.2461891 | I9: =VLOOKUP(I$2&$A9,'Raw'!$A$2:$Z$1225,9,FALSE) -> -5.3296636 | J9: =VLOOKUP(J$2&$A9,'Raw'!$A$2:$Z$1225,9,FALSE) -> -5.3901452 | ... Z9: =VLOOKUP(Z$2&$A9,'Raw'!$A$2:$Z$1225,9,FALSE) -> -5.4416065
A10: 37257 | B10: 37257 | C10: =VLOOKUP(C$2&$A10,'Raw'!$A$2:$Z$1225,9,FALSE) -> -1.9405679 | D10: =VLOOKUP(D$2&$A10,'Raw'!$A$2:$Z$1225,9,FALSE) -> -2.0647879 | E10: =VLOOKUP(E$2&$A10,'Raw'!$A$2:$Z$1225,9,FALSE) -> -8.4612549 | F10: =VLOOKUP(F$2&$A10,'Raw'!$A$2:$Z$1225,9,FALSE) -> -8.6351518 | G10: =VLOOKUP(G$2&$A10,'Raw'!$A$2:$Z$1225,9,FALSE) -> -1.9460355 | H10: =VLOOKUP(H$2&$A10,'Raw'!$A$2:$Z$1225,9,FALSE) -> -2.071956 | I10: =VLOOKUP(I$2&$A10,'Raw'!$A$2:$Z$1225,9,FALSE) -> -8.4323106 | J10: =VLOOKUP(J$2&$A10,'Raw'!$A$2:$Z$1225,9,FALSE) -> -8.6063731 | ... Z10: =VLOOKUP(Z$2&$A10,'Raw'!$A$2:$Z$1225,9,FALSE) -> -8.6935721
A11: 37622 | B11: 37622 | C11: =VLOOKUP(C$2&$A11,'Raw'!$A$2:$Z$1225,9,FALSE) -> -2.3690923 | D11: =VLOOKUP(D$2&$A11,'Raw'!$A$2:$Z$1225,9,FALSE) -> -2.5755415 | E11: =VLOOKUP(E$2&$A11,'Raw'!$A$2:$Z$1225,9,FALSE) -> -10.187797 | F11: =VLOOKUP(F$2&$A11,'Raw'!$A$2:$Z$1225,9,FALSE) -> -10.51796 | G11: =VLOOKUP(G$2&$A11,'Raw'!$A$2:$Z$1225,9,FALSE) -> -2.3767797 | H11: =VLOOKUP(H$2&$A11,'Raw'!$A$2:$Z$1225,9,FALSE) -> -2.5891233 | I11: =VLOOKUP(I$2&$A11,'Raw'!$A$2:$Z$1225,9,FALSE) -> -10.121136 | J11: =VLOOKUP(J$2&$A11,'Raw'!$A$2:$Z$1225,9,FALSE) -> -10.462111 | ... Z11: =VLOOKUP(Z$2&$A11,'Raw'!$A$2:$Z$1225,9,FALSE) -> -10.572723
A12: 37987 | B12: 37987 | C12: =VLOOKUP(C$2&$A12,'Raw'!$A$2:$Z$1225,9,FALSE) -> -2.6067881 | D12: =VLOOKUP(D$2&$A12,'Raw'!$A$2:$Z$1225,9,FALSE) -> -2.894311 | E12: =VLOOKUP(E$2&$A12,'Raw'!$A$2:$Z$1225,9,FALSE) -> -11.093353 | F12: =VLOOKUP(F$2&$A12,'Raw'!$A$2:$Z$1225,9,FALSE) -> -11.6184 | G12: =VLOOKUP(G$2&$A12,'Raw'!$A$2:$Z$1225,9,FALSE) -> -2.6173318 | H12: =VLOOKUP(H$2&$A12,'Raw'!$A$2:$Z$1225,9,FALSE) -> -2.9189934 | I12: =VLOOKUP(I$2&$A12,'Raw'!$A$2:$Z$1225,9,FALSE) -> -10.979435 | J12: =VLOOKUP(J$2&$A12,'Raw'!$A$2:$Z$1225,9,FALSE) -> -11.543302 | ... Z12: =VLOOKUP(Z$2&$A12,'Raw'!$A$2:$Z$1225,9,FALSE) -> -11.670501
A13: 38353 | B13: 38353 | C13: =VLOOKUP(C$2&$A13,'Raw'!$A$2:$Z$1225,9,FALSE) -> -2.7332304 | D13: =VLOOKUP(D$2&$A13,'Raw'!$A$2:$Z$1225,9,FALSE) -> -3.0957171 | E13: =VLOOKUP(E$2&$A13,'Raw'!$A$2:$Z$1225,9,FALSE) -> -11.516958 | F13: =VLOOKUP(F$2&$A13,'Raw'!$A$2:$Z$1225,9,FALSE) -> -12.267592 | G13: =VLOOKUP(G$2&$A13,'Raw'!$A$2:$Z$1225,9,FALSE) -> -2.7472576 | H13: =VLOOKUP(H$2&$A13,'Raw'!$A$2:$Z$1225,9,FALSE) -> -3.1368032 | I13: =VLOOKUP(I$2&$A13,'Raw'!$A$2:$Z$1225,9,FALSE) -> -11.350755 | J13: =VLOOKUP(J$2&$A13,'Raw'!$A$2:$Z$1225,9,FALSE) -> -12.193159 | ... Z13: =VLOOKUP(Z$2&$A13,'Raw'!$A$2:$Z$1225,9,FALSE) -> -12.332113
A14: 38718 | B14: 38718 | C14: =VLOOKUP(C$2&$A14,'Raw'!$A$2:$Z$1225,9,FALSE) -> -2.7935594 | D14: =VLOOKUP(D$2&$A14,'Raw'!$A$2:$Z$1225,9,FALSE) -> -3.2219462 | E14: =VLOOKUP(E$2&$A14,'Raw'!$A$2:$Z$1225,9,FALSE) -> -11.654312 | F14: =VLOOKUP(F$2&$A14,'Raw'!$A$2:$Z$1225,9,FALSE) -> -12.650947 | G14: =VLOOKUP(G$2&$A14,'Raw'!$A$2:$Z$1225,9,FALSE) -> -2.8112208 | H14: =VLOOKUP(H$2&$A14,'Raw'!$A$2:$Z$1225,9,FALSE) -> -3.2839083 | I14: =VLOOKUP(I$2&$A14,'Raw'!$A$2:$Z$1225,9,FALSE) -> -11.434822 | J14: =VLOOKUP(J$2&$A14,'Raw'!$A$2:$Z$1225,9,FALSE) -> -12.606433 | ... Z14: =VLOOKUP(Z$2&$A14,'Raw'!$A$2:$Z$1225,9,FALSE) -> -12.752033
A15: 39083 | B15: 39083 | C15: =VLOOKUP(C$2&$A15,'Raw'!$A$2:$Z$1225,9,FALSE) -> -2.813172 | D15: =VLOOKUP(D$2&$A15,'Raw'!$A$2:$Z$1225,9,FALSE) -> -3.296691 | E15: =VLOOKUP(E$2&$A15,'Raw'!$A$2:$Z$1225,9,FALSE) -> -11.62028 | F15: =VLOOKUP(F$2&$A15,'Raw'!$A$2:$Z$1225,9,FALSE) -> -12.871944 | G15: =VLOOKUP(G$2&$A15,'Raw'!$A$2:$Z$1225,9,FALSE) -> -2.8340397 | H15: =VLOOKUP(H$2&$A15,'Raw'!$A$2:$Z$1225,9,FALSE) -> -3.3820412 | I15: =VLOOKUP(I$2&$A15,'Raw'!$A$2:$Z$1225,9,FALSE) -> -11.349978 | J15: =VLOOKUP(J$2&$A15,'Raw'!$A$2:$Z$1225,9,FALSE) -> -12.891956 | ... Z15: =VLOOKUP(Z$2&$A15,'Raw'!$A$2:$Z$1225,9,FALSE) -> -13.038095
A16: 39448 | B16: 39448 | C16: =VLOOKUP(C$2&$A16,'Raw'!$A$2:$Z$1225,9,FALSE) -> -2.8068016 | D16: =VLOOKUP(D$2&$A16,'Raw'!$A$2:$Z$1225,9,FALSE) -> -3.3339572 | E16: =VLOOKUP(E$2&$A16,'Raw'!$A$2:$Z$1225,9,FALSE) -> -11.484108 | F16: =VLOOKUP(F$2&$A16,'Raw'!$A$2:$Z$1225,9,FALSE) -> -12.988695 | G16: =VLOOKUP(G$2&$A16,'Raw'!$A$2:$Z$1225,9,FALSE) -> -2.8300433 | H16: =VLOOKUP(H$2&$A16,'Raw'!$A$2:$Z$1225,9,FALSE) -> -3.4425311 | I16: =VLOOKUP(I$2&$A16,'Raw'!$A$2:$Z$1225,9,FALSE) -> -11.168377 | J16: =VLOOKUP(J$2&$A16,'Raw'!$A$2:$Z$1225,9,FALSE) -> -13.108598 | ... Z16: =VLOOKUP(Z$2&$A16,'Raw'!$A$2:$Z$1225,9,FALSE) -> -13.24858
A17: 39814 | B17: 39814 | C17: =VLOOKUP(C$2&$A17,'Raw'!$A$2:$Z$1225,9,FALSE) -> -2.783466 | D17: =VLOOKUP(D$2&$A17,'Raw'!$A$2:$Z$1225,9,FALSE) -> -3.3428495 | E17: =VLOOKUP(E$2&$A17,'Raw'!$A$2:$Z$1225,9,FALSE) -> -11.288732 | F17: =VLOOKUP(F$2&$A17,'Raw'!$A$2:$Z$1225,9,FALSE) -> -13.034274 | G17: =VLOOKUP(G$2&$A17,'Raw'!$A$2:$Z$1225,9,FALSE) -> -2.808141 | H17: =VLOOKUP(H$2&$A17,'Raw'!$A$2:$Z$1225,9,FALSE) -> -3.4715045 | I17: =VLOOKUP(I$2&$A17,'Raw'!$A$2:$Z$1225,9,FALSE) -> -10.935301 | J17: =VLOOKUP(J$2&$A17,'Raw'!$A$2:$Z$1225,9,FALSE) -> -13.285571 | ... Z17: =VLOOKUP(Z$2&$A17,'Raw'!$A$2:$Z$1225,9,FALSE) -> -13.413198
A18: 40179 | B18: 40179 | C18: =VLOOKUP(C$2&$A18,'Raw'!$A$2:$Z$1225,9,FALSE) -> -2.7490331 | D18: =VLOOKUP(D$2&$A18,'Raw'!$A$2:$Z$1225,9,FALSE) -> -3.329971 | E18: =VLOOKUP(E$2&$A18,'Raw'!$A$2:$Z$1225,9,FALSE) -> -11.061343 | F18: =VLOOKUP(F$2&$A18,'Raw'!$A$2:$Z$1225,9,FALSE) -> -13.027905 | G18: =VLOOKUP(G$2&$A18,'Raw'!$A$2:$Z$1225,9,FALSE) -> -2.7743723 | H18: =VLOOKUP(H$2&$A18,'Raw'!$A$2:$Z$1225,9,FALSE) -> -3.4726708 | I18: =VLOOKUP(I$2&$A18,'Raw'!$A$2:$Z$1225,9,FALSE) -> -10.67972 | J18: =VLOOKUP(J$2&$A18,'Raw'!$A$2:$Z$1225,9,FALSE) -> -13.434131 | ... Z18: =VLOOKUP(Z$2&$A18,'Raw'!$A$2:$Z$1225,9,FALSE) -> -13.545036
A19: 40544 | B19: 40544 | C19: =VLOOKUP(C$2&$A19,'Raw'!$A$2:$Z$1225,9,FALSE) -> -2.7075323 | D19: =VLOOKUP(D$2&$A19,'Raw'!$A$2:$Z$1225,9,FALSE) -> -3.3005478 | E19: =VLOOKUP(E$2&$A19,'Raw'!$A$2:$Z$1225,9,FALSE) -> -10.81928 | F19: =VLOOKUP(F$2&$A19,'Raw'!$A$2:$Z$1225,9,FALSE) -> -12.98112 | G19: =VLOOKUP(G$2&$A19,'Raw'!$A$2:$Z$1225,9,FALSE) -> -2.7331212 | H19: =VLOOKUP(H$2&$A19,'Raw'!$A$2:$Z$1225,9,FALSE) -> -3.4487952 | I19: =VLOOKUP(I$2&$A19,'Raw'!$A$2:$Z$1225,9,FALSE) -> -10.420196 | J19: =VLOOKUP(J$2&$A19,'Raw'!$A$2:$Z$1225,9,FALSE) -> -13.554722 | ... Z19: =VLOOKUP(Z$2&$A19,'Raw'!$A$2:$Z$1225,9,FALSE) -> -13.647601
... A58: 54789 | B58: 54789 | C58: =VLOOKUP(C$2&$A58,'Raw'!$A$2:$Z$1225,9,FALSE) -> -1.3557224 | D58: =VLOOKUP(D$2&$A58,'Raw'!$A$2:$Z$1225,9,FALSE) -> -1.6632798 | E58: =VLOOKUP(E$2&$A58,'Raw'!$A$2:$Z$1225,9,FALSE) -> -5.6019702 | F58: =VLOOKUP(F$2&$A58,'Raw'!$A$2:$Z$1225,9,FALSE) -> -6.3946058 | G58: =VLOOKUP(G$2&$A58,'Raw'!$A$2:$Z$1225,9,FALSE) -> -1.4217316 | H58: =VLOOKUP(H$2&$A58,'Raw'!$A$2:$Z$1225,9,FALSE) -> -1.5407785 | I58: =VLOOKUP(I$2&$A58,'Raw'!$A$2:$Z$1225,9,FALSE) -> -4.967916 | J58: =VLOOKUP(J$2&$A58,'Raw'!$A$2:$Z$1225,9,FALSE) -> -6.8334172 | ... Z58: =VLOOKUP(Z$2&$A58,'Raw'!$A$2:$Z$1225,9,FALSE) -> -6.9340098

Sheet Overview
A1: ASSUMPTIONS | F1: PIB | H1: Emploi (en milliers) | J1: Emissions | L1: Double dividende
A2: Model version | B2: Firm redistribution of the carbon tax | C2: Wage equation | D2: Flexibility of the economy | E2: Exposure to foreign competition | F2: Short run (10 years) | G2: Long run (50 years) | H2: Short run (10 years) | I2: Long run (50 years) | J2: Short run (10 years) | K2: Long run (50 years) | L2: Short run | M2: Long run
A3: Neo-keynesian | B3: Lump-sum REDIS_LS = 1 | C3: WS WAGE_EQ = 0 | D3: Low (0.2) FLEX = 0 | E3: 0.6 | F3: ='Raw'!G573 -> -0.0012550694 | G3: ='Raw'!G613 -> -0.0020839507 | H3: ='Raw'!H573 -> 40.34072 | I3: ='Raw'!H613 -> 13.52087 | J3: ='Raw'!I573 -> -2.7490331 | K3: ='Raw'!I613 -> -1.3557224 | L3: no | M3: no
E4: 2 | F4: ='Raw'!G522 -> -0.39843167 | G4: ='Raw'!G562 -> -0.17885163 | H4: ='Raw'!H522 -> -75.38742 | I4: ='Raw'!H562 -> -43.00319 | J4: ='Raw'!I522 -> -3.329971 | K4: ='Raw'!I562 -> -1.6632798 | L4: no | M4: no
D5: High (2) FLEX = 1 | E5: 0.6 | F5: ='Raw'!G471 -> 1.2058317 | G5: ='Raw'!G511 -> 0.39419209 | H5: ='Raw'!H471 -> 307.47118 | I5: ='Raw'!H511 -> 120.14003 | J5: ='Raw'!I471 -> -11.061343 | K5: ='Raw'!I511 -> -5.6019702 | L5: yes | M5: yes
E6: 2 | F6: ='Raw'!G420 -> 0.16304986 | G6: ='Raw'!G460 -> 0.22326131 | H6: ='Raw'!H420 -> 0.37843 | I6: ='Raw'!H460 -> 53.48757 | J6: ='Raw'!I420 -> -13.027905 | K6: ='Raw'!I460 -> -6.3946058 | L6: yes | M6: yes
C7: Philips constant NAIRU WAGE_EQ = 1 | D7: Low (0.2) FLEX = 0 | E7: 0.6 | F7: ='Raw'!G369 -> 0.0379475 | G7: ='Raw'!G409 -> -0.03460935 | H7: ='Raw'!H369 -> 55.61598 | I7: ='Raw'!H409 -> 1.96573 | J7: ='Raw'!I369 -> -2.7743723 | K7: ='Raw'!I409 -> -1.4217316 | L7: yes | M7: no
E8: 2 | F8: ='Raw'!G318 -> -0.48759968 | G8: ='Raw'!G358 -> -0.021464767 | H8: ='Raw'!H318 -> -102.29471 | I8: ='Raw'!H358 -> 29.6362 | J8: ='Raw'!I318 -> -3.4726708 | K8: ='Raw'!I358 -> -1.5407785 | L8: no | M8: no
D9: High (2) FLEX = 1 | E9: 0.6 | F9: ='Raw'!G267 -> 1.2479307 | G9: ='Raw'!G307 -> 0.25266444 | H9: ='Raw'!H267 -> 320.3488 | I9: ='Raw'!H307 -> -42.79675 | J9: ='Raw'!I267 -> -10.67972 | K9: ='Raw'!I307 -> -4.967916 | L9: yes | M9: yes
E10: 2 | F10: ='Raw'!G216 -> -0.16361932 | G10: ='Raw'!G256 -> 0.14381471 | H10: ='Raw'!H216 -> -96.91009 | I10: ='Raw'!H256 -> 11.57543 | J10: ='Raw'!I216 -> -13.434131 | K10: ='Raw'!I256 -> -6.8334172 | L10: no | M10: yes
C11: Time-varying NAIRU WAGE_EQ = 2 | D11: Low (0.2) FLEX = 0 | E11: 0.6 | F11: ='Raw'!G165 -> 0.027176619 | G11: ='Raw'!G205 -> -0.022368401 | H11: ='Raw'!H165 -> 55.85813 | I11: ='Raw'!H205 -> 26.02072 | J11: ='Raw'!I165 -> -2.811409 | K11: ='Raw'!I205 -> -1.4349851 | L11: yes | M11: no
E12: 2 | F12: ='Raw'!G114 -> -0.47020027 | G12: ='Raw'!G154 -> -0.074260872 | H12: ='Raw'!H114 -> -95.67223 | I12: ='Raw'!H154 -> 13.74355 | J12: ='Raw'!I114 -> -3.4573497 | K12: ='Raw'!I154 -> -1.5944864 | L12: no | M12: no
D13: High (2) FLEX = 1 | E13: 0.6 | F13: ='Raw'!G63 -> 1.2294836 | G13: ='Raw'!G103 -> 0.29266795 | H13: ='Raw'!H63 -> 323.70055 | I13: ='Raw'!H103 -> 12.77295 | J13: ='Raw'!I63 -> -10.925082 | K13: ='Raw'!I103 -> -5.2887635 | L13: yes | M13: yes
E14: 2 | F14: ='Raw'!G12 -> -0.085714113 | G14: ='Raw'!G52 -> 0.13820538 | H14: ='Raw'!H12 -> -68.61086 | I14: ='Raw'!H52 -> 31.57553 | J14: ='Raw'!I12 -> -13.386621 | K14: ='Raw'!I52 -> -6.7824838 | L14: no | M14: yes
B15: Reduction of the employers' social cotization tax rate REDIS_LS = 0 | C15: WS WAGE_EQ = 0 | D15: Low (0.2) FLEX = 0 | E15: 0.6 | F15: ='Raw'!G1185 -> -0.082343574 | G15: ='Raw'!G1225 -> -0.03564723 | H15: ='Raw'!H1185 -> 41.14203 | I15: ='Raw'!H1225 -> 13.90153 | J15: ='Raw'!I1185 -> -2.9782837 | K15: ='Raw'!I1225 -> -1.4672772 | L15: no | M15: no
E16: 2 | F16: ='Raw'!G1134 -> -0.46269456 | G16: ='Raw'!G1174 -> -0.22486339 | H16: ='Raw'!H1134 -> -70.18692 | I16: ='Raw'!H1174 -> -46.29786 | J16: ='Raw'!I1134 -> -3.5366615 | K16: ='Raw'!I1174 -> -1.788464 | L16: no | M16: no
D17: High (2) FLEX = 1 | E17: 0.6 | F17: ='Raw'!G1083 -> 1.1285047 | G17: ='Raw'!G1123 -> 0.36148764 | H17: ='Raw'!H1083 -> 306.79197 | I17: ='Raw'!H1123 -> 120.25275 | J17: ='Raw'!I1083 -> -11.246783 | K17: ='Raw'!I1123 -> -5.6805169 | L17: yes | M17: yes
E18: 2 | F18: ='Raw'!G1032 -> 0.10249085 | G18: ='Raw'!G1072 -> 0.17870841 | H18: ='Raw'!H1032 -> 3.97368 | I18: ='Raw'!H1072 -> 50.02928 | J18: ='Raw'!I1032 -> -13.181185 | K18: ='Raw'!I1072 -> -6.48916 | L18: yes | M18: yes
C19: Philips constant NAIRU WAGE_EQ = 1 | D19: Low (0.2) FLEX = 0 | E19: 0.6 | F19: ='Raw'!G981 -> -0.045193717 | G19: ='Raw'!G1021 -> -0.11369894 | H19: ='Raw'!H981 -> 61.51557 | I19: ='Raw'!H1021 -> -2.60144 | J19: ='Raw'!I981 -> -3.0249269 | K19: ='Raw'!I1021 -> -1.5945768 | L19: no | M19: no
E20: 2 | F20: ='Raw'!G930 -> -0.56879589 | G20: ='Raw'!G970 -> -0.086717533 | H20: ='Raw'!H930 -> -95.81974 | I20: ='Raw'!H970 -> 23.98734 | J20: ='Raw'!I930 -> -3.7117833 | K20: ='Raw'!I970 -> -1.70334 | L20: no | M20: no
D21: High (2) FLEX = 1 | E21: 0.6 | F21: ='Raw'!G879 -> 1.165763 | G21: ='Raw'!G919 -> 0.18530323 | H21: ='Raw'!H879 -> 321.96312 | I21: ='Raw'!H919 -> -46.50162 | J21: ='Raw'!I879 -> -10.851639 | K21: ='Raw'!I919 -> -5.0486637 | L21: yes | M21: yes
E22: 2 | F22: ='Raw'!G828 -> -0.23976288 | G22: ='Raw'!G868 -> 0.085491617 | H22: ='Raw'!H828 -> -93.30356 | I22: ='Raw'!H868 -> 8.54036 | J22: ='Raw'!I828 -> -13.595838 | K22: ='Raw'!I868 -> -6.9520832 | L22: no | M22: yes
C23: Time-varying NAIRU WAGE_EQ = 2 | D23: Low (0.2) FLEX = 0 | E23: 0.6 | F23: ='Raw'!G777 -> -0.057551167 | G23: ='Raw'!G817 -> -0.098861436 | H23: ='Raw'!H777 -> 61.85945 | I23: ='Raw'!H817 -> 38.397 | J23: ='Raw'!I777 -> -3.067837 | K23: ='Raw'!I817 -> -1.6373546 | L23: no | M23: no
E24: 2 | F24: ='Raw'!G726 -> -0.54218604 | G24: ='Raw'!G766 -> -0.15081669 | H24: ='Raw'!H726 -> -85.6334 | I24: ='Raw'!H766 -> 8.28863 | J24: ='Raw'!I726 -> -3.69029 | K24: ='Raw'!I766 -> -1.7777919 | L24: no | M24: no
D25: High (2) FLEX = 1 | E25: 0.6 | F25: ='Raw'!G675 -> 1.1468688 | G25: ='Raw'!G715 -> 0.22220074 | H25: ='Raw'!H675 -> 325.68781 | I25: ='Raw'!H715 -> 16.49786 | J25: ='Raw'!I675 -> -11.10637 | K25: ='Raw'!I715 -> -5.3739933 | L25: yes | M25: yes
E26: 2 | F26: ='Raw'!G624 -> -0.15368556 | G26: ='Raw'!G664 -> 0.064385249 | H26: ='Raw'!H624 -> -61.80414 | I26: ='Raw'!H664 -> 27.00479 | J26: ='Raw'!I624 -> -13.545036 | K26: ='Raw'!I664 -> -6.9340098 | L26: no | M26: yes

Sheet Paper charts
A1: Table 1: Overview the existence of a short-term double dividend depending on various model settings
A2: Firm redistribution of the carbon tax | C2: Lump-sum REDIS_LS = 1 | F2: Reduction of the employers' social cotization tax rate REDIS_LS = 0
A3: Wage equation | C3: WS WAGE_EQ = 0 | D3: Philips constant NAIRU WAGE_EQ = 1 | E3: Time-varying NAIRU WAGE_EQ = 2 | F3: WS WAGE_EQ = 0 | G3: Philips constant NAIRU WAGE_EQ = 1 | H3: Time-varying NAIRU WAGE_EQ = 2
A5: Flexibility of the economy | B5: Exposure to foreign competition
A6: Low (0.2) FLEX = 0 | B6: Low (0.6) | C6: =Overview!L3 -> no | D6: =Overview!L7 -> yes | E6: =Overview!L11 -> yes | F6: =Overview!L15 -> no | G6: =Overview!L19 -> no | H6: =Overview!L23 -> no
B7: High (2) | C7: =Overview!L4 -> no | D7: =Overview!L8 -> no | E7: =Overview!L12 -> no | F7: =Overview!L16 -> no | G7: =Overview!L20 -> no | H7: =Overview!L24 -> no
A8: High (2) FLEX = 1 | B8: Low (0.6) | C8: =Overview!L5 -> yes | D8: =Overview!L9 -> yes | E8: =Overview!L13 -> yes | F8: =Overview!L17 -> yes | G8: =Overview!L21 -> yes | H8: =Overview!L25 -> yes
B9: High (2) | C9: =Overview!L6 -> yes | D9: =Overview!L10 -> no | E9: =Overview!L14 -> no | F9: =Overview!L18 -> yes | G9: =Overview!L22 -> no | H9: =Overview!L26 -> no
A12: Table 2: Overview of the CO2 emissions deviation from baseline scenario fifty years after the introduction of a carbon tax
A13: Firm redistribution of the carbon tax | C13: Lump-sum REDIS_LS = 1 | F13: Reduction of the employers' social cotization tax rate REDIS_LS = 0
A14: Wage equation | C14: WS WAGE_EQ = 0 | D14: Philips constant NAIRU WAGE_EQ = 1 | E14: Time-varying NAIRU WAGE_EQ = 2 | F14: WS WAGE_EQ = 0 | G14: Philips constant NAIRU WAGE_EQ = 1 | H14: Time-varying NAIRU WAGE_EQ = 2
A16: Flexibility of the economy | B16: Exposure to foreign competition
A17: Low (0.2) FLEX = 0 | B17: Low (0.6) | C17: =Table_Dynam_EMS!C58 -> -1.3557224 | D17: =Table_Dynam_EMS!G58 -> -1.4217316 | E17: =Table_Dynam_EMS!K58 -> -1.4349851 | F17: =Table_Dynam_EMS!O58 -> -1.4672772 | G17: =Table_Dynam_EMS!S58 -> -1.5945768 | H17: =Table_Dynam_EMS!W58 -> -1.6373546
B18: High (2) | C18: =Table_Dynam_EMS!D58 -> -1.6632798 | D18: =Table_Dynam_EMS!H58 -> -1.5407785 | E18: =Table_Dynam_EMS!L58 -> -1.5944864 | F18: =Table_Dynam_EMS!P58 -> -1.788464 | G18: =Table_Dynam_EMS!T58 -> -1.70334 | H18: =Table_Dynam_EMS!X58 -> -1.7777919
A19: High (2) FLEX = 1 | B19: Low (0.6) | C19: =Table_Dynam_EMS!E58 -> -5.6019702 | D19: =Table_Dynam_EMS!I58 -> -4.967916 | E19: =Table_Dynam_EMS!M58 -> -5.2887635 | F19: =Table_Dynam_EMS!Q58 -> -5.6805169 | G19: =Table_Dynam_EMS!U58 -> -5.0486637 | H19: =Table_Dynam_EMS!Y58 -> -5.3739933
B20: High (2) | C20: =Table_Dynam_EMS!F58 -> -6.3946058 | D20: =Table_Dynam_EMS!J58 -> -6.8334172 | E20: =Table_Dynam_EMS!N58 -> -6.7824838 | F20: =Table_Dynam_EMS!R58 -> -6.48916 | G20: =Table_Dynam_EMS!V58 -> -6.9520832 | H20: =Table_Dynam_EMS!Z58 -> -6.9340098
A23: Table 3: Spread of GDP deviations from baseline for the factor of exposure to foreign competition
A24: Firm redistribution of the carbon tax | C24: Lump-sum REDIS_LS = 1 | F24: Reduction of the employers' social cotization tax rate REDIS_LS = 0
A25: Wage equation | C25: WS WAGE_EQ = 0 | D25: Philips constant NAIRU WAGE_EQ = 1 | E25: Time-varying NAIRU WAGE_EQ = 2 | F25: WS WAGE_EQ = 0 | G25: Philips constant NAIRU WAGE_EQ = 1 | H25: Time-varying NAIRU WAGE_EQ = 2
A27: Flexibility of the economy | C27: Low exp. - High exp. | D27: Low exp. - High exp. | E27: Low exp. - High exp. | F27: Low exp. - High exp. | G27: Low exp. - High exp. | H27: Low exp. - High exp.
A28: Low (0.2) FLEX = 0 | C28: =C46-C47 -> 0.3971766 | D28: =D46-D47 -> 0.52554718 | E28: =E46-E47 -> 0.49737688 | F28: =F46-F47 -> 0.38035099 | G28: =G46-G47 -> 0.52360217 | H28: =H46-H47 -> 0.48463487
A29: High (2) FLEX = 1 | C29: =C48-C49 -> 1.0427818 | D29: =D48-D49 -> 1.41155 | E29: =E48-E49 -> 1.3151977 | F29: =F48-F49 -> 1.0260138 | G29: =G48-G49 -> 1.4055258 | H29: =H48-H49 -> 1.3005544
A32: Table 4: Spread of GDP deviations from baseline for the factor of flexibility of the economy
A33: Firm redistribution of the carbon tax | C33: Lump-sum REDIS_LS = 1 | F33: Reduction of the employers' social cotization tax rate REDIS_LS = 0
A34: Wage equation | C34: WS WAGE_EQ = 0 | D34: Philips constant NAIRU WAGE_EQ = 1 | E34: Time-varying NAIRU WAGE_EQ = 2 | F34: WS WAGE_EQ = 0 | G34: Philips constant NAIRU WAGE_EQ = 1 | H34: Time-varying NAIRU WAGE_EQ = 2
A36: Exposure to foreign competition | C36: High com. - low com. | D36: High com. - low com. | E36: High com. - low com. | F36: High com. - low com. | G36: High com. - low com. | H36: High com. - low com.
A37: Low (0.6) | C37: =C48-C46 -> 1.2070868 | D37: =D48-D46 -> 1.2099832 | E37: =E48-E46 -> 1.2023069 | F37: =F48-F46 -> 1.2108483 | G37: =G48-G46 -> 1.2109567 | H37: =H48-H46 -> 1.20442
A38: High (2) | C38: =C49-C47 -> 0.56148153 | D38: =D49-D47 -> 0.32398036 | E38: =E49-E47 -> 0.38448615 | F38: =F49-F47 -> 0.56518541 | G38: =G49-G47 -> 0.32903301 | H38: =H49-H47 -> 0.38850048
A41: Table 5: Overview of the GDP (in volume) deviation from baseline scenario 10 years after the introduction of a carbon tax
A42: Firm redistribution of the carbon tax | C42: Lump-sum REDIS_LS = 1 | F42: Reduction of the employers' social cotization tax rate REDIS_LS = 0 | K42: Lump-sum Social security contributions
A43: Wage equation | C43: WS WAGE_EQ = 0 | D43: Philips constant NAIRU WAGE_EQ = 1 | E43: Time-varying NAIRU WAGE_EQ = 2 | F43: WS WAGE_EQ = 0 | G43: Philips constant NAIRU WAGE_EQ = 1 | H43: Time-varying NAIRU WAGE_EQ = 2 | K43: Wage-Setting Constant NAIRU TV NAIRU Wage-Setting Constant NAIRU TV NAIRU
K44: Low flexibility 0.35 0.47 0.45 0.50 0.57 0.55
A45: Flexibility of the economy | B45: Exposure to foreign competition | K45: High flexibility 0.95 1.29 1.20 0.94 1.28 1.18
A46: Low (0.2) FLEX = 0 | B46: Low (0.6) | C46: =Table_Dynam_GDP!C18 -> -0.0012550694 | D46: =Table_Dynam_GDP!G18 -> 0.0379475 | E46: =Table_Dynam_GDP!K18 -> 0.027176619 | F46: =Table_Dynam_GDP!O18 -> -0.082343574 | G46: =Table_Dynam_GDP!S18 -> -0.045193717 | H46: =Table_Dynam_GDP!W18 -> -0.057551167
B47: High (2) | C47: =Table_Dynam_GDP!D18 -> -0.39843167 | D47: =Table_Dynam_GDP!H18 -> -0.48759968 | E47: =Table_Dynam_GDP!L18 -> -0.47020027 | F47: =Table_Dynam_GDP!P18 -> -0.46269456 | G47: =Table_Dynam_GDP!T18 -> -0.56879589 | H47: =Table_Dynam_GDP!X18 -> -0.54218604 | K47: =-0.01--0.36 -> 0.35
A48: High (2) FLEX = 1 | B48: Low (0.6) | C48: =Table_Dynam_GDP!E18 -> 1.2058317 | D48: =Table_Dynam_GDP!I18 -> 1.2479307 | E48: =Table_Dynam_GDP!M18 -> 1.2294836 | F48: =Table_Dynam_GDP!Q18 -> 1.1285047 | G48: =Table_Dynam_GDP!U18 -> 1.165763 | H48: =Table_Dynam_GDP!Y18 -> 1.1468688 | K48: =1.07-0.12 -> 0.95
B49: High (2) | C49: =Table_Dynam_GDP!F18 -> 0.16304986 | D49: =Table_Dynam_GDP!J18 -> -0.16361932 | E49: =Table_Dynam_GDP!N18 -> -0.085714113 | F49: =Table_Dynam_GDP!R18 -> 0.10249085 | G49: =Table_Dynam_GDP!V18 -> -0.23976288 | H49: =Table_Dynam_GDP!Z18 -> -0.15368556
A52: Table 6: Overview the existence of a long-term dividend depending on various model settings
A53: Firm redistribution of the carbon tax | C53: Lump-sum REDIS_LS = 1 | F53: Reduction of the employers' social cotization tax rate REDIS_LS = 0
A54: Wage equation | C54: WS WAGE_EQ = 0 | D54: Philips constant NAIRU WAGE_EQ = 1 | E54: Time-varying NAIRU WAGE_EQ = 2 | F54: WS WAGE_EQ = 0 | G54: Philips constant NAIRU WAGE_EQ = 1 | H54: Time-varying NAIRU WAGE_EQ = 2
...

Sheet Explorer
B2: OVERVIEW
B4: Output variable | D4: Salaire nominal brut | E4: =VLOOKUP(D4,Lists!A1:B20,2,FALSE) -> 100*(w_1/w_0-1)
B6: Firm redistribution | D6: Lump-sum | E6: =VLOOKUP(D6,Lists!C1:D2,2,FALSE) -> 1
B7: Wage equation | D7: Wage setting | E7: =VLOOKUP(D7,Lists!E1:F3,2,FALSE) -> 0
B8: Flexibility | D8: High | E8: =VLOOKUP(D8,Lists!G1:H2,2,FALSE) -> 1
B9: Exposure to foreign competition | D9: High | E9: =VLOOKUP(D9,Lists!I1:J2,2,FALSE) -> 1
B13: 2000 | C13: =INDEX('Raw'!$1:$1048576,MATCH($B13&"."&$E$6&"."&$E$7&"."&$E$8&"."&$E$9,index!$A:$A,0),MATCH(Explorer!$E$4,'Raw'!$1:$1,0)) -> 0
B14: 2001 | C14: =INDEX('Raw'!$1:$1048576,MATCH($B14&"."&$E$6&"."&$E$7&"."&$E$8&"."&$E$9,index!$A:$A,0),MATCH(Explorer!$E$4,'Raw'!$1:$1,0)) -> 0.027108494
B15: 2002 | C15: =INDEX('Raw'!$1:$1048576,MATCH($B15&"."&$E$6&"."&$E$7&"."&$E$8&"."&$E$9,index!$A:$A,0),MATCH(Explorer!$E$4,'Raw'!$1:$1,0)) -> 0.20298216
B16: 2003 | C16: =INDEX('Raw'!$1:$1048576,MATCH($B16&"."&$E$6&"."&$E$7&"."&$E$8&"."&$E$9,index!$A:$A,0),MATCH(Explorer!$E$4,'Raw'!$1:$1,0)) -> 0.41806224
B17: 2004 | C17: =INDEX('Raw'!$1:$1048576,MATCH($B17&"."&$E$6&"."&$E$7&"."&$E$8&"."&$E$9,index!$A:$A,0),MATCH(Explorer!$E$4,'Raw'!$1:$1,0)) -> 0.64675163
B18: 2005 | C18: =INDEX('Raw'!$1:$1048576,MATCH($B18&"."&$E$6&"."&$E$7&"."&$E$8&"."&$E$9,index!$A:$A,0),MATCH(Explorer!$E$4,'Raw'!$1:$1,0)) -> 0.87844359
B19: 2006 | C19: =INDEX('Raw'!$1:$1048576,MATCH($B19&"."&$E$6&"."&$E$7&"."&$E$8&"."&$E$9,index!$A:$A,0),MATCH(Explorer!$E$4,'Raw'!$1:$1,0)) -> 1.1029259
B20: 2007 | C20: =INDEX('Raw'!$1:$1048576,MATCH($B20&"."&$E$6&"."&$E$7&"."&$E$8&"."&$E$9,index!$A:$A,0),MATCH(Explorer!$E$4,'Raw'!$1:$1,0)) -> 1.3102441
B21: 2008 | C21: =INDEX('Raw'!$1:$1048576,MATCH($B21&"."&$E$6&"."&$E$7&"."&$E$8&"."&$E$9,index!$A:$A,0),MATCH(Explorer!$E$4,'Raw'!$1:$1,0)) -> 1.4926091
B22: 2009 | C22: =INDEX('Raw'!$1:$1048576,MATCH($B22&"."&$E$6&"."&$E$7&"."&$E$8&"."&$E$9,index!$A:$A,0),MATCH(Explorer!$E$4,'Raw'!$1:$1,0)) -> 1.645373
B23: 2010 | C23: =INDEX('Raw'!$1:$1048576,MATCH($B23&"."&$E$6&"."&$E$7&"."&$E$8&"."&$E$9,index!$A:$A,0),MATCH(Explorer!$E$4,'Raw'!$1:$1,0)) -> 1.7669581
B24: 2011 | C24: =INDEX('Raw'!$1:$1048576,MATCH($B24&"."&$E$6&"."&$E$7&"."&$E$8&"."&$E$9,index!$A:$A,0),MATCH(Explorer!$E$4,'Raw'!$1:$1,0)) -> 1.8582198
... B63: 2050 | C63: =INDEX('Raw'!$1:$1048576,MATCH($B63&"."&$E$6&"."&$E$7&"."&$E$8&"."&$E$9,index!$A:$A,0),MATCH(Explorer!$E$4,'Raw'!$1:$1,0)) -> 0.76524837

Sheet Redistribution
B2: FIRM REDISTRIBUTION
B4: Output variable | D4: Investissement | F4: =VLOOKUP(D4,Lists!A1:B20,2,FALSE) -> 100*(i_1/i_0-1)
B6: Wage equation | D6: Constant NAIRU | F6: =VLOOKUP(D6,Lists!E1:F3,2,FALSE) -> 1
B7: Flexibility | D7: Low | F7: =VLOOKUP(D7,Lists!G1:H2,2,FALSE) -> 0
B8: Exposure to foreign competition | D8: Low
F9: =VLOOKUP(D8,Lists!I1:J2,2,FALSE) -> 0
B30: Firm redistribution | D30: Employers' social security contributions | E30: Lump-sum transfer
B31: Year | D31: 0 | E31: 1
B32: 2000 | D32: =INDEX('Raw'!$1:$1048576,MATCH($B32&"."&D$31&"."&$F$6&"."&$F$7&"."&$F$9,index!$A:$A,0),MATCH($F$4,'Raw'!$1:$1,0)) -> 0 | E32: =INDEX('Raw'!$1:$1048576,MATCH($B32&"."&E$31&"."&$F$6&"."&$F$7&"."&$F$9,index!$A:$A,0),MATCH($F$4,'Raw'!$1:$1,0)) -> 0 | F32: 0
B33: 2001 | D33: =INDEX('Raw'!$1:$1048576,MATCH($B33&"."&D$31&"."&$F$6&"."&$F$7&"."&$F$9,index!$A:$A,0),MATCH($F$4,'Raw'!$1:$1,0)) -> -0.23157975 | E33: =INDEX('Raw'!$1:$1048576,MATCH($B33&"."&E$31&"."&$F$6&"."&$F$7&"."&$F$9,index!$A:$A,0),MATCH($F$4,'Raw'!$1:$1,0)) -> -0.16013591 | F33: 1
B34: 2002 | D34: =INDEX('Raw'!$1:$1048576,MATCH($B34&"."&D$31&"."&$F$6&"."&$F$7&"."&$F$9,index!$A:$A,0),MATCH($F$4,'Raw'!$1:$1,0)) -> -0.43135215 | E34: =INDEX('Raw'!$1:$1048576,MATCH($B34&"."&E$31&"."&$F$6&"."&$F$7&"."&$F$9,index!$A:$A,0),MATCH($F$4,'Raw'!$1:$1,0)) -> -0.29345599 | F34: 2
B35: 2003 | D35: =INDEX('Raw'!$1:$1048576,MATCH($B35&"."&D$31&"."&$F$6&"."&$F$7&"."&$F$9,index!$A:$A,0),MATCH($F$4,'Raw'!$1:$1,0)) -> -0.59088652 | E35: =INDEX('Raw'!$1:$1048576,MATCH($B35&"."&E$31&"."&$F$6&"."&$F$7&"."&$F$9,index!$A:$A,0),MATCH($F$4,'Raw'!$1:$1,0)) -> -0.39350667 | F35: 3
B36: 2004 | D36: =INDEX('Raw'!$1:$1048576,MATCH($B36&"."&D$31&"."&$F$6&"."&$F$7&"."&$F$9,index!$A:$A,0),MATCH($F$4,'Raw'!$1:$1,0)) -> -0.71977973 | E36: =INDEX('Raw'!$1:$1048576,MATCH($B36&"."&E$31&"."&$F$6&"."&$F$7&"."&$F$9,index!$A:$A,0),MATCH($F$4,'Raw'!$1:$1,0)) -> -0.46897991 | F36: 4
B37: 2005 | D37: =INDEX('Raw'!$1:$1048576,MATCH($B37&"."&D$31&"."&$F$6&"."&$F$7&"."&$F$9,index!$A:$A,0),MATCH($F$4,'Raw'!$1:$1,0)) -> -0.82798199 | E37: =INDEX('Raw'!$1:$1048576,MATCH($B37&"."&E$31&"."&$F$6&"."&$F$7&"."&$F$9,index!$A:$A,0),MATCH($F$4,'Raw'!$1:$1,0)) -> -0.52837182 | F37: 5
B38: 2006 | D38: =INDEX('Raw'!$1:$1048576,MATCH($B38&"."&D$31&"."&$F$6&"."&$F$7&"."&$F$9,index!$A:$A,0),MATCH($F$4,'Raw'!$1:$1,0)) -> -0.921134 | E38: =INDEX('Raw'!$1:$1048576,MATCH($B38&"."&E$31&"."&$F$6&"."&$F$7&"."&$F$9,index!$A:$A,0),MATCH($F$4,'Raw'!$1:$1,0)) -> -0.57619978 | F38: 6
B39: 2007 | D39: =INDEX('Raw'!$1:$1048576,MATCH($B39&"."&D$31&"."&$F$6&"."&$F$7&"."&$F$9,index!$A:$A,0),MATCH($F$4,'Raw'!$1:$1,0)) -> -1.001364 | E39: =INDEX('Raw'!$1:$1048576,MATCH($B39&"."&E$31&"."&$F$6&"."&$F$7&"."&$F$9,index!$A:$A,0),MATCH($F$4,'Raw'!$1:$1,0)) -> -0.61394895 | F39: 7
B40: 2008 | D40: =INDEX('Raw'!$1:$1048576,MATCH($B40&"."&D$31&"."&$F$6&"."&$F$7&"."&$F$9,index!$A:$A,0),MATCH($F$4,'Raw'!$1:$1,0)) -> -1.0691209 | E40: =INDEX('Raw'!$1:$1048576,MATCH($B40&"."&E$31&"."&$F$6&"."&$F$7&"."&$F$9,index!$A:$A,0),MATCH($F$4,'Raw'!$1:$1,0)) -> -0.64178776 | F40: 8
B41: 2009 | D41: =INDEX('Raw'!$1:$1048576,MATCH($B41&"."&D$31&"."&$F$6&"."&$F$7&"."&$F$9,index!$A:$A,0),MATCH($F$4,'Raw'!$1:$1,0)) -> -1.1245274 | E41: =INDEX('Raw'!$1:$1048576,MATCH($B41&"."&E$31&"."&$F$6&"."&$F$7&"."&$F$9,index!$A:$A,0),MATCH($F$4,'Raw'!$1:$1,0)) -> -0.65975476 | F41: 9
B42: 2010 | D42: =INDEX('Raw'!$1:$1048576,MATCH($B42&"."&D$31&"."&$F$6&"."&$F$7&"."&$F$9,index!$A:$A,0),MATCH($F$4,'Raw'!$1:$1,0)) -> -1.168046 | E42: =INDEX('Raw'!$1:$1048576,MATCH($B42&"."&E$31&"."&$F$6&"."&$F$7&"."&$F$9,index!$A:$A,0),MATCH($F$4,'Raw'!$1:$1,0)) -> -0.66829493 | F42: 10
B43: 2011 | D43: =INDEX('Raw'!$1:$1048576,MATCH($B43&"."&D$31&"."&$F$6&"."&$F$7&"."&$F$9,index!$A:$A,0),MATCH($F$4,'Raw'!$1:$1,0)) -> -1.2006486 | E43: =INDEX('Raw'!$1:$1048576,MATCH($B43&"."&E$31&"."&$F$6&"."&$F$7&"."&$F$9,index!$A:$A,0),MATCH($F$4,'Raw'!$1:$1,0)) -> -0.6683544 | F43: 11
... B82: 2050 | D82: =INDEX('Raw'!$1:$1048576,MATCH($B82&"."&D$31&"."&$F$6&"."&$F$7&"."&$F$9,index!$A:$A,0),MATCH($F$4,'Raw'!$1:$1,0)) -> -0.61524525 | E82: =INDEX('Raw'!$1:$1048576,MATCH($B82&"."&E$31&"."&$F$6&"."&$F$7&"."&$F$9,index!$A:$A,0),MATCH($F$4,'Raw'!$1:$1,0)) -> -0.098277711 | F82: 50

Sheet Wage equation
B2: WAGE EQUATION MODELIZATION
B4: Output variable | D4: GDP in volume | G4: =VLOOKUP(D4,Lists!A1:B20,2,FALSE) -> 100*(gdp_1/gdp_0-1)
B6: Firm redistribution | D6: Lump-sum | G6: =VLOOKUP(D6,Lists!C1:D2,2,FALSE) -> 1
B7: Flexibility | D7: High | G7: =VLOOKUP(D7,Lists!G1:H2,2,FALSE) -> 1
B8: Exposure to foreign competition | D8: High | G8: =VLOOKUP(D8,Lists!I1:J2,2,FALSE) -> 1
B30: Wage equation | D30: Wage-Setting | E30: Constant NAIRU | F30: Time-varying NAIRU
B31: Year | D31: 0 | E31: 1 | F31: 2
B32: 2000 | D32: =INDEX('Raw'!$1:$1048576,MATCH($B32&"."&$G$6&"."&D$31&"."&$G$7&"."&$G$8,index!$A:$A,0),MATCH($G$4,'Raw'!$1:$1,0)) -> 0 | E32: =INDEX('Raw'!$1:$1048576,MATCH($B32&"."&$G$6&"."&E$31&"."&$G$7&"."&$G$8,index!$A:$A,0),MATCH($G$4,'Raw'!$1:$1,0)) -> 0 | F32: =INDEX('Raw'!$1:$1048576,MATCH($B32&"."&$G$6&"."&F$31&"."&$G$7&"."&$G$8,index!$A:$A,0),MATCH($G$4,'Raw'!$1:$1,0)) -> 0
B33: 2001 | D33: =INDEX('Raw'!$1:$1048576,MATCH($B33&"."&$G$6&"."&D$31&"."&$G$7&"."&$G$8,index!$A:$A,0),MATCH($G$4,'Raw'!$1:$1,0)) -> 0.21895396 | E33: =INDEX('Raw'!$1:$1048576,MATCH($B33&"."&$G$6&"."&E$31&"."&$G$7&"."&$G$8,index!$A:$A,0),MATCH($G$4,'Raw'!$1:$1,0)) -> 0.2194539 | F33: =INDEX('Raw'!$1:$1048576,MATCH($B33&"."&$G$6&"."&F$31&"."&$G$7&"."&$G$8,index!$A:$A,0),MATCH($G$4,'Raw'!$1:$1,0)) -> 0.2191321
B34: 2002 | D34: =INDEX('Raw'!$1:$1048576,MATCH($B34&"."&$G$6&"."&D$31&"."&$G$7&"."&$G$8,index!$A:$A,0),MATCH($G$4,'Raw'!$1:$1,0)) -> 0.38987568 | E34: =INDEX('Raw'!$1:$1048576,MATCH($B34&"."&$G$6&"."&E$31&"."&$G$7&"."&$G$8,index!$A:$A,0),MATCH($G$4,'Raw'!$1:$1,0)) -> 0.38919889 | F34: =INDEX('Raw'!$1:$1048576,MATCH($B34&"."&$G$6&"."&F$31&"."&$G$7&"."&$G$8,index!$A:$A,0),MATCH($G$4,'Raw'!$1:$1,0)) -> 0.38850495
B35: 2003 | D35: =INDEX('Raw'!$1:$1048576,MATCH($B35&"."&$G$6&"."&D$31&"."&$G$7&"."&$G$8,index!$A:$A,0),MATCH($G$4,'Raw'!$1:$1,0)) -> 0.48419046 | E35: =INDEX('Raw'!$1:$1048576,MATCH($B35&"."&$G$6&"."&E$31&"."&$G$7&"."&$G$8,index!$A:$A,0),MATCH($G$4,'Raw'!$1:$1,0)) -> 0.47730126 | F35: =INDEX('Raw'!$1:$1048576,MATCH($B35&"."&$G$6&"."&F$31&"."&$G$7&"."&$G$8,index!$A:$A,0),MATCH($G$4,'Raw'!$1:$1,0)) -> 0.47718577
B36: 2004 | D36: =INDEX('Raw'!$1:$1048576,MATCH($B36&"."&$G$6&"."&D$31&"."&$G$7&"."&$G$8,index!$A:$A,0),MATCH($G$4,'Raw'!$1:$1,0)) -> 0.51029402 | E36: =INDEX('Raw'!$1:$1048576,MATCH($B36&"."&$G$6&"."&E$31&"."&$G$7&"."&$G$8,index!$A:$A,0),MATCH($G$4,'Raw'!$1:$1,0)) -> 0.48857956 | F36: =INDEX('Raw'!$1:$1048576,MATCH($B36&"."&$G$6&"."&F$31&"."&$G$7&"."&$G$8,index!$A:$A,0),MATCH($G$4,'Raw'!$1:$1,0)) -> 0.49131181
B37: 2005 | D37: =INDEX('Raw'!$1:$1048576,MATCH($B37&"."&$G$6&"."&D$31&"."&$G$7&"."&$G$8,index!$A:$A,0),MATCH($G$4,'Raw'!$1:$1,0)) -> 0.48686757 | E37: =INDEX('Raw'!$1:$1048576,MATCH($B37&"."&$G$6&"."&E$31&"."&$G$7&"."&$G$8,index!$A:$A,0),MATCH($G$4,'Raw'!$1:$1,0)) -> 0.43889934 | F37: =INDEX('Raw'!$1:$1048576,MATCH($B37&"."&$G$6&"."&F$31&"."&$G$7&"."&$G$8,index!$A:$A,0),MATCH($G$4,'Raw'!$1:$1,0)) -> 0.44784291
B38: 2006 | D38: =INDEX('Raw'!$1:$1048576,MATCH($B38&"."&$G$6&"."&D$31&"."&$G$7&"."&$G$8,index!$A:$A,0),MATCH($G$4,'Raw'!$1:$1,0)) -> 0.43298585 | E38: =INDEX('Raw'!$1:$1048576,MATCH($B38&"."&$G$6&"."&E$31&"."&$G$7&"."&$G$8,index!$A:$A,0),MATCH($G$4,'Raw'!$1:$1,0)) -> 0.3460622 | F38: =INDEX('Raw'!$1:$1048576,MATCH($B38&"."&$G$6&"."&F$31&"."&$G$7&"."&$G$8,index!$A:$A,0),MATCH($G$4,'Raw'!$1:$1,0)) -> 0.36503783
B39: 2007 | D39: =INDEX('Raw'!$1:$1048576,MATCH($B39&"."&$G$6&"."&D$31&"."&$G$7&"."&$G$8,index!$A:$A,0),MATCH($G$4,'Raw'!$1:$1,0)) -> 0.36420726 | E39: =INDEX('Raw'!$1:$1048576,MATCH($B39&"."&$G$6&"."&E$31&"."&$G$7&"."&$G$8,index!$A:$A,0),MATCH($G$4,'Raw'!$1:$1,0)) -> 0.22632896 | F39: =INDEX('Raw'!$1:$1048576,MATCH($B39&"."&$G$6&"."&F$31&"."&$G$7&"."&$G$8,index!$A:$A,0),MATCH($G$4,'Raw'!$1:$1,0)) -> 0.25877544
B40: 2008 | D40: =INDEX('Raw'!$1:$1048576,MATCH($B40&"."&$G$6&"."&D$31&"."&$G$7&"."&$G$8,index!$A:$A,0),MATCH($G$4,'Raw'!$1:$1,0)) -> 0.29178901 | E40: =INDEX('Raw'!$1:$1048576,MATCH($B40&"."&$G$6&"."&E$31&"."&$G$7&"."&$G$8,index!$A:$A,0),MATCH($G$4,'Raw'!$1:$1,0)) -> 0.09370955 | F40: =INDEX('Raw'!$1:$1048576,MATCH($B40&"."&$G$6&"."&F$31&"."&$G$7&"."&$G$8,index!$A:$A,0),MATCH($G$4,'Raw'!$1:$1,0)) -> 0.14183679
B41: 2009 | D41: =INDEX('Raw'!$1:$1048576,MATCH($B41&"."&$G$6&"."&D$31&"."&$G$7&"."&$G$8,index!$A:$A,0),MATCH($G$4,'Raw'!$1:$1,0)) -> 0.22321561 | E41: =INDEX('Raw'!$1:$1048576,MATCH($B41&"."&$G$6&"."&E$31&"."&$G$7&"."&$G$8,index!$A:$A,0),MATCH($G$4,'Raw'!$1:$1,0)) -> -0.03975143 | F41: =INDEX('Raw'!$1:$1048576,MATCH($B41&"."&$G$6&"."&F$31&"."&$G$7&"."&$G$8,index!$A:$A,0),MATCH($G$4,'Raw'!$1:$1,0)) -> 0.024330124
B42: 2010 | D42: =INDEX('Raw'!$1:$1048576,MATCH($B42&"."&$G$6&"."&D$31&"."&$G$7&"."&$G$8,index!$A:$A,0),MATCH($G$4,'Raw'!$1:$1,0)) -> 0.16304986 | E42: =INDEX('Raw'!$1:$1048576,MATCH($B42&"."&$G$6&"."&E$31&"."&$G$7&"."&$G$8,index!$A:$A,0),MATCH($G$4,'Raw'!$1:$1,0)) -> -0.16361932 | F42: =INDEX('Raw'!$1:$1048576,MATCH($B42&"."&$G$6&"."&F$31&"."&$G$7&"."&$G$8,index!$A:$A,0),MATCH($G$4,'Raw'!$1:$1,0)) -> -0.085714113
B43: 2011 | D43: =INDEX('Raw'!$1:$1048576,MATCH($B43&"."&$G$6&"."&D$31&"."&$G$7&"."&$G$8,index!$A:$A,0),MATCH($G$4,'Raw'!$1:$1,0)) -> 0.11371069 | E43: =INDEX('Raw'!$1:$1048576,MATCH($B43&"."&$G$6&"."&E$31&"."&$G$7&"."&$G$8,index!$A:$A,0),MATCH($G$4,'Raw'!$1:$1,0)) -> -0.26896422 | F43: =INDEX('Raw'!$1:$1048576,MATCH($B43&"."&$G$6&"."&F$31&"."&$G$7&"."&$G$8,index!$A:$A,0),MATCH($G$4,'Raw'!$1:$1,0)) -> -0.1819393
... B82: 2050 | D82: =INDEX('Raw'!$1:$1048576,MATCH($B82&"."&$G$6&"."&D$31&"."&$G$7&"."&$G$8,index!$A:$A,0),MATCH($G$4,'Raw'!$1:$1,0)) -> 0.22326131 | E82: =INDEX('Raw'!$1:$1048576,MATCH($B82&"."&$G$6&"."&E$31&"."&$G$7&"."&$G$8,index!$A:$A,0),MATCH($G$4,'Raw'!$1:$1,0)) -> 0.14381471 | F82: =INDEX('Raw'!$1:$1048576,MATCH($B82&"."&$G$6&"."&F$31&"."&$G$7&"."&$G$8,index!$A:$A,0),MATCH($G$4,'Raw'!$1:$1,0)) -> 0.13820538

Sheet Flexibility
B2: FLEXIBILITY OF THE ECONOMY
B4: Output variable | D4: GDP in volume | G4: =VLOOKUP(D4,Lists!A1:B20,2,FALSE) -> 100*(gdp_1/gdp_0-1)
B6: Firm redistribution | D6: Lump-sum | G6: =VLOOKUP(D6,Lists!C1:D2,2,FALSE) -> 1
B7: Wage equation | D7: Wage setting | G7: =VLOOKUP(D7,Lists!E1:F3,2,FALSE) -> 0
B8: Exposure to foreign competition | D8: High | G8: =VLOOKUP(D8,Lists!I1:J2,2,FALSE) -> 1
B29: Flexibility | D29: Low flexibility | E29: High flexibility
B30: Year | D30: 0 | E30: 1
B31: 2000 | D31: =INDEX('Raw'!$1:$1048576,MATCH($B31&"."&$G$6&"."&$G$7&"."&D$30&"."&$G$8,index!$A:$A,0),MATCH($G$4,'Raw'!$1:$1,0)) -> 0 | E31: =INDEX('Raw'!$1:$1048576,MATCH($B31&"."&$G$6&"."&$G$7&"."&E$30&"."&$G$8,index!$A:$A,0),MATCH($G$4,'Raw'!$1:$1,0)) -> 0
B32: 2001 | D32: =INDEX('Raw'!$1:$1048576,MATCH($B32&"."&$G$6&"."&$G$7&"."&D$30&"."&$G$8,index!$A:$A,0),MATCH($G$4,'Raw'!$1:$1,0)) -> 0.0015880665 | E32: =INDEX('Raw'!$1:$1048576,MATCH($B32&"."&$G$6&"."&$G$7&"."&E$30&"."&$G$8,index!$A:$A,0),MATCH($G$4,'Raw'!$1:$1,0)) -> 0.21895396
B33: 2002 | D33: =INDEX('Raw'!$1:$1048576,MATCH($B33&"."&$G$6&"."&$G$7&"."&D$30&"."&$G$8,index!$A:$A,0),MATCH($G$4,'Raw'!$1:$1,0)) -> -0.0098470345 | E33: =INDEX('Raw'!$1:$1048576,MATCH($B33&"."&$G$6&"."&$G$7&"."&E$30&"."&$G$8,index!$A:$A,0),MATCH($G$4,'Raw'!$1:$1,0)) -> 0.38987568
B34: 2003 | D34: =INDEX('Raw'!$1:$1048576,MATCH($B34&"."&$G$6&"."&$G$7&"."&D$30&"."&$G$8,index!$A:$A,0),MATCH($G$4,'Raw'!$1:$1,0)) -> -0.039937835 | E34: =INDEX('Raw'!$1:$1048576,MATCH($B34&"."&$G$6&"."&$G$7&"."&E$30&"."&$G$8,index!$A:$A,0),MATCH($G$4,'Raw'!$1:$1,0)) -> 0.48419046
B35: 2004 | D35: =INDEX('Raw'!$1:$1048576,MATCH($B35&"."&$G$6&"."&$G$7&"."&D$30&"."&$G$8,index!$A:$A,0),MATCH($G$4,'Raw'!$1:$1,0)) -> -0.088370303 | E35: =INDEX('Raw'!$1:$1048576,MATCH($B35&"."&$G$6&"."&$G$7&"."&E$30&"."&$G$8,index!$A:$A,0),MATCH($G$4,'Raw'!$1:$1,0)) -> 0.51029402
B36: 2005 | D36: =INDEX('Raw'!$1:$1048576,MATCH($B36&"."&$G$6&"."&$G$7&"."&D$30&"."&$G$8,index!$A:$A,0),MATCH($G$4,'Raw'!$1:$1,0)) -> -0.14876528 | E36: =INDEX('Raw'!$1:$1048576,MATCH($B36&"."&$G$6&"."&$G$7&"."&E$30&"."&$G$8,index!$A:$A,0),MATCH($G$4,'Raw'!$1:$1,0)) -> 0.48686757
B37: 2006 | D37: =INDEX('Raw'!$1:$1048576,MATCH($B37&"."&$G$6&"."&$G$7&"."&D$30&"."&$G$8,index!$A:$A,0),MATCH($G$4,'Raw'!$1:$1,0)) -> -0.21295868 | E37: =INDEX('Raw'!$1:$1048576,MATCH($B37&"."&$G$6&"."&$G$7&"."&E$30&"."&$G$8,index!$A:$A,0),MATCH($G$4,'Raw'!$1:$1,0)) -> 0.43298585
B38: 2007 | D38: =INDEX('Raw'!$1:$1048576,MATCH($B38&"."&$G$6&"."&$G$7&"."&D$30&"."&$G$8,index!$A:$A,0),MATCH($G$4,'Raw'!$1:$1,0)) -> -0.27386337 | E38: =INDEX('Raw'!$1:$1048576,MATCH($B38&"."&$G$6&"."&$G$7&"."&E$30&"."&$G$8,index!$A:$A,0),MATCH($G$4,'Raw'!$1:$1,0)) -> 0.36420726
B39: 2008 | D39: =INDEX('Raw'!$1:$1048576,MATCH($B39&"."&$G$6&"."&$G$7&"."&D$30&"."&$G$8,index!$A:$A,0),MATCH($G$4,'Raw'!$1:$1,0)) -> -0.32656275 | E39: =INDEX('Raw'!$1:$1048576,MATCH($B39&"."&$G$6&"."&$G$7&"."&E$30&"."&$G$8,index!$A:$A,0),MATCH($G$4,'Raw'!$1:$1,0)) -> 0.29178901
B40: 2009 | D40: =INDEX('Raw'!$1:$1048576,MATCH($B40&"."&$G$6&"."&$G$7&"."&D$30&"."&$G$8,index!$A:$A,0),MATCH($G$4,'Raw'!$1:$1,0)) -> -0.36836754 | E40: =INDEX('Raw'!$1:$1048576,MATCH($B40&"."&$G$6&"."&$G$7&"."&E$30&"."&$G$8,index!$A:$A,0),MATCH($G$4,'Raw'!$1:$1,0)) -> 0.22321561
B41: 2010 | D41: =INDEX('Raw'!$1:$1048576,MATCH($B41&"."&$G$6&"."&$G$7&"."&D$30&"."&$G$8,index!$A:$A,0),MATCH($G$4,'Raw'!$1:$1,0)) -> -0.39843167 | E41: =INDEX('Raw'!$1:$1048576,MATCH($B41&"."&$G$6&"."&$G$7&"."&E$30&"."&$G$8,index!$A:$A,0),MATCH($G$4,'Raw'!$1:$1,0)) -> 0.16304986
B42: 2011 | D42: =INDEX('Raw'!$1:$1048576,MATCH($B42&"."&$G$6&"."&$G$7&"."&D$30&"."&$G$8,index!$A:$A,0),MATCH($G$4,'Raw'!$1:$1,0)) -> -0.41724841 | E42: =INDEX('Raw'!$1:$1048576,MATCH($B42&"."&$G$6&"."&$G$7&"."&E$30&"."&$G$8,index!$A:$A,0),MATCH($G$4,'Raw'!$1:$1,0)) -> 0.11371069
... B81: 2050 | D81: =INDEX('Raw'!$1:$1048576,MATCH($B81&"."&$G$6&"."&$G$7&"."&D$30&"."&$G$8,index!$A:$A,0),MATCH($G$4,'Raw'!$1:$1,0)) -> -0.17885163 | E81: =INDEX('Raw'!$1:$1048576,MATCH($B81&"."&$G$6&"."&$G$7&"."&E$30&"."&$G$8,index!$A:$A,0),MATCH($G$4,'Raw'!$1:$1,0)) -> 0.22326131

Sheet Exposure
B2: EXPOSITION TO FOREIGN COMPETITION
B4: Output variable | D4: GDP in volume | G4: =VLOOKUP(D4,Lists!A1:B20,2,FALSE) -> 100*(gdp_1/gdp_0-1)
B6: Firm redistribution | D6: Lump-sum | G6: =VLOOKUP(D6,Lists!C1:D2,2,FALSE) -> 1
B7: Wage equation | D7: Wage setting | G7: =VLOOKUP(D7,Lists!E1:F3,2,FALSE) -> 0
B8: Flexibility | D8: Low | G8: =VLOOKUP(D8,Lists!G1:H2,2,FALSE) -> 0
B29: Exposition | D29: Low exposure | E29: High exposure
B30: Year | D30: 0 | E30: 1
B31: 2000 | D31: =INDEX('Raw'!$1:$1048576,MATCH($B31&"."&$G$6&"."&$G$7&"."&$G$8&"."&D$30,index!$A:$A,0),MATCH($G$4,'Raw'!$1:$1,0)) -> 0 | E31: =INDEX('Raw'!$1:$1048576,MATCH($B31&"."&$G$6&"."&$G$7&"."&$G$8&"."&E$30,index!$A:$A,0),MATCH($G$4,'Raw'!$1:$1,0)) -> 0
B32: 2001 | D32: =INDEX('Raw'!$1:$1048576,MATCH($B32&"."&$G$6&"."&$G$7&"."&$G$8&"."&D$30,index!$A:$A,0),MATCH($G$4,'Raw'!$1:$1,0)) -> 0.03119858 | E32: =INDEX('Raw'!$1:$1048576,MATCH($B32&"."&$G$6&"."&$G$7&"."&$G$8&"."&E$30,index!$A:$A,0),MATCH($G$4,'Raw'!$1:$1,0)) -> 0.0015880665
B33: 2002 | D33: =INDEX('Raw'!$1:$1048576,MATCH($B33&"."&$G$6&"."&$G$7&"."&$G$8&"."&D$30,index!$A:$A,0),MATCH($G$4,'Raw'!$1:$1,0)) -> 0.063863963 | E33: =INDEX('Raw'!$1:$1048576,MATCH($B33&"."&$G$6&"."&$G$7&"."&$G$8&"."&E$30,index!$A:$A,0),MATCH($G$4,'Raw'!$1:$1,0)) -> -0.0098470345
