Workbook

Sheet Feuil1
B1: 42005 | C1: 42370 | D1: 42736 | E1: 43101 | F1: 43466 | G1: 43831 | H1: 44197 | I1: 44562 | J1: 44927 | K1: 45292 | L1: 45658 | M1: 46023 | N1: 46388 | O1: 46753 | P1: 47119 | Q1: 47484 | R1: 47849 | S1: 48214 | T1: 48580 | U1: 48945 | V1: 49310 | W1: 49675 | X1: 50041 | Y1: 50406 | Z1: 50771 | AA1: 51136 | AB1: 51502 | AC1: 51867 | AD1: 52232 | AE1: 52597 | AF1: 52963 | AG1: 53328 | AH1: 53693 | AI1: 54058 | AJ1: 54424 | AK1: 54789
A2: =[1]Macro!A47 -> gdp_2 | B2: =[1]Macro!B47 -> 2197953 | C2: =[1]Macro!C47 -> 2239237.1 | D2: =[1]Macro!D47 -> 2285529.5 | E2: =[1]Macro!E47 -> 2336270.9 | F2: =[1]Macro!F47 -> 2390477.8 | G2: =[1]Macro!G47 -> 2447784.8 | H2: =[1]Macro!H47 -> 2506128.2 | ... AK2: =[1]Macro!AK47 -> 4724867.5
A3: =[1]Results!E1600 -> IA_2 | B3: =[1]Results!F1600 -> 472737.8 | C3: =[1]Results!G1600 -> 480957.93 | D3: =[1]Results!H1600 -> 491179.38 | E3: =[1]Results!I1600 -> 502875.6 | F3: =[1]Results!J1600 -> 515844.87 | G3: =[1]Results!K1600 -> 529909.54 | H3: =[1]Results!L1600 -> 544718.54 | ... AK3: =[1]Results!AO1600 -> 1355907.6
A4: =[1]Results!E1702 -> CH_2 | B4: =[1]Results!F1702 -> 1202789 | C4: =[1]Results!G1702 -> 1221919.5 | D4: =[1]Results!H1702 -> 1245838.2 | E4: =[1]Results!I1702 -> 1273725.1 | F4: =[1]Results!J1702 -> 1304420.2 | G4: =[1]Results!K1702 -> 1337400 | H4: =[1]Results!L1702 -> 1370863.7 | ... AK4: =[1]Results!AO1702 -> 2502483.2
A5: =[1]Export!A2 -> x_2 | B5: =[1]Export!B2 -> 631198.05 | C5: =[1]Export!C2 -> 654756.82 | D5: =[1]Export!D2 -> 678323.2 | E5: =[1]Export!E2 -> 701920.1 | F5: =[1]Export!F2 -> 725764.98 | G5: =[1]Export!G2 -> 749970.06 | H5: =[1]Export!H2 -> 774470.51 | ... AK5: =[1]Export!AK2 -> 1548734
A6: =[1]Import!A2 -> m_2 | B6: =[1]Import!B2 -> 655146.23 | C6: =[1]Import!C2 -> 667640.22 | D6: =[1]Import!D2 -> 683473.1 | E6: =[1]Import!E2 -> 701191.81 | F6: =[1]Import!F2 -> 720525.49 | G6: =[1]Import!G2 -> 741130.34 | H6: =[1]Import!H2 -> 762260.61 | ... AK6: =[1]Import!AK2 -> 1596300.9
A7: =[1]Macro!A49 -> spend_g_val_2 | B7: =[1]Macro!B49 -> 1178854.2 | C7: =[1]Macro!C49 -> 1219274.6 | D7: =[1]Macro!D49 -> 1258349.8 | E7: =[1]Macro!E49 -> 1300078.3 | F7: =[1]Macro!F49 -> 1343849.5 | G7: =[1]Macro!G49 -> 1386732.5 | H7: =[1]Macro!H49 -> 1430531.5 | ... AK7: =[1]Macro!AK49 -> 2713444.5
A8: =[1]Macro!A50 -> inc_g_val_2 | B8: =[1]Macro!B50 -> 1011152.6 | C8: =[1]Macro!C50 -> 1048701.7 | D8: =[1]Macro!D50 -> 1091835 | E8: =[1]Macro!E50 -> 1140625.2 | F8: =[1]Macro!F50 -> 1194173.9 | G8: =[1]Macro!G50 -> 1252277.6 | H8: =[1]Macro!H50 -> 1314926.9 | ... AK8: =[1]Macro!AK50 -> 4664684
A9: =[1]Macro!A51 -> bal_g_tot_val_2 | B9: =[1]Macro!B51 -> -65724.459 | C9: =[1]Macro!C51 -> -65309.65 | D9: =[1]Macro!D51 -> -57986.037 | E9: =[1]Macro!E51 -> -48025.027 | F9: =[1]Macro!F51 -> -35846.289 | G9: =[1]Macro!G51 -> -18833.264 | H9: =[1]Macro!H51 -> 958.74692 | ... AK9: =[1]Macro!AK51 -> 1454933.5
A10: =[1]Macro!A52 -> debt_g_val_2 | B10: =[1]Macro!B52 -> 2105265.8 | C10: =[1]Macro!C52 -> 2170575.5 | D10: =[1]Macro!D52 -> 2228561.5 | E10: =[1]Macro!E52 -> 2276586.5 | F10: =[1]Macro!F52 -> 2312432.8 | G10: =[1]Macro!G52 -> 2331266.1 | H10: =[1]Macro!H52 -> 2330307.3 | ... AK10: =[1]Macro!AK52 -> -11381052
A11: =[1]Macro!A53 -> pch_2 | B11: =[1]Macro!B53 -> 1.0019287 | C11: =[1]Macro!C53 -> 1.0214946 | D11: =[1]Macro!D53 -> 1.041886 | E11: =[1]Macro!E53 -> 1.0642234 | F11: =[1]Macro!F53 -> 1.0859774 | G11: =[1]Macro!G53 -> 1.1087035 | H11: =[1]Macro!H53 -> 1.133503 | ... AK11: =[1]Macro!AK53 -> 2.0925952
A12: =[1]Macro!A54 -> pgdp_2 | B12: =[1]Macro!B54 -> 1.0015748 | C12: =[1]Macro!C54 -> 1.0230752 | D12: =[1]Macro!D54 -> 1.0456738 | E12: =[1]Macro!E54 -> 1.0706742 | F12: =[1]Macro!F54 -> 1.095908 | G12: =[1]Macro!G54 -> 1.1224796 | H12: =[1]Macro!H54 -> 1.1506011 | ... AK12: =[1]Macro!AK54 -> 2.2948358
A13: =[1]Macro!A55 -> py_2 | B13: =[1]Macro!B55 -> 1.0006765 | C13: =[1]Macro!C55 -> 1.0208243 | D13: =[1]Macro!D55 -> 1.0419147 | E13: =[1]Macro!E55 -> 1.0648661 | F13: =[1]Macro!F55 -> 1.0886365 | G13: =[1]Macro!G55 -> 1.1135518 | H13: =[1]Macro!H55 -> 1.1406468 | ... AK13: =[1]Macro!AK55 -> 2.2077108
A14: =[1]Macro!A56 -> pm_2 | B14: =[1]Macro!B56 -> 1 | C14: =[1]Macro!C56 -> 1.0126181 | D14: =[1]Macro!D56 -> 1.0253816 | E14: =[1]Macro!E56 -> 1.0382882 | F14: =[1]Macro!F56 -> 1.0513468 | G14: =[1]Macro!G56 -> 1.0645632 | H14: =[1]Macro!H56 -> 1.0816469 | ... AK14: =[1]Macro!AK56 -> 1.6422207
A15: =[1]Macro!A57 -> pi_2 | B15: =[1]Macro!B57 -> 1.0011136 | C15: =[1]Macro!C57 -> 1.0199106 | D15: =[1]Macro!D57 -> 1.0396066 | E15: =[1]Macro!E57 -> 1.0616317 | F15: =[1]Macro!F57 -> 1.0845147 | G15: =[1]Macro!G57 -> 1.1088021 | H15: =[1]Macro!H57 -> 1.1354192 | ... AK15: =[1]Macro!AK57 -> 2.1784036
A16: =[1]Macro!A58 -> px_2 | B16: =[1]Macro!B58 -> 1.0009288 | C16: =[1]Macro!C58 -> 1.020737 | D16: =[1]Macro!D58 -> 1.0413841 | E16: =[1]Macro!E58 -> 1.0636815 | F16: =[1]Macro!F58 -> 1.0862989 | G16: =[1]Macro!G58 -> 1.1096044 | H16: =[1]Macro!H58 -> 1.1350647 | ... AK16: =[1]Macro!AK58 -> 2.1165128
A17: =[1]Macro!A59 -> cu_2 | B17: =[1]Macro!B59 -> 0.99335227 | C17: =[1]Macro!C59 -> 1.0100363 | D17: =[1]Macro!D59 -> 1.0285712 | E17: =[1]Macro!E59 -> 1.0497166 | F17: =[1]Macro!F59 -> 1.0709883 | G17: =[1]Macro!G59 -> 1.0938783 | H17: =[1]Macro!H59 -> 1.1201302 | ... AK17: =[1]Macro!AK59 -> 2.2159142
A18: =[1]Macro!A60 -> f_l_2 | B18: =[1]Macro!B60 -> 27379.148 | C18: =[1]Macro!C60 -> 27521.356 | D18: =[1]Macro!D60 -> 27744.413 | E18: =[1]Macro!E60 -> 28034.314 | F18: =[1]Macro!F60 -> 28370.702 | G18: =[1]Macro!G60 -> 28740.316 | H18: =[1]Macro!H60 -> 29122.564 | ... AK18: =[1]Macro!AK60 -> 37956.72
... A26: =[1]Macro!A68 -> c_mat_2 | B26: =[1]Macro!B68 -> 1.0004669 | C26: =[1]Macro!C68 -> 1.0190717 | D26: =[1]Macro!D68 -> 1.0384569 | E26: =[1]Macro!E68 -> 1.0593318 | F26: =[1]Macro!F68 -> 1.080945 | G26: =[1]Macro!G68 -> 1.1035255 | H26: =[1]Macro!H68 -> 1.1276609 | ... AK26: =[1]Macro!AK68 -> 2.0711131
A27: =[1]Results!E1513 -> VA_agrf_2 | B27: =[1]Results!F1513 -> 36098.159 | C27: =[1]Results!G1513 -> 36619.673 | D27: =[1]Results!H1513 -> 37234.245 | E27: =[1]Results!I1513 -> 37940.841 | F27: =[1]Results!J1513 -> 38736.809 | G27: =[1]Results!K1513 -> 39605.486 | H27: =[1]Results!L1513 -> 40510.719 | ... AK27: =[1]Results!AO1513 -> 72126.793
A28: =[1]Results!E1514 -> VA_sagr_2 | B28: =[1]Results!F1514 -> 30808.957 | C28: =[1]Results!G1514 -> 31370.245 | D28: =[1]Results!H1514 -> 32018.461 | E28: =[1]Results!I1514 -> 32758.732 | F28: =[1]Results!J1514 -> 33562.515 | G28: =[1]Results!K1514 -> 34424.823 | H28: =[1]Results!L1514 -> 35316.121 | ... AK28: =[1]Results!AO1514 -> 65693.345
A29: =[1]Results!E1515 -> VA_sfor_2 | B29: =[1]Results!F1515 -> 5289.202 | C29: =[1]Results!G1515 -> 5249.4279 | D29: =[1]Results!H1515 -> 5215.7836 | E29: =[1]Results!I1515 -> 5182.1089 | F29: =[1]Results!J1515 -> 5174.2938 | G29: =[1]Results!K1515 -> 5180.6625 | H29: =[1]Results!L1515 -> 5194.598 | ... AK29: =[1]Results!AO1515 -> 6433.448
A30: =[1]Results!E1516 -> VA_ind_2 | B30: =[1]Results!F1516 -> 331692.74 | C30: =[1]Results!G1516 -> 339804.87 | D30: =[1]Results!H1516 -> 348264.54 | E30: =[1]Results!I1516 -> 357303.88 | F30: =[1]Results!J1516 -> 366864.75 | G30: =[1]Results!K1516 -> 376901.55 | H30: =[1]Results!L1516 -> 387187.94 | ... AK30: =[1]Results!AO1516 -> 843909.66
A31: =[1]Results!E1517 -> VA_sfoo_2 | B31: =[1]Results!F1517 -> 43690.453 | C31: =[1]Results!G1517 -> 44542.175 | D31: =[1]Results!H1517 -> 45491.199 | E31: =[1]Results!I1517 -> 46571.077 | F31: =[1]Results!J1517 -> 47732.524 | G31: =[1]Results!K1517 -> 48972.786 | H31: =[1]Results!L1517 -> 50247.621 | ... AK31: =[1]Results!AO1517 -> 93652.297
A32: =[1]Results!E1518 -> VA_sveh_2 | B32: =[1]Results!F1518 -> 29848.047 | C32: =[1]Results!G1518 -> 31129.693 | D32: =[1]Results!H1518 -> 32294.997 | E32: =[1]Results!I1518 -> 33405.019 | F32: =[1]Results!J1518 -> 34512.006 | G32: =[1]Results!K1518 -> 35602.856 | H32: =[1]Results!L1518 -> 36660.388 | ... AK32: =[1]Results!AO1518 -> 71923.47
A33: =[1]Results!E1519 -> VA_sgla_2 | B33: =[1]Results!F1519 -> 7904.2817 | C33: =[1]Results!G1519 -> 8066.2908 | D33: =[1]Results!H1519 -> 8241.6986 | E33: =[1]Results!I1519 -> 8430.708 | F33: =[1]Results!J1519 -> 8633.1747 | G33: =[1]Results!K1519 -> 8849.2095 | H33: =[1]Results!L1519 -> 9074.2893 | ... AK33: =[1]Results!AO1519 -> 18541.703
A34: =[1]Results!E1520 -> VA_spap_2 | B34: =[1]Results!F1520 -> 4277.9101 | C34: =[1]Results!G1520 -> 4387.0944 | D34: =[1]Results!H1520 -> 4495.3804 | E34: =[1]Results!I1520 -> 4610.0227 | F34: =[1]Results!J1520 -> 4729.8374 | G34: =[1]Results!K1520 -> 4854.7218 | H34: =[1]Results!L1520 -> 4981.0929 | ... AK34: =[1]Results!AO1520 -> 9296.7753
A35: =[1]Results!E1521 -> VA_sche_2 | B35: =[1]Results!F1521 -> 26174.001 | C35: =[1]Results!G1521 -> 26954.206 | D35: =[1]Results!H1521 -> 27691.911 | E35: =[1]Results!I1521 -> 28452.506 | F35: =[1]Results!J1521 -> 29243.105 | G35: =[1]Results!K1521 -> 30064.529 | H35: =[1]Results!L1521 -> 30896.878 | ... AK35: =[1]Results!AO1521 -> 56514.265
A36: =[1]Results!E1522 -> VA_spla_2 | B36: =[1]Results!F1522 -> 11103.246 | C36: =[1]Results!G1522 -> 11407.943 | D36: =[1]Results!H1522 -> 11715.087 | E36: =[1]Results!I1522 -> 12034.482 | F36: =[1]Results!J1522 -> 12365.915 | G36: =[1]Results!K1522 -> 12708.798 | H36: =[1]Results!L1522 -> 13056.977 | ... AK36: =[1]Results!AO1522 -> 25219.715
A37: =[1]Results!E1523 -> VA_smet_2 | B37: =[1]Results!F1523 -> 24632.932 | C37: =[1]Results!G1523 -> 25322.523 | D37: =[1]Results!H1523 -> 26008.488 | E37: =[1]Results!I1523 -> 26714.506 | F37: =[1]Results!J1523 -> 27445.087 | G37: =[1]Results!K1523 -> 28200.85 | H37: =[1]Results!L1523 -> 28970.091 | ... AK37: =[1]Results!AO1523 -> 55197.674
A38: =[1]Results!E1524 -> VA_sigo_2 | B38: =[1]Results!F1524 -> 30238.345 | C38: =[1]Results!G1524 -> 31341.507 | D38: =[1]Results!H1524 -> 32362.251 | E38: =[1]Results!I1524 -> 33391.247 | F38: =[1]Results!J1524 -> 34442.162 | G38: =[1]Results!K1524 -> 35515.878 | H38: =[1]Results!L1524 -> 36604.109 | ... AK38: =[1]Results!AO1524 -> 76570.692
... A64: =[1]Results!E1550 -> VA_seot_2 | B64: =[1]Results!F1550 -> -1482.5662 | C64: =[1]Results!G1550 -> -1505.0874 | D64: =[1]Results!H1550 -> -1527.0199 | E64: =[1]Results!I1550 -> -1550.6478 | F64: =[1]Results!J1550 -> -1572.5587 | G64: =[1]Results!K1550 -> -1594.488 | H64: =[1]Results!L1550 -> -1617.6403 | ... AK64: =[1]Results!AO1550 -> -2813.3483
A65: =[1]Emissions!A825 -> ems_co2_2 | B65: =[1]Emissions!B825 -> 348.01866 | C65: =[1]Emissions!C825 -> 348.28377 | D65: =[1]Emissions!D825 -> 348.67347 | E65: =[1]Emissions!E825 -> 348.87085 | F65: =[1]Emissions!F825 -> 351.10244 | G65: =[1]Emissions!G825 -> 354.89581 | H65: =[1]Emissions!H825 -> 359.01144 | ... AK65: =[1]Emissions!AK825 -> 147.03038
A66: =[1]Emissions!A826 -> ems_ci_co2_2 | B66: =[1]Emissions!B826 -> 213.27376 | C66: =[1]Emissions!C826 -> 214.38286 | D66: =[1]Emissions!D826 -> 215.69244 | E66: =[1]Emissions!E826 -> 216.73342 | F66: =[1]Emissions!F826 -> 219.1232 | G66: =[1]Emissions!G826 -> 222.63933 | H66: =[1]Emissions!H826 -> 226.48197 | ... AK66: =[1]Emissions!AK826 -> 93.766923
A67: =[1]Emissions!A827 -> ems_y_co2_2 | B67: =[1]Emissions!B827 -> 0.027534944 | C67: =[1]Emissions!C827 -> 0.028000754 | D67: =[1]Emissions!D827 -> 0.028553127 | E67: =[1]Emissions!E827 -> 0.029187546 | F67: =[1]Emissions!F827 -> 0.029887854 | G67: =[1]Emissions!G827 -> 0.030647866 | H67: =[1]Emissions!H827 -> 0.031440404 | ... AK67: =[1]Emissions!AK827 -> 0.058117794
A68: =[1]Emissions!A828 -> ems_mat_co2_2 | B68: =[1]Emissions!B828 -> 15.226879 | C68: =[1]Emissions!C828 -> 15.483759 | D68: =[1]Emissions!D828 -> 15.78032 | E68: =[1]Emissions!E828 -> 16.100702 | F68: =[1]Emissions!F828 -> 16.445879 | G68: =[1]Emissions!G828 -> 16.816248 | H68: =[1]Emissions!H828 -> 17.200623 | ... AK68: =[1]Emissions!AK828 -> 32.502948
A69: =[1]Emissions!A829 -> ems_ch_co2_2 | B69: =[1]Emissions!B829 -> 119.49049 | C69: =[1]Emissions!C829 -> 118.38914 | D69: =[1]Emissions!D829 -> 117.17215 | E69: =[1]Emissions!E829 -> 116.00754 | F69: =[1]Emissions!F829 -> 115.50346 | G69: =[1]Emissions!G829 -> 115.40958 | H69: =[1]Emissions!H829 -> 115.2974 | ... AK69: =[1]Emissions!AK829 -> 20.702396
A70: =OFFSET([1]Production!A$2,2*(ROW(A69)-ROW($A$69)),0) -> y_2 | B70: =OFFSET([1]Production!B$2,2*(ROW(B69)-ROW($A$69)),0) -> 3854147.4 | C70: =OFFSET([1]Production!C$2,2*(ROW(C69)-ROW($A$69)),0) -> 3927350.4 | D70: =OFFSET([1]Production!D$2,2*(ROW(D69)-ROW($A$69)),0) -> 4010764.8 | E70: =OFFSET([1]Production!E$2,2*(ROW(E69)-ROW($A$69)),0) -> 4101945.5 | F70: =OFFSET([1]Production!F$2,2*(ROW(F69)-ROW($A$69)),0) -> 4199327.1 | G70: =OFFSET([1]Production!G$2,2*(ROW(G69)-ROW($A$69)),0) -> 4302260.3 | H70: =OFFSET([1]Production!H$2,2*(ROW(H69)-ROW($A$69)),0) -> 4407425 | ... AK70: =OFFSET([1]Production!AK$2,2*(ROW(AK69)-ROW($A$69)),0) -> 8763009.8
A71: =OFFSET([1]Production!A$2,2*(ROW(A70)-ROW($A$69)),0) -> y_sagr_2 | B71: =OFFSET([1]Production!B$2,2*(ROW(B70)-ROW($A$69)),0) -> 81750.877 | C71: =OFFSET([1]Production!C$2,2*(ROW(C70)-ROW($A$69)),0) -> 83133.86 | D71: =OFFSET([1]Production!D$2,2*(ROW(D70)-ROW($A$69)),0) -> 84773.846 | E71: =OFFSET([1]Production!E$2,2*(ROW(E70)-ROW($A$69)),0) -> 86657.429 | F71: =OFFSET([1]Production!F$2,2*(ROW(F70)-ROW($A$69)),0) -> 88736.635 | G71: =OFFSET([1]Production!G$2,2*(ROW(G70)-ROW($A$69)),0) -> 90993.101 | H71: =OFFSET([1]Production!H$2,2*(ROW(H70)-ROW($A$69)),0) -> 93346.134 | ... AK71: =OFFSET([1]Production!AK$2,2*(ROW(AK70)-ROW($A$69)),0) -> 172550.94
A72: =OFFSET([1]Production!A$2,2*(ROW(A71)-ROW($A$69)),0) -> y_sfor_2 | B72: =OFFSET([1]Production!B$2,2*(ROW(B71)-ROW($A$69)),0) -> 6533.6203 | C72: =OFFSET([1]Production!C$2,2*(ROW(C71)-ROW($A$69)),0) -> 6485.6083 | D72: =OFFSET([1]Production!D$2,2*(ROW(D71)-ROW($A$69)),0) -> 6442.2161 | E72: =OFFSET([1]Production!E$2,2*(ROW(E71)-ROW($A$69)),0) -> 6398.553 | F72: =OFFSET([1]Production!F$2,2*(ROW(F71)-ROW($A$69)),0) -> 6386.8241 | G72: =OFFSET([1]Production!G$2,2*(ROW(G71)-ROW($A$69)),0) -> 6393.5007 | H72: =OFFSET([1]Production!H$2,2*(ROW(H71)-ROW($A$69)),0) -> 6410.05 | ... AK72: =OFFSET([1]Production!AK$2,2*(ROW(AK71)-ROW($A$69)),0) -> 7913.9703
...
