Workbook

Sheet template
A1: Model | B1: Scenario | C1: Region | D1: Variable | E1: Sector | F1: Type of variable | G1: Unit | H1: 44197 | I1: 44562 | J1: 44927 | K1: 45292 | L1: 45658 | M1: 46023 | N1: 46388 | O1: 46753 | P1: 47119 | Q1: 47484 | R1: 47849 | S1: 48214 | T1: 48580 | U1: 48945 | V1: 49310 | W1: 49675 | X1: 50041 | Y1: 50406 | Z1: 50771 | AA1: 51136 | AB1: 51502 | AC1: 51867 | AD1: 52232 | AE1: 52597 | AF1: 52963 | AG1: 53328 | AH1: 53693 | AI1: 54058 | AJ1: 54424 | AK1: 54789
A2: Three-ME | B2: Baseline | C2: France | D2: GDP | E2: Macro | F2: Volume | G2: Index (base: 2021) | H2: =base!H2/base!$H2*100 -> 100 | I2: =base!I2/base!$H2*100 -> 101.73226 | J2: =base!J2/base!$H2*100 -> 103.48099 | K2: =base!K2/base!$H2*100 -> 105.25508 | L2: =base!L2/base!$H2*100 -> 107.13135 | M2: =base!M2/base!$H2*100 -> 109.00319 | N2: =base!N2/base!$H2*100 -> 110.88445 | O2: =base!O2/base!$H2*100 -> 112.70971 | ... AK2: =base!AK2/base!$H2*100 -> 181.44477
A3: Three-ME | B3: Baseline | C3: France | D3: Investment | E3: Macro | F3: Volume | G3: Index (base: 2021) | H3: =base!H3/base!$H3*100 -> 100 | I3: =base!I3/base!$H3*100 -> 102.06437 | J3: =base!J3/base!$H3*100 -> 104.16792 | K3: =base!K3/base!$H3*100 -> 106.32098 | L3: =base!L3/base!$H3*100 -> 108.57172 | M3: =base!M3/base!$H3*100 -> 110.8963 | N3: =base!N3/base!$H3*100 -> 113.28523 | O3: =base!O3/base!$H3*100 -> 115.69089 | ... AK3: =base!AK3/base!$H3*100 -> 210.29322
A4: Three-ME | B4: Baseline | C4: France | D4: Consumption | E4: Macro | F4: Volume | G4: Index (base: 2021) | H4: =base!H4/base!$H4*100 -> 100 | I4: =base!I4/base!$H4*100 -> 101.74308 | J4: =base!J4/base!$H4*100 -> 103.47191 | K4: =base!K4/base!$H4*100 -> 105.21222 | L4: =base!L4/base!$H4*100 -> 107.04674 | M4: =base!M4/base!$H4*100 -> 108.90535 | N4: =base!N4/base!$H4*100 -> 110.79802 | O4: =base!O4/base!$H4*100 -> 112.69632 | ... AK4: =base!AK4/base!$H4*100 -> 173.81573
A5: Three-ME | B5: Baseline | C5: France | D5: Exports | E5: Macro | F5: Volume | G5: Index (base: 2021) | H5: =base!H5/base!$H5*100 -> 100 | I5: =base!I5/base!$H5*100 -> 102.0279 | J5: =base!J5/base!$H5*100 -> 104.06896 | K5: =base!K5/base!$H5*100 -> 106.12641 | L5: =base!L5/base!$H5*100 -> 108.20656 | M5: =base!M5/base!$H5*100 -> 110.30617 | N5: =base!N5/base!$H5*100 -> 112.31688 | O5: =base!O5/base!$H5*100 -> 114.01927 | ... AK5: =base!AK5/base!$H5*100 -> 205.5912
A6: Three-ME | B6: Baseline | C6: France | D6: Imports | E6: Macro | F6: Volume | G6: Index (base: 2021) | H6: =base!H6/base!$H6*100 -> 100 | I6: =base!I6/base!$H6*100 -> 101.89677 | J6: =base!J6/base!$H6*100 -> 103.81433 | K6: =base!K6/base!$H6*100 -> 105.774 | L6: =base!L6/base!$H6*100 -> 107.8377 | M6: =base!M6/base!$H6*100 -> 109.94956 | N6: =base!N6/base!$H6*100 -> 112.09449 | O6: =base!O6/base!$H6*100 -> 114.187 | ... AK6: =base!AK6/base!$H6*100 -> 193.49794
A7: Three-ME | B7: Baseline | C7: France | D7: Public surplus | E7: Macro | F7: Value | G7: Euro | H7: =base!H7/(base!H$2*base!H$14) -> -0.017059773 | I7: =base!I7/(base!I$2*base!I$14) -> -0.014458075 | J7: =base!J7/(base!J$2*base!J$14) -> -0.012104855 | K7: =base!K7/(base!K$2*base!K$14) -> -0.0097878892 | L7: =base!L7/(base!L$2*base!L$14) -> -0.0079707217 | M7: =base!M7/(base!M$2*base!M$14) -> -0.005320899 | N7: =base!N7/(base!N$2*base!N$14) -> -0.0026919127 | O7: =base!O7/(base!O$2*base!O$14) -> -0.00035473458 | ... AK7: =base!AK7/(base!AK$2*base!AK$14) -> 0.086218259
A8: Three-ME | B8: Baseline | C8: France | D8: Public debt | E8: Macro | F8: Value | G8: Euro | H8: =base!H8/(base!H$2*base!H$14) -> 0.90067846 | I8: =base!I8/(base!I$2*base!I$14) -> 0.88266612 | J8: =base!J8/(base!J$2*base!J$14) -> 0.86265177 | K8: =base!K8/(base!K$2*base!K$14) -> 0.84088707 | L8: =base!L8/(base!L$2*base!L$14) -> 0.8175116 | M8: =base!M8/(base!M$2*base!M$14) -> 0.79268949 | N8: =base!N8/(base!N$2*base!N$14) -> 0.76654865 | O8: =base!O8/(base!O$2*base!O$14) -> 0.74009614 | ... AK8: =base!AK8/(base!AK$2*base!AK$14) -> -0.24372015
A9: Three-ME | B9: Baseline | C9: France | D9: Primary public surplus | E9: Macro | F9: Value | G9: Euro | H9: =base!H9/(base!H$2*base!H$14) -> 0.00024634369 | I9: =base!I9/(base!I$2*base!I$14) -> 0.0026588286 | J9: =base!J9/(base!J$2*base!J$14) -> 0.0049478458 | K9: =base!K9/(base!K$2*base!K$14) -> 0.0071516912 | L9: =base!L9/(base!L$2*base!L$14) -> 0.0087255598 | M9: =base!M9/(base!M$2*base!M$14) -> 0.011021242 | N9: =base!N9/(base!N$2*base!N$14) -> 0.01313751 | O9: =base!O9/(base!O$2*base!O$14) -> 0.014801491 | ... AK9: =base!AK9/(base!AK$2*base!AK$14) -> 0.082314554
A10: Three-ME | B10: Baseline | C10: France | D10: Energy bill | E10: Macro | F10: Value | G10: Euro | H10: =base!H10/(base!H$2*base!H$14) -> 0.012332001 | I10: =base!I10/(base!I$2*base!I$14) -> 0.012909544 | J10: =base!J10/(base!J$2*base!J$14) -> 0.013407687 | K10: =base!K10/(base!K$2*base!K$14) -> 0.013851872 | L10: =base!L10/(base!L$2*base!L$14) -> 0.0142569 | M10: =base!M10/(base!M$2*base!M$14) -> 0.014628682 | N10: =base!N10/(base!N$2*base!N$14) -> 0.014967865 | O10: =base!O10/(base!O$2*base!O$14) -> 0.015286233 | ... AK10: =base!AK10/(base!AK$2*base!AK$14) -> 0.013689193
A11: Three-ME | B11: Baseline | C11: France | D11: Trade balance | E11: Macro | F11: Value | G11: Euro | H11: =base!H11/(base!H$2*base!H$14) -> 0.0038523426 | I11: =base!I11/(base!I$2*base!I$14) -> 0.0051382561 | J11: =base!J11/(base!J$2*base!J$14) -> 0.0065536224 | K11: =base!K11/(base!K$2*base!K$14) -> 0.0079791662 | L11: =base!L11/(base!L$2*base!L$14) -> 0.0092102944 | M11: =base!M11/(base!M$2*base!M$14) -> 0.010483146 | N11: =base!N11/(base!N$2*base!N$14) -> 0.011555301 | O11: =base!O11/(base!O$2*base!O$14) -> 0.012010948 | ... AK11: =base!AK11/(base!AK$2*base!AK$14) -> 0.053407928
A12: Three-ME | B12: Baseline | C12: France | D12: Unemployment rate | E12: Macro | F12: Rate | G12: Share of total population | H12: =base!H12 -> 0.13674745 | I12: =base!I12 -> 0.13471467 | J12: =base!J12 -> 0.1328859 | K12: =base!K12 -> 0.13122862 | L12: =base!L12 -> 0.13056274 | M12: =base!M12 -> 0.12881535 | N12: =base!N12 -> 0.12735848 | O12: =base!O12 -> 0.12643905 | ... AK12: =base!AK12 -> 0.047327205
A13: Three-ME | B13: Baseline | C13: France | D13: Consumption deflator | E13: Macro | F13: Price | G13: Index (base: 2021) | H13: =base!H13/base!$H13*100 -> 100 | I13: =base!I13/base!$H13*100 -> 101.863 | J13: =base!J13/base!$H13*100 -> 103.79455 | K13: =base!K13/base!$H13*100 -> 105.77845 | L13: =base!L13/base!$H13*100 -> 107.80236 | M13: =base!M13/base!$H13*100 -> 109.84389 | N13: =base!N13/base!$H13*100 -> 111.87612 | O13: =base!O13/base!$H13*100 -> 113.86681 | ... AK13: =base!AK13/base!$H13*100 -> 160.74456
A14: Three-ME | B14: Baseline | C14: France | D14: GDP deflator | E14: Macro | F14: Price | G14: Index (base: 2021) | H14: =base!H14/base!$H14*100 -> 100 | I14: =base!I14/base!$H14*100 -> 101.97349 | J14: =base!J14/base!$H14*100 -> 104.03598 | K14: =base!K14/base!$H14*100 -> 106.16558 | L14: =base!L14/base!$H14*100 -> 108.34506 | M14: =base!M14/base!$H14*100 -> 110.5611 | N14: =base!N14/base!$H14*100 -> 112.78779 | O14: =base!O14/base!$H14*100 -> 114.98235 | ... AK14: =base!AK14/base!$H14*100 -> 167.56184
A15: Three-ME | B15: Baseline | C15: France | D15: Production deflator | E15: Macro | F15: Price | G15: Index (base: 2021) | H15: =base!H15/base!$H15*100 -> 100 | I15: =base!I15/base!$H15*100 -> 101.96647 | J15: =base!J15/base!$H15*100 -> 104.01015 | K15: =base!K15/base!$H15*100 -> 106.11419 | L15: =base!L15/base!$H15*100 -> 108.26415 | M15: =base!M15/base!$H15*100 -> 110.44216 | N15: =base!N15/base!$H15*100 -> 112.62174 | O15: =base!O15/base!$H15*100 -> 114.76469 | ... AK15: =base!AK15/base!$H15*100 -> 165.22657
A16: Three-ME | B16: Baseline | C16: France | D16: Deflator of imports | E16: Macro | F16: Price | G16: Index (base: 2021) | H16: =base!H16/base!$H16*100 -> 100 | I16: =base!I16/base!$H16*100 -> 101.59796 | J16: =base!J16/base!$H16*100 -> 103.20926 | K16: =base!K16/base!$H16*100 -> 104.83374 | L16: =base!L16/base!$H16*100 -> 106.471 | M16: =base!M16/base!$H16*100 -> 108.06445 | N16: =base!N16/base!$H16*100 -> 109.57958 | O16: =base!O16/base!$H16*100 -> 111.00945 | ... AK16: =base!AK16/base!$H16*100 -> 145.2737
A17: Three-ME | B17: Baseline | C17: France | D17: Deflator of investment | E17: Macro | F17: Price | G17: Index (base: 2021) | H17: =base!H17/base!$H17*100 -> 100 | I17: =base!I17/base!$H17*100 -> 101.91092 | J17: =base!J17/base!$H17*100 -> 103.90329 | K17: =base!K17/base!$H17*100 -> 105.94716 | L17: =base!L17/base!$H17*100 -> 108.02127 | M17: =base!M17/base!$H17*100 -> 110.09562 | N17: =base!N17/base!$H17*100 -> 112.13605 | O17: =base!O17/base!$H17*100 -> 114.10277 | ... AK17: =base!AK17/base!$H17*100 -> 164.66812
A18: Three-ME | B18: Baseline | C18: France | D18: Deflator of exports | E18: Macro | F18: Price | G18: Index (base: 2021) | H18: =base!H18/base!$H18*100 -> 100 | I18: =base!I18/base!$H18*100 -> 101.91738 | J18: =base!J18/base!$H18*100 -> 103.91903 | K18: =base!K18/base!$H18*100 -> 105.98257 | L18: =base!L18/base!$H18*100 -> 108.08923 | M18: =base!M18/base!$H18*100 -> 110.21335 | N18: =base!N18/base!$H18*100 -> 112.3226 | O18: =base!O18/base!$H18*100 -> 114.37743 | ... AK18: =base!AK18/base!$H18*100 -> 161.94193
A19: Three-ME | B19: Baseline | C19: France | D19: Unit cost of production | E19: Macro | F19: Price | G19: Index (base: 2021) | H19: =base!H19/base!$H19*100 -> 100 | I19: =base!I19/base!$H19*100 -> 101.97602 | J19: =base!J19/base!$H19*100 -> 104.01913 | K19: =base!K19/base!$H19*100 -> 106.11079 | L19: =base!L19/base!$H19*100 -> 108.21293 | M19: =base!M19/base!$H19*100 -> 110.35757 | N19: =base!N19/base!$H19*100 -> 112.50187 | O19: =base!O19/base!$H19*100 -> 114.62575 | ... AK19: =base!AK19/base!$H19*100 -> 165.68315
A20: Three-ME | B20: Baseline | C20: France | D20: Employment | E20: Macro | F20: Thousands of people | G20: Number | H20: =base!H20 -> 28279.679 | I20: =base!I20 -> 28464.796 | J20: =base!J20 -> 28643.926 | K20: =base!K20 -> 28817.205 | L20: =base!L20 -> 28997.285 | M20: =base!M20 -> 29172.28 | N20: =base!N20 -> 29338.304 | O20: =base!O20 -> 29483.766 | ... AK20: =base!AK20 -> 35122.491
A21: Three-ME | B21: Baseline | C21: France | D21: Firms' capital | E21: Macro | F21: Volume | G21: Value | H21: =base!H21/base!$H21*100 -> 100 | I21: =base!I21/base!$H21*100 -> 101.52555 | J21: =base!J21/base!$H21*100 -> 103.12538 | K21: =base!K21/base!$H21*100 -> 104.79817 | L21: =base!L21/base!$H21*100 -> 106.54719 | M21: =base!M21/base!$H21*100 -> 108.37324 | N21: =base!N21/base!$H21*100 -> 110.27616 | O21: =base!O21/base!$H21*100 -> 112.25137 | ... AK21: =base!AK21/base!$H21*100 -> 185.67194
A22: Three-ME | B22: Baseline | C22: France | D22: Firms' energy consumption | E22: Macro | F22: Volume | H22: =base!H22/base!$H22*100 -> 100 | I22: =base!I22/base!$H22*100 -> 101.19988 | J22: =base!J22/base!$H22*100 -> 102.39717 | K22: =base!K22/base!$H22*100 -> 103.5847 | L22: =base!L22/base!$H22*100 -> 104.80002 | M22: =base!M22/base!$H22*100 -> 105.99895 | N22: =base!N22/base!$H22*100 -> 107.1543 | O22: =base!O22/base!$H22*100 -> 108.18717 | ... AK22: =base!AK22/base!$H22*100 -> 167.84115
A23: Three-ME | B23: Baseline | C23: France | D23: Material consumption | E23: Macro | F23: Volume | H23: =base!H23/base!$H23*100 -> 100 | I23: =base!I23/base!$H23*100 -> 101.79193 | J23: =base!J23/base!$H23*100 -> 103.59454 | K23: =base!K23/base!$H23*100 -> 105.41719 | L23: =base!L23/base!$H23*100 -> 107.31747 | M23: =base!M23/base!$H23*100 -> 109.23699 | N23: =base!N23/base!$H23*100 -> 111.15829 | O23: =base!O23/base!$H23*100 -> 113.00664 | ... AK23: =base!AK23/base!$H23*100 -> 186.71125
A24: Three-ME | B24: Baseline | C24: France | D24: Wage | E24: Macro | F24: Value | G24: Index (base: 2021) | H24: =base!H24 -> 49.398758 | I24: =base!I24 -> 50.90364 | J24: =base!J24 -> 52.467274 | K24: =base!K24 -> 54.096553 | L24: =base!L24 -> 55.782829 | M24: =base!M24 -> 57.544746 | N24: =base!N24 -> 59.373827 | O24: =base!O24 -> 61.254823 | ... AK24: =base!AK24 -> 120.17709
A25: Three-ME | B25: Baseline | C25: France | D25: Labor cost | E25: Macro | F25: Value | G25: Unit cost | H25: =base!H25 -> 62.913273 | I25: =base!I25 -> 64.829861 | J25: =base!J25 -> 66.821275 | K25: =base!K25 -> 68.896292 | L25: =base!L25 -> 71.0439 | M25: =base!M25 -> 73.287841 | N25: =base!N25 -> 75.617323 | O25: =base!O25 -> 78.012922 | ... AK25: =base!AK25 -> 153.05514
A26: Three-ME | B26: Baseline | C26: France | D26: Capital cost | E26: Macro | F26: Value | G26: Unit cost | H26: =base!H26 -> 0.093613883 | I26: =base!I26 -> 0.095758072 | J26: =base!J26 -> 0.097959031 | K26: =base!K26 -> 0.10012844 | L26: =base!L26 -> 0.1022399 | M26: =base!M26 -> 0.10422871 | N26: =base!N26 -> 0.10603624 | O26: =base!O26 -> 0.10760077 | ... AK26: =base!AK26 -> 0.16458273
A27: Three-ME | B27: Baseline | C27: France | D27: Energy cost | E27: Macro | F27: Value | G27: Unit cost | H27: =base!H27 -> 1.2338385 | I27: =base!I27 -> 1.2869446 | J27: =base!J27 -> 1.3437479 | K27: =base!K27 -> 1.402716 | L27: =base!L27 -> 1.4631574 | M27: =base!M27 -> 1.5242745 | N27: =base!N27 -> 1.5854229 | O27: =base!O27 -> 1.646138 | ... AK27: =base!AK27 -> 2.4674337
A28: Three-ME | B28: Baseline | C28: France | D28: Material cost | E28: Macro | F28: Value | G28: Unit cost | H28: =base!H28 -> 1.1110215 | I28: =base!I28 -> 1.1309432 | J28: =base!J28 -> 1.1515104 | K28: =base!K28 -> 1.172613 | L28: =base!L28 -> 1.1941428 | M28: =base!M28 -> 1.2158519 | N28: =base!N28 -> 1.2374427 | O28: =base!O28 -> 1.2585563 | ... AK28: =base!AK28 -> 1.7747975
A29: Three-ME | B29: Baseline | C29: France | D29: Value added | E29: Agriculture | F29: Volume | G29: Index (base: 2021) | H29: =base!H30/base!$H30*100 -> 100 | I29: =base!I30/base!$H30*100 -> 101.7519 | J29: =base!J30/base!$H30*100 -> 103.52415 | K29: =base!K30/base!$H30*100 -> 105.32054 | L29: =base!L30/base!$H30*100 -> 107.1926 | M29: =base!M30/base!$H30*100 -> 109.08246 | N29: =base!N30/base!$H30*100 -> 110.95802 | O29: =base!O30/base!$H30*100 -> 112.72312 | ... AK29: =base!AK30/base!$H30*100 -> 184.72539
A30: Three-ME | B30: Baseline | C30: France | D30: Value added | E30: Forestry | F30: Volume | G30: Index (base: 2021) | H30: =base!H31/base!$H31*100 -> 100 | I30: =base!I31/base!$H31*100 -> 100.076 | J30: =base!J31/base!$H31*100 -> 100.2264 | K30: =base!K31/base!$H31*100 -> 100.42857 | L30: =base!L31/base!$H31*100 -> 100.71365 | M30: =base!M31/base!$H31*100 -> 100.99122 | N30: =base!N31/base!$H31*100 -> 101.24665 | O30: =base!O31/base!$H31*100 -> 101.4463 | ... AK30: =base!AK31/base!$H31*100 -> 120.42202
A31: Three-ME | B31: Baseline | C31: France | D31: Value added | E31: Food | F31: Volume | G31: Index (base: 2021) | H31: =base!H33/base!$H33*100 -> 100 | I31: =base!I33/base!$H33*100 -> 101.81589 | J31: =base!J33/base!$H33*100 -> 103.65101 | K31: =base!K33/base!$H33*100 -> 105.51076 | L31: =base!L33/base!$H33*100 -> 107.46054 | M31: =base!M33/base!$H33*100 -> 109.41639 | N31: =base!N33/base!$H33*100 -> 111.36644 | O31: =base!O33/base!$H33*100 -> 113.22708 | ... AK31: =base!AK33/base!$H33*100 -> 183.84562
A32: Three-ME | B32: Baseline | C32: France | D32: Value added | E32: Vehicles | F32: Volume | G32: Index (base: 2021) | H32: =base!H34/base!$H34*100 -> 100 | I32: =base!I34/base!$H34*100 -> 101.91781 | J32: =base!J34/base!$H34*100 -> 103.82673 | K32: =base!K34/base!$H34*100 -> 105.76301 | L32: =base!L34/base!$H34*100 -> 107.76951 | M32: =base!M34/base!$H34*100 -> 109.80732 | N32: =base!N34/base!$H34*100 -> 111.7846 | O32: =base!O34/base!$H34*100 -> 113.49741 | ... AK32: =base!AK34/base!$H34*100 -> 197.65678
A33: Three-ME | B33: Baseline | C33: France | D33: Value added | E33: Glass | F33: Volume | G33: Index (base: 2021) | H33: =base!H35/base!$H35*100 -> 100 | I33: =base!I35/base!$H35*100 -> 101.84774 | J33: =base!J35/base!$H35*100 -> 103.73212 | K33: =base!K35/base!$H35*100 -> 105.65673 | L33: =base!L35/base!$H35*100 -> 107.66839 | M33: =base!M35/base!$H35*100 -> 109.71887 | N33: =base!N35/base!$H35*100 -> 111.78221 | O33: =base!O35/base!$H35*100 -> 113.77681 | ... AK33: =base!AK35/base!$H35*100 -> 198.12511
A34: Three-ME | B34: Baseline | C34: France | D34: Value added | E34: Paper | F34: Volume | G34: Index (base: 2021) | H34: =base!H36/base!$H36*100 -> 100 | I34: =base!I36/base!$H36*100 -> 101.73081 | J34: =base!J36/base!$H36*100 -> 103.46254 | K34: =base!K36/base!$H36*100 -> 105.20178 | L34: =base!L36/base!$H36*100 -> 106.99815 | M34: =base!M36/base!$H36*100 -> 108.78699 | N34: =base!N36/base!$H36*100 -> 110.52157 | O34: =base!O36/base!$H36*100 -> 112.0705 | ... AK34: =base!AK36/base!$H36*100 -> 185.92311
A35: Three-ME | B35: Baseline | C35: France | D35: Value added | E35: Chemicals | F35: Volume | G35: Index (base: 2021) | H35: =base!H37/base!$H37*100 -> 100 | I35: =base!I37/base!$H37*100 -> 101.75131 | J35: =base!J37/base!$H37*100 -> 103.48913 | K35: =base!K37/base!$H37*100 -> 105.21617 | L35: =base!L37/base!$H37*100 -> 106.97002 | M35: =base!M37/base!$H37*100 -> 108.7031 | N35: =base!N37/base!$H37*100 -> 110.35014 | O35: =base!O37/base!$H37*100 -> 111.74718 | ... AK35: =base!AK37/base!$H37*100 -> 189.73009
A36: Three-ME | B36: Baseline | C36: France | D36: Value added | E36: Plastics | F36: Volume | G36: Index (base: 2021) | H36: =base!H38/base!$H38*100 -> 100 | I36: =base!I38/base!$H38*100 -> 101.78816 | J36: =base!J38/base!$H38*100 -> 103.58753 | K36: =base!K38/base!$H38*100 -> 105.40395 | L36: =base!L38/base!$H38*100 -> 107.26989 | M36: =base!M38/base!$H38*100 -> 109.14884 | N36: =base!N38/base!$H38*100 -> 110.97123 | O36: =base!O38/base!$H38*100 -> 112.58747 | ... AK36: =base!AK38/base!$H38*100 -> 192.60679
A37: Three-ME | B37: Baseline | C37: France | D37: Value added | E37: Metallurgy | F37: Volume | G37: Index (base: 2021) | H37: =base!H39/base!$H39*100 -> 100 | I37: =base!I39/base!$H39*100 -> 101.80462 | J37: =base!J39/base!$H39*100 -> 103.62821 | K37: =base!K39/base!$H39*100 -> 105.47671 | L37: =base!L39/base!$H39*100 -> 107.38119 | M37: =base!M39/base!$H39*100 -> 109.30618 | N37: =base!N39/base!$H39*100 -> 111.18016 | O37: =base!O39/base!$H39*100 -> 112.85108 | ... AK37: =base!AK39/base!$H39*100 -> 196.32402
A38: Three-ME | B38: Baseline | C38: France | D38: Value added | E38: Industry goods | F38: Volume | G38: Index (base: 2021) | H38: =base!H40/base!$H40*100 -> 100 | I38: =base!I40/base!$H40*100 -> 101.98466 | J38: =base!J40/base!$H40*100 -> 103.98469 | K38: =base!K40/base!$H40*100 -> 106.007 | L38: =base!L40/base!$H40*100 -> 108.07109 | M38: =base!M40/base!$H40*100 -> 110.15847 | N38: =base!N40/base!$H40*100 -> 112.16875 | O38: =base!O40/base!$H40*100 -> 113.90366 | ... AK38: =base!AK40/base!$H40*100 -> 202.23499
A39: Three-ME | B39: Baseline | C39: France | D39: Value added | E39: Consumer goods | F39: Volume | G39: Index (base: 2021) | H39: =base!H41/base!$H41*100 -> 100 | I39: =base!I41/base!$H41*100 -> 101.8146 | J39: =base!J41/base!$H41*100 -> 103.6511 | K39: =base!K41/base!$H41*100 -> 105.51883 | L39: =base!L41/base!$H41*100 -> 107.46743 | M39: =base!M41/base!$H41*100 -> 109.44188 | N39: =base!N41/base!$H41*100 -> 111.40622 | O39: =base!O41/base!$H41*100 -> 113.25055 | ... AK39: =base!AK41/base!$H41*100 -> 191.88955
A40: Three-ME | B40: Baseline | C40: France | D40: Value added | E40: Construction | F40: Volume | G40: Index (base: 2021) | H40: =base!H42/base!$H42*100 -> 100 | I40: =base!I42/base!$H42*100 -> 102.07582 | J40: =base!J42/base!$H42*100 -> 104.20169 | K40: =base!K42/base!$H42*100 -> 106.38877 | L40: =base!L42/base!$H42*100 -> 108.69541 | M40: =base!M42/base!$H42*100 -> 111.08026 | N40: =base!N42/base!$H42*100 -> 113.55113 | O40: =base!O42/base!$H42*100 -> 116.0805 | ... AK40: =base!AK42/base!$H42*100 -> 213.17769
...

Sheet base
B1: 42005 | C1: 42370 | D1: 42736 | E1: 43101 | F1: 43466 | G1: 43831 | H1: 44197 | I1: 44562 | J1: 44927 | K1: 45292 | L1: 45658 | M1: 46023 | N1: 46388 | O1: 46753 | P1: 47119 | Q1: 47484 | R1: 47849 | S1: 48214 | T1: 48580 | U1: 48945 | V1: 49310 | W1: 49675 | X1: 50041 | Y1: 50406 | Z1: 50771 | AA1: 51136 | AB1: 51502 | AC1: 51867 | AD1: 52232 | AE1: 52597 | AF1: 52963 | AG1: 53328 | AH1: 53693 | AI1: 54058 | AJ1: 54424 | AK1: 54789
A2: =[1]Macro!A99 -> gdp_0 | B2: =[1]Macro!B99 -> 2197953 | C2: =[1]Macro!C99 -> 2230476.4 | D2: =[1]Macro!D99 -> 2266147.4 | E2: =[1]Macro!E99 -> 2304476.7 | F2: =[1]Macro!F99 -> 2344700.1 | G2: =[1]Macro!G99 -> 2386655 | H2: =[1]Macro!H99 -> 2428465.8 | ... AK2: =[1]Macro!AK99 -> 4406324
A3: =[1]Results!E1639 -> IA_0 | B3: =[1]Results!F1639 -> 472737.8 | C3: =[1]Results!G1639 -> 479640.45 | D3: =[1]Results!H1639 -> 487700.59 | E3: =[1]Results!I1639 -> 496636.8 | F3: =[1]Results!J1639 -> 506358.69 | G3: =[1]Results!K1639 -> 516731.29 | H3: =[1]Results!L1639 -> 527414.47 | ... AK3: =[1]Results!AO1639 -> 1109116.9
A4: =[1]Results!E1731 -> CH_0 | B4: =[1]Results!F1731 -> 1202789 | C4: =[1]Results!G1731 -> 1220397.5 | D4: =[1]Results!H1731 -> 1240919.3 | E4: =[1]Results!I1731 -> 1263569.8 | F4: =[1]Results!J1731 -> 1287361.8 | G4: =[1]Results!K1731 -> 1311977.1 | H4: =[1]Results!L1731 -> 1335837.5 | ... AK4: =[1]Results!AO1731 -> 2321895.8
A5: =[1]Export!A3 -> x_0 | B5: =[1]Export!B3 -> 631198.05 | C5: =[1]Export!C3 -> 645659.12 | D5: =[1]Export!D3 -> 659829.13 | E5: =[1]Export!E3 -> 673817.85 | F5: =[1]Export!F3 -> 687886.09 | G5: =[1]Export!G3 -> 702162.43 | H5: =[1]Export!H3 -> 716590.17 | ... AK5: =[1]Export!AK3 -> 1473246.3
A6: =[1]Import!A3 -> m_0 | B6: =[1]Import!B3 -> 655146.23 | C6: =[1]Import!C3 -> 664463.74 | D6: =[1]Import!D3 -> 675963.41 | E6: =[1]Import!E3 -> 688489.73 | F6: =[1]Import!F3 -> 701879.78 | G6: =[1]Import!G3 -> 715851.24 | H6: =[1]Import!H3 -> 729712.43 | ... AK6: =[1]Import!AK3 -> 1411978.5
A7: =[1]Macro!A72 -> bal_g_tot_val_0 | B7: =[1]Macro!B72 -> -65724.458 | C7: =[1]Macro!C72 -> -68542.988 | D7: =[1]Macro!D72 -> -66434.788 | E7: =[1]Macro!E72 -> -63456.443 | F7: =[1]Macro!F72 -> -60105.648 | G7: =[1]Macro!G72 -> -53781.563 | H7: =[1]Macro!H72 -> -46675.665 | ... AK7: =[1]Macro!AK72 -> 717193.04
A8: =[1]Macro!A73 -> debt_g_val_0 | B8: =[1]Macro!B73 -> 2105265.8 | C8: =[1]Macro!C73 -> 2173808.8 | D8: =[1]Macro!D73 -> 2240243.6 | E8: =[1]Macro!E73 -> 2303700 | F8: =[1]Macro!F73 -> 2363805.7 | G8: =[1]Macro!G73 -> 2417587.2 | H8: =[1]Macro!H73 -> 2464262.9 | ... AK8: =[1]Macro!AK73 -> -2027347.8
A9: =[1]Macro!A95 -> bal_g_prim_val_0 | B9: =[1]Macro!B95 -> -21358.417 | C9: =[1]Macro!C95 -> -20676.422 | D9: =[1]Macro!D95 -> -19223.797 | E9: =[1]Macro!E95 -> -16334.445 | F9: =[1]Macro!F95 -> -11655.009 | G9: =[1]Macro!G95 -> -6167.4624 | H9: =[1]Macro!H95 -> 673.99816 | ... AK9: =[1]Macro!AK95 -> 684720.68
A10: =[1]Macro!A96 -> ener_bill_0 | B10: =[1]Macro!B96 -> 28684.77 | C10: =[1]Macro!C96 -> 29034.892 | D10: =[1]Macro!D96 -> 29339.235 | E10: =[1]Macro!E96 -> 29587.102 | F10: =[1]Macro!F96 -> 30059.54 | G10: =[1]Macro!G96 -> 30716.5 | H10: =[1]Macro!H96 -> 33740.446 | ... AK10: =[1]Macro!AK96 -> 113871.4
A11: =[1]Macro!A97 -> bal_trade_val_0 | B11: =[1]Macro!B97 -> -23361.949 | C11: =[1]Macro!C97 -> -14334.785 | D11: =[1]Macro!D97 -> -7730.366 | E11: =[1]Macro!E97 -> -1774.1393 | F11: =[1]Macro!F97 -> 3079.9967 | G11: =[1]Macro!G97 -> 7509.9023 | H11: =[1]Macro!H97 -> 10540.038 | ... AK11: =[1]Macro!AK97 -> 444265.46
A12: =[1]Macro!A98 -> unr_0 | B12: =[1]Macro!B98 -> 0.14242623 | C12: =[1]Macro!C98 -> 0.14261844 | D12: =[1]Macro!D98 -> 0.14265441 | E12: =[1]Macro!E98 -> 0.14186411 | F12: =[1]Macro!F98 -> 0.14058843 | G12: =[1]Macro!G98 -> 0.1389887 | H12: =[1]Macro!H98 -> 0.13674745 | ... AK12: =[1]Macro!AK98 -> 0.047327205
A13: =[1]Macro!A74 -> pch_0 | B13: =[1]Macro!B74 -> 1.0019287 | C13: =[1]Macro!C74 -> 1.0209119 | D13: =[1]Macro!D74 -> 1.0398984 | E13: =[1]Macro!E74 -> 1.0599435 | F13: =[1]Macro!F74 -> 1.078494 | G13: =[1]Macro!G74 -> 1.0971251 | H13: =[1]Macro!H74 -> 1.1169742 | ... AK13: =[1]Macro!AK74 -> 1.7954752
A14: =[1]Macro!A75 -> pgdp_0 | B14: =[1]Macro!B75 -> 1.0015748 | C14: =[1]Macro!C75 -> 1.0222259 | D14: =[1]Macro!D75 -> 1.0427743 | E14: =[1]Macro!E75 -> 1.06443 | F14: =[1]Macro!F75 -> 1.0850099 | G14: =[1]Macro!G75 -> 1.1056596 | H14: =[1]Macro!H75 -> 1.1266403 | ... AK14: =[1]Macro!AK75 -> 1.8878191
A15: =[1]Macro!A76 -> py_0 | B15: =[1]Macro!B76 -> 1.0006765 | C15: =[1]Macro!C76 -> 1.0200906 | D15: =[1]Macro!D76 -> 1.0394175 | E15: =[1]Macro!E76 -> 1.0594942 | F15: =[1]Macro!F76 -> 1.079276 | G15: =[1]Macro!G76 -> 1.0991176 | H15: =[1]Macro!H76 -> 1.1200898 | ... AK15: =[1]Macro!AK76 -> 1.8506859
A16: =[1]Macro!A77 -> pm_0 | B16: =[1]Macro!B77 -> 1 | C16: =[1]Macro!C77 -> 1.0126187 | D16: =[1]Macro!D77 -> 1.0253847 | E16: =[1]Macro!E77 -> 1.038296 | F16: =[1]Macro!F77 -> 1.0513623 | G16: =[1]Macro!G77 -> 1.0645895 | H16: =[1]Macro!H77 -> 1.0817288 | ... AK16: =[1]Macro!AK77 -> 1.5714675
A17: =[1]Macro!A78 -> pi_0 | B17: =[1]Macro!B78 -> 1.0011136 | C17: =[1]Macro!C78 -> 1.0191048 | D17: =[1]Macro!D78 -> 1.0367895 | E17: =[1]Macro!E78 -> 1.0555264 | F17: =[1]Macro!F78 -> 1.0738987 | G17: =[1]Macro!G78 -> 1.0925687 | H17: =[1]Macro!H78 -> 1.1125794 | ... AK17: =[1]Macro!AK78 -> 1.8320636
A18: =[1]Macro!A79 -> px_0 | B18: =[1]Macro!B79 -> 1.0009288 | C18: =[1]Macro!C79 -> 1.0199092 | D18: =[1]Macro!D79 -> 1.038742 | E18: =[1]Macro!E79 -> 1.0582712 | F18: =[1]Macro!F79 -> 1.0772277 | G18: =[1]Macro!G79 -> 1.0960393 | H18: =[1]Macro!H79 -> 1.1162461 | ... AK18: =[1]Macro!AK79 -> 1.8076704
A19: =[1]Macro!A80 -> cu_0 | B19: =[1]Macro!B80 -> 0.99335227 | C19: =[1]Macro!C80 -> 1.0104374 | D19: =[1]Macro!D80 -> 1.0279936 | E19: =[1]Macro!E80 -> 1.046912 | F19: =[1]Macro!F80 -> 1.0647773 | G19: =[1]Macro!G80 -> 1.083175 | H19: =[1]Macro!H80 -> 1.1039332 | ... AK19: =[1]Macro!AK80 -> 1.8290313
A20: =[1]Macro!A81 -> f_l_0 | B20: =[1]Macro!B81 -> 27379.148 | C20: =[1]Macro!C81 -> 27463.028 | D20: =[1]Macro!D81 -> 27580.776 | E20: =[1]Macro!E81 -> 27730.779 | F20: =[1]Macro!F81 -> 27902.628 | G20: =[1]Macro!G81 -> 28090.563 | H20: =[1]Macro!H81 -> 28279.679 | ... AK20: =[1]Macro!AK81 -> 35122.491
A21: =[1]Macro!A82 -> f_k_0 | B21: =[1]Macro!B82 -> 5223867.2 | C21: =[1]Macro!C82 -> 5285598.3 | D21: =[1]Macro!D82 -> 5350451 | E21: =[1]Macro!E82 -> 5419051.7 | F21: =[1]Macro!F82 -> 5491886.3 | G21: =[1]Macro!G82 -> 5569266.7 | H21: =[1]Macro!H82 -> 5651139.8 | ... AK21: =[1]Macro!AK82 -> 10492581
A22: =[1]Macro!A83 -> f_e_0 | B22: =[1]Macro!B83 -> 128715.09 | C22: =[1]Macro!C83 -> 129845.11 | D22: =[1]Macro!D83 -> 130908.4 | E22: =[1]Macro!E83 -> 131946.02 | F22: =[1]Macro!F83 -> 133196.59 | G22: =[1]Macro!G83 -> 134698.61 | H22: =[1]Macro!H83 -> 136301.1 | ... AK22: =[1]Macro!AK83 -> 228769.33
A23: =[1]Macro!A84 -> f_mat_0 | B23: =[1]Macro!B84 -> 1758477.5 | C23: =[1]Macro!C84 -> 1784507.9 | D23: =[1]Macro!D84 -> 1813592.5 | E23: =[1]Macro!E84 -> 1844865 | F23: =[1]Macro!F84 -> 1877854 | G23: =[1]Macro!G84 -> 1912361.4 | H23: =[1]Macro!H84 -> 1947120 | ... AK23: =[1]Macro!AK84 -> 3635492.1
A24: =[1]Macro!A85 -> w_0 | B24: =[1]Macro!B85 -> 41.206115 | C24: =[1]Macro!C85 -> 42.474185 | D24: =[1]Macro!D85 -> 43.782653 | E24: =[1]Macro!E85 -> 45.126543 | F24: =[1]Macro!F85 -> 46.518731 | G24: =[1]Macro!G85 -> 47.94126 | H24: =[1]Macro!H85 -> 49.398758 | ... AK24: =[1]Macro!AK85 -> 120.17709
... A28: =[1]Macro!A89 -> c_mat_0 | B28: =[1]Macro!B89 -> 1.0004669 | C28: =[1]Macro!C89 -> 1.0184736 | D28: =[1]Macro!D89 -> 1.0364266 | E28: =[1]Macro!E89 -> 1.0549734 | F28: =[1]Macro!F89 -> 1.0733596 | G28: =[1]Macro!G89 -> 1.0918361 | H28: =[1]Macro!H89 -> 1.1110215 | ... AK28: =[1]Macro!AK89 -> 1.7747975
A29: =[1]Results!E1552 -> VA_agrf_0 | B29: =[1]Results!F1552 -> 36098.159 | C29: =[1]Results!G1552 -> 36421.501 | D29: =[1]Results!H1552 -> 36813.129 | E29: =[1]Results!I1552 -> 37266.283 | F29: =[1]Results!J1552 -> 37780.952 | G29: =[1]Results!K1552 -> 38345.706 | H29: =[1]Results!L1552 -> 38928.936 | ... AK29: =[1]Results!AO1552 -> 68631.967
A30: =[1]Results!E1553 -> VA_sagr_0 | B30: =[1]Results!F1553 -> 30808.957 | C30: =[1]Results!G1553 -> 31184.966 | D30: =[1]Results!H1553 -> 31625.026 | E30: =[1]Results!I1553 -> 32127.895 | F30: =[1]Results!J1553 -> 32667.725 | G30: =[1]Results!K1553 -> 33243.213 | H30: =[1]Results!L1553 -> 33828.64 | ... AK30: =[1]Results!AO1553 -> 62490.087
A31: =[1]Results!E1554 -> VA_sfor_0 | B31: =[1]Results!F1554 -> 5289.202 | C31: =[1]Results!G1554 -> 5236.5354 | D31: =[1]Results!H1554 -> 5188.1023 | E31: =[1]Results!I1554 -> 5138.3884 | F31: =[1]Results!J1554 -> 5113.2264 | G31: =[1]Results!K1554 -> 5102.4936 | H31: =[1]Results!L1554 -> 5100.2965 | ... AK31: =[1]Results!AO1554 -> 6141.8799
A32: =[1]Results!E1555 -> VA_ind_0 | B32: =[1]Results!F1555 -> 331692.74 | C32: =[1]Results!G1555 -> 337438.2 | D32: =[1]Results!H1555 -> 343505.96 | E32: =[1]Results!I1555 -> 349929.82 | F32: =[1]Results!J1555 -> 356653.64 | G32: =[1]Results!K1555 -> 363647.64 | H32: =[1]Results!L1555 -> 370695.93 | ... AK32: =[1]Results!AO1555 -> 739765
A33: =[1]Results!E1556 -> VA_sfoo_0 | B33: =[1]Results!F1556 -> 43690.453 | C33: =[1]Results!G1556 -> 44313.022 | D33: =[1]Results!H1556 -> 45008.475 | E33: =[1]Results!I1556 -> 45790.966 | F33: =[1]Results!J1556 -> 46614.025 | G33: =[1]Results!K1556 -> 47479.998 | H33: =[1]Results!L1556 -> 48350.105 | ... AK33: =[1]Results!AO1556 -> 88889.55
A34: =[1]Results!E1557 -> VA_sveh_0 | B34: =[1]Results!F1557 -> 29848.047 | C34: =[1]Results!G1557 -> 30681.863 | D34: =[1]Results!H1557 -> 31486.643 | E34: =[1]Results!I1557 -> 32239.342 | F34: =[1]Results!J1557 -> 32983.67 | G34: =[1]Results!K1557 -> 33705.808 | H34: =[1]Results!L1557 -> 34386.97 | ... AK34: =[1]Results!AO1557 -> 67968.18
A35: =[1]Results!E1558 -> VA_sgla_0 | B35: =[1]Results!F1558 -> 7904.2817 | C35: =[1]Results!G1558 -> 8022.9587 | D35: =[1]Results!H1558 -> 8150.4235 | E35: =[1]Results!I1558 -> 8285.942 | F35: =[1]Results!J1558 -> 8429.9887 | G35: =[1]Results!K1558 -> 8583.1305 | H35: =[1]Results!L1558 -> 8741.0302 | ... AK35: =[1]Results!AO1558 -> 17318.176
A36: =[1]Results!E1559 -> VA_spap_0 | B36: =[1]Results!F1559 -> 4277.9101 | C36: =[1]Results!G1559 -> 4348.1288 | D36: =[1]Results!H1559 -> 4420.0588 | E36: =[1]Results!I1559 -> 4496.2852 | F36: =[1]Results!J1559 -> 4575.3695 | G36: =[1]Results!K1559 -> 4657.5485 | H36: =[1]Results!L1559 -> 4739.6266 | ... AK36: =[1]Results!AO1559 -> 8812.0612
A37: =[1]Results!E1560 -> VA_sche_0 | B37: =[1]Results!F1560 -> 26174.001 | C37: =[1]Results!G1560 -> 26647.117 | D37: =[1]Results!H1560 -> 27106.822 | E37: =[1]Results!I1560 -> 27579.385 | F37: =[1]Results!J1560 -> 28069.008 | G37: =[1]Results!K1560 -> 28578.174 | H37: =[1]Results!L1560 -> 29089.267 | ... AK37: =[1]Results!AO1560 -> 55191.091
A38: =[1]Results!E1561 -> VA_spla_0 | B38: =[1]Results!F1561 -> 11103.246 | C38: =[1]Results!G1561 -> 11296.887 | D38: =[1]Results!H1561 -> 11493.862 | E38: =[1]Results!I1561 -> 11697.826 | F38: =[1]Results!J1561 -> 11908.623 | G38: =[1]Results!K1561 -> 12126.487 | H38: =[1]Results!L1561 -> 12346.113 | ... AK38: =[1]Results!AO1561 -> 23779.451
A39: =[1]Results!E1562 -> VA_smet_0 | B39: =[1]Results!F1562 -> 24632.932 | C39: =[1]Results!G1562 -> 25066.115 | D39: =[1]Results!H1562 -> 25507.094 | E39: =[1]Results!I1562 -> 25959.82 | F39: =[1]Results!J1562 -> 26427.307 | G39: =[1]Results!K1562 -> 26911.267 | H39: =[1]Results!L1562 -> 27401.084 | ... AK39: =[1]Results!AO1562 -> 53794.91
A40: =[1]Results!E1563 -> VA_sigo_0 | B40: =[1]Results!F1563 -> 30238.345 | C40: =[1]Results!G1563 -> 30922.967 | D40: =[1]Results!H1563 -> 31563.983 | E40: =[1]Results!I1563 -> 32207.175 | F40: =[1]Results!J1563 -> 32862.536 | G40: =[1]Results!K1563 -> 33531.396 | H40: =[1]Results!L1563 -> 34205.98 | ... AK40: =[1]Results!AO1563 -> 69176.458
... A66: =[1]Results!E1589 -> VA_seot_0 | B66: =[1]Results!F1589 -> -1482.5662 | C66: =[1]Results!G1589 -> -1500.0569 | D66: =[1]Results!H1589 -> -1514.9428 | E66: =[1]Results!I1589 -> -1530.5361 | F66: =[1]Results!J1589 -> -1543.7595 | G66: =[1]Results!K1589 -> -1556.626 | H66: =[1]Results!L1589 -> -1570.5321 | ... AK66: =[1]Results!AO1589 -> -2434.9585
A67: =[1]Emissions!A820 -> ems_co2_0 | B67: =[1]Emissions!B820 -> 348.01864 | C67: =[1]Emissions!C820 -> 347.12999 | D67: =[1]Emissions!D820 -> 345.9606 | E67: =[1]Emissions!E820 -> 344.35911 | F67: =[1]Emissions!F820 -> 344.57747 | G67: =[1]Emissions!G820 -> 346.16873 | H67: =[1]Emissions!H820 -> 347.92632 | ... AK67: =[1]Emissions!AK820 -> 511.73421
A68: =[1]Emissions!A821 -> ems_ci_co2_0 | B68: =[1]Emissions!B821 -> 213.27374 | C68: =[1]Emissions!C821 -> 213.29498 | D68: =[1]Emissions!D821 -> 213.13965 | E68: =[1]Emissions!E821 -> 212.5091 | F68: =[1]Emissions!F821 -> 213.04677 | G68: =[1]Emissions!G821 -> 214.54738 | H68: =[1]Emissions!H821 -> 216.2543 | ... AK68: =[1]Emissions!AK821 -> 361.1347
...

Sheet Orderly
B1: 42005 | C1: 42370 | D1: 42736 | E1: 43101 | F1: 43466 | G1: 43831 | H1: 44197 | I1: 44562 | J1: 44927 | K1: 45292 | L1: 45658 | M1: 46023 | N1: 46388 | O1: 46753 | P1: 47119 | Q1: 47484 | R1: 47849 | S1: 48214 | T1: 48580 | U1: 48945 | V1: 49310 | W1: 49675 | X1: 50041 | Y1: 50406 | Z1: 50771 | AA1: 51136 | AB1: 51502 | AC1: 51867 | AD1: 52232 | AE1: 52597 | AF1: 52963 | AG1: 53328 | AH1: 53693 | AI1: 54058 | AJ1: 54424 | AK1: 54789
A2: =[1]Macro!A47 -> gdp_2 | B2: =[1]Macro!B47 -> 2197953 | C2: =[1]Macro!C47 -> 2230476.4 | D2: =[1]Macro!D47 -> 2266147.4 | E2: =[1]Macro!E47 -> 2304476.7 | F2: =[1]Macro!F47 -> 2344700.1 | G2: =[1]Macro!G47 -> 2386655 | H2: =[1]Macro!H47 -> 2429108.1 | ... AK2: =[1]Macro!AK47 -> 4517957.1
A3: =[1]Results!E1600 -> IA_2 | B3: =[1]Results!F1600 -> 472737.8 | C3: =[1]Results!G1600 -> 479640.45 | D3: =[1]Results!H1600 -> 487700.59 | E3: =[1]Results!I1600 -> 496636.8 | F3: =[1]Results!J1600 -> 506358.69 | G3: =[1]Results!K1600 -> 516731.29 | H3: =[1]Results!L1600 -> 527542.26 | ... AK3: =[1]Results!AO1600 -> 1278323
A4: =[1]Results!E1702 -> CH_2 | B4: =[1]Results!F1702 -> 1202789 | C4: =[1]Results!G1702 -> 1220397.5 | D4: =[1]Results!H1702 -> 1240919.3 | E4: =[1]Results!I1702 -> 1263569.8 | F4: =[1]Results!J1702 -> 1287361.8 | G4: =[1]Results!K1702 -> 1311977.1 | H4: =[1]Results!L1702 -> 1336547.3 | ... AK4: =[1]Results!AO1702 -> 2416198
A5: =[1]Export!A2 -> x_2 | B5: =[1]Export!B2 -> 631198.05 | C5: =[1]Export!C2 -> 645659.12 | D5: =[1]Export!D2 -> 659829.13 | E5: =[1]Export!E2 -> 673817.85 | F5: =[1]Export!F2 -> 687886.09 | G5: =[1]Export!G2 -> 702162.43 | H5: =[1]Export!H2 -> 716701.79 | ... AK5: =[1]Export!AK2 -> 1398524
A6: =[1]Import!A2 -> m_2 | B6: =[1]Import!B2 -> 655146.23 | C6: =[1]Import!C2 -> 664463.74 | D6: =[1]Import!D2 -> 675963.41 | E6: =[1]Import!E2 -> 688489.73 | F6: =[1]Import!F2 -> 701879.78 | G6: =[1]Import!G2 -> 715851.24 | H6: =[1]Import!H2 -> 730019.19 | ... AK6: =[1]Import!AK2 -> 1489131.4
A7: =[1]Macro!A51 -> bal_g_tot_val_2 | B7: =[1]Macro!B51 -> -65724.458 | C7: =[1]Macro!C51 -> -68542.988 | D7: =[1]Macro!D51 -> -66434.789 | E7: =[1]Macro!E51 -> -63456.443 | F7: =[1]Macro!F51 -> -60105.648 | G7: =[1]Macro!G51 -> -53781.563 | H7: =[1]Macro!H51 -> -46448.662 | ... AK7: =[1]Macro!AK51 -> 1063387.2
A8: =[1]Macro!A52 -> debt_g_val_2 | B8: =[1]Macro!B52 -> 2105265.8 | C8: =[1]Macro!C52 -> 2173808.8 | D8: =[1]Macro!D52 -> 2240243.6 | E8: =[1]Macro!E52 -> 2303700 | F8: =[1]Macro!F52 -> 2363805.7 | G8: =[1]Macro!G52 -> 2417587.2 | H8: =[1]Macro!H52 -> 2464035.9 | ... AK8: =[1]Macro!AK52 -> -4724207.2
A9: =[1]Macro!A91 -> bal_g_prim_val_2 | B9: =[1]Macro!B91 -> -21358.417 | C9: =[1]Macro!C91 -> -20676.422 | D9: =[1]Macro!D91 -> -19223.797 | E9: =[1]Macro!E91 -> -16334.445 | F9: =[1]Macro!F91 -> -11655.008 | G9: =[1]Macro!G91 -> -6167.4622 | H9: =[1]Macro!H91 -> 901.00115 | ... AK9: =[1]Macro!AK91 -> 975742.2
A10: =[1]Macro!A92 -> ener_bill_2 | B10: =[1]Macro!B92 -> 28684.77 | C10: =[1]Macro!C92 -> 29034.892 | D10: =[1]Macro!D92 -> 29339.235 | E10: =[1]Macro!E92 -> 29587.101 | F10: =[1]Macro!F92 -> 30059.54 | G10: =[1]Macro!G92 -> 30716.5 | H10: =[1]Macro!H92 -> 31824.967 | ... AK10: =[1]Macro!AK92 -> 26311.515
A11: =[1]Macro!A93 -> bal_trade_val_2 | B11: =[1]Macro!B93 -> -23361.949 | C11: =[1]Macro!C93 -> -14334.785 | D11: =[1]Macro!D93 -> -7730.3659 | E11: =[1]Macro!E93 -> -1774.1391 | F11: =[1]Macro!F93 -> 3079.9969 | G11: =[1]Macro!G93 -> 7509.9025 | H11: =[1]Macro!H93 -> 11845.058 | ... AK11: =[1]Macro!AK93 -> 398488.97
A12: =[1]Macro!A94 -> unr_2 | B12: =[1]Macro!B94 -> 0.14242623 | C12: =[1]Macro!C94 -> 0.14261844 | D12: =[1]Macro!D94 -> 0.14265441 | E12: =[1]Macro!E94 -> 0.14186411 | F12: =[1]Macro!F94 -> 0.14058843 | G12: =[1]Macro!G94 -> 0.1389887 | H12: =[1]Macro!H94 -> 0.13668008 | ... AK12: =[1]Macro!AK94 -> 0.013801406
A13: =[1]Macro!A53 -> pch_2 | B13: =[1]Macro!B53 -> 1.0019287 | C13: =[1]Macro!C53 -> 1.0209119 | D13: =[1]Macro!D53 -> 1.0398984 | E13: =[1]Macro!E53 -> 1.0599435 | F13: =[1]Macro!F53 -> 1.078494 | G13: =[1]Macro!G53 -> 1.0971251 | H13: =[1]Macro!H53 -> 1.1160388 | ... AK13: =[1]Macro!AK53 -> 1.9819788
A14: =[1]Macro!A54 -> pgdp_2 | B14: =[1]Macro!B54 -> 1.0015748 | C14: =[1]Macro!C54 -> 1.0222259 | D14: =[1]Macro!D54 -> 1.0427743 | E14: =[1]Macro!E54 -> 1.06443 | F14: =[1]Macro!F54 -> 1.0850099 | G14: =[1]Macro!G54 -> 1.1056596 | H14: =[1]Macro!H54 -> 1.1264998 | ... AK14: =[1]Macro!AK54 -> 2.1535227
A15: =[1]Macro!A55 -> py_2 | B15: =[1]Macro!B55 -> 1.0006765 | C15: =[1]Macro!C55 -> 1.0200906 | D15: =[1]Macro!D55 -> 1.0394175 | E15: =[1]Macro!E55 -> 1.0594942 | F15: =[1]Macro!F55 -> 1.079276 | G15: =[1]Macro!G55 -> 1.0991176 | H15: =[1]Macro!H55 -> 1.1192759 | ... AK15: =[1]Macro!AK55 -> 2.0871764
A16: =[1]Macro!A56 -> pm_2 | B16: =[1]Macro!B56 -> 1 | C16: =[1]Macro!C56 -> 1.0126187 | D16: =[1]Macro!D56 -> 1.0253847 | E16: =[1]Macro!E56 -> 1.038296 | F16: =[1]Macro!F56 -> 1.0513623 | G16: =[1]Macro!G56 -> 1.0645895 | H16: =[1]Macro!H56 -> 1.078541 | ... AK16: =[1]Macro!AK56 -> 1.6169305
A17: =[1]Macro!A57 -> pi_2 | B17: =[1]Macro!B57 -> 1.0011136 | C17: =[1]Macro!C57 -> 1.0191048 | D17: =[1]Macro!D57 -> 1.0367895 | E17: =[1]Macro!E57 -> 1.0555264 | F17: =[1]Macro!F57 -> 1.0738987 | G17: =[1]Macro!G57 -> 1.0925687 | H17: =[1]Macro!H57 -> 1.1118314 | ... AK17: =[1]Macro!AK57 -> 2.0877229
A18: =[1]Macro!A58 -> px_2 | B18: =[1]Macro!B58 -> 1.0009288 | C18: =[1]Macro!C58 -> 1.0199092 | D18: =[1]Macro!D58 -> 1.038742 | E18: =[1]Macro!E58 -> 1.0582712 | F18: =[1]Macro!F58 -> 1.0772277 | G18: =[1]Macro!G58 -> 1.0960393 | H18: =[1]Macro!H58 -> 1.1151091 | ... AK18: =[1]Macro!AK58 -> 2.0066234
A19: =[1]Macro!A59 -> cu_2 | B19: =[1]Macro!B59 -> 0.99335227 | C19: =[1]Macro!C59 -> 1.0104374 | D19: =[1]Macro!D59 -> 1.0279936 | E19: =[1]Macro!E59 -> 1.046912 | F19: =[1]Macro!F59 -> 1.0647773 | G19: =[1]Macro!G59 -> 1.083175 | H19: =[1]Macro!H59 -> 1.102419 | ... AK19: =[1]Macro!AK59 -> 2.1028333
A20: =[1]Macro!A60 -> f_l_2 | B20: =[1]Macro!B60 -> 27379.148 | C20: =[1]Macro!C60 -> 27463.028 | D20: =[1]Macro!D60 -> 27580.776 | E20: =[1]Macro!E60 -> 27730.779 | F20: =[1]Macro!F60 -> 27902.628 | G20: =[1]Macro!G60 -> 28090.563 | H20: =[1]Macro!H60 -> 28282.274 | ... AK20: =[1]Macro!AK60 -> 36776.975
A21: =[1]Macro!A61 -> f_k_2 | B21: =[1]Macro!B61 -> 5223867.2 | C21: =[1]Macro!C61 -> 5285598.3 | D21: =[1]Macro!D61 -> 5350451 | E21: =[1]Macro!E61 -> 5419051.7 | F21: =[1]Macro!F61 -> 5491886.3 | G21: =[1]Macro!G61 -> 5569266.7 | H21: =[1]Macro!H61 -> 5651267.6 | ... AK21: =[1]Macro!AK61 -> 11308943
A22: =[1]Macro!A62 -> f_e_2 | B22: =[1]Macro!B62 -> 128715.09 | C22: =[1]Macro!C62 -> 129845.11 | D22: =[1]Macro!D62 -> 130908.4 | E22: =[1]Macro!E62 -> 131946.02 | F22: =[1]Macro!F62 -> 133196.59 | G22: =[1]Macro!G62 -> 134698.61 | H22: =[1]Macro!H62 -> 136399.87 | ... AK22: =[1]Macro!AK62 -> 705067.95
A23: =[1]Macro!A63 -> f_mat_2 | B23: =[1]Macro!B63 -> 1758477.5 | C23: =[1]Macro!C63 -> 1784507.9 | D23: =[1]Macro!D63 -> 1813592.5 | E23: =[1]Macro!E63 -> 1844865 | F23: =[1]Macro!F63 -> 1877854 | G23: =[1]Macro!G63 -> 1912361.4 | H23: =[1]Macro!H63 -> 1947622.2 | ... AK23: =[1]Macro!AK63 -> 3834440.5
A24: =[1]Macro!A64 -> w_2 | B24: =[1]Macro!B64 -> 41.206115 | C24: =[1]Macro!C64 -> 42.474185 | D24: =[1]Macro!D64 -> 43.782653 | E24: =[1]Macro!E64 -> 45.126543 | F24: =[1]Macro!F64 -> 46.518731 | G24: =[1]Macro!G64 -> 47.94126 | H24: =[1]Macro!H64 -> 49.399442 | ... AK24: =[1]Macro!AK64 -> 137.17285
... A28: =[1]Macro!A68 -> c_mat_2 | B28: =[1]Macro!B68 -> 1.0004669 | C28: =[1]Macro!C68 -> 1.0184736 | D28: =[1]Macro!D68 -> 1.0364266 | E28: =[1]Macro!E68 -> 1.0549734 | F28: =[1]Macro!F68 -> 1.0733596 | G28: =[1]Macro!G68 -> 1.0918361 | H28: =[1]Macro!H68 -> 1.1105362 | ... AK28: =[1]Macro!AK68 -> 1.975243
A29: =[1]Results!E1513 -> VA_agrf_2 | B29: =[1]Results!F1513 -> 36098.159 | C29: =[1]Results!G1513 -> 36421.501 | D29: =[1]Results!H1513 -> 36813.129 | E29: =[1]Results!I1513 -> 37266.283 | F29: =[1]Results!J1513 -> 37780.952 | G29: =[1]Results!K1513 -> 38345.706 | H29: =[1]Results!L1513 -> 38939.771 | ... AK29: =[1]Results!AO1513 -> 68235.331
A30: =[1]Results!E1514 -> VA_sagr_2 | B30: =[1]Results!F1514 -> 30808.957 | C30: =[1]Results!G1514 -> 31184.966 | D30: =[1]Results!H1514 -> 31625.026 | E30: =[1]Results!I1514 -> 32127.895 | F30: =[1]Results!J1514 -> 32667.725 | G30: =[1]Results!K1514 -> 33243.213 | H30: =[1]Results!L1514 -> 33839.747 | ... AK30: =[1]Results!AO1514 -> 62585.006
A31: =[1]Results!E1515 -> VA_sfor_2 | B31: =[1]Results!F1515 -> 5289.202 | C31: =[1]Results!G1515 -> 5236.5354 | D31: =[1]Results!H1515 -> 5188.1023 | E31: =[1]Results!I1515 -> 5138.3884 | F31: =[1]Results!J1515 -> 5113.2264 | G31: =[1]Results!K1515 -> 5102.4936 | H31: =[1]Results!L1515 -> 5100.0235 | ... AK31: =[1]Results!AO1515 -> 5650.3249
A32: =[1]Results!E1516 -> VA_ind_2 | B32: =[1]Results!F1516 -> 331692.74 | C32: =[1]Results!G1516 -> 337438.2 | D32: =[1]Results!H1516 -> 343505.96 | E32: =[1]Results!I1516 -> 349929.82 | F32: =[1]Results!J1516 -> 356653.64 | G32: =[1]Results!K1516 -> 363647.64 | H32: =[1]Results!L1516 -> 370795.68 | ... AK32: =[1]Results!AO1516 -> 796063.71
A33: =[1]Results!E1517 -> VA_sfoo_2 | B33: =[1]Results!F1517 -> 43690.453 | C33: =[1]Results!G1517 -> 44313.022 | D33: =[1]Results!H1517 -> 45008.475 | E33: =[1]Results!I1517 -> 45790.966 | F33: =[1]Results!J1517 -> 46614.025 | G33: =[1]Results!K1517 -> 47479.998 | H33: =[1]Results!L1517 -> 48363.635 | ... AK33: =[1]Results!AO1517 -> 89705.323
A34: =[1]Results!E1518 -> VA_sveh_2 | B34: =[1]Results!F1518 -> 29848.047 | C34: =[1]Results!G1518 -> 30681.863 | D34: =[1]Results!H1518 -> 31486.643 | E34: =[1]Results!I1518 -> 32239.342 | F34: =[1]Results!J1518 -> 32983.67 | G34: =[1]Results!K1518 -> 33705.808 | H34: =[1]Results!L1518 -> 34399.173 | ... AK34: =[1]Results!AO1518 -> 64898.172
A35: =[1]Results!E1519 -> VA_sgla_2 | B35: =[1]Results!F1519 -> 7904.2817 | C35: =[1]Results!G1519 -> 8022.9587 | D35: =[1]Results!H1519 -> 8150.4235 | E35: =[1]Results!I1519 -> 8285.942 | F35: =[1]Results!J1519 -> 8429.9887 | G35: =[1]Results!K1519 -> 8583.1305 | H35: =[1]Results!L1519 -> 8742.7436 | ... AK35: =[1]Results!AO1519 -> 17833.69
A36: =[1]Results!E1520 -> VA_spap_2 | B36: =[1]Results!F1520 -> 4277.9101 | C36: =[1]Results!G1520 -> 4348.1288 | D36: =[1]Results!H1520 -> 4420.0588 | E36: =[1]Results!I1520 -> 4496.2852 | F36: =[1]Results!J1520 -> 4575.3695 | G36: =[1]Results!K1520 -> 4657.5485 | H36: =[1]Results!L1520 -> 4741.3756 | ... AK36: =[1]Results!AO1520 -> 8860.573
A37: =[1]Results!E1521 -> VA_sche_2 | B37: =[1]Results!F1521 -> 26174.001 | C37: =[1]Results!G1521 -> 26647.117 | D37: =[1]Results!H1521 -> 27106.822 | E37: =[1]Results!I1521 -> 27579.385 | F37: =[1]Results!J1521 -> 28069.008 | G37: =[1]Results!K1521 -> 28578.174 | H37: =[1]Results!L1521 -> 29100.407 | ... AK37: =[1]Results!AO1521 -> 53287.483
A38: =[1]Results!E1522 -> VA_spla_2 | B38: =[1]Results!F1522 -> 11103.246 | C38: =[1]Results!G1522 -> 11296.887 | D38: =[1]Results!H1522 -> 11493.862 | E38: =[1]Results!I1522 -> 11697.826 | F38: =[1]Results!J1522 -> 11908.623 | G38: =[1]Results!K1522 -> 12126.487 | H38: =[1]Results!L1522 -> 12349.12 | ... AK38: =[1]Results!AO1522 -> 23826.608
A39: =[1]Results!E1523 -> VA_smet_2 | B39: =[1]Results!F1523 -> 24632.932 | C39: =[1]Results!G1523 -> 25066.115 | D39: =[1]Results!H1523 -> 25507.094 | E39: =[1]Results!I1523 -> 25959.82 | F39: =[1]Results!J1523 -> 26427.307 | G39: =[1]Results!K1523 -> 26911.267 | H39: =[1]Results!L1523 -> 27407.709 | ... AK39: =[1]Results!AO1523 -> 52035.279
A40: =[1]Results!E1524 -> VA_sigo_2 | B40: =[1]Results!F1524 -> 30238.345 | C40: =[1]Results!G1524 -> 30922.967 | D40: =[1]Results!H1524 -> 31563.983 | E40: =[1]Results!I1524 -> 32207.175 | F40: =[1]Results!J1524 -> 32862.536 | G40: =[1]Results!K1524 -> 33531.396 | H40: =[1]Results!L1524 -> 34210.86 | ... AK40: =[1]Results!AO1524 -> 70053.389
... A66: =[1]Results!E1550 -> VA_seot_2 | B66: =[1]Results!F1550 -> -1482.5662 | C66: =[1]Results!G1550 -> -1500.0569 | D66: =[1]Results!H1550 -> -1514.9428 | E66: =[1]Results!I1550 -> -1530.5361 | F66: =[1]Results!J1550 -> -1543.7595 | G66: =[1]Results!K1550 -> -1556.626 | H66: =[1]Results!L1550 -> -1570.0078 | ... AK66: =[1]Results!AO1550 -> -3742.7262
A67: =[1]Emissions!A825 -> ems_co2_2 | B67: =[1]Emissions!B825 -> 348.01866 | C67: =[1]Emissions!C825 -> 347.13002 | D67: =[1]Emissions!D825 -> 345.96062 | E67: =[1]Emissions!E825 -> 344.35913 | F67: =[1]Emissions!F825 -> 344.57749 | G67: =[1]Emissions!G825 -> 346.16875 | H67: =[1]Emissions!H825 -> 348.70131 | ... AK67: =[1]Emissions!AK825 -> 143.5138
A68: =[1]Emissions!A826 -> ems_ci_co2_2 | B68: =[1]Emissions!B826 -> 213.27376 | C68: =[1]Emissions!C826 -> 213.295 | D68: =[1]Emissions!D826 -> 213.13966 | E68: =[1]Emissions!E826 -> 212.50912 | F68: =[1]Emissions!F826 -> 213.04679 | G68: =[1]Emissions!G826 -> 214.54739 | H68: =[1]Emissions!H826 -> 216.75806 | ... AK68: =[1]Emissions!AK826 -> 97.303405
...
